2023-07-11 12:55:21,170 INFO    StreamThr :108266 [internal.py:wandb_internal():86] W&B internal server running at pid: 108266, started at: 2023-07-11 12:55:21.169625
2023-07-11 12:55:21,172 DEBUG   HandlerThread:108266 [handler.py:handle_request():144] handle_request: status
2023-07-11 12:55:21,173 INFO    WriterThread:108266 [datastore.py:open_for_write():85] open: /home/zhuhe/HPE-with-Diffusion/wandb/run-20230711_125521-hh51ey3p/run-hh51ey3p.wandb
2023-07-11 12:55:21,174 DEBUG   SenderThread:108266 [sender.py:send():369] send: header
2023-07-11 12:55:21,174 DEBUG   SenderThread:108266 [sender.py:send():369] send: run
2023-07-11 12:55:22,037 INFO    SenderThread:108266 [dir_watcher.py:__init__():211] watching files in: /home/zhuhe/HPE-with-Diffusion/wandb/run-20230711_125521-hh51ey3p/files
2023-07-11 12:55:22,037 INFO    SenderThread:108266 [sender.py:_start_run_threads():1100] run started: hh51ey3p with start time 1689051321.169547
2023-07-11 12:55:22,037 DEBUG   SenderThread:108266 [sender.py:send_request():396] send_request: summary_record
2023-07-11 12:55:22,037 INFO    SenderThread:108266 [sender.py:_save_file():1354] saving file wandb-summary.json with policy end
2023-07-11 12:55:22,039 DEBUG   HandlerThread:108266 [handler.py:handle_request():144] handle_request: check_version
2023-07-11 12:55:22,039 DEBUG   SenderThread:108266 [sender.py:send_request():396] send_request: check_version
2023-07-11 12:55:22,234 DEBUG   HandlerThread:108266 [handler.py:handle_request():144] handle_request: run_start
2023-07-11 12:55:22,243 DEBUG   HandlerThread:108266 [system_info.py:__init__():31] System info init
2023-07-11 12:55:22,243 DEBUG   HandlerThread:108266 [system_info.py:__init__():46] System info init done
2023-07-11 12:55:22,243 INFO    HandlerThread:108266 [system_monitor.py:start():181] Starting system monitor
2023-07-11 12:55:22,243 INFO    SystemMonitor:108266 [system_monitor.py:_start():145] Starting system asset monitoring threads
2023-07-11 12:55:22,244 INFO    HandlerThread:108266 [system_monitor.py:probe():201] Collecting system info
2023-07-11 12:55:22,244 INFO    SystemMonitor:108266 [interfaces.py:start():190] Started cpu monitoring
2023-07-11 12:55:22,245 INFO    SystemMonitor:108266 [interfaces.py:start():190] Started disk monitoring
2023-07-11 12:55:22,246 INFO    SystemMonitor:108266 [interfaces.py:start():190] Started gpu monitoring
2023-07-11 12:55:22,247 INFO    SystemMonitor:108266 [interfaces.py:start():190] Started memory monitoring
2023-07-11 12:55:22,248 INFO    SystemMonitor:108266 [interfaces.py:start():190] Started network monitoring
2023-07-11 12:55:22,264 DEBUG   HandlerThread:108266 [system_info.py:probe():195] Probing system
2023-07-11 12:55:22,273 DEBUG   HandlerThread:108266 [gitlib.py:_init_repo():53] git repository is invalid
2023-07-11 12:55:22,273 DEBUG   HandlerThread:108266 [system_info.py:probe():240] Probing system done
2023-07-11 12:55:22,273 DEBUG   HandlerThread:108266 [system_monitor.py:probe():210] {'os': 'Linux-5.19.0-46-generic-x86_64-with-glibc2.35', 'python': '3.9.16', 'heartbeatAt': '2023-07-11T04:55:22.264249', 'startedAt': '2023-07-11T04:55:21.163953', 'docker': None, 'cuda': None, 'args': ('--config', '/home/zhuhe/HPE-with-Diffusion/config/sanitycheck_val.json', '--phase', 'val', '--gpu_ids', '1'), 'state': 'running', 'program': '/home/zhuhe/HPE-with-Diffusion/main.py', 'codePath': 'main.py', 'host': '415-2', 'username': 'zhuhe', 'executable': '/home/zhuhe/.conda/envs/diffhpe/bin/python', 'cpu_count': 16, 'cpu_count_logical': 24, 'cpu_freq': {'current': 2446.8062916666663, 'min': 800.0, 'max': 4783.333333333333}, 'cpu_freq_per_core': [{'current': 1579.488, 'min': 800.0, 'max': 5100.0}, {'current': 5100.0, 'min': 800.0, 'max': 5100.0}, {'current': 1566.412, 'min': 800.0, 'max': 5100.0}, {'current': 2100.0, 'min': 800.0, 'max': 5100.0}, {'current': 2100.0, 'min': 800.0, 'max': 5100.0}, {'current': 1572.397, 'min': 800.0, 'max': 5100.0}, {'current': 2932.616, 'min': 800.0, 'max': 5100.0}, {'current': 2100.0, 'min': 800.0, 'max': 5100.0}, {'current': 1550.508, 'min': 800.0, 'max': 5200.0}, {'current': 2100.0, 'min': 800.0, 'max': 5200.0}, {'current': 1498.996, 'min': 800.0, 'max': 5200.0}, {'current': 2100.0, 'min': 800.0, 'max': 5200.0}, {'current': 2100.0, 'min': 800.0, 'max': 5100.0}, {'current': 1871.055, 'min': 800.0, 'max': 5100.0}, {'current': 1726.278, 'min': 800.0, 'max': 5100.0}, {'current': 2100.0, 'min': 800.0, 'max': 5100.0}, {'current': 2100.0, 'min': 800.0, 'max': 4100.0}, {'current': 2100.0, 'min': 800.0, 'max': 4100.0}, {'current': 995.528, 'min': 800.0, 'max': 4100.0}, {'current': 2100.0, 'min': 800.0, 'max': 4100.0}, {'current': 2100.0, 'min': 800.0, 'max': 4100.0}, {'current': 2100.0, 'min': 800.0, 'max': 4100.0}, {'current': 2100.0, 'min': 800.0, 'max': 4100.0}, {'current': 2100.0, 'min': 800.0, 'max': 4100.0}], 'disk': {'total': 93.31179428100586, 'used': 0.019886016845703125}, 'gpu': 'NVIDIA GeForce RTX 3090', 'gpu_count': 2, 'gpu_devices': [{'name': 'NVIDIA GeForce RTX 3090', 'memory_total': 25769803776}, {'name': 'NVIDIA GeForce RTX 3090', 'memory_total': 25769803776}], 'memory': {'total': 31.185558319091797}}
2023-07-11 12:55:22,273 INFO    HandlerThread:108266 [system_monitor.py:probe():211] Finished collecting system info
2023-07-11 12:55:22,274 INFO    HandlerThread:108266 [system_monitor.py:probe():214] Publishing system info
2023-07-11 12:55:22,274 DEBUG   HandlerThread:108266 [system_info.py:_save_pip():51] Saving list of pip packages installed into the current environment
2023-07-11 12:55:22,274 DEBUG   HandlerThread:108266 [system_info.py:_save_pip():67] Saving pip packages done
2023-07-11 12:55:22,274 DEBUG   HandlerThread:108266 [system_info.py:_save_conda():74] Saving list of conda packages installed into the current environment
2023-07-11 12:55:23,038 INFO    Thread-12 :108266 [dir_watcher.py:_on_file_created():272] file/dir created: /home/zhuhe/HPE-with-Diffusion/wandb/run-20230711_125521-hh51ey3p/files/wandb-summary.json
2023-07-11 12:55:23,038 INFO    Thread-12 :108266 [dir_watcher.py:_on_file_created():272] file/dir created: /home/zhuhe/HPE-with-Diffusion/wandb/run-20230711_125521-hh51ey3p/files/conda-environment.yaml
2023-07-11 12:55:23,038 INFO    Thread-12 :108266 [dir_watcher.py:_on_file_created():272] file/dir created: /home/zhuhe/HPE-with-Diffusion/wandb/run-20230711_125521-hh51ey3p/files/requirements.txt
2023-07-11 12:55:23,162 DEBUG   HandlerThread:108266 [system_info.py:_save_conda():86] Saving conda packages done
2023-07-11 12:55:23,162 INFO    HandlerThread:108266 [system_monitor.py:probe():216] Finished publishing system info
2023-07-11 12:55:23,164 DEBUG   SenderThread:108266 [sender.py:send():369] send: files
2023-07-11 12:55:23,164 INFO    SenderThread:108266 [sender.py:_save_file():1354] saving file wandb-metadata.json with policy now
2023-07-11 12:55:23,166 DEBUG   HandlerThread:108266 [handler.py:handle_request():144] handle_request: stop_status
2023-07-11 12:55:23,167 DEBUG   SenderThread:108266 [sender.py:send_request():396] send_request: stop_status
2023-07-11 12:55:23,629 ERROR   wandb-upload_0:108266 [internal_api.py:upload_file():2192] upload_file exception https://storage.googleapis.com/wandb-production.appspot.com/ada4321/DiffHPE/hh51ey3p/wandb-metadata.json?Expires=1689137723&GoogleAccessId=gorilla-files-url-signer-man%40wandb-production.iam.gserviceaccount.com&Signature=PwtRqBsA%2B%2FrhwC4ZW5UtF1NpqyqPfSsyWINR7aUlXi4QmdW%2Bqta7HmxVTapBFvBvpDIDkcQNuecynUjEatEDJrd7YSVgg6dWTvZ%2BId6UU1kXNXH0KiNIDc1QbNkQE75WQMiQ5wKL5ZvKNSm3BhnQt9ePb7vnRRaCkHoqy6F%2FfHm%2BMg1oGt%2Fy8HXjhwkKctHFvIMwjk8scVN8481sX%2FKXpeNRXAKjx8qyd3VgiJVm4eYIFJe3mBG5VZb6%2BSZE2RddAg4EDnr7AdRsAHLowMVwCmadYMiRN23nqeC4CS4T%2FwdlSlI6T9M%2FqY%2FqXveDMUW6nKb%2BH6RK8AfyuOUfB%2Bqnsg%3D%3D: 404 Client Error: Not Found for url: https://storage.googleapis.com/wandb-production.appspot.com/ada4321/DiffHPE/hh51ey3p/wandb-metadata.json?Expires=1689137723&GoogleAccessId=gorilla-files-url-signer-man%40wandb-production.iam.gserviceaccount.com&Signature=PwtRqBsA%2B%2FrhwC4ZW5UtF1NpqyqPfSsyWINR7aUlXi4QmdW%2Bqta7HmxVTapBFvBvpDIDkcQNuecynUjEatEDJrd7YSVgg6dWTvZ%2BId6UU1kXNXH0KiNIDc1QbNkQE75WQMiQ5wKL5ZvKNSm3BhnQt9ePb7vnRRaCkHoqy6F%2FfHm%2BMg1oGt%2Fy8HXjhwkKctHFvIMwjk8scVN8481sX%2FKXpeNRXAKjx8qyd3VgiJVm4eYIFJe3mBG5VZb6%2BSZE2RddAg4EDnr7AdRsAHLowMVwCmadYMiRN23nqeC4CS4T%2FwdlSlI6T9M%2FqY%2FqXveDMUW6nKb%2BH6RK8AfyuOUfB%2Bqnsg%3D%3D
2023-07-11 12:55:23,630 ERROR   wandb-upload_0:108266 [internal_api.py:upload_file():2194] upload_file request headers: {'User-Agent': 'python-requests/2.31.0', 'Accept-Encoding': 'gzip, deflate', 'Accept': '*/*', 'Connection': 'keep-alive', 'Content-Length': '3785'}
2023-07-11 12:55:23,630 ERROR   wandb-upload_0:108266 [internal_api.py:upload_file():2196] upload_file response body: b'<!DOCTYPE html>\n<html lang=en>\n  <meta charset=utf-8>\n  <meta name=viewport content="initial-scale=1, minimum-scale=1, width=device-width">\n  <title>Error 404 (Not Found)!!1</title>\n  <style>\n    *{margin:0;padding:0}html,code{font:15px/22px arial,sans-serif}html{background:#fff;color:#222;padding:15px}body{margin:7% auto 0;max-width:390px;min-height:180px;padding:30px 0 15px}* > body{background:url(//www.google.com/images/errors/robot.png) 100% 5px no-repeat;padding-right:205px}p{margin:11px 0 22px;overflow:hidden}ins{color:#777;text-decoration:none}a img{border:0}@media screen and (max-width:772px){body{background:none;margin-top:0;max-width:none;padding-right:0}}#logo{background:url(//www.google.com/images/branding/googlelogo/1x/googlelogo_color_150x54dp.png) no-repeat;margin-left:-5px}@media only screen and (min-resolution:192dpi){#logo{background:url(//www.google.com/images/branding/googlelogo/2x/googlelogo_color_150x54dp.png) no-repeat 0% 0%/100% 100%;-moz-border-image:url(//www.google.com/images/branding/googlelogo/2x/googlelogo_color_150x54dp.png) 0}}@media only screen and (-webkit-min-device-pixel-ratio:2){#logo{background:url(//www.google.com/images/branding/googlelogo/2x/googlelogo_color_150x54dp.png) no-repeat;-webkit-background-size:100% 100%}}#logo{display:inline-block;height:54px;width:150px}\n  </style>\n  <a href=//www.google.com/><span id=logo aria-label=Google></span></a>\n  <p><b>404.</b> <ins>That\xe2\x80\x99s an error.</ins>\n  <p>The requested URL <code>/wandb-production.appspot.com/ada4321/DiffHPE/hh51ey3p/wandb-metadata.json</code> was not found on this server.  <ins>That\xe2\x80\x99s all we know.</ins>\n'
2023-07-11 12:55:23,764 DEBUG   SenderThread:108266 [sender.py:send():369] send: telemetry
2023-07-11 12:55:24,038 INFO    Thread-12 :108266 [dir_watcher.py:_on_file_modified():289] file/dir modified: /home/zhuhe/HPE-with-Diffusion/wandb/run-20230711_125521-hh51ey3p/files/conda-environment.yaml
2023-07-11 12:55:24,038 INFO    Thread-12 :108266 [dir_watcher.py:_on_file_created():272] file/dir created: /home/zhuhe/HPE-with-Diffusion/wandb/run-20230711_125521-hh51ey3p/files/wandb-metadata.json
2023-07-11 12:55:24,038 INFO    Thread-12 :108266 [dir_watcher.py:_on_file_created():272] file/dir created: /home/zhuhe/HPE-with-Diffusion/wandb/run-20230711_125521-hh51ey3p/files/output.log
2023-07-11 12:55:24,158 ERROR   wandb-upload_0:108266 [upload_job.py:push():136] Failed to upload file: /tmp/tmp_70itzldwandb/m1cf7xiw-wandb-metadata.json
Traceback (most recent call last):
  File "/home/zhuhe/.conda/envs/diffhpe/lib/python3.9/site-packages/wandb/apis/normalize.py", line 41, in wrapper
    return func(*args, **kwargs)
  File "/home/zhuhe/.conda/envs/diffhpe/lib/python3.9/site-packages/wandb/sdk/lib/retry.py", line 212, in wrapped_fn
    return retrier(*args, **kargs)
  File "/home/zhuhe/.conda/envs/diffhpe/lib/python3.9/site-packages/wandb/sdk/lib/retry.py", line 131, in __call__
    result = self._call_fn(*args, **kwargs)
  File "/home/zhuhe/.conda/envs/diffhpe/lib/python3.9/site-packages/wandb/sdk/internal/internal_api.py", line 2218, in upload_file
    wandb._sentry.reraise(e)
  File "/home/zhuhe/.conda/envs/diffhpe/lib/python3.9/site-packages/wandb/analytics/sentry.py", line 146, in reraise
    raise exc.with_traceback(sys.exc_info()[2])
  File "/home/zhuhe/.conda/envs/diffhpe/lib/python3.9/site-packages/wandb/sdk/internal/internal_api.py", line 2190, in upload_file
    response.raise_for_status()
  File "/home/zhuhe/.conda/envs/diffhpe/lib/python3.9/site-packages/requests/models.py", line 1021, in raise_for_status
    raise HTTPError(http_error_msg, response=self)
requests.exceptions.HTTPError: 404 Client Error: Not Found for url: https://storage.googleapis.com/wandb-production.appspot.com/ada4321/DiffHPE/hh51ey3p/wandb-metadata.json?Expires=1689137723&GoogleAccessId=gorilla-files-url-signer-man%40wandb-production.iam.gserviceaccount.com&Signature=PwtRqBsA%2B%2FrhwC4ZW5UtF1NpqyqPfSsyWINR7aUlXi4QmdW%2Bqta7HmxVTapBFvBvpDIDkcQNuecynUjEatEDJrd7YSVgg6dWTvZ%2BId6UU1kXNXH0KiNIDc1QbNkQE75WQMiQ5wKL5ZvKNSm3BhnQt9ePb7vnRRaCkHoqy6F%2FfHm%2BMg1oGt%2Fy8HXjhwkKctHFvIMwjk8scVN8481sX%2FKXpeNRXAKjx8qyd3VgiJVm4eYIFJe3mBG5VZb6%2BSZE2RddAg4EDnr7AdRsAHLowMVwCmadYMiRN23nqeC4CS4T%2FwdlSlI6T9M%2FqY%2FqXveDMUW6nKb%2BH6RK8AfyuOUfB%2Bqnsg%3D%3D

During handling of the above exception, another exception occurred:

Traceback (most recent call last):
  File "/home/zhuhe/.conda/envs/diffhpe/lib/python3.9/site-packages/wandb/filesync/upload_job.py", line 127, in push
    self._api.upload_file_retry(
  File "/home/zhuhe/.conda/envs/diffhpe/lib/python3.9/site-packages/wandb/apis/normalize.py", line 51, in wrapper
    raise CommError(message, error)
wandb.errors.CommError: <Response [404]>
2023-07-11 12:55:24,366 ERROR   Thread-11 :108266 [step_upload.py:_handle_event():200] Failed to upload file: /tmp/tmp_70itzldwandb/m1cf7xiw-wandb-metadata.json
Traceback (most recent call last):
  File "/home/zhuhe/.conda/envs/diffhpe/lib/python3.9/site-packages/wandb/apis/normalize.py", line 41, in wrapper
    return func(*args, **kwargs)
  File "/home/zhuhe/.conda/envs/diffhpe/lib/python3.9/site-packages/wandb/sdk/lib/retry.py", line 212, in wrapped_fn
    return retrier(*args, **kargs)
  File "/home/zhuhe/.conda/envs/diffhpe/lib/python3.9/site-packages/wandb/sdk/lib/retry.py", line 131, in __call__
    result = self._call_fn(*args, **kwargs)
  File "/home/zhuhe/.conda/envs/diffhpe/lib/python3.9/site-packages/wandb/sdk/internal/internal_api.py", line 2218, in upload_file
    wandb._sentry.reraise(e)
  File "/home/zhuhe/.conda/envs/diffhpe/lib/python3.9/site-packages/wandb/analytics/sentry.py", line 146, in reraise
    raise exc.with_traceback(sys.exc_info()[2])
  File "/home/zhuhe/.conda/envs/diffhpe/lib/python3.9/site-packages/wandb/sdk/internal/internal_api.py", line 2190, in upload_file
    response.raise_for_status()
  File "/home/zhuhe/.conda/envs/diffhpe/lib/python3.9/site-packages/requests/models.py", line 1021, in raise_for_status
    raise HTTPError(http_error_msg, response=self)
requests.exceptions.HTTPError: 404 Client Error: Not Found for url: https://storage.googleapis.com/wandb-production.appspot.com/ada4321/DiffHPE/hh51ey3p/wandb-metadata.json?Expires=1689137723&GoogleAccessId=gorilla-files-url-signer-man%40wandb-production.iam.gserviceaccount.com&Signature=PwtRqBsA%2B%2FrhwC4ZW5UtF1NpqyqPfSsyWINR7aUlXi4QmdW%2Bqta7HmxVTapBFvBvpDIDkcQNuecynUjEatEDJrd7YSVgg6dWTvZ%2BId6UU1kXNXH0KiNIDc1QbNkQE75WQMiQ5wKL5ZvKNSm3BhnQt9ePb7vnRRaCkHoqy6F%2FfHm%2BMg1oGt%2Fy8HXjhwkKctHFvIMwjk8scVN8481sX%2FKXpeNRXAKjx8qyd3VgiJVm4eYIFJe3mBG5VZb6%2BSZE2RddAg4EDnr7AdRsAHLowMVwCmadYMiRN23nqeC4CS4T%2FwdlSlI6T9M%2FqY%2FqXveDMUW6nKb%2BH6RK8AfyuOUfB%2Bqnsg%3D%3D

During handling of the above exception, another exception occurred:

Traceback (most recent call last):
  File "/home/zhuhe/.conda/envs/diffhpe/lib/python3.9/concurrent/futures/thread.py", line 58, in run
    result = self.fn(*self.args, **self.kwargs)
  File "/home/zhuhe/.conda/envs/diffhpe/lib/python3.9/site-packages/wandb/filesync/step_upload.py", line 288, in run_and_notify
    self._do_upload_sync(event)
  File "/home/zhuhe/.conda/envs/diffhpe/lib/python3.9/site-packages/wandb/filesync/step_upload.py", line 330, in _do_upload_sync
    job.run()
  File "/home/zhuhe/.conda/envs/diffhpe/lib/python3.9/site-packages/wandb/filesync/upload_job.py", line 57, in run
    self.push()
  File "/home/zhuhe/.conda/envs/diffhpe/lib/python3.9/site-packages/wandb/filesync/upload_job.py", line 127, in push
    self._api.upload_file_retry(
  File "/home/zhuhe/.conda/envs/diffhpe/lib/python3.9/site-packages/wandb/apis/normalize.py", line 51, in wrapper
    raise CommError(message, error)
wandb.errors.CommError: <Response [404]>
2023-07-11 12:55:26,038 INFO    Thread-12 :108266 [dir_watcher.py:_on_file_modified():289] file/dir modified: /home/zhuhe/HPE-with-Diffusion/wandb/run-20230711_125521-hh51ey3p/files/output.log
2023-07-11 12:55:26,255 DEBUG   HandlerThread:108266 [handler.py:handle_request():144] handle_request: status_report
2023-07-11 12:55:28,039 INFO    Thread-12 :108266 [dir_watcher.py:_on_file_modified():289] file/dir modified: /home/zhuhe/HPE-with-Diffusion/wandb/run-20230711_125521-hh51ey3p/files/output.log
2023-07-11 12:55:31,162 DEBUG   SenderThread:108266 [sender.py:send():369] send: telemetry
2023-07-11 12:55:32,040 INFO    Thread-12 :108266 [dir_watcher.py:_on_file_modified():289] file/dir modified: /home/zhuhe/HPE-with-Diffusion/wandb/run-20230711_125521-hh51ey3p/files/output.log
2023-07-11 12:55:32,223 DEBUG   HandlerThread:108266 [handler.py:handle_request():144] handle_request: status_report
2023-07-11 12:55:34,316 DEBUG   SenderThread:108266 [sender.py:send():369] send: exit
2023-07-11 12:55:34,316 INFO    SenderThread:108266 [sender.py:send_exit():574] handling exit code: 1
2023-07-11 12:55:34,316 INFO    SenderThread:108266 [sender.py:send_exit():576] handling runtime: 12
2023-07-11 12:55:34,316 INFO    SenderThread:108266 [sender.py:_save_file():1354] saving file wandb-summary.json with policy end
2023-07-11 12:55:34,316 INFO    SenderThread:108266 [sender.py:send_exit():582] send defer
2023-07-11 12:55:34,316 DEBUG   HandlerThread:108266 [handler.py:handle_request():144] handle_request: defer
2023-07-11 12:55:34,317 INFO    HandlerThread:108266 [handler.py:handle_request_defer():170] handle defer: 0
2023-07-11 12:55:34,317 DEBUG   SenderThread:108266 [sender.py:send_request():396] send_request: defer
2023-07-11 12:55:34,317 INFO    SenderThread:108266 [sender.py:send_request_defer():598] handle sender defer: 0
2023-07-11 12:55:34,317 INFO    SenderThread:108266 [sender.py:transition_state():602] send defer: 1
2023-07-11 12:55:34,317 DEBUG   HandlerThread:108266 [handler.py:handle_request():144] handle_request: defer
2023-07-11 12:55:34,317 INFO    HandlerThread:108266 [handler.py:handle_request_defer():170] handle defer: 1
2023-07-11 12:55:34,317 DEBUG   SenderThread:108266 [sender.py:send_request():396] send_request: defer
2023-07-11 12:55:34,317 INFO    SenderThread:108266 [sender.py:send_request_defer():598] handle sender defer: 1
2023-07-11 12:55:34,317 INFO    SenderThread:108266 [sender.py:transition_state():602] send defer: 2
2023-07-11 12:55:34,317 DEBUG   HandlerThread:108266 [handler.py:handle_request():144] handle_request: defer
2023-07-11 12:55:34,317 INFO    HandlerThread:108266 [handler.py:handle_request_defer():170] handle defer: 2
2023-07-11 12:55:34,317 INFO    HandlerThread:108266 [system_monitor.py:finish():190] Stopping system monitor
2023-07-11 12:55:34,317 DEBUG   SystemMonitor:108266 [system_monitor.py:_start():159] Starting system metrics aggregation loop
2023-07-11 12:55:34,317 DEBUG   SystemMonitor:108266 [system_monitor.py:_start():166] Finished system metrics aggregation loop
2023-07-11 12:55:34,317 DEBUG   SystemMonitor:108266 [system_monitor.py:_start():170] Publishing last batch of metrics
2023-07-11 12:55:34,318 INFO    HandlerThread:108266 [interfaces.py:finish():202] Joined cpu monitor
2023-07-11 12:55:34,318 INFO    HandlerThread:108266 [interfaces.py:finish():202] Joined disk monitor
2023-07-11 12:55:34,373 INFO    HandlerThread:108266 [interfaces.py:finish():202] Joined gpu monitor
2023-07-11 12:55:34,373 INFO    HandlerThread:108266 [interfaces.py:finish():202] Joined memory monitor
2023-07-11 12:55:34,373 INFO    HandlerThread:108266 [interfaces.py:finish():202] Joined network monitor
2023-07-11 12:55:34,373 DEBUG   SenderThread:108266 [sender.py:send_request():396] send_request: defer
2023-07-11 12:55:34,373 INFO    SenderThread:108266 [sender.py:send_request_defer():598] handle sender defer: 2
2023-07-11 12:55:34,373 INFO    SenderThread:108266 [sender.py:transition_state():602] send defer: 3
2023-07-11 12:55:34,373 DEBUG   SenderThread:108266 [sender.py:send():369] send: stats
2023-07-11 12:55:34,373 DEBUG   HandlerThread:108266 [handler.py:handle_request():144] handle_request: defer
2023-07-11 12:55:34,373 INFO    HandlerThread:108266 [handler.py:handle_request_defer():170] handle defer: 3
2023-07-11 12:55:34,374 DEBUG   SenderThread:108266 [sender.py:send_request():396] send_request: defer
2023-07-11 12:55:34,374 INFO    SenderThread:108266 [sender.py:send_request_defer():598] handle sender defer: 3
2023-07-11 12:55:34,374 INFO    SenderThread:108266 [sender.py:transition_state():602] send defer: 4
2023-07-11 12:55:34,374 DEBUG   HandlerThread:108266 [handler.py:handle_request():144] handle_request: defer
2023-07-11 12:55:34,374 INFO    HandlerThread:108266 [handler.py:handle_request_defer():170] handle defer: 4
2023-07-11 12:55:34,374 DEBUG   SenderThread:108266 [sender.py:send_request():396] send_request: defer
2023-07-11 12:55:34,374 INFO    SenderThread:108266 [sender.py:send_request_defer():598] handle sender defer: 4
2023-07-11 12:55:34,374 INFO    SenderThread:108266 [sender.py:transition_state():602] send defer: 5
2023-07-11 12:55:34,374 DEBUG   HandlerThread:108266 [handler.py:handle_request():144] handle_request: defer
2023-07-11 12:55:34,374 INFO    HandlerThread:108266 [handler.py:handle_request_defer():170] handle defer: 5
2023-07-11 12:55:34,374 DEBUG   SenderThread:108266 [sender.py:send():369] send: summary
2023-07-11 12:55:34,375 INFO    SenderThread:108266 [sender.py:_save_file():1354] saving file wandb-summary.json with policy end
2023-07-11 12:55:34,375 DEBUG   SenderThread:108266 [sender.py:send_request():396] send_request: defer
2023-07-11 12:55:34,375 INFO    SenderThread:108266 [sender.py:send_request_defer():598] handle sender defer: 5
2023-07-11 12:55:34,375 INFO    SenderThread:108266 [sender.py:transition_state():602] send defer: 6
2023-07-11 12:55:34,375 DEBUG   HandlerThread:108266 [handler.py:handle_request():144] handle_request: defer
2023-07-11 12:55:34,375 INFO    HandlerThread:108266 [handler.py:handle_request_defer():170] handle defer: 6
2023-07-11 12:55:34,375 DEBUG   SenderThread:108266 [sender.py:send_request():396] send_request: defer
2023-07-11 12:55:34,375 INFO    SenderThread:108266 [sender.py:send_request_defer():598] handle sender defer: 6
2023-07-11 12:55:34,377 DEBUG   HandlerThread:108266 [handler.py:handle_request():144] handle_request: status_report
2023-07-11 12:55:34,662 INFO    SenderThread:108266 [sender.py:transition_state():602] send defer: 7
2023-07-11 12:55:34,662 DEBUG   HandlerThread:108266 [handler.py:handle_request():144] handle_request: defer
2023-07-11 12:55:34,662 INFO    HandlerThread:108266 [handler.py:handle_request_defer():170] handle defer: 7
2023-07-11 12:55:34,663 DEBUG   SenderThread:108266 [sender.py:send_request():396] send_request: defer
2023-07-11 12:55:34,663 INFO    SenderThread:108266 [sender.py:send_request_defer():598] handle sender defer: 7
2023-07-11 12:55:35,042 INFO    Thread-12 :108266 [dir_watcher.py:_on_file_modified():289] file/dir modified: /home/zhuhe/HPE-with-Diffusion/wandb/run-20230711_125521-hh51ey3p/files/wandb-summary.json
2023-07-11 12:55:35,043 INFO    Thread-12 :108266 [dir_watcher.py:_on_file_modified():289] file/dir modified: /home/zhuhe/HPE-with-Diffusion/wandb/run-20230711_125521-hh51ey3p/files/config.yaml
2023-07-11 12:55:35,316 DEBUG   HandlerThread:108266 [handler.py:handle_request():144] handle_request: poll_exit
2023-07-11 12:55:36,043 INFO    Thread-12 :108266 [dir_watcher.py:_on_file_modified():289] file/dir modified: /home/zhuhe/HPE-with-Diffusion/wandb/run-20230711_125521-hh51ey3p/files/output.log
2023-07-11 12:55:37,789 INFO    SenderThread:108266 [sender.py:transition_state():602] send defer: 8
2023-07-11 12:55:37,790 DEBUG   SenderThread:108266 [sender.py:send_request():396] send_request: poll_exit
2023-07-11 12:55:37,790 DEBUG   HandlerThread:108266 [handler.py:handle_request():144] handle_request: defer
2023-07-11 12:55:37,791 INFO    HandlerThread:108266 [handler.py:handle_request_defer():170] handle defer: 8
2023-07-11 12:55:37,791 DEBUG   SenderThread:108266 [sender.py:send_request():396] send_request: defer
2023-07-11 12:55:37,791 INFO    SenderThread:108266 [sender.py:send_request_defer():598] handle sender defer: 8
2023-07-11 12:55:37,792 INFO    SenderThread:108266 [job_builder.py:build():232] Attempting to build job artifact
2023-07-11 12:55:37,792 INFO    SenderThread:108266 [job_builder.py:build():266] no source found
2023-07-11 12:55:37,792 INFO    SenderThread:108266 [sender.py:transition_state():602] send defer: 9
2023-07-11 12:55:37,792 DEBUG   HandlerThread:108266 [handler.py:handle_request():144] handle_request: defer
2023-07-11 12:55:37,793 INFO    HandlerThread:108266 [handler.py:handle_request_defer():170] handle defer: 9
2023-07-11 12:55:37,793 DEBUG   SenderThread:108266 [sender.py:send_request():396] send_request: defer
2023-07-11 12:55:37,793 INFO    SenderThread:108266 [sender.py:send_request_defer():598] handle sender defer: 9
2023-07-11 12:55:37,793 INFO    SenderThread:108266 [dir_watcher.py:finish():359] shutting down directory watcher
2023-07-11 12:55:38,044 INFO    Thread-12 :108266 [dir_watcher.py:_on_file_modified():289] file/dir modified: /home/zhuhe/HPE-with-Diffusion/wandb/run-20230711_125521-hh51ey3p/files/output.log
2023-07-11 12:55:38,045 INFO    SenderThread:108266 [dir_watcher.py:finish():389] scan: /home/zhuhe/HPE-with-Diffusion/wandb/run-20230711_125521-hh51ey3p/files
2023-07-11 12:55:38,045 INFO    SenderThread:108266 [dir_watcher.py:finish():403] scan save: /home/zhuhe/HPE-with-Diffusion/wandb/run-20230711_125521-hh51ey3p/files/wandb-metadata.json wandb-metadata.json
2023-07-11 12:55:38,045 INFO    SenderThread:108266 [dir_watcher.py:finish():403] scan save: /home/zhuhe/HPE-with-Diffusion/wandb/run-20230711_125521-hh51ey3p/files/config.yaml config.yaml
2023-07-11 12:55:38,046 INFO    SenderThread:108266 [dir_watcher.py:finish():403] scan save: /home/zhuhe/HPE-with-Diffusion/wandb/run-20230711_125521-hh51ey3p/files/requirements.txt requirements.txt
2023-07-11 12:55:38,046 INFO    SenderThread:108266 [dir_watcher.py:finish():403] scan save: /home/zhuhe/HPE-with-Diffusion/wandb/run-20230711_125521-hh51ey3p/files/wandb-summary.json wandb-summary.json
2023-07-11 12:55:38,046 INFO    SenderThread:108266 [dir_watcher.py:finish():403] scan save: /home/zhuhe/HPE-with-Diffusion/wandb/run-20230711_125521-hh51ey3p/files/conda-environment.yaml conda-environment.yaml
2023-07-11 12:55:38,046 INFO    SenderThread:108266 [dir_watcher.py:finish():403] scan save: /home/zhuhe/HPE-with-Diffusion/wandb/run-20230711_125521-hh51ey3p/files/output.log output.log
2023-07-11 12:55:38,046 INFO    SenderThread:108266 [sender.py:transition_state():602] send defer: 10
2023-07-11 12:55:38,047 DEBUG   HandlerThread:108266 [handler.py:handle_request():144] handle_request: defer
2023-07-11 12:55:38,047 INFO    HandlerThread:108266 [handler.py:handle_request_defer():170] handle defer: 10
2023-07-11 12:55:38,057 DEBUG   SenderThread:108266 [sender.py:send_request():396] send_request: defer
2023-07-11 12:55:38,057 INFO    SenderThread:108266 [sender.py:send_request_defer():598] handle sender defer: 10
2023-07-11 12:55:38,057 INFO    SenderThread:108266 [file_pusher.py:finish():159] shutting down file pusher
2023-07-11 12:55:38,544 ERROR   wandb-upload_0:108266 [internal_api.py:upload_file():2192] upload_file exception https://storage.googleapis.com/wandb-production.appspot.com/ada4321/DiffHPE/hh51ey3p/requirements.txt?Expires=1689137738&GoogleAccessId=gorilla-files-url-signer-man%40wandb-production.iam.gserviceaccount.com&Signature=dKBK2ibEYUtz3ZWsmvy7pXLD8JK%2FM%2F6TCnoFNZLYzvBM8MozWZ1vBwVdb1S7bDmFhD47fna5W7CffgctOe1VVD%2F6%2Bwp1qZPAG1hbM%2BBWLr7xZUzzBaxJ%2FduEnSxiI%2BQegX%2BQP06DUT5O4YRlFo33Rlj8TKHiHmjG6Uh2c2951d%2Bb0KS2fWAVMvBKofMTIHZjk5%2Bjs8%2BQCz9c0V%2FvHkolaSNNpdgpFQxLJDc1AIpWN4Pm2wKx6%2FRg3WW44z5fZgoy6NWqd3w6tgI8%2FhvyUSOKT%2F%2BcK%2BLVlumbN5HuTH5ONUHZd73RPT3Sf4lNvA7yQHZ0ieF1gji63MXdJ%2Fy4fEXyUg%3D%3D: 404 Client Error: Not Found for url: https://storage.googleapis.com/wandb-production.appspot.com/ada4321/DiffHPE/hh51ey3p/requirements.txt?Expires=1689137738&GoogleAccessId=gorilla-files-url-signer-man%40wandb-production.iam.gserviceaccount.com&Signature=dKBK2ibEYUtz3ZWsmvy7pXLD8JK%2FM%2F6TCnoFNZLYzvBM8MozWZ1vBwVdb1S7bDmFhD47fna5W7CffgctOe1VVD%2F6%2Bwp1qZPAG1hbM%2BBWLr7xZUzzBaxJ%2FduEnSxiI%2BQegX%2BQP06DUT5O4YRlFo33Rlj8TKHiHmjG6Uh2c2951d%2Bb0KS2fWAVMvBKofMTIHZjk5%2Bjs8%2BQCz9c0V%2FvHkolaSNNpdgpFQxLJDc1AIpWN4Pm2wKx6%2FRg3WW44z5fZgoy6NWqd3w6tgI8%2FhvyUSOKT%2F%2BcK%2BLVlumbN5HuTH5ONUHZd73RPT3Sf4lNvA7yQHZ0ieF1gji63MXdJ%2Fy4fEXyUg%3D%3D
2023-07-11 12:55:38,545 ERROR   wandb-upload_0:108266 [internal_api.py:upload_file():2194] upload_file request headers: {'User-Agent': 'python-requests/2.31.0', 'Accept-Encoding': 'gzip, deflate', 'Accept': '*/*', 'Connection': 'keep-alive', 'Content-Length': '926'}
2023-07-11 12:55:38,545 ERROR   wandb-upload_0:108266 [internal_api.py:upload_file():2196] upload_file response body: b'<!DOCTYPE html>\n<html lang=en>\n  <meta charset=utf-8>\n  <meta name=viewport content="initial-scale=1, minimum-scale=1, width=device-width">\n  <title>Error 404 (Not Found)!!1</title>\n  <style>\n    *{margin:0;padding:0}html,code{font:15px/22px arial,sans-serif}html{background:#fff;color:#222;padding:15px}body{margin:7% auto 0;max-width:390px;min-height:180px;padding:30px 0 15px}* > body{background:url(//www.google.com/images/errors/robot.png) 100% 5px no-repeat;padding-right:205px}p{margin:11px 0 22px;overflow:hidden}ins{color:#777;text-decoration:none}a img{border:0}@media screen and (max-width:772px){body{background:none;margin-top:0;max-width:none;padding-right:0}}#logo{background:url(//www.google.com/images/branding/googlelogo/1x/googlelogo_color_150x54dp.png) no-repeat;margin-left:-5px}@media only screen and (min-resolution:192dpi){#logo{background:url(//www.google.com/images/branding/googlelogo/2x/googlelogo_color_150x54dp.png) no-repeat 0% 0%/100% 100%;-moz-border-image:url(//www.google.com/images/branding/googlelogo/2x/googlelogo_color_150x54dp.png) 0}}@media only screen and (-webkit-min-device-pixel-ratio:2){#logo{background:url(//www.google.com/images/branding/googlelogo/2x/googlelogo_color_150x54dp.png) no-repeat;-webkit-background-size:100% 100%}}#logo{display:inline-block;height:54px;width:150px}\n  </style>\n  <a href=//www.google.com/><span id=logo aria-label=Google></span></a>\n  <p><b>404.</b> <ins>That\xe2\x80\x99s an error.</ins>\n  <p>The requested URL <code>/wandb-production.appspot.com/ada4321/DiffHPE/hh51ey3p/requirements.txt</code> was not found on this server.  <ins>That\xe2\x80\x99s all we know.</ins>\n'
2023-07-11 12:55:38,553 ERROR   wandb-upload_1:108266 [internal_api.py:upload_file():2192] upload_file exception https://storage.googleapis.com/wandb-production.appspot.com/ada4321/DiffHPE/hh51ey3p/config.yaml?Expires=1689137738&GoogleAccessId=gorilla-files-url-signer-man%40wandb-production.iam.gserviceaccount.com&Signature=OXxyi6xmA4FRhQzEwOaJxOueiFItnFWlT3fAIWugYhUTo7%2Ftk%2FTv%2B1YlVJ%2FJoPe0dBHJOPOE09KIq7rPKjhQEWWOFpydDi30BlUAtceweDz4L4mkM8a32nqJxXwvxXuXlBU02poQjkBeUPXK13QHVO%2Fuor03Z8Ikiw1Q4XxiUZbq5zj92pZUCJ6SorX38cQk6b7aWZWP4uNruKQRUk0yB2ml%2Fbk%2BaoqCvCgzQPKkjZPxHPFLMSTBNctjDTfVclpbVY%2Ft9tYwp9hqwtAj%2BLd%2BPtLP3yRULfekfCu%2FZ5OgwTE1mRMbW7ekPVoIBsfmIJpI77YQJfESk5DVXBU1%2Fpyewg%3D%3D: 404 Client Error: Not Found for url: https://storage.googleapis.com/wandb-production.appspot.com/ada4321/DiffHPE/hh51ey3p/config.yaml?Expires=1689137738&GoogleAccessId=gorilla-files-url-signer-man%40wandb-production.iam.gserviceaccount.com&Signature=OXxyi6xmA4FRhQzEwOaJxOueiFItnFWlT3fAIWugYhUTo7%2Ftk%2FTv%2B1YlVJ%2FJoPe0dBHJOPOE09KIq7rPKjhQEWWOFpydDi30BlUAtceweDz4L4mkM8a32nqJxXwvxXuXlBU02poQjkBeUPXK13QHVO%2Fuor03Z8Ikiw1Q4XxiUZbq5zj92pZUCJ6SorX38cQk6b7aWZWP4uNruKQRUk0yB2ml%2Fbk%2BaoqCvCgzQPKkjZPxHPFLMSTBNctjDTfVclpbVY%2Ft9tYwp9hqwtAj%2BLd%2BPtLP3yRULfekfCu%2FZ5OgwTE1mRMbW7ekPVoIBsfmIJpI77YQJfESk5DVXBU1%2Fpyewg%3D%3D
2023-07-11 12:55:38,553 ERROR   wandb-upload_1:108266 [internal_api.py:upload_file():2194] upload_file request headers: {'User-Agent': 'python-requests/2.31.0', 'Accept-Encoding': 'gzip, deflate', 'Accept': '*/*', 'Connection': 'keep-alive', 'Content-Length': '558'}
2023-07-11 12:55:38,553 ERROR   wandb-upload_1:108266 [internal_api.py:upload_file():2196] upload_file response body: b'<!DOCTYPE html>\n<html lang=en>\n  <meta charset=utf-8>\n  <meta name=viewport content="initial-scale=1, minimum-scale=1, width=device-width">\n  <title>Error 404 (Not Found)!!1</title>\n  <style>\n    *{margin:0;padding:0}html,code{font:15px/22px arial,sans-serif}html{background:#fff;color:#222;padding:15px}body{margin:7% auto 0;max-width:390px;min-height:180px;padding:30px 0 15px}* > body{background:url(//www.google.com/images/errors/robot.png) 100% 5px no-repeat;padding-right:205px}p{margin:11px 0 22px;overflow:hidden}ins{color:#777;text-decoration:none}a img{border:0}@media screen and (max-width:772px){body{background:none;margin-top:0;max-width:none;padding-right:0}}#logo{background:url(//www.google.com/images/branding/googlelogo/1x/googlelogo_color_150x54dp.png) no-repeat;margin-left:-5px}@media only screen and (min-resolution:192dpi){#logo{background:url(//www.google.com/images/branding/googlelogo/2x/googlelogo_color_150x54dp.png) no-repeat 0% 0%/100% 100%;-moz-border-image:url(//www.google.com/images/branding/googlelogo/2x/googlelogo_color_150x54dp.png) 0}}@media only screen and (-webkit-min-device-pixel-ratio:2){#logo{background:url(//www.google.com/images/branding/googlelogo/2x/googlelogo_color_150x54dp.png) no-repeat;-webkit-background-size:100% 100%}}#logo{display:inline-block;height:54px;width:150px}\n  </style>\n  <a href=//www.google.com/><span id=logo aria-label=Google></span></a>\n  <p><b>404.</b> <ins>That\xe2\x80\x99s an error.</ins>\n  <p>The requested URL <code>/wandb-production.appspot.com/ada4321/DiffHPE/hh51ey3p/config.yaml</code> was not found on this server.  <ins>That\xe2\x80\x99s all we know.</ins>\n'
2023-07-11 12:55:38,906 ERROR   wandb-upload_3:108266 [internal_api.py:upload_file():2192] upload_file exception https://storage.googleapis.com/wandb-production.appspot.com/ada4321/DiffHPE/hh51ey3p/conda-environment.yaml?Expires=1689137738&GoogleAccessId=gorilla-files-url-signer-man%40wandb-production.iam.gserviceaccount.com&Signature=P4OTcTuNpNhwsJ1UUKG78w%2B9KdDoSgP9SGveaqmiwfLTXF%2FzvZTBnqb1PP2QnTCDcMIyU8%2FawlU3PDuwF%2B9RH2vXMB1w483cKqa%2BGkFFfTMRIA1HTZa%2BOY2pCYMMfJCuKCN4NsrvaqyLWGhejoZIP6w8b9puLU5DkbwVchB%2BcZEABqNBBeVchAKrUy9p2J1Ia99crR1b1CZPtH8%2BVPLUHJzoIPIFGmJKyRGpa6MXAtuCpHW7w6BsVj%2Bfj55CfBWgkST2rP1n7RvNqFY6LZcnWK4ek4pcN9QcdC2YSUvE6MVgKhM9UATjyohR%2BDfskXTZNj29GLKBB9u2L9QJ9HKUJQ%3D%3D: 404 Client Error: Not Found for url: https://storage.googleapis.com/wandb-production.appspot.com/ada4321/DiffHPE/hh51ey3p/conda-environment.yaml?Expires=1689137738&GoogleAccessId=gorilla-files-url-signer-man%40wandb-production.iam.gserviceaccount.com&Signature=P4OTcTuNpNhwsJ1UUKG78w%2B9KdDoSgP9SGveaqmiwfLTXF%2FzvZTBnqb1PP2QnTCDcMIyU8%2FawlU3PDuwF%2B9RH2vXMB1w483cKqa%2BGkFFfTMRIA1HTZa%2BOY2pCYMMfJCuKCN4NsrvaqyLWGhejoZIP6w8b9puLU5DkbwVchB%2BcZEABqNBBeVchAKrUy9p2J1Ia99crR1b1CZPtH8%2BVPLUHJzoIPIFGmJKyRGpa6MXAtuCpHW7w6BsVj%2Bfj55CfBWgkST2rP1n7RvNqFY6LZcnWK4ek4pcN9QcdC2YSUvE6MVgKhM9UATjyohR%2BDfskXTZNj29GLKBB9u2L9QJ9HKUJQ%3D%3D
2023-07-11 12:55:38,906 ERROR   wandb-upload_3:108266 [internal_api.py:upload_file():2194] upload_file request headers: {'User-Agent': 'python-requests/2.31.0', 'Accept-Encoding': 'gzip, deflate', 'Accept': '*/*', 'Connection': 'keep-alive', 'Content-Length': '1925'}
2023-07-11 12:55:38,906 ERROR   wandb-upload_3:108266 [internal_api.py:upload_file():2196] upload_file response body: b'<!DOCTYPE html>\n<html lang=en>\n  <meta charset=utf-8>\n  <meta name=viewport content="initial-scale=1, minimum-scale=1, width=device-width">\n  <title>Error 404 (Not Found)!!1</title>\n  <style>\n    *{margin:0;padding:0}html,code{font:15px/22px arial,sans-serif}html{background:#fff;color:#222;padding:15px}body{margin:7% auto 0;max-width:390px;min-height:180px;padding:30px 0 15px}* > body{background:url(//www.google.com/images/errors/robot.png) 100% 5px no-repeat;padding-right:205px}p{margin:11px 0 22px;overflow:hidden}ins{color:#777;text-decoration:none}a img{border:0}@media screen and (max-width:772px){body{background:none;margin-top:0;max-width:none;padding-right:0}}#logo{background:url(//www.google.com/images/branding/googlelogo/1x/googlelogo_color_150x54dp.png) no-repeat;margin-left:-5px}@media only screen and (min-resolution:192dpi){#logo{background:url(//www.google.com/images/branding/googlelogo/2x/googlelogo_color_150x54dp.png) no-repeat 0% 0%/100% 100%;-moz-border-image:url(//www.google.com/images/branding/googlelogo/2x/googlelogo_color_150x54dp.png) 0}}@media only screen and (-webkit-min-device-pixel-ratio:2){#logo{background:url(//www.google.com/images/branding/googlelogo/2x/googlelogo_color_150x54dp.png) no-repeat;-webkit-background-size:100% 100%}}#logo{display:inline-block;height:54px;width:150px}\n  </style>\n  <a href=//www.google.com/><span id=logo aria-label=Google></span></a>\n  <p><b>404.</b> <ins>That\xe2\x80\x99s an error.</ins>\n  <p>The requested URL <code>/wandb-production.appspot.com/ada4321/DiffHPE/hh51ey3p/conda-environment.yaml</code> was not found on this server.  <ins>That\xe2\x80\x99s all we know.</ins>\n'
2023-07-11 12:55:38,909 ERROR   wandb-upload_2:108266 [internal_api.py:upload_file():2192] upload_file exception https://storage.googleapis.com/wandb-production.appspot.com/ada4321/DiffHPE/hh51ey3p/wandb-summary.json?Expires=1689137738&GoogleAccessId=gorilla-files-url-signer-man%40wandb-production.iam.gserviceaccount.com&Signature=rrPUll%2FT8rCO6rxC35KTnwZohmx3K3OKl0nyMir12za4LNAMQ1cgXN8vCHKTqoVtVakPGaZl%2B9gahDsnubXCtanvkWoy5wXnH2RR5XC47JZDG19qvOqojsSWyDrDTUs2rx9DTRmsUpgjSgLaMMHZYK%2BoHjPFN%2BJBsM1%2BEGJOwHpa%2Fdoudp88s3I8q23QZP9OSreG52ZRlAFu44e4BunFaeNcV0EcQiXBxngrYRK6CwID2JWIfxV7OeEenRaWfE9XN8yNtQvyhUH35KA4OMI%2BPWuaWPejfSq617tZj%2BuLJQcBcxLTTlf6o8Q8IlLNtMvzsPmbogTm%2BCj0N6KFokj%2F7A%3D%3D: 404 Client Error: Not Found for url: https://storage.googleapis.com/wandb-production.appspot.com/ada4321/DiffHPE/hh51ey3p/wandb-summary.json?Expires=1689137738&GoogleAccessId=gorilla-files-url-signer-man%40wandb-production.iam.gserviceaccount.com&Signature=rrPUll%2FT8rCO6rxC35KTnwZohmx3K3OKl0nyMir12za4LNAMQ1cgXN8vCHKTqoVtVakPGaZl%2B9gahDsnubXCtanvkWoy5wXnH2RR5XC47JZDG19qvOqojsSWyDrDTUs2rx9DTRmsUpgjSgLaMMHZYK%2BoHjPFN%2BJBsM1%2BEGJOwHpa%2Fdoudp88s3I8q23QZP9OSreG52ZRlAFu44e4BunFaeNcV0EcQiXBxngrYRK6CwID2JWIfxV7OeEenRaWfE9XN8yNtQvyhUH35KA4OMI%2BPWuaWPejfSq617tZj%2BuLJQcBcxLTTlf6o8Q8IlLNtMvzsPmbogTm%2BCj0N6KFokj%2F7A%3D%3D
2023-07-11 12:55:38,910 ERROR   wandb-upload_2:108266 [internal_api.py:upload_file():2194] upload_file request headers: {'User-Agent': 'python-requests/2.31.0', 'Accept-Encoding': 'gzip, deflate', 'Accept': '*/*', 'Connection': 'keep-alive', 'Content-Length': '27'}
2023-07-11 12:55:38,910 ERROR   wandb-upload_2:108266 [internal_api.py:upload_file():2196] upload_file response body: b'<!DOCTYPE html>\n<html lang=en>\n  <meta charset=utf-8>\n  <meta name=viewport content="initial-scale=1, minimum-scale=1, width=device-width">\n  <title>Error 404 (Not Found)!!1</title>\n  <style>\n    *{margin:0;padding:0}html,code{font:15px/22px arial,sans-serif}html{background:#fff;color:#222;padding:15px}body{margin:7% auto 0;max-width:390px;min-height:180px;padding:30px 0 15px}* > body{background:url(//www.google.com/images/errors/robot.png) 100% 5px no-repeat;padding-right:205px}p{margin:11px 0 22px;overflow:hidden}ins{color:#777;text-decoration:none}a img{border:0}@media screen and (max-width:772px){body{background:none;margin-top:0;max-width:none;padding-right:0}}#logo{background:url(//www.google.com/images/branding/googlelogo/1x/googlelogo_color_150x54dp.png) no-repeat;margin-left:-5px}@media only screen and (min-resolution:192dpi){#logo{background:url(//www.google.com/images/branding/googlelogo/2x/googlelogo_color_150x54dp.png) no-repeat 0% 0%/100% 100%;-moz-border-image:url(//www.google.com/images/branding/googlelogo/2x/googlelogo_color_150x54dp.png) 0}}@media only screen and (-webkit-min-device-pixel-ratio:2){#logo{background:url(//www.google.com/images/branding/googlelogo/2x/googlelogo_color_150x54dp.png) no-repeat;-webkit-background-size:100% 100%}}#logo{display:inline-block;height:54px;width:150px}\n  </style>\n  <a href=//www.google.com/><span id=logo aria-label=Google></span></a>\n  <p><b>404.</b> <ins>That\xe2\x80\x99s an error.</ins>\n  <p>The requested URL <code>/wandb-production.appspot.com/ada4321/DiffHPE/hh51ey3p/wandb-summary.json</code> was not found on this server.  <ins>That\xe2\x80\x99s all we know.</ins>\n'
2023-07-11 12:55:38,923 ERROR   wandb-upload_4:108266 [internal_api.py:upload_file():2192] upload_file exception https://storage.googleapis.com/wandb-production.appspot.com/ada4321/DiffHPE/hh51ey3p/output.log?Expires=1689137738&GoogleAccessId=gorilla-files-url-signer-man%40wandb-production.iam.gserviceaccount.com&Signature=cebFtNm8c%2F6%2BPIr9DNA%2BQLd%2FW3bZY7CzTQXnIBFX6cMCRr%2Fc71x%2FmvUtUjWnjLel9qZwN5R8byLkyViIcyBlY4qgh3M5%2FliHDzYBZ5%2B43qacwE9Sy9%2Fq%2BWEDWuVhdria0YBcxtzVC4A22OqrA295V8IYETRExe3DlZTfuPp2ITKGo6eEAfMdQ4vNp%2BJixIb7uDZtP9zfHpD7Qh2mPUMpa%2BURXSrip1ypmJb9NT72ksyjTyUqkSj%2FLyv%2BRq8MKFDuZaMphQC336uiVACd0cTfdX3OnR8BFcO7IMVhb1%2BBykCKjT0EKQgBLv1BBdJvWQAKn%2BODwY15hjn1fxK9Dp5DXQ%3D%3D: 404 Client Error: Not Found for url: https://storage.googleapis.com/wandb-production.appspot.com/ada4321/DiffHPE/hh51ey3p/output.log?Expires=1689137738&GoogleAccessId=gorilla-files-url-signer-man%40wandb-production.iam.gserviceaccount.com&Signature=cebFtNm8c%2F6%2BPIr9DNA%2BQLd%2FW3bZY7CzTQXnIBFX6cMCRr%2Fc71x%2FmvUtUjWnjLel9qZwN5R8byLkyViIcyBlY4qgh3M5%2FliHDzYBZ5%2B43qacwE9Sy9%2Fq%2BWEDWuVhdria0YBcxtzVC4A22OqrA295V8IYETRExe3DlZTfuPp2ITKGo6eEAfMdQ4vNp%2BJixIb7uDZtP9zfHpD7Qh2mPUMpa%2BURXSrip1ypmJb9NT72ksyjTyUqkSj%2FLyv%2BRq8MKFDuZaMphQC336uiVACd0cTfdX3OnR8BFcO7IMVhb1%2BBykCKjT0EKQgBLv1BBdJvWQAKn%2BODwY15hjn1fxK9Dp5DXQ%3D%3D
2023-07-11 12:55:38,923 ERROR   wandb-upload_4:108266 [internal_api.py:upload_file():2194] upload_file request headers: {'User-Agent': 'python-requests/2.31.0', 'Accept-Encoding': 'gzip, deflate', 'Accept': '*/*', 'Connection': 'keep-alive', 'Content-Length': '5271'}
2023-07-11 12:55:38,923 ERROR   wandb-upload_4:108266 [internal_api.py:upload_file():2196] upload_file response body: b'<!DOCTYPE html>\n<html lang=en>\n  <meta charset=utf-8>\n  <meta name=viewport content="initial-scale=1, minimum-scale=1, width=device-width">\n  <title>Error 404 (Not Found)!!1</title>\n  <style>\n    *{margin:0;padding:0}html,code{font:15px/22px arial,sans-serif}html{background:#fff;color:#222;padding:15px}body{margin:7% auto 0;max-width:390px;min-height:180px;padding:30px 0 15px}* > body{background:url(//www.google.com/images/errors/robot.png) 100% 5px no-repeat;padding-right:205px}p{margin:11px 0 22px;overflow:hidden}ins{color:#777;text-decoration:none}a img{border:0}@media screen and (max-width:772px){body{background:none;margin-top:0;max-width:none;padding-right:0}}#logo{background:url(//www.google.com/images/branding/googlelogo/1x/googlelogo_color_150x54dp.png) no-repeat;margin-left:-5px}@media only screen and (min-resolution:192dpi){#logo{background:url(//www.google.com/images/branding/googlelogo/2x/googlelogo_color_150x54dp.png) no-repeat 0% 0%/100% 100%;-moz-border-image:url(//www.google.com/images/branding/googlelogo/2x/googlelogo_color_150x54dp.png) 0}}@media only screen and (-webkit-min-device-pixel-ratio:2){#logo{background:url(//www.google.com/images/branding/googlelogo/2x/googlelogo_color_150x54dp.png) no-repeat;-webkit-background-size:100% 100%}}#logo{display:inline-block;height:54px;width:150px}\n  </style>\n  <a href=//www.google.com/><span id=logo aria-label=Google></span></a>\n  <p><b>404.</b> <ins>That\xe2\x80\x99s an error.</ins>\n  <p>The requested URL <code>/wandb-production.appspot.com/ada4321/DiffHPE/hh51ey3p/output.log</code> was not found on this server.  <ins>That\xe2\x80\x99s all we know.</ins>\n'
2023-07-11 12:55:39,586 ERROR   wandb-upload_0:108266 [upload_job.py:push():136] Failed to upload file: /home/zhuhe/HPE-with-Diffusion/wandb/run-20230711_125521-hh51ey3p/files/requirements.txt
Traceback (most recent call last):
  File "/home/zhuhe/.conda/envs/diffhpe/lib/python3.9/site-packages/wandb/apis/normalize.py", line 41, in wrapper
    return func(*args, **kwargs)
  File "/home/zhuhe/.conda/envs/diffhpe/lib/python3.9/site-packages/wandb/sdk/lib/retry.py", line 212, in wrapped_fn
    return retrier(*args, **kargs)
  File "/home/zhuhe/.conda/envs/diffhpe/lib/python3.9/site-packages/wandb/sdk/lib/retry.py", line 131, in __call__
    result = self._call_fn(*args, **kwargs)
  File "/home/zhuhe/.conda/envs/diffhpe/lib/python3.9/site-packages/wandb/sdk/internal/internal_api.py", line 2218, in upload_file
    wandb._sentry.reraise(e)
  File "/home/zhuhe/.conda/envs/diffhpe/lib/python3.9/site-packages/wandb/analytics/sentry.py", line 146, in reraise
    raise exc.with_traceback(sys.exc_info()[2])
  File "/home/zhuhe/.conda/envs/diffhpe/lib/python3.9/site-packages/wandb/sdk/internal/internal_api.py", line 2190, in upload_file
    response.raise_for_status()
  File "/home/zhuhe/.conda/envs/diffhpe/lib/python3.9/site-packages/requests/models.py", line 1021, in raise_for_status
    raise HTTPError(http_error_msg, response=self)
requests.exceptions.HTTPError: 404 Client Error: Not Found for url: https://storage.googleapis.com/wandb-production.appspot.com/ada4321/DiffHPE/hh51ey3p/requirements.txt?Expires=1689137738&GoogleAccessId=gorilla-files-url-signer-man%40wandb-production.iam.gserviceaccount.com&Signature=dKBK2ibEYUtz3ZWsmvy7pXLD8JK%2FM%2F6TCnoFNZLYzvBM8MozWZ1vBwVdb1S7bDmFhD47fna5W7CffgctOe1VVD%2F6%2Bwp1qZPAG1hbM%2BBWLr7xZUzzBaxJ%2FduEnSxiI%2BQegX%2BQP06DUT5O4YRlFo33Rlj8TKHiHmjG6Uh2c2951d%2Bb0KS2fWAVMvBKofMTIHZjk5%2Bjs8%2BQCz9c0V%2FvHkolaSNNpdgpFQxLJDc1AIpWN4Pm2wKx6%2FRg3WW44z5fZgoy6NWqd3w6tgI8%2FhvyUSOKT%2F%2BcK%2BLVlumbN5HuTH5ONUHZd73RPT3Sf4lNvA7yQHZ0ieF1gji63MXdJ%2Fy4fEXyUg%3D%3D

During handling of the above exception, another exception occurred:

Traceback (most recent call last):
  File "/home/zhuhe/.conda/envs/diffhpe/lib/python3.9/site-packages/wandb/filesync/upload_job.py", line 127, in push
    self._api.upload_file_retry(
  File "/home/zhuhe/.conda/envs/diffhpe/lib/python3.9/site-packages/wandb/apis/normalize.py", line 51, in wrapper
    raise CommError(message, error)
wandb.errors.CommError: <Response [404]>
2023-07-11 12:55:39,587 ERROR   wandb-upload_1:108266 [upload_job.py:push():136] Failed to upload file: /home/zhuhe/HPE-with-Diffusion/wandb/run-20230711_125521-hh51ey3p/files/config.yaml
Traceback (most recent call last):
  File "/home/zhuhe/.conda/envs/diffhpe/lib/python3.9/site-packages/wandb/apis/normalize.py", line 41, in wrapper
    return func(*args, **kwargs)
  File "/home/zhuhe/.conda/envs/diffhpe/lib/python3.9/site-packages/wandb/sdk/lib/retry.py", line 212, in wrapped_fn
    return retrier(*args, **kargs)
  File "/home/zhuhe/.conda/envs/diffhpe/lib/python3.9/site-packages/wandb/sdk/lib/retry.py", line 131, in __call__
    result = self._call_fn(*args, **kwargs)
  File "/home/zhuhe/.conda/envs/diffhpe/lib/python3.9/site-packages/wandb/sdk/internal/internal_api.py", line 2218, in upload_file
    wandb._sentry.reraise(e)
  File "/home/zhuhe/.conda/envs/diffhpe/lib/python3.9/site-packages/wandb/analytics/sentry.py", line 146, in reraise
    raise exc.with_traceback(sys.exc_info()[2])
  File "/home/zhuhe/.conda/envs/diffhpe/lib/python3.9/site-packages/wandb/sdk/internal/internal_api.py", line 2190, in upload_file
    response.raise_for_status()
  File "/home/zhuhe/.conda/envs/diffhpe/lib/python3.9/site-packages/requests/models.py", line 1021, in raise_for_status
    raise HTTPError(http_error_msg, response=self)
requests.exceptions.HTTPError: 404 Client Error: Not Found for url: https://storage.googleapis.com/wandb-production.appspot.com/ada4321/DiffHPE/hh51ey3p/config.yaml?Expires=1689137738&GoogleAccessId=gorilla-files-url-signer-man%40wandb-production.iam.gserviceaccount.com&Signature=OXxyi6xmA4FRhQzEwOaJxOueiFItnFWlT3fAIWugYhUTo7%2Ftk%2FTv%2B1YlVJ%2FJoPe0dBHJOPOE09KIq7rPKjhQEWWOFpydDi30BlUAtceweDz4L4mkM8a32nqJxXwvxXuXlBU02poQjkBeUPXK13QHVO%2Fuor03Z8Ikiw1Q4XxiUZbq5zj92pZUCJ6SorX38cQk6b7aWZWP4uNruKQRUk0yB2ml%2Fbk%2BaoqCvCgzQPKkjZPxHPFLMSTBNctjDTfVclpbVY%2Ft9tYwp9hqwtAj%2BLd%2BPtLP3yRULfekfCu%2FZ5OgwTE1mRMbW7ekPVoIBsfmIJpI77YQJfESk5DVXBU1%2Fpyewg%3D%3D

During handling of the above exception, another exception occurred:

Traceback (most recent call last):
  File "/home/zhuhe/.conda/envs/diffhpe/lib/python3.9/site-packages/wandb/filesync/upload_job.py", line 127, in push
    self._api.upload_file_retry(
  File "/home/zhuhe/.conda/envs/diffhpe/lib/python3.9/site-packages/wandb/apis/normalize.py", line 51, in wrapper
    raise CommError(message, error)
wandb.errors.CommError: <Response [404]>
2023-07-11 12:55:39,587 ERROR   wandb-upload_2:108266 [upload_job.py:push():136] Failed to upload file: /home/zhuhe/HPE-with-Diffusion/wandb/run-20230711_125521-hh51ey3p/files/wandb-summary.json
Traceback (most recent call last):
  File "/home/zhuhe/.conda/envs/diffhpe/lib/python3.9/site-packages/wandb/apis/normalize.py", line 41, in wrapper
    return func(*args, **kwargs)
  File "/home/zhuhe/.conda/envs/diffhpe/lib/python3.9/site-packages/wandb/sdk/lib/retry.py", line 212, in wrapped_fn
    return retrier(*args, **kargs)
  File "/home/zhuhe/.conda/envs/diffhpe/lib/python3.9/site-packages/wandb/sdk/lib/retry.py", line 131, in __call__
    result = self._call_fn(*args, **kwargs)
  File "/home/zhuhe/.conda/envs/diffhpe/lib/python3.9/site-packages/wandb/sdk/internal/internal_api.py", line 2218, in upload_file
    wandb._sentry.reraise(e)
  File "/home/zhuhe/.conda/envs/diffhpe/lib/python3.9/site-packages/wandb/analytics/sentry.py", line 146, in reraise
    raise exc.with_traceback(sys.exc_info()[2])
  File "/home/zhuhe/.conda/envs/diffhpe/lib/python3.9/site-packages/wandb/sdk/internal/internal_api.py", line 2190, in upload_file
    response.raise_for_status()
  File "/home/zhuhe/.conda/envs/diffhpe/lib/python3.9/site-packages/requests/models.py", line 1021, in raise_for_status
    raise HTTPError(http_error_msg, response=self)
requests.exceptions.HTTPError: 404 Client Error: Not Found for url: https://storage.googleapis.com/wandb-production.appspot.com/ada4321/DiffHPE/hh51ey3p/wandb-summary.json?Expires=1689137738&GoogleAccessId=gorilla-files-url-signer-man%40wandb-production.iam.gserviceaccount.com&Signature=rrPUll%2FT8rCO6rxC35KTnwZohmx3K3OKl0nyMir12za4LNAMQ1cgXN8vCHKTqoVtVakPGaZl%2B9gahDsnubXCtanvkWoy5wXnH2RR5XC47JZDG19qvOqojsSWyDrDTUs2rx9DTRmsUpgjSgLaMMHZYK%2BoHjPFN%2BJBsM1%2BEGJOwHpa%2Fdoudp88s3I8q23QZP9OSreG52ZRlAFu44e4BunFaeNcV0EcQiXBxngrYRK6CwID2JWIfxV7OeEenRaWfE9XN8yNtQvyhUH35KA4OMI%2BPWuaWPejfSq617tZj%2BuLJQcBcxLTTlf6o8Q8IlLNtMvzsPmbogTm%2BCj0N6KFokj%2F7A%3D%3D

During handling of the above exception, another exception occurred:

Traceback (most recent call last):
  File "/home/zhuhe/.conda/envs/diffhpe/lib/python3.9/site-packages/wandb/filesync/upload_job.py", line 127, in push
    self._api.upload_file_retry(
  File "/home/zhuhe/.conda/envs/diffhpe/lib/python3.9/site-packages/wandb/apis/normalize.py", line 51, in wrapper
    raise CommError(message, error)
wandb.errors.CommError: <Response [404]>
2023-07-11 12:55:39,588 ERROR   wandb-upload_3:108266 [upload_job.py:push():136] Failed to upload file: /home/zhuhe/HPE-with-Diffusion/wandb/run-20230711_125521-hh51ey3p/files/conda-environment.yaml
Traceback (most recent call last):
  File "/home/zhuhe/.conda/envs/diffhpe/lib/python3.9/site-packages/wandb/apis/normalize.py", line 41, in wrapper
    return func(*args, **kwargs)
  File "/home/zhuhe/.conda/envs/diffhpe/lib/python3.9/site-packages/wandb/sdk/lib/retry.py", line 212, in wrapped_fn
    return retrier(*args, **kargs)
  File "/home/zhuhe/.conda/envs/diffhpe/lib/python3.9/site-packages/wandb/sdk/lib/retry.py", line 131, in __call__
    result = self._call_fn(*args, **kwargs)
  File "/home/zhuhe/.conda/envs/diffhpe/lib/python3.9/site-packages/wandb/sdk/internal/internal_api.py", line 2218, in upload_file
    wandb._sentry.reraise(e)
  File "/home/zhuhe/.conda/envs/diffhpe/lib/python3.9/site-packages/wandb/analytics/sentry.py", line 146, in reraise
    raise exc.with_traceback(sys.exc_info()[2])
  File "/home/zhuhe/.conda/envs/diffhpe/lib/python3.9/site-packages/wandb/sdk/internal/internal_api.py", line 2190, in upload_file
    response.raise_for_status()
  File "/home/zhuhe/.conda/envs/diffhpe/lib/python3.9/site-packages/requests/models.py", line 1021, in raise_for_status
    raise HTTPError(http_error_msg, response=self)
requests.exceptions.HTTPError: 404 Client Error: Not Found for url: https://storage.googleapis.com/wandb-production.appspot.com/ada4321/DiffHPE/hh51ey3p/conda-environment.yaml?Expires=1689137738&GoogleAccessId=gorilla-files-url-signer-man%40wandb-production.iam.gserviceaccount.com&Signature=P4OTcTuNpNhwsJ1UUKG78w%2B9KdDoSgP9SGveaqmiwfLTXF%2FzvZTBnqb1PP2QnTCDcMIyU8%2FawlU3PDuwF%2B9RH2vXMB1w483cKqa%2BGkFFfTMRIA1HTZa%2BOY2pCYMMfJCuKCN4NsrvaqyLWGhejoZIP6w8b9puLU5DkbwVchB%2BcZEABqNBBeVchAKrUy9p2J1Ia99crR1b1CZPtH8%2BVPLUHJzoIPIFGmJKyRGpa6MXAtuCpHW7w6BsVj%2Bfj55CfBWgkST2rP1n7RvNqFY6LZcnWK4ek4pcN9QcdC2YSUvE6MVgKhM9UATjyohR%2BDfskXTZNj29GLKBB9u2L9QJ9HKUJQ%3D%3D

During handling of the above exception, another exception occurred:

Traceback (most recent call last):
  File "/home/zhuhe/.conda/envs/diffhpe/lib/python3.9/site-packages/wandb/filesync/upload_job.py", line 127, in push
    self._api.upload_file_retry(
  File "/home/zhuhe/.conda/envs/diffhpe/lib/python3.9/site-packages/wandb/apis/normalize.py", line 51, in wrapper
    raise CommError(message, error)
wandb.errors.CommError: <Response [404]>
2023-07-11 12:55:39,588 ERROR   wandb-upload_4:108266 [upload_job.py:push():136] Failed to upload file: /home/zhuhe/HPE-with-Diffusion/wandb/run-20230711_125521-hh51ey3p/files/output.log
Traceback (most recent call last):
  File "/home/zhuhe/.conda/envs/diffhpe/lib/python3.9/site-packages/wandb/apis/normalize.py", line 41, in wrapper
    return func(*args, **kwargs)
  File "/home/zhuhe/.conda/envs/diffhpe/lib/python3.9/site-packages/wandb/sdk/lib/retry.py", line 212, in wrapped_fn
    return retrier(*args, **kargs)
  File "/home/zhuhe/.conda/envs/diffhpe/lib/python3.9/site-packages/wandb/sdk/lib/retry.py", line 131, in __call__
    result = self._call_fn(*args, **kwargs)
  File "/home/zhuhe/.conda/envs/diffhpe/lib/python3.9/site-packages/wandb/sdk/internal/internal_api.py", line 2218, in upload_file
    wandb._sentry.reraise(e)
  File "/home/zhuhe/.conda/envs/diffhpe/lib/python3.9/site-packages/wandb/analytics/sentry.py", line 146, in reraise
    raise exc.with_traceback(sys.exc_info()[2])
  File "/home/zhuhe/.conda/envs/diffhpe/lib/python3.9/site-packages/wandb/sdk/internal/internal_api.py", line 2190, in upload_file
    response.raise_for_status()
  File "/home/zhuhe/.conda/envs/diffhpe/lib/python3.9/site-packages/requests/models.py", line 1021, in raise_for_status
    raise HTTPError(http_error_msg, response=self)
requests.exceptions.HTTPError: 404 Client Error: Not Found for url: https://storage.googleapis.com/wandb-production.appspot.com/ada4321/DiffHPE/hh51ey3p/output.log?Expires=1689137738&GoogleAccessId=gorilla-files-url-signer-man%40wandb-production.iam.gserviceaccount.com&Signature=cebFtNm8c%2F6%2BPIr9DNA%2BQLd%2FW3bZY7CzTQXnIBFX6cMCRr%2Fc71x%2FmvUtUjWnjLel9qZwN5R8byLkyViIcyBlY4qgh3M5%2FliHDzYBZ5%2B43qacwE9Sy9%2Fq%2BWEDWuVhdria0YBcxtzVC4A22OqrA295V8IYETRExe3DlZTfuPp2ITKGo6eEAfMdQ4vNp%2BJixIb7uDZtP9zfHpD7Qh2mPUMpa%2BURXSrip1ypmJb9NT72ksyjTyUqkSj%2FLyv%2BRq8MKFDuZaMphQC336uiVACd0cTfdX3OnR8BFcO7IMVhb1%2BBykCKjT0EKQgBLv1BBdJvWQAKn%2BODwY15hjn1fxK9Dp5DXQ%3D%3D

During handling of the above exception, another exception occurred:

Traceback (most recent call last):
  File "/home/zhuhe/.conda/envs/diffhpe/lib/python3.9/site-packages/wandb/filesync/upload_job.py", line 127, in push
    self._api.upload_file_retry(
  File "/home/zhuhe/.conda/envs/diffhpe/lib/python3.9/site-packages/wandb/apis/normalize.py", line 51, in wrapper
    raise CommError(message, error)
wandb.errors.CommError: <Response [404]>
2023-07-11 12:55:40,318 DEBUG   HandlerThread:108266 [handler.py:handle_request():144] handle_request: keepalive
2023-07-11 12:55:40,637 ERROR   Thread-11 :108266 [step_upload.py:_handle_event():200] Failed to upload file: /home/zhuhe/HPE-with-Diffusion/wandb/run-20230711_125521-hh51ey3p/files/requirements.txt
Traceback (most recent call last):
  File "/home/zhuhe/.conda/envs/diffhpe/lib/python3.9/site-packages/wandb/apis/normalize.py", line 41, in wrapper
    return func(*args, **kwargs)
  File "/home/zhuhe/.conda/envs/diffhpe/lib/python3.9/site-packages/wandb/sdk/lib/retry.py", line 212, in wrapped_fn
    return retrier(*args, **kargs)
  File "/home/zhuhe/.conda/envs/diffhpe/lib/python3.9/site-packages/wandb/sdk/lib/retry.py", line 131, in __call__
    result = self._call_fn(*args, **kwargs)
  File "/home/zhuhe/.conda/envs/diffhpe/lib/python3.9/site-packages/wandb/sdk/internal/internal_api.py", line 2218, in upload_file
    wandb._sentry.reraise(e)
  File "/home/zhuhe/.conda/envs/diffhpe/lib/python3.9/site-packages/wandb/analytics/sentry.py", line 146, in reraise
    raise exc.with_traceback(sys.exc_info()[2])
  File "/home/zhuhe/.conda/envs/diffhpe/lib/python3.9/site-packages/wandb/sdk/internal/internal_api.py", line 2190, in upload_file
    response.raise_for_status()
  File "/home/zhuhe/.conda/envs/diffhpe/lib/python3.9/site-packages/requests/models.py", line 1021, in raise_for_status
    raise HTTPError(http_error_msg, response=self)
requests.exceptions.HTTPError: 404 Client Error: Not Found for url: https://storage.googleapis.com/wandb-production.appspot.com/ada4321/DiffHPE/hh51ey3p/requirements.txt?Expires=1689137738&GoogleAccessId=gorilla-files-url-signer-man%40wandb-production.iam.gserviceaccount.com&Signature=dKBK2ibEYUtz3ZWsmvy7pXLD8JK%2FM%2F6TCnoFNZLYzvBM8MozWZ1vBwVdb1S7bDmFhD47fna5W7CffgctOe1VVD%2F6%2Bwp1qZPAG1hbM%2BBWLr7xZUzzBaxJ%2FduEnSxiI%2BQegX%2BQP06DUT5O4YRlFo33Rlj8TKHiHmjG6Uh2c2951d%2Bb0KS2fWAVMvBKofMTIHZjk5%2Bjs8%2BQCz9c0V%2FvHkolaSNNpdgpFQxLJDc1AIpWN4Pm2wKx6%2FRg3WW44z5fZgoy6NWqd3w6tgI8%2FhvyUSOKT%2F%2BcK%2BLVlumbN5HuTH5ONUHZd73RPT3Sf4lNvA7yQHZ0ieF1gji63MXdJ%2Fy4fEXyUg%3D%3D

During handling of the above exception, another exception occurred:

Traceback (most recent call last):
  File "/home/zhuhe/.conda/envs/diffhpe/lib/python3.9/concurrent/futures/thread.py", line 58, in run
    result = self.fn(*self.args, **self.kwargs)
  File "/home/zhuhe/.conda/envs/diffhpe/lib/python3.9/site-packages/wandb/filesync/step_upload.py", line 288, in run_and_notify
    self._do_upload_sync(event)
  File "/home/zhuhe/.conda/envs/diffhpe/lib/python3.9/site-packages/wandb/filesync/step_upload.py", line 330, in _do_upload_sync
    job.run()
  File "/home/zhuhe/.conda/envs/diffhpe/lib/python3.9/site-packages/wandb/filesync/upload_job.py", line 57, in run
    self.push()
  File "/home/zhuhe/.conda/envs/diffhpe/lib/python3.9/site-packages/wandb/filesync/upload_job.py", line 127, in push
    self._api.upload_file_retry(
  File "/home/zhuhe/.conda/envs/diffhpe/lib/python3.9/site-packages/wandb/apis/normalize.py", line 51, in wrapper
    raise CommError(message, error)
wandb.errors.CommError: <Response [404]>
2023-07-11 12:55:40,639 ERROR   Thread-11 :108266 [step_upload.py:_handle_event():200] Failed to upload file: /home/zhuhe/HPE-with-Diffusion/wandb/run-20230711_125521-hh51ey3p/files/config.yaml
Traceback (most recent call last):
  File "/home/zhuhe/.conda/envs/diffhpe/lib/python3.9/site-packages/wandb/apis/normalize.py", line 41, in wrapper
    return func(*args, **kwargs)
  File "/home/zhuhe/.conda/envs/diffhpe/lib/python3.9/site-packages/wandb/sdk/lib/retry.py", line 212, in wrapped_fn
    return retrier(*args, **kargs)
  File "/home/zhuhe/.conda/envs/diffhpe/lib/python3.9/site-packages/wandb/sdk/lib/retry.py", line 131, in __call__
    result = self._call_fn(*args, **kwargs)
  File "/home/zhuhe/.conda/envs/diffhpe/lib/python3.9/site-packages/wandb/sdk/internal/internal_api.py", line 2218, in upload_file
    wandb._sentry.reraise(e)
  File "/home/zhuhe/.conda/envs/diffhpe/lib/python3.9/site-packages/wandb/analytics/sentry.py", line 146, in reraise
    raise exc.with_traceback(sys.exc_info()[2])
  File "/home/zhuhe/.conda/envs/diffhpe/lib/python3.9/site-packages/wandb/sdk/internal/internal_api.py", line 2190, in upload_file
    response.raise_for_status()
  File "/home/zhuhe/.conda/envs/diffhpe/lib/python3.9/site-packages/requests/models.py", line 1021, in raise_for_status
    raise HTTPError(http_error_msg, response=self)
requests.exceptions.HTTPError: 404 Client Error: Not Found for url: https://storage.googleapis.com/wandb-production.appspot.com/ada4321/DiffHPE/hh51ey3p/config.yaml?Expires=1689137738&GoogleAccessId=gorilla-files-url-signer-man%40wandb-production.iam.gserviceaccount.com&Signature=OXxyi6xmA4FRhQzEwOaJxOueiFItnFWlT3fAIWugYhUTo7%2Ftk%2FTv%2B1YlVJ%2FJoPe0dBHJOPOE09KIq7rPKjhQEWWOFpydDi30BlUAtceweDz4L4mkM8a32nqJxXwvxXuXlBU02poQjkBeUPXK13QHVO%2Fuor03Z8Ikiw1Q4XxiUZbq5zj92pZUCJ6SorX38cQk6b7aWZWP4uNruKQRUk0yB2ml%2Fbk%2BaoqCvCgzQPKkjZPxHPFLMSTBNctjDTfVclpbVY%2Ft9tYwp9hqwtAj%2BLd%2BPtLP3yRULfekfCu%2FZ5OgwTE1mRMbW7ekPVoIBsfmIJpI77YQJfESk5DVXBU1%2Fpyewg%3D%3D

During handling of the above exception, another exception occurred:

Traceback (most recent call last):
  File "/home/zhuhe/.conda/envs/diffhpe/lib/python3.9/concurrent/futures/thread.py", line 58, in run
    result = self.fn(*self.args, **self.kwargs)
  File "/home/zhuhe/.conda/envs/diffhpe/lib/python3.9/site-packages/wandb/filesync/step_upload.py", line 288, in run_and_notify
    self._do_upload_sync(event)
  File "/home/zhuhe/.conda/envs/diffhpe/lib/python3.9/site-packages/wandb/filesync/step_upload.py", line 330, in _do_upload_sync
    job.run()
  File "/home/zhuhe/.conda/envs/diffhpe/lib/python3.9/site-packages/wandb/filesync/upload_job.py", line 57, in run
    self.push()
  File "/home/zhuhe/.conda/envs/diffhpe/lib/python3.9/site-packages/wandb/filesync/upload_job.py", line 127, in push
    self._api.upload_file_retry(
  File "/home/zhuhe/.conda/envs/diffhpe/lib/python3.9/site-packages/wandb/apis/normalize.py", line 51, in wrapper
    raise CommError(message, error)
wandb.errors.CommError: <Response [404]>
2023-07-11 12:55:40,641 ERROR   Thread-11 :108266 [step_upload.py:_handle_event():200] Failed to upload file: /home/zhuhe/HPE-with-Diffusion/wandb/run-20230711_125521-hh51ey3p/files/wandb-summary.json
Traceback (most recent call last):
  File "/home/zhuhe/.conda/envs/diffhpe/lib/python3.9/site-packages/wandb/apis/normalize.py", line 41, in wrapper
    return func(*args, **kwargs)
  File "/home/zhuhe/.conda/envs/diffhpe/lib/python3.9/site-packages/wandb/sdk/lib/retry.py", line 212, in wrapped_fn
    return retrier(*args, **kargs)
  File "/home/zhuhe/.conda/envs/diffhpe/lib/python3.9/site-packages/wandb/sdk/lib/retry.py", line 131, in __call__
    result = self._call_fn(*args, **kwargs)
  File "/home/zhuhe/.conda/envs/diffhpe/lib/python3.9/site-packages/wandb/sdk/internal/internal_api.py", line 2218, in upload_file
    wandb._sentry.reraise(e)
  File "/home/zhuhe/.conda/envs/diffhpe/lib/python3.9/site-packages/wandb/analytics/sentry.py", line 146, in reraise
    raise exc.with_traceback(sys.exc_info()[2])
  File "/home/zhuhe/.conda/envs/diffhpe/lib/python3.9/site-packages/wandb/sdk/internal/internal_api.py", line 2190, in upload_file
    response.raise_for_status()
  File "/home/zhuhe/.conda/envs/diffhpe/lib/python3.9/site-packages/requests/models.py", line 1021, in raise_for_status
    raise HTTPError(http_error_msg, response=self)
requests.exceptions.HTTPError: 404 Client Error: Not Found for url: https://storage.googleapis.com/wandb-production.appspot.com/ada4321/DiffHPE/hh51ey3p/wandb-summary.json?Expires=1689137738&GoogleAccessId=gorilla-files-url-signer-man%40wandb-production.iam.gserviceaccount.com&Signature=rrPUll%2FT8rCO6rxC35KTnwZohmx3K3OKl0nyMir12za4LNAMQ1cgXN8vCHKTqoVtVakPGaZl%2B9gahDsnubXCtanvkWoy5wXnH2RR5XC47JZDG19qvOqojsSWyDrDTUs2rx9DTRmsUpgjSgLaMMHZYK%2BoHjPFN%2BJBsM1%2BEGJOwHpa%2Fdoudp88s3I8q23QZP9OSreG52ZRlAFu44e4BunFaeNcV0EcQiXBxngrYRK6CwID2JWIfxV7OeEenRaWfE9XN8yNtQvyhUH35KA4OMI%2BPWuaWPejfSq617tZj%2BuLJQcBcxLTTlf6o8Q8IlLNtMvzsPmbogTm%2BCj0N6KFokj%2F7A%3D%3D

During handling of the above exception, another exception occurred:

Traceback (most recent call last):
  File "/home/zhuhe/.conda/envs/diffhpe/lib/python3.9/concurrent/futures/thread.py", line 58, in run
    result = self.fn(*self.args, **self.kwargs)
  File "/home/zhuhe/.conda/envs/diffhpe/lib/python3.9/site-packages/wandb/filesync/step_upload.py", line 288, in run_and_notify
    self._do_upload_sync(event)
  File "/home/zhuhe/.conda/envs/diffhpe/lib/python3.9/site-packages/wandb/filesync/step_upload.py", line 330, in _do_upload_sync
    job.run()
  File "/home/zhuhe/.conda/envs/diffhpe/lib/python3.9/site-packages/wandb/filesync/upload_job.py", line 57, in run
    self.push()
  File "/home/zhuhe/.conda/envs/diffhpe/lib/python3.9/site-packages/wandb/filesync/upload_job.py", line 127, in push
    self._api.upload_file_retry(
  File "/home/zhuhe/.conda/envs/diffhpe/lib/python3.9/site-packages/wandb/apis/normalize.py", line 51, in wrapper
    raise CommError(message, error)
wandb.errors.CommError: <Response [404]>
2023-07-11 12:55:40,641 ERROR   Thread-11 :108266 [step_upload.py:_handle_event():200] Failed to upload file: /home/zhuhe/HPE-with-Diffusion/wandb/run-20230711_125521-hh51ey3p/files/output.log
Traceback (most recent call last):
  File "/home/zhuhe/.conda/envs/diffhpe/lib/python3.9/site-packages/wandb/apis/normalize.py", line 41, in wrapper
    return func(*args, **kwargs)
  File "/home/zhuhe/.conda/envs/diffhpe/lib/python3.9/site-packages/wandb/sdk/lib/retry.py", line 212, in wrapped_fn
    return retrier(*args, **kargs)
  File "/home/zhuhe/.conda/envs/diffhpe/lib/python3.9/site-packages/wandb/sdk/lib/retry.py", line 131, in __call__
    result = self._call_fn(*args, **kwargs)
  File "/home/zhuhe/.conda/envs/diffhpe/lib/python3.9/site-packages/wandb/sdk/internal/internal_api.py", line 2218, in upload_file
    wandb._sentry.reraise(e)
  File "/home/zhuhe/.conda/envs/diffhpe/lib/python3.9/site-packages/wandb/analytics/sentry.py", line 146, in reraise
    raise exc.with_traceback(sys.exc_info()[2])
  File "/home/zhuhe/.conda/envs/diffhpe/lib/python3.9/site-packages/wandb/sdk/internal/internal_api.py", line 2190, in upload_file
    response.raise_for_status()
  File "/home/zhuhe/.conda/envs/diffhpe/lib/python3.9/site-packages/requests/models.py", line 1021, in raise_for_status
    raise HTTPError(http_error_msg, response=self)
requests.exceptions.HTTPError: 404 Client Error: Not Found for url: https://storage.googleapis.com/wandb-production.appspot.com/ada4321/DiffHPE/hh51ey3p/output.log?Expires=1689137738&GoogleAccessId=gorilla-files-url-signer-man%40wandb-production.iam.gserviceaccount.com&Signature=cebFtNm8c%2F6%2BPIr9DNA%2BQLd%2FW3bZY7CzTQXnIBFX6cMCRr%2Fc71x%2FmvUtUjWnjLel9qZwN5R8byLkyViIcyBlY4qgh3M5%2FliHDzYBZ5%2B43qacwE9Sy9%2Fq%2BWEDWuVhdria0YBcxtzVC4A22OqrA295V8IYETRExe3DlZTfuPp2ITKGo6eEAfMdQ4vNp%2BJixIb7uDZtP9zfHpD7Qh2mPUMpa%2BURXSrip1ypmJb9NT72ksyjTyUqkSj%2FLyv%2BRq8MKFDuZaMphQC336uiVACd0cTfdX3OnR8BFcO7IMVhb1%2BBykCKjT0EKQgBLv1BBdJvWQAKn%2BODwY15hjn1fxK9Dp5DXQ%3D%3D

During handling of the above exception, another exception occurred:

Traceback (most recent call last):
  File "/home/zhuhe/.conda/envs/diffhpe/lib/python3.9/concurrent/futures/thread.py", line 58, in run
    result = self.fn(*self.args, **self.kwargs)
  File "/home/zhuhe/.conda/envs/diffhpe/lib/python3.9/site-packages/wandb/filesync/step_upload.py", line 288, in run_and_notify
    self._do_upload_sync(event)
  File "/home/zhuhe/.conda/envs/diffhpe/lib/python3.9/site-packages/wandb/filesync/step_upload.py", line 330, in _do_upload_sync
    job.run()
  File "/home/zhuhe/.conda/envs/diffhpe/lib/python3.9/site-packages/wandb/filesync/upload_job.py", line 57, in run
    self.push()
  File "/home/zhuhe/.conda/envs/diffhpe/lib/python3.9/site-packages/wandb/filesync/upload_job.py", line 127, in push
    self._api.upload_file_retry(
  File "/home/zhuhe/.conda/envs/diffhpe/lib/python3.9/site-packages/wandb/apis/normalize.py", line 51, in wrapper
    raise CommError(message, error)
wandb.errors.CommError: <Response [404]>
2023-07-11 12:55:40,641 ERROR   Thread-11 :108266 [step_upload.py:_handle_event():200] Failed to upload file: /home/zhuhe/HPE-with-Diffusion/wandb/run-20230711_125521-hh51ey3p/files/conda-environment.yaml
Traceback (most recent call last):
  File "/home/zhuhe/.conda/envs/diffhpe/lib/python3.9/site-packages/wandb/apis/normalize.py", line 41, in wrapper
    return func(*args, **kwargs)
  File "/home/zhuhe/.conda/envs/diffhpe/lib/python3.9/site-packages/wandb/sdk/lib/retry.py", line 212, in wrapped_fn
    return retrier(*args, **kargs)
  File "/home/zhuhe/.conda/envs/diffhpe/lib/python3.9/site-packages/wandb/sdk/lib/retry.py", line 131, in __call__
    result = self._call_fn(*args, **kwargs)
  File "/home/zhuhe/.conda/envs/diffhpe/lib/python3.9/site-packages/wandb/sdk/internal/internal_api.py", line 2218, in upload_file
    wandb._sentry.reraise(e)
  File "/home/zhuhe/.conda/envs/diffhpe/lib/python3.9/site-packages/wandb/analytics/sentry.py", line 146, in reraise
    raise exc.with_traceback(sys.exc_info()[2])
  File "/home/zhuhe/.conda/envs/diffhpe/lib/python3.9/site-packages/wandb/sdk/internal/internal_api.py", line 2190, in upload_file
    response.raise_for_status()
  File "/home/zhuhe/.conda/envs/diffhpe/lib/python3.9/site-packages/requests/models.py", line 1021, in raise_for_status
    raise HTTPError(http_error_msg, response=self)
requests.exceptions.HTTPError: 404 Client Error: Not Found for url: https://storage.googleapis.com/wandb-production.appspot.com/ada4321/DiffHPE/hh51ey3p/conda-environment.yaml?Expires=1689137738&GoogleAccessId=gorilla-files-url-signer-man%40wandb-production.iam.gserviceaccount.com&Signature=P4OTcTuNpNhwsJ1UUKG78w%2B9KdDoSgP9SGveaqmiwfLTXF%2FzvZTBnqb1PP2QnTCDcMIyU8%2FawlU3PDuwF%2B9RH2vXMB1w483cKqa%2BGkFFfTMRIA1HTZa%2BOY2pCYMMfJCuKCN4NsrvaqyLWGhejoZIP6w8b9puLU5DkbwVchB%2BcZEABqNBBeVchAKrUy9p2J1Ia99crR1b1CZPtH8%2BVPLUHJzoIPIFGmJKyRGpa6MXAtuCpHW7w6BsVj%2Bfj55CfBWgkST2rP1n7RvNqFY6LZcnWK4ek4pcN9QcdC2YSUvE6MVgKhM9UATjyohR%2BDfskXTZNj29GLKBB9u2L9QJ9HKUJQ%3D%3D

During handling of the above exception, another exception occurred:

Traceback (most recent call last):
  File "/home/zhuhe/.conda/envs/diffhpe/lib/python3.9/concurrent/futures/thread.py", line 58, in run
    result = self.fn(*self.args, **self.kwargs)
  File "/home/zhuhe/.conda/envs/diffhpe/lib/python3.9/site-packages/wandb/filesync/step_upload.py", line 288, in run_and_notify
    self._do_upload_sync(event)
  File "/home/zhuhe/.conda/envs/diffhpe/lib/python3.9/site-packages/wandb/filesync/step_upload.py", line 330, in _do_upload_sync
    job.run()
  File "/home/zhuhe/.conda/envs/diffhpe/lib/python3.9/site-packages/wandb/filesync/upload_job.py", line 57, in run
    self.push()
  File "/home/zhuhe/.conda/envs/diffhpe/lib/python3.9/site-packages/wandb/filesync/upload_job.py", line 127, in push
    self._api.upload_file_retry(
  File "/home/zhuhe/.conda/envs/diffhpe/lib/python3.9/site-packages/wandb/apis/normalize.py", line 51, in wrapper
    raise CommError(message, error)
wandb.errors.CommError: <Response [404]>
2023-07-11 12:55:40,842 INFO    Thread-11 :108266 [sender.py:transition_state():602] send defer: 11
2023-07-11 12:55:40,842 DEBUG   HandlerThread:108266 [handler.py:handle_request():144] handle_request: defer
2023-07-11 12:55:40,843 INFO    HandlerThread:108266 [handler.py:handle_request_defer():170] handle defer: 11
2023-07-11 12:55:40,843 DEBUG   SenderThread:108266 [sender.py:send_request():396] send_request: defer
2023-07-11 12:55:40,844 INFO    SenderThread:108266 [sender.py:send_request_defer():598] handle sender defer: 11
2023-07-11 12:55:40,844 INFO    SenderThread:108266 [file_pusher.py:join():164] waiting for file pusher
2023-07-11 12:55:40,844 INFO    SenderThread:108266 [sender.py:transition_state():602] send defer: 12
2023-07-11 12:55:40,844 DEBUG   HandlerThread:108266 [handler.py:handle_request():144] handle_request: defer
2023-07-11 12:55:40,844 INFO    HandlerThread:108266 [handler.py:handle_request_defer():170] handle defer: 12
2023-07-11 12:55:40,845 DEBUG   SenderThread:108266 [sender.py:send_request():396] send_request: defer
2023-07-11 12:55:40,845 INFO    SenderThread:108266 [sender.py:send_request_defer():598] handle sender defer: 12
2023-07-11 12:55:41,108 INFO    SenderThread:108266 [sender.py:transition_state():602] send defer: 13
2023-07-11 12:55:41,109 DEBUG   HandlerThread:108266 [handler.py:handle_request():144] handle_request: defer
2023-07-11 12:55:41,109 INFO    HandlerThread:108266 [handler.py:handle_request_defer():170] handle defer: 13
2023-07-11 12:55:41,110 DEBUG   SenderThread:108266 [sender.py:send_request():396] send_request: defer
2023-07-11 12:55:41,110 INFO    SenderThread:108266 [sender.py:send_request_defer():598] handle sender defer: 13
2023-07-11 12:55:41,110 INFO    SenderThread:108266 [sender.py:transition_state():602] send defer: 14
2023-07-11 12:55:41,110 DEBUG   HandlerThread:108266 [handler.py:handle_request():144] handle_request: defer
2023-07-11 12:55:41,111 INFO    HandlerThread:108266 [handler.py:handle_request_defer():170] handle defer: 14
2023-07-11 12:55:41,111 DEBUG   SenderThread:108266 [sender.py:send():369] send: final
2023-07-11 12:55:41,112 DEBUG   SenderThread:108266 [sender.py:send():369] send: footer
2023-07-11 12:55:41,112 DEBUG   SenderThread:108266 [sender.py:send_request():396] send_request: defer
2023-07-11 12:55:41,112 INFO    SenderThread:108266 [sender.py:send_request_defer():598] handle sender defer: 14
2023-07-11 12:55:41,113 DEBUG   HandlerThread:108266 [handler.py:handle_request():144] handle_request: poll_exit
2023-07-11 12:55:41,113 DEBUG   SenderThread:108266 [sender.py:send_request():396] send_request: poll_exit
2023-07-11 12:55:41,115 DEBUG   HandlerThread:108266 [handler.py:handle_request():144] handle_request: server_info
2023-07-11 12:55:41,115 DEBUG   HandlerThread:108266 [handler.py:handle_request():144] handle_request: get_summary
2023-07-11 12:55:41,115 DEBUG   HandlerThread:108266 [handler.py:handle_request():144] handle_request: sampled_history
2023-07-11 12:55:41,116 DEBUG   SenderThread:108266 [sender.py:send_request():396] send_request: server_info
2023-07-11 12:55:41,565 INFO    MainThread:108266 [wandb_run.py:_footer_history_summary_info():3467] rendering history
2023-07-11 12:55:41,565 INFO    MainThread:108266 [wandb_run.py:_footer_history_summary_info():3499] rendering summary
2023-07-11 12:55:41,566 INFO    MainThread:108266 [wandb_run.py:_footer_sync_info():3426] logging synced files
2023-07-11 12:55:41,566 DEBUG   HandlerThread:108266 [handler.py:handle_request():144] handle_request: shutdown
2023-07-11 12:55:41,566 INFO    HandlerThread:108266 [handler.py:finish():854] shutting down handler
2023-07-11 12:55:42,116 INFO    WriterThread:108266 [datastore.py:close():298] close: /home/zhuhe/HPE-with-Diffusion/wandb/run-20230711_125521-hh51ey3p/run-hh51ey3p.wandb
2023-07-11 12:55:42,565 INFO    SenderThread:108266 [sender.py:finish():1526] shutting down sender
2023-07-11 12:55:42,565 INFO    SenderThread:108266 [file_pusher.py:finish():159] shutting down file pusher
2023-07-11 12:55:42,565 INFO    SenderThread:108266 [file_pusher.py:join():164] waiting for file pusher
