2023-07-10 14:40:55,111 INFO    StreamThr :29778 [internal.py:wandb_internal():86] W&B internal server running at pid: 29778, started at: 2023-07-10 14:40:55.110913
2023-07-10 14:40:55,112 DEBUG   HandlerThread:29778 [handler.py:handle_request():144] handle_request: status
2023-07-10 14:40:55,113 INFO    WriterThread:29778 [datastore.py:open_for_write():85] open: /home/zhuhe/HPE-with-Diffusion/wandb/run-20230710_144055-mqgir0zw/run-mqgir0zw.wandb
2023-07-10 14:40:55,113 DEBUG   SenderThread:29778 [sender.py:send():369] send: header
2023-07-10 14:40:55,113 DEBUG   SenderThread:29778 [sender.py:send():369] send: run
2023-07-10 14:40:55,116 DEBUG   SenderThread:29778 [gitlib.py:_init_repo():53] git repository is invalid
2023-07-10 14:40:55,964 INFO    SenderThread:29778 [dir_watcher.py:__init__():211] watching files in: /home/zhuhe/HPE-with-Diffusion/wandb/run-20230710_144055-mqgir0zw/files
2023-07-10 14:40:55,964 INFO    SenderThread:29778 [sender.py:_start_run_threads():1100] run started: mqgir0zw with start time 1688971255.111117
2023-07-10 14:40:55,964 DEBUG   SenderThread:29778 [sender.py:send_request():396] send_request: summary_record
2023-07-10 14:40:55,964 INFO    SenderThread:29778 [sender.py:_save_file():1354] saving file wandb-summary.json with policy end
2023-07-10 14:40:55,965 DEBUG   HandlerThread:29778 [handler.py:handle_request():144] handle_request: check_version
2023-07-10 14:40:55,966 DEBUG   SenderThread:29778 [sender.py:send_request():396] send_request: check_version
2023-07-10 14:40:56,571 DEBUG   HandlerThread:29778 [handler.py:handle_request():144] handle_request: run_start
2023-07-10 14:40:56,575 DEBUG   HandlerThread:29778 [system_info.py:__init__():31] System info init
2023-07-10 14:40:56,575 DEBUG   HandlerThread:29778 [system_info.py:__init__():46] System info init done
2023-07-10 14:40:56,575 INFO    HandlerThread:29778 [system_monitor.py:start():181] Starting system monitor
2023-07-10 14:40:56,576 INFO    SystemMonitor:29778 [system_monitor.py:_start():145] Starting system asset monitoring threads
2023-07-10 14:40:56,576 INFO    HandlerThread:29778 [system_monitor.py:probe():201] Collecting system info
2023-07-10 14:40:56,576 INFO    SystemMonitor:29778 [interfaces.py:start():190] Started cpu monitoring
2023-07-10 14:40:56,577 INFO    SystemMonitor:29778 [interfaces.py:start():190] Started disk monitoring
2023-07-10 14:40:56,577 INFO    SystemMonitor:29778 [interfaces.py:start():190] Started gpu monitoring
2023-07-10 14:40:56,578 INFO    SystemMonitor:29778 [interfaces.py:start():190] Started memory monitoring
2023-07-10 14:40:56,578 INFO    SystemMonitor:29778 [interfaces.py:start():190] Started network monitoring
2023-07-10 14:40:56,593 DEBUG   HandlerThread:29778 [system_info.py:probe():195] Probing system
2023-07-10 14:40:56,593 DEBUG   HandlerThread:29778 [gitlib.py:_init_repo():53] git repository is invalid
2023-07-10 14:40:56,593 DEBUG   HandlerThread:29778 [system_info.py:probe():240] Probing system done
2023-07-10 14:40:56,593 DEBUG   HandlerThread:29778 [system_monitor.py:probe():210] {'os': 'Linux-5.19.0-46-generic-x86_64-with-glibc2.35', 'python': '3.9.16', 'heartbeatAt': '2023-07-10T06:40:56.593518', 'startedAt': '2023-07-10T06:40:55.107727', 'docker': None, 'cuda': None, 'args': (), 'state': 'running', 'program': '/home/zhuhe/HPE-with-Diffusion/main.py', 'codePath': 'main.py', 'host': '415-2', 'username': 'zhuhe', 'executable': '/home/zhuhe/.conda/envs/diffhpe/bin/python', 'cpu_count': 16, 'cpu_count_logical': 24, 'cpu_freq': {'current': 4108.961666666667, 'min': 800.0, 'max': 4783.333333333333}, 'cpu_freq_per_core': [{'current': 5099.985, 'min': 800.0, 'max': 5100.0}, {'current': 5100.0, 'min': 800.0, 'max': 5100.0}, {'current': 5100.0, 'min': 800.0, 'max': 5100.0}, {'current': 5100.0, 'min': 800.0, 'max': 5100.0}, {'current': 5100.015, 'min': 800.0, 'max': 5100.0}, {'current': 2100.0, 'min': 800.0, 'max': 5100.0}, {'current': 4977.402, 'min': 800.0, 'max': 5100.0}, {'current': 4311.727, 'min': 800.0, 'max': 5100.0}, {'current': 5029.26, 'min': 800.0, 'max': 5200.0}, {'current': 5049.349, 'min': 800.0, 'max': 5200.0}, {'current': 5100.0, 'min': 800.0, 'max': 5200.0}, {'current': 2100.0, 'min': 800.0, 'max': 5200.0}, {'current': 5099.984, 'min': 800.0, 'max': 5100.0}, {'current': 2100.0, 'min': 800.0, 'max': 5100.0}, {'current': 5098.852, 'min': 800.0, 'max': 5100.0}, {'current': 2100.0, 'min': 800.0, 'max': 5100.0}, {'current': 3700.03, 'min': 800.0, 'max': 4100.0}, {'current': 3774.004, 'min': 800.0, 'max': 4100.0}, {'current': 3773.767, 'min': 800.0, 'max': 4100.0}, {'current': 3775.25, 'min': 800.0, 'max': 4100.0}, {'current': 3775.168, 'min': 800.0, 'max': 4100.0}, {'current': 3775.182, 'min': 800.0, 'max': 4100.0}, {'current': 3775.133, 'min': 800.0, 'max': 4100.0}, {'current': 3699.972, 'min': 800.0, 'max': 4100.0}], 'disk': {'total': 93.31179428100586, 'used': 0.017879486083984375}, 'gpu': 'NVIDIA GeForce RTX 3090', 'gpu_count': 2, 'gpu_devices': [{'name': 'NVIDIA GeForce RTX 3090', 'memory_total': 25769803776}, {'name': 'NVIDIA GeForce RTX 3090', 'memory_total': 25769803776}], 'memory': {'total': 31.185562133789062}}
2023-07-10 14:40:56,593 INFO    HandlerThread:29778 [system_monitor.py:probe():211] Finished collecting system info
2023-07-10 14:40:56,593 INFO    HandlerThread:29778 [system_monitor.py:probe():214] Publishing system info
2023-07-10 14:40:56,593 DEBUG   HandlerThread:29778 [system_info.py:_save_pip():51] Saving list of pip packages installed into the current environment
2023-07-10 14:40:56,593 DEBUG   HandlerThread:29778 [system_info.py:_save_pip():67] Saving pip packages done
2023-07-10 14:40:56,593 DEBUG   HandlerThread:29778 [system_info.py:_save_conda():74] Saving list of conda packages installed into the current environment
2023-07-10 14:40:56,965 INFO    Thread-12 :29778 [dir_watcher.py:_on_file_created():272] file/dir created: /home/zhuhe/HPE-with-Diffusion/wandb/run-20230710_144055-mqgir0zw/files/conda-environment.yaml
2023-07-10 14:40:56,965 INFO    Thread-12 :29778 [dir_watcher.py:_on_file_created():272] file/dir created: /home/zhuhe/HPE-with-Diffusion/wandb/run-20230710_144055-mqgir0zw/files/requirements.txt
2023-07-10 14:40:56,965 INFO    Thread-12 :29778 [dir_watcher.py:_on_file_created():272] file/dir created: /home/zhuhe/HPE-with-Diffusion/wandb/run-20230710_144055-mqgir0zw/files/wandb-summary.json
2023-07-10 14:40:57,423 DEBUG   HandlerThread:29778 [system_info.py:_save_conda():86] Saving conda packages done
2023-07-10 14:40:57,424 INFO    HandlerThread:29778 [system_monitor.py:probe():216] Finished publishing system info
2023-07-10 14:40:57,426 DEBUG   SenderThread:29778 [sender.py:send():369] send: files
2023-07-10 14:40:57,426 INFO    SenderThread:29778 [sender.py:_save_file():1354] saving file wandb-metadata.json with policy now
2023-07-10 14:40:57,428 DEBUG   HandlerThread:29778 [handler.py:handle_request():144] handle_request: stop_status
2023-07-10 14:40:57,428 DEBUG   SenderThread:29778 [sender.py:send_request():396] send_request: stop_status
2023-07-10 14:40:57,899 ERROR   wandb-upload_0:29778 [internal_api.py:upload_file():2192] upload_file exception https://storage.googleapis.com/wandb-production.appspot.com/ada4321/uncategorized/mqgir0zw/wandb-metadata.json?Expires=1689057657&GoogleAccessId=gorilla-files-url-signer-man%40wandb-production.iam.gserviceaccount.com&Signature=CmE5RuJvk6xw6sMOU2lHvhQdFGyywdGFaofZkfMt1MBWm%2F3QCiQXrbvdKas%2FkfMFGimGaNw7cBt6LgYYCrBi8AUHZVEieQhxxXSDtns9X%2Bad3FIaIY%2BoS%2FAxxj08yFk5sX%2FiVdFImI9SX2cV%2BOhKCpoNM0BGJmVDYlzRCPDPh0WAZPt1A2NYyDkQ6i%2BDKfm1NpyHrap2wmtsMybWAqfV7LZsqqlLEneVJAbMfgxPCUI62V0z21wR1WGV9%2B579WThyTEIsK1O3GsAgtL4FKuFp%2BKl2I2GVZE5XdYaVDKImSyupDRy2T0sBwkZLLZsnZ2PMlgGNZ0JTRz4vzeoRlTBVg%3D%3D: 404 Client Error: Not Found for url: https://storage.googleapis.com/wandb-production.appspot.com/ada4321/uncategorized/mqgir0zw/wandb-metadata.json?Expires=1689057657&GoogleAccessId=gorilla-files-url-signer-man%40wandb-production.iam.gserviceaccount.com&Signature=CmE5RuJvk6xw6sMOU2lHvhQdFGyywdGFaofZkfMt1MBWm%2F3QCiQXrbvdKas%2FkfMFGimGaNw7cBt6LgYYCrBi8AUHZVEieQhxxXSDtns9X%2Bad3FIaIY%2BoS%2FAxxj08yFk5sX%2FiVdFImI9SX2cV%2BOhKCpoNM0BGJmVDYlzRCPDPh0WAZPt1A2NYyDkQ6i%2BDKfm1NpyHrap2wmtsMybWAqfV7LZsqqlLEneVJAbMfgxPCUI62V0z21wR1WGV9%2B579WThyTEIsK1O3GsAgtL4FKuFp%2BKl2I2GVZE5XdYaVDKImSyupDRy2T0sBwkZLLZsnZ2PMlgGNZ0JTRz4vzeoRlTBVg%3D%3D
2023-07-10 14:40:57,899 ERROR   wandb-upload_0:29778 [internal_api.py:upload_file():2194] upload_file request headers: {'User-Agent': 'python-requests/2.31.0', 'Accept-Encoding': 'gzip, deflate', 'Accept': '*/*', 'Connection': 'keep-alive', 'Content-Length': '3634'}
2023-07-10 14:40:57,899 ERROR   wandb-upload_0:29778 [internal_api.py:upload_file():2196] upload_file response body: b'<!DOCTYPE html>\n<html lang=en>\n  <meta charset=utf-8>\n  <meta name=viewport content="initial-scale=1, minimum-scale=1, width=device-width">\n  <title>Error 404 (Not Found)!!1</title>\n  <style>\n    *{margin:0;padding:0}html,code{font:15px/22px arial,sans-serif}html{background:#fff;color:#222;padding:15px}body{margin:7% auto 0;max-width:390px;min-height:180px;padding:30px 0 15px}* > body{background:url(//www.google.com/images/errors/robot.png) 100% 5px no-repeat;padding-right:205px}p{margin:11px 0 22px;overflow:hidden}ins{color:#777;text-decoration:none}a img{border:0}@media screen and (max-width:772px){body{background:none;margin-top:0;max-width:none;padding-right:0}}#logo{background:url(//www.google.com/images/branding/googlelogo/1x/googlelogo_color_150x54dp.png) no-repeat;margin-left:-5px}@media only screen and (min-resolution:192dpi){#logo{background:url(//www.google.com/images/branding/googlelogo/2x/googlelogo_color_150x54dp.png) no-repeat 0% 0%/100% 100%;-moz-border-image:url(//www.google.com/images/branding/googlelogo/2x/googlelogo_color_150x54dp.png) 0}}@media only screen and (-webkit-min-device-pixel-ratio:2){#logo{background:url(//www.google.com/images/branding/googlelogo/2x/googlelogo_color_150x54dp.png) no-repeat;-webkit-background-size:100% 100%}}#logo{display:inline-block;height:54px;width:150px}\n  </style>\n  <a href=//www.google.com/><span id=logo aria-label=Google></span></a>\n  <p><b>404.</b> <ins>That\xe2\x80\x99s an error.</ins>\n  <p>The requested URL <code>/wandb-production.appspot.com/ada4321/uncategorized/mqgir0zw/wandb-metadata.json</code> was not found on this server.  <ins>That\xe2\x80\x99s all we know.</ins>\n'
2023-07-10 14:40:57,965 INFO    Thread-12 :29778 [dir_watcher.py:_on_file_modified():289] file/dir modified: /home/zhuhe/HPE-with-Diffusion/wandb/run-20230710_144055-mqgir0zw/files/conda-environment.yaml
2023-07-10 14:40:57,965 INFO    Thread-12 :29778 [dir_watcher.py:_on_file_created():272] file/dir created: /home/zhuhe/HPE-with-Diffusion/wandb/run-20230710_144055-mqgir0zw/files/wandb-metadata.json
2023-07-10 14:40:57,970 DEBUG   SenderThread:29778 [sender.py:send():369] send: telemetry
2023-07-10 14:40:57,970 DEBUG   SenderThread:29778 [sender.py:send():369] send: exit
2023-07-10 14:40:57,970 INFO    SenderThread:29778 [sender.py:send_exit():574] handling exit code: 1
2023-07-10 14:40:57,971 INFO    SenderThread:29778 [sender.py:send_exit():576] handling runtime: 0
2023-07-10 14:40:57,971 INFO    SenderThread:29778 [sender.py:_save_file():1354] saving file wandb-summary.json with policy end
2023-07-10 14:40:57,971 INFO    SenderThread:29778 [sender.py:send_exit():582] send defer
2023-07-10 14:40:57,971 DEBUG   HandlerThread:29778 [handler.py:handle_request():144] handle_request: defer
2023-07-10 14:40:57,971 INFO    HandlerThread:29778 [handler.py:handle_request_defer():170] handle defer: 0
2023-07-10 14:40:57,971 DEBUG   SenderThread:29778 [sender.py:send_request():396] send_request: defer
2023-07-10 14:40:57,971 INFO    SenderThread:29778 [sender.py:send_request_defer():598] handle sender defer: 0
2023-07-10 14:40:57,971 INFO    SenderThread:29778 [sender.py:transition_state():602] send defer: 1
2023-07-10 14:40:57,971 DEBUG   HandlerThread:29778 [handler.py:handle_request():144] handle_request: defer
2023-07-10 14:40:57,971 INFO    HandlerThread:29778 [handler.py:handle_request_defer():170] handle defer: 1
2023-07-10 14:40:57,972 DEBUG   SenderThread:29778 [sender.py:send_request():396] send_request: defer
2023-07-10 14:40:57,972 INFO    SenderThread:29778 [sender.py:send_request_defer():598] handle sender defer: 1
2023-07-10 14:40:57,972 INFO    SenderThread:29778 [sender.py:transition_state():602] send defer: 2
2023-07-10 14:40:57,972 DEBUG   HandlerThread:29778 [handler.py:handle_request():144] handle_request: defer
2023-07-10 14:40:57,972 INFO    HandlerThread:29778 [handler.py:handle_request_defer():170] handle defer: 2
2023-07-10 14:40:57,972 INFO    HandlerThread:29778 [system_monitor.py:finish():190] Stopping system monitor
2023-07-10 14:40:57,972 DEBUG   SystemMonitor:29778 [system_monitor.py:_start():159] Starting system metrics aggregation loop
2023-07-10 14:40:57,972 DEBUG   SystemMonitor:29778 [system_monitor.py:_start():166] Finished system metrics aggregation loop
2023-07-10 14:40:57,973 DEBUG   SystemMonitor:29778 [system_monitor.py:_start():170] Publishing last batch of metrics
2023-07-10 14:40:57,973 INFO    HandlerThread:29778 [interfaces.py:finish():202] Joined cpu monitor
2023-07-10 14:40:57,973 INFO    HandlerThread:29778 [interfaces.py:finish():202] Joined disk monitor
2023-07-10 14:40:58,016 INFO    HandlerThread:29778 [interfaces.py:finish():202] Joined gpu monitor
2023-07-10 14:40:58,016 INFO    HandlerThread:29778 [interfaces.py:finish():202] Joined memory monitor
2023-07-10 14:40:58,016 INFO    HandlerThread:29778 [interfaces.py:finish():202] Joined network monitor
2023-07-10 14:40:58,017 DEBUG   SenderThread:29778 [sender.py:send_request():396] send_request: defer
2023-07-10 14:40:58,017 INFO    SenderThread:29778 [sender.py:send_request_defer():598] handle sender defer: 2
2023-07-10 14:40:58,017 INFO    SenderThread:29778 [sender.py:transition_state():602] send defer: 3
2023-07-10 14:40:58,017 DEBUG   SenderThread:29778 [sender.py:send():369] send: stats
2023-07-10 14:40:58,017 DEBUG   HandlerThread:29778 [handler.py:handle_request():144] handle_request: defer
2023-07-10 14:40:58,017 INFO    HandlerThread:29778 [handler.py:handle_request_defer():170] handle defer: 3
2023-07-10 14:40:58,017 DEBUG   SenderThread:29778 [sender.py:send_request():396] send_request: defer
2023-07-10 14:40:58,017 INFO    SenderThread:29778 [sender.py:send_request_defer():598] handle sender defer: 3
2023-07-10 14:40:58,018 INFO    SenderThread:29778 [sender.py:transition_state():602] send defer: 4
2023-07-10 14:40:58,018 DEBUG   HandlerThread:29778 [handler.py:handle_request():144] handle_request: defer
2023-07-10 14:40:58,018 INFO    HandlerThread:29778 [handler.py:handle_request_defer():170] handle defer: 4
2023-07-10 14:40:58,018 DEBUG   SenderThread:29778 [sender.py:send_request():396] send_request: defer
2023-07-10 14:40:58,018 INFO    SenderThread:29778 [sender.py:send_request_defer():598] handle sender defer: 4
2023-07-10 14:40:58,018 INFO    SenderThread:29778 [sender.py:transition_state():602] send defer: 5
2023-07-10 14:40:58,018 DEBUG   HandlerThread:29778 [handler.py:handle_request():144] handle_request: defer
2023-07-10 14:40:58,018 INFO    HandlerThread:29778 [handler.py:handle_request_defer():170] handle defer: 5
2023-07-10 14:40:58,018 DEBUG   SenderThread:29778 [sender.py:send():369] send: summary
2023-07-10 14:40:58,018 INFO    SenderThread:29778 [sender.py:_save_file():1354] saving file wandb-summary.json with policy end
2023-07-10 14:40:58,019 DEBUG   SenderThread:29778 [sender.py:send_request():396] send_request: defer
2023-07-10 14:40:58,019 INFO    SenderThread:29778 [sender.py:send_request_defer():598] handle sender defer: 5
2023-07-10 14:40:58,019 INFO    SenderThread:29778 [sender.py:transition_state():602] send defer: 6
2023-07-10 14:40:58,019 DEBUG   HandlerThread:29778 [handler.py:handle_request():144] handle_request: defer
2023-07-10 14:40:58,019 INFO    HandlerThread:29778 [handler.py:handle_request_defer():170] handle defer: 6
2023-07-10 14:40:58,019 DEBUG   SenderThread:29778 [sender.py:send_request():396] send_request: defer
2023-07-10 14:40:58,019 INFO    SenderThread:29778 [sender.py:send_request_defer():598] handle sender defer: 6
2023-07-10 14:40:58,022 DEBUG   HandlerThread:29778 [handler.py:handle_request():144] handle_request: status_report
2023-07-10 14:40:58,259 INFO    SenderThread:29778 [sender.py:transition_state():602] send defer: 7
2023-07-10 14:40:58,260 DEBUG   HandlerThread:29778 [handler.py:handle_request():144] handle_request: defer
2023-07-10 14:40:58,260 INFO    HandlerThread:29778 [handler.py:handle_request_defer():170] handle defer: 7
2023-07-10 14:40:58,260 DEBUG   SenderThread:29778 [sender.py:send_request():396] send_request: defer
2023-07-10 14:40:58,260 INFO    SenderThread:29778 [sender.py:send_request_defer():598] handle sender defer: 7
2023-07-10 14:40:58,430 DEBUG   HandlerThread:29778 [handler.py:handle_request():144] handle_request: poll_exit
2023-07-10 14:40:58,965 INFO    Thread-12 :29778 [dir_watcher.py:_on_file_modified():289] file/dir modified: /home/zhuhe/HPE-with-Diffusion/wandb/run-20230710_144055-mqgir0zw/files/config.yaml
2023-07-10 14:40:58,965 INFO    Thread-12 :29778 [dir_watcher.py:_on_file_modified():289] file/dir modified: /home/zhuhe/HPE-with-Diffusion/wandb/run-20230710_144055-mqgir0zw/files/wandb-summary.json
2023-07-10 14:40:58,965 INFO    Thread-12 :29778 [dir_watcher.py:_on_file_created():272] file/dir created: /home/zhuhe/HPE-with-Diffusion/wandb/run-20230710_144055-mqgir0zw/files/output.log
2023-07-10 14:40:59,334 ERROR   wandb-upload_0:29778 [upload_job.py:push():136] Failed to upload file: /tmp/tmpaku3traxwandb/e158r7a4-wandb-metadata.json
Traceback (most recent call last):
  File "/home/zhuhe/.conda/envs/diffhpe/lib/python3.9/site-packages/wandb/apis/normalize.py", line 41, in wrapper
    return func(*args, **kwargs)
  File "/home/zhuhe/.conda/envs/diffhpe/lib/python3.9/site-packages/wandb/sdk/lib/retry.py", line 212, in wrapped_fn
    return retrier(*args, **kargs)
  File "/home/zhuhe/.conda/envs/diffhpe/lib/python3.9/site-packages/wandb/sdk/lib/retry.py", line 131, in __call__
    result = self._call_fn(*args, **kwargs)
  File "/home/zhuhe/.conda/envs/diffhpe/lib/python3.9/site-packages/wandb/sdk/internal/internal_api.py", line 2218, in upload_file
    wandb._sentry.reraise(e)
  File "/home/zhuhe/.conda/envs/diffhpe/lib/python3.9/site-packages/wandb/analytics/sentry.py", line 146, in reraise
    raise exc.with_traceback(sys.exc_info()[2])
  File "/home/zhuhe/.conda/envs/diffhpe/lib/python3.9/site-packages/wandb/sdk/internal/internal_api.py", line 2190, in upload_file
    response.raise_for_status()
  File "/home/zhuhe/.conda/envs/diffhpe/lib/python3.9/site-packages/requests/models.py", line 1021, in raise_for_status
    raise HTTPError(http_error_msg, response=self)
requests.exceptions.HTTPError: 404 Client Error: Not Found for url: https://storage.googleapis.com/wandb-production.appspot.com/ada4321/uncategorized/mqgir0zw/wandb-metadata.json?Expires=1689057657&GoogleAccessId=gorilla-files-url-signer-man%40wandb-production.iam.gserviceaccount.com&Signature=CmE5RuJvk6xw6sMOU2lHvhQdFGyywdGFaofZkfMt1MBWm%2F3QCiQXrbvdKas%2FkfMFGimGaNw7cBt6LgYYCrBi8AUHZVEieQhxxXSDtns9X%2Bad3FIaIY%2BoS%2FAxxj08yFk5sX%2FiVdFImI9SX2cV%2BOhKCpoNM0BGJmVDYlzRCPDPh0WAZPt1A2NYyDkQ6i%2BDKfm1NpyHrap2wmtsMybWAqfV7LZsqqlLEneVJAbMfgxPCUI62V0z21wR1WGV9%2B579WThyTEIsK1O3GsAgtL4FKuFp%2BKl2I2GVZE5XdYaVDKImSyupDRy2T0sBwkZLLZsnZ2PMlgGNZ0JTRz4vzeoRlTBVg%3D%3D

During handling of the above exception, another exception occurred:

Traceback (most recent call last):
  File "/home/zhuhe/.conda/envs/diffhpe/lib/python3.9/site-packages/wandb/filesync/upload_job.py", line 127, in push
    self._api.upload_file_retry(
  File "/home/zhuhe/.conda/envs/diffhpe/lib/python3.9/site-packages/wandb/apis/normalize.py", line 51, in wrapper
    raise CommError(message, error)
wandb.errors.CommError: <Response [404]>
2023-07-10 14:40:59,545 ERROR   Thread-11 :29778 [step_upload.py:_handle_event():200] Failed to upload file: /tmp/tmpaku3traxwandb/e158r7a4-wandb-metadata.json
Traceback (most recent call last):
  File "/home/zhuhe/.conda/envs/diffhpe/lib/python3.9/site-packages/wandb/apis/normalize.py", line 41, in wrapper
    return func(*args, **kwargs)
  File "/home/zhuhe/.conda/envs/diffhpe/lib/python3.9/site-packages/wandb/sdk/lib/retry.py", line 212, in wrapped_fn
    return retrier(*args, **kargs)
  File "/home/zhuhe/.conda/envs/diffhpe/lib/python3.9/site-packages/wandb/sdk/lib/retry.py", line 131, in __call__
    result = self._call_fn(*args, **kwargs)
  File "/home/zhuhe/.conda/envs/diffhpe/lib/python3.9/site-packages/wandb/sdk/internal/internal_api.py", line 2218, in upload_file
    wandb._sentry.reraise(e)
  File "/home/zhuhe/.conda/envs/diffhpe/lib/python3.9/site-packages/wandb/analytics/sentry.py", line 146, in reraise
    raise exc.with_traceback(sys.exc_info()[2])
  File "/home/zhuhe/.conda/envs/diffhpe/lib/python3.9/site-packages/wandb/sdk/internal/internal_api.py", line 2190, in upload_file
    response.raise_for_status()
  File "/home/zhuhe/.conda/envs/diffhpe/lib/python3.9/site-packages/requests/models.py", line 1021, in raise_for_status
    raise HTTPError(http_error_msg, response=self)
requests.exceptions.HTTPError: 404 Client Error: Not Found for url: https://storage.googleapis.com/wandb-production.appspot.com/ada4321/uncategorized/mqgir0zw/wandb-metadata.json?Expires=1689057657&GoogleAccessId=gorilla-files-url-signer-man%40wandb-production.iam.gserviceaccount.com&Signature=CmE5RuJvk6xw6sMOU2lHvhQdFGyywdGFaofZkfMt1MBWm%2F3QCiQXrbvdKas%2FkfMFGimGaNw7cBt6LgYYCrBi8AUHZVEieQhxxXSDtns9X%2Bad3FIaIY%2BoS%2FAxxj08yFk5sX%2FiVdFImI9SX2cV%2BOhKCpoNM0BGJmVDYlzRCPDPh0WAZPt1A2NYyDkQ6i%2BDKfm1NpyHrap2wmtsMybWAqfV7LZsqqlLEneVJAbMfgxPCUI62V0z21wR1WGV9%2B579WThyTEIsK1O3GsAgtL4FKuFp%2BKl2I2GVZE5XdYaVDKImSyupDRy2T0sBwkZLLZsnZ2PMlgGNZ0JTRz4vzeoRlTBVg%3D%3D

During handling of the above exception, another exception occurred:

Traceback (most recent call last):
  File "/home/zhuhe/.conda/envs/diffhpe/lib/python3.9/concurrent/futures/thread.py", line 58, in run
    result = self.fn(*self.args, **self.kwargs)
  File "/home/zhuhe/.conda/envs/diffhpe/lib/python3.9/site-packages/wandb/filesync/step_upload.py", line 288, in run_and_notify
    self._do_upload_sync(event)
  File "/home/zhuhe/.conda/envs/diffhpe/lib/python3.9/site-packages/wandb/filesync/step_upload.py", line 330, in _do_upload_sync
    job.run()
  File "/home/zhuhe/.conda/envs/diffhpe/lib/python3.9/site-packages/wandb/filesync/upload_job.py", line 57, in run
    self.push()
  File "/home/zhuhe/.conda/envs/diffhpe/lib/python3.9/site-packages/wandb/filesync/upload_job.py", line 127, in push
    self._api.upload_file_retry(
  File "/home/zhuhe/.conda/envs/diffhpe/lib/python3.9/site-packages/wandb/apis/normalize.py", line 51, in wrapper
    raise CommError(message, error)
wandb.errors.CommError: <Response [404]>
2023-07-10 14:40:59,977 INFO    SenderThread:29778 [sender.py:transition_state():602] send defer: 8
2023-07-10 14:40:59,977 DEBUG   SenderThread:29778 [sender.py:send_request():396] send_request: poll_exit
2023-07-10 14:40:59,977 DEBUG   HandlerThread:29778 [handler.py:handle_request():144] handle_request: defer
2023-07-10 14:40:59,977 INFO    HandlerThread:29778 [handler.py:handle_request_defer():170] handle defer: 8
2023-07-10 14:40:59,978 DEBUG   SenderThread:29778 [sender.py:send_request():396] send_request: defer
2023-07-10 14:40:59,978 INFO    SenderThread:29778 [sender.py:send_request_defer():598] handle sender defer: 8
2023-07-10 14:40:59,978 INFO    SenderThread:29778 [job_builder.py:build():232] Attempting to build job artifact
2023-07-10 14:40:59,978 INFO    SenderThread:29778 [job_builder.py:build():266] no source found
2023-07-10 14:40:59,978 INFO    SenderThread:29778 [sender.py:transition_state():602] send defer: 9
2023-07-10 14:40:59,978 DEBUG   HandlerThread:29778 [handler.py:handle_request():144] handle_request: defer
2023-07-10 14:40:59,978 INFO    HandlerThread:29778 [handler.py:handle_request_defer():170] handle defer: 9
2023-07-10 14:40:59,978 DEBUG   SenderThread:29778 [sender.py:send_request():396] send_request: defer
2023-07-10 14:40:59,978 INFO    SenderThread:29778 [sender.py:send_request_defer():598] handle sender defer: 9
2023-07-10 14:40:59,978 INFO    SenderThread:29778 [dir_watcher.py:finish():359] shutting down directory watcher
2023-07-10 14:41:00,965 INFO    Thread-12 :29778 [dir_watcher.py:_on_file_modified():289] file/dir modified: /home/zhuhe/HPE-with-Diffusion/wandb/run-20230710_144055-mqgir0zw/files/output.log
2023-07-10 14:41:00,966 INFO    SenderThread:29778 [dir_watcher.py:finish():389] scan: /home/zhuhe/HPE-with-Diffusion/wandb/run-20230710_144055-mqgir0zw/files
2023-07-10 14:41:00,966 INFO    SenderThread:29778 [dir_watcher.py:finish():403] scan save: /home/zhuhe/HPE-with-Diffusion/wandb/run-20230710_144055-mqgir0zw/files/wandb-metadata.json wandb-metadata.json
2023-07-10 14:41:00,966 INFO    SenderThread:29778 [dir_watcher.py:finish():403] scan save: /home/zhuhe/HPE-with-Diffusion/wandb/run-20230710_144055-mqgir0zw/files/config.yaml config.yaml
2023-07-10 14:41:00,966 INFO    SenderThread:29778 [dir_watcher.py:finish():403] scan save: /home/zhuhe/HPE-with-Diffusion/wandb/run-20230710_144055-mqgir0zw/files/requirements.txt requirements.txt
2023-07-10 14:41:00,966 INFO    SenderThread:29778 [dir_watcher.py:finish():403] scan save: /home/zhuhe/HPE-with-Diffusion/wandb/run-20230710_144055-mqgir0zw/files/wandb-summary.json wandb-summary.json
2023-07-10 14:41:00,966 INFO    SenderThread:29778 [dir_watcher.py:finish():403] scan save: /home/zhuhe/HPE-with-Diffusion/wandb/run-20230710_144055-mqgir0zw/files/conda-environment.yaml conda-environment.yaml
2023-07-10 14:41:00,967 INFO    SenderThread:29778 [dir_watcher.py:finish():403] scan save: /home/zhuhe/HPE-with-Diffusion/wandb/run-20230710_144055-mqgir0zw/files/output.log output.log
2023-07-10 14:41:00,967 INFO    SenderThread:29778 [sender.py:transition_state():602] send defer: 10
2023-07-10 14:41:00,967 DEBUG   HandlerThread:29778 [handler.py:handle_request():144] handle_request: defer
2023-07-10 14:41:00,967 INFO    HandlerThread:29778 [handler.py:handle_request_defer():170] handle defer: 10
2023-07-10 14:41:00,971 DEBUG   SenderThread:29778 [sender.py:send_request():396] send_request: defer
2023-07-10 14:41:00,971 INFO    SenderThread:29778 [sender.py:send_request_defer():598] handle sender defer: 10
2023-07-10 14:41:00,971 INFO    SenderThread:29778 [file_pusher.py:finish():159] shutting down file pusher
2023-07-10 14:41:01,445 ERROR   wandb-upload_1:29778 [internal_api.py:upload_file():2192] upload_file exception https://storage.googleapis.com/wandb-production.appspot.com/ada4321/uncategorized/mqgir0zw/config.yaml?Expires=1689057661&GoogleAccessId=gorilla-files-url-signer-man%40wandb-production.iam.gserviceaccount.com&Signature=JXSBHjTTiDPXej2a9wWIJsb5ZFKhkro%2BqZpXdB7v15n2QXvs0bedUQJ8PnPvsYlbQfHVV87mXqMZgVZ4ZmNJBOhM51dCWZjD6%2FLo6VmfdNw%2FlB6Q54fUOcVT324BdVcLqiKDTcOWiQfU5KgCoAwpxh24dC2w%2B5anbv791wSYzKYrZnTr0sSRQ0yKwwgWZpM4W%2Brcrg2lmEfedQRgTtgKtm5nwzYQcpzeV4VEtdOD%2BYU5PU1ZP86ZqUVx8iOlh3ZI0TNqX8sm40S0c%2F1YFawDvcKS%2BPAxExtccyL0wj01PKPQ13rjQxRYcCh%2FTVIU5FnylyF3KfEbnLbCaif%2BF2im0w%3D%3D: 404 Client Error: Not Found for url: https://storage.googleapis.com/wandb-production.appspot.com/ada4321/uncategorized/mqgir0zw/config.yaml?Expires=1689057661&GoogleAccessId=gorilla-files-url-signer-man%40wandb-production.iam.gserviceaccount.com&Signature=JXSBHjTTiDPXej2a9wWIJsb5ZFKhkro%2BqZpXdB7v15n2QXvs0bedUQJ8PnPvsYlbQfHVV87mXqMZgVZ4ZmNJBOhM51dCWZjD6%2FLo6VmfdNw%2FlB6Q54fUOcVT324BdVcLqiKDTcOWiQfU5KgCoAwpxh24dC2w%2B5anbv791wSYzKYrZnTr0sSRQ0yKwwgWZpM4W%2Brcrg2lmEfedQRgTtgKtm5nwzYQcpzeV4VEtdOD%2BYU5PU1ZP86ZqUVx8iOlh3ZI0TNqX8sm40S0c%2F1YFawDvcKS%2BPAxExtccyL0wj01PKPQ13rjQxRYcCh%2FTVIU5FnylyF3KfEbnLbCaif%2BF2im0w%3D%3D
2023-07-10 14:41:01,445 ERROR   wandb-upload_1:29778 [internal_api.py:upload_file():2194] upload_file request headers: {'User-Agent': 'python-requests/2.31.0', 'Accept-Encoding': 'gzip, deflate', 'Accept': '*/*', 'Connection': 'keep-alive', 'Content-Length': '583'}
2023-07-10 14:41:01,445 ERROR   wandb-upload_1:29778 [internal_api.py:upload_file():2196] upload_file response body: b'<!DOCTYPE html>\n<html lang=en>\n  <meta charset=utf-8>\n  <meta name=viewport content="initial-scale=1, minimum-scale=1, width=device-width">\n  <title>Error 404 (Not Found)!!1</title>\n  <style>\n    *{margin:0;padding:0}html,code{font:15px/22px arial,sans-serif}html{background:#fff;color:#222;padding:15px}body{margin:7% auto 0;max-width:390px;min-height:180px;padding:30px 0 15px}* > body{background:url(//www.google.com/images/errors/robot.png) 100% 5px no-repeat;padding-right:205px}p{margin:11px 0 22px;overflow:hidden}ins{color:#777;text-decoration:none}a img{border:0}@media screen and (max-width:772px){body{background:none;margin-top:0;max-width:none;padding-right:0}}#logo{background:url(//www.google.com/images/branding/googlelogo/1x/googlelogo_color_150x54dp.png) no-repeat;margin-left:-5px}@media only screen and (min-resolution:192dpi){#logo{background:url(//www.google.com/images/branding/googlelogo/2x/googlelogo_color_150x54dp.png) no-repeat 0% 0%/100% 100%;-moz-border-image:url(//www.google.com/images/branding/googlelogo/2x/googlelogo_color_150x54dp.png) 0}}@media only screen and (-webkit-min-device-pixel-ratio:2){#logo{background:url(//www.google.com/images/branding/googlelogo/2x/googlelogo_color_150x54dp.png) no-repeat;-webkit-background-size:100% 100%}}#logo{display:inline-block;height:54px;width:150px}\n  </style>\n  <a href=//www.google.com/><span id=logo aria-label=Google></span></a>\n  <p><b>404.</b> <ins>That\xe2\x80\x99s an error.</ins>\n  <p>The requested URL <code>/wandb-production.appspot.com/ada4321/uncategorized/mqgir0zw/config.yaml</code> was not found on this server.  <ins>That\xe2\x80\x99s all we know.</ins>\n'
2023-07-10 14:41:01,449 ERROR   wandb-upload_0:29778 [internal_api.py:upload_file():2192] upload_file exception https://storage.googleapis.com/wandb-production.appspot.com/ada4321/uncategorized/mqgir0zw/requirements.txt?Expires=1689057661&GoogleAccessId=gorilla-files-url-signer-man%40wandb-production.iam.gserviceaccount.com&Signature=dqklbw%2BtOSWXGyYPKcI1u2bdJLJ%2BAwcsH9QGPn9e45dynS214y3dWthq9%2B3K%2BX5C4hdjPGgIt8UbspmilAIpu9EAzsn1x6qZaDtF2APmpEg6mE4oomz%2BgsnxzX1QwUjkhtPc%2BihoI5EQaG4Lxo%2FFY4uloIrL8uMSBLBzxYrhsbTC6ZxMFhuLb17sbP3FE6B3HGWAM4CJH30ss5fuIlXDuY1BzPTsFx7x98omzIZ%2F9gPktH8a7bH5xMvXmEL1b67aa0Bo76B9uxbR9cOy965QjDD3%2FPk8cMN%2BQNbjZDUVu20tJDqdvMyVs7dw1gv%2BpC%2B9v30mLmRREwxz9GkY8DOO0w%3D%3D: 404 Client Error: Not Found for url: https://storage.googleapis.com/wandb-production.appspot.com/ada4321/uncategorized/mqgir0zw/requirements.txt?Expires=1689057661&GoogleAccessId=gorilla-files-url-signer-man%40wandb-production.iam.gserviceaccount.com&Signature=dqklbw%2BtOSWXGyYPKcI1u2bdJLJ%2BAwcsH9QGPn9e45dynS214y3dWthq9%2B3K%2BX5C4hdjPGgIt8UbspmilAIpu9EAzsn1x6qZaDtF2APmpEg6mE4oomz%2BgsnxzX1QwUjkhtPc%2BihoI5EQaG4Lxo%2FFY4uloIrL8uMSBLBzxYrhsbTC6ZxMFhuLb17sbP3FE6B3HGWAM4CJH30ss5fuIlXDuY1BzPTsFx7x98omzIZ%2F9gPktH8a7bH5xMvXmEL1b67aa0Bo76B9uxbR9cOy965QjDD3%2FPk8cMN%2BQNbjZDUVu20tJDqdvMyVs7dw1gv%2BpC%2B9v30mLmRREwxz9GkY8DOO0w%3D%3D
2023-07-10 14:41:01,449 ERROR   wandb-upload_0:29778 [internal_api.py:upload_file():2194] upload_file request headers: {'User-Agent': 'python-requests/2.31.0', 'Accept-Encoding': 'gzip, deflate', 'Accept': '*/*', 'Connection': 'keep-alive', 'Content-Length': '910'}
2023-07-10 14:41:01,449 ERROR   wandb-upload_0:29778 [internal_api.py:upload_file():2196] upload_file response body: b'<!DOCTYPE html>\n<html lang=en>\n  <meta charset=utf-8>\n  <meta name=viewport content="initial-scale=1, minimum-scale=1, width=device-width">\n  <title>Error 404 (Not Found)!!1</title>\n  <style>\n    *{margin:0;padding:0}html,code{font:15px/22px arial,sans-serif}html{background:#fff;color:#222;padding:15px}body{margin:7% auto 0;max-width:390px;min-height:180px;padding:30px 0 15px}* > body{background:url(//www.google.com/images/errors/robot.png) 100% 5px no-repeat;padding-right:205px}p{margin:11px 0 22px;overflow:hidden}ins{color:#777;text-decoration:none}a img{border:0}@media screen and (max-width:772px){body{background:none;margin-top:0;max-width:none;padding-right:0}}#logo{background:url(//www.google.com/images/branding/googlelogo/1x/googlelogo_color_150x54dp.png) no-repeat;margin-left:-5px}@media only screen and (min-resolution:192dpi){#logo{background:url(//www.google.com/images/branding/googlelogo/2x/googlelogo_color_150x54dp.png) no-repeat 0% 0%/100% 100%;-moz-border-image:url(//www.google.com/images/branding/googlelogo/2x/googlelogo_color_150x54dp.png) 0}}@media only screen and (-webkit-min-device-pixel-ratio:2){#logo{background:url(//www.google.com/images/branding/googlelogo/2x/googlelogo_color_150x54dp.png) no-repeat;-webkit-background-size:100% 100%}}#logo{display:inline-block;height:54px;width:150px}\n  </style>\n  <a href=//www.google.com/><span id=logo aria-label=Google></span></a>\n  <p><b>404.</b> <ins>That\xe2\x80\x99s an error.</ins>\n  <p>The requested URL <code>/wandb-production.appspot.com/ada4321/uncategorized/mqgir0zw/requirements.txt</code> was not found on this server.  <ins>That\xe2\x80\x99s all we know.</ins>\n'
2023-07-10 14:41:01,815 ERROR   wandb-upload_2:29778 [internal_api.py:upload_file():2192] upload_file exception https://storage.googleapis.com/wandb-production.appspot.com/ada4321/uncategorized/mqgir0zw/wandb-summary.json?Expires=1689057661&GoogleAccessId=gorilla-files-url-signer-man%40wandb-production.iam.gserviceaccount.com&Signature=gD11Ui3HrVcGzP3sQTdJ9S1JHGbXHC8ZYLgX7UH51sAr1t51Qhl0MIumrh9%2BDNDvuqUVrZZJ9CXOu1Qb8pgNwQJnQ2ujMCOzEyL%2F4HGV4eJEvC2tVKpHynLDNMXpbMb4d6SxMGisUDJGflHtMoknInnhR5iK5PiYgMYLumsR6v9NCcFDWq3lFGQdTAsTfLEYyrOKYhfe0PneQp049OeTjUmnfL%2Ba%2FltUKnD0%2FpzfC0OLeMJARf7oQZFCnqVfF6iDporhEOW325xtsT9rOUB1CXiKDLmB8d%2BF3m6gFvx0IOL9xUt6p6gElD0txWLL1eROxeNbp3%2FfyM5zmItGTO0zhg%3D%3D: 404 Client Error: Not Found for url: https://storage.googleapis.com/wandb-production.appspot.com/ada4321/uncategorized/mqgir0zw/wandb-summary.json?Expires=1689057661&GoogleAccessId=gorilla-files-url-signer-man%40wandb-production.iam.gserviceaccount.com&Signature=gD11Ui3HrVcGzP3sQTdJ9S1JHGbXHC8ZYLgX7UH51sAr1t51Qhl0MIumrh9%2BDNDvuqUVrZZJ9CXOu1Qb8pgNwQJnQ2ujMCOzEyL%2F4HGV4eJEvC2tVKpHynLDNMXpbMb4d6SxMGisUDJGflHtMoknInnhR5iK5PiYgMYLumsR6v9NCcFDWq3lFGQdTAsTfLEYyrOKYhfe0PneQp049OeTjUmnfL%2Ba%2FltUKnD0%2FpzfC0OLeMJARf7oQZFCnqVfF6iDporhEOW325xtsT9rOUB1CXiKDLmB8d%2BF3m6gFvx0IOL9xUt6p6gElD0txWLL1eROxeNbp3%2FfyM5zmItGTO0zhg%3D%3D
2023-07-10 14:41:01,815 ERROR   wandb-upload_2:29778 [internal_api.py:upload_file():2194] upload_file request headers: {'User-Agent': 'python-requests/2.31.0', 'Accept-Encoding': 'gzip, deflate', 'Accept': '*/*', 'Connection': 'keep-alive', 'Content-Length': '26'}
2023-07-10 14:41:01,815 ERROR   wandb-upload_2:29778 [internal_api.py:upload_file():2196] upload_file response body: b'<!DOCTYPE html>\n<html lang=en>\n  <meta charset=utf-8>\n  <meta name=viewport content="initial-scale=1, minimum-scale=1, width=device-width">\n  <title>Error 404 (Not Found)!!1</title>\n  <style>\n    *{margin:0;padding:0}html,code{font:15px/22px arial,sans-serif}html{background:#fff;color:#222;padding:15px}body{margin:7% auto 0;max-width:390px;min-height:180px;padding:30px 0 15px}* > body{background:url(//www.google.com/images/errors/robot.png) 100% 5px no-repeat;padding-right:205px}p{margin:11px 0 22px;overflow:hidden}ins{color:#777;text-decoration:none}a img{border:0}@media screen and (max-width:772px){body{background:none;margin-top:0;max-width:none;padding-right:0}}#logo{background:url(//www.google.com/images/branding/googlelogo/1x/googlelogo_color_150x54dp.png) no-repeat;margin-left:-5px}@media only screen and (min-resolution:192dpi){#logo{background:url(//www.google.com/images/branding/googlelogo/2x/googlelogo_color_150x54dp.png) no-repeat 0% 0%/100% 100%;-moz-border-image:url(//www.google.com/images/branding/googlelogo/2x/googlelogo_color_150x54dp.png) 0}}@media only screen and (-webkit-min-device-pixel-ratio:2){#logo{background:url(//www.google.com/images/branding/googlelogo/2x/googlelogo_color_150x54dp.png) no-repeat;-webkit-background-size:100% 100%}}#logo{display:inline-block;height:54px;width:150px}\n  </style>\n  <a href=//www.google.com/><span id=logo aria-label=Google></span></a>\n  <p><b>404.</b> <ins>That\xe2\x80\x99s an error.</ins>\n  <p>The requested URL <code>/wandb-production.appspot.com/ada4321/uncategorized/mqgir0zw/wandb-summary.json</code> was not found on this server.  <ins>That\xe2\x80\x99s all we know.</ins>\n'
2023-07-10 14:41:01,817 ERROR   wandb-upload_4:29778 [internal_api.py:upload_file():2192] upload_file exception https://storage.googleapis.com/wandb-production.appspot.com/ada4321/uncategorized/mqgir0zw/output.log?Expires=1689057661&GoogleAccessId=gorilla-files-url-signer-man%40wandb-production.iam.gserviceaccount.com&Signature=b2pVyxM85FI2ccsN2eWdzZ0IE38%2B8Cx8LU2MaBm%2BH%2FHbmvLt62jUjVL3Kq%2BZBfJySSZqxGxdtABZZUsIXjMFcNP97wtKUCixUvQWEIESGW4Exgf5k7zS94R2kuwpiAEjRhzUk45WiG7or3wRCDS6felwz2Q9TQl0D8CBo3MsrzfeDFbgOZAN8zak07HF0SIEN2uytOmnATnERMuxc9UnDDL6orcAIra8cTbj3wWe7zDzXk7aqk%2FP9lKLV%2B8fFvIJysEPgcQDId529Rh6pNG3P8lwnBc7bqhCtEYhpbStY%2FlTwkmoScT3WAtm3ubfBEzm6TfBOnOMvk%2FERdH%2FiYE%2Fjg%3D%3D: 404 Client Error: Not Found for url: https://storage.googleapis.com/wandb-production.appspot.com/ada4321/uncategorized/mqgir0zw/output.log?Expires=1689057661&GoogleAccessId=gorilla-files-url-signer-man%40wandb-production.iam.gserviceaccount.com&Signature=b2pVyxM85FI2ccsN2eWdzZ0IE38%2B8Cx8LU2MaBm%2BH%2FHbmvLt62jUjVL3Kq%2BZBfJySSZqxGxdtABZZUsIXjMFcNP97wtKUCixUvQWEIESGW4Exgf5k7zS94R2kuwpiAEjRhzUk45WiG7or3wRCDS6felwz2Q9TQl0D8CBo3MsrzfeDFbgOZAN8zak07HF0SIEN2uytOmnATnERMuxc9UnDDL6orcAIra8cTbj3wWe7zDzXk7aqk%2FP9lKLV%2B8fFvIJysEPgcQDId529Rh6pNG3P8lwnBc7bqhCtEYhpbStY%2FlTwkmoScT3WAtm3ubfBEzm6TfBOnOMvk%2FERdH%2FiYE%2Fjg%3D%3D
2023-07-10 14:41:01,817 ERROR   wandb-upload_4:29778 [internal_api.py:upload_file():2194] upload_file request headers: {'User-Agent': 'python-requests/2.31.0', 'Accept-Encoding': 'gzip, deflate', 'Accept': '*/*', 'Connection': 'keep-alive', 'Content-Length': '2649'}
2023-07-10 14:41:01,817 ERROR   wandb-upload_4:29778 [internal_api.py:upload_file():2196] upload_file response body: b'<!DOCTYPE html>\n<html lang=en>\n  <meta charset=utf-8>\n  <meta name=viewport content="initial-scale=1, minimum-scale=1, width=device-width">\n  <title>Error 404 (Not Found)!!1</title>\n  <style>\n    *{margin:0;padding:0}html,code{font:15px/22px arial,sans-serif}html{background:#fff;color:#222;padding:15px}body{margin:7% auto 0;max-width:390px;min-height:180px;padding:30px 0 15px}* > body{background:url(//www.google.com/images/errors/robot.png) 100% 5px no-repeat;padding-right:205px}p{margin:11px 0 22px;overflow:hidden}ins{color:#777;text-decoration:none}a img{border:0}@media screen and (max-width:772px){body{background:none;margin-top:0;max-width:none;padding-right:0}}#logo{background:url(//www.google.com/images/branding/googlelogo/1x/googlelogo_color_150x54dp.png) no-repeat;margin-left:-5px}@media only screen and (min-resolution:192dpi){#logo{background:url(//www.google.com/images/branding/googlelogo/2x/googlelogo_color_150x54dp.png) no-repeat 0% 0%/100% 100%;-moz-border-image:url(//www.google.com/images/branding/googlelogo/2x/googlelogo_color_150x54dp.png) 0}}@media only screen and (-webkit-min-device-pixel-ratio:2){#logo{background:url(//www.google.com/images/branding/googlelogo/2x/googlelogo_color_150x54dp.png) no-repeat;-webkit-background-size:100% 100%}}#logo{display:inline-block;height:54px;width:150px}\n  </style>\n  <a href=//www.google.com/><span id=logo aria-label=Google></span></a>\n  <p><b>404.</b> <ins>That\xe2\x80\x99s an error.</ins>\n  <p>The requested URL <code>/wandb-production.appspot.com/ada4321/uncategorized/mqgir0zw/output.log</code> was not found on this server.  <ins>That\xe2\x80\x99s all we know.</ins>\n'
2023-07-10 14:41:01,838 ERROR   wandb-upload_3:29778 [internal_api.py:upload_file():2192] upload_file exception https://storage.googleapis.com/wandb-production.appspot.com/ada4321/uncategorized/mqgir0zw/conda-environment.yaml?Expires=1689057661&GoogleAccessId=gorilla-files-url-signer-man%40wandb-production.iam.gserviceaccount.com&Signature=IeMDm1JDRrCOd5ana6Bs9GDmcnEfjpgrLeyJ0gr5DefXwWJAybgP7AkDCg8U4cHwha0F9VGzw7h0HKq24nciscIDKFWQdv4Uq3i%2BmU%2FMel04vdl56AVOulgTyD%2BAaaz63aGXT1ZkahqYm3cgFlFO1RrFrs9QzxWpCw3j4%2FuAunx7uJHTkOMejJobyc37wzL1PO7tE%2Bs7J4GG2a3xoETWIO5pa1p7GkI4JKCrjjnaO3Y2TD1RNxLhEiuyPOfFKBpV9WQScRSZoh0RIIZI8ACEvg5FJcM34N3SjKd5Roi5oeCEXlwgy2C%2FuDRPRS%2BozUL3ljKGf7YEpvsZTClEdf23Cg%3D%3D: 404 Client Error: Not Found for url: https://storage.googleapis.com/wandb-production.appspot.com/ada4321/uncategorized/mqgir0zw/conda-environment.yaml?Expires=1689057661&GoogleAccessId=gorilla-files-url-signer-man%40wandb-production.iam.gserviceaccount.com&Signature=IeMDm1JDRrCOd5ana6Bs9GDmcnEfjpgrLeyJ0gr5DefXwWJAybgP7AkDCg8U4cHwha0F9VGzw7h0HKq24nciscIDKFWQdv4Uq3i%2BmU%2FMel04vdl56AVOulgTyD%2BAaaz63aGXT1ZkahqYm3cgFlFO1RrFrs9QzxWpCw3j4%2FuAunx7uJHTkOMejJobyc37wzL1PO7tE%2Bs7J4GG2a3xoETWIO5pa1p7GkI4JKCrjjnaO3Y2TD1RNxLhEiuyPOfFKBpV9WQScRSZoh0RIIZI8ACEvg5FJcM34N3SjKd5Roi5oeCEXlwgy2C%2FuDRPRS%2BozUL3ljKGf7YEpvsZTClEdf23Cg%3D%3D
2023-07-10 14:41:01,838 ERROR   wandb-upload_3:29778 [internal_api.py:upload_file():2194] upload_file request headers: {'User-Agent': 'python-requests/2.31.0', 'Accept-Encoding': 'gzip, deflate', 'Accept': '*/*', 'Connection': 'keep-alive', 'Content-Length': '1903'}
2023-07-10 14:41:01,838 ERROR   wandb-upload_3:29778 [internal_api.py:upload_file():2196] upload_file response body: b'<!DOCTYPE html>\n<html lang=en>\n  <meta charset=utf-8>\n  <meta name=viewport content="initial-scale=1, minimum-scale=1, width=device-width">\n  <title>Error 404 (Not Found)!!1</title>\n  <style>\n    *{margin:0;padding:0}html,code{font:15px/22px arial,sans-serif}html{background:#fff;color:#222;padding:15px}body{margin:7% auto 0;max-width:390px;min-height:180px;padding:30px 0 15px}* > body{background:url(//www.google.com/images/errors/robot.png) 100% 5px no-repeat;padding-right:205px}p{margin:11px 0 22px;overflow:hidden}ins{color:#777;text-decoration:none}a img{border:0}@media screen and (max-width:772px){body{background:none;margin-top:0;max-width:none;padding-right:0}}#logo{background:url(//www.google.com/images/branding/googlelogo/1x/googlelogo_color_150x54dp.png) no-repeat;margin-left:-5px}@media only screen and (min-resolution:192dpi){#logo{background:url(//www.google.com/images/branding/googlelogo/2x/googlelogo_color_150x54dp.png) no-repeat 0% 0%/100% 100%;-moz-border-image:url(//www.google.com/images/branding/googlelogo/2x/googlelogo_color_150x54dp.png) 0}}@media only screen and (-webkit-min-device-pixel-ratio:2){#logo{background:url(//www.google.com/images/branding/googlelogo/2x/googlelogo_color_150x54dp.png) no-repeat;-webkit-background-size:100% 100%}}#logo{display:inline-block;height:54px;width:150px}\n  </style>\n  <a href=//www.google.com/><span id=logo aria-label=Google></span></a>\n  <p><b>404.</b> <ins>That\xe2\x80\x99s an error.</ins>\n  <p>The requested URL <code>/wandb-production.appspot.com/ada4321/uncategorized/mqgir0zw/conda-environment.yaml</code> was not found on this server.  <ins>That\xe2\x80\x99s all we know.</ins>\n'
2023-07-10 14:41:02,496 ERROR   wandb-upload_1:29778 [upload_job.py:push():136] Failed to upload file: /home/zhuhe/HPE-with-Diffusion/wandb/run-20230710_144055-mqgir0zw/files/config.yaml
Traceback (most recent call last):
  File "/home/zhuhe/.conda/envs/diffhpe/lib/python3.9/site-packages/wandb/apis/normalize.py", line 41, in wrapper
    return func(*args, **kwargs)
  File "/home/zhuhe/.conda/envs/diffhpe/lib/python3.9/site-packages/wandb/sdk/lib/retry.py", line 212, in wrapped_fn
    return retrier(*args, **kargs)
  File "/home/zhuhe/.conda/envs/diffhpe/lib/python3.9/site-packages/wandb/sdk/lib/retry.py", line 131, in __call__
    result = self._call_fn(*args, **kwargs)
  File "/home/zhuhe/.conda/envs/diffhpe/lib/python3.9/site-packages/wandb/sdk/internal/internal_api.py", line 2218, in upload_file
    wandb._sentry.reraise(e)
  File "/home/zhuhe/.conda/envs/diffhpe/lib/python3.9/site-packages/wandb/analytics/sentry.py", line 146, in reraise
    raise exc.with_traceback(sys.exc_info()[2])
  File "/home/zhuhe/.conda/envs/diffhpe/lib/python3.9/site-packages/wandb/sdk/internal/internal_api.py", line 2190, in upload_file
    response.raise_for_status()
  File "/home/zhuhe/.conda/envs/diffhpe/lib/python3.9/site-packages/requests/models.py", line 1021, in raise_for_status
    raise HTTPError(http_error_msg, response=self)
requests.exceptions.HTTPError: 404 Client Error: Not Found for url: https://storage.googleapis.com/wandb-production.appspot.com/ada4321/uncategorized/mqgir0zw/config.yaml?Expires=1689057661&GoogleAccessId=gorilla-files-url-signer-man%40wandb-production.iam.gserviceaccount.com&Signature=JXSBHjTTiDPXej2a9wWIJsb5ZFKhkro%2BqZpXdB7v15n2QXvs0bedUQJ8PnPvsYlbQfHVV87mXqMZgVZ4ZmNJBOhM51dCWZjD6%2FLo6VmfdNw%2FlB6Q54fUOcVT324BdVcLqiKDTcOWiQfU5KgCoAwpxh24dC2w%2B5anbv791wSYzKYrZnTr0sSRQ0yKwwgWZpM4W%2Brcrg2lmEfedQRgTtgKtm5nwzYQcpzeV4VEtdOD%2BYU5PU1ZP86ZqUVx8iOlh3ZI0TNqX8sm40S0c%2F1YFawDvcKS%2BPAxExtccyL0wj01PKPQ13rjQxRYcCh%2FTVIU5FnylyF3KfEbnLbCaif%2BF2im0w%3D%3D

During handling of the above exception, another exception occurred:

Traceback (most recent call last):
  File "/home/zhuhe/.conda/envs/diffhpe/lib/python3.9/site-packages/wandb/filesync/upload_job.py", line 127, in push
    self._api.upload_file_retry(
  File "/home/zhuhe/.conda/envs/diffhpe/lib/python3.9/site-packages/wandb/apis/normalize.py", line 51, in wrapper
    raise CommError(message, error)
wandb.errors.CommError: <Response [404]>
2023-07-10 14:41:02,497 ERROR   wandb-upload_0:29778 [upload_job.py:push():136] Failed to upload file: /home/zhuhe/HPE-with-Diffusion/wandb/run-20230710_144055-mqgir0zw/files/requirements.txt
Traceback (most recent call last):
  File "/home/zhuhe/.conda/envs/diffhpe/lib/python3.9/site-packages/wandb/apis/normalize.py", line 41, in wrapper
    return func(*args, **kwargs)
  File "/home/zhuhe/.conda/envs/diffhpe/lib/python3.9/site-packages/wandb/sdk/lib/retry.py", line 212, in wrapped_fn
    return retrier(*args, **kargs)
  File "/home/zhuhe/.conda/envs/diffhpe/lib/python3.9/site-packages/wandb/sdk/lib/retry.py", line 131, in __call__
    result = self._call_fn(*args, **kwargs)
  File "/home/zhuhe/.conda/envs/diffhpe/lib/python3.9/site-packages/wandb/sdk/internal/internal_api.py", line 2218, in upload_file
    wandb._sentry.reraise(e)
  File "/home/zhuhe/.conda/envs/diffhpe/lib/python3.9/site-packages/wandb/analytics/sentry.py", line 146, in reraise
    raise exc.with_traceback(sys.exc_info()[2])
  File "/home/zhuhe/.conda/envs/diffhpe/lib/python3.9/site-packages/wandb/sdk/internal/internal_api.py", line 2190, in upload_file
    response.raise_for_status()
  File "/home/zhuhe/.conda/envs/diffhpe/lib/python3.9/site-packages/requests/models.py", line 1021, in raise_for_status
    raise HTTPError(http_error_msg, response=self)
requests.exceptions.HTTPError: 404 Client Error: Not Found for url: https://storage.googleapis.com/wandb-production.appspot.com/ada4321/uncategorized/mqgir0zw/requirements.txt?Expires=1689057661&GoogleAccessId=gorilla-files-url-signer-man%40wandb-production.iam.gserviceaccount.com&Signature=dqklbw%2BtOSWXGyYPKcI1u2bdJLJ%2BAwcsH9QGPn9e45dynS214y3dWthq9%2B3K%2BX5C4hdjPGgIt8UbspmilAIpu9EAzsn1x6qZaDtF2APmpEg6mE4oomz%2BgsnxzX1QwUjkhtPc%2BihoI5EQaG4Lxo%2FFY4uloIrL8uMSBLBzxYrhsbTC6ZxMFhuLb17sbP3FE6B3HGWAM4CJH30ss5fuIlXDuY1BzPTsFx7x98omzIZ%2F9gPktH8a7bH5xMvXmEL1b67aa0Bo76B9uxbR9cOy965QjDD3%2FPk8cMN%2BQNbjZDUVu20tJDqdvMyVs7dw1gv%2BpC%2B9v30mLmRREwxz9GkY8DOO0w%3D%3D

During handling of the above exception, another exception occurred:

Traceback (most recent call last):
  File "/home/zhuhe/.conda/envs/diffhpe/lib/python3.9/site-packages/wandb/filesync/upload_job.py", line 127, in push
    self._api.upload_file_retry(
  File "/home/zhuhe/.conda/envs/diffhpe/lib/python3.9/site-packages/wandb/apis/normalize.py", line 51, in wrapper
    raise CommError(message, error)
wandb.errors.CommError: <Response [404]>
2023-07-10 14:41:02,497 ERROR   wandb-upload_4:29778 [upload_job.py:push():136] Failed to upload file: /home/zhuhe/HPE-with-Diffusion/wandb/run-20230710_144055-mqgir0zw/files/output.log
Traceback (most recent call last):
  File "/home/zhuhe/.conda/envs/diffhpe/lib/python3.9/site-packages/wandb/apis/normalize.py", line 41, in wrapper
    return func(*args, **kwargs)
  File "/home/zhuhe/.conda/envs/diffhpe/lib/python3.9/site-packages/wandb/sdk/lib/retry.py", line 212, in wrapped_fn
    return retrier(*args, **kargs)
  File "/home/zhuhe/.conda/envs/diffhpe/lib/python3.9/site-packages/wandb/sdk/lib/retry.py", line 131, in __call__
    result = self._call_fn(*args, **kwargs)
  File "/home/zhuhe/.conda/envs/diffhpe/lib/python3.9/site-packages/wandb/sdk/internal/internal_api.py", line 2218, in upload_file
    wandb._sentry.reraise(e)
  File "/home/zhuhe/.conda/envs/diffhpe/lib/python3.9/site-packages/wandb/analytics/sentry.py", line 146, in reraise
    raise exc.with_traceback(sys.exc_info()[2])
  File "/home/zhuhe/.conda/envs/diffhpe/lib/python3.9/site-packages/wandb/sdk/internal/internal_api.py", line 2190, in upload_file
    response.raise_for_status()
  File "/home/zhuhe/.conda/envs/diffhpe/lib/python3.9/site-packages/requests/models.py", line 1021, in raise_for_status
    raise HTTPError(http_error_msg, response=self)
requests.exceptions.HTTPError: 404 Client Error: Not Found for url: https://storage.googleapis.com/wandb-production.appspot.com/ada4321/uncategorized/mqgir0zw/output.log?Expires=1689057661&GoogleAccessId=gorilla-files-url-signer-man%40wandb-production.iam.gserviceaccount.com&Signature=b2pVyxM85FI2ccsN2eWdzZ0IE38%2B8Cx8LU2MaBm%2BH%2FHbmvLt62jUjVL3Kq%2BZBfJySSZqxGxdtABZZUsIXjMFcNP97wtKUCixUvQWEIESGW4Exgf5k7zS94R2kuwpiAEjRhzUk45WiG7or3wRCDS6felwz2Q9TQl0D8CBo3MsrzfeDFbgOZAN8zak07HF0SIEN2uytOmnATnERMuxc9UnDDL6orcAIra8cTbj3wWe7zDzXk7aqk%2FP9lKLV%2B8fFvIJysEPgcQDId529Rh6pNG3P8lwnBc7bqhCtEYhpbStY%2FlTwkmoScT3WAtm3ubfBEzm6TfBOnOMvk%2FERdH%2FiYE%2Fjg%3D%3D

During handling of the above exception, another exception occurred:

Traceback (most recent call last):
  File "/home/zhuhe/.conda/envs/diffhpe/lib/python3.9/site-packages/wandb/filesync/upload_job.py", line 127, in push
    self._api.upload_file_retry(
  File "/home/zhuhe/.conda/envs/diffhpe/lib/python3.9/site-packages/wandb/apis/normalize.py", line 51, in wrapper
    raise CommError(message, error)
wandb.errors.CommError: <Response [404]>
2023-07-10 14:41:02,497 ERROR   wandb-upload_3:29778 [upload_job.py:push():136] Failed to upload file: /home/zhuhe/HPE-with-Diffusion/wandb/run-20230710_144055-mqgir0zw/files/conda-environment.yaml
Traceback (most recent call last):
  File "/home/zhuhe/.conda/envs/diffhpe/lib/python3.9/site-packages/wandb/apis/normalize.py", line 41, in wrapper
    return func(*args, **kwargs)
  File "/home/zhuhe/.conda/envs/diffhpe/lib/python3.9/site-packages/wandb/sdk/lib/retry.py", line 212, in wrapped_fn
    return retrier(*args, **kargs)
  File "/home/zhuhe/.conda/envs/diffhpe/lib/python3.9/site-packages/wandb/sdk/lib/retry.py", line 131, in __call__
    result = self._call_fn(*args, **kwargs)
  File "/home/zhuhe/.conda/envs/diffhpe/lib/python3.9/site-packages/wandb/sdk/internal/internal_api.py", line 2218, in upload_file
    wandb._sentry.reraise(e)
  File "/home/zhuhe/.conda/envs/diffhpe/lib/python3.9/site-packages/wandb/analytics/sentry.py", line 146, in reraise
    raise exc.with_traceback(sys.exc_info()[2])
  File "/home/zhuhe/.conda/envs/diffhpe/lib/python3.9/site-packages/wandb/sdk/internal/internal_api.py", line 2190, in upload_file
    response.raise_for_status()
  File "/home/zhuhe/.conda/envs/diffhpe/lib/python3.9/site-packages/requests/models.py", line 1021, in raise_for_status
    raise HTTPError(http_error_msg, response=self)
requests.exceptions.HTTPError: 404 Client Error: Not Found for url: https://storage.googleapis.com/wandb-production.appspot.com/ada4321/uncategorized/mqgir0zw/conda-environment.yaml?Expires=1689057661&GoogleAccessId=gorilla-files-url-signer-man%40wandb-production.iam.gserviceaccount.com&Signature=IeMDm1JDRrCOd5ana6Bs9GDmcnEfjpgrLeyJ0gr5DefXwWJAybgP7AkDCg8U4cHwha0F9VGzw7h0HKq24nciscIDKFWQdv4Uq3i%2BmU%2FMel04vdl56AVOulgTyD%2BAaaz63aGXT1ZkahqYm3cgFlFO1RrFrs9QzxWpCw3j4%2FuAunx7uJHTkOMejJobyc37wzL1PO7tE%2Bs7J4GG2a3xoETWIO5pa1p7GkI4JKCrjjnaO3Y2TD1RNxLhEiuyPOfFKBpV9WQScRSZoh0RIIZI8ACEvg5FJcM34N3SjKd5Roi5oeCEXlwgy2C%2FuDRPRS%2BozUL3ljKGf7YEpvsZTClEdf23Cg%3D%3D

During handling of the above exception, another exception occurred:

Traceback (most recent call last):
  File "/home/zhuhe/.conda/envs/diffhpe/lib/python3.9/site-packages/wandb/filesync/upload_job.py", line 127, in push
    self._api.upload_file_retry(
  File "/home/zhuhe/.conda/envs/diffhpe/lib/python3.9/site-packages/wandb/apis/normalize.py", line 51, in wrapper
    raise CommError(message, error)
wandb.errors.CommError: <Response [404]>
2023-07-10 14:41:02,497 ERROR   wandb-upload_2:29778 [upload_job.py:push():136] Failed to upload file: /home/zhuhe/HPE-with-Diffusion/wandb/run-20230710_144055-mqgir0zw/files/wandb-summary.json
Traceback (most recent call last):
  File "/home/zhuhe/.conda/envs/diffhpe/lib/python3.9/site-packages/wandb/apis/normalize.py", line 41, in wrapper
    return func(*args, **kwargs)
  File "/home/zhuhe/.conda/envs/diffhpe/lib/python3.9/site-packages/wandb/sdk/lib/retry.py", line 212, in wrapped_fn
    return retrier(*args, **kargs)
  File "/home/zhuhe/.conda/envs/diffhpe/lib/python3.9/site-packages/wandb/sdk/lib/retry.py", line 131, in __call__
    result = self._call_fn(*args, **kwargs)
  File "/home/zhuhe/.conda/envs/diffhpe/lib/python3.9/site-packages/wandb/sdk/internal/internal_api.py", line 2218, in upload_file
    wandb._sentry.reraise(e)
  File "/home/zhuhe/.conda/envs/diffhpe/lib/python3.9/site-packages/wandb/analytics/sentry.py", line 146, in reraise
    raise exc.with_traceback(sys.exc_info()[2])
  File "/home/zhuhe/.conda/envs/diffhpe/lib/python3.9/site-packages/wandb/sdk/internal/internal_api.py", line 2190, in upload_file
    response.raise_for_status()
  File "/home/zhuhe/.conda/envs/diffhpe/lib/python3.9/site-packages/requests/models.py", line 1021, in raise_for_status
    raise HTTPError(http_error_msg, response=self)
requests.exceptions.HTTPError: 404 Client Error: Not Found for url: https://storage.googleapis.com/wandb-production.appspot.com/ada4321/uncategorized/mqgir0zw/wandb-summary.json?Expires=1689057661&GoogleAccessId=gorilla-files-url-signer-man%40wandb-production.iam.gserviceaccount.com&Signature=gD11Ui3HrVcGzP3sQTdJ9S1JHGbXHC8ZYLgX7UH51sAr1t51Qhl0MIumrh9%2BDNDvuqUVrZZJ9CXOu1Qb8pgNwQJnQ2ujMCOzEyL%2F4HGV4eJEvC2tVKpHynLDNMXpbMb4d6SxMGisUDJGflHtMoknInnhR5iK5PiYgMYLumsR6v9NCcFDWq3lFGQdTAsTfLEYyrOKYhfe0PneQp049OeTjUmnfL%2Ba%2FltUKnD0%2FpzfC0OLeMJARf7oQZFCnqVfF6iDporhEOW325xtsT9rOUB1CXiKDLmB8d%2BF3m6gFvx0IOL9xUt6p6gElD0txWLL1eROxeNbp3%2FfyM5zmItGTO0zhg%3D%3D

During handling of the above exception, another exception occurred:

Traceback (most recent call last):
  File "/home/zhuhe/.conda/envs/diffhpe/lib/python3.9/site-packages/wandb/filesync/upload_job.py", line 127, in push
    self._api.upload_file_retry(
  File "/home/zhuhe/.conda/envs/diffhpe/lib/python3.9/site-packages/wandb/apis/normalize.py", line 51, in wrapper
    raise CommError(message, error)
wandb.errors.CommError: <Response [404]>
2023-07-10 14:41:03,432 DEBUG   HandlerThread:29778 [handler.py:handle_request():144] handle_request: keepalive
2023-07-10 14:41:03,553 ERROR   Thread-11 :29778 [step_upload.py:_handle_event():200] Failed to upload file: /home/zhuhe/HPE-with-Diffusion/wandb/run-20230710_144055-mqgir0zw/files/requirements.txt
Traceback (most recent call last):
  File "/home/zhuhe/.conda/envs/diffhpe/lib/python3.9/site-packages/wandb/apis/normalize.py", line 41, in wrapper
    return func(*args, **kwargs)
  File "/home/zhuhe/.conda/envs/diffhpe/lib/python3.9/site-packages/wandb/sdk/lib/retry.py", line 212, in wrapped_fn
    return retrier(*args, **kargs)
  File "/home/zhuhe/.conda/envs/diffhpe/lib/python3.9/site-packages/wandb/sdk/lib/retry.py", line 131, in __call__
    result = self._call_fn(*args, **kwargs)
  File "/home/zhuhe/.conda/envs/diffhpe/lib/python3.9/site-packages/wandb/sdk/internal/internal_api.py", line 2218, in upload_file
    wandb._sentry.reraise(e)
  File "/home/zhuhe/.conda/envs/diffhpe/lib/python3.9/site-packages/wandb/analytics/sentry.py", line 146, in reraise
    raise exc.with_traceback(sys.exc_info()[2])
  File "/home/zhuhe/.conda/envs/diffhpe/lib/python3.9/site-packages/wandb/sdk/internal/internal_api.py", line 2190, in upload_file
    response.raise_for_status()
  File "/home/zhuhe/.conda/envs/diffhpe/lib/python3.9/site-packages/requests/models.py", line 1021, in raise_for_status
    raise HTTPError(http_error_msg, response=self)
requests.exceptions.HTTPError: 404 Client Error: Not Found for url: https://storage.googleapis.com/wandb-production.appspot.com/ada4321/uncategorized/mqgir0zw/requirements.txt?Expires=1689057661&GoogleAccessId=gorilla-files-url-signer-man%40wandb-production.iam.gserviceaccount.com&Signature=dqklbw%2BtOSWXGyYPKcI1u2bdJLJ%2BAwcsH9QGPn9e45dynS214y3dWthq9%2B3K%2BX5C4hdjPGgIt8UbspmilAIpu9EAzsn1x6qZaDtF2APmpEg6mE4oomz%2BgsnxzX1QwUjkhtPc%2BihoI5EQaG4Lxo%2FFY4uloIrL8uMSBLBzxYrhsbTC6ZxMFhuLb17sbP3FE6B3HGWAM4CJH30ss5fuIlXDuY1BzPTsFx7x98omzIZ%2F9gPktH8a7bH5xMvXmEL1b67aa0Bo76B9uxbR9cOy965QjDD3%2FPk8cMN%2BQNbjZDUVu20tJDqdvMyVs7dw1gv%2BpC%2B9v30mLmRREwxz9GkY8DOO0w%3D%3D

During handling of the above exception, another exception occurred:

Traceback (most recent call last):
  File "/home/zhuhe/.conda/envs/diffhpe/lib/python3.9/concurrent/futures/thread.py", line 58, in run
    result = self.fn(*self.args, **self.kwargs)
  File "/home/zhuhe/.conda/envs/diffhpe/lib/python3.9/site-packages/wandb/filesync/step_upload.py", line 288, in run_and_notify
    self._do_upload_sync(event)
  File "/home/zhuhe/.conda/envs/diffhpe/lib/python3.9/site-packages/wandb/filesync/step_upload.py", line 330, in _do_upload_sync
    job.run()
  File "/home/zhuhe/.conda/envs/diffhpe/lib/python3.9/site-packages/wandb/filesync/upload_job.py", line 57, in run
    self.push()
  File "/home/zhuhe/.conda/envs/diffhpe/lib/python3.9/site-packages/wandb/filesync/upload_job.py", line 127, in push
    self._api.upload_file_retry(
  File "/home/zhuhe/.conda/envs/diffhpe/lib/python3.9/site-packages/wandb/apis/normalize.py", line 51, in wrapper
    raise CommError(message, error)
wandb.errors.CommError: <Response [404]>
2023-07-10 14:41:03,553 ERROR   Thread-11 :29778 [step_upload.py:_handle_event():200] Failed to upload file: /home/zhuhe/HPE-with-Diffusion/wandb/run-20230710_144055-mqgir0zw/files/config.yaml
Traceback (most recent call last):
  File "/home/zhuhe/.conda/envs/diffhpe/lib/python3.9/site-packages/wandb/apis/normalize.py", line 41, in wrapper
    return func(*args, **kwargs)
  File "/home/zhuhe/.conda/envs/diffhpe/lib/python3.9/site-packages/wandb/sdk/lib/retry.py", line 212, in wrapped_fn
    return retrier(*args, **kargs)
  File "/home/zhuhe/.conda/envs/diffhpe/lib/python3.9/site-packages/wandb/sdk/lib/retry.py", line 131, in __call__
    result = self._call_fn(*args, **kwargs)
  File "/home/zhuhe/.conda/envs/diffhpe/lib/python3.9/site-packages/wandb/sdk/internal/internal_api.py", line 2218, in upload_file
    wandb._sentry.reraise(e)
  File "/home/zhuhe/.conda/envs/diffhpe/lib/python3.9/site-packages/wandb/analytics/sentry.py", line 146, in reraise
    raise exc.with_traceback(sys.exc_info()[2])
  File "/home/zhuhe/.conda/envs/diffhpe/lib/python3.9/site-packages/wandb/sdk/internal/internal_api.py", line 2190, in upload_file
    response.raise_for_status()
  File "/home/zhuhe/.conda/envs/diffhpe/lib/python3.9/site-packages/requests/models.py", line 1021, in raise_for_status
    raise HTTPError(http_error_msg, response=self)
requests.exceptions.HTTPError: 404 Client Error: Not Found for url: https://storage.googleapis.com/wandb-production.appspot.com/ada4321/uncategorized/mqgir0zw/config.yaml?Expires=1689057661&GoogleAccessId=gorilla-files-url-signer-man%40wandb-production.iam.gserviceaccount.com&Signature=JXSBHjTTiDPXej2a9wWIJsb5ZFKhkro%2BqZpXdB7v15n2QXvs0bedUQJ8PnPvsYlbQfHVV87mXqMZgVZ4ZmNJBOhM51dCWZjD6%2FLo6VmfdNw%2FlB6Q54fUOcVT324BdVcLqiKDTcOWiQfU5KgCoAwpxh24dC2w%2B5anbv791wSYzKYrZnTr0sSRQ0yKwwgWZpM4W%2Brcrg2lmEfedQRgTtgKtm5nwzYQcpzeV4VEtdOD%2BYU5PU1ZP86ZqUVx8iOlh3ZI0TNqX8sm40S0c%2F1YFawDvcKS%2BPAxExtccyL0wj01PKPQ13rjQxRYcCh%2FTVIU5FnylyF3KfEbnLbCaif%2BF2im0w%3D%3D

During handling of the above exception, another exception occurred:

Traceback (most recent call last):
  File "/home/zhuhe/.conda/envs/diffhpe/lib/python3.9/concurrent/futures/thread.py", line 58, in run
    result = self.fn(*self.args, **self.kwargs)
  File "/home/zhuhe/.conda/envs/diffhpe/lib/python3.9/site-packages/wandb/filesync/step_upload.py", line 288, in run_and_notify
    self._do_upload_sync(event)
  File "/home/zhuhe/.conda/envs/diffhpe/lib/python3.9/site-packages/wandb/filesync/step_upload.py", line 330, in _do_upload_sync
    job.run()
  File "/home/zhuhe/.conda/envs/diffhpe/lib/python3.9/site-packages/wandb/filesync/upload_job.py", line 57, in run
    self.push()
  File "/home/zhuhe/.conda/envs/diffhpe/lib/python3.9/site-packages/wandb/filesync/upload_job.py", line 127, in push
    self._api.upload_file_retry(
  File "/home/zhuhe/.conda/envs/diffhpe/lib/python3.9/site-packages/wandb/apis/normalize.py", line 51, in wrapper
    raise CommError(message, error)
wandb.errors.CommError: <Response [404]>
2023-07-10 14:41:03,553 ERROR   Thread-11 :29778 [step_upload.py:_handle_event():200] Failed to upload file: /home/zhuhe/HPE-with-Diffusion/wandb/run-20230710_144055-mqgir0zw/files/output.log
Traceback (most recent call last):
  File "/home/zhuhe/.conda/envs/diffhpe/lib/python3.9/site-packages/wandb/apis/normalize.py", line 41, in wrapper
    return func(*args, **kwargs)
  File "/home/zhuhe/.conda/envs/diffhpe/lib/python3.9/site-packages/wandb/sdk/lib/retry.py", line 212, in wrapped_fn
    return retrier(*args, **kargs)
  File "/home/zhuhe/.conda/envs/diffhpe/lib/python3.9/site-packages/wandb/sdk/lib/retry.py", line 131, in __call__
    result = self._call_fn(*args, **kwargs)
  File "/home/zhuhe/.conda/envs/diffhpe/lib/python3.9/site-packages/wandb/sdk/internal/internal_api.py", line 2218, in upload_file
    wandb._sentry.reraise(e)
  File "/home/zhuhe/.conda/envs/diffhpe/lib/python3.9/site-packages/wandb/analytics/sentry.py", line 146, in reraise
    raise exc.with_traceback(sys.exc_info()[2])
  File "/home/zhuhe/.conda/envs/diffhpe/lib/python3.9/site-packages/wandb/sdk/internal/internal_api.py", line 2190, in upload_file
    response.raise_for_status()
  File "/home/zhuhe/.conda/envs/diffhpe/lib/python3.9/site-packages/requests/models.py", line 1021, in raise_for_status
    raise HTTPError(http_error_msg, response=self)
requests.exceptions.HTTPError: 404 Client Error: Not Found for url: https://storage.googleapis.com/wandb-production.appspot.com/ada4321/uncategorized/mqgir0zw/output.log?Expires=1689057661&GoogleAccessId=gorilla-files-url-signer-man%40wandb-production.iam.gserviceaccount.com&Signature=b2pVyxM85FI2ccsN2eWdzZ0IE38%2B8Cx8LU2MaBm%2BH%2FHbmvLt62jUjVL3Kq%2BZBfJySSZqxGxdtABZZUsIXjMFcNP97wtKUCixUvQWEIESGW4Exgf5k7zS94R2kuwpiAEjRhzUk45WiG7or3wRCDS6felwz2Q9TQl0D8CBo3MsrzfeDFbgOZAN8zak07HF0SIEN2uytOmnATnERMuxc9UnDDL6orcAIra8cTbj3wWe7zDzXk7aqk%2FP9lKLV%2B8fFvIJysEPgcQDId529Rh6pNG3P8lwnBc7bqhCtEYhpbStY%2FlTwkmoScT3WAtm3ubfBEzm6TfBOnOMvk%2FERdH%2FiYE%2Fjg%3D%3D

During handling of the above exception, another exception occurred:

Traceback (most recent call last):
  File "/home/zhuhe/.conda/envs/diffhpe/lib/python3.9/concurrent/futures/thread.py", line 58, in run
    result = self.fn(*self.args, **self.kwargs)
  File "/home/zhuhe/.conda/envs/diffhpe/lib/python3.9/site-packages/wandb/filesync/step_upload.py", line 288, in run_and_notify
    self._do_upload_sync(event)
  File "/home/zhuhe/.conda/envs/diffhpe/lib/python3.9/site-packages/wandb/filesync/step_upload.py", line 330, in _do_upload_sync
    job.run()
  File "/home/zhuhe/.conda/envs/diffhpe/lib/python3.9/site-packages/wandb/filesync/upload_job.py", line 57, in run
    self.push()
  File "/home/zhuhe/.conda/envs/diffhpe/lib/python3.9/site-packages/wandb/filesync/upload_job.py", line 127, in push
    self._api.upload_file_retry(
  File "/home/zhuhe/.conda/envs/diffhpe/lib/python3.9/site-packages/wandb/apis/normalize.py", line 51, in wrapper
    raise CommError(message, error)
wandb.errors.CommError: <Response [404]>
2023-07-10 14:41:03,554 ERROR   Thread-11 :29778 [step_upload.py:_handle_event():200] Failed to upload file: /home/zhuhe/HPE-with-Diffusion/wandb/run-20230710_144055-mqgir0zw/files/conda-environment.yaml
Traceback (most recent call last):
  File "/home/zhuhe/.conda/envs/diffhpe/lib/python3.9/site-packages/wandb/apis/normalize.py", line 41, in wrapper
    return func(*args, **kwargs)
  File "/home/zhuhe/.conda/envs/diffhpe/lib/python3.9/site-packages/wandb/sdk/lib/retry.py", line 212, in wrapped_fn
    return retrier(*args, **kargs)
  File "/home/zhuhe/.conda/envs/diffhpe/lib/python3.9/site-packages/wandb/sdk/lib/retry.py", line 131, in __call__
    result = self._call_fn(*args, **kwargs)
  File "/home/zhuhe/.conda/envs/diffhpe/lib/python3.9/site-packages/wandb/sdk/internal/internal_api.py", line 2218, in upload_file
    wandb._sentry.reraise(e)
  File "/home/zhuhe/.conda/envs/diffhpe/lib/python3.9/site-packages/wandb/analytics/sentry.py", line 146, in reraise
    raise exc.with_traceback(sys.exc_info()[2])
  File "/home/zhuhe/.conda/envs/diffhpe/lib/python3.9/site-packages/wandb/sdk/internal/internal_api.py", line 2190, in upload_file
    response.raise_for_status()
  File "/home/zhuhe/.conda/envs/diffhpe/lib/python3.9/site-packages/requests/models.py", line 1021, in raise_for_status
    raise HTTPError(http_error_msg, response=self)
requests.exceptions.HTTPError: 404 Client Error: Not Found for url: https://storage.googleapis.com/wandb-production.appspot.com/ada4321/uncategorized/mqgir0zw/conda-environment.yaml?Expires=1689057661&GoogleAccessId=gorilla-files-url-signer-man%40wandb-production.iam.gserviceaccount.com&Signature=IeMDm1JDRrCOd5ana6Bs9GDmcnEfjpgrLeyJ0gr5DefXwWJAybgP7AkDCg8U4cHwha0F9VGzw7h0HKq24nciscIDKFWQdv4Uq3i%2BmU%2FMel04vdl56AVOulgTyD%2BAaaz63aGXT1ZkahqYm3cgFlFO1RrFrs9QzxWpCw3j4%2FuAunx7uJHTkOMejJobyc37wzL1PO7tE%2Bs7J4GG2a3xoETWIO5pa1p7GkI4JKCrjjnaO3Y2TD1RNxLhEiuyPOfFKBpV9WQScRSZoh0RIIZI8ACEvg5FJcM34N3SjKd5Roi5oeCEXlwgy2C%2FuDRPRS%2BozUL3ljKGf7YEpvsZTClEdf23Cg%3D%3D

During handling of the above exception, another exception occurred:

Traceback (most recent call last):
  File "/home/zhuhe/.conda/envs/diffhpe/lib/python3.9/concurrent/futures/thread.py", line 58, in run
    result = self.fn(*self.args, **self.kwargs)
  File "/home/zhuhe/.conda/envs/diffhpe/lib/python3.9/site-packages/wandb/filesync/step_upload.py", line 288, in run_and_notify
    self._do_upload_sync(event)
  File "/home/zhuhe/.conda/envs/diffhpe/lib/python3.9/site-packages/wandb/filesync/step_upload.py", line 330, in _do_upload_sync
    job.run()
  File "/home/zhuhe/.conda/envs/diffhpe/lib/python3.9/site-packages/wandb/filesync/upload_job.py", line 57, in run
    self.push()
  File "/home/zhuhe/.conda/envs/diffhpe/lib/python3.9/site-packages/wandb/filesync/upload_job.py", line 127, in push
    self._api.upload_file_retry(
  File "/home/zhuhe/.conda/envs/diffhpe/lib/python3.9/site-packages/wandb/apis/normalize.py", line 51, in wrapper
    raise CommError(message, error)
wandb.errors.CommError: <Response [404]>
2023-07-10 14:41:03,554 ERROR   Thread-11 :29778 [step_upload.py:_handle_event():200] Failed to upload file: /home/zhuhe/HPE-with-Diffusion/wandb/run-20230710_144055-mqgir0zw/files/wandb-summary.json
Traceback (most recent call last):
  File "/home/zhuhe/.conda/envs/diffhpe/lib/python3.9/site-packages/wandb/apis/normalize.py", line 41, in wrapper
    return func(*args, **kwargs)
  File "/home/zhuhe/.conda/envs/diffhpe/lib/python3.9/site-packages/wandb/sdk/lib/retry.py", line 212, in wrapped_fn
    return retrier(*args, **kargs)
  File "/home/zhuhe/.conda/envs/diffhpe/lib/python3.9/site-packages/wandb/sdk/lib/retry.py", line 131, in __call__
    result = self._call_fn(*args, **kwargs)
  File "/home/zhuhe/.conda/envs/diffhpe/lib/python3.9/site-packages/wandb/sdk/internal/internal_api.py", line 2218, in upload_file
    wandb._sentry.reraise(e)
  File "/home/zhuhe/.conda/envs/diffhpe/lib/python3.9/site-packages/wandb/analytics/sentry.py", line 146, in reraise
    raise exc.with_traceback(sys.exc_info()[2])
  File "/home/zhuhe/.conda/envs/diffhpe/lib/python3.9/site-packages/wandb/sdk/internal/internal_api.py", line 2190, in upload_file
    response.raise_for_status()
  File "/home/zhuhe/.conda/envs/diffhpe/lib/python3.9/site-packages/requests/models.py", line 1021, in raise_for_status
    raise HTTPError(http_error_msg, response=self)
requests.exceptions.HTTPError: 404 Client Error: Not Found for url: https://storage.googleapis.com/wandb-production.appspot.com/ada4321/uncategorized/mqgir0zw/wandb-summary.json?Expires=1689057661&GoogleAccessId=gorilla-files-url-signer-man%40wandb-production.iam.gserviceaccount.com&Signature=gD11Ui3HrVcGzP3sQTdJ9S1JHGbXHC8ZYLgX7UH51sAr1t51Qhl0MIumrh9%2BDNDvuqUVrZZJ9CXOu1Qb8pgNwQJnQ2ujMCOzEyL%2F4HGV4eJEvC2tVKpHynLDNMXpbMb4d6SxMGisUDJGflHtMoknInnhR5iK5PiYgMYLumsR6v9NCcFDWq3lFGQdTAsTfLEYyrOKYhfe0PneQp049OeTjUmnfL%2Ba%2FltUKnD0%2FpzfC0OLeMJARf7oQZFCnqVfF6iDporhEOW325xtsT9rOUB1CXiKDLmB8d%2BF3m6gFvx0IOL9xUt6p6gElD0txWLL1eROxeNbp3%2FfyM5zmItGTO0zhg%3D%3D

During handling of the above exception, another exception occurred:

Traceback (most recent call last):
  File "/home/zhuhe/.conda/envs/diffhpe/lib/python3.9/concurrent/futures/thread.py", line 58, in run
    result = self.fn(*self.args, **self.kwargs)
  File "/home/zhuhe/.conda/envs/diffhpe/lib/python3.9/site-packages/wandb/filesync/step_upload.py", line 288, in run_and_notify
    self._do_upload_sync(event)
  File "/home/zhuhe/.conda/envs/diffhpe/lib/python3.9/site-packages/wandb/filesync/step_upload.py", line 330, in _do_upload_sync
    job.run()
  File "/home/zhuhe/.conda/envs/diffhpe/lib/python3.9/site-packages/wandb/filesync/upload_job.py", line 57, in run
    self.push()
  File "/home/zhuhe/.conda/envs/diffhpe/lib/python3.9/site-packages/wandb/filesync/upload_job.py", line 127, in push
    self._api.upload_file_retry(
  File "/home/zhuhe/.conda/envs/diffhpe/lib/python3.9/site-packages/wandb/apis/normalize.py", line 51, in wrapper
    raise CommError(message, error)
wandb.errors.CommError: <Response [404]>
2023-07-10 14:41:03,754 INFO    Thread-11 :29778 [sender.py:transition_state():602] send defer: 11
2023-07-10 14:41:03,754 DEBUG   HandlerThread:29778 [handler.py:handle_request():144] handle_request: defer
2023-07-10 14:41:03,754 INFO    HandlerThread:29778 [handler.py:handle_request_defer():170] handle defer: 11
2023-07-10 14:41:03,755 DEBUG   SenderThread:29778 [sender.py:send_request():396] send_request: defer
2023-07-10 14:41:03,755 INFO    SenderThread:29778 [sender.py:send_request_defer():598] handle sender defer: 11
2023-07-10 14:41:03,755 INFO    SenderThread:29778 [file_pusher.py:join():164] waiting for file pusher
2023-07-10 14:41:03,755 INFO    SenderThread:29778 [sender.py:transition_state():602] send defer: 12
2023-07-10 14:41:03,755 DEBUG   HandlerThread:29778 [handler.py:handle_request():144] handle_request: defer
2023-07-10 14:41:03,755 INFO    HandlerThread:29778 [handler.py:handle_request_defer():170] handle defer: 12
2023-07-10 14:41:03,755 DEBUG   SenderThread:29778 [sender.py:send_request():396] send_request: defer
2023-07-10 14:41:03,755 INFO    SenderThread:29778 [sender.py:send_request_defer():598] handle sender defer: 12
2023-07-10 14:41:04,003 INFO    SenderThread:29778 [sender.py:transition_state():602] send defer: 13
2023-07-10 14:41:04,003 DEBUG   HandlerThread:29778 [handler.py:handle_request():144] handle_request: defer
2023-07-10 14:41:04,003 INFO    HandlerThread:29778 [handler.py:handle_request_defer():170] handle defer: 13
2023-07-10 14:41:04,003 DEBUG   SenderThread:29778 [sender.py:send_request():396] send_request: defer
2023-07-10 14:41:04,003 INFO    SenderThread:29778 [sender.py:send_request_defer():598] handle sender defer: 13
2023-07-10 14:41:04,003 INFO    SenderThread:29778 [sender.py:transition_state():602] send defer: 14
2023-07-10 14:41:04,003 DEBUG   HandlerThread:29778 [handler.py:handle_request():144] handle_request: defer
2023-07-10 14:41:04,003 INFO    HandlerThread:29778 [handler.py:handle_request_defer():170] handle defer: 14
2023-07-10 14:41:04,003 DEBUG   SenderThread:29778 [sender.py:send():369] send: final
2023-07-10 14:41:04,004 DEBUG   SenderThread:29778 [sender.py:send():369] send: footer
2023-07-10 14:41:04,004 DEBUG   SenderThread:29778 [sender.py:send_request():396] send_request: defer
2023-07-10 14:41:04,004 INFO    SenderThread:29778 [sender.py:send_request_defer():598] handle sender defer: 14
2023-07-10 14:41:04,004 DEBUG   HandlerThread:29778 [handler.py:handle_request():144] handle_request: poll_exit
2023-07-10 14:41:04,004 DEBUG   HandlerThread:29778 [handler.py:handle_request():144] handle_request: server_info
2023-07-10 14:41:04,004 DEBUG   HandlerThread:29778 [handler.py:handle_request():144] handle_request: get_summary
2023-07-10 14:41:04,004 DEBUG   SenderThread:29778 [sender.py:send_request():396] send_request: poll_exit
2023-07-10 14:41:04,005 DEBUG   SenderThread:29778 [sender.py:send_request():396] send_request: server_info
2023-07-10 14:41:04,006 DEBUG   HandlerThread:29778 [handler.py:handle_request():144] handle_request: sampled_history
2023-07-10 14:41:04,477 INFO    MainThread:29778 [wandb_run.py:_footer_history_summary_info():3467] rendering history
2023-07-10 14:41:04,478 INFO    MainThread:29778 [wandb_run.py:_footer_history_summary_info():3499] rendering summary
2023-07-10 14:41:04,478 INFO    MainThread:29778 [wandb_run.py:_footer_sync_info():3426] logging synced files
2023-07-10 14:41:04,478 DEBUG   HandlerThread:29778 [handler.py:handle_request():144] handle_request: shutdown
2023-07-10 14:41:04,478 INFO    HandlerThread:29778 [handler.py:finish():854] shutting down handler
2023-07-10 14:41:05,005 INFO    WriterThread:29778 [datastore.py:close():298] close: /home/zhuhe/HPE-with-Diffusion/wandb/run-20230710_144055-mqgir0zw/run-mqgir0zw.wandb
2023-07-10 14:41:05,477 INFO    SenderThread:29778 [sender.py:finish():1526] shutting down sender
2023-07-10 14:41:05,477 INFO    SenderThread:29778 [file_pusher.py:finish():159] shutting down file pusher
2023-07-10 14:41:05,478 INFO    SenderThread:29778 [file_pusher.py:join():164] waiting for file pusher
