2023-07-10 14:59:04,225 INFO    StreamThr :33349 [internal.py:wandb_internal():86] W&B internal server running at pid: 33349, started at: 2023-07-10 14:59:04.225120
2023-07-10 14:59:04,226 DEBUG   HandlerThread:33349 [handler.py:handle_request():144] handle_request: status
2023-07-10 14:59:04,228 INFO    WriterThread:33349 [datastore.py:open_for_write():85] open: /home/zhuhe/HPE-with-Diffusion/wandb/run-20230710_145904-uerlbknf/run-uerlbknf.wandb
2023-07-10 14:59:04,229 DEBUG   SenderThread:33349 [sender.py:send():369] send: header
2023-07-10 14:59:04,229 DEBUG   SenderThread:33349 [sender.py:send():369] send: run
2023-07-10 14:59:05,191 INFO    SenderThread:33349 [dir_watcher.py:__init__():211] watching files in: /home/zhuhe/HPE-with-Diffusion/wandb/run-20230710_145904-uerlbknf/files
2023-07-10 14:59:05,191 INFO    SenderThread:33349 [sender.py:_start_run_threads():1100] run started: uerlbknf with start time 1688972344.224884
2023-07-10 14:59:05,191 DEBUG   SenderThread:33349 [sender.py:send_request():396] send_request: summary_record
2023-07-10 14:59:05,191 INFO    SenderThread:33349 [sender.py:_save_file():1354] saving file wandb-summary.json with policy end
2023-07-10 14:59:05,194 DEBUG   HandlerThread:33349 [handler.py:handle_request():144] handle_request: check_version
2023-07-10 14:59:05,194 DEBUG   SenderThread:33349 [sender.py:send_request():396] send_request: check_version
2023-07-10 14:59:05,377 DEBUG   HandlerThread:33349 [handler.py:handle_request():144] handle_request: run_start
2023-07-10 14:59:05,383 DEBUG   HandlerThread:33349 [system_info.py:__init__():31] System info init
2023-07-10 14:59:05,383 DEBUG   HandlerThread:33349 [system_info.py:__init__():46] System info init done
2023-07-10 14:59:05,383 INFO    HandlerThread:33349 [system_monitor.py:start():181] Starting system monitor
2023-07-10 14:59:05,384 INFO    SystemMonitor:33349 [system_monitor.py:_start():145] Starting system asset monitoring threads
2023-07-10 14:59:05,384 INFO    HandlerThread:33349 [system_monitor.py:probe():201] Collecting system info
2023-07-10 14:59:05,384 INFO    SystemMonitor:33349 [interfaces.py:start():190] Started cpu monitoring
2023-07-10 14:59:05,384 INFO    SystemMonitor:33349 [interfaces.py:start():190] Started disk monitoring
2023-07-10 14:59:05,385 INFO    SystemMonitor:33349 [interfaces.py:start():190] Started gpu monitoring
2023-07-10 14:59:05,385 INFO    SystemMonitor:33349 [interfaces.py:start():190] Started memory monitoring
2023-07-10 14:59:05,385 INFO    SystemMonitor:33349 [interfaces.py:start():190] Started network monitoring
2023-07-10 14:59:05,400 DEBUG   HandlerThread:33349 [system_info.py:probe():195] Probing system
2023-07-10 14:59:05,403 DEBUG   HandlerThread:33349 [gitlib.py:_init_repo():53] git repository is invalid
2023-07-10 14:59:05,403 DEBUG   HandlerThread:33349 [system_info.py:probe():240] Probing system done
2023-07-10 14:59:05,403 DEBUG   HandlerThread:33349 [system_monitor.py:probe():210] {'os': 'Linux-5.19.0-46-generic-x86_64-with-glibc2.35', 'python': '3.9.16', 'heartbeatAt': '2023-07-10T06:59:05.400460', 'startedAt': '2023-07-10T06:59:04.221125', 'docker': None, 'cuda': None, 'args': ('--phase', 'train', '--gpu_ids', '1'), 'state': 'running', 'program': '/home/zhuhe/HPE-with-Diffusion/main.py', 'codePath': 'main.py', 'host': '415-2', 'username': 'zhuhe', 'executable': '/home/zhuhe/.conda/envs/diffhpe/bin/python', 'cpu_count': 16, 'cpu_count_logical': 24, 'cpu_freq': {'current': 4519.546208333334, 'min': 800.0, 'max': 4783.333333333333}, 'cpu_freq_per_core': [{'current': 5056.437, 'min': 800.0, 'max': 5100.0}, {'current': 4955.279, 'min': 800.0, 'max': 5100.0}, {'current': 5100.0, 'min': 800.0, 'max': 5100.0}, {'current': 5100.0, 'min': 800.0, 'max': 5100.0}, {'current': 5073.332, 'min': 800.0, 'max': 5100.0}, {'current': 4638.604, 'min': 800.0, 'max': 5100.0}, {'current': 5100.0, 'min': 800.0, 'max': 5100.0}, {'current': 4880.847, 'min': 800.0, 'max': 5100.0}, {'current': 5099.987, 'min': 800.0, 'max': 5200.0}, {'current': 5100.0, 'min': 800.0, 'max': 5200.0}, {'current': 5100.0, 'min': 800.0, 'max': 5200.0}, {'current': 2100.0, 'min': 800.0, 'max': 5200.0}, {'current': 5100.0, 'min': 800.0, 'max': 5100.0}, {'current': 5100.0, 'min': 800.0, 'max': 5100.0}, {'current': 5080.178, 'min': 800.0, 'max': 5100.0}, {'current': 5068.141, 'min': 800.0, 'max': 5100.0}, {'current': 3852.171, 'min': 800.0, 'max': 4100.0}, {'current': 3852.003, 'min': 800.0, 'max': 4100.0}, {'current': 3851.943, 'min': 800.0, 'max': 4100.0}, {'current': 3852.027, 'min': 800.0, 'max': 4100.0}, {'current': 3852.0, 'min': 800.0, 'max': 4100.0}, {'current': 3852.255, 'min': 800.0, 'max': 4100.0}, {'current': 3852.063, 'min': 800.0, 'max': 4100.0}, {'current': 3851.842, 'min': 800.0, 'max': 4100.0}], 'disk': {'total': 93.31179428100586, 'used': 0.017879486083984375}, 'gpu': 'NVIDIA GeForce RTX 3090', 'gpu_count': 2, 'gpu_devices': [{'name': 'NVIDIA GeForce RTX 3090', 'memory_total': 25769803776}, {'name': 'NVIDIA GeForce RTX 3090', 'memory_total': 25769803776}], 'memory': {'total': 31.185562133789062}}
2023-07-10 14:59:05,403 INFO    HandlerThread:33349 [system_monitor.py:probe():211] Finished collecting system info
2023-07-10 14:59:05,403 INFO    HandlerThread:33349 [system_monitor.py:probe():214] Publishing system info
2023-07-10 14:59:05,403 DEBUG   HandlerThread:33349 [system_info.py:_save_pip():51] Saving list of pip packages installed into the current environment
2023-07-10 14:59:05,403 DEBUG   HandlerThread:33349 [system_info.py:_save_pip():67] Saving pip packages done
2023-07-10 14:59:05,403 DEBUG   HandlerThread:33349 [system_info.py:_save_conda():74] Saving list of conda packages installed into the current environment
2023-07-10 14:59:06,165 DEBUG   HandlerThread:33349 [system_info.py:_save_conda():86] Saving conda packages done
2023-07-10 14:59:06,166 INFO    HandlerThread:33349 [system_monitor.py:probe():216] Finished publishing system info
2023-07-10 14:59:06,168 DEBUG   SenderThread:33349 [sender.py:send():369] send: files
2023-07-10 14:59:06,168 INFO    SenderThread:33349 [sender.py:_save_file():1354] saving file wandb-metadata.json with policy now
2023-07-10 14:59:06,172 DEBUG   HandlerThread:33349 [handler.py:handle_request():144] handle_request: stop_status
2023-07-10 14:59:06,172 DEBUG   SenderThread:33349 [sender.py:send_request():396] send_request: stop_status
2023-07-10 14:59:06,192 INFO    Thread-12 :33349 [dir_watcher.py:_on_file_created():272] file/dir created: /home/zhuhe/HPE-with-Diffusion/wandb/run-20230710_145904-uerlbknf/files/wandb-summary.json
2023-07-10 14:59:06,192 INFO    Thread-12 :33349 [dir_watcher.py:_on_file_created():272] file/dir created: /home/zhuhe/HPE-with-Diffusion/wandb/run-20230710_145904-uerlbknf/files/requirements.txt
2023-07-10 14:59:06,192 INFO    Thread-12 :33349 [dir_watcher.py:_on_file_created():272] file/dir created: /home/zhuhe/HPE-with-Diffusion/wandb/run-20230710_145904-uerlbknf/files/wandb-metadata.json
2023-07-10 14:59:06,192 INFO    Thread-12 :33349 [dir_watcher.py:_on_file_created():272] file/dir created: /home/zhuhe/HPE-with-Diffusion/wandb/run-20230710_145904-uerlbknf/files/conda-environment.yaml
2023-07-10 14:59:07,176 DEBUG   HandlerThread:33349 [handler.py:handle_request():144] handle_request: poll_exit
2023-07-10 14:59:07,318 ERROR   wandb-upload_0:33349 [internal_api.py:upload_file():2192] upload_file exception https://storage.googleapis.com/wandb-production.appspot.com/ada4321/DiffHPE/uerlbknf/wandb-metadata.json?Expires=1689058746&GoogleAccessId=gorilla-files-url-signer-man%40wandb-production.iam.gserviceaccount.com&Signature=JrKNS0D3etjsY1%2FabohuabO6KGjXDuic0eUQ8Q9pBUD7YOOVh1VHI3qLNkdvLs4nsoOBEfDGtD1ni9PrDcIPnlW99TrSdJTzP2GZfnDjI3GJz1vBul%2B7daud7IsdG5MqiZ07TFv5UlTeqFFEBQBGgYb01BHoj4fP3sJFNsDYYB86%2BHI%2BCv9PKvRj6HOSDZVjQyfkRvMn65AbpbZGUdfbkI%2BErW91gm%2FSNRqrD0Dx%2FGyxWoc7jTzPquzX7ceM7GKCfeXxGAQGo2lb4jwl7MgTEk4e%2FCjFkx2AF9tuaVURuPP3Yol9cI1MuALHbwEpB%2BaMjBbNsqyWsrj%2BFV1PDmLlUw%3D%3D: 404 Client Error: Not Found for url: https://storage.googleapis.com/wandb-production.appspot.com/ada4321/DiffHPE/uerlbknf/wandb-metadata.json?Expires=1689058746&GoogleAccessId=gorilla-files-url-signer-man%40wandb-production.iam.gserviceaccount.com&Signature=JrKNS0D3etjsY1%2FabohuabO6KGjXDuic0eUQ8Q9pBUD7YOOVh1VHI3qLNkdvLs4nsoOBEfDGtD1ni9PrDcIPnlW99TrSdJTzP2GZfnDjI3GJz1vBul%2B7daud7IsdG5MqiZ07TFv5UlTeqFFEBQBGgYb01BHoj4fP3sJFNsDYYB86%2BHI%2BCv9PKvRj6HOSDZVjQyfkRvMn65AbpbZGUdfbkI%2BErW91gm%2FSNRqrD0Dx%2FGyxWoc7jTzPquzX7ceM7GKCfeXxGAQGo2lb4jwl7MgTEk4e%2FCjFkx2AF9tuaVURuPP3Yol9cI1MuALHbwEpB%2BaMjBbNsqyWsrj%2BFV1PDmLlUw%3D%3D
2023-07-10 14:59:07,318 ERROR   wandb-upload_0:33349 [internal_api.py:upload_file():2194] upload_file request headers: {'User-Agent': 'python-requests/2.31.0', 'Accept-Encoding': 'gzip, deflate', 'Accept': '*/*', 'Connection': 'keep-alive', 'Content-Length': '3709'}
2023-07-10 14:59:07,318 ERROR   wandb-upload_0:33349 [internal_api.py:upload_file():2196] upload_file response body: b'<!DOCTYPE html>\n<html lang=en>\n  <meta charset=utf-8>\n  <meta name=viewport content="initial-scale=1, minimum-scale=1, width=device-width">\n  <title>Error 404 (Not Found)!!1</title>\n  <style>\n    *{margin:0;padding:0}html,code{font:15px/22px arial,sans-serif}html{background:#fff;color:#222;padding:15px}body{margin:7% auto 0;max-width:390px;min-height:180px;padding:30px 0 15px}* > body{background:url(//www.google.com/images/errors/robot.png) 100% 5px no-repeat;padding-right:205px}p{margin:11px 0 22px;overflow:hidden}ins{color:#777;text-decoration:none}a img{border:0}@media screen and (max-width:772px){body{background:none;margin-top:0;max-width:none;padding-right:0}}#logo{background:url(//www.google.com/images/branding/googlelogo/1x/googlelogo_color_150x54dp.png) no-repeat;margin-left:-5px}@media only screen and (min-resolution:192dpi){#logo{background:url(//www.google.com/images/branding/googlelogo/2x/googlelogo_color_150x54dp.png) no-repeat 0% 0%/100% 100%;-moz-border-image:url(//www.google.com/images/branding/googlelogo/2x/googlelogo_color_150x54dp.png) 0}}@media only screen and (-webkit-min-device-pixel-ratio:2){#logo{background:url(//www.google.com/images/branding/googlelogo/2x/googlelogo_color_150x54dp.png) no-repeat;-webkit-background-size:100% 100%}}#logo{display:inline-block;height:54px;width:150px}\n  </style>\n  <a href=//www.google.com/><span id=logo aria-label=Google></span></a>\n  <p><b>404.</b> <ins>That\xe2\x80\x99s an error.</ins>\n  <p>The requested URL <code>/wandb-production.appspot.com/ada4321/DiffHPE/uerlbknf/wandb-metadata.json</code> was not found on this server.  <ins>That\xe2\x80\x99s all we know.</ins>\n'
2023-07-10 14:59:07,464 DEBUG   SenderThread:33349 [sender.py:send():369] send: telemetry
2023-07-10 14:59:07,464 DEBUG   SenderThread:33349 [sender.py:send():369] send: exit
2023-07-10 14:59:07,464 INFO    SenderThread:33349 [sender.py:send_exit():574] handling exit code: 1
2023-07-10 14:59:07,464 INFO    SenderThread:33349 [sender.py:send_exit():576] handling runtime: 0
2023-07-10 14:59:07,465 INFO    SenderThread:33349 [sender.py:_save_file():1354] saving file wandb-summary.json with policy end
2023-07-10 14:59:07,465 INFO    SenderThread:33349 [sender.py:send_exit():582] send defer
2023-07-10 14:59:07,465 DEBUG   SenderThread:33349 [sender.py:send_request():396] send_request: poll_exit
2023-07-10 14:59:07,465 DEBUG   HandlerThread:33349 [handler.py:handle_request():144] handle_request: defer
2023-07-10 14:59:07,465 INFO    HandlerThread:33349 [handler.py:handle_request_defer():170] handle defer: 0
2023-07-10 14:59:07,465 DEBUG   SenderThread:33349 [sender.py:send_request():396] send_request: defer
2023-07-10 14:59:07,465 INFO    SenderThread:33349 [sender.py:send_request_defer():598] handle sender defer: 0
2023-07-10 14:59:07,465 INFO    SenderThread:33349 [sender.py:transition_state():602] send defer: 1
2023-07-10 14:59:07,465 DEBUG   HandlerThread:33349 [handler.py:handle_request():144] handle_request: defer
2023-07-10 14:59:07,465 INFO    HandlerThread:33349 [handler.py:handle_request_defer():170] handle defer: 1
2023-07-10 14:59:07,466 DEBUG   SenderThread:33349 [sender.py:send_request():396] send_request: defer
2023-07-10 14:59:07,466 INFO    SenderThread:33349 [sender.py:send_request_defer():598] handle sender defer: 1
2023-07-10 14:59:07,466 INFO    SenderThread:33349 [sender.py:transition_state():602] send defer: 2
2023-07-10 14:59:07,466 DEBUG   HandlerThread:33349 [handler.py:handle_request():144] handle_request: defer
2023-07-10 14:59:07,466 INFO    HandlerThread:33349 [handler.py:handle_request_defer():170] handle defer: 2
2023-07-10 14:59:07,466 INFO    HandlerThread:33349 [system_monitor.py:finish():190] Stopping system monitor
2023-07-10 14:59:07,466 DEBUG   SystemMonitor:33349 [system_monitor.py:_start():159] Starting system metrics aggregation loop
2023-07-10 14:59:07,466 DEBUG   SystemMonitor:33349 [system_monitor.py:_start():166] Finished system metrics aggregation loop
2023-07-10 14:59:07,466 DEBUG   SystemMonitor:33349 [system_monitor.py:_start():170] Publishing last batch of metrics
2023-07-10 14:59:07,466 INFO    HandlerThread:33349 [interfaces.py:finish():202] Joined cpu monitor
2023-07-10 14:59:07,466 INFO    HandlerThread:33349 [interfaces.py:finish():202] Joined disk monitor
2023-07-10 14:59:07,508 INFO    HandlerThread:33349 [interfaces.py:finish():202] Joined gpu monitor
2023-07-10 14:59:07,509 INFO    HandlerThread:33349 [interfaces.py:finish():202] Joined memory monitor
2023-07-10 14:59:07,509 INFO    HandlerThread:33349 [interfaces.py:finish():202] Joined network monitor
2023-07-10 14:59:07,509 DEBUG   SenderThread:33349 [sender.py:send_request():396] send_request: defer
2023-07-10 14:59:07,509 INFO    SenderThread:33349 [sender.py:send_request_defer():598] handle sender defer: 2
2023-07-10 14:59:07,509 INFO    SenderThread:33349 [sender.py:transition_state():602] send defer: 3
2023-07-10 14:59:07,509 DEBUG   SenderThread:33349 [sender.py:send():369] send: stats
2023-07-10 14:59:07,509 DEBUG   HandlerThread:33349 [handler.py:handle_request():144] handle_request: defer
2023-07-10 14:59:07,509 INFO    HandlerThread:33349 [handler.py:handle_request_defer():170] handle defer: 3
2023-07-10 14:59:07,510 DEBUG   SenderThread:33349 [sender.py:send_request():396] send_request: defer
2023-07-10 14:59:07,510 INFO    SenderThread:33349 [sender.py:send_request_defer():598] handle sender defer: 3
2023-07-10 14:59:07,510 INFO    SenderThread:33349 [sender.py:transition_state():602] send defer: 4
2023-07-10 14:59:07,510 DEBUG   HandlerThread:33349 [handler.py:handle_request():144] handle_request: defer
2023-07-10 14:59:07,510 INFO    HandlerThread:33349 [handler.py:handle_request_defer():170] handle defer: 4
2023-07-10 14:59:07,510 DEBUG   SenderThread:33349 [sender.py:send_request():396] send_request: defer
2023-07-10 14:59:07,510 INFO    SenderThread:33349 [sender.py:send_request_defer():598] handle sender defer: 4
2023-07-10 14:59:07,510 INFO    SenderThread:33349 [sender.py:transition_state():602] send defer: 5
2023-07-10 14:59:07,510 DEBUG   HandlerThread:33349 [handler.py:handle_request():144] handle_request: defer
2023-07-10 14:59:07,510 INFO    HandlerThread:33349 [handler.py:handle_request_defer():170] handle defer: 5
2023-07-10 14:59:07,510 DEBUG   SenderThread:33349 [sender.py:send():369] send: summary
2023-07-10 14:59:07,511 INFO    SenderThread:33349 [sender.py:_save_file():1354] saving file wandb-summary.json with policy end
2023-07-10 14:59:07,511 DEBUG   SenderThread:33349 [sender.py:send_request():396] send_request: defer
2023-07-10 14:59:07,511 INFO    SenderThread:33349 [sender.py:send_request_defer():598] handle sender defer: 5
2023-07-10 14:59:07,511 INFO    SenderThread:33349 [sender.py:transition_state():602] send defer: 6
2023-07-10 14:59:07,511 DEBUG   HandlerThread:33349 [handler.py:handle_request():144] handle_request: defer
2023-07-10 14:59:07,511 INFO    HandlerThread:33349 [handler.py:handle_request_defer():170] handle defer: 6
2023-07-10 14:59:07,511 DEBUG   SenderThread:33349 [sender.py:send_request():396] send_request: defer
2023-07-10 14:59:07,511 INFO    SenderThread:33349 [sender.py:send_request_defer():598] handle sender defer: 6
2023-07-10 14:59:07,513 DEBUG   HandlerThread:33349 [handler.py:handle_request():144] handle_request: status_report
2023-07-10 14:59:07,789 INFO    SenderThread:33349 [sender.py:transition_state():602] send defer: 7
2023-07-10 14:59:07,789 DEBUG   HandlerThread:33349 [handler.py:handle_request():144] handle_request: defer
2023-07-10 14:59:07,789 INFO    HandlerThread:33349 [handler.py:handle_request_defer():170] handle defer: 7
2023-07-10 14:59:07,789 DEBUG   SenderThread:33349 [sender.py:send_request():396] send_request: defer
2023-07-10 14:59:07,789 INFO    SenderThread:33349 [sender.py:send_request_defer():598] handle sender defer: 7
2023-07-10 14:59:08,176 DEBUG   HandlerThread:33349 [handler.py:handle_request():144] handle_request: poll_exit
2023-07-10 14:59:08,192 INFO    Thread-12 :33349 [dir_watcher.py:_on_file_modified():289] file/dir modified: /home/zhuhe/HPE-with-Diffusion/wandb/run-20230710_145904-uerlbknf/files/wandb-summary.json
2023-07-10 14:59:08,192 INFO    Thread-12 :33349 [dir_watcher.py:_on_file_modified():289] file/dir modified: /home/zhuhe/HPE-with-Diffusion/wandb/run-20230710_145904-uerlbknf/files/config.yaml
2023-07-10 14:59:08,192 INFO    Thread-12 :33349 [dir_watcher.py:_on_file_created():272] file/dir created: /home/zhuhe/HPE-with-Diffusion/wandb/run-20230710_145904-uerlbknf/files/output.log
2023-07-10 14:59:08,503 ERROR   wandb-upload_0:33349 [upload_job.py:push():136] Failed to upload file: /tmp/tmpsbwp7t1fwandb/p7yqu9rz-wandb-metadata.json
Traceback (most recent call last):
  File "/home/zhuhe/.conda/envs/diffhpe/lib/python3.9/site-packages/wandb/apis/normalize.py", line 41, in wrapper
    return func(*args, **kwargs)
  File "/home/zhuhe/.conda/envs/diffhpe/lib/python3.9/site-packages/wandb/sdk/lib/retry.py", line 212, in wrapped_fn
    return retrier(*args, **kargs)
  File "/home/zhuhe/.conda/envs/diffhpe/lib/python3.9/site-packages/wandb/sdk/lib/retry.py", line 131, in __call__
    result = self._call_fn(*args, **kwargs)
  File "/home/zhuhe/.conda/envs/diffhpe/lib/python3.9/site-packages/wandb/sdk/internal/internal_api.py", line 2218, in upload_file
    wandb._sentry.reraise(e)
  File "/home/zhuhe/.conda/envs/diffhpe/lib/python3.9/site-packages/wandb/analytics/sentry.py", line 146, in reraise
    raise exc.with_traceback(sys.exc_info()[2])
  File "/home/zhuhe/.conda/envs/diffhpe/lib/python3.9/site-packages/wandb/sdk/internal/internal_api.py", line 2190, in upload_file
    response.raise_for_status()
  File "/home/zhuhe/.conda/envs/diffhpe/lib/python3.9/site-packages/requests/models.py", line 1021, in raise_for_status
    raise HTTPError(http_error_msg, response=self)
requests.exceptions.HTTPError: 404 Client Error: Not Found for url: https://storage.googleapis.com/wandb-production.appspot.com/ada4321/DiffHPE/uerlbknf/wandb-metadata.json?Expires=1689058746&GoogleAccessId=gorilla-files-url-signer-man%40wandb-production.iam.gserviceaccount.com&Signature=JrKNS0D3etjsY1%2FabohuabO6KGjXDuic0eUQ8Q9pBUD7YOOVh1VHI3qLNkdvLs4nsoOBEfDGtD1ni9PrDcIPnlW99TrSdJTzP2GZfnDjI3GJz1vBul%2B7daud7IsdG5MqiZ07TFv5UlTeqFFEBQBGgYb01BHoj4fP3sJFNsDYYB86%2BHI%2BCv9PKvRj6HOSDZVjQyfkRvMn65AbpbZGUdfbkI%2BErW91gm%2FSNRqrD0Dx%2FGyxWoc7jTzPquzX7ceM7GKCfeXxGAQGo2lb4jwl7MgTEk4e%2FCjFkx2AF9tuaVURuPP3Yol9cI1MuALHbwEpB%2BaMjBbNsqyWsrj%2BFV1PDmLlUw%3D%3D

During handling of the above exception, another exception occurred:

Traceback (most recent call last):
  File "/home/zhuhe/.conda/envs/diffhpe/lib/python3.9/site-packages/wandb/filesync/upload_job.py", line 127, in push
    self._api.upload_file_retry(
  File "/home/zhuhe/.conda/envs/diffhpe/lib/python3.9/site-packages/wandb/apis/normalize.py", line 51, in wrapper
    raise CommError(message, error)
wandb.errors.CommError: <Response [404]>
2023-07-10 14:59:08,719 ERROR   Thread-11 :33349 [step_upload.py:_handle_event():200] Failed to upload file: /tmp/tmpsbwp7t1fwandb/p7yqu9rz-wandb-metadata.json
Traceback (most recent call last):
  File "/home/zhuhe/.conda/envs/diffhpe/lib/python3.9/site-packages/wandb/apis/normalize.py", line 41, in wrapper
    return func(*args, **kwargs)
  File "/home/zhuhe/.conda/envs/diffhpe/lib/python3.9/site-packages/wandb/sdk/lib/retry.py", line 212, in wrapped_fn
    return retrier(*args, **kargs)
  File "/home/zhuhe/.conda/envs/diffhpe/lib/python3.9/site-packages/wandb/sdk/lib/retry.py", line 131, in __call__
    result = self._call_fn(*args, **kwargs)
  File "/home/zhuhe/.conda/envs/diffhpe/lib/python3.9/site-packages/wandb/sdk/internal/internal_api.py", line 2218, in upload_file
    wandb._sentry.reraise(e)
  File "/home/zhuhe/.conda/envs/diffhpe/lib/python3.9/site-packages/wandb/analytics/sentry.py", line 146, in reraise
    raise exc.with_traceback(sys.exc_info()[2])
  File "/home/zhuhe/.conda/envs/diffhpe/lib/python3.9/site-packages/wandb/sdk/internal/internal_api.py", line 2190, in upload_file
    response.raise_for_status()
  File "/home/zhuhe/.conda/envs/diffhpe/lib/python3.9/site-packages/requests/models.py", line 1021, in raise_for_status
    raise HTTPError(http_error_msg, response=self)
requests.exceptions.HTTPError: 404 Client Error: Not Found for url: https://storage.googleapis.com/wandb-production.appspot.com/ada4321/DiffHPE/uerlbknf/wandb-metadata.json?Expires=1689058746&GoogleAccessId=gorilla-files-url-signer-man%40wandb-production.iam.gserviceaccount.com&Signature=JrKNS0D3etjsY1%2FabohuabO6KGjXDuic0eUQ8Q9pBUD7YOOVh1VHI3qLNkdvLs4nsoOBEfDGtD1ni9PrDcIPnlW99TrSdJTzP2GZfnDjI3GJz1vBul%2B7daud7IsdG5MqiZ07TFv5UlTeqFFEBQBGgYb01BHoj4fP3sJFNsDYYB86%2BHI%2BCv9PKvRj6HOSDZVjQyfkRvMn65AbpbZGUdfbkI%2BErW91gm%2FSNRqrD0Dx%2FGyxWoc7jTzPquzX7ceM7GKCfeXxGAQGo2lb4jwl7MgTEk4e%2FCjFkx2AF9tuaVURuPP3Yol9cI1MuALHbwEpB%2BaMjBbNsqyWsrj%2BFV1PDmLlUw%3D%3D

During handling of the above exception, another exception occurred:

Traceback (most recent call last):
  File "/home/zhuhe/.conda/envs/diffhpe/lib/python3.9/concurrent/futures/thread.py", line 58, in run
    result = self.fn(*self.args, **self.kwargs)
  File "/home/zhuhe/.conda/envs/diffhpe/lib/python3.9/site-packages/wandb/filesync/step_upload.py", line 288, in run_and_notify
    self._do_upload_sync(event)
  File "/home/zhuhe/.conda/envs/diffhpe/lib/python3.9/site-packages/wandb/filesync/step_upload.py", line 330, in _do_upload_sync
    job.run()
  File "/home/zhuhe/.conda/envs/diffhpe/lib/python3.9/site-packages/wandb/filesync/upload_job.py", line 57, in run
    self.push()
  File "/home/zhuhe/.conda/envs/diffhpe/lib/python3.9/site-packages/wandb/filesync/upload_job.py", line 127, in push
    self._api.upload_file_retry(
  File "/home/zhuhe/.conda/envs/diffhpe/lib/python3.9/site-packages/wandb/apis/normalize.py", line 51, in wrapper
    raise CommError(message, error)
wandb.errors.CommError: <Response [404]>
2023-07-10 14:59:09,469 INFO    SenderThread:33349 [sender.py:transition_state():602] send defer: 8
2023-07-10 14:59:09,469 DEBUG   SenderThread:33349 [sender.py:send_request():396] send_request: poll_exit
2023-07-10 14:59:09,469 DEBUG   HandlerThread:33349 [handler.py:handle_request():144] handle_request: defer
2023-07-10 14:59:09,469 INFO    HandlerThread:33349 [handler.py:handle_request_defer():170] handle defer: 8
2023-07-10 14:59:09,470 DEBUG   SenderThread:33349 [sender.py:send_request():396] send_request: defer
2023-07-10 14:59:09,470 INFO    SenderThread:33349 [sender.py:send_request_defer():598] handle sender defer: 8
2023-07-10 14:59:09,470 INFO    SenderThread:33349 [job_builder.py:build():232] Attempting to build job artifact
2023-07-10 14:59:09,470 INFO    SenderThread:33349 [job_builder.py:build():266] no source found
2023-07-10 14:59:09,470 INFO    SenderThread:33349 [sender.py:transition_state():602] send defer: 9
2023-07-10 14:59:09,470 DEBUG   HandlerThread:33349 [handler.py:handle_request():144] handle_request: defer
2023-07-10 14:59:09,470 INFO    HandlerThread:33349 [handler.py:handle_request_defer():170] handle defer: 9
2023-07-10 14:59:09,470 DEBUG   SenderThread:33349 [sender.py:send_request():396] send_request: defer
2023-07-10 14:59:09,470 INFO    SenderThread:33349 [sender.py:send_request_defer():598] handle sender defer: 9
2023-07-10 14:59:09,470 INFO    SenderThread:33349 [dir_watcher.py:finish():359] shutting down directory watcher
2023-07-10 14:59:10,193 INFO    Thread-12 :33349 [dir_watcher.py:_on_file_modified():289] file/dir modified: /home/zhuhe/HPE-with-Diffusion/wandb/run-20230710_145904-uerlbknf/files/output.log
2023-07-10 14:59:10,193 INFO    SenderThread:33349 [dir_watcher.py:finish():389] scan: /home/zhuhe/HPE-with-Diffusion/wandb/run-20230710_145904-uerlbknf/files
2023-07-10 14:59:10,193 INFO    SenderThread:33349 [dir_watcher.py:finish():403] scan save: /home/zhuhe/HPE-with-Diffusion/wandb/run-20230710_145904-uerlbknf/files/wandb-metadata.json wandb-metadata.json
2023-07-10 14:59:10,193 INFO    SenderThread:33349 [dir_watcher.py:finish():403] scan save: /home/zhuhe/HPE-with-Diffusion/wandb/run-20230710_145904-uerlbknf/files/config.yaml config.yaml
2023-07-10 14:59:10,193 INFO    SenderThread:33349 [dir_watcher.py:finish():403] scan save: /home/zhuhe/HPE-with-Diffusion/wandb/run-20230710_145904-uerlbknf/files/requirements.txt requirements.txt
2023-07-10 14:59:10,193 INFO    SenderThread:33349 [dir_watcher.py:finish():403] scan save: /home/zhuhe/HPE-with-Diffusion/wandb/run-20230710_145904-uerlbknf/files/wandb-summary.json wandb-summary.json
2023-07-10 14:59:10,193 INFO    SenderThread:33349 [dir_watcher.py:finish():403] scan save: /home/zhuhe/HPE-with-Diffusion/wandb/run-20230710_145904-uerlbknf/files/conda-environment.yaml conda-environment.yaml
2023-07-10 14:59:10,193 INFO    SenderThread:33349 [dir_watcher.py:finish():403] scan save: /home/zhuhe/HPE-with-Diffusion/wandb/run-20230710_145904-uerlbknf/files/output.log output.log
2023-07-10 14:59:10,195 INFO    SenderThread:33349 [sender.py:transition_state():602] send defer: 10
2023-07-10 14:59:10,195 DEBUG   HandlerThread:33349 [handler.py:handle_request():144] handle_request: defer
2023-07-10 14:59:10,195 INFO    HandlerThread:33349 [handler.py:handle_request_defer():170] handle defer: 10
2023-07-10 14:59:10,197 DEBUG   SenderThread:33349 [sender.py:send_request():396] send_request: defer
2023-07-10 14:59:10,197 INFO    SenderThread:33349 [sender.py:send_request_defer():598] handle sender defer: 10
2023-07-10 14:59:10,197 INFO    SenderThread:33349 [file_pusher.py:finish():159] shutting down file pusher
2023-07-10 14:59:10,642 ERROR   wandb-upload_0:33349 [internal_api.py:upload_file():2192] upload_file exception https://storage.googleapis.com/wandb-production.appspot.com/ada4321/DiffHPE/uerlbknf/config.yaml?Expires=1689058750&GoogleAccessId=gorilla-files-url-signer-man%40wandb-production.iam.gserviceaccount.com&Signature=rnWQoqwvgF%2BG0SsxFzM3%2Bty8eExoCNLAMgnJqni8JBRwaWBBrGzelhHutmiTwvpU4N1GdGIvsTGHh4vMgLi%2BhhyPBNOMIbZQnzqdJWeg3cGdxfZ0uz4iSBIR3%2BMGu621Uqk05wcF9CahuI%2BJkHrgK9ketTT%2F6%2FWkBiLmvG02Nqc4ovWvtjlhFpDI86zf%2FmW7Q8RFn4MjBBB2HsRzT7TJYNq3TRcshJ0rkohf1rmtl2%2FHfhL%2FgM28pRxx29XqoMeLwP61QdiwYziag3ED9qplXU3se9cHuJPd0qU3dAf82HsNZGPS%2BwouPqtzQQLGqAwEnlp4NiOfiOu5UkdjgBmV1Q%3D%3D: 404 Client Error: Not Found for url: https://storage.googleapis.com/wandb-production.appspot.com/ada4321/DiffHPE/uerlbknf/config.yaml?Expires=1689058750&GoogleAccessId=gorilla-files-url-signer-man%40wandb-production.iam.gserviceaccount.com&Signature=rnWQoqwvgF%2BG0SsxFzM3%2Bty8eExoCNLAMgnJqni8JBRwaWBBrGzelhHutmiTwvpU4N1GdGIvsTGHh4vMgLi%2BhhyPBNOMIbZQnzqdJWeg3cGdxfZ0uz4iSBIR3%2BMGu621Uqk05wcF9CahuI%2BJkHrgK9ketTT%2F6%2FWkBiLmvG02Nqc4ovWvtjlhFpDI86zf%2FmW7Q8RFn4MjBBB2HsRzT7TJYNq3TRcshJ0rkohf1rmtl2%2FHfhL%2FgM28pRxx29XqoMeLwP61QdiwYziag3ED9qplXU3se9cHuJPd0qU3dAf82HsNZGPS%2BwouPqtzQQLGqAwEnlp4NiOfiOu5UkdjgBmV1Q%3D%3D
2023-07-10 14:59:10,643 ERROR   wandb-upload_0:33349 [internal_api.py:upload_file():2194] upload_file request headers: {'User-Agent': 'python-requests/2.31.0', 'Accept-Encoding': 'gzip, deflate', 'Accept': '*/*', 'Connection': 'keep-alive', 'Content-Length': '514'}
2023-07-10 14:59:10,643 ERROR   wandb-upload_0:33349 [internal_api.py:upload_file():2196] upload_file response body: b'<!DOCTYPE html>\n<html lang=en>\n  <meta charset=utf-8>\n  <meta name=viewport content="initial-scale=1, minimum-scale=1, width=device-width">\n  <title>Error 404 (Not Found)!!1</title>\n  <style>\n    *{margin:0;padding:0}html,code{font:15px/22px arial,sans-serif}html{background:#fff;color:#222;padding:15px}body{margin:7% auto 0;max-width:390px;min-height:180px;padding:30px 0 15px}* > body{background:url(//www.google.com/images/errors/robot.png) 100% 5px no-repeat;padding-right:205px}p{margin:11px 0 22px;overflow:hidden}ins{color:#777;text-decoration:none}a img{border:0}@media screen and (max-width:772px){body{background:none;margin-top:0;max-width:none;padding-right:0}}#logo{background:url(//www.google.com/images/branding/googlelogo/1x/googlelogo_color_150x54dp.png) no-repeat;margin-left:-5px}@media only screen and (min-resolution:192dpi){#logo{background:url(//www.google.com/images/branding/googlelogo/2x/googlelogo_color_150x54dp.png) no-repeat 0% 0%/100% 100%;-moz-border-image:url(//www.google.com/images/branding/googlelogo/2x/googlelogo_color_150x54dp.png) 0}}@media only screen and (-webkit-min-device-pixel-ratio:2){#logo{background:url(//www.google.com/images/branding/googlelogo/2x/googlelogo_color_150x54dp.png) no-repeat;-webkit-background-size:100% 100%}}#logo{display:inline-block;height:54px;width:150px}\n  </style>\n  <a href=//www.google.com/><span id=logo aria-label=Google></span></a>\n  <p><b>404.</b> <ins>That\xe2\x80\x99s an error.</ins>\n  <p>The requested URL <code>/wandb-production.appspot.com/ada4321/DiffHPE/uerlbknf/config.yaml</code> was not found on this server.  <ins>That\xe2\x80\x99s all we know.</ins>\n'
2023-07-10 14:59:10,657 ERROR   wandb-upload_1:33349 [internal_api.py:upload_file():2192] upload_file exception https://storage.googleapis.com/wandb-production.appspot.com/ada4321/DiffHPE/uerlbknf/requirements.txt?Expires=1689058750&GoogleAccessId=gorilla-files-url-signer-man%40wandb-production.iam.gserviceaccount.com&Signature=lxG4GoRGc39ftF8%2B6HCeSgAKCrrR4nc9lbZ6HaesM8k%2F88v2Z%2BiGgthEIFEylhvSkaOA7A8WncBoOrKtPtgeLwfscaeeH%2B5dJwB5c0bNPAUmBMgLW4nk0sxVqikA8E8%2FOx2r37al1AkefUp3SIRK5mb0px8pNDw%2FWLH4FErCoXMel0wwo5Ibk7%2F6HRodYf0tihtENwgdqg00TKDKvc9QryRM9Kr4aansy5lpxDM9NRx%2FbPuduqrQ3zsj6ZJK5mJ71TFnv4nJQ2DuBs0bOAO1NvB%2B96bz8KlMSAjpOzwtxOOW0hPY2OHqXi6sDgXiH%2FGWDqiM9zHPb63YWNq4lNbZ0w%3D%3D: 404 Client Error: Not Found for url: https://storage.googleapis.com/wandb-production.appspot.com/ada4321/DiffHPE/uerlbknf/requirements.txt?Expires=1689058750&GoogleAccessId=gorilla-files-url-signer-man%40wandb-production.iam.gserviceaccount.com&Signature=lxG4GoRGc39ftF8%2B6HCeSgAKCrrR4nc9lbZ6HaesM8k%2F88v2Z%2BiGgthEIFEylhvSkaOA7A8WncBoOrKtPtgeLwfscaeeH%2B5dJwB5c0bNPAUmBMgLW4nk0sxVqikA8E8%2FOx2r37al1AkefUp3SIRK5mb0px8pNDw%2FWLH4FErCoXMel0wwo5Ibk7%2F6HRodYf0tihtENwgdqg00TKDKvc9QryRM9Kr4aansy5lpxDM9NRx%2FbPuduqrQ3zsj6ZJK5mJ71TFnv4nJQ2DuBs0bOAO1NvB%2B96bz8KlMSAjpOzwtxOOW0hPY2OHqXi6sDgXiH%2FGWDqiM9zHPb63YWNq4lNbZ0w%3D%3D
2023-07-10 14:59:10,657 ERROR   wandb-upload_1:33349 [internal_api.py:upload_file():2194] upload_file request headers: {'User-Agent': 'python-requests/2.31.0', 'Accept-Encoding': 'gzip, deflate', 'Accept': '*/*', 'Connection': 'keep-alive', 'Content-Length': '910'}
2023-07-10 14:59:10,657 ERROR   wandb-upload_1:33349 [internal_api.py:upload_file():2196] upload_file response body: b'<!DOCTYPE html>\n<html lang=en>\n  <meta charset=utf-8>\n  <meta name=viewport content="initial-scale=1, minimum-scale=1, width=device-width">\n  <title>Error 404 (Not Found)!!1</title>\n  <style>\n    *{margin:0;padding:0}html,code{font:15px/22px arial,sans-serif}html{background:#fff;color:#222;padding:15px}body{margin:7% auto 0;max-width:390px;min-height:180px;padding:30px 0 15px}* > body{background:url(//www.google.com/images/errors/robot.png) 100% 5px no-repeat;padding-right:205px}p{margin:11px 0 22px;overflow:hidden}ins{color:#777;text-decoration:none}a img{border:0}@media screen and (max-width:772px){body{background:none;margin-top:0;max-width:none;padding-right:0}}#logo{background:url(//www.google.com/images/branding/googlelogo/1x/googlelogo_color_150x54dp.png) no-repeat;margin-left:-5px}@media only screen and (min-resolution:192dpi){#logo{background:url(//www.google.com/images/branding/googlelogo/2x/googlelogo_color_150x54dp.png) no-repeat 0% 0%/100% 100%;-moz-border-image:url(//www.google.com/images/branding/googlelogo/2x/googlelogo_color_150x54dp.png) 0}}@media only screen and (-webkit-min-device-pixel-ratio:2){#logo{background:url(//www.google.com/images/branding/googlelogo/2x/googlelogo_color_150x54dp.png) no-repeat;-webkit-background-size:100% 100%}}#logo{display:inline-block;height:54px;width:150px}\n  </style>\n  <a href=//www.google.com/><span id=logo aria-label=Google></span></a>\n  <p><b>404.</b> <ins>That\xe2\x80\x99s an error.</ins>\n  <p>The requested URL <code>/wandb-production.appspot.com/ada4321/DiffHPE/uerlbknf/requirements.txt</code> was not found on this server.  <ins>That\xe2\x80\x99s all we know.</ins>\n'
2023-07-10 14:59:10,977 ERROR   wandb-upload_3:33349 [internal_api.py:upload_file():2192] upload_file exception https://storage.googleapis.com/wandb-production.appspot.com/ada4321/DiffHPE/uerlbknf/conda-environment.yaml?Expires=1689058750&GoogleAccessId=gorilla-files-url-signer-man%40wandb-production.iam.gserviceaccount.com&Signature=mcofxEv4yPMALHfM7iF44gPI6vDf6VNFN1VNinpLz9YmobTAKG0axF5YgwFiCOxpankQ9vyO%2FFSgqtolZE58CbFvPefuHrOYXHPM5imBwpKqS%2FEFblIgv7U0%2FoUk8KGXHSN2dggDY%2B0QPS67wIwCWSf65hLKG%2FXnoR5AOkeU17FPgIT9K2MN%2BZUyRYd90iYEciGTUIWXV9WKUvym1axGl5Pj8sU7N2l%2FOq9LTyPVr5Aye0P6OlAmeHEzWj%2FmZ7ZVoDlWJt9naUHmUdsbj%2FBVvl5%2F5JpFt4Q0xQriZlvsl6qG8p7ayRK7Uif77SwEXFKLrL0wiFmoW3%2BV79r1sRPvow%3D%3D: 404 Client Error: Not Found for url: https://storage.googleapis.com/wandb-production.appspot.com/ada4321/DiffHPE/uerlbknf/conda-environment.yaml?Expires=1689058750&GoogleAccessId=gorilla-files-url-signer-man%40wandb-production.iam.gserviceaccount.com&Signature=mcofxEv4yPMALHfM7iF44gPI6vDf6VNFN1VNinpLz9YmobTAKG0axF5YgwFiCOxpankQ9vyO%2FFSgqtolZE58CbFvPefuHrOYXHPM5imBwpKqS%2FEFblIgv7U0%2FoUk8KGXHSN2dggDY%2B0QPS67wIwCWSf65hLKG%2FXnoR5AOkeU17FPgIT9K2MN%2BZUyRYd90iYEciGTUIWXV9WKUvym1axGl5Pj8sU7N2l%2FOq9LTyPVr5Aye0P6OlAmeHEzWj%2FmZ7ZVoDlWJt9naUHmUdsbj%2FBVvl5%2F5JpFt4Q0xQriZlvsl6qG8p7ayRK7Uif77SwEXFKLrL0wiFmoW3%2BV79r1sRPvow%3D%3D
2023-07-10 14:59:10,977 ERROR   wandb-upload_3:33349 [internal_api.py:upload_file():2194] upload_file request headers: {'User-Agent': 'python-requests/2.31.0', 'Accept-Encoding': 'gzip, deflate', 'Accept': '*/*', 'Connection': 'keep-alive', 'Content-Length': '1903'}
2023-07-10 14:59:10,977 ERROR   wandb-upload_3:33349 [internal_api.py:upload_file():2196] upload_file response body: b'<!DOCTYPE html>\n<html lang=en>\n  <meta charset=utf-8>\n  <meta name=viewport content="initial-scale=1, minimum-scale=1, width=device-width">\n  <title>Error 404 (Not Found)!!1</title>\n  <style>\n    *{margin:0;padding:0}html,code{font:15px/22px arial,sans-serif}html{background:#fff;color:#222;padding:15px}body{margin:7% auto 0;max-width:390px;min-height:180px;padding:30px 0 15px}* > body{background:url(//www.google.com/images/errors/robot.png) 100% 5px no-repeat;padding-right:205px}p{margin:11px 0 22px;overflow:hidden}ins{color:#777;text-decoration:none}a img{border:0}@media screen and (max-width:772px){body{background:none;margin-top:0;max-width:none;padding-right:0}}#logo{background:url(//www.google.com/images/branding/googlelogo/1x/googlelogo_color_150x54dp.png) no-repeat;margin-left:-5px}@media only screen and (min-resolution:192dpi){#logo{background:url(//www.google.com/images/branding/googlelogo/2x/googlelogo_color_150x54dp.png) no-repeat 0% 0%/100% 100%;-moz-border-image:url(//www.google.com/images/branding/googlelogo/2x/googlelogo_color_150x54dp.png) 0}}@media only screen and (-webkit-min-device-pixel-ratio:2){#logo{background:url(//www.google.com/images/branding/googlelogo/2x/googlelogo_color_150x54dp.png) no-repeat;-webkit-background-size:100% 100%}}#logo{display:inline-block;height:54px;width:150px}\n  </style>\n  <a href=//www.google.com/><span id=logo aria-label=Google></span></a>\n  <p><b>404.</b> <ins>That\xe2\x80\x99s an error.</ins>\n  <p>The requested URL <code>/wandb-production.appspot.com/ada4321/DiffHPE/uerlbknf/conda-environment.yaml</code> was not found on this server.  <ins>That\xe2\x80\x99s all we know.</ins>\n'
2023-07-10 14:59:11,001 ERROR   wandb-upload_2:33349 [internal_api.py:upload_file():2192] upload_file exception https://storage.googleapis.com/wandb-production.appspot.com/ada4321/DiffHPE/uerlbknf/wandb-summary.json?Expires=1689058750&GoogleAccessId=gorilla-files-url-signer-man%40wandb-production.iam.gserviceaccount.com&Signature=QuRtvNtgqmSDj5B5SYem743ouxSgMNQVhdan9hTXYS4pgwL3UT%2FMdU6W1I%2BVPJMLuPezqo5X7tXDdpZsbnDqt%2Bl2JleA%2BR%2Fek3%2Bzr0%2BnSRfBoPhVU9nLQaJNwRpqdTyHQBodmGdCL1LFUFdeKli17HT54kTIiFmdRxX6FX4JsCJbQhKhxfCBGOSxMh8QTRlTHxkQW%2BUyERfjg4EmNpI6OdWNikLYlNIeHcEy6w7wnMNylLqHTbUoIstJuuVOlSVsB3NInJ8FL08UhLpYRq%2BA942l2WZ1Lo1VoObZErIiN4t33fizzg1fl5X3w3g6yMMaEmYSrqE2soOOX7HI92gkIw%3D%3D: 404 Client Error: Not Found for url: https://storage.googleapis.com/wandb-production.appspot.com/ada4321/DiffHPE/uerlbknf/wandb-summary.json?Expires=1689058750&GoogleAccessId=gorilla-files-url-signer-man%40wandb-production.iam.gserviceaccount.com&Signature=QuRtvNtgqmSDj5B5SYem743ouxSgMNQVhdan9hTXYS4pgwL3UT%2FMdU6W1I%2BVPJMLuPezqo5X7tXDdpZsbnDqt%2Bl2JleA%2BR%2Fek3%2Bzr0%2BnSRfBoPhVU9nLQaJNwRpqdTyHQBodmGdCL1LFUFdeKli17HT54kTIiFmdRxX6FX4JsCJbQhKhxfCBGOSxMh8QTRlTHxkQW%2BUyERfjg4EmNpI6OdWNikLYlNIeHcEy6w7wnMNylLqHTbUoIstJuuVOlSVsB3NInJ8FL08UhLpYRq%2BA942l2WZ1Lo1VoObZErIiN4t33fizzg1fl5X3w3g6yMMaEmYSrqE2soOOX7HI92gkIw%3D%3D
2023-07-10 14:59:11,001 ERROR   wandb-upload_4:33349 [internal_api.py:upload_file():2192] upload_file exception https://storage.googleapis.com/wandb-production.appspot.com/ada4321/DiffHPE/uerlbknf/output.log?Expires=1689058750&GoogleAccessId=gorilla-files-url-signer-man%40wandb-production.iam.gserviceaccount.com&Signature=YrjoGGR6RGcxcFOgYvddWVGquHpDNp6rK37Pj%2FmW56pyU4Q0NP5KwCuCx1AGc5Rd0sa5aoMsNT6gVnnyuVEYoxKPqH%2F%2BbuDmcWDwICLK5r2ysEWFACk4qlpRJz1dwytsDkMPpQK1X6GcCydTsktzyLtMaMI3f4D9ktV977WYxDVeEGf4OukzH52aT0waQgsBEnCKnWr%2FW%2BCw8KHUSpc39JeeTHxDFlPriy38pVI%2FRvFuxPwReh4Uf%2Bjy7WyORkbt2DrQAqK%2F6D9Fkjv60rBUjebmbnN5vzcAIl1c%2F4jZDF9a3aKC9BQeg9hzAz3GVcx4lekknFq8cI5FM1fZS2a%2BNA%3D%3D: 404 Client Error: Not Found for url: https://storage.googleapis.com/wandb-production.appspot.com/ada4321/DiffHPE/uerlbknf/output.log?Expires=1689058750&GoogleAccessId=gorilla-files-url-signer-man%40wandb-production.iam.gserviceaccount.com&Signature=YrjoGGR6RGcxcFOgYvddWVGquHpDNp6rK37Pj%2FmW56pyU4Q0NP5KwCuCx1AGc5Rd0sa5aoMsNT6gVnnyuVEYoxKPqH%2F%2BbuDmcWDwICLK5r2ysEWFACk4qlpRJz1dwytsDkMPpQK1X6GcCydTsktzyLtMaMI3f4D9ktV977WYxDVeEGf4OukzH52aT0waQgsBEnCKnWr%2FW%2BCw8KHUSpc39JeeTHxDFlPriy38pVI%2FRvFuxPwReh4Uf%2Bjy7WyORkbt2DrQAqK%2F6D9Fkjv60rBUjebmbnN5vzcAIl1c%2F4jZDF9a3aKC9BQeg9hzAz3GVcx4lekknFq8cI5FM1fZS2a%2BNA%3D%3D
2023-07-10 14:59:11,001 ERROR   wandb-upload_2:33349 [internal_api.py:upload_file():2194] upload_file request headers: {'User-Agent': 'python-requests/2.31.0', 'Accept-Encoding': 'gzip, deflate', 'Accept': '*/*', 'Connection': 'keep-alive', 'Content-Length': '26'}
2023-07-10 14:59:11,001 ERROR   wandb-upload_4:33349 [internal_api.py:upload_file():2194] upload_file request headers: {'User-Agent': 'python-requests/2.31.0', 'Accept-Encoding': 'gzip, deflate', 'Accept': '*/*', 'Connection': 'keep-alive', 'Content-Length': '2733'}
2023-07-10 14:59:11,001 ERROR   wandb-upload_2:33349 [internal_api.py:upload_file():2196] upload_file response body: b'<!DOCTYPE html>\n<html lang=en>\n  <meta charset=utf-8>\n  <meta name=viewport content="initial-scale=1, minimum-scale=1, width=device-width">\n  <title>Error 404 (Not Found)!!1</title>\n  <style>\n    *{margin:0;padding:0}html,code{font:15px/22px arial,sans-serif}html{background:#fff;color:#222;padding:15px}body{margin:7% auto 0;max-width:390px;min-height:180px;padding:30px 0 15px}* > body{background:url(//www.google.com/images/errors/robot.png) 100% 5px no-repeat;padding-right:205px}p{margin:11px 0 22px;overflow:hidden}ins{color:#777;text-decoration:none}a img{border:0}@media screen and (max-width:772px){body{background:none;margin-top:0;max-width:none;padding-right:0}}#logo{background:url(//www.google.com/images/branding/googlelogo/1x/googlelogo_color_150x54dp.png) no-repeat;margin-left:-5px}@media only screen and (min-resolution:192dpi){#logo{background:url(//www.google.com/images/branding/googlelogo/2x/googlelogo_color_150x54dp.png) no-repeat 0% 0%/100% 100%;-moz-border-image:url(//www.google.com/images/branding/googlelogo/2x/googlelogo_color_150x54dp.png) 0}}@media only screen and (-webkit-min-device-pixel-ratio:2){#logo{background:url(//www.google.com/images/branding/googlelogo/2x/googlelogo_color_150x54dp.png) no-repeat;-webkit-background-size:100% 100%}}#logo{display:inline-block;height:54px;width:150px}\n  </style>\n  <a href=//www.google.com/><span id=logo aria-label=Google></span></a>\n  <p><b>404.</b> <ins>That\xe2\x80\x99s an error.</ins>\n  <p>The requested URL <code>/wandb-production.appspot.com/ada4321/DiffHPE/uerlbknf/wandb-summary.json</code> was not found on this server.  <ins>That\xe2\x80\x99s all we know.</ins>\n'
2023-07-10 14:59:11,002 ERROR   wandb-upload_4:33349 [internal_api.py:upload_file():2196] upload_file response body: b'<!DOCTYPE html>\n<html lang=en>\n  <meta charset=utf-8>\n  <meta name=viewport content="initial-scale=1, minimum-scale=1, width=device-width">\n  <title>Error 404 (Not Found)!!1</title>\n  <style>\n    *{margin:0;padding:0}html,code{font:15px/22px arial,sans-serif}html{background:#fff;color:#222;padding:15px}body{margin:7% auto 0;max-width:390px;min-height:180px;padding:30px 0 15px}* > body{background:url(//www.google.com/images/errors/robot.png) 100% 5px no-repeat;padding-right:205px}p{margin:11px 0 22px;overflow:hidden}ins{color:#777;text-decoration:none}a img{border:0}@media screen and (max-width:772px){body{background:none;margin-top:0;max-width:none;padding-right:0}}#logo{background:url(//www.google.com/images/branding/googlelogo/1x/googlelogo_color_150x54dp.png) no-repeat;margin-left:-5px}@media only screen and (min-resolution:192dpi){#logo{background:url(//www.google.com/images/branding/googlelogo/2x/googlelogo_color_150x54dp.png) no-repeat 0% 0%/100% 100%;-moz-border-image:url(//www.google.com/images/branding/googlelogo/2x/googlelogo_color_150x54dp.png) 0}}@media only screen and (-webkit-min-device-pixel-ratio:2){#logo{background:url(//www.google.com/images/branding/googlelogo/2x/googlelogo_color_150x54dp.png) no-repeat;-webkit-background-size:100% 100%}}#logo{display:inline-block;height:54px;width:150px}\n  </style>\n  <a href=//www.google.com/><span id=logo aria-label=Google></span></a>\n  <p><b>404.</b> <ins>That\xe2\x80\x99s an error.</ins>\n  <p>The requested URL <code>/wandb-production.appspot.com/ada4321/DiffHPE/uerlbknf/output.log</code> was not found on this server.  <ins>That\xe2\x80\x99s all we know.</ins>\n'
2023-07-10 14:59:11,709 ERROR   wandb-upload_0:33349 [upload_job.py:push():136] Failed to upload file: /home/zhuhe/HPE-with-Diffusion/wandb/run-20230710_145904-uerlbknf/files/config.yaml
Traceback (most recent call last):
  File "/home/zhuhe/.conda/envs/diffhpe/lib/python3.9/site-packages/wandb/apis/normalize.py", line 41, in wrapper
    return func(*args, **kwargs)
  File "/home/zhuhe/.conda/envs/diffhpe/lib/python3.9/site-packages/wandb/sdk/lib/retry.py", line 212, in wrapped_fn
    return retrier(*args, **kargs)
  File "/home/zhuhe/.conda/envs/diffhpe/lib/python3.9/site-packages/wandb/sdk/lib/retry.py", line 131, in __call__
    result = self._call_fn(*args, **kwargs)
  File "/home/zhuhe/.conda/envs/diffhpe/lib/python3.9/site-packages/wandb/sdk/internal/internal_api.py", line 2218, in upload_file
    wandb._sentry.reraise(e)
  File "/home/zhuhe/.conda/envs/diffhpe/lib/python3.9/site-packages/wandb/analytics/sentry.py", line 146, in reraise
    raise exc.with_traceback(sys.exc_info()[2])
  File "/home/zhuhe/.conda/envs/diffhpe/lib/python3.9/site-packages/wandb/sdk/internal/internal_api.py", line 2190, in upload_file
    response.raise_for_status()
  File "/home/zhuhe/.conda/envs/diffhpe/lib/python3.9/site-packages/requests/models.py", line 1021, in raise_for_status
    raise HTTPError(http_error_msg, response=self)
requests.exceptions.HTTPError: 404 Client Error: Not Found for url: https://storage.googleapis.com/wandb-production.appspot.com/ada4321/DiffHPE/uerlbknf/config.yaml?Expires=1689058750&GoogleAccessId=gorilla-files-url-signer-man%40wandb-production.iam.gserviceaccount.com&Signature=rnWQoqwvgF%2BG0SsxFzM3%2Bty8eExoCNLAMgnJqni8JBRwaWBBrGzelhHutmiTwvpU4N1GdGIvsTGHh4vMgLi%2BhhyPBNOMIbZQnzqdJWeg3cGdxfZ0uz4iSBIR3%2BMGu621Uqk05wcF9CahuI%2BJkHrgK9ketTT%2F6%2FWkBiLmvG02Nqc4ovWvtjlhFpDI86zf%2FmW7Q8RFn4MjBBB2HsRzT7TJYNq3TRcshJ0rkohf1rmtl2%2FHfhL%2FgM28pRxx29XqoMeLwP61QdiwYziag3ED9qplXU3se9cHuJPd0qU3dAf82HsNZGPS%2BwouPqtzQQLGqAwEnlp4NiOfiOu5UkdjgBmV1Q%3D%3D

During handling of the above exception, another exception occurred:

Traceback (most recent call last):
  File "/home/zhuhe/.conda/envs/diffhpe/lib/python3.9/site-packages/wandb/filesync/upload_job.py", line 127, in push
    self._api.upload_file_retry(
  File "/home/zhuhe/.conda/envs/diffhpe/lib/python3.9/site-packages/wandb/apis/normalize.py", line 51, in wrapper
    raise CommError(message, error)
wandb.errors.CommError: <Response [404]>
2023-07-10 14:59:11,710 ERROR   wandb-upload_1:33349 [upload_job.py:push():136] Failed to upload file: /home/zhuhe/HPE-with-Diffusion/wandb/run-20230710_145904-uerlbknf/files/requirements.txt
Traceback (most recent call last):
  File "/home/zhuhe/.conda/envs/diffhpe/lib/python3.9/site-packages/wandb/apis/normalize.py", line 41, in wrapper
    return func(*args, **kwargs)
  File "/home/zhuhe/.conda/envs/diffhpe/lib/python3.9/site-packages/wandb/sdk/lib/retry.py", line 212, in wrapped_fn
    return retrier(*args, **kargs)
  File "/home/zhuhe/.conda/envs/diffhpe/lib/python3.9/site-packages/wandb/sdk/lib/retry.py", line 131, in __call__
    result = self._call_fn(*args, **kwargs)
  File "/home/zhuhe/.conda/envs/diffhpe/lib/python3.9/site-packages/wandb/sdk/internal/internal_api.py", line 2218, in upload_file
    wandb._sentry.reraise(e)
  File "/home/zhuhe/.conda/envs/diffhpe/lib/python3.9/site-packages/wandb/analytics/sentry.py", line 146, in reraise
    raise exc.with_traceback(sys.exc_info()[2])
  File "/home/zhuhe/.conda/envs/diffhpe/lib/python3.9/site-packages/wandb/sdk/internal/internal_api.py", line 2190, in upload_file
    response.raise_for_status()
  File "/home/zhuhe/.conda/envs/diffhpe/lib/python3.9/site-packages/requests/models.py", line 1021, in raise_for_status
    raise HTTPError(http_error_msg, response=self)
requests.exceptions.HTTPError: 404 Client Error: Not Found for url: https://storage.googleapis.com/wandb-production.appspot.com/ada4321/DiffHPE/uerlbknf/requirements.txt?Expires=1689058750&GoogleAccessId=gorilla-files-url-signer-man%40wandb-production.iam.gserviceaccount.com&Signature=lxG4GoRGc39ftF8%2B6HCeSgAKCrrR4nc9lbZ6HaesM8k%2F88v2Z%2BiGgthEIFEylhvSkaOA7A8WncBoOrKtPtgeLwfscaeeH%2B5dJwB5c0bNPAUmBMgLW4nk0sxVqikA8E8%2FOx2r37al1AkefUp3SIRK5mb0px8pNDw%2FWLH4FErCoXMel0wwo5Ibk7%2F6HRodYf0tihtENwgdqg00TKDKvc9QryRM9Kr4aansy5lpxDM9NRx%2FbPuduqrQ3zsj6ZJK5mJ71TFnv4nJQ2DuBs0bOAO1NvB%2B96bz8KlMSAjpOzwtxOOW0hPY2OHqXi6sDgXiH%2FGWDqiM9zHPb63YWNq4lNbZ0w%3D%3D

During handling of the above exception, another exception occurred:

Traceback (most recent call last):
  File "/home/zhuhe/.conda/envs/diffhpe/lib/python3.9/site-packages/wandb/filesync/upload_job.py", line 127, in push
    self._api.upload_file_retry(
  File "/home/zhuhe/.conda/envs/diffhpe/lib/python3.9/site-packages/wandb/apis/normalize.py", line 51, in wrapper
    raise CommError(message, error)
wandb.errors.CommError: <Response [404]>
2023-07-10 14:59:11,710 ERROR   wandb-upload_2:33349 [upload_job.py:push():136] Failed to upload file: /home/zhuhe/HPE-with-Diffusion/wandb/run-20230710_145904-uerlbknf/files/wandb-summary.json
Traceback (most recent call last):
  File "/home/zhuhe/.conda/envs/diffhpe/lib/python3.9/site-packages/wandb/apis/normalize.py", line 41, in wrapper
    return func(*args, **kwargs)
  File "/home/zhuhe/.conda/envs/diffhpe/lib/python3.9/site-packages/wandb/sdk/lib/retry.py", line 212, in wrapped_fn
    return retrier(*args, **kargs)
  File "/home/zhuhe/.conda/envs/diffhpe/lib/python3.9/site-packages/wandb/sdk/lib/retry.py", line 131, in __call__
    result = self._call_fn(*args, **kwargs)
  File "/home/zhuhe/.conda/envs/diffhpe/lib/python3.9/site-packages/wandb/sdk/internal/internal_api.py", line 2218, in upload_file
    wandb._sentry.reraise(e)
  File "/home/zhuhe/.conda/envs/diffhpe/lib/python3.9/site-packages/wandb/analytics/sentry.py", line 146, in reraise
    raise exc.with_traceback(sys.exc_info()[2])
  File "/home/zhuhe/.conda/envs/diffhpe/lib/python3.9/site-packages/wandb/sdk/internal/internal_api.py", line 2190, in upload_file
    response.raise_for_status()
  File "/home/zhuhe/.conda/envs/diffhpe/lib/python3.9/site-packages/requests/models.py", line 1021, in raise_for_status
    raise HTTPError(http_error_msg, response=self)
requests.exceptions.HTTPError: 404 Client Error: Not Found for url: https://storage.googleapis.com/wandb-production.appspot.com/ada4321/DiffHPE/uerlbknf/wandb-summary.json?Expires=1689058750&GoogleAccessId=gorilla-files-url-signer-man%40wandb-production.iam.gserviceaccount.com&Signature=QuRtvNtgqmSDj5B5SYem743ouxSgMNQVhdan9hTXYS4pgwL3UT%2FMdU6W1I%2BVPJMLuPezqo5X7tXDdpZsbnDqt%2Bl2JleA%2BR%2Fek3%2Bzr0%2BnSRfBoPhVU9nLQaJNwRpqdTyHQBodmGdCL1LFUFdeKli17HT54kTIiFmdRxX6FX4JsCJbQhKhxfCBGOSxMh8QTRlTHxkQW%2BUyERfjg4EmNpI6OdWNikLYlNIeHcEy6w7wnMNylLqHTbUoIstJuuVOlSVsB3NInJ8FL08UhLpYRq%2BA942l2WZ1Lo1VoObZErIiN4t33fizzg1fl5X3w3g6yMMaEmYSrqE2soOOX7HI92gkIw%3D%3D

During handling of the above exception, another exception occurred:

Traceback (most recent call last):
  File "/home/zhuhe/.conda/envs/diffhpe/lib/python3.9/site-packages/wandb/filesync/upload_job.py", line 127, in push
    self._api.upload_file_retry(
  File "/home/zhuhe/.conda/envs/diffhpe/lib/python3.9/site-packages/wandb/apis/normalize.py", line 51, in wrapper
    raise CommError(message, error)
wandb.errors.CommError: <Response [404]>
2023-07-10 14:59:11,710 ERROR   wandb-upload_4:33349 [upload_job.py:push():136] Failed to upload file: /home/zhuhe/HPE-with-Diffusion/wandb/run-20230710_145904-uerlbknf/files/output.log
Traceback (most recent call last):
  File "/home/zhuhe/.conda/envs/diffhpe/lib/python3.9/site-packages/wandb/apis/normalize.py", line 41, in wrapper
    return func(*args, **kwargs)
  File "/home/zhuhe/.conda/envs/diffhpe/lib/python3.9/site-packages/wandb/sdk/lib/retry.py", line 212, in wrapped_fn
    return retrier(*args, **kargs)
  File "/home/zhuhe/.conda/envs/diffhpe/lib/python3.9/site-packages/wandb/sdk/lib/retry.py", line 131, in __call__
    result = self._call_fn(*args, **kwargs)
  File "/home/zhuhe/.conda/envs/diffhpe/lib/python3.9/site-packages/wandb/sdk/internal/internal_api.py", line 2218, in upload_file
    wandb._sentry.reraise(e)
  File "/home/zhuhe/.conda/envs/diffhpe/lib/python3.9/site-packages/wandb/analytics/sentry.py", line 146, in reraise
    raise exc.with_traceback(sys.exc_info()[2])
  File "/home/zhuhe/.conda/envs/diffhpe/lib/python3.9/site-packages/wandb/sdk/internal/internal_api.py", line 2190, in upload_file
    response.raise_for_status()
  File "/home/zhuhe/.conda/envs/diffhpe/lib/python3.9/site-packages/requests/models.py", line 1021, in raise_for_status
    raise HTTPError(http_error_msg, response=self)
requests.exceptions.HTTPError: 404 Client Error: Not Found for url: https://storage.googleapis.com/wandb-production.appspot.com/ada4321/DiffHPE/uerlbknf/output.log?Expires=1689058750&GoogleAccessId=gorilla-files-url-signer-man%40wandb-production.iam.gserviceaccount.com&Signature=YrjoGGR6RGcxcFOgYvddWVGquHpDNp6rK37Pj%2FmW56pyU4Q0NP5KwCuCx1AGc5Rd0sa5aoMsNT6gVnnyuVEYoxKPqH%2F%2BbuDmcWDwICLK5r2ysEWFACk4qlpRJz1dwytsDkMPpQK1X6GcCydTsktzyLtMaMI3f4D9ktV977WYxDVeEGf4OukzH52aT0waQgsBEnCKnWr%2FW%2BCw8KHUSpc39JeeTHxDFlPriy38pVI%2FRvFuxPwReh4Uf%2Bjy7WyORkbt2DrQAqK%2F6D9Fkjv60rBUjebmbnN5vzcAIl1c%2F4jZDF9a3aKC9BQeg9hzAz3GVcx4lekknFq8cI5FM1fZS2a%2BNA%3D%3D

During handling of the above exception, another exception occurred:

Traceback (most recent call last):
  File "/home/zhuhe/.conda/envs/diffhpe/lib/python3.9/site-packages/wandb/filesync/upload_job.py", line 127, in push
    self._api.upload_file_retry(
  File "/home/zhuhe/.conda/envs/diffhpe/lib/python3.9/site-packages/wandb/apis/normalize.py", line 51, in wrapper
    raise CommError(message, error)
wandb.errors.CommError: <Response [404]>
2023-07-10 14:59:11,710 ERROR   wandb-upload_3:33349 [upload_job.py:push():136] Failed to upload file: /home/zhuhe/HPE-with-Diffusion/wandb/run-20230710_145904-uerlbknf/files/conda-environment.yaml
Traceback (most recent call last):
  File "/home/zhuhe/.conda/envs/diffhpe/lib/python3.9/site-packages/wandb/apis/normalize.py", line 41, in wrapper
    return func(*args, **kwargs)
  File "/home/zhuhe/.conda/envs/diffhpe/lib/python3.9/site-packages/wandb/sdk/lib/retry.py", line 212, in wrapped_fn
    return retrier(*args, **kargs)
  File "/home/zhuhe/.conda/envs/diffhpe/lib/python3.9/site-packages/wandb/sdk/lib/retry.py", line 131, in __call__
    result = self._call_fn(*args, **kwargs)
  File "/home/zhuhe/.conda/envs/diffhpe/lib/python3.9/site-packages/wandb/sdk/internal/internal_api.py", line 2218, in upload_file
    wandb._sentry.reraise(e)
  File "/home/zhuhe/.conda/envs/diffhpe/lib/python3.9/site-packages/wandb/analytics/sentry.py", line 146, in reraise
    raise exc.with_traceback(sys.exc_info()[2])
  File "/home/zhuhe/.conda/envs/diffhpe/lib/python3.9/site-packages/wandb/sdk/internal/internal_api.py", line 2190, in upload_file
    response.raise_for_status()
  File "/home/zhuhe/.conda/envs/diffhpe/lib/python3.9/site-packages/requests/models.py", line 1021, in raise_for_status
    raise HTTPError(http_error_msg, response=self)
requests.exceptions.HTTPError: 404 Client Error: Not Found for url: https://storage.googleapis.com/wandb-production.appspot.com/ada4321/DiffHPE/uerlbknf/conda-environment.yaml?Expires=1689058750&GoogleAccessId=gorilla-files-url-signer-man%40wandb-production.iam.gserviceaccount.com&Signature=mcofxEv4yPMALHfM7iF44gPI6vDf6VNFN1VNinpLz9YmobTAKG0axF5YgwFiCOxpankQ9vyO%2FFSgqtolZE58CbFvPefuHrOYXHPM5imBwpKqS%2FEFblIgv7U0%2FoUk8KGXHSN2dggDY%2B0QPS67wIwCWSf65hLKG%2FXnoR5AOkeU17FPgIT9K2MN%2BZUyRYd90iYEciGTUIWXV9WKUvym1axGl5Pj8sU7N2l%2FOq9LTyPVr5Aye0P6OlAmeHEzWj%2FmZ7ZVoDlWJt9naUHmUdsbj%2FBVvl5%2F5JpFt4Q0xQriZlvsl6qG8p7ayRK7Uif77SwEXFKLrL0wiFmoW3%2BV79r1sRPvow%3D%3D

During handling of the above exception, another exception occurred:

Traceback (most recent call last):
  File "/home/zhuhe/.conda/envs/diffhpe/lib/python3.9/site-packages/wandb/filesync/upload_job.py", line 127, in push
    self._api.upload_file_retry(
  File "/home/zhuhe/.conda/envs/diffhpe/lib/python3.9/site-packages/wandb/apis/normalize.py", line 51, in wrapper
    raise CommError(message, error)
wandb.errors.CommError: <Response [404]>
2023-07-10 14:59:12,785 ERROR   Thread-11 :33349 [step_upload.py:_handle_event():200] Failed to upload file: /home/zhuhe/HPE-with-Diffusion/wandb/run-20230710_145904-uerlbknf/files/config.yaml
Traceback (most recent call last):
  File "/home/zhuhe/.conda/envs/diffhpe/lib/python3.9/site-packages/wandb/apis/normalize.py", line 41, in wrapper
    return func(*args, **kwargs)
  File "/home/zhuhe/.conda/envs/diffhpe/lib/python3.9/site-packages/wandb/sdk/lib/retry.py", line 212, in wrapped_fn
    return retrier(*args, **kargs)
  File "/home/zhuhe/.conda/envs/diffhpe/lib/python3.9/site-packages/wandb/sdk/lib/retry.py", line 131, in __call__
    result = self._call_fn(*args, **kwargs)
  File "/home/zhuhe/.conda/envs/diffhpe/lib/python3.9/site-packages/wandb/sdk/internal/internal_api.py", line 2218, in upload_file
    wandb._sentry.reraise(e)
  File "/home/zhuhe/.conda/envs/diffhpe/lib/python3.9/site-packages/wandb/analytics/sentry.py", line 146, in reraise
    raise exc.with_traceback(sys.exc_info()[2])
  File "/home/zhuhe/.conda/envs/diffhpe/lib/python3.9/site-packages/wandb/sdk/internal/internal_api.py", line 2190, in upload_file
    response.raise_for_status()
  File "/home/zhuhe/.conda/envs/diffhpe/lib/python3.9/site-packages/requests/models.py", line 1021, in raise_for_status
    raise HTTPError(http_error_msg, response=self)
requests.exceptions.HTTPError: 404 Client Error: Not Found for url: https://storage.googleapis.com/wandb-production.appspot.com/ada4321/DiffHPE/uerlbknf/config.yaml?Expires=1689058750&GoogleAccessId=gorilla-files-url-signer-man%40wandb-production.iam.gserviceaccount.com&Signature=rnWQoqwvgF%2BG0SsxFzM3%2Bty8eExoCNLAMgnJqni8JBRwaWBBrGzelhHutmiTwvpU4N1GdGIvsTGHh4vMgLi%2BhhyPBNOMIbZQnzqdJWeg3cGdxfZ0uz4iSBIR3%2BMGu621Uqk05wcF9CahuI%2BJkHrgK9ketTT%2F6%2FWkBiLmvG02Nqc4ovWvtjlhFpDI86zf%2FmW7Q8RFn4MjBBB2HsRzT7TJYNq3TRcshJ0rkohf1rmtl2%2FHfhL%2FgM28pRxx29XqoMeLwP61QdiwYziag3ED9qplXU3se9cHuJPd0qU3dAf82HsNZGPS%2BwouPqtzQQLGqAwEnlp4NiOfiOu5UkdjgBmV1Q%3D%3D

During handling of the above exception, another exception occurred:

Traceback (most recent call last):
  File "/home/zhuhe/.conda/envs/diffhpe/lib/python3.9/concurrent/futures/thread.py", line 58, in run
    result = self.fn(*self.args, **self.kwargs)
  File "/home/zhuhe/.conda/envs/diffhpe/lib/python3.9/site-packages/wandb/filesync/step_upload.py", line 288, in run_and_notify
    self._do_upload_sync(event)
  File "/home/zhuhe/.conda/envs/diffhpe/lib/python3.9/site-packages/wandb/filesync/step_upload.py", line 330, in _do_upload_sync
    job.run()
  File "/home/zhuhe/.conda/envs/diffhpe/lib/python3.9/site-packages/wandb/filesync/upload_job.py", line 57, in run
    self.push()
  File "/home/zhuhe/.conda/envs/diffhpe/lib/python3.9/site-packages/wandb/filesync/upload_job.py", line 127, in push
    self._api.upload_file_retry(
  File "/home/zhuhe/.conda/envs/diffhpe/lib/python3.9/site-packages/wandb/apis/normalize.py", line 51, in wrapper
    raise CommError(message, error)
wandb.errors.CommError: <Response [404]>
2023-07-10 14:59:12,785 ERROR   Thread-11 :33349 [step_upload.py:_handle_event():200] Failed to upload file: /home/zhuhe/HPE-with-Diffusion/wandb/run-20230710_145904-uerlbknf/files/wandb-summary.json
Traceback (most recent call last):
  File "/home/zhuhe/.conda/envs/diffhpe/lib/python3.9/site-packages/wandb/apis/normalize.py", line 41, in wrapper
    return func(*args, **kwargs)
  File "/home/zhuhe/.conda/envs/diffhpe/lib/python3.9/site-packages/wandb/sdk/lib/retry.py", line 212, in wrapped_fn
    return retrier(*args, **kargs)
  File "/home/zhuhe/.conda/envs/diffhpe/lib/python3.9/site-packages/wandb/sdk/lib/retry.py", line 131, in __call__
    result = self._call_fn(*args, **kwargs)
  File "/home/zhuhe/.conda/envs/diffhpe/lib/python3.9/site-packages/wandb/sdk/internal/internal_api.py", line 2218, in upload_file
    wandb._sentry.reraise(e)
  File "/home/zhuhe/.conda/envs/diffhpe/lib/python3.9/site-packages/wandb/analytics/sentry.py", line 146, in reraise
    raise exc.with_traceback(sys.exc_info()[2])
  File "/home/zhuhe/.conda/envs/diffhpe/lib/python3.9/site-packages/wandb/sdk/internal/internal_api.py", line 2190, in upload_file
    response.raise_for_status()
  File "/home/zhuhe/.conda/envs/diffhpe/lib/python3.9/site-packages/requests/models.py", line 1021, in raise_for_status
    raise HTTPError(http_error_msg, response=self)
requests.exceptions.HTTPError: 404 Client Error: Not Found for url: https://storage.googleapis.com/wandb-production.appspot.com/ada4321/DiffHPE/uerlbknf/wandb-summary.json?Expires=1689058750&GoogleAccessId=gorilla-files-url-signer-man%40wandb-production.iam.gserviceaccount.com&Signature=QuRtvNtgqmSDj5B5SYem743ouxSgMNQVhdan9hTXYS4pgwL3UT%2FMdU6W1I%2BVPJMLuPezqo5X7tXDdpZsbnDqt%2Bl2JleA%2BR%2Fek3%2Bzr0%2BnSRfBoPhVU9nLQaJNwRpqdTyHQBodmGdCL1LFUFdeKli17HT54kTIiFmdRxX6FX4JsCJbQhKhxfCBGOSxMh8QTRlTHxkQW%2BUyERfjg4EmNpI6OdWNikLYlNIeHcEy6w7wnMNylLqHTbUoIstJuuVOlSVsB3NInJ8FL08UhLpYRq%2BA942l2WZ1Lo1VoObZErIiN4t33fizzg1fl5X3w3g6yMMaEmYSrqE2soOOX7HI92gkIw%3D%3D

During handling of the above exception, another exception occurred:

Traceback (most recent call last):
  File "/home/zhuhe/.conda/envs/diffhpe/lib/python3.9/concurrent/futures/thread.py", line 58, in run
    result = self.fn(*self.args, **self.kwargs)
  File "/home/zhuhe/.conda/envs/diffhpe/lib/python3.9/site-packages/wandb/filesync/step_upload.py", line 288, in run_and_notify
    self._do_upload_sync(event)
  File "/home/zhuhe/.conda/envs/diffhpe/lib/python3.9/site-packages/wandb/filesync/step_upload.py", line 330, in _do_upload_sync
    job.run()
  File "/home/zhuhe/.conda/envs/diffhpe/lib/python3.9/site-packages/wandb/filesync/upload_job.py", line 57, in run
    self.push()
  File "/home/zhuhe/.conda/envs/diffhpe/lib/python3.9/site-packages/wandb/filesync/upload_job.py", line 127, in push
    self._api.upload_file_retry(
  File "/home/zhuhe/.conda/envs/diffhpe/lib/python3.9/site-packages/wandb/apis/normalize.py", line 51, in wrapper
    raise CommError(message, error)
wandb.errors.CommError: <Response [404]>
2023-07-10 14:59:12,786 ERROR   Thread-11 :33349 [step_upload.py:_handle_event():200] Failed to upload file: /home/zhuhe/HPE-with-Diffusion/wandb/run-20230710_145904-uerlbknf/files/output.log
Traceback (most recent call last):
  File "/home/zhuhe/.conda/envs/diffhpe/lib/python3.9/site-packages/wandb/apis/normalize.py", line 41, in wrapper
    return func(*args, **kwargs)
  File "/home/zhuhe/.conda/envs/diffhpe/lib/python3.9/site-packages/wandb/sdk/lib/retry.py", line 212, in wrapped_fn
    return retrier(*args, **kargs)
  File "/home/zhuhe/.conda/envs/diffhpe/lib/python3.9/site-packages/wandb/sdk/lib/retry.py", line 131, in __call__
    result = self._call_fn(*args, **kwargs)
  File "/home/zhuhe/.conda/envs/diffhpe/lib/python3.9/site-packages/wandb/sdk/internal/internal_api.py", line 2218, in upload_file
    wandb._sentry.reraise(e)
  File "/home/zhuhe/.conda/envs/diffhpe/lib/python3.9/site-packages/wandb/analytics/sentry.py", line 146, in reraise
    raise exc.with_traceback(sys.exc_info()[2])
  File "/home/zhuhe/.conda/envs/diffhpe/lib/python3.9/site-packages/wandb/sdk/internal/internal_api.py", line 2190, in upload_file
    response.raise_for_status()
  File "/home/zhuhe/.conda/envs/diffhpe/lib/python3.9/site-packages/requests/models.py", line 1021, in raise_for_status
    raise HTTPError(http_error_msg, response=self)
requests.exceptions.HTTPError: 404 Client Error: Not Found for url: https://storage.googleapis.com/wandb-production.appspot.com/ada4321/DiffHPE/uerlbknf/output.log?Expires=1689058750&GoogleAccessId=gorilla-files-url-signer-man%40wandb-production.iam.gserviceaccount.com&Signature=YrjoGGR6RGcxcFOgYvddWVGquHpDNp6rK37Pj%2FmW56pyU4Q0NP5KwCuCx1AGc5Rd0sa5aoMsNT6gVnnyuVEYoxKPqH%2F%2BbuDmcWDwICLK5r2ysEWFACk4qlpRJz1dwytsDkMPpQK1X6GcCydTsktzyLtMaMI3f4D9ktV977WYxDVeEGf4OukzH52aT0waQgsBEnCKnWr%2FW%2BCw8KHUSpc39JeeTHxDFlPriy38pVI%2FRvFuxPwReh4Uf%2Bjy7WyORkbt2DrQAqK%2F6D9Fkjv60rBUjebmbnN5vzcAIl1c%2F4jZDF9a3aKC9BQeg9hzAz3GVcx4lekknFq8cI5FM1fZS2a%2BNA%3D%3D

During handling of the above exception, another exception occurred:

Traceback (most recent call last):
  File "/home/zhuhe/.conda/envs/diffhpe/lib/python3.9/concurrent/futures/thread.py", line 58, in run
    result = self.fn(*self.args, **self.kwargs)
  File "/home/zhuhe/.conda/envs/diffhpe/lib/python3.9/site-packages/wandb/filesync/step_upload.py", line 288, in run_and_notify
    self._do_upload_sync(event)
  File "/home/zhuhe/.conda/envs/diffhpe/lib/python3.9/site-packages/wandb/filesync/step_upload.py", line 330, in _do_upload_sync
    job.run()
  File "/home/zhuhe/.conda/envs/diffhpe/lib/python3.9/site-packages/wandb/filesync/upload_job.py", line 57, in run
    self.push()
  File "/home/zhuhe/.conda/envs/diffhpe/lib/python3.9/site-packages/wandb/filesync/upload_job.py", line 127, in push
    self._api.upload_file_retry(
  File "/home/zhuhe/.conda/envs/diffhpe/lib/python3.9/site-packages/wandb/apis/normalize.py", line 51, in wrapper
    raise CommError(message, error)
wandb.errors.CommError: <Response [404]>
2023-07-10 14:59:12,786 ERROR   Thread-11 :33349 [step_upload.py:_handle_event():200] Failed to upload file: /home/zhuhe/HPE-with-Diffusion/wandb/run-20230710_145904-uerlbknf/files/conda-environment.yaml
Traceback (most recent call last):
  File "/home/zhuhe/.conda/envs/diffhpe/lib/python3.9/site-packages/wandb/apis/normalize.py", line 41, in wrapper
    return func(*args, **kwargs)
  File "/home/zhuhe/.conda/envs/diffhpe/lib/python3.9/site-packages/wandb/sdk/lib/retry.py", line 212, in wrapped_fn
    return retrier(*args, **kargs)
  File "/home/zhuhe/.conda/envs/diffhpe/lib/python3.9/site-packages/wandb/sdk/lib/retry.py", line 131, in __call__
    result = self._call_fn(*args, **kwargs)
  File "/home/zhuhe/.conda/envs/diffhpe/lib/python3.9/site-packages/wandb/sdk/internal/internal_api.py", line 2218, in upload_file
    wandb._sentry.reraise(e)
  File "/home/zhuhe/.conda/envs/diffhpe/lib/python3.9/site-packages/wandb/analytics/sentry.py", line 146, in reraise
    raise exc.with_traceback(sys.exc_info()[2])
  File "/home/zhuhe/.conda/envs/diffhpe/lib/python3.9/site-packages/wandb/sdk/internal/internal_api.py", line 2190, in upload_file
    response.raise_for_status()
  File "/home/zhuhe/.conda/envs/diffhpe/lib/python3.9/site-packages/requests/models.py", line 1021, in raise_for_status
    raise HTTPError(http_error_msg, response=self)
requests.exceptions.HTTPError: 404 Client Error: Not Found for url: https://storage.googleapis.com/wandb-production.appspot.com/ada4321/DiffHPE/uerlbknf/conda-environment.yaml?Expires=1689058750&GoogleAccessId=gorilla-files-url-signer-man%40wandb-production.iam.gserviceaccount.com&Signature=mcofxEv4yPMALHfM7iF44gPI6vDf6VNFN1VNinpLz9YmobTAKG0axF5YgwFiCOxpankQ9vyO%2FFSgqtolZE58CbFvPefuHrOYXHPM5imBwpKqS%2FEFblIgv7U0%2FoUk8KGXHSN2dggDY%2B0QPS67wIwCWSf65hLKG%2FXnoR5AOkeU17FPgIT9K2MN%2BZUyRYd90iYEciGTUIWXV9WKUvym1axGl5Pj8sU7N2l%2FOq9LTyPVr5Aye0P6OlAmeHEzWj%2FmZ7ZVoDlWJt9naUHmUdsbj%2FBVvl5%2F5JpFt4Q0xQriZlvsl6qG8p7ayRK7Uif77SwEXFKLrL0wiFmoW3%2BV79r1sRPvow%3D%3D

During handling of the above exception, another exception occurred:

Traceback (most recent call last):
  File "/home/zhuhe/.conda/envs/diffhpe/lib/python3.9/concurrent/futures/thread.py", line 58, in run
    result = self.fn(*self.args, **self.kwargs)
  File "/home/zhuhe/.conda/envs/diffhpe/lib/python3.9/site-packages/wandb/filesync/step_upload.py", line 288, in run_and_notify
    self._do_upload_sync(event)
  File "/home/zhuhe/.conda/envs/diffhpe/lib/python3.9/site-packages/wandb/filesync/step_upload.py", line 330, in _do_upload_sync
    job.run()
  File "/home/zhuhe/.conda/envs/diffhpe/lib/python3.9/site-packages/wandb/filesync/upload_job.py", line 57, in run
    self.push()
  File "/home/zhuhe/.conda/envs/diffhpe/lib/python3.9/site-packages/wandb/filesync/upload_job.py", line 127, in push
    self._api.upload_file_retry(
  File "/home/zhuhe/.conda/envs/diffhpe/lib/python3.9/site-packages/wandb/apis/normalize.py", line 51, in wrapper
    raise CommError(message, error)
wandb.errors.CommError: <Response [404]>
2023-07-10 14:59:12,786 ERROR   Thread-11 :33349 [step_upload.py:_handle_event():200] Failed to upload file: /home/zhuhe/HPE-with-Diffusion/wandb/run-20230710_145904-uerlbknf/files/requirements.txt
Traceback (most recent call last):
  File "/home/zhuhe/.conda/envs/diffhpe/lib/python3.9/site-packages/wandb/apis/normalize.py", line 41, in wrapper
    return func(*args, **kwargs)
  File "/home/zhuhe/.conda/envs/diffhpe/lib/python3.9/site-packages/wandb/sdk/lib/retry.py", line 212, in wrapped_fn
    return retrier(*args, **kargs)
  File "/home/zhuhe/.conda/envs/diffhpe/lib/python3.9/site-packages/wandb/sdk/lib/retry.py", line 131, in __call__
    result = self._call_fn(*args, **kwargs)
  File "/home/zhuhe/.conda/envs/diffhpe/lib/python3.9/site-packages/wandb/sdk/internal/internal_api.py", line 2218, in upload_file
    wandb._sentry.reraise(e)
  File "/home/zhuhe/.conda/envs/diffhpe/lib/python3.9/site-packages/wandb/analytics/sentry.py", line 146, in reraise
    raise exc.with_traceback(sys.exc_info()[2])
  File "/home/zhuhe/.conda/envs/diffhpe/lib/python3.9/site-packages/wandb/sdk/internal/internal_api.py", line 2190, in upload_file
    response.raise_for_status()
  File "/home/zhuhe/.conda/envs/diffhpe/lib/python3.9/site-packages/requests/models.py", line 1021, in raise_for_status
    raise HTTPError(http_error_msg, response=self)
requests.exceptions.HTTPError: 404 Client Error: Not Found for url: https://storage.googleapis.com/wandb-production.appspot.com/ada4321/DiffHPE/uerlbknf/requirements.txt?Expires=1689058750&GoogleAccessId=gorilla-files-url-signer-man%40wandb-production.iam.gserviceaccount.com&Signature=lxG4GoRGc39ftF8%2B6HCeSgAKCrrR4nc9lbZ6HaesM8k%2F88v2Z%2BiGgthEIFEylhvSkaOA7A8WncBoOrKtPtgeLwfscaeeH%2B5dJwB5c0bNPAUmBMgLW4nk0sxVqikA8E8%2FOx2r37al1AkefUp3SIRK5mb0px8pNDw%2FWLH4FErCoXMel0wwo5Ibk7%2F6HRodYf0tihtENwgdqg00TKDKvc9QryRM9Kr4aansy5lpxDM9NRx%2FbPuduqrQ3zsj6ZJK5mJ71TFnv4nJQ2DuBs0bOAO1NvB%2B96bz8KlMSAjpOzwtxOOW0hPY2OHqXi6sDgXiH%2FGWDqiM9zHPb63YWNq4lNbZ0w%3D%3D

During handling of the above exception, another exception occurred:

Traceback (most recent call last):
  File "/home/zhuhe/.conda/envs/diffhpe/lib/python3.9/concurrent/futures/thread.py", line 58, in run
    result = self.fn(*self.args, **self.kwargs)
  File "/home/zhuhe/.conda/envs/diffhpe/lib/python3.9/site-packages/wandb/filesync/step_upload.py", line 288, in run_and_notify
    self._do_upload_sync(event)
  File "/home/zhuhe/.conda/envs/diffhpe/lib/python3.9/site-packages/wandb/filesync/step_upload.py", line 330, in _do_upload_sync
    job.run()
  File "/home/zhuhe/.conda/envs/diffhpe/lib/python3.9/site-packages/wandb/filesync/upload_job.py", line 57, in run
    self.push()
  File "/home/zhuhe/.conda/envs/diffhpe/lib/python3.9/site-packages/wandb/filesync/upload_job.py", line 127, in push
    self._api.upload_file_retry(
  File "/home/zhuhe/.conda/envs/diffhpe/lib/python3.9/site-packages/wandb/apis/normalize.py", line 51, in wrapper
    raise CommError(message, error)
wandb.errors.CommError: <Response [404]>
2023-07-10 14:59:12,986 INFO    Thread-11 :33349 [sender.py:transition_state():602] send defer: 11
2023-07-10 14:59:12,986 DEBUG   HandlerThread:33349 [handler.py:handle_request():144] handle_request: defer
2023-07-10 14:59:12,986 INFO    HandlerThread:33349 [handler.py:handle_request_defer():170] handle defer: 11
2023-07-10 14:59:12,987 DEBUG   SenderThread:33349 [sender.py:send_request():396] send_request: defer
2023-07-10 14:59:12,987 INFO    SenderThread:33349 [sender.py:send_request_defer():598] handle sender defer: 11
2023-07-10 14:59:12,987 INFO    SenderThread:33349 [file_pusher.py:join():164] waiting for file pusher
2023-07-10 14:59:12,987 INFO    SenderThread:33349 [sender.py:transition_state():602] send defer: 12
2023-07-10 14:59:12,987 DEBUG   HandlerThread:33349 [handler.py:handle_request():144] handle_request: defer
2023-07-10 14:59:12,987 INFO    HandlerThread:33349 [handler.py:handle_request_defer():170] handle defer: 12
2023-07-10 14:59:12,987 DEBUG   SenderThread:33349 [sender.py:send_request():396] send_request: defer
2023-07-10 14:59:12,987 INFO    SenderThread:33349 [sender.py:send_request_defer():598] handle sender defer: 12
2023-07-10 14:59:13,179 DEBUG   HandlerThread:33349 [handler.py:handle_request():144] handle_request: keepalive
2023-07-10 14:59:13,250 INFO    SenderThread:33349 [sender.py:transition_state():602] send defer: 13
2023-07-10 14:59:13,251 DEBUG   HandlerThread:33349 [handler.py:handle_request():144] handle_request: defer
2023-07-10 14:59:13,251 INFO    HandlerThread:33349 [handler.py:handle_request_defer():170] handle defer: 13
2023-07-10 14:59:13,251 DEBUG   SenderThread:33349 [sender.py:send_request():396] send_request: defer
2023-07-10 14:59:13,251 INFO    SenderThread:33349 [sender.py:send_request_defer():598] handle sender defer: 13
2023-07-10 14:59:13,251 INFO    SenderThread:33349 [sender.py:transition_state():602] send defer: 14
2023-07-10 14:59:13,251 DEBUG   HandlerThread:33349 [handler.py:handle_request():144] handle_request: defer
2023-07-10 14:59:13,251 INFO    HandlerThread:33349 [handler.py:handle_request_defer():170] handle defer: 14
2023-07-10 14:59:13,251 DEBUG   SenderThread:33349 [sender.py:send():369] send: final
2023-07-10 14:59:13,251 DEBUG   SenderThread:33349 [sender.py:send():369] send: footer
2023-07-10 14:59:13,251 DEBUG   SenderThread:33349 [sender.py:send_request():396] send_request: defer
2023-07-10 14:59:13,251 INFO    SenderThread:33349 [sender.py:send_request_defer():598] handle sender defer: 14
2023-07-10 14:59:13,252 DEBUG   HandlerThread:33349 [handler.py:handle_request():144] handle_request: poll_exit
2023-07-10 14:59:13,252 DEBUG   HandlerThread:33349 [handler.py:handle_request():144] handle_request: server_info
2023-07-10 14:59:13,252 DEBUG   HandlerThread:33349 [handler.py:handle_request():144] handle_request: get_summary
2023-07-10 14:59:13,252 DEBUG   SenderThread:33349 [sender.py:send_request():396] send_request: poll_exit
2023-07-10 14:59:13,252 DEBUG   HandlerThread:33349 [handler.py:handle_request():144] handle_request: sampled_history
2023-07-10 14:59:13,253 DEBUG   SenderThread:33349 [sender.py:send_request():396] send_request: server_info
2023-07-10 14:59:13,694 INFO    MainThread:33349 [wandb_run.py:_footer_history_summary_info():3467] rendering history
2023-07-10 14:59:13,694 INFO    MainThread:33349 [wandb_run.py:_footer_history_summary_info():3499] rendering summary
2023-07-10 14:59:13,694 INFO    MainThread:33349 [wandb_run.py:_footer_sync_info():3426] logging synced files
2023-07-10 14:59:13,695 DEBUG   HandlerThread:33349 [handler.py:handle_request():144] handle_request: shutdown
2023-07-10 14:59:13,695 INFO    HandlerThread:33349 [handler.py:finish():854] shutting down handler
2023-07-10 14:59:14,252 INFO    WriterThread:33349 [datastore.py:close():298] close: /home/zhuhe/HPE-with-Diffusion/wandb/run-20230710_145904-uerlbknf/run-uerlbknf.wandb
2023-07-10 14:59:14,694 INFO    SenderThread:33349 [sender.py:finish():1526] shutting down sender
2023-07-10 14:59:14,694 INFO    SenderThread:33349 [file_pusher.py:finish():159] shutting down file pusher
2023-07-10 14:59:14,694 INFO    SenderThread:33349 [file_pusher.py:join():164] waiting for file pusher
