2023-07-10 15:41:37,462 INFO    StreamThr :46753 [internal.py:wandb_internal():86] W&B internal server running at pid: 46753, started at: 2023-07-10 15:41:37.462261
2023-07-10 15:41:37,463 DEBUG   HandlerThread:46753 [handler.py:handle_request():144] handle_request: status
2023-07-10 15:41:37,464 INFO    WriterThread:46753 [datastore.py:open_for_write():85] open: /home/zhuhe/HPE-with-Diffusion/wandb/run-20230710_154137-agz50rdx/run-agz50rdx.wandb
2023-07-10 15:41:37,465 DEBUG   SenderThread:46753 [sender.py:send():369] send: header
2023-07-10 15:41:37,465 DEBUG   SenderThread:46753 [sender.py:send():369] send: run
2023-07-10 15:41:38,259 INFO    SenderThread:46753 [dir_watcher.py:__init__():211] watching files in: /home/zhuhe/HPE-with-Diffusion/wandb/run-20230710_154137-agz50rdx/files
2023-07-10 15:41:38,259 INFO    SenderThread:46753 [sender.py:_start_run_threads():1100] run started: agz50rdx with start time 1688974897.461954
2023-07-10 15:41:38,259 DEBUG   SenderThread:46753 [sender.py:send_request():396] send_request: summary_record
2023-07-10 15:41:38,259 INFO    SenderThread:46753 [sender.py:_save_file():1354] saving file wandb-summary.json with policy end
2023-07-10 15:41:38,262 DEBUG   HandlerThread:46753 [handler.py:handle_request():144] handle_request: check_version
2023-07-10 15:41:38,262 DEBUG   SenderThread:46753 [sender.py:send_request():396] send_request: check_version
2023-07-10 15:41:38,445 DEBUG   HandlerThread:46753 [handler.py:handle_request():144] handle_request: run_start
2023-07-10 15:41:38,449 DEBUG   HandlerThread:46753 [system_info.py:__init__():31] System info init
2023-07-10 15:41:38,449 DEBUG   HandlerThread:46753 [system_info.py:__init__():46] System info init done
2023-07-10 15:41:38,449 INFO    HandlerThread:46753 [system_monitor.py:start():181] Starting system monitor
2023-07-10 15:41:38,449 INFO    SystemMonitor:46753 [system_monitor.py:_start():145] Starting system asset monitoring threads
2023-07-10 15:41:38,449 INFO    HandlerThread:46753 [system_monitor.py:probe():201] Collecting system info
2023-07-10 15:41:38,450 INFO    SystemMonitor:46753 [interfaces.py:start():190] Started cpu monitoring
2023-07-10 15:41:38,450 INFO    SystemMonitor:46753 [interfaces.py:start():190] Started disk monitoring
2023-07-10 15:41:38,451 INFO    SystemMonitor:46753 [interfaces.py:start():190] Started gpu monitoring
2023-07-10 15:41:38,451 INFO    SystemMonitor:46753 [interfaces.py:start():190] Started memory monitoring
2023-07-10 15:41:38,451 INFO    SystemMonitor:46753 [interfaces.py:start():190] Started network monitoring
2023-07-10 15:41:38,465 DEBUG   HandlerThread:46753 [system_info.py:probe():195] Probing system
2023-07-10 15:41:38,468 DEBUG   HandlerThread:46753 [gitlib.py:_init_repo():53] git repository is invalid
2023-07-10 15:41:38,468 DEBUG   HandlerThread:46753 [system_info.py:probe():240] Probing system done
2023-07-10 15:41:38,468 DEBUG   HandlerThread:46753 [system_monitor.py:probe():210] {'os': 'Linux-5.19.0-46-generic-x86_64-with-glibc2.35', 'python': '3.9.16', 'heartbeatAt': '2023-07-10T07:41:38.465185', 'startedAt': '2023-07-10T07:41:37.458894', 'docker': None, 'cuda': None, 'args': ('--phase', 'train', '--gpu_ids', '1'), 'state': 'running', 'program': '/home/zhuhe/HPE-with-Diffusion/main.py', 'codePath': 'main.py', 'host': '415-2', 'username': 'zhuhe', 'executable': '/home/zhuhe/.conda/envs/diffhpe/bin/python', 'cpu_count': 16, 'cpu_count_logical': 24, 'cpu_freq': {'current': 3664.3554583333334, 'min': 800.0, 'max': 4783.333333333333}, 'cpu_freq_per_core': [{'current': 5104.602, 'min': 800.0, 'max': 5100.0}, {'current': 5110.2, 'min': 800.0, 'max': 5100.0}, {'current': 5035.151, 'min': 800.0, 'max': 5100.0}, {'current': 5100.0, 'min': 800.0, 'max': 5100.0}, {'current': 2100.0, 'min': 800.0, 'max': 5100.0}, {'current': 5100.0, 'min': 800.0, 'max': 5100.0}, {'current': 5100.0, 'min': 800.0, 'max': 5100.0}, {'current': 2100.0, 'min': 800.0, 'max': 5100.0}, {'current': 5100.0, 'min': 800.0, 'max': 5200.0}, {'current': 2100.0, 'min': 800.0, 'max': 5200.0}, {'current': 5099.889, 'min': 800.0, 'max': 5200.0}, {'current': 2100.0, 'min': 800.0, 'max': 5200.0}, {'current': 5100.0, 'min': 800.0, 'max': 5100.0}, {'current': 5100.0, 'min': 800.0, 'max': 5100.0}, {'current': 5110.782, 'min': 800.0, 'max': 5100.0}, {'current': 5100.0, 'min': 800.0, 'max': 5100.0}, {'current': 2100.0, 'min': 800.0, 'max': 4100.0}, {'current': 2100.0, 'min': 800.0, 'max': 4100.0}, {'current': 2100.0, 'min': 800.0, 'max': 4100.0}, {'current': 2100.0, 'min': 800.0, 'max': 4100.0}, {'current': 2100.0, 'min': 800.0, 'max': 4100.0}, {'current': 2100.0, 'min': 800.0, 'max': 4100.0}, {'current': 2100.0, 'min': 800.0, 'max': 4100.0}, {'current': 2100.0, 'min': 800.0, 'max': 4100.0}], 'disk': {'total': 93.31179428100586, 'used': 0.01844024658203125}, 'gpu': 'NVIDIA GeForce RTX 3090', 'gpu_count': 2, 'gpu_devices': [{'name': 'NVIDIA GeForce RTX 3090', 'memory_total': 25769803776}, {'name': 'NVIDIA GeForce RTX 3090', 'memory_total': 25769803776}], 'memory': {'total': 31.185562133789062}}
2023-07-10 15:41:38,469 INFO    HandlerThread:46753 [system_monitor.py:probe():211] Finished collecting system info
2023-07-10 15:41:38,469 INFO    HandlerThread:46753 [system_monitor.py:probe():214] Publishing system info
2023-07-10 15:41:38,469 DEBUG   HandlerThread:46753 [system_info.py:_save_pip():51] Saving list of pip packages installed into the current environment
2023-07-10 15:41:38,469 DEBUG   HandlerThread:46753 [system_info.py:_save_pip():67] Saving pip packages done
2023-07-10 15:41:38,469 DEBUG   HandlerThread:46753 [system_info.py:_save_conda():74] Saving list of conda packages installed into the current environment
2023-07-10 15:41:39,260 INFO    Thread-12 :46753 [dir_watcher.py:_on_file_created():272] file/dir created: /home/zhuhe/HPE-with-Diffusion/wandb/run-20230710_154137-agz50rdx/files/conda-environment.yaml
2023-07-10 15:41:39,261 INFO    Thread-12 :46753 [dir_watcher.py:_on_file_created():272] file/dir created: /home/zhuhe/HPE-with-Diffusion/wandb/run-20230710_154137-agz50rdx/files/wandb-summary.json
2023-07-10 15:41:39,261 INFO    Thread-12 :46753 [dir_watcher.py:_on_file_created():272] file/dir created: /home/zhuhe/HPE-with-Diffusion/wandb/run-20230710_154137-agz50rdx/files/requirements.txt
2023-07-10 15:41:39,322 DEBUG   HandlerThread:46753 [system_info.py:_save_conda():86] Saving conda packages done
2023-07-10 15:41:39,322 INFO    HandlerThread:46753 [system_monitor.py:probe():216] Finished publishing system info
2023-07-10 15:41:39,324 DEBUG   SenderThread:46753 [sender.py:send():369] send: files
2023-07-10 15:41:39,324 INFO    SenderThread:46753 [sender.py:_save_file():1354] saving file wandb-metadata.json with policy now
2023-07-10 15:41:39,327 DEBUG   HandlerThread:46753 [handler.py:handle_request():144] handle_request: stop_status
2023-07-10 15:41:39,328 DEBUG   SenderThread:46753 [sender.py:send_request():396] send_request: stop_status
2023-07-10 15:41:39,815 ERROR   wandb-upload_0:46753 [internal_api.py:upload_file():2192] upload_file exception https://storage.googleapis.com/wandb-production.appspot.com/ada4321/DiffHPE/agz50rdx/wandb-metadata.json?Expires=1689061299&GoogleAccessId=gorilla-files-url-signer-man%40wandb-production.iam.gserviceaccount.com&Signature=mM9vtLn%2BD3BpIomcZJD6R5kCTQb%2FLR6h4e283loMMc1tHTegoQQIsyv%2BToW1epmSDD%2BD8O8vIR8jGyDvtnXfHqc3plBry5nm0R2c74wUqcNlHTG6c71b%2BvJ6UP3x5LRsTDP6i%2FZQG6VNznK5BV1zQFzz46EcApn6A8MwT1WaVAonP3gmbYWLz2x4lcHsnWoY6R8inBx2Ti0WrtxBvBplbImYBT11CqpRb97BRYpiG4%2B1Et7ERrdDXhBH00kdnyXNT9AFP%2FHR0yNkhbo6LZrR99Y3PFavqczKlQMQz8yUcOBh%2FkvVJs57UxUFwZ3Yo%2Fv%2B5GadqeFflCAwwAuTNNHkhw%3D%3D: 404 Client Error: Not Found for url: https://storage.googleapis.com/wandb-production.appspot.com/ada4321/DiffHPE/agz50rdx/wandb-metadata.json?Expires=1689061299&GoogleAccessId=gorilla-files-url-signer-man%40wandb-production.iam.gserviceaccount.com&Signature=mM9vtLn%2BD3BpIomcZJD6R5kCTQb%2FLR6h4e283loMMc1tHTegoQQIsyv%2BToW1epmSDD%2BD8O8vIR8jGyDvtnXfHqc3plBry5nm0R2c74wUqcNlHTG6c71b%2BvJ6UP3x5LRsTDP6i%2FZQG6VNznK5BV1zQFzz46EcApn6A8MwT1WaVAonP3gmbYWLz2x4lcHsnWoY6R8inBx2Ti0WrtxBvBplbImYBT11CqpRb97BRYpiG4%2B1Et7ERrdDXhBH00kdnyXNT9AFP%2FHR0yNkhbo6LZrR99Y3PFavqczKlQMQz8yUcOBh%2FkvVJs57UxUFwZ3Yo%2Fv%2B5GadqeFflCAwwAuTNNHkhw%3D%3D
2023-07-10 15:41:39,815 ERROR   wandb-upload_0:46753 [internal_api.py:upload_file():2194] upload_file request headers: {'User-Agent': 'python-requests/2.31.0', 'Accept-Encoding': 'gzip, deflate', 'Accept': '*/*', 'Connection': 'keep-alive', 'Content-Length': '3687'}
2023-07-10 15:41:39,815 ERROR   wandb-upload_0:46753 [internal_api.py:upload_file():2196] upload_file response body: b'<!DOCTYPE html>\n<html lang=en>\n  <meta charset=utf-8>\n  <meta name=viewport content="initial-scale=1, minimum-scale=1, width=device-width">\n  <title>Error 404 (Not Found)!!1</title>\n  <style>\n    *{margin:0;padding:0}html,code{font:15px/22px arial,sans-serif}html{background:#fff;color:#222;padding:15px}body{margin:7% auto 0;max-width:390px;min-height:180px;padding:30px 0 15px}* > body{background:url(//www.google.com/images/errors/robot.png) 100% 5px no-repeat;padding-right:205px}p{margin:11px 0 22px;overflow:hidden}ins{color:#777;text-decoration:none}a img{border:0}@media screen and (max-width:772px){body{background:none;margin-top:0;max-width:none;padding-right:0}}#logo{background:url(//www.google.com/images/branding/googlelogo/1x/googlelogo_color_150x54dp.png) no-repeat;margin-left:-5px}@media only screen and (min-resolution:192dpi){#logo{background:url(//www.google.com/images/branding/googlelogo/2x/googlelogo_color_150x54dp.png) no-repeat 0% 0%/100% 100%;-moz-border-image:url(//www.google.com/images/branding/googlelogo/2x/googlelogo_color_150x54dp.png) 0}}@media only screen and (-webkit-min-device-pixel-ratio:2){#logo{background:url(//www.google.com/images/branding/googlelogo/2x/googlelogo_color_150x54dp.png) no-repeat;-webkit-background-size:100% 100%}}#logo{display:inline-block;height:54px;width:150px}\n  </style>\n  <a href=//www.google.com/><span id=logo aria-label=Google></span></a>\n  <p><b>404.</b> <ins>That\xe2\x80\x99s an error.</ins>\n  <p>The requested URL <code>/wandb-production.appspot.com/ada4321/DiffHPE/agz50rdx/wandb-metadata.json</code> was not found on this server.  <ins>That\xe2\x80\x99s all we know.</ins>\n'
2023-07-10 15:41:39,901 DEBUG   SenderThread:46753 [sender.py:send():369] send: telemetry
2023-07-10 15:41:40,260 INFO    Thread-12 :46753 [dir_watcher.py:_on_file_created():272] file/dir created: /home/zhuhe/HPE-with-Diffusion/wandb/run-20230710_154137-agz50rdx/files/output.log
2023-07-10 15:41:40,260 INFO    Thread-12 :46753 [dir_watcher.py:_on_file_created():272] file/dir created: /home/zhuhe/HPE-with-Diffusion/wandb/run-20230710_154137-agz50rdx/files/wandb-metadata.json
2023-07-10 15:41:40,387 ERROR   wandb-upload_0:46753 [upload_job.py:push():136] Failed to upload file: /tmp/tmpfccaoh2hwandb/wccok2tk-wandb-metadata.json
Traceback (most recent call last):
  File "/home/zhuhe/.conda/envs/diffhpe/lib/python3.9/site-packages/wandb/apis/normalize.py", line 41, in wrapper
    return func(*args, **kwargs)
  File "/home/zhuhe/.conda/envs/diffhpe/lib/python3.9/site-packages/wandb/sdk/lib/retry.py", line 212, in wrapped_fn
    return retrier(*args, **kargs)
  File "/home/zhuhe/.conda/envs/diffhpe/lib/python3.9/site-packages/wandb/sdk/lib/retry.py", line 131, in __call__
    result = self._call_fn(*args, **kwargs)
  File "/home/zhuhe/.conda/envs/diffhpe/lib/python3.9/site-packages/wandb/sdk/internal/internal_api.py", line 2218, in upload_file
    wandb._sentry.reraise(e)
  File "/home/zhuhe/.conda/envs/diffhpe/lib/python3.9/site-packages/wandb/analytics/sentry.py", line 146, in reraise
    raise exc.with_traceback(sys.exc_info()[2])
  File "/home/zhuhe/.conda/envs/diffhpe/lib/python3.9/site-packages/wandb/sdk/internal/internal_api.py", line 2190, in upload_file
    response.raise_for_status()
  File "/home/zhuhe/.conda/envs/diffhpe/lib/python3.9/site-packages/requests/models.py", line 1021, in raise_for_status
    raise HTTPError(http_error_msg, response=self)
requests.exceptions.HTTPError: 404 Client Error: Not Found for url: https://storage.googleapis.com/wandb-production.appspot.com/ada4321/DiffHPE/agz50rdx/wandb-metadata.json?Expires=1689061299&GoogleAccessId=gorilla-files-url-signer-man%40wandb-production.iam.gserviceaccount.com&Signature=mM9vtLn%2BD3BpIomcZJD6R5kCTQb%2FLR6h4e283loMMc1tHTegoQQIsyv%2BToW1epmSDD%2BD8O8vIR8jGyDvtnXfHqc3plBry5nm0R2c74wUqcNlHTG6c71b%2BvJ6UP3x5LRsTDP6i%2FZQG6VNznK5BV1zQFzz46EcApn6A8MwT1WaVAonP3gmbYWLz2x4lcHsnWoY6R8inBx2Ti0WrtxBvBplbImYBT11CqpRb97BRYpiG4%2B1Et7ERrdDXhBH00kdnyXNT9AFP%2FHR0yNkhbo6LZrR99Y3PFavqczKlQMQz8yUcOBh%2FkvVJs57UxUFwZ3Yo%2Fv%2B5GadqeFflCAwwAuTNNHkhw%3D%3D

During handling of the above exception, another exception occurred:

Traceback (most recent call last):
  File "/home/zhuhe/.conda/envs/diffhpe/lib/python3.9/site-packages/wandb/filesync/upload_job.py", line 127, in push
    self._api.upload_file_retry(
  File "/home/zhuhe/.conda/envs/diffhpe/lib/python3.9/site-packages/wandb/apis/normalize.py", line 51, in wrapper
    raise CommError(message, error)
wandb.errors.CommError: <Response [404]>
2023-07-10 15:41:40,608 ERROR   Thread-11 :46753 [step_upload.py:_handle_event():200] Failed to upload file: /tmp/tmpfccaoh2hwandb/wccok2tk-wandb-metadata.json
Traceback (most recent call last):
  File "/home/zhuhe/.conda/envs/diffhpe/lib/python3.9/site-packages/wandb/apis/normalize.py", line 41, in wrapper
    return func(*args, **kwargs)
  File "/home/zhuhe/.conda/envs/diffhpe/lib/python3.9/site-packages/wandb/sdk/lib/retry.py", line 212, in wrapped_fn
    return retrier(*args, **kargs)
  File "/home/zhuhe/.conda/envs/diffhpe/lib/python3.9/site-packages/wandb/sdk/lib/retry.py", line 131, in __call__
    result = self._call_fn(*args, **kwargs)
  File "/home/zhuhe/.conda/envs/diffhpe/lib/python3.9/site-packages/wandb/sdk/internal/internal_api.py", line 2218, in upload_file
    wandb._sentry.reraise(e)
  File "/home/zhuhe/.conda/envs/diffhpe/lib/python3.9/site-packages/wandb/analytics/sentry.py", line 146, in reraise
    raise exc.with_traceback(sys.exc_info()[2])
  File "/home/zhuhe/.conda/envs/diffhpe/lib/python3.9/site-packages/wandb/sdk/internal/internal_api.py", line 2190, in upload_file
    response.raise_for_status()
  File "/home/zhuhe/.conda/envs/diffhpe/lib/python3.9/site-packages/requests/models.py", line 1021, in raise_for_status
    raise HTTPError(http_error_msg, response=self)
requests.exceptions.HTTPError: 404 Client Error: Not Found for url: https://storage.googleapis.com/wandb-production.appspot.com/ada4321/DiffHPE/agz50rdx/wandb-metadata.json?Expires=1689061299&GoogleAccessId=gorilla-files-url-signer-man%40wandb-production.iam.gserviceaccount.com&Signature=mM9vtLn%2BD3BpIomcZJD6R5kCTQb%2FLR6h4e283loMMc1tHTegoQQIsyv%2BToW1epmSDD%2BD8O8vIR8jGyDvtnXfHqc3plBry5nm0R2c74wUqcNlHTG6c71b%2BvJ6UP3x5LRsTDP6i%2FZQG6VNznK5BV1zQFzz46EcApn6A8MwT1WaVAonP3gmbYWLz2x4lcHsnWoY6R8inBx2Ti0WrtxBvBplbImYBT11CqpRb97BRYpiG4%2B1Et7ERrdDXhBH00kdnyXNT9AFP%2FHR0yNkhbo6LZrR99Y3PFavqczKlQMQz8yUcOBh%2FkvVJs57UxUFwZ3Yo%2Fv%2B5GadqeFflCAwwAuTNNHkhw%3D%3D

During handling of the above exception, another exception occurred:

Traceback (most recent call last):
  File "/home/zhuhe/.conda/envs/diffhpe/lib/python3.9/concurrent/futures/thread.py", line 58, in run
    result = self.fn(*self.args, **self.kwargs)
  File "/home/zhuhe/.conda/envs/diffhpe/lib/python3.9/site-packages/wandb/filesync/step_upload.py", line 288, in run_and_notify
    self._do_upload_sync(event)
  File "/home/zhuhe/.conda/envs/diffhpe/lib/python3.9/site-packages/wandb/filesync/step_upload.py", line 330, in _do_upload_sync
    job.run()
  File "/home/zhuhe/.conda/envs/diffhpe/lib/python3.9/site-packages/wandb/filesync/upload_job.py", line 57, in run
    self.push()
  File "/home/zhuhe/.conda/envs/diffhpe/lib/python3.9/site-packages/wandb/filesync/upload_job.py", line 127, in push
    self._api.upload_file_retry(
  File "/home/zhuhe/.conda/envs/diffhpe/lib/python3.9/site-packages/wandb/apis/normalize.py", line 51, in wrapper
    raise CommError(message, error)
wandb.errors.CommError: <Response [404]>
2023-07-10 15:41:42,261 INFO    Thread-12 :46753 [dir_watcher.py:_on_file_modified():289] file/dir modified: /home/zhuhe/HPE-with-Diffusion/wandb/run-20230710_154137-agz50rdx/files/output.log
2023-07-10 15:41:42,836 DEBUG   HandlerThread:46753 [handler.py:handle_request():144] handle_request: status_report
2023-07-10 15:41:44,261 INFO    Thread-12 :46753 [dir_watcher.py:_on_file_modified():289] file/dir modified: /home/zhuhe/HPE-with-Diffusion/wandb/run-20230710_154137-agz50rdx/files/output.log
2023-07-10 15:41:47,481 DEBUG   SenderThread:46753 [sender.py:send():369] send: exit
2023-07-10 15:41:47,481 INFO    SenderThread:46753 [sender.py:send_exit():574] handling exit code: 1
2023-07-10 15:41:47,481 INFO    SenderThread:46753 [sender.py:send_exit():576] handling runtime: 9
2023-07-10 15:41:47,482 INFO    SenderThread:46753 [sender.py:_save_file():1354] saving file wandb-summary.json with policy end
2023-07-10 15:41:47,482 INFO    SenderThread:46753 [sender.py:send_exit():582] send defer
2023-07-10 15:41:47,482 DEBUG   HandlerThread:46753 [handler.py:handle_request():144] handle_request: defer
2023-07-10 15:41:47,482 INFO    HandlerThread:46753 [handler.py:handle_request_defer():170] handle defer: 0
2023-07-10 15:41:47,482 DEBUG   SenderThread:46753 [sender.py:send_request():396] send_request: defer
2023-07-10 15:41:47,482 INFO    SenderThread:46753 [sender.py:send_request_defer():598] handle sender defer: 0
2023-07-10 15:41:47,482 INFO    SenderThread:46753 [sender.py:transition_state():602] send defer: 1
2023-07-10 15:41:47,482 DEBUG   HandlerThread:46753 [handler.py:handle_request():144] handle_request: defer
2023-07-10 15:41:47,482 INFO    HandlerThread:46753 [handler.py:handle_request_defer():170] handle defer: 1
2023-07-10 15:41:47,482 DEBUG   SenderThread:46753 [sender.py:send_request():396] send_request: defer
2023-07-10 15:41:47,482 INFO    SenderThread:46753 [sender.py:send_request_defer():598] handle sender defer: 1
2023-07-10 15:41:47,482 INFO    SenderThread:46753 [sender.py:transition_state():602] send defer: 2
2023-07-10 15:41:47,483 DEBUG   HandlerThread:46753 [handler.py:handle_request():144] handle_request: defer
2023-07-10 15:41:47,483 INFO    HandlerThread:46753 [handler.py:handle_request_defer():170] handle defer: 2
2023-07-10 15:41:47,483 INFO    HandlerThread:46753 [system_monitor.py:finish():190] Stopping system monitor
2023-07-10 15:41:47,483 INFO    HandlerThread:46753 [interfaces.py:finish():202] Joined cpu monitor
2023-07-10 15:41:47,483 INFO    HandlerThread:46753 [interfaces.py:finish():202] Joined disk monitor
2023-07-10 15:41:47,484 DEBUG   SystemMonitor:46753 [system_monitor.py:_start():159] Starting system metrics aggregation loop
2023-07-10 15:41:47,484 DEBUG   SystemMonitor:46753 [system_monitor.py:_start():166] Finished system metrics aggregation loop
2023-07-10 15:41:47,484 DEBUG   SystemMonitor:46753 [system_monitor.py:_start():170] Publishing last batch of metrics
2023-07-10 15:41:47,549 INFO    HandlerThread:46753 [interfaces.py:finish():202] Joined gpu monitor
2023-07-10 15:41:47,549 INFO    HandlerThread:46753 [interfaces.py:finish():202] Joined memory monitor
2023-07-10 15:41:47,549 INFO    HandlerThread:46753 [interfaces.py:finish():202] Joined network monitor
2023-07-10 15:41:47,549 DEBUG   SenderThread:46753 [sender.py:send_request():396] send_request: defer
2023-07-10 15:41:47,549 INFO    SenderThread:46753 [sender.py:send_request_defer():598] handle sender defer: 2
2023-07-10 15:41:47,549 INFO    SenderThread:46753 [sender.py:transition_state():602] send defer: 3
2023-07-10 15:41:47,549 DEBUG   SenderThread:46753 [sender.py:send():369] send: stats
2023-07-10 15:41:47,550 DEBUG   HandlerThread:46753 [handler.py:handle_request():144] handle_request: defer
2023-07-10 15:41:47,550 INFO    HandlerThread:46753 [handler.py:handle_request_defer():170] handle defer: 3
2023-07-10 15:41:47,550 DEBUG   SenderThread:46753 [sender.py:send_request():396] send_request: defer
2023-07-10 15:41:47,550 INFO    SenderThread:46753 [sender.py:send_request_defer():598] handle sender defer: 3
2023-07-10 15:41:47,550 INFO    SenderThread:46753 [sender.py:transition_state():602] send defer: 4
2023-07-10 15:41:47,550 DEBUG   HandlerThread:46753 [handler.py:handle_request():144] handle_request: defer
2023-07-10 15:41:47,550 INFO    HandlerThread:46753 [handler.py:handle_request_defer():170] handle defer: 4
2023-07-10 15:41:47,551 DEBUG   SenderThread:46753 [sender.py:send_request():396] send_request: defer
2023-07-10 15:41:47,551 INFO    SenderThread:46753 [sender.py:send_request_defer():598] handle sender defer: 4
2023-07-10 15:41:47,551 INFO    SenderThread:46753 [sender.py:transition_state():602] send defer: 5
2023-07-10 15:41:47,551 DEBUG   HandlerThread:46753 [handler.py:handle_request():144] handle_request: defer
2023-07-10 15:41:47,551 INFO    HandlerThread:46753 [handler.py:handle_request_defer():170] handle defer: 5
2023-07-10 15:41:47,551 DEBUG   SenderThread:46753 [sender.py:send():369] send: summary
2023-07-10 15:41:47,551 INFO    SenderThread:46753 [sender.py:_save_file():1354] saving file wandb-summary.json with policy end
2023-07-10 15:41:47,551 DEBUG   SenderThread:46753 [sender.py:send_request():396] send_request: defer
2023-07-10 15:41:47,551 INFO    SenderThread:46753 [sender.py:send_request_defer():598] handle sender defer: 5
2023-07-10 15:41:47,551 INFO    SenderThread:46753 [sender.py:transition_state():602] send defer: 6
2023-07-10 15:41:47,552 DEBUG   HandlerThread:46753 [handler.py:handle_request():144] handle_request: defer
2023-07-10 15:41:47,552 INFO    HandlerThread:46753 [handler.py:handle_request_defer():170] handle defer: 6
2023-07-10 15:41:47,552 DEBUG   SenderThread:46753 [sender.py:send_request():396] send_request: defer
2023-07-10 15:41:47,552 INFO    SenderThread:46753 [sender.py:send_request_defer():598] handle sender defer: 6
2023-07-10 15:41:47,553 DEBUG   HandlerThread:46753 [handler.py:handle_request():144] handle_request: status_report
2023-07-10 15:41:47,828 INFO    SenderThread:46753 [sender.py:transition_state():602] send defer: 7
2023-07-10 15:41:47,828 DEBUG   HandlerThread:46753 [handler.py:handle_request():144] handle_request: defer
2023-07-10 15:41:47,828 INFO    HandlerThread:46753 [handler.py:handle_request_defer():170] handle defer: 7
2023-07-10 15:41:47,828 DEBUG   SenderThread:46753 [sender.py:send_request():396] send_request: defer
2023-07-10 15:41:47,828 INFO    SenderThread:46753 [sender.py:send_request_defer():598] handle sender defer: 7
2023-07-10 15:41:48,262 INFO    Thread-12 :46753 [dir_watcher.py:_on_file_modified():289] file/dir modified: /home/zhuhe/HPE-with-Diffusion/wandb/run-20230710_154137-agz50rdx/files/wandb-summary.json
2023-07-10 15:41:48,263 INFO    Thread-12 :46753 [dir_watcher.py:_on_file_modified():289] file/dir modified: /home/zhuhe/HPE-with-Diffusion/wandb/run-20230710_154137-agz50rdx/files/config.yaml
2023-07-10 15:41:48,263 INFO    Thread-12 :46753 [dir_watcher.py:_on_file_modified():289] file/dir modified: /home/zhuhe/HPE-with-Diffusion/wandb/run-20230710_154137-agz50rdx/files/output.log
2023-07-10 15:41:48,481 DEBUG   HandlerThread:46753 [handler.py:handle_request():144] handle_request: poll_exit
2023-07-10 15:41:50,263 INFO    Thread-12 :46753 [dir_watcher.py:_on_file_modified():289] file/dir modified: /home/zhuhe/HPE-with-Diffusion/wandb/run-20230710_154137-agz50rdx/files/output.log
2023-07-10 15:41:51,916 INFO    SenderThread:46753 [sender.py:transition_state():602] send defer: 8
2023-07-10 15:41:51,916 DEBUG   SenderThread:46753 [sender.py:send_request():396] send_request: poll_exit
2023-07-10 15:41:51,916 DEBUG   HandlerThread:46753 [handler.py:handle_request():144] handle_request: defer
2023-07-10 15:41:51,917 INFO    HandlerThread:46753 [handler.py:handle_request_defer():170] handle defer: 8
2023-07-10 15:41:51,917 DEBUG   SenderThread:46753 [sender.py:send_request():396] send_request: defer
2023-07-10 15:41:51,917 INFO    SenderThread:46753 [sender.py:send_request_defer():598] handle sender defer: 8
2023-07-10 15:41:51,917 INFO    SenderThread:46753 [job_builder.py:build():232] Attempting to build job artifact
2023-07-10 15:41:51,917 INFO    SenderThread:46753 [job_builder.py:build():266] no source found
2023-07-10 15:41:51,917 INFO    SenderThread:46753 [sender.py:transition_state():602] send defer: 9
2023-07-10 15:41:51,917 DEBUG   HandlerThread:46753 [handler.py:handle_request():144] handle_request: defer
2023-07-10 15:41:51,917 INFO    HandlerThread:46753 [handler.py:handle_request_defer():170] handle defer: 9
2023-07-10 15:41:51,917 DEBUG   SenderThread:46753 [sender.py:send_request():396] send_request: defer
2023-07-10 15:41:51,917 INFO    SenderThread:46753 [sender.py:send_request_defer():598] handle sender defer: 9
2023-07-10 15:41:51,917 INFO    SenderThread:46753 [dir_watcher.py:finish():359] shutting down directory watcher
2023-07-10 15:41:52,264 INFO    Thread-12 :46753 [dir_watcher.py:_on_file_modified():289] file/dir modified: /home/zhuhe/HPE-with-Diffusion/wandb/run-20230710_154137-agz50rdx/files/output.log
2023-07-10 15:41:52,264 INFO    SenderThread:46753 [dir_watcher.py:finish():389] scan: /home/zhuhe/HPE-with-Diffusion/wandb/run-20230710_154137-agz50rdx/files
2023-07-10 15:41:52,264 INFO    SenderThread:46753 [dir_watcher.py:finish():403] scan save: /home/zhuhe/HPE-with-Diffusion/wandb/run-20230710_154137-agz50rdx/files/wandb-metadata.json wandb-metadata.json
2023-07-10 15:41:52,264 INFO    SenderThread:46753 [dir_watcher.py:finish():403] scan save: /home/zhuhe/HPE-with-Diffusion/wandb/run-20230710_154137-agz50rdx/files/config.yaml config.yaml
2023-07-10 15:41:52,264 INFO    SenderThread:46753 [dir_watcher.py:finish():403] scan save: /home/zhuhe/HPE-with-Diffusion/wandb/run-20230710_154137-agz50rdx/files/requirements.txt requirements.txt
2023-07-10 15:41:52,264 INFO    SenderThread:46753 [dir_watcher.py:finish():403] scan save: /home/zhuhe/HPE-with-Diffusion/wandb/run-20230710_154137-agz50rdx/files/wandb-summary.json wandb-summary.json
2023-07-10 15:41:52,264 INFO    SenderThread:46753 [dir_watcher.py:finish():403] scan save: /home/zhuhe/HPE-with-Diffusion/wandb/run-20230710_154137-agz50rdx/files/conda-environment.yaml conda-environment.yaml
2023-07-10 15:41:52,264 INFO    SenderThread:46753 [dir_watcher.py:finish():403] scan save: /home/zhuhe/HPE-with-Diffusion/wandb/run-20230710_154137-agz50rdx/files/output.log output.log
2023-07-10 15:41:52,264 INFO    SenderThread:46753 [sender.py:transition_state():602] send defer: 10
2023-07-10 15:41:52,265 DEBUG   HandlerThread:46753 [handler.py:handle_request():144] handle_request: defer
2023-07-10 15:41:52,267 INFO    HandlerThread:46753 [handler.py:handle_request_defer():170] handle defer: 10
2023-07-10 15:41:52,271 DEBUG   SenderThread:46753 [sender.py:send_request():396] send_request: defer
2023-07-10 15:41:52,272 INFO    SenderThread:46753 [sender.py:send_request_defer():598] handle sender defer: 10
2023-07-10 15:41:52,272 INFO    SenderThread:46753 [file_pusher.py:finish():159] shutting down file pusher
2023-07-10 15:41:52,768 ERROR   wandb-upload_0:46753 [internal_api.py:upload_file():2192] upload_file exception https://storage.googleapis.com/wandb-production.appspot.com/ada4321/DiffHPE/agz50rdx/config.yaml?Expires=1689061312&GoogleAccessId=gorilla-files-url-signer-man%40wandb-production.iam.gserviceaccount.com&Signature=XAhw2DdpwRtZyaBOAPsRMLnS1seWWAbOP5WOMJWUY29LLV9Z45Ilb03Kmrqr9yvNcd%2FAmHtIveexjbwh6US1%2BmuWbzT4ZprP9SP26N%2Ba5MMtM7dQ1jsJqnEvI7cEihQcoQZVVAroqzxmiTApgK2Sz1MOXEiMWjxDKI%2F6OIh%2BOE3vIiOlVEA6M%2Fzu1GYR%2FC7C0TP%2FSxNXThbfQP%2FRpsgv7%2BQDtwUyfEZnC3iYaUJ%2Fsb14LvjEVkzD5qbOmn6tbFqxy5agRQMfvD%2BbxeOmeHIjA0buri4FE9V46f5y6xCyEKK%2FcWD22uhlmSJK8AoLus83Bz1DrwmYpoWV2PZzwSo2AQ%3D%3D: 404 Client Error: Not Found for url: https://storage.googleapis.com/wandb-production.appspot.com/ada4321/DiffHPE/agz50rdx/config.yaml?Expires=1689061312&GoogleAccessId=gorilla-files-url-signer-man%40wandb-production.iam.gserviceaccount.com&Signature=XAhw2DdpwRtZyaBOAPsRMLnS1seWWAbOP5WOMJWUY29LLV9Z45Ilb03Kmrqr9yvNcd%2FAmHtIveexjbwh6US1%2BmuWbzT4ZprP9SP26N%2Ba5MMtM7dQ1jsJqnEvI7cEihQcoQZVVAroqzxmiTApgK2Sz1MOXEiMWjxDKI%2F6OIh%2BOE3vIiOlVEA6M%2Fzu1GYR%2FC7C0TP%2FSxNXThbfQP%2FRpsgv7%2BQDtwUyfEZnC3iYaUJ%2Fsb14LvjEVkzD5qbOmn6tbFqxy5agRQMfvD%2BbxeOmeHIjA0buri4FE9V46f5y6xCyEKK%2FcWD22uhlmSJK8AoLus83Bz1DrwmYpoWV2PZzwSo2AQ%3D%3D
2023-07-10 15:41:52,768 ERROR   wandb-upload_0:46753 [internal_api.py:upload_file():2194] upload_file request headers: {'User-Agent': 'python-requests/2.31.0', 'Accept-Encoding': 'gzip, deflate', 'Accept': '*/*', 'Connection': 'keep-alive', 'Content-Length': '514'}
2023-07-10 15:41:52,768 ERROR   wandb-upload_0:46753 [internal_api.py:upload_file():2196] upload_file response body: b'<!DOCTYPE html>\n<html lang=en>\n  <meta charset=utf-8>\n  <meta name=viewport content="initial-scale=1, minimum-scale=1, width=device-width">\n  <title>Error 404 (Not Found)!!1</title>\n  <style>\n    *{margin:0;padding:0}html,code{font:15px/22px arial,sans-serif}html{background:#fff;color:#222;padding:15px}body{margin:7% auto 0;max-width:390px;min-height:180px;padding:30px 0 15px}* > body{background:url(//www.google.com/images/errors/robot.png) 100% 5px no-repeat;padding-right:205px}p{margin:11px 0 22px;overflow:hidden}ins{color:#777;text-decoration:none}a img{border:0}@media screen and (max-width:772px){body{background:none;margin-top:0;max-width:none;padding-right:0}}#logo{background:url(//www.google.com/images/branding/googlelogo/1x/googlelogo_color_150x54dp.png) no-repeat;margin-left:-5px}@media only screen and (min-resolution:192dpi){#logo{background:url(//www.google.com/images/branding/googlelogo/2x/googlelogo_color_150x54dp.png) no-repeat 0% 0%/100% 100%;-moz-border-image:url(//www.google.com/images/branding/googlelogo/2x/googlelogo_color_150x54dp.png) 0}}@media only screen and (-webkit-min-device-pixel-ratio:2){#logo{background:url(//www.google.com/images/branding/googlelogo/2x/googlelogo_color_150x54dp.png) no-repeat;-webkit-background-size:100% 100%}}#logo{display:inline-block;height:54px;width:150px}\n  </style>\n  <a href=//www.google.com/><span id=logo aria-label=Google></span></a>\n  <p><b>404.</b> <ins>That\xe2\x80\x99s an error.</ins>\n  <p>The requested URL <code>/wandb-production.appspot.com/ada4321/DiffHPE/agz50rdx/config.yaml</code> was not found on this server.  <ins>That\xe2\x80\x99s all we know.</ins>\n'
2023-07-10 15:41:52,770 ERROR   wandb-upload_1:46753 [internal_api.py:upload_file():2192] upload_file exception https://storage.googleapis.com/wandb-production.appspot.com/ada4321/DiffHPE/agz50rdx/requirements.txt?Expires=1689061312&GoogleAccessId=gorilla-files-url-signer-man%40wandb-production.iam.gserviceaccount.com&Signature=BMejroOEp%2BATGltq5jVExLTKiYPQfVg27inE7GNQtYkMxl%2BEyY7fAy0rtKgoVajjNVrFxDznYQxbLMISqGJ%2BaeP1VgIEdyZSo88cpAw%2FePGLxNcP4im3kIWC9ZLABquz%2FaaDZiaYM0wojCMmWE2Pu%2Bujb4lO6GzZfMeMgd20TV2VRmRyFiZztALyDahjCqySr4zEtwMIKWe%2FZD27JCxVoVtSAaCDpfMGYsKpk2d0M3%2FJ8asiNQn7ohS1QJpOu%2BBjfsXyAWTqDvw41vGRtEAktJLXJ%2BngJIPnmoufJl7qaBVis916DZFeSK7Kn8qrGZcbCAYHgYr%2BxlM%2BmfhmsKWZMw%3D%3D: 404 Client Error: Not Found for url: https://storage.googleapis.com/wandb-production.appspot.com/ada4321/DiffHPE/agz50rdx/requirements.txt?Expires=1689061312&GoogleAccessId=gorilla-files-url-signer-man%40wandb-production.iam.gserviceaccount.com&Signature=BMejroOEp%2BATGltq5jVExLTKiYPQfVg27inE7GNQtYkMxl%2BEyY7fAy0rtKgoVajjNVrFxDznYQxbLMISqGJ%2BaeP1VgIEdyZSo88cpAw%2FePGLxNcP4im3kIWC9ZLABquz%2FaaDZiaYM0wojCMmWE2Pu%2Bujb4lO6GzZfMeMgd20TV2VRmRyFiZztALyDahjCqySr4zEtwMIKWe%2FZD27JCxVoVtSAaCDpfMGYsKpk2d0M3%2FJ8asiNQn7ohS1QJpOu%2BBjfsXyAWTqDvw41vGRtEAktJLXJ%2BngJIPnmoufJl7qaBVis916DZFeSK7Kn8qrGZcbCAYHgYr%2BxlM%2BmfhmsKWZMw%3D%3D
2023-07-10 15:41:52,770 ERROR   wandb-upload_1:46753 [internal_api.py:upload_file():2194] upload_file request headers: {'User-Agent': 'python-requests/2.31.0', 'Accept-Encoding': 'gzip, deflate', 'Accept': '*/*', 'Connection': 'keep-alive', 'Content-Length': '910'}
2023-07-10 15:41:52,770 ERROR   wandb-upload_1:46753 [internal_api.py:upload_file():2196] upload_file response body: b'<!DOCTYPE html>\n<html lang=en>\n  <meta charset=utf-8>\n  <meta name=viewport content="initial-scale=1, minimum-scale=1, width=device-width">\n  <title>Error 404 (Not Found)!!1</title>\n  <style>\n    *{margin:0;padding:0}html,code{font:15px/22px arial,sans-serif}html{background:#fff;color:#222;padding:15px}body{margin:7% auto 0;max-width:390px;min-height:180px;padding:30px 0 15px}* > body{background:url(//www.google.com/images/errors/robot.png) 100% 5px no-repeat;padding-right:205px}p{margin:11px 0 22px;overflow:hidden}ins{color:#777;text-decoration:none}a img{border:0}@media screen and (max-width:772px){body{background:none;margin-top:0;max-width:none;padding-right:0}}#logo{background:url(//www.google.com/images/branding/googlelogo/1x/googlelogo_color_150x54dp.png) no-repeat;margin-left:-5px}@media only screen and (min-resolution:192dpi){#logo{background:url(//www.google.com/images/branding/googlelogo/2x/googlelogo_color_150x54dp.png) no-repeat 0% 0%/100% 100%;-moz-border-image:url(//www.google.com/images/branding/googlelogo/2x/googlelogo_color_150x54dp.png) 0}}@media only screen and (-webkit-min-device-pixel-ratio:2){#logo{background:url(//www.google.com/images/branding/googlelogo/2x/googlelogo_color_150x54dp.png) no-repeat;-webkit-background-size:100% 100%}}#logo{display:inline-block;height:54px;width:150px}\n  </style>\n  <a href=//www.google.com/><span id=logo aria-label=Google></span></a>\n  <p><b>404.</b> <ins>That\xe2\x80\x99s an error.</ins>\n  <p>The requested URL <code>/wandb-production.appspot.com/ada4321/DiffHPE/agz50rdx/requirements.txt</code> was not found on this server.  <ins>That\xe2\x80\x99s all we know.</ins>\n'
2023-07-10 15:41:53,057 ERROR   wandb-upload_2:46753 [internal_api.py:upload_file():2192] upload_file exception https://storage.googleapis.com/wandb-production.appspot.com/ada4321/DiffHPE/agz50rdx/wandb-summary.json?Expires=1689061312&GoogleAccessId=gorilla-files-url-signer-man%40wandb-production.iam.gserviceaccount.com&Signature=DAogDQBWR7Osn%2FzTuzM5BvybJU3M4iUe8lyCqstiQIwHXqG6oU8hWqb70adzmMqzR0TaIb8aNt1ebOiL7Cxh%2F9306w3fDWrilL0Fj6LQPCN07IzlHu1kzyZi3OMzyMge%2BjrXxKCzJMYkLb6SWh%2FrDfUqx6hM5FpOFpPCr9IrZen1KUGvRLPIpGSIeX9LZrUufSZb4NkMcMT5Sn1zUT%2BwN3U%2BBXFGVKDBzpWtjZ4bUi8sdjI%2B5hcnTzaYw3lAwwdBQA2PbJt6d3diGtOGxc6Q7ru6fcogwvtJrZud14f0FigxDPn8UD90WgR8NNZZcB24lbx5JNUJK8%2BiSp%2FmvT2KGg%3D%3D: 404 Client Error: Not Found for url: https://storage.googleapis.com/wandb-production.appspot.com/ada4321/DiffHPE/agz50rdx/wandb-summary.json?Expires=1689061312&GoogleAccessId=gorilla-files-url-signer-man%40wandb-production.iam.gserviceaccount.com&Signature=DAogDQBWR7Osn%2FzTuzM5BvybJU3M4iUe8lyCqstiQIwHXqG6oU8hWqb70adzmMqzR0TaIb8aNt1ebOiL7Cxh%2F9306w3fDWrilL0Fj6LQPCN07IzlHu1kzyZi3OMzyMge%2BjrXxKCzJMYkLb6SWh%2FrDfUqx6hM5FpOFpPCr9IrZen1KUGvRLPIpGSIeX9LZrUufSZb4NkMcMT5Sn1zUT%2BwN3U%2BBXFGVKDBzpWtjZ4bUi8sdjI%2B5hcnTzaYw3lAwwdBQA2PbJt6d3diGtOGxc6Q7ru6fcogwvtJrZud14f0FigxDPn8UD90WgR8NNZZcB24lbx5JNUJK8%2BiSp%2FmvT2KGg%3D%3D
2023-07-10 15:41:53,057 ERROR   wandb-upload_2:46753 [internal_api.py:upload_file():2194] upload_file request headers: {'User-Agent': 'python-requests/2.31.0', 'Accept-Encoding': 'gzip, deflate', 'Accept': '*/*', 'Connection': 'keep-alive', 'Content-Length': '26'}
2023-07-10 15:41:53,057 ERROR   wandb-upload_2:46753 [internal_api.py:upload_file():2196] upload_file response body: b'<!DOCTYPE html>\n<html lang=en>\n  <meta charset=utf-8>\n  <meta name=viewport content="initial-scale=1, minimum-scale=1, width=device-width">\n  <title>Error 404 (Not Found)!!1</title>\n  <style>\n    *{margin:0;padding:0}html,code{font:15px/22px arial,sans-serif}html{background:#fff;color:#222;padding:15px}body{margin:7% auto 0;max-width:390px;min-height:180px;padding:30px 0 15px}* > body{background:url(//www.google.com/images/errors/robot.png) 100% 5px no-repeat;padding-right:205px}p{margin:11px 0 22px;overflow:hidden}ins{color:#777;text-decoration:none}a img{border:0}@media screen and (max-width:772px){body{background:none;margin-top:0;max-width:none;padding-right:0}}#logo{background:url(//www.google.com/images/branding/googlelogo/1x/googlelogo_color_150x54dp.png) no-repeat;margin-left:-5px}@media only screen and (min-resolution:192dpi){#logo{background:url(//www.google.com/images/branding/googlelogo/2x/googlelogo_color_150x54dp.png) no-repeat 0% 0%/100% 100%;-moz-border-image:url(//www.google.com/images/branding/googlelogo/2x/googlelogo_color_150x54dp.png) 0}}@media only screen and (-webkit-min-device-pixel-ratio:2){#logo{background:url(//www.google.com/images/branding/googlelogo/2x/googlelogo_color_150x54dp.png) no-repeat;-webkit-background-size:100% 100%}}#logo{display:inline-block;height:54px;width:150px}\n  </style>\n  <a href=//www.google.com/><span id=logo aria-label=Google></span></a>\n  <p><b>404.</b> <ins>That\xe2\x80\x99s an error.</ins>\n  <p>The requested URL <code>/wandb-production.appspot.com/ada4321/DiffHPE/agz50rdx/wandb-summary.json</code> was not found on this server.  <ins>That\xe2\x80\x99s all we know.</ins>\n'
2023-07-10 15:41:53,081 ERROR   wandb-upload_3:46753 [internal_api.py:upload_file():2192] upload_file exception https://storage.googleapis.com/wandb-production.appspot.com/ada4321/DiffHPE/agz50rdx/conda-environment.yaml?Expires=1689061312&GoogleAccessId=gorilla-files-url-signer-man%40wandb-production.iam.gserviceaccount.com&Signature=q%2BfT%2BnHvlyQyraB%2F9M2bMuRSISM4nmYvKe4Hg7t%2FFWaGIDc2M75TCUMJ6F45jH%2FtPrvzLIbGsT8w2IeeTWxaDT8ktrzyf4PLbcwYY3ak8rRhR9pygZ%2BWs4YuAppEqlYtihmJjjkdqAfvSdyBntrck3fLLib%2B6WC1KxA4BuCmYqU2kxigLFnsIjVki10YO7xNhqiA3mr1dlK%2FAEjWbc6lzpiF7hDfETSPvHJWcxMW7S9FFGeawJhBxjMrP39uyYEJ%2B8tu%2FmSimKYwLn4up8XaIQd%2BSs4f%2F5oPjEozCddkmlAiOp5EnVuFn7p0jIwhZkLF3NhqUJzH%2F%2FcuxMGY4eRnsA%3D%3D: 404 Client Error: Not Found for url: https://storage.googleapis.com/wandb-production.appspot.com/ada4321/DiffHPE/agz50rdx/conda-environment.yaml?Expires=1689061312&GoogleAccessId=gorilla-files-url-signer-man%40wandb-production.iam.gserviceaccount.com&Signature=q%2BfT%2BnHvlyQyraB%2F9M2bMuRSISM4nmYvKe4Hg7t%2FFWaGIDc2M75TCUMJ6F45jH%2FtPrvzLIbGsT8w2IeeTWxaDT8ktrzyf4PLbcwYY3ak8rRhR9pygZ%2BWs4YuAppEqlYtihmJjjkdqAfvSdyBntrck3fLLib%2B6WC1KxA4BuCmYqU2kxigLFnsIjVki10YO7xNhqiA3mr1dlK%2FAEjWbc6lzpiF7hDfETSPvHJWcxMW7S9FFGeawJhBxjMrP39uyYEJ%2B8tu%2FmSimKYwLn4up8XaIQd%2BSs4f%2F5oPjEozCddkmlAiOp5EnVuFn7p0jIwhZkLF3NhqUJzH%2F%2FcuxMGY4eRnsA%3D%3D
2023-07-10 15:41:53,081 ERROR   wandb-upload_3:46753 [internal_api.py:upload_file():2194] upload_file request headers: {'User-Agent': 'python-requests/2.31.0', 'Accept-Encoding': 'gzip, deflate', 'Accept': '*/*', 'Connection': 'keep-alive', 'Content-Length': '1903'}
2023-07-10 15:41:53,081 ERROR   wandb-upload_3:46753 [internal_api.py:upload_file():2196] upload_file response body: b'<!DOCTYPE html>\n<html lang=en>\n  <meta charset=utf-8>\n  <meta name=viewport content="initial-scale=1, minimum-scale=1, width=device-width">\n  <title>Error 404 (Not Found)!!1</title>\n  <style>\n    *{margin:0;padding:0}html,code{font:15px/22px arial,sans-serif}html{background:#fff;color:#222;padding:15px}body{margin:7% auto 0;max-width:390px;min-height:180px;padding:30px 0 15px}* > body{background:url(//www.google.com/images/errors/robot.png) 100% 5px no-repeat;padding-right:205px}p{margin:11px 0 22px;overflow:hidden}ins{color:#777;text-decoration:none}a img{border:0}@media screen and (max-width:772px){body{background:none;margin-top:0;max-width:none;padding-right:0}}#logo{background:url(//www.google.com/images/branding/googlelogo/1x/googlelogo_color_150x54dp.png) no-repeat;margin-left:-5px}@media only screen and (min-resolution:192dpi){#logo{background:url(//www.google.com/images/branding/googlelogo/2x/googlelogo_color_150x54dp.png) no-repeat 0% 0%/100% 100%;-moz-border-image:url(//www.google.com/images/branding/googlelogo/2x/googlelogo_color_150x54dp.png) 0}}@media only screen and (-webkit-min-device-pixel-ratio:2){#logo{background:url(//www.google.com/images/branding/googlelogo/2x/googlelogo_color_150x54dp.png) no-repeat;-webkit-background-size:100% 100%}}#logo{display:inline-block;height:54px;width:150px}\n  </style>\n  <a href=//www.google.com/><span id=logo aria-label=Google></span></a>\n  <p><b>404.</b> <ins>That\xe2\x80\x99s an error.</ins>\n  <p>The requested URL <code>/wandb-production.appspot.com/ada4321/DiffHPE/agz50rdx/conda-environment.yaml</code> was not found on this server.  <ins>That\xe2\x80\x99s all we know.</ins>\n'
2023-07-10 15:41:53,087 ERROR   wandb-upload_4:46753 [internal_api.py:upload_file():2192] upload_file exception https://storage.googleapis.com/wandb-production.appspot.com/ada4321/DiffHPE/agz50rdx/output.log?Expires=1689061312&GoogleAccessId=gorilla-files-url-signer-man%40wandb-production.iam.gserviceaccount.com&Signature=EWLKgeUTo5s%2FZRmMZIItPArJqzZYA7DbRkrYHyfJF4plgMhGFcXANwvEqbkDT4GEBiKxsfwGm520nqH67qanj2SGR5onvGH85941GLQmNrAu8hfjJa2Hnu3ZzZq7E6bR9ajszyoStwPB%2F5iv%2B15mBmuKbXu5vmolzepdvdd94oh7Yy%2BxsQDEm0XQajW1oAfhx%2BtMNNj0tQPmiMd1boajrrQpuR%2BVI7h42Kc6TIt4sDIY4HjHP714chP48yYxNL6mjbH1dK%2BzJjWOpeFS%2Belc1hzTUxfhQk%2BrjqhD9R28AbhcrJeOrbVkP8qKal30TzEMClsIoQGlri8G7MD4MrIJzg%3D%3D: 404 Client Error: Not Found for url: https://storage.googleapis.com/wandb-production.appspot.com/ada4321/DiffHPE/agz50rdx/output.log?Expires=1689061312&GoogleAccessId=gorilla-files-url-signer-man%40wandb-production.iam.gserviceaccount.com&Signature=EWLKgeUTo5s%2FZRmMZIItPArJqzZYA7DbRkrYHyfJF4plgMhGFcXANwvEqbkDT4GEBiKxsfwGm520nqH67qanj2SGR5onvGH85941GLQmNrAu8hfjJa2Hnu3ZzZq7E6bR9ajszyoStwPB%2F5iv%2B15mBmuKbXu5vmolzepdvdd94oh7Yy%2BxsQDEm0XQajW1oAfhx%2BtMNNj0tQPmiMd1boajrrQpuR%2BVI7h42Kc6TIt4sDIY4HjHP714chP48yYxNL6mjbH1dK%2BzJjWOpeFS%2Belc1hzTUxfhQk%2BrjqhD9R28AbhcrJeOrbVkP8qKal30TzEMClsIoQGlri8G7MD4MrIJzg%3D%3D
2023-07-10 15:41:53,087 ERROR   wandb-upload_4:46753 [internal_api.py:upload_file():2194] upload_file request headers: {'User-Agent': 'python-requests/2.31.0', 'Accept-Encoding': 'gzip, deflate', 'Accept': '*/*', 'Connection': 'keep-alive', 'Content-Length': '3190'}
2023-07-10 15:41:53,087 ERROR   wandb-upload_4:46753 [internal_api.py:upload_file():2196] upload_file response body: b'<!DOCTYPE html>\n<html lang=en>\n  <meta charset=utf-8>\n  <meta name=viewport content="initial-scale=1, minimum-scale=1, width=device-width">\n  <title>Error 404 (Not Found)!!1</title>\n  <style>\n    *{margin:0;padding:0}html,code{font:15px/22px arial,sans-serif}html{background:#fff;color:#222;padding:15px}body{margin:7% auto 0;max-width:390px;min-height:180px;padding:30px 0 15px}* > body{background:url(//www.google.com/images/errors/robot.png) 100% 5px no-repeat;padding-right:205px}p{margin:11px 0 22px;overflow:hidden}ins{color:#777;text-decoration:none}a img{border:0}@media screen and (max-width:772px){body{background:none;margin-top:0;max-width:none;padding-right:0}}#logo{background:url(//www.google.com/images/branding/googlelogo/1x/googlelogo_color_150x54dp.png) no-repeat;margin-left:-5px}@media only screen and (min-resolution:192dpi){#logo{background:url(//www.google.com/images/branding/googlelogo/2x/googlelogo_color_150x54dp.png) no-repeat 0% 0%/100% 100%;-moz-border-image:url(//www.google.com/images/branding/googlelogo/2x/googlelogo_color_150x54dp.png) 0}}@media only screen and (-webkit-min-device-pixel-ratio:2){#logo{background:url(//www.google.com/images/branding/googlelogo/2x/googlelogo_color_150x54dp.png) no-repeat;-webkit-background-size:100% 100%}}#logo{display:inline-block;height:54px;width:150px}\n  </style>\n  <a href=//www.google.com/><span id=logo aria-label=Google></span></a>\n  <p><b>404.</b> <ins>That\xe2\x80\x99s an error.</ins>\n  <p>The requested URL <code>/wandb-production.appspot.com/ada4321/DiffHPE/agz50rdx/output.log</code> was not found on this server.  <ins>That\xe2\x80\x99s all we know.</ins>\n'
2023-07-10 15:41:53,482 DEBUG   HandlerThread:46753 [handler.py:handle_request():144] handle_request: keepalive
2023-07-10 15:41:53,850 ERROR   wandb-upload_0:46753 [upload_job.py:push():136] Failed to upload file: /home/zhuhe/HPE-with-Diffusion/wandb/run-20230710_154137-agz50rdx/files/config.yaml
Traceback (most recent call last):
  File "/home/zhuhe/.conda/envs/diffhpe/lib/python3.9/site-packages/wandb/apis/normalize.py", line 41, in wrapper
    return func(*args, **kwargs)
  File "/home/zhuhe/.conda/envs/diffhpe/lib/python3.9/site-packages/wandb/sdk/lib/retry.py", line 212, in wrapped_fn
    return retrier(*args, **kargs)
  File "/home/zhuhe/.conda/envs/diffhpe/lib/python3.9/site-packages/wandb/sdk/lib/retry.py", line 131, in __call__
    result = self._call_fn(*args, **kwargs)
  File "/home/zhuhe/.conda/envs/diffhpe/lib/python3.9/site-packages/wandb/sdk/internal/internal_api.py", line 2218, in upload_file
    wandb._sentry.reraise(e)
  File "/home/zhuhe/.conda/envs/diffhpe/lib/python3.9/site-packages/wandb/analytics/sentry.py", line 146, in reraise
    raise exc.with_traceback(sys.exc_info()[2])
  File "/home/zhuhe/.conda/envs/diffhpe/lib/python3.9/site-packages/wandb/sdk/internal/internal_api.py", line 2190, in upload_file
    response.raise_for_status()
  File "/home/zhuhe/.conda/envs/diffhpe/lib/python3.9/site-packages/requests/models.py", line 1021, in raise_for_status
    raise HTTPError(http_error_msg, response=self)
requests.exceptions.HTTPError: 404 Client Error: Not Found for url: https://storage.googleapis.com/wandb-production.appspot.com/ada4321/DiffHPE/agz50rdx/config.yaml?Expires=1689061312&GoogleAccessId=gorilla-files-url-signer-man%40wandb-production.iam.gserviceaccount.com&Signature=XAhw2DdpwRtZyaBOAPsRMLnS1seWWAbOP5WOMJWUY29LLV9Z45Ilb03Kmrqr9yvNcd%2FAmHtIveexjbwh6US1%2BmuWbzT4ZprP9SP26N%2Ba5MMtM7dQ1jsJqnEvI7cEihQcoQZVVAroqzxmiTApgK2Sz1MOXEiMWjxDKI%2F6OIh%2BOE3vIiOlVEA6M%2Fzu1GYR%2FC7C0TP%2FSxNXThbfQP%2FRpsgv7%2BQDtwUyfEZnC3iYaUJ%2Fsb14LvjEVkzD5qbOmn6tbFqxy5agRQMfvD%2BbxeOmeHIjA0buri4FE9V46f5y6xCyEKK%2FcWD22uhlmSJK8AoLus83Bz1DrwmYpoWV2PZzwSo2AQ%3D%3D

During handling of the above exception, another exception occurred:

Traceback (most recent call last):
  File "/home/zhuhe/.conda/envs/diffhpe/lib/python3.9/site-packages/wandb/filesync/upload_job.py", line 127, in push
    self._api.upload_file_retry(
  File "/home/zhuhe/.conda/envs/diffhpe/lib/python3.9/site-packages/wandb/apis/normalize.py", line 51, in wrapper
    raise CommError(message, error)
wandb.errors.CommError: <Response [404]>
2023-07-10 15:41:53,851 ERROR   wandb-upload_1:46753 [upload_job.py:push():136] Failed to upload file: /home/zhuhe/HPE-with-Diffusion/wandb/run-20230710_154137-agz50rdx/files/requirements.txt
Traceback (most recent call last):
  File "/home/zhuhe/.conda/envs/diffhpe/lib/python3.9/site-packages/wandb/apis/normalize.py", line 41, in wrapper
    return func(*args, **kwargs)
  File "/home/zhuhe/.conda/envs/diffhpe/lib/python3.9/site-packages/wandb/sdk/lib/retry.py", line 212, in wrapped_fn
    return retrier(*args, **kargs)
  File "/home/zhuhe/.conda/envs/diffhpe/lib/python3.9/site-packages/wandb/sdk/lib/retry.py", line 131, in __call__
    result = self._call_fn(*args, **kwargs)
  File "/home/zhuhe/.conda/envs/diffhpe/lib/python3.9/site-packages/wandb/sdk/internal/internal_api.py", line 2218, in upload_file
    wandb._sentry.reraise(e)
  File "/home/zhuhe/.conda/envs/diffhpe/lib/python3.9/site-packages/wandb/analytics/sentry.py", line 146, in reraise
    raise exc.with_traceback(sys.exc_info()[2])
  File "/home/zhuhe/.conda/envs/diffhpe/lib/python3.9/site-packages/wandb/sdk/internal/internal_api.py", line 2190, in upload_file
    response.raise_for_status()
  File "/home/zhuhe/.conda/envs/diffhpe/lib/python3.9/site-packages/requests/models.py", line 1021, in raise_for_status
    raise HTTPError(http_error_msg, response=self)
requests.exceptions.HTTPError: 404 Client Error: Not Found for url: https://storage.googleapis.com/wandb-production.appspot.com/ada4321/DiffHPE/agz50rdx/requirements.txt?Expires=1689061312&GoogleAccessId=gorilla-files-url-signer-man%40wandb-production.iam.gserviceaccount.com&Signature=BMejroOEp%2BATGltq5jVExLTKiYPQfVg27inE7GNQtYkMxl%2BEyY7fAy0rtKgoVajjNVrFxDznYQxbLMISqGJ%2BaeP1VgIEdyZSo88cpAw%2FePGLxNcP4im3kIWC9ZLABquz%2FaaDZiaYM0wojCMmWE2Pu%2Bujb4lO6GzZfMeMgd20TV2VRmRyFiZztALyDahjCqySr4zEtwMIKWe%2FZD27JCxVoVtSAaCDpfMGYsKpk2d0M3%2FJ8asiNQn7ohS1QJpOu%2BBjfsXyAWTqDvw41vGRtEAktJLXJ%2BngJIPnmoufJl7qaBVis916DZFeSK7Kn8qrGZcbCAYHgYr%2BxlM%2BmfhmsKWZMw%3D%3D

During handling of the above exception, another exception occurred:

Traceback (most recent call last):
  File "/home/zhuhe/.conda/envs/diffhpe/lib/python3.9/site-packages/wandb/filesync/upload_job.py", line 127, in push
    self._api.upload_file_retry(
  File "/home/zhuhe/.conda/envs/diffhpe/lib/python3.9/site-packages/wandb/apis/normalize.py", line 51, in wrapper
    raise CommError(message, error)
wandb.errors.CommError: <Response [404]>
2023-07-10 15:41:53,852 ERROR   wandb-upload_2:46753 [upload_job.py:push():136] Failed to upload file: /home/zhuhe/HPE-with-Diffusion/wandb/run-20230710_154137-agz50rdx/files/wandb-summary.json
Traceback (most recent call last):
  File "/home/zhuhe/.conda/envs/diffhpe/lib/python3.9/site-packages/wandb/apis/normalize.py", line 41, in wrapper
    return func(*args, **kwargs)
  File "/home/zhuhe/.conda/envs/diffhpe/lib/python3.9/site-packages/wandb/sdk/lib/retry.py", line 212, in wrapped_fn
    return retrier(*args, **kargs)
  File "/home/zhuhe/.conda/envs/diffhpe/lib/python3.9/site-packages/wandb/sdk/lib/retry.py", line 131, in __call__
    result = self._call_fn(*args, **kwargs)
  File "/home/zhuhe/.conda/envs/diffhpe/lib/python3.9/site-packages/wandb/sdk/internal/internal_api.py", line 2218, in upload_file
    wandb._sentry.reraise(e)
  File "/home/zhuhe/.conda/envs/diffhpe/lib/python3.9/site-packages/wandb/analytics/sentry.py", line 146, in reraise
    raise exc.with_traceback(sys.exc_info()[2])
  File "/home/zhuhe/.conda/envs/diffhpe/lib/python3.9/site-packages/wandb/sdk/internal/internal_api.py", line 2190, in upload_file
    response.raise_for_status()
  File "/home/zhuhe/.conda/envs/diffhpe/lib/python3.9/site-packages/requests/models.py", line 1021, in raise_for_status
    raise HTTPError(http_error_msg, response=self)
requests.exceptions.HTTPError: 404 Client Error: Not Found for url: https://storage.googleapis.com/wandb-production.appspot.com/ada4321/DiffHPE/agz50rdx/wandb-summary.json?Expires=1689061312&GoogleAccessId=gorilla-files-url-signer-man%40wandb-production.iam.gserviceaccount.com&Signature=DAogDQBWR7Osn%2FzTuzM5BvybJU3M4iUe8lyCqstiQIwHXqG6oU8hWqb70adzmMqzR0TaIb8aNt1ebOiL7Cxh%2F9306w3fDWrilL0Fj6LQPCN07IzlHu1kzyZi3OMzyMge%2BjrXxKCzJMYkLb6SWh%2FrDfUqx6hM5FpOFpPCr9IrZen1KUGvRLPIpGSIeX9LZrUufSZb4NkMcMT5Sn1zUT%2BwN3U%2BBXFGVKDBzpWtjZ4bUi8sdjI%2B5hcnTzaYw3lAwwdBQA2PbJt6d3diGtOGxc6Q7ru6fcogwvtJrZud14f0FigxDPn8UD90WgR8NNZZcB24lbx5JNUJK8%2BiSp%2FmvT2KGg%3D%3D

During handling of the above exception, another exception occurred:

Traceback (most recent call last):
  File "/home/zhuhe/.conda/envs/diffhpe/lib/python3.9/site-packages/wandb/filesync/upload_job.py", line 127, in push
    self._api.upload_file_retry(
  File "/home/zhuhe/.conda/envs/diffhpe/lib/python3.9/site-packages/wandb/apis/normalize.py", line 51, in wrapper
    raise CommError(message, error)
wandb.errors.CommError: <Response [404]>
2023-07-10 15:41:53,852 ERROR   wandb-upload_3:46753 [upload_job.py:push():136] Failed to upload file: /home/zhuhe/HPE-with-Diffusion/wandb/run-20230710_154137-agz50rdx/files/conda-environment.yaml
Traceback (most recent call last):
  File "/home/zhuhe/.conda/envs/diffhpe/lib/python3.9/site-packages/wandb/apis/normalize.py", line 41, in wrapper
    return func(*args, **kwargs)
  File "/home/zhuhe/.conda/envs/diffhpe/lib/python3.9/site-packages/wandb/sdk/lib/retry.py", line 212, in wrapped_fn
    return retrier(*args, **kargs)
  File "/home/zhuhe/.conda/envs/diffhpe/lib/python3.9/site-packages/wandb/sdk/lib/retry.py", line 131, in __call__
    result = self._call_fn(*args, **kwargs)
  File "/home/zhuhe/.conda/envs/diffhpe/lib/python3.9/site-packages/wandb/sdk/internal/internal_api.py", line 2218, in upload_file
    wandb._sentry.reraise(e)
  File "/home/zhuhe/.conda/envs/diffhpe/lib/python3.9/site-packages/wandb/analytics/sentry.py", line 146, in reraise
    raise exc.with_traceback(sys.exc_info()[2])
  File "/home/zhuhe/.conda/envs/diffhpe/lib/python3.9/site-packages/wandb/sdk/internal/internal_api.py", line 2190, in upload_file
    response.raise_for_status()
  File "/home/zhuhe/.conda/envs/diffhpe/lib/python3.9/site-packages/requests/models.py", line 1021, in raise_for_status
    raise HTTPError(http_error_msg, response=self)
requests.exceptions.HTTPError: 404 Client Error: Not Found for url: https://storage.googleapis.com/wandb-production.appspot.com/ada4321/DiffHPE/agz50rdx/conda-environment.yaml?Expires=1689061312&GoogleAccessId=gorilla-files-url-signer-man%40wandb-production.iam.gserviceaccount.com&Signature=q%2BfT%2BnHvlyQyraB%2F9M2bMuRSISM4nmYvKe4Hg7t%2FFWaGIDc2M75TCUMJ6F45jH%2FtPrvzLIbGsT8w2IeeTWxaDT8ktrzyf4PLbcwYY3ak8rRhR9pygZ%2BWs4YuAppEqlYtihmJjjkdqAfvSdyBntrck3fLLib%2B6WC1KxA4BuCmYqU2kxigLFnsIjVki10YO7xNhqiA3mr1dlK%2FAEjWbc6lzpiF7hDfETSPvHJWcxMW7S9FFGeawJhBxjMrP39uyYEJ%2B8tu%2FmSimKYwLn4up8XaIQd%2BSs4f%2F5oPjEozCddkmlAiOp5EnVuFn7p0jIwhZkLF3NhqUJzH%2F%2FcuxMGY4eRnsA%3D%3D

During handling of the above exception, another exception occurred:

Traceback (most recent call last):
  File "/home/zhuhe/.conda/envs/diffhpe/lib/python3.9/site-packages/wandb/filesync/upload_job.py", line 127, in push
    self._api.upload_file_retry(
  File "/home/zhuhe/.conda/envs/diffhpe/lib/python3.9/site-packages/wandb/apis/normalize.py", line 51, in wrapper
    raise CommError(message, error)
wandb.errors.CommError: <Response [404]>
2023-07-10 15:41:53,852 ERROR   wandb-upload_4:46753 [upload_job.py:push():136] Failed to upload file: /home/zhuhe/HPE-with-Diffusion/wandb/run-20230710_154137-agz50rdx/files/output.log
Traceback (most recent call last):
  File "/home/zhuhe/.conda/envs/diffhpe/lib/python3.9/site-packages/wandb/apis/normalize.py", line 41, in wrapper
    return func(*args, **kwargs)
  File "/home/zhuhe/.conda/envs/diffhpe/lib/python3.9/site-packages/wandb/sdk/lib/retry.py", line 212, in wrapped_fn
    return retrier(*args, **kargs)
  File "/home/zhuhe/.conda/envs/diffhpe/lib/python3.9/site-packages/wandb/sdk/lib/retry.py", line 131, in __call__
    result = self._call_fn(*args, **kwargs)
  File "/home/zhuhe/.conda/envs/diffhpe/lib/python3.9/site-packages/wandb/sdk/internal/internal_api.py", line 2218, in upload_file
    wandb._sentry.reraise(e)
  File "/home/zhuhe/.conda/envs/diffhpe/lib/python3.9/site-packages/wandb/analytics/sentry.py", line 146, in reraise
    raise exc.with_traceback(sys.exc_info()[2])
  File "/home/zhuhe/.conda/envs/diffhpe/lib/python3.9/site-packages/wandb/sdk/internal/internal_api.py", line 2190, in upload_file
    response.raise_for_status()
  File "/home/zhuhe/.conda/envs/diffhpe/lib/python3.9/site-packages/requests/models.py", line 1021, in raise_for_status
    raise HTTPError(http_error_msg, response=self)
requests.exceptions.HTTPError: 404 Client Error: Not Found for url: https://storage.googleapis.com/wandb-production.appspot.com/ada4321/DiffHPE/agz50rdx/output.log?Expires=1689061312&GoogleAccessId=gorilla-files-url-signer-man%40wandb-production.iam.gserviceaccount.com&Signature=EWLKgeUTo5s%2FZRmMZIItPArJqzZYA7DbRkrYHyfJF4plgMhGFcXANwvEqbkDT4GEBiKxsfwGm520nqH67qanj2SGR5onvGH85941GLQmNrAu8hfjJa2Hnu3ZzZq7E6bR9ajszyoStwPB%2F5iv%2B15mBmuKbXu5vmolzepdvdd94oh7Yy%2BxsQDEm0XQajW1oAfhx%2BtMNNj0tQPmiMd1boajrrQpuR%2BVI7h42Kc6TIt4sDIY4HjHP714chP48yYxNL6mjbH1dK%2BzJjWOpeFS%2Belc1hzTUxfhQk%2BrjqhD9R28AbhcrJeOrbVkP8qKal30TzEMClsIoQGlri8G7MD4MrIJzg%3D%3D

During handling of the above exception, another exception occurred:

Traceback (most recent call last):
  File "/home/zhuhe/.conda/envs/diffhpe/lib/python3.9/site-packages/wandb/filesync/upload_job.py", line 127, in push
    self._api.upload_file_retry(
  File "/home/zhuhe/.conda/envs/diffhpe/lib/python3.9/site-packages/wandb/apis/normalize.py", line 51, in wrapper
    raise CommError(message, error)
wandb.errors.CommError: <Response [404]>
2023-07-10 15:41:54,940 ERROR   Thread-11 :46753 [step_upload.py:_handle_event():200] Failed to upload file: /home/zhuhe/HPE-with-Diffusion/wandb/run-20230710_154137-agz50rdx/files/config.yaml
Traceback (most recent call last):
  File "/home/zhuhe/.conda/envs/diffhpe/lib/python3.9/site-packages/wandb/apis/normalize.py", line 41, in wrapper
    return func(*args, **kwargs)
  File "/home/zhuhe/.conda/envs/diffhpe/lib/python3.9/site-packages/wandb/sdk/lib/retry.py", line 212, in wrapped_fn
    return retrier(*args, **kargs)
  File "/home/zhuhe/.conda/envs/diffhpe/lib/python3.9/site-packages/wandb/sdk/lib/retry.py", line 131, in __call__
    result = self._call_fn(*args, **kwargs)
  File "/home/zhuhe/.conda/envs/diffhpe/lib/python3.9/site-packages/wandb/sdk/internal/internal_api.py", line 2218, in upload_file
    wandb._sentry.reraise(e)
  File "/home/zhuhe/.conda/envs/diffhpe/lib/python3.9/site-packages/wandb/analytics/sentry.py", line 146, in reraise
    raise exc.with_traceback(sys.exc_info()[2])
  File "/home/zhuhe/.conda/envs/diffhpe/lib/python3.9/site-packages/wandb/sdk/internal/internal_api.py", line 2190, in upload_file
    response.raise_for_status()
  File "/home/zhuhe/.conda/envs/diffhpe/lib/python3.9/site-packages/requests/models.py", line 1021, in raise_for_status
    raise HTTPError(http_error_msg, response=self)
requests.exceptions.HTTPError: 404 Client Error: Not Found for url: https://storage.googleapis.com/wandb-production.appspot.com/ada4321/DiffHPE/agz50rdx/config.yaml?Expires=1689061312&GoogleAccessId=gorilla-files-url-signer-man%40wandb-production.iam.gserviceaccount.com&Signature=XAhw2DdpwRtZyaBOAPsRMLnS1seWWAbOP5WOMJWUY29LLV9Z45Ilb03Kmrqr9yvNcd%2FAmHtIveexjbwh6US1%2BmuWbzT4ZprP9SP26N%2Ba5MMtM7dQ1jsJqnEvI7cEihQcoQZVVAroqzxmiTApgK2Sz1MOXEiMWjxDKI%2F6OIh%2BOE3vIiOlVEA6M%2Fzu1GYR%2FC7C0TP%2FSxNXThbfQP%2FRpsgv7%2BQDtwUyfEZnC3iYaUJ%2Fsb14LvjEVkzD5qbOmn6tbFqxy5agRQMfvD%2BbxeOmeHIjA0buri4FE9V46f5y6xCyEKK%2FcWD22uhlmSJK8AoLus83Bz1DrwmYpoWV2PZzwSo2AQ%3D%3D

During handling of the above exception, another exception occurred:

Traceback (most recent call last):
  File "/home/zhuhe/.conda/envs/diffhpe/lib/python3.9/concurrent/futures/thread.py", line 58, in run
    result = self.fn(*self.args, **self.kwargs)
  File "/home/zhuhe/.conda/envs/diffhpe/lib/python3.9/site-packages/wandb/filesync/step_upload.py", line 288, in run_and_notify
    self._do_upload_sync(event)
  File "/home/zhuhe/.conda/envs/diffhpe/lib/python3.9/site-packages/wandb/filesync/step_upload.py", line 330, in _do_upload_sync
    job.run()
  File "/home/zhuhe/.conda/envs/diffhpe/lib/python3.9/site-packages/wandb/filesync/upload_job.py", line 57, in run
    self.push()
  File "/home/zhuhe/.conda/envs/diffhpe/lib/python3.9/site-packages/wandb/filesync/upload_job.py", line 127, in push
    self._api.upload_file_retry(
  File "/home/zhuhe/.conda/envs/diffhpe/lib/python3.9/site-packages/wandb/apis/normalize.py", line 51, in wrapper
    raise CommError(message, error)
wandb.errors.CommError: <Response [404]>
2023-07-10 15:41:54,941 ERROR   Thread-11 :46753 [step_upload.py:_handle_event():200] Failed to upload file: /home/zhuhe/HPE-with-Diffusion/wandb/run-20230710_154137-agz50rdx/files/requirements.txt
Traceback (most recent call last):
  File "/home/zhuhe/.conda/envs/diffhpe/lib/python3.9/site-packages/wandb/apis/normalize.py", line 41, in wrapper
    return func(*args, **kwargs)
  File "/home/zhuhe/.conda/envs/diffhpe/lib/python3.9/site-packages/wandb/sdk/lib/retry.py", line 212, in wrapped_fn
    return retrier(*args, **kargs)
  File "/home/zhuhe/.conda/envs/diffhpe/lib/python3.9/site-packages/wandb/sdk/lib/retry.py", line 131, in __call__
    result = self._call_fn(*args, **kwargs)
  File "/home/zhuhe/.conda/envs/diffhpe/lib/python3.9/site-packages/wandb/sdk/internal/internal_api.py", line 2218, in upload_file
    wandb._sentry.reraise(e)
  File "/home/zhuhe/.conda/envs/diffhpe/lib/python3.9/site-packages/wandb/analytics/sentry.py", line 146, in reraise
    raise exc.with_traceback(sys.exc_info()[2])
  File "/home/zhuhe/.conda/envs/diffhpe/lib/python3.9/site-packages/wandb/sdk/internal/internal_api.py", line 2190, in upload_file
    response.raise_for_status()
  File "/home/zhuhe/.conda/envs/diffhpe/lib/python3.9/site-packages/requests/models.py", line 1021, in raise_for_status
    raise HTTPError(http_error_msg, response=self)
requests.exceptions.HTTPError: 404 Client Error: Not Found for url: https://storage.googleapis.com/wandb-production.appspot.com/ada4321/DiffHPE/agz50rdx/requirements.txt?Expires=1689061312&GoogleAccessId=gorilla-files-url-signer-man%40wandb-production.iam.gserviceaccount.com&Signature=BMejroOEp%2BATGltq5jVExLTKiYPQfVg27inE7GNQtYkMxl%2BEyY7fAy0rtKgoVajjNVrFxDznYQxbLMISqGJ%2BaeP1VgIEdyZSo88cpAw%2FePGLxNcP4im3kIWC9ZLABquz%2FaaDZiaYM0wojCMmWE2Pu%2Bujb4lO6GzZfMeMgd20TV2VRmRyFiZztALyDahjCqySr4zEtwMIKWe%2FZD27JCxVoVtSAaCDpfMGYsKpk2d0M3%2FJ8asiNQn7ohS1QJpOu%2BBjfsXyAWTqDvw41vGRtEAktJLXJ%2BngJIPnmoufJl7qaBVis916DZFeSK7Kn8qrGZcbCAYHgYr%2BxlM%2BmfhmsKWZMw%3D%3D

During handling of the above exception, another exception occurred:

Traceback (most recent call last):
  File "/home/zhuhe/.conda/envs/diffhpe/lib/python3.9/concurrent/futures/thread.py", line 58, in run
    result = self.fn(*self.args, **self.kwargs)
  File "/home/zhuhe/.conda/envs/diffhpe/lib/python3.9/site-packages/wandb/filesync/step_upload.py", line 288, in run_and_notify
    self._do_upload_sync(event)
  File "/home/zhuhe/.conda/envs/diffhpe/lib/python3.9/site-packages/wandb/filesync/step_upload.py", line 330, in _do_upload_sync
    job.run()
  File "/home/zhuhe/.conda/envs/diffhpe/lib/python3.9/site-packages/wandb/filesync/upload_job.py", line 57, in run
    self.push()
  File "/home/zhuhe/.conda/envs/diffhpe/lib/python3.9/site-packages/wandb/filesync/upload_job.py", line 127, in push
    self._api.upload_file_retry(
  File "/home/zhuhe/.conda/envs/diffhpe/lib/python3.9/site-packages/wandb/apis/normalize.py", line 51, in wrapper
    raise CommError(message, error)
wandb.errors.CommError: <Response [404]>
2023-07-10 15:41:54,941 ERROR   Thread-11 :46753 [step_upload.py:_handle_event():200] Failed to upload file: /home/zhuhe/HPE-with-Diffusion/wandb/run-20230710_154137-agz50rdx/files/wandb-summary.json
Traceback (most recent call last):
  File "/home/zhuhe/.conda/envs/diffhpe/lib/python3.9/site-packages/wandb/apis/normalize.py", line 41, in wrapper
    return func(*args, **kwargs)
  File "/home/zhuhe/.conda/envs/diffhpe/lib/python3.9/site-packages/wandb/sdk/lib/retry.py", line 212, in wrapped_fn
    return retrier(*args, **kargs)
  File "/home/zhuhe/.conda/envs/diffhpe/lib/python3.9/site-packages/wandb/sdk/lib/retry.py", line 131, in __call__
    result = self._call_fn(*args, **kwargs)
  File "/home/zhuhe/.conda/envs/diffhpe/lib/python3.9/site-packages/wandb/sdk/internal/internal_api.py", line 2218, in upload_file
    wandb._sentry.reraise(e)
  File "/home/zhuhe/.conda/envs/diffhpe/lib/python3.9/site-packages/wandb/analytics/sentry.py", line 146, in reraise
    raise exc.with_traceback(sys.exc_info()[2])
  File "/home/zhuhe/.conda/envs/diffhpe/lib/python3.9/site-packages/wandb/sdk/internal/internal_api.py", line 2190, in upload_file
    response.raise_for_status()
  File "/home/zhuhe/.conda/envs/diffhpe/lib/python3.9/site-packages/requests/models.py", line 1021, in raise_for_status
    raise HTTPError(http_error_msg, response=self)
requests.exceptions.HTTPError: 404 Client Error: Not Found for url: https://storage.googleapis.com/wandb-production.appspot.com/ada4321/DiffHPE/agz50rdx/wandb-summary.json?Expires=1689061312&GoogleAccessId=gorilla-files-url-signer-man%40wandb-production.iam.gserviceaccount.com&Signature=DAogDQBWR7Osn%2FzTuzM5BvybJU3M4iUe8lyCqstiQIwHXqG6oU8hWqb70adzmMqzR0TaIb8aNt1ebOiL7Cxh%2F9306w3fDWrilL0Fj6LQPCN07IzlHu1kzyZi3OMzyMge%2BjrXxKCzJMYkLb6SWh%2FrDfUqx6hM5FpOFpPCr9IrZen1KUGvRLPIpGSIeX9LZrUufSZb4NkMcMT5Sn1zUT%2BwN3U%2BBXFGVKDBzpWtjZ4bUi8sdjI%2B5hcnTzaYw3lAwwdBQA2PbJt6d3diGtOGxc6Q7ru6fcogwvtJrZud14f0FigxDPn8UD90WgR8NNZZcB24lbx5JNUJK8%2BiSp%2FmvT2KGg%3D%3D

During handling of the above exception, another exception occurred:

Traceback (most recent call last):
  File "/home/zhuhe/.conda/envs/diffhpe/lib/python3.9/concurrent/futures/thread.py", line 58, in run
    result = self.fn(*self.args, **self.kwargs)
  File "/home/zhuhe/.conda/envs/diffhpe/lib/python3.9/site-packages/wandb/filesync/step_upload.py", line 288, in run_and_notify
    self._do_upload_sync(event)
  File "/home/zhuhe/.conda/envs/diffhpe/lib/python3.9/site-packages/wandb/filesync/step_upload.py", line 330, in _do_upload_sync
    job.run()
  File "/home/zhuhe/.conda/envs/diffhpe/lib/python3.9/site-packages/wandb/filesync/upload_job.py", line 57, in run
    self.push()
  File "/home/zhuhe/.conda/envs/diffhpe/lib/python3.9/site-packages/wandb/filesync/upload_job.py", line 127, in push
    self._api.upload_file_retry(
  File "/home/zhuhe/.conda/envs/diffhpe/lib/python3.9/site-packages/wandb/apis/normalize.py", line 51, in wrapper
    raise CommError(message, error)
wandb.errors.CommError: <Response [404]>
2023-07-10 15:41:54,941 ERROR   Thread-11 :46753 [step_upload.py:_handle_event():200] Failed to upload file: /home/zhuhe/HPE-with-Diffusion/wandb/run-20230710_154137-agz50rdx/files/conda-environment.yaml
Traceback (most recent call last):
  File "/home/zhuhe/.conda/envs/diffhpe/lib/python3.9/site-packages/wandb/apis/normalize.py", line 41, in wrapper
    return func(*args, **kwargs)
  File "/home/zhuhe/.conda/envs/diffhpe/lib/python3.9/site-packages/wandb/sdk/lib/retry.py", line 212, in wrapped_fn
    return retrier(*args, **kargs)
  File "/home/zhuhe/.conda/envs/diffhpe/lib/python3.9/site-packages/wandb/sdk/lib/retry.py", line 131, in __call__
    result = self._call_fn(*args, **kwargs)
  File "/home/zhuhe/.conda/envs/diffhpe/lib/python3.9/site-packages/wandb/sdk/internal/internal_api.py", line 2218, in upload_file
    wandb._sentry.reraise(e)
  File "/home/zhuhe/.conda/envs/diffhpe/lib/python3.9/site-packages/wandb/analytics/sentry.py", line 146, in reraise
    raise exc.with_traceback(sys.exc_info()[2])
  File "/home/zhuhe/.conda/envs/diffhpe/lib/python3.9/site-packages/wandb/sdk/internal/internal_api.py", line 2190, in upload_file
    response.raise_for_status()
  File "/home/zhuhe/.conda/envs/diffhpe/lib/python3.9/site-packages/requests/models.py", line 1021, in raise_for_status
    raise HTTPError(http_error_msg, response=self)
requests.exceptions.HTTPError: 404 Client Error: Not Found for url: https://storage.googleapis.com/wandb-production.appspot.com/ada4321/DiffHPE/agz50rdx/conda-environment.yaml?Expires=1689061312&GoogleAccessId=gorilla-files-url-signer-man%40wandb-production.iam.gserviceaccount.com&Signature=q%2BfT%2BnHvlyQyraB%2F9M2bMuRSISM4nmYvKe4Hg7t%2FFWaGIDc2M75TCUMJ6F45jH%2FtPrvzLIbGsT8w2IeeTWxaDT8ktrzyf4PLbcwYY3ak8rRhR9pygZ%2BWs4YuAppEqlYtihmJjjkdqAfvSdyBntrck3fLLib%2B6WC1KxA4BuCmYqU2kxigLFnsIjVki10YO7xNhqiA3mr1dlK%2FAEjWbc6lzpiF7hDfETSPvHJWcxMW7S9FFGeawJhBxjMrP39uyYEJ%2B8tu%2FmSimKYwLn4up8XaIQd%2BSs4f%2F5oPjEozCddkmlAiOp5EnVuFn7p0jIwhZkLF3NhqUJzH%2F%2FcuxMGY4eRnsA%3D%3D

During handling of the above exception, another exception occurred:

Traceback (most recent call last):
  File "/home/zhuhe/.conda/envs/diffhpe/lib/python3.9/concurrent/futures/thread.py", line 58, in run
    result = self.fn(*self.args, **self.kwargs)
  File "/home/zhuhe/.conda/envs/diffhpe/lib/python3.9/site-packages/wandb/filesync/step_upload.py", line 288, in run_and_notify
    self._do_upload_sync(event)
  File "/home/zhuhe/.conda/envs/diffhpe/lib/python3.9/site-packages/wandb/filesync/step_upload.py", line 330, in _do_upload_sync
    job.run()
  File "/home/zhuhe/.conda/envs/diffhpe/lib/python3.9/site-packages/wandb/filesync/upload_job.py", line 57, in run
    self.push()
  File "/home/zhuhe/.conda/envs/diffhpe/lib/python3.9/site-packages/wandb/filesync/upload_job.py", line 127, in push
    self._api.upload_file_retry(
  File "/home/zhuhe/.conda/envs/diffhpe/lib/python3.9/site-packages/wandb/apis/normalize.py", line 51, in wrapper
    raise CommError(message, error)
wandb.errors.CommError: <Response [404]>
2023-07-10 15:41:54,942 ERROR   Thread-11 :46753 [step_upload.py:_handle_event():200] Failed to upload file: /home/zhuhe/HPE-with-Diffusion/wandb/run-20230710_154137-agz50rdx/files/output.log
Traceback (most recent call last):
  File "/home/zhuhe/.conda/envs/diffhpe/lib/python3.9/site-packages/wandb/apis/normalize.py", line 41, in wrapper
    return func(*args, **kwargs)
  File "/home/zhuhe/.conda/envs/diffhpe/lib/python3.9/site-packages/wandb/sdk/lib/retry.py", line 212, in wrapped_fn
    return retrier(*args, **kargs)
  File "/home/zhuhe/.conda/envs/diffhpe/lib/python3.9/site-packages/wandb/sdk/lib/retry.py", line 131, in __call__
    result = self._call_fn(*args, **kwargs)
  File "/home/zhuhe/.conda/envs/diffhpe/lib/python3.9/site-packages/wandb/sdk/internal/internal_api.py", line 2218, in upload_file
    wandb._sentry.reraise(e)
  File "/home/zhuhe/.conda/envs/diffhpe/lib/python3.9/site-packages/wandb/analytics/sentry.py", line 146, in reraise
    raise exc.with_traceback(sys.exc_info()[2])
  File "/home/zhuhe/.conda/envs/diffhpe/lib/python3.9/site-packages/wandb/sdk/internal/internal_api.py", line 2190, in upload_file
    response.raise_for_status()
  File "/home/zhuhe/.conda/envs/diffhpe/lib/python3.9/site-packages/requests/models.py", line 1021, in raise_for_status
    raise HTTPError(http_error_msg, response=self)
requests.exceptions.HTTPError: 404 Client Error: Not Found for url: https://storage.googleapis.com/wandb-production.appspot.com/ada4321/DiffHPE/agz50rdx/output.log?Expires=1689061312&GoogleAccessId=gorilla-files-url-signer-man%40wandb-production.iam.gserviceaccount.com&Signature=EWLKgeUTo5s%2FZRmMZIItPArJqzZYA7DbRkrYHyfJF4plgMhGFcXANwvEqbkDT4GEBiKxsfwGm520nqH67qanj2SGR5onvGH85941GLQmNrAu8hfjJa2Hnu3ZzZq7E6bR9ajszyoStwPB%2F5iv%2B15mBmuKbXu5vmolzepdvdd94oh7Yy%2BxsQDEm0XQajW1oAfhx%2BtMNNj0tQPmiMd1boajrrQpuR%2BVI7h42Kc6TIt4sDIY4HjHP714chP48yYxNL6mjbH1dK%2BzJjWOpeFS%2Belc1hzTUxfhQk%2BrjqhD9R28AbhcrJeOrbVkP8qKal30TzEMClsIoQGlri8G7MD4MrIJzg%3D%3D

During handling of the above exception, another exception occurred:

Traceback (most recent call last):
  File "/home/zhuhe/.conda/envs/diffhpe/lib/python3.9/concurrent/futures/thread.py", line 58, in run
    result = self.fn(*self.args, **self.kwargs)
  File "/home/zhuhe/.conda/envs/diffhpe/lib/python3.9/site-packages/wandb/filesync/step_upload.py", line 288, in run_and_notify
    self._do_upload_sync(event)
  File "/home/zhuhe/.conda/envs/diffhpe/lib/python3.9/site-packages/wandb/filesync/step_upload.py", line 330, in _do_upload_sync
    job.run()
  File "/home/zhuhe/.conda/envs/diffhpe/lib/python3.9/site-packages/wandb/filesync/upload_job.py", line 57, in run
    self.push()
  File "/home/zhuhe/.conda/envs/diffhpe/lib/python3.9/site-packages/wandb/filesync/upload_job.py", line 127, in push
    self._api.upload_file_retry(
  File "/home/zhuhe/.conda/envs/diffhpe/lib/python3.9/site-packages/wandb/apis/normalize.py", line 51, in wrapper
    raise CommError(message, error)
wandb.errors.CommError: <Response [404]>
2023-07-10 15:41:55,142 INFO    Thread-11 :46753 [sender.py:transition_state():602] send defer: 11
2023-07-10 15:41:55,142 DEBUG   HandlerThread:46753 [handler.py:handle_request():144] handle_request: defer
2023-07-10 15:41:55,142 INFO    HandlerThread:46753 [handler.py:handle_request_defer():170] handle defer: 11
2023-07-10 15:41:55,143 DEBUG   SenderThread:46753 [sender.py:send_request():396] send_request: defer
2023-07-10 15:41:55,143 INFO    SenderThread:46753 [sender.py:send_request_defer():598] handle sender defer: 11
2023-07-10 15:41:55,143 INFO    SenderThread:46753 [file_pusher.py:join():164] waiting for file pusher
2023-07-10 15:41:55,143 INFO    SenderThread:46753 [sender.py:transition_state():602] send defer: 12
2023-07-10 15:41:55,143 DEBUG   HandlerThread:46753 [handler.py:handle_request():144] handle_request: defer
2023-07-10 15:41:55,143 INFO    HandlerThread:46753 [handler.py:handle_request_defer():170] handle defer: 12
2023-07-10 15:41:55,143 DEBUG   SenderThread:46753 [sender.py:send_request():396] send_request: defer
2023-07-10 15:41:55,143 INFO    SenderThread:46753 [sender.py:send_request_defer():598] handle sender defer: 12
2023-07-10 15:41:55,409 INFO    SenderThread:46753 [sender.py:transition_state():602] send defer: 13
2023-07-10 15:41:55,409 DEBUG   HandlerThread:46753 [handler.py:handle_request():144] handle_request: defer
2023-07-10 15:41:55,409 INFO    HandlerThread:46753 [handler.py:handle_request_defer():170] handle defer: 13
2023-07-10 15:41:55,410 DEBUG   SenderThread:46753 [sender.py:send_request():396] send_request: defer
2023-07-10 15:41:55,410 INFO    SenderThread:46753 [sender.py:send_request_defer():598] handle sender defer: 13
2023-07-10 15:41:55,410 INFO    SenderThread:46753 [sender.py:transition_state():602] send defer: 14
2023-07-10 15:41:55,410 DEBUG   HandlerThread:46753 [handler.py:handle_request():144] handle_request: defer
2023-07-10 15:41:55,410 INFO    HandlerThread:46753 [handler.py:handle_request_defer():170] handle defer: 14
2023-07-10 15:41:55,410 DEBUG   SenderThread:46753 [sender.py:send():369] send: final
2023-07-10 15:41:55,410 DEBUG   SenderThread:46753 [sender.py:send():369] send: footer
2023-07-10 15:41:55,410 DEBUG   SenderThread:46753 [sender.py:send_request():396] send_request: defer
2023-07-10 15:41:55,410 INFO    SenderThread:46753 [sender.py:send_request_defer():598] handle sender defer: 14
2023-07-10 15:41:55,411 DEBUG   HandlerThread:46753 [handler.py:handle_request():144] handle_request: poll_exit
2023-07-10 15:41:55,411 DEBUG   HandlerThread:46753 [handler.py:handle_request():144] handle_request: server_info
2023-07-10 15:41:55,411 DEBUG   HandlerThread:46753 [handler.py:handle_request():144] handle_request: get_summary
2023-07-10 15:41:55,411 DEBUG   HandlerThread:46753 [handler.py:handle_request():144] handle_request: sampled_history
2023-07-10 15:41:55,412 DEBUG   SenderThread:46753 [sender.py:send_request():396] send_request: poll_exit
2023-07-10 15:41:55,412 DEBUG   SenderThread:46753 [sender.py:send_request():396] send_request: server_info
2023-07-10 15:41:55,860 INFO    MainThread:46753 [wandb_run.py:_footer_history_summary_info():3467] rendering history
2023-07-10 15:41:55,860 INFO    MainThread:46753 [wandb_run.py:_footer_history_summary_info():3499] rendering summary
2023-07-10 15:41:55,860 INFO    MainThread:46753 [wandb_run.py:_footer_sync_info():3426] logging synced files
2023-07-10 15:41:55,860 DEBUG   HandlerThread:46753 [handler.py:handle_request():144] handle_request: shutdown
2023-07-10 15:41:55,860 INFO    HandlerThread:46753 [handler.py:finish():854] shutting down handler
2023-07-10 15:41:56,412 INFO    WriterThread:46753 [datastore.py:close():298] close: /home/zhuhe/HPE-with-Diffusion/wandb/run-20230710_154137-agz50rdx/run-agz50rdx.wandb
2023-07-10 15:41:56,860 INFO    SenderThread:46753 [sender.py:finish():1526] shutting down sender
2023-07-10 15:41:56,860 INFO    SenderThread:46753 [file_pusher.py:finish():159] shutting down file pusher
2023-07-10 15:41:56,860 INFO    SenderThread:46753 [file_pusher.py:join():164] waiting for file pusher
