2023-07-10 18:43:56,819 INFO    StreamThr :20949 [internal.py:wandb_internal():86] W&B internal server running at pid: 20949, started at: 2023-07-10 18:43:56.819488
2023-07-10 18:43:56,821 DEBUG   HandlerThread:20949 [handler.py:handle_request():144] handle_request: status
2023-07-10 18:43:56,821 INFO    WriterThread:20949 [datastore.py:open_for_write():85] open: /home/zhuhe/HPE-with-Diffusion/wandb/run-20230710_184356-uq8ma9hv/run-uq8ma9hv.wandb
2023-07-10 18:43:56,822 DEBUG   SenderThread:20949 [sender.py:send():369] send: header
2023-07-10 18:43:56,822 DEBUG   SenderThread:20949 [sender.py:send():369] send: run
2023-07-10 18:43:57,727 INFO    SenderThread:20949 [dir_watcher.py:__init__():211] watching files in: /home/zhuhe/HPE-with-Diffusion/wandb/run-20230710_184356-uq8ma9hv/files
2023-07-10 18:43:57,727 INFO    SenderThread:20949 [sender.py:_start_run_threads():1100] run started: uq8ma9hv with start time 1688985836.818627
2023-07-10 18:43:57,727 DEBUG   SenderThread:20949 [sender.py:send_request():396] send_request: summary_record
2023-07-10 18:43:57,727 INFO    SenderThread:20949 [sender.py:_save_file():1354] saving file wandb-summary.json with policy end
2023-07-10 18:43:57,729 DEBUG   HandlerThread:20949 [handler.py:handle_request():144] handle_request: check_version
2023-07-10 18:43:57,729 DEBUG   SenderThread:20949 [sender.py:send_request():396] send_request: check_version
2023-07-10 18:43:57,907 DEBUG   HandlerThread:20949 [handler.py:handle_request():144] handle_request: run_start
2023-07-10 18:43:57,911 DEBUG   HandlerThread:20949 [system_info.py:__init__():31] System info init
2023-07-10 18:43:57,911 DEBUG   HandlerThread:20949 [system_info.py:__init__():46] System info init done
2023-07-10 18:43:57,911 INFO    HandlerThread:20949 [system_monitor.py:start():181] Starting system monitor
2023-07-10 18:43:57,911 INFO    SystemMonitor:20949 [system_monitor.py:_start():145] Starting system asset monitoring threads
2023-07-10 18:43:57,911 INFO    HandlerThread:20949 [system_monitor.py:probe():201] Collecting system info
2023-07-10 18:43:57,912 INFO    SystemMonitor:20949 [interfaces.py:start():190] Started cpu monitoring
2023-07-10 18:43:57,913 INFO    SystemMonitor:20949 [interfaces.py:start():190] Started disk monitoring
2023-07-10 18:43:57,913 INFO    SystemMonitor:20949 [interfaces.py:start():190] Started gpu monitoring
2023-07-10 18:43:57,913 INFO    SystemMonitor:20949 [interfaces.py:start():190] Started memory monitoring
2023-07-10 18:43:57,914 INFO    SystemMonitor:20949 [interfaces.py:start():190] Started network monitoring
2023-07-10 18:43:57,928 DEBUG   HandlerThread:20949 [system_info.py:probe():195] Probing system
2023-07-10 18:43:57,931 DEBUG   HandlerThread:20949 [gitlib.py:_init_repo():53] git repository is invalid
2023-07-10 18:43:57,931 DEBUG   HandlerThread:20949 [system_info.py:probe():240] Probing system done
2023-07-10 18:43:57,931 DEBUG   HandlerThread:20949 [system_monitor.py:probe():210] {'os': 'Linux-5.19.0-46-generic-x86_64-with-glibc2.35', 'python': '3.9.16', 'heartbeatAt': '2023-07-10T10:43:57.928908', 'startedAt': '2023-07-10T10:43:56.815364', 'docker': None, 'cuda': None, 'args': ('--phase', 'train', '--gpu_ids', '1'), 'state': 'running', 'program': '/home/zhuhe/HPE-with-Diffusion/main.py', 'codePath': 'main.py', 'host': '415-2', 'username': 'zhuhe', 'executable': '/home/zhuhe/.conda/envs/diffhpe/bin/python', 'cpu_count': 16, 'cpu_count_logical': 24, 'cpu_freq': {'current': 4259.004416666667, 'min': 800.0, 'max': 4783.333333333333}, 'cpu_freq_per_core': [{'current': 5037.444, 'min': 800.0, 'max': 5100.0}, {'current': 5002.872, 'min': 800.0, 'max': 5100.0}, {'current': 5100.0, 'min': 800.0, 'max': 5100.0}, {'current': 4204.844, 'min': 800.0, 'max': 5100.0}, {'current': 5003.417, 'min': 800.0, 'max': 5100.0}, {'current': 5094.426, 'min': 800.0, 'max': 5100.0}, {'current': 4912.733, 'min': 800.0, 'max': 5100.0}, {'current': 4374.107, 'min': 800.0, 'max': 5100.0}, {'current': 5132.071, 'min': 800.0, 'max': 5200.0}, {'current': 2100.0, 'min': 800.0, 'max': 5200.0}, {'current': 5031.84, 'min': 800.0, 'max': 5200.0}, {'current': 2100.0, 'min': 800.0, 'max': 5200.0}, {'current': 5042.833, 'min': 800.0, 'max': 5100.0}, {'current': 4383.286, 'min': 800.0, 'max': 5100.0}, {'current': 5000.357, 'min': 800.0, 'max': 5100.0}, {'current': 5087.928, 'min': 800.0, 'max': 5100.0}, {'current': 3703.649, 'min': 800.0, 'max': 4100.0}, {'current': 3700.014, 'min': 800.0, 'max': 4100.0}, {'current': 3699.974, 'min': 800.0, 'max': 4100.0}, {'current': 3704.268, 'min': 800.0, 'max': 4100.0}, {'current': 3700.004, 'min': 800.0, 'max': 4100.0}, {'current': 3700.011, 'min': 800.0, 'max': 4100.0}, {'current': 3699.996, 'min': 800.0, 'max': 4100.0}, {'current': 3700.032, 'min': 800.0, 'max': 4100.0}], 'disk': {'total': 93.31179428100586, 'used': 0.01807403564453125}, 'gpu': 'NVIDIA GeForce RTX 3090', 'gpu_count': 2, 'gpu_devices': [{'name': 'NVIDIA GeForce RTX 3090', 'memory_total': 25769803776}, {'name': 'NVIDIA GeForce RTX 3090', 'memory_total': 25769803776}], 'memory': {'total': 31.185558319091797}}
2023-07-10 18:43:57,931 INFO    HandlerThread:20949 [system_monitor.py:probe():211] Finished collecting system info
2023-07-10 18:43:57,931 INFO    HandlerThread:20949 [system_monitor.py:probe():214] Publishing system info
2023-07-10 18:43:57,931 DEBUG   HandlerThread:20949 [system_info.py:_save_pip():51] Saving list of pip packages installed into the current environment
2023-07-10 18:43:57,931 DEBUG   HandlerThread:20949 [system_info.py:_save_pip():67] Saving pip packages done
2023-07-10 18:43:57,931 DEBUG   HandlerThread:20949 [system_info.py:_save_conda():74] Saving list of conda packages installed into the current environment
2023-07-10 18:43:58,698 DEBUG   HandlerThread:20949 [system_info.py:_save_conda():86] Saving conda packages done
2023-07-10 18:43:58,698 INFO    HandlerThread:20949 [system_monitor.py:probe():216] Finished publishing system info
2023-07-10 18:43:58,700 DEBUG   SenderThread:20949 [sender.py:send():369] send: files
2023-07-10 18:43:58,700 INFO    SenderThread:20949 [sender.py:_save_file():1354] saving file wandb-metadata.json with policy now
2023-07-10 18:43:58,703 DEBUG   HandlerThread:20949 [handler.py:handle_request():144] handle_request: stop_status
2023-07-10 18:43:58,703 DEBUG   SenderThread:20949 [sender.py:send_request():396] send_request: stop_status
2023-07-10 18:43:58,728 INFO    Thread-12 :20949 [dir_watcher.py:_on_file_created():272] file/dir created: /home/zhuhe/HPE-with-Diffusion/wandb/run-20230710_184356-uq8ma9hv/files/conda-environment.yaml
2023-07-10 18:43:58,728 INFO    Thread-12 :20949 [dir_watcher.py:_on_file_created():272] file/dir created: /home/zhuhe/HPE-with-Diffusion/wandb/run-20230710_184356-uq8ma9hv/files/wandb-summary.json
2023-07-10 18:43:58,728 INFO    Thread-12 :20949 [dir_watcher.py:_on_file_created():272] file/dir created: /home/zhuhe/HPE-with-Diffusion/wandb/run-20230710_184356-uq8ma9hv/files/wandb-metadata.json
2023-07-10 18:43:58,728 INFO    Thread-12 :20949 [dir_watcher.py:_on_file_created():272] file/dir created: /home/zhuhe/HPE-with-Diffusion/wandb/run-20230710_184356-uq8ma9hv/files/requirements.txt
2023-07-10 18:43:59,195 ERROR   wandb-upload_0:20949 [internal_api.py:upload_file():2192] upload_file exception https://storage.googleapis.com/wandb-production.appspot.com/ada4321/DiffHPE/uq8ma9hv/wandb-metadata.json?Expires=1689072238&GoogleAccessId=gorilla-files-url-signer-man%40wandb-production.iam.gserviceaccount.com&Signature=BLOC8JPickawEusAiEPzSvEKaWYJ0nC0BJIg9lzORA6V26ylg2fuYCLjlJQyg4iVveH5BmcEYv%2BVRCEXJ%2FjNdJt4rE%2BRV4upwPwwkKVA%2BiyHYXMypoQY6tz25U2fCUlogl%2Bpjrl29Anj9B%2F%2FJoY4yg7aAIoDazj1vZCulXz6f763L%2Fq%2FZ4laRhI%2Bgw2R%2FnwERxUtsRudy7cdSq2Jd4AutgsOZ%2BCXpLFv6H9mKKkCg%2FDePHe77%2FkjAirQCjyzwo8TnDFkEVHrFKP%2B1DNhPf%2FzPmvllJqVLRJubb7z79mN%2B0otZdoGIyQolaRvrySO1RC2vr7u%2FM%2BoY2NMdwW5GEQd7g%3D%3D: 404 Client Error: Not Found for url: https://storage.googleapis.com/wandb-production.appspot.com/ada4321/DiffHPE/uq8ma9hv/wandb-metadata.json?Expires=1689072238&GoogleAccessId=gorilla-files-url-signer-man%40wandb-production.iam.gserviceaccount.com&Signature=BLOC8JPickawEusAiEPzSvEKaWYJ0nC0BJIg9lzORA6V26ylg2fuYCLjlJQyg4iVveH5BmcEYv%2BVRCEXJ%2FjNdJt4rE%2BRV4upwPwwkKVA%2BiyHYXMypoQY6tz25U2fCUlogl%2Bpjrl29Anj9B%2F%2FJoY4yg7aAIoDazj1vZCulXz6f763L%2Fq%2FZ4laRhI%2Bgw2R%2FnwERxUtsRudy7cdSq2Jd4AutgsOZ%2BCXpLFv6H9mKKkCg%2FDePHe77%2FkjAirQCjyzwo8TnDFkEVHrFKP%2B1DNhPf%2FzPmvllJqVLRJubb7z79mN%2B0otZdoGIyQolaRvrySO1RC2vr7u%2FM%2BoY2NMdwW5GEQd7g%3D%3D
2023-07-10 18:43:59,195 ERROR   wandb-upload_0:20949 [internal_api.py:upload_file():2194] upload_file request headers: {'User-Agent': 'python-requests/2.31.0', 'Accept-Encoding': 'gzip, deflate', 'Accept': '*/*', 'Connection': 'keep-alive', 'Content-Length': '3719'}
2023-07-10 18:43:59,195 ERROR   wandb-upload_0:20949 [internal_api.py:upload_file():2196] upload_file response body: b'<!DOCTYPE html>\n<html lang=en>\n  <meta charset=utf-8>\n  <meta name=viewport content="initial-scale=1, minimum-scale=1, width=device-width">\n  <title>Error 404 (Not Found)!!1</title>\n  <style>\n    *{margin:0;padding:0}html,code{font:15px/22px arial,sans-serif}html{background:#fff;color:#222;padding:15px}body{margin:7% auto 0;max-width:390px;min-height:180px;padding:30px 0 15px}* > body{background:url(//www.google.com/images/errors/robot.png) 100% 5px no-repeat;padding-right:205px}p{margin:11px 0 22px;overflow:hidden}ins{color:#777;text-decoration:none}a img{border:0}@media screen and (max-width:772px){body{background:none;margin-top:0;max-width:none;padding-right:0}}#logo{background:url(//www.google.com/images/branding/googlelogo/1x/googlelogo_color_150x54dp.png) no-repeat;margin-left:-5px}@media only screen and (min-resolution:192dpi){#logo{background:url(//www.google.com/images/branding/googlelogo/2x/googlelogo_color_150x54dp.png) no-repeat 0% 0%/100% 100%;-moz-border-image:url(//www.google.com/images/branding/googlelogo/2x/googlelogo_color_150x54dp.png) 0}}@media only screen and (-webkit-min-device-pixel-ratio:2){#logo{background:url(//www.google.com/images/branding/googlelogo/2x/googlelogo_color_150x54dp.png) no-repeat;-webkit-background-size:100% 100%}}#logo{display:inline-block;height:54px;width:150px}\n  </style>\n  <a href=//www.google.com/><span id=logo aria-label=Google></span></a>\n  <p><b>404.</b> <ins>That\xe2\x80\x99s an error.</ins>\n  <p>The requested URL <code>/wandb-production.appspot.com/ada4321/DiffHPE/uq8ma9hv/wandb-metadata.json</code> was not found on this server.  <ins>That\xe2\x80\x99s all we know.</ins>\n'
2023-07-10 18:43:59,252 DEBUG   SenderThread:20949 [sender.py:send():369] send: telemetry
2023-07-10 18:43:59,729 INFO    Thread-12 :20949 [dir_watcher.py:_on_file_created():272] file/dir created: /home/zhuhe/HPE-with-Diffusion/wandb/run-20230710_184356-uq8ma9hv/files/output.log
2023-07-10 18:43:59,816 ERROR   wandb-upload_0:20949 [upload_job.py:push():136] Failed to upload file: /tmp/tmp8r5w_1ybwandb/gwcdo1gw-wandb-metadata.json
Traceback (most recent call last):
  File "/home/zhuhe/.conda/envs/diffhpe/lib/python3.9/site-packages/wandb/apis/normalize.py", line 41, in wrapper
    return func(*args, **kwargs)
  File "/home/zhuhe/.conda/envs/diffhpe/lib/python3.9/site-packages/wandb/sdk/lib/retry.py", line 212, in wrapped_fn
    return retrier(*args, **kargs)
  File "/home/zhuhe/.conda/envs/diffhpe/lib/python3.9/site-packages/wandb/sdk/lib/retry.py", line 131, in __call__
    result = self._call_fn(*args, **kwargs)
  File "/home/zhuhe/.conda/envs/diffhpe/lib/python3.9/site-packages/wandb/sdk/internal/internal_api.py", line 2218, in upload_file
    wandb._sentry.reraise(e)
  File "/home/zhuhe/.conda/envs/diffhpe/lib/python3.9/site-packages/wandb/analytics/sentry.py", line 146, in reraise
    raise exc.with_traceback(sys.exc_info()[2])
  File "/home/zhuhe/.conda/envs/diffhpe/lib/python3.9/site-packages/wandb/sdk/internal/internal_api.py", line 2190, in upload_file
    response.raise_for_status()
  File "/home/zhuhe/.conda/envs/diffhpe/lib/python3.9/site-packages/requests/models.py", line 1021, in raise_for_status
    raise HTTPError(http_error_msg, response=self)
requests.exceptions.HTTPError: 404 Client Error: Not Found for url: https://storage.googleapis.com/wandb-production.appspot.com/ada4321/DiffHPE/uq8ma9hv/wandb-metadata.json?Expires=1689072238&GoogleAccessId=gorilla-files-url-signer-man%40wandb-production.iam.gserviceaccount.com&Signature=BLOC8JPickawEusAiEPzSvEKaWYJ0nC0BJIg9lzORA6V26ylg2fuYCLjlJQyg4iVveH5BmcEYv%2BVRCEXJ%2FjNdJt4rE%2BRV4upwPwwkKVA%2BiyHYXMypoQY6tz25U2fCUlogl%2Bpjrl29Anj9B%2F%2FJoY4yg7aAIoDazj1vZCulXz6f763L%2Fq%2FZ4laRhI%2Bgw2R%2FnwERxUtsRudy7cdSq2Jd4AutgsOZ%2BCXpLFv6H9mKKkCg%2FDePHe77%2FkjAirQCjyzwo8TnDFkEVHrFKP%2B1DNhPf%2FzPmvllJqVLRJubb7z79mN%2B0otZdoGIyQolaRvrySO1RC2vr7u%2FM%2BoY2NMdwW5GEQd7g%3D%3D

During handling of the above exception, another exception occurred:

Traceback (most recent call last):
  File "/home/zhuhe/.conda/envs/diffhpe/lib/python3.9/site-packages/wandb/filesync/upload_job.py", line 127, in push
    self._api.upload_file_retry(
  File "/home/zhuhe/.conda/envs/diffhpe/lib/python3.9/site-packages/wandb/apis/normalize.py", line 51, in wrapper
    raise CommError(message, error)
wandb.errors.CommError: <Response [404]>
2023-07-10 18:44:00,043 ERROR   Thread-11 :20949 [step_upload.py:_handle_event():200] Failed to upload file: /tmp/tmp8r5w_1ybwandb/gwcdo1gw-wandb-metadata.json
Traceback (most recent call last):
  File "/home/zhuhe/.conda/envs/diffhpe/lib/python3.9/site-packages/wandb/apis/normalize.py", line 41, in wrapper
    return func(*args, **kwargs)
  File "/home/zhuhe/.conda/envs/diffhpe/lib/python3.9/site-packages/wandb/sdk/lib/retry.py", line 212, in wrapped_fn
    return retrier(*args, **kargs)
  File "/home/zhuhe/.conda/envs/diffhpe/lib/python3.9/site-packages/wandb/sdk/lib/retry.py", line 131, in __call__
    result = self._call_fn(*args, **kwargs)
  File "/home/zhuhe/.conda/envs/diffhpe/lib/python3.9/site-packages/wandb/sdk/internal/internal_api.py", line 2218, in upload_file
    wandb._sentry.reraise(e)
  File "/home/zhuhe/.conda/envs/diffhpe/lib/python3.9/site-packages/wandb/analytics/sentry.py", line 146, in reraise
    raise exc.with_traceback(sys.exc_info()[2])
  File "/home/zhuhe/.conda/envs/diffhpe/lib/python3.9/site-packages/wandb/sdk/internal/internal_api.py", line 2190, in upload_file
    response.raise_for_status()
  File "/home/zhuhe/.conda/envs/diffhpe/lib/python3.9/site-packages/requests/models.py", line 1021, in raise_for_status
    raise HTTPError(http_error_msg, response=self)
requests.exceptions.HTTPError: 404 Client Error: Not Found for url: https://storage.googleapis.com/wandb-production.appspot.com/ada4321/DiffHPE/uq8ma9hv/wandb-metadata.json?Expires=1689072238&GoogleAccessId=gorilla-files-url-signer-man%40wandb-production.iam.gserviceaccount.com&Signature=BLOC8JPickawEusAiEPzSvEKaWYJ0nC0BJIg9lzORA6V26ylg2fuYCLjlJQyg4iVveH5BmcEYv%2BVRCEXJ%2FjNdJt4rE%2BRV4upwPwwkKVA%2BiyHYXMypoQY6tz25U2fCUlogl%2Bpjrl29Anj9B%2F%2FJoY4yg7aAIoDazj1vZCulXz6f763L%2Fq%2FZ4laRhI%2Bgw2R%2FnwERxUtsRudy7cdSq2Jd4AutgsOZ%2BCXpLFv6H9mKKkCg%2FDePHe77%2FkjAirQCjyzwo8TnDFkEVHrFKP%2B1DNhPf%2FzPmvllJqVLRJubb7z79mN%2B0otZdoGIyQolaRvrySO1RC2vr7u%2FM%2BoY2NMdwW5GEQd7g%3D%3D

During handling of the above exception, another exception occurred:

Traceback (most recent call last):
  File "/home/zhuhe/.conda/envs/diffhpe/lib/python3.9/concurrent/futures/thread.py", line 58, in run
    result = self.fn(*self.args, **self.kwargs)
  File "/home/zhuhe/.conda/envs/diffhpe/lib/python3.9/site-packages/wandb/filesync/step_upload.py", line 288, in run_and_notify
    self._do_upload_sync(event)
  File "/home/zhuhe/.conda/envs/diffhpe/lib/python3.9/site-packages/wandb/filesync/step_upload.py", line 330, in _do_upload_sync
    job.run()
  File "/home/zhuhe/.conda/envs/diffhpe/lib/python3.9/site-packages/wandb/filesync/upload_job.py", line 57, in run
    self.push()
  File "/home/zhuhe/.conda/envs/diffhpe/lib/python3.9/site-packages/wandb/filesync/upload_job.py", line 127, in push
    self._api.upload_file_retry(
  File "/home/zhuhe/.conda/envs/diffhpe/lib/python3.9/site-packages/wandb/apis/normalize.py", line 51, in wrapper
    raise CommError(message, error)
wandb.errors.CommError: <Response [404]>
2023-07-10 18:44:01,729 INFO    Thread-12 :20949 [dir_watcher.py:_on_file_modified():289] file/dir modified: /home/zhuhe/HPE-with-Diffusion/wandb/run-20230710_184356-uq8ma9hv/files/output.log
2023-07-10 18:44:02,192 DEBUG   HandlerThread:20949 [handler.py:handle_request():144] handle_request: status_report
2023-07-10 18:44:03,730 INFO    Thread-12 :20949 [dir_watcher.py:_on_file_modified():289] file/dir modified: /home/zhuhe/HPE-with-Diffusion/wandb/run-20230710_184356-uq8ma9hv/files/output.log
2023-07-10 18:44:06,511 DEBUG   SenderThread:20949 [sender.py:send():369] send: telemetry
2023-07-10 18:44:07,572 DEBUG   HandlerThread:20949 [handler.py:handle_request():144] handle_request: status_report
2023-07-10 18:44:07,731 INFO    Thread-12 :20949 [dir_watcher.py:_on_file_modified():289] file/dir modified: /home/zhuhe/HPE-with-Diffusion/wandb/run-20230710_184356-uq8ma9hv/files/output.log
2023-07-10 18:44:10,541 DEBUG   SenderThread:20949 [sender.py:send():369] send: exit
2023-07-10 18:44:10,541 INFO    SenderThread:20949 [sender.py:send_exit():574] handling exit code: 1
2023-07-10 18:44:10,541 INFO    SenderThread:20949 [sender.py:send_exit():576] handling runtime: 12
2023-07-10 18:44:10,542 INFO    SenderThread:20949 [sender.py:_save_file():1354] saving file wandb-summary.json with policy end
2023-07-10 18:44:10,542 INFO    SenderThread:20949 [sender.py:send_exit():582] send defer
2023-07-10 18:44:10,542 DEBUG   HandlerThread:20949 [handler.py:handle_request():144] handle_request: defer
2023-07-10 18:44:10,542 INFO    HandlerThread:20949 [handler.py:handle_request_defer():170] handle defer: 0
2023-07-10 18:44:10,542 DEBUG   SenderThread:20949 [sender.py:send_request():396] send_request: defer
2023-07-10 18:44:10,542 INFO    SenderThread:20949 [sender.py:send_request_defer():598] handle sender defer: 0
2023-07-10 18:44:10,542 INFO    SenderThread:20949 [sender.py:transition_state():602] send defer: 1
2023-07-10 18:44:10,542 DEBUG   HandlerThread:20949 [handler.py:handle_request():144] handle_request: defer
2023-07-10 18:44:10,542 INFO    HandlerThread:20949 [handler.py:handle_request_defer():170] handle defer: 1
2023-07-10 18:44:10,542 DEBUG   SenderThread:20949 [sender.py:send_request():396] send_request: defer
2023-07-10 18:44:10,542 INFO    SenderThread:20949 [sender.py:send_request_defer():598] handle sender defer: 1
2023-07-10 18:44:10,542 INFO    SenderThread:20949 [sender.py:transition_state():602] send defer: 2
2023-07-10 18:44:10,542 DEBUG   HandlerThread:20949 [handler.py:handle_request():144] handle_request: defer
2023-07-10 18:44:10,542 INFO    HandlerThread:20949 [handler.py:handle_request_defer():170] handle defer: 2
2023-07-10 18:44:10,542 INFO    HandlerThread:20949 [system_monitor.py:finish():190] Stopping system monitor
2023-07-10 18:44:10,543 INFO    HandlerThread:20949 [interfaces.py:finish():202] Joined cpu monitor
2023-07-10 18:44:10,543 INFO    HandlerThread:20949 [interfaces.py:finish():202] Joined disk monitor
2023-07-10 18:44:10,543 DEBUG   SystemMonitor:20949 [system_monitor.py:_start():159] Starting system metrics aggregation loop
2023-07-10 18:44:10,543 DEBUG   SystemMonitor:20949 [system_monitor.py:_start():166] Finished system metrics aggregation loop
2023-07-10 18:44:10,543 DEBUG   SystemMonitor:20949 [system_monitor.py:_start():170] Publishing last batch of metrics
2023-07-10 18:44:10,590 INFO    HandlerThread:20949 [interfaces.py:finish():202] Joined gpu monitor
2023-07-10 18:44:10,590 INFO    HandlerThread:20949 [interfaces.py:finish():202] Joined memory monitor
2023-07-10 18:44:10,590 INFO    HandlerThread:20949 [interfaces.py:finish():202] Joined network monitor
2023-07-10 18:44:10,591 DEBUG   SenderThread:20949 [sender.py:send_request():396] send_request: defer
2023-07-10 18:44:10,591 INFO    SenderThread:20949 [sender.py:send_request_defer():598] handle sender defer: 2
2023-07-10 18:44:10,591 INFO    SenderThread:20949 [sender.py:transition_state():602] send defer: 3
2023-07-10 18:44:10,591 DEBUG   SenderThread:20949 [sender.py:send():369] send: stats
2023-07-10 18:44:10,591 DEBUG   HandlerThread:20949 [handler.py:handle_request():144] handle_request: defer
2023-07-10 18:44:10,591 INFO    HandlerThread:20949 [handler.py:handle_request_defer():170] handle defer: 3
2023-07-10 18:44:10,591 DEBUG   SenderThread:20949 [sender.py:send_request():396] send_request: defer
2023-07-10 18:44:10,591 INFO    SenderThread:20949 [sender.py:send_request_defer():598] handle sender defer: 3
2023-07-10 18:44:10,591 INFO    SenderThread:20949 [sender.py:transition_state():602] send defer: 4
2023-07-10 18:44:10,592 DEBUG   HandlerThread:20949 [handler.py:handle_request():144] handle_request: defer
2023-07-10 18:44:10,592 INFO    HandlerThread:20949 [handler.py:handle_request_defer():170] handle defer: 4
2023-07-10 18:44:10,592 DEBUG   SenderThread:20949 [sender.py:send_request():396] send_request: defer
2023-07-10 18:44:10,592 INFO    SenderThread:20949 [sender.py:send_request_defer():598] handle sender defer: 4
2023-07-10 18:44:10,592 INFO    SenderThread:20949 [sender.py:transition_state():602] send defer: 5
2023-07-10 18:44:10,592 DEBUG   HandlerThread:20949 [handler.py:handle_request():144] handle_request: defer
2023-07-10 18:44:10,592 INFO    HandlerThread:20949 [handler.py:handle_request_defer():170] handle defer: 5
2023-07-10 18:44:10,592 DEBUG   SenderThread:20949 [sender.py:send():369] send: summary
2023-07-10 18:44:10,593 INFO    SenderThread:20949 [sender.py:_save_file():1354] saving file wandb-summary.json with policy end
2023-07-10 18:44:10,593 DEBUG   SenderThread:20949 [sender.py:send_request():396] send_request: defer
2023-07-10 18:44:10,593 INFO    SenderThread:20949 [sender.py:send_request_defer():598] handle sender defer: 5
2023-07-10 18:44:10,593 INFO    SenderThread:20949 [sender.py:transition_state():602] send defer: 6
2023-07-10 18:44:10,593 DEBUG   HandlerThread:20949 [handler.py:handle_request():144] handle_request: defer
2023-07-10 18:44:10,593 INFO    HandlerThread:20949 [handler.py:handle_request_defer():170] handle defer: 6
2023-07-10 18:44:10,593 DEBUG   SenderThread:20949 [sender.py:send_request():396] send_request: defer
2023-07-10 18:44:10,593 INFO    SenderThread:20949 [sender.py:send_request_defer():598] handle sender defer: 6
2023-07-10 18:44:10,597 DEBUG   HandlerThread:20949 [handler.py:handle_request():144] handle_request: status_report
2023-07-10 18:44:10,732 INFO    Thread-12 :20949 [dir_watcher.py:_on_file_modified():289] file/dir modified: /home/zhuhe/HPE-with-Diffusion/wandb/run-20230710_184356-uq8ma9hv/files/wandb-summary.json
2023-07-10 18:44:11,542 DEBUG   HandlerThread:20949 [handler.py:handle_request():144] handle_request: poll_exit
2023-07-10 18:44:11,732 INFO    Thread-12 :20949 [dir_watcher.py:_on_file_modified():289] file/dir modified: /home/zhuhe/HPE-with-Diffusion/wandb/run-20230710_184356-uq8ma9hv/files/output.log
2023-07-10 18:44:11,948 INFO    SenderThread:20949 [sender.py:transition_state():602] send defer: 7
2023-07-10 18:44:11,949 DEBUG   SenderThread:20949 [sender.py:send_request():396] send_request: poll_exit
2023-07-10 18:44:11,949 DEBUG   HandlerThread:20949 [handler.py:handle_request():144] handle_request: defer
2023-07-10 18:44:11,949 INFO    HandlerThread:20949 [handler.py:handle_request_defer():170] handle defer: 7
2023-07-10 18:44:11,949 DEBUG   SenderThread:20949 [sender.py:send_request():396] send_request: defer
2023-07-10 18:44:11,949 INFO    SenderThread:20949 [sender.py:send_request_defer():598] handle sender defer: 7
2023-07-10 18:44:12,542 DEBUG   HandlerThread:20949 [handler.py:handle_request():144] handle_request: poll_exit
2023-07-10 18:44:12,732 INFO    Thread-12 :20949 [dir_watcher.py:_on_file_modified():289] file/dir modified: /home/zhuhe/HPE-with-Diffusion/wandb/run-20230710_184356-uq8ma9hv/files/config.yaml
2023-07-10 18:44:15,285 INFO    SenderThread:20949 [sender.py:transition_state():602] send defer: 8
2023-07-10 18:44:15,285 DEBUG   SenderThread:20949 [sender.py:send_request():396] send_request: poll_exit
2023-07-10 18:44:15,285 DEBUG   HandlerThread:20949 [handler.py:handle_request():144] handle_request: defer
2023-07-10 18:44:15,285 INFO    HandlerThread:20949 [handler.py:handle_request_defer():170] handle defer: 8
2023-07-10 18:44:15,286 DEBUG   SenderThread:20949 [sender.py:send_request():396] send_request: defer
2023-07-10 18:44:15,286 INFO    SenderThread:20949 [sender.py:send_request_defer():598] handle sender defer: 8
2023-07-10 18:44:15,286 INFO    SenderThread:20949 [job_builder.py:build():232] Attempting to build job artifact
2023-07-10 18:44:15,286 INFO    SenderThread:20949 [job_builder.py:build():266] no source found
2023-07-10 18:44:15,286 INFO    SenderThread:20949 [sender.py:transition_state():602] send defer: 9
2023-07-10 18:44:15,286 DEBUG   HandlerThread:20949 [handler.py:handle_request():144] handle_request: defer
2023-07-10 18:44:15,286 INFO    HandlerThread:20949 [handler.py:handle_request_defer():170] handle defer: 9
2023-07-10 18:44:15,286 DEBUG   SenderThread:20949 [sender.py:send_request():396] send_request: defer
2023-07-10 18:44:15,286 INFO    SenderThread:20949 [sender.py:send_request_defer():598] handle sender defer: 9
2023-07-10 18:44:15,286 INFO    SenderThread:20949 [dir_watcher.py:finish():359] shutting down directory watcher
2023-07-10 18:44:15,733 INFO    Thread-12 :20949 [dir_watcher.py:_on_file_modified():289] file/dir modified: /home/zhuhe/HPE-with-Diffusion/wandb/run-20230710_184356-uq8ma9hv/files/output.log
2023-07-10 18:44:15,733 INFO    SenderThread:20949 [dir_watcher.py:finish():389] scan: /home/zhuhe/HPE-with-Diffusion/wandb/run-20230710_184356-uq8ma9hv/files
2023-07-10 18:44:15,733 INFO    SenderThread:20949 [dir_watcher.py:finish():403] scan save: /home/zhuhe/HPE-with-Diffusion/wandb/run-20230710_184356-uq8ma9hv/files/wandb-metadata.json wandb-metadata.json
2023-07-10 18:44:15,733 INFO    SenderThread:20949 [dir_watcher.py:finish():403] scan save: /home/zhuhe/HPE-with-Diffusion/wandb/run-20230710_184356-uq8ma9hv/files/config.yaml config.yaml
2023-07-10 18:44:15,733 INFO    SenderThread:20949 [dir_watcher.py:finish():403] scan save: /home/zhuhe/HPE-with-Diffusion/wandb/run-20230710_184356-uq8ma9hv/files/requirements.txt requirements.txt
2023-07-10 18:44:15,734 INFO    SenderThread:20949 [dir_watcher.py:finish():403] scan save: /home/zhuhe/HPE-with-Diffusion/wandb/run-20230710_184356-uq8ma9hv/files/wandb-summary.json wandb-summary.json
2023-07-10 18:44:15,734 INFO    SenderThread:20949 [dir_watcher.py:finish():403] scan save: /home/zhuhe/HPE-with-Diffusion/wandb/run-20230710_184356-uq8ma9hv/files/conda-environment.yaml conda-environment.yaml
2023-07-10 18:44:15,734 INFO    SenderThread:20949 [dir_watcher.py:finish():403] scan save: /home/zhuhe/HPE-with-Diffusion/wandb/run-20230710_184356-uq8ma9hv/files/output.log output.log
2023-07-10 18:44:15,736 INFO    SenderThread:20949 [sender.py:transition_state():602] send defer: 10
2023-07-10 18:44:15,750 DEBUG   HandlerThread:20949 [handler.py:handle_request():144] handle_request: defer
2023-07-10 18:44:15,750 INFO    HandlerThread:20949 [handler.py:handle_request_defer():170] handle defer: 10
2023-07-10 18:44:15,752 DEBUG   SenderThread:20949 [sender.py:send_request():396] send_request: defer
2023-07-10 18:44:15,752 INFO    SenderThread:20949 [sender.py:send_request_defer():598] handle sender defer: 10
2023-07-10 18:44:15,752 INFO    SenderThread:20949 [file_pusher.py:finish():159] shutting down file pusher
2023-07-10 18:44:16,185 ERROR   wandb-upload_1:20949 [internal_api.py:upload_file():2192] upload_file exception https://storage.googleapis.com/wandb-production.appspot.com/ada4321/DiffHPE/uq8ma9hv/config.yaml?Expires=1689072255&GoogleAccessId=gorilla-files-url-signer-man%40wandb-production.iam.gserviceaccount.com&Signature=wimTKfPPEzOrQ%2FmftwijPp8P3D%2Fpgfm%2FG4WkbmHSd0mJbDVtiRViAGDOo%2BfHVRQtWe%2FapVmkWZvppF%2BqWGaIl%2F1wlmcs1Z913t7jrOe9b5gPObcwn633sK8NzhcTi%2FJux8v%2FeHtpCzxs9uG%2Fgdqtnx6WNUPGbb6cqGplmIVMvi58AFfpHN10O9WyuhavGmAl6xxYQfm6qP9zHYjl3NFMaHE7Dotm53F92yb7Hl%2BesupkyqzFee9ujSAmtzT9OffWGyZU2txj07N%2BD28om7zgm%2B62fCNxPLuMhS1eUjw%2FdmPxpzG5owX74w%2FyMl8pVP2ntqzdI1DhDwlIEzKDVxB8cQ%3D%3D: 404 Client Error: Not Found for url: https://storage.googleapis.com/wandb-production.appspot.com/ada4321/DiffHPE/uq8ma9hv/config.yaml?Expires=1689072255&GoogleAccessId=gorilla-files-url-signer-man%40wandb-production.iam.gserviceaccount.com&Signature=wimTKfPPEzOrQ%2FmftwijPp8P3D%2Fpgfm%2FG4WkbmHSd0mJbDVtiRViAGDOo%2BfHVRQtWe%2FapVmkWZvppF%2BqWGaIl%2F1wlmcs1Z913t7jrOe9b5gPObcwn633sK8NzhcTi%2FJux8v%2FeHtpCzxs9uG%2Fgdqtnx6WNUPGbb6cqGplmIVMvi58AFfpHN10O9WyuhavGmAl6xxYQfm6qP9zHYjl3NFMaHE7Dotm53F92yb7Hl%2BesupkyqzFee9ujSAmtzT9OffWGyZU2txj07N%2BD28om7zgm%2B62fCNxPLuMhS1eUjw%2FdmPxpzG5owX74w%2FyMl8pVP2ntqzdI1DhDwlIEzKDVxB8cQ%3D%3D
2023-07-10 18:44:16,185 ERROR   wandb-upload_1:20949 [internal_api.py:upload_file():2194] upload_file request headers: {'User-Agent': 'python-requests/2.31.0', 'Accept-Encoding': 'gzip, deflate', 'Accept': '*/*', 'Connection': 'keep-alive', 'Content-Length': '525'}
2023-07-10 18:44:16,185 ERROR   wandb-upload_1:20949 [internal_api.py:upload_file():2196] upload_file response body: b'<!DOCTYPE html>\n<html lang=en>\n  <meta charset=utf-8>\n  <meta name=viewport content="initial-scale=1, minimum-scale=1, width=device-width">\n  <title>Error 404 (Not Found)!!1</title>\n  <style>\n    *{margin:0;padding:0}html,code{font:15px/22px arial,sans-serif}html{background:#fff;color:#222;padding:15px}body{margin:7% auto 0;max-width:390px;min-height:180px;padding:30px 0 15px}* > body{background:url(//www.google.com/images/errors/robot.png) 100% 5px no-repeat;padding-right:205px}p{margin:11px 0 22px;overflow:hidden}ins{color:#777;text-decoration:none}a img{border:0}@media screen and (max-width:772px){body{background:none;margin-top:0;max-width:none;padding-right:0}}#logo{background:url(//www.google.com/images/branding/googlelogo/1x/googlelogo_color_150x54dp.png) no-repeat;margin-left:-5px}@media only screen and (min-resolution:192dpi){#logo{background:url(//www.google.com/images/branding/googlelogo/2x/googlelogo_color_150x54dp.png) no-repeat 0% 0%/100% 100%;-moz-border-image:url(//www.google.com/images/branding/googlelogo/2x/googlelogo_color_150x54dp.png) 0}}@media only screen and (-webkit-min-device-pixel-ratio:2){#logo{background:url(//www.google.com/images/branding/googlelogo/2x/googlelogo_color_150x54dp.png) no-repeat;-webkit-background-size:100% 100%}}#logo{display:inline-block;height:54px;width:150px}\n  </style>\n  <a href=//www.google.com/><span id=logo aria-label=Google></span></a>\n  <p><b>404.</b> <ins>That\xe2\x80\x99s an error.</ins>\n  <p>The requested URL <code>/wandb-production.appspot.com/ada4321/DiffHPE/uq8ma9hv/config.yaml</code> was not found on this server.  <ins>That\xe2\x80\x99s all we know.</ins>\n'
2023-07-10 18:44:16,203 ERROR   wandb-upload_0:20949 [internal_api.py:upload_file():2192] upload_file exception https://storage.googleapis.com/wandb-production.appspot.com/ada4321/DiffHPE/uq8ma9hv/requirements.txt?Expires=1689072255&GoogleAccessId=gorilla-files-url-signer-man%40wandb-production.iam.gserviceaccount.com&Signature=rBkrnoyd1C7kmPLWvAYRg96atmkn5jXa%2BtGoGLGPzZ7%2FnMtHm4kXMSk9yFvo5IRYnJawri%2BnSHjojBxO0fhn6oabC3VHTChlEiDmKexefd2vfbyg%2FwngKGZRo4F88PwyVOCXfuXAOoRfrFEZFc79CJGzl%2FRMMfpVY03sFIe9aB3RjOGmA%2FxNaPsJyZbt%2FEFgjCoyl1yfkuBzqiEknO0Cc%2FSe7bd%2FyYWgX3PYU2PxOeq7bLL3OWq9Oo1wwUmW6hqNEsrNo9stdmFpag4MShsWxAsYIewuuw1Lun7Emhvp0nuKxdcMPX1zZSj6dXdM5CcE1QIkP4Gv4Gt9NQx7%2Bu5R%2FQ%3D%3D: 404 Client Error: Not Found for url: https://storage.googleapis.com/wandb-production.appspot.com/ada4321/DiffHPE/uq8ma9hv/requirements.txt?Expires=1689072255&GoogleAccessId=gorilla-files-url-signer-man%40wandb-production.iam.gserviceaccount.com&Signature=rBkrnoyd1C7kmPLWvAYRg96atmkn5jXa%2BtGoGLGPzZ7%2FnMtHm4kXMSk9yFvo5IRYnJawri%2BnSHjojBxO0fhn6oabC3VHTChlEiDmKexefd2vfbyg%2FwngKGZRo4F88PwyVOCXfuXAOoRfrFEZFc79CJGzl%2FRMMfpVY03sFIe9aB3RjOGmA%2FxNaPsJyZbt%2FEFgjCoyl1yfkuBzqiEknO0Cc%2FSe7bd%2FyYWgX3PYU2PxOeq7bLL3OWq9Oo1wwUmW6hqNEsrNo9stdmFpag4MShsWxAsYIewuuw1Lun7Emhvp0nuKxdcMPX1zZSj6dXdM5CcE1QIkP4Gv4Gt9NQx7%2Bu5R%2FQ%3D%3D
2023-07-10 18:44:16,203 ERROR   wandb-upload_0:20949 [internal_api.py:upload_file():2194] upload_file request headers: {'User-Agent': 'python-requests/2.31.0', 'Accept-Encoding': 'gzip, deflate', 'Accept': '*/*', 'Connection': 'keep-alive', 'Content-Length': '926'}
2023-07-10 18:44:16,203 ERROR   wandb-upload_0:20949 [internal_api.py:upload_file():2196] upload_file response body: b'<!DOCTYPE html>\n<html lang=en>\n  <meta charset=utf-8>\n  <meta name=viewport content="initial-scale=1, minimum-scale=1, width=device-width">\n  <title>Error 404 (Not Found)!!1</title>\n  <style>\n    *{margin:0;padding:0}html,code{font:15px/22px arial,sans-serif}html{background:#fff;color:#222;padding:15px}body{margin:7% auto 0;max-width:390px;min-height:180px;padding:30px 0 15px}* > body{background:url(//www.google.com/images/errors/robot.png) 100% 5px no-repeat;padding-right:205px}p{margin:11px 0 22px;overflow:hidden}ins{color:#777;text-decoration:none}a img{border:0}@media screen and (max-width:772px){body{background:none;margin-top:0;max-width:none;padding-right:0}}#logo{background:url(//www.google.com/images/branding/googlelogo/1x/googlelogo_color_150x54dp.png) no-repeat;margin-left:-5px}@media only screen and (min-resolution:192dpi){#logo{background:url(//www.google.com/images/branding/googlelogo/2x/googlelogo_color_150x54dp.png) no-repeat 0% 0%/100% 100%;-moz-border-image:url(//www.google.com/images/branding/googlelogo/2x/googlelogo_color_150x54dp.png) 0}}@media only screen and (-webkit-min-device-pixel-ratio:2){#logo{background:url(//www.google.com/images/branding/googlelogo/2x/googlelogo_color_150x54dp.png) no-repeat;-webkit-background-size:100% 100%}}#logo{display:inline-block;height:54px;width:150px}\n  </style>\n  <a href=//www.google.com/><span id=logo aria-label=Google></span></a>\n  <p><b>404.</b> <ins>That\xe2\x80\x99s an error.</ins>\n  <p>The requested URL <code>/wandb-production.appspot.com/ada4321/DiffHPE/uq8ma9hv/requirements.txt</code> was not found on this server.  <ins>That\xe2\x80\x99s all we know.</ins>\n'
2023-07-10 18:44:16,533 ERROR   wandb-upload_4:20949 [internal_api.py:upload_file():2192] upload_file exception https://storage.googleapis.com/wandb-production.appspot.com/ada4321/DiffHPE/uq8ma9hv/output.log?Expires=1689072256&GoogleAccessId=gorilla-files-url-signer-man%40wandb-production.iam.gserviceaccount.com&Signature=DR2gxug%2FY24enTkNDQRLaffQyzUKma2duwF5zP3BX43P1ejS42aEZd8fyRAWY1EHtPwrfhyrSAZEWI5PmHgh39%2FO%2BQUsPqtzXyADdb6Bmw69IEXjMTxzYujfPJrphjOLL7ixR1esfwMFrZvj0j93ldbiDLScfXIDBKJTC1Med247AiiyrBdJyaevCwVRi7Sr4usqJ7z65gEA8KfDpoBLofERDkZihXeoxmFezwXmuvA4VRkm2m7Kg7V2AhOiPH9POe4SrJ0YAfN%2FII1fuvKPxx%2BzGW09SSCE3we2yDypumFeJvXXugqPW9HY4OWuDU7qtAFurImgMoqMN7c6nuXLwg%3D%3D: 404 Client Error: Not Found for url: https://storage.googleapis.com/wandb-production.appspot.com/ada4321/DiffHPE/uq8ma9hv/output.log?Expires=1689072256&GoogleAccessId=gorilla-files-url-signer-man%40wandb-production.iam.gserviceaccount.com&Signature=DR2gxug%2FY24enTkNDQRLaffQyzUKma2duwF5zP3BX43P1ejS42aEZd8fyRAWY1EHtPwrfhyrSAZEWI5PmHgh39%2FO%2BQUsPqtzXyADdb6Bmw69IEXjMTxzYujfPJrphjOLL7ixR1esfwMFrZvj0j93ldbiDLScfXIDBKJTC1Med247AiiyrBdJyaevCwVRi7Sr4usqJ7z65gEA8KfDpoBLofERDkZihXeoxmFezwXmuvA4VRkm2m7Kg7V2AhOiPH9POe4SrJ0YAfN%2FII1fuvKPxx%2BzGW09SSCE3we2yDypumFeJvXXugqPW9HY4OWuDU7qtAFurImgMoqMN7c6nuXLwg%3D%3D
2023-07-10 18:44:16,533 ERROR   wandb-upload_4:20949 [internal_api.py:upload_file():2194] upload_file request headers: {'User-Agent': 'python-requests/2.31.0', 'Accept-Encoding': 'gzip, deflate', 'Accept': '*/*', 'Connection': 'keep-alive', 'Content-Length': '26341'}
2023-07-10 18:44:16,533 ERROR   wandb-upload_4:20949 [internal_api.py:upload_file():2196] upload_file response body: b'<!DOCTYPE html>\n<html lang=en>\n  <meta charset=utf-8>\n  <meta name=viewport content="initial-scale=1, minimum-scale=1, width=device-width">\n  <title>Error 404 (Not Found)!!1</title>\n  <style>\n    *{margin:0;padding:0}html,code{font:15px/22px arial,sans-serif}html{background:#fff;color:#222;padding:15px}body{margin:7% auto 0;max-width:390px;min-height:180px;padding:30px 0 15px}* > body{background:url(//www.google.com/images/errors/robot.png) 100% 5px no-repeat;padding-right:205px}p{margin:11px 0 22px;overflow:hidden}ins{color:#777;text-decoration:none}a img{border:0}@media screen and (max-width:772px){body{background:none;margin-top:0;max-width:none;padding-right:0}}#logo{background:url(//www.google.com/images/branding/googlelogo/1x/googlelogo_color_150x54dp.png) no-repeat;margin-left:-5px}@media only screen and (min-resolution:192dpi){#logo{background:url(//www.google.com/images/branding/googlelogo/2x/googlelogo_color_150x54dp.png) no-repeat 0% 0%/100% 100%;-moz-border-image:url(//www.google.com/images/branding/googlelogo/2x/googlelogo_color_150x54dp.png) 0}}@media only screen and (-webkit-min-device-pixel-ratio:2){#logo{background:url(//www.google.com/images/branding/googlelogo/2x/googlelogo_color_150x54dp.png) no-repeat;-webkit-background-size:100% 100%}}#logo{display:inline-block;height:54px;width:150px}\n  </style>\n  <a href=//www.google.com/><span id=logo aria-label=Google></span></a>\n  <p><b>404.</b> <ins>That\xe2\x80\x99s an error.</ins>\n  <p>The requested URL <code>/wandb-production.appspot.com/ada4321/DiffHPE/uq8ma9hv/output.log</code> was not found on this server.  <ins>That\xe2\x80\x99s all we know.</ins>\n'
2023-07-10 18:44:16,570 ERROR   wandb-upload_3:20949 [internal_api.py:upload_file():2192] upload_file exception https://storage.googleapis.com/wandb-production.appspot.com/ada4321/DiffHPE/uq8ma9hv/conda-environment.yaml?Expires=1689072256&GoogleAccessId=gorilla-files-url-signer-man%40wandb-production.iam.gserviceaccount.com&Signature=SkN9GityVHopFSUQsCUMuBltu0BqhFlENVKrED6U380XcAZdU1pMTLwJk09MaIYw2P2OgN4xvv8z9%2FEGmswLvrAZdpUxG2mLHHY4fC1ryOgQ8kdLUth8R8JzTtwnq1tWpyuFlq1JjevY0Cw3Rsqmqmh7BXQPOmAJt1SQOEIHZAG24wVy9hMBwAAzXzEjUFGCLnMW%2BcYKriWcUPdACbYceNv2LMLAzu1KT%2FM9ne9tKryLkvMf9Fs6hMmdM4eNWMA2rSvrxicJvl3QJEyxNcnRlJkxgJ8Lq0Uyg%2Fav3XmeBgignT4ioTI%2BrhGoRGc8x%2BSbh7219CHO1A5%2FIieua9tdbg%3D%3D: 404 Client Error: Not Found for url: https://storage.googleapis.com/wandb-production.appspot.com/ada4321/DiffHPE/uq8ma9hv/conda-environment.yaml?Expires=1689072256&GoogleAccessId=gorilla-files-url-signer-man%40wandb-production.iam.gserviceaccount.com&Signature=SkN9GityVHopFSUQsCUMuBltu0BqhFlENVKrED6U380XcAZdU1pMTLwJk09MaIYw2P2OgN4xvv8z9%2FEGmswLvrAZdpUxG2mLHHY4fC1ryOgQ8kdLUth8R8JzTtwnq1tWpyuFlq1JjevY0Cw3Rsqmqmh7BXQPOmAJt1SQOEIHZAG24wVy9hMBwAAzXzEjUFGCLnMW%2BcYKriWcUPdACbYceNv2LMLAzu1KT%2FM9ne9tKryLkvMf9Fs6hMmdM4eNWMA2rSvrxicJvl3QJEyxNcnRlJkxgJ8Lq0Uyg%2Fav3XmeBgignT4ioTI%2BrhGoRGc8x%2BSbh7219CHO1A5%2FIieua9tdbg%3D%3D
2023-07-10 18:44:16,570 ERROR   wandb-upload_3:20949 [internal_api.py:upload_file():2194] upload_file request headers: {'User-Agent': 'python-requests/2.31.0', 'Accept-Encoding': 'gzip, deflate', 'Accept': '*/*', 'Connection': 'keep-alive', 'Content-Length': '1925'}
2023-07-10 18:44:16,570 ERROR   wandb-upload_3:20949 [internal_api.py:upload_file():2196] upload_file response body: b'<!DOCTYPE html>\n<html lang=en>\n  <meta charset=utf-8>\n  <meta name=viewport content="initial-scale=1, minimum-scale=1, width=device-width">\n  <title>Error 404 (Not Found)!!1</title>\n  <style>\n    *{margin:0;padding:0}html,code{font:15px/22px arial,sans-serif}html{background:#fff;color:#222;padding:15px}body{margin:7% auto 0;max-width:390px;min-height:180px;padding:30px 0 15px}* > body{background:url(//www.google.com/images/errors/robot.png) 100% 5px no-repeat;padding-right:205px}p{margin:11px 0 22px;overflow:hidden}ins{color:#777;text-decoration:none}a img{border:0}@media screen and (max-width:772px){body{background:none;margin-top:0;max-width:none;padding-right:0}}#logo{background:url(//www.google.com/images/branding/googlelogo/1x/googlelogo_color_150x54dp.png) no-repeat;margin-left:-5px}@media only screen and (min-resolution:192dpi){#logo{background:url(//www.google.com/images/branding/googlelogo/2x/googlelogo_color_150x54dp.png) no-repeat 0% 0%/100% 100%;-moz-border-image:url(//www.google.com/images/branding/googlelogo/2x/googlelogo_color_150x54dp.png) 0}}@media only screen and (-webkit-min-device-pixel-ratio:2){#logo{background:url(//www.google.com/images/branding/googlelogo/2x/googlelogo_color_150x54dp.png) no-repeat;-webkit-background-size:100% 100%}}#logo{display:inline-block;height:54px;width:150px}\n  </style>\n  <a href=//www.google.com/><span id=logo aria-label=Google></span></a>\n  <p><b>404.</b> <ins>That\xe2\x80\x99s an error.</ins>\n  <p>The requested URL <code>/wandb-production.appspot.com/ada4321/DiffHPE/uq8ma9hv/conda-environment.yaml</code> was not found on this server.  <ins>That\xe2\x80\x99s all we know.</ins>\n'
2023-07-10 18:44:16,579 ERROR   wandb-upload_2:20949 [internal_api.py:upload_file():2192] upload_file exception https://storage.googleapis.com/wandb-production.appspot.com/ada4321/DiffHPE/uq8ma9hv/wandb-summary.json?Expires=1689072256&GoogleAccessId=gorilla-files-url-signer-man%40wandb-production.iam.gserviceaccount.com&Signature=UB1f2XgcfImp4Bb5J43CNxQ%2BawvjcZ78oHHBrClGQPD63aM6hmChNhAy1oHnvbeM2IZkiUdvay1IzETWdTMY7JrbgkXr3%2FzAP1%2Bjr0z%2BrVNiyP6ICZvrnWIzFUZIm7N5cufA10WOJ0gW5bVndpsXowQ3ovO8A9QZCy36r8UTJvV5AKw6X6PLbOKDEGtw6RLGckEBOx45PMA4XYQABTJWJeQSxzgiNoc5whxQQIIahgPjq9byZNNTOs5AFInNOsXSPNgtqYz0DcDdVqwlg2IOwnJoyWi%2B98Y6I%2FVMb9%2FNAxGUz6PLdYaDCnt%2FiGQzR3OWuf5kY1zssOXBVhV%2BO8Opzg%3D%3D: 404 Client Error: Not Found for url: https://storage.googleapis.com/wandb-production.appspot.com/ada4321/DiffHPE/uq8ma9hv/wandb-summary.json?Expires=1689072256&GoogleAccessId=gorilla-files-url-signer-man%40wandb-production.iam.gserviceaccount.com&Signature=UB1f2XgcfImp4Bb5J43CNxQ%2BawvjcZ78oHHBrClGQPD63aM6hmChNhAy1oHnvbeM2IZkiUdvay1IzETWdTMY7JrbgkXr3%2FzAP1%2Bjr0z%2BrVNiyP6ICZvrnWIzFUZIm7N5cufA10WOJ0gW5bVndpsXowQ3ovO8A9QZCy36r8UTJvV5AKw6X6PLbOKDEGtw6RLGckEBOx45PMA4XYQABTJWJeQSxzgiNoc5whxQQIIahgPjq9byZNNTOs5AFInNOsXSPNgtqYz0DcDdVqwlg2IOwnJoyWi%2B98Y6I%2FVMb9%2FNAxGUz6PLdYaDCnt%2FiGQzR3OWuf5kY1zssOXBVhV%2BO8Opzg%3D%3D
2023-07-10 18:44:16,580 ERROR   wandb-upload_2:20949 [internal_api.py:upload_file():2194] upload_file request headers: {'User-Agent': 'python-requests/2.31.0', 'Accept-Encoding': 'gzip, deflate', 'Accept': '*/*', 'Connection': 'keep-alive', 'Content-Length': '27'}
2023-07-10 18:44:16,580 ERROR   wandb-upload_2:20949 [internal_api.py:upload_file():2196] upload_file response body: b'<!DOCTYPE html>\n<html lang=en>\n  <meta charset=utf-8>\n  <meta name=viewport content="initial-scale=1, minimum-scale=1, width=device-width">\n  <title>Error 404 (Not Found)!!1</title>\n  <style>\n    *{margin:0;padding:0}html,code{font:15px/22px arial,sans-serif}html{background:#fff;color:#222;padding:15px}body{margin:7% auto 0;max-width:390px;min-height:180px;padding:30px 0 15px}* > body{background:url(//www.google.com/images/errors/robot.png) 100% 5px no-repeat;padding-right:205px}p{margin:11px 0 22px;overflow:hidden}ins{color:#777;text-decoration:none}a img{border:0}@media screen and (max-width:772px){body{background:none;margin-top:0;max-width:none;padding-right:0}}#logo{background:url(//www.google.com/images/branding/googlelogo/1x/googlelogo_color_150x54dp.png) no-repeat;margin-left:-5px}@media only screen and (min-resolution:192dpi){#logo{background:url(//www.google.com/images/branding/googlelogo/2x/googlelogo_color_150x54dp.png) no-repeat 0% 0%/100% 100%;-moz-border-image:url(//www.google.com/images/branding/googlelogo/2x/googlelogo_color_150x54dp.png) 0}}@media only screen and (-webkit-min-device-pixel-ratio:2){#logo{background:url(//www.google.com/images/branding/googlelogo/2x/googlelogo_color_150x54dp.png) no-repeat;-webkit-background-size:100% 100%}}#logo{display:inline-block;height:54px;width:150px}\n  </style>\n  <a href=//www.google.com/><span id=logo aria-label=Google></span></a>\n  <p><b>404.</b> <ins>That\xe2\x80\x99s an error.</ins>\n  <p>The requested URL <code>/wandb-production.appspot.com/ada4321/DiffHPE/uq8ma9hv/wandb-summary.json</code> was not found on this server.  <ins>That\xe2\x80\x99s all we know.</ins>\n'
2023-07-10 18:44:17,315 ERROR   wandb-upload_1:20949 [upload_job.py:push():136] Failed to upload file: /home/zhuhe/HPE-with-Diffusion/wandb/run-20230710_184356-uq8ma9hv/files/config.yaml
Traceback (most recent call last):
  File "/home/zhuhe/.conda/envs/diffhpe/lib/python3.9/site-packages/wandb/apis/normalize.py", line 41, in wrapper
    return func(*args, **kwargs)
  File "/home/zhuhe/.conda/envs/diffhpe/lib/python3.9/site-packages/wandb/sdk/lib/retry.py", line 212, in wrapped_fn
    return retrier(*args, **kargs)
  File "/home/zhuhe/.conda/envs/diffhpe/lib/python3.9/site-packages/wandb/sdk/lib/retry.py", line 131, in __call__
    result = self._call_fn(*args, **kwargs)
  File "/home/zhuhe/.conda/envs/diffhpe/lib/python3.9/site-packages/wandb/sdk/internal/internal_api.py", line 2218, in upload_file
    wandb._sentry.reraise(e)
  File "/home/zhuhe/.conda/envs/diffhpe/lib/python3.9/site-packages/wandb/analytics/sentry.py", line 146, in reraise
    raise exc.with_traceback(sys.exc_info()[2])
  File "/home/zhuhe/.conda/envs/diffhpe/lib/python3.9/site-packages/wandb/sdk/internal/internal_api.py", line 2190, in upload_file
    response.raise_for_status()
  File "/home/zhuhe/.conda/envs/diffhpe/lib/python3.9/site-packages/requests/models.py", line 1021, in raise_for_status
    raise HTTPError(http_error_msg, response=self)
requests.exceptions.HTTPError: 404 Client Error: Not Found for url: https://storage.googleapis.com/wandb-production.appspot.com/ada4321/DiffHPE/uq8ma9hv/config.yaml?Expires=1689072255&GoogleAccessId=gorilla-files-url-signer-man%40wandb-production.iam.gserviceaccount.com&Signature=wimTKfPPEzOrQ%2FmftwijPp8P3D%2Fpgfm%2FG4WkbmHSd0mJbDVtiRViAGDOo%2BfHVRQtWe%2FapVmkWZvppF%2BqWGaIl%2F1wlmcs1Z913t7jrOe9b5gPObcwn633sK8NzhcTi%2FJux8v%2FeHtpCzxs9uG%2Fgdqtnx6WNUPGbb6cqGplmIVMvi58AFfpHN10O9WyuhavGmAl6xxYQfm6qP9zHYjl3NFMaHE7Dotm53F92yb7Hl%2BesupkyqzFee9ujSAmtzT9OffWGyZU2txj07N%2BD28om7zgm%2B62fCNxPLuMhS1eUjw%2FdmPxpzG5owX74w%2FyMl8pVP2ntqzdI1DhDwlIEzKDVxB8cQ%3D%3D

During handling of the above exception, another exception occurred:

Traceback (most recent call last):
  File "/home/zhuhe/.conda/envs/diffhpe/lib/python3.9/site-packages/wandb/filesync/upload_job.py", line 127, in push
    self._api.upload_file_retry(
  File "/home/zhuhe/.conda/envs/diffhpe/lib/python3.9/site-packages/wandb/apis/normalize.py", line 51, in wrapper
    raise CommError(message, error)
wandb.errors.CommError: <Response [404]>
2023-07-10 18:44:17,316 ERROR   wandb-upload_0:20949 [upload_job.py:push():136] Failed to upload file: /home/zhuhe/HPE-with-Diffusion/wandb/run-20230710_184356-uq8ma9hv/files/requirements.txt
Traceback (most recent call last):
  File "/home/zhuhe/.conda/envs/diffhpe/lib/python3.9/site-packages/wandb/apis/normalize.py", line 41, in wrapper
    return func(*args, **kwargs)
  File "/home/zhuhe/.conda/envs/diffhpe/lib/python3.9/site-packages/wandb/sdk/lib/retry.py", line 212, in wrapped_fn
    return retrier(*args, **kargs)
  File "/home/zhuhe/.conda/envs/diffhpe/lib/python3.9/site-packages/wandb/sdk/lib/retry.py", line 131, in __call__
    result = self._call_fn(*args, **kwargs)
  File "/home/zhuhe/.conda/envs/diffhpe/lib/python3.9/site-packages/wandb/sdk/internal/internal_api.py", line 2218, in upload_file
    wandb._sentry.reraise(e)
  File "/home/zhuhe/.conda/envs/diffhpe/lib/python3.9/site-packages/wandb/analytics/sentry.py", line 146, in reraise
    raise exc.with_traceback(sys.exc_info()[2])
  File "/home/zhuhe/.conda/envs/diffhpe/lib/python3.9/site-packages/wandb/sdk/internal/internal_api.py", line 2190, in upload_file
    response.raise_for_status()
  File "/home/zhuhe/.conda/envs/diffhpe/lib/python3.9/site-packages/requests/models.py", line 1021, in raise_for_status
    raise HTTPError(http_error_msg, response=self)
requests.exceptions.HTTPError: 404 Client Error: Not Found for url: https://storage.googleapis.com/wandb-production.appspot.com/ada4321/DiffHPE/uq8ma9hv/requirements.txt?Expires=1689072255&GoogleAccessId=gorilla-files-url-signer-man%40wandb-production.iam.gserviceaccount.com&Signature=rBkrnoyd1C7kmPLWvAYRg96atmkn5jXa%2BtGoGLGPzZ7%2FnMtHm4kXMSk9yFvo5IRYnJawri%2BnSHjojBxO0fhn6oabC3VHTChlEiDmKexefd2vfbyg%2FwngKGZRo4F88PwyVOCXfuXAOoRfrFEZFc79CJGzl%2FRMMfpVY03sFIe9aB3RjOGmA%2FxNaPsJyZbt%2FEFgjCoyl1yfkuBzqiEknO0Cc%2FSe7bd%2FyYWgX3PYU2PxOeq7bLL3OWq9Oo1wwUmW6hqNEsrNo9stdmFpag4MShsWxAsYIewuuw1Lun7Emhvp0nuKxdcMPX1zZSj6dXdM5CcE1QIkP4Gv4Gt9NQx7%2Bu5R%2FQ%3D%3D

During handling of the above exception, another exception occurred:

Traceback (most recent call last):
  File "/home/zhuhe/.conda/envs/diffhpe/lib/python3.9/site-packages/wandb/filesync/upload_job.py", line 127, in push
    self._api.upload_file_retry(
  File "/home/zhuhe/.conda/envs/diffhpe/lib/python3.9/site-packages/wandb/apis/normalize.py", line 51, in wrapper
    raise CommError(message, error)
wandb.errors.CommError: <Response [404]>
2023-07-10 18:44:17,316 ERROR   wandb-upload_3:20949 [upload_job.py:push():136] Failed to upload file: /home/zhuhe/HPE-with-Diffusion/wandb/run-20230710_184356-uq8ma9hv/files/conda-environment.yaml
Traceback (most recent call last):
  File "/home/zhuhe/.conda/envs/diffhpe/lib/python3.9/site-packages/wandb/apis/normalize.py", line 41, in wrapper
    return func(*args, **kwargs)
  File "/home/zhuhe/.conda/envs/diffhpe/lib/python3.9/site-packages/wandb/sdk/lib/retry.py", line 212, in wrapped_fn
    return retrier(*args, **kargs)
  File "/home/zhuhe/.conda/envs/diffhpe/lib/python3.9/site-packages/wandb/sdk/lib/retry.py", line 131, in __call__
    result = self._call_fn(*args, **kwargs)
  File "/home/zhuhe/.conda/envs/diffhpe/lib/python3.9/site-packages/wandb/sdk/internal/internal_api.py", line 2218, in upload_file
    wandb._sentry.reraise(e)
  File "/home/zhuhe/.conda/envs/diffhpe/lib/python3.9/site-packages/wandb/analytics/sentry.py", line 146, in reraise
    raise exc.with_traceback(sys.exc_info()[2])
  File "/home/zhuhe/.conda/envs/diffhpe/lib/python3.9/site-packages/wandb/sdk/internal/internal_api.py", line 2190, in upload_file
    response.raise_for_status()
  File "/home/zhuhe/.conda/envs/diffhpe/lib/python3.9/site-packages/requests/models.py", line 1021, in raise_for_status
    raise HTTPError(http_error_msg, response=self)
requests.exceptions.HTTPError: 404 Client Error: Not Found for url: https://storage.googleapis.com/wandb-production.appspot.com/ada4321/DiffHPE/uq8ma9hv/conda-environment.yaml?Expires=1689072256&GoogleAccessId=gorilla-files-url-signer-man%40wandb-production.iam.gserviceaccount.com&Signature=SkN9GityVHopFSUQsCUMuBltu0BqhFlENVKrED6U380XcAZdU1pMTLwJk09MaIYw2P2OgN4xvv8z9%2FEGmswLvrAZdpUxG2mLHHY4fC1ryOgQ8kdLUth8R8JzTtwnq1tWpyuFlq1JjevY0Cw3Rsqmqmh7BXQPOmAJt1SQOEIHZAG24wVy9hMBwAAzXzEjUFGCLnMW%2BcYKriWcUPdACbYceNv2LMLAzu1KT%2FM9ne9tKryLkvMf9Fs6hMmdM4eNWMA2rSvrxicJvl3QJEyxNcnRlJkxgJ8Lq0Uyg%2Fav3XmeBgignT4ioTI%2BrhGoRGc8x%2BSbh7219CHO1A5%2FIieua9tdbg%3D%3D

During handling of the above exception, another exception occurred:

Traceback (most recent call last):
  File "/home/zhuhe/.conda/envs/diffhpe/lib/python3.9/site-packages/wandb/filesync/upload_job.py", line 127, in push
    self._api.upload_file_retry(
  File "/home/zhuhe/.conda/envs/diffhpe/lib/python3.9/site-packages/wandb/apis/normalize.py", line 51, in wrapper
    raise CommError(message, error)
wandb.errors.CommError: <Response [404]>
2023-07-10 18:44:17,317 ERROR   wandb-upload_4:20949 [upload_job.py:push():136] Failed to upload file: /home/zhuhe/HPE-with-Diffusion/wandb/run-20230710_184356-uq8ma9hv/files/output.log
Traceback (most recent call last):
  File "/home/zhuhe/.conda/envs/diffhpe/lib/python3.9/site-packages/wandb/apis/normalize.py", line 41, in wrapper
    return func(*args, **kwargs)
  File "/home/zhuhe/.conda/envs/diffhpe/lib/python3.9/site-packages/wandb/sdk/lib/retry.py", line 212, in wrapped_fn
    return retrier(*args, **kargs)
  File "/home/zhuhe/.conda/envs/diffhpe/lib/python3.9/site-packages/wandb/sdk/lib/retry.py", line 131, in __call__
    result = self._call_fn(*args, **kwargs)
  File "/home/zhuhe/.conda/envs/diffhpe/lib/python3.9/site-packages/wandb/sdk/internal/internal_api.py", line 2218, in upload_file
    wandb._sentry.reraise(e)
  File "/home/zhuhe/.conda/envs/diffhpe/lib/python3.9/site-packages/wandb/analytics/sentry.py", line 146, in reraise
    raise exc.with_traceback(sys.exc_info()[2])
  File "/home/zhuhe/.conda/envs/diffhpe/lib/python3.9/site-packages/wandb/sdk/internal/internal_api.py", line 2190, in upload_file
    response.raise_for_status()
  File "/home/zhuhe/.conda/envs/diffhpe/lib/python3.9/site-packages/requests/models.py", line 1021, in raise_for_status
    raise HTTPError(http_error_msg, response=self)
requests.exceptions.HTTPError: 404 Client Error: Not Found for url: https://storage.googleapis.com/wandb-production.appspot.com/ada4321/DiffHPE/uq8ma9hv/output.log?Expires=1689072256&GoogleAccessId=gorilla-files-url-signer-man%40wandb-production.iam.gserviceaccount.com&Signature=DR2gxug%2FY24enTkNDQRLaffQyzUKma2duwF5zP3BX43P1ejS42aEZd8fyRAWY1EHtPwrfhyrSAZEWI5PmHgh39%2FO%2BQUsPqtzXyADdb6Bmw69IEXjMTxzYujfPJrphjOLL7ixR1esfwMFrZvj0j93ldbiDLScfXIDBKJTC1Med247AiiyrBdJyaevCwVRi7Sr4usqJ7z65gEA8KfDpoBLofERDkZihXeoxmFezwXmuvA4VRkm2m7Kg7V2AhOiPH9POe4SrJ0YAfN%2FII1fuvKPxx%2BzGW09SSCE3we2yDypumFeJvXXugqPW9HY4OWuDU7qtAFurImgMoqMN7c6nuXLwg%3D%3D

During handling of the above exception, another exception occurred:

Traceback (most recent call last):
  File "/home/zhuhe/.conda/envs/diffhpe/lib/python3.9/site-packages/wandb/filesync/upload_job.py", line 127, in push
    self._api.upload_file_retry(
  File "/home/zhuhe/.conda/envs/diffhpe/lib/python3.9/site-packages/wandb/apis/normalize.py", line 51, in wrapper
    raise CommError(message, error)
wandb.errors.CommError: <Response [404]>
2023-07-10 18:44:17,317 ERROR   wandb-upload_2:20949 [upload_job.py:push():136] Failed to upload file: /home/zhuhe/HPE-with-Diffusion/wandb/run-20230710_184356-uq8ma9hv/files/wandb-summary.json
Traceback (most recent call last):
  File "/home/zhuhe/.conda/envs/diffhpe/lib/python3.9/site-packages/wandb/apis/normalize.py", line 41, in wrapper
    return func(*args, **kwargs)
  File "/home/zhuhe/.conda/envs/diffhpe/lib/python3.9/site-packages/wandb/sdk/lib/retry.py", line 212, in wrapped_fn
    return retrier(*args, **kargs)
  File "/home/zhuhe/.conda/envs/diffhpe/lib/python3.9/site-packages/wandb/sdk/lib/retry.py", line 131, in __call__
    result = self._call_fn(*args, **kwargs)
  File "/home/zhuhe/.conda/envs/diffhpe/lib/python3.9/site-packages/wandb/sdk/internal/internal_api.py", line 2218, in upload_file
    wandb._sentry.reraise(e)
  File "/home/zhuhe/.conda/envs/diffhpe/lib/python3.9/site-packages/wandb/analytics/sentry.py", line 146, in reraise
    raise exc.with_traceback(sys.exc_info()[2])
  File "/home/zhuhe/.conda/envs/diffhpe/lib/python3.9/site-packages/wandb/sdk/internal/internal_api.py", line 2190, in upload_file
    response.raise_for_status()
  File "/home/zhuhe/.conda/envs/diffhpe/lib/python3.9/site-packages/requests/models.py", line 1021, in raise_for_status
    raise HTTPError(http_error_msg, response=self)
requests.exceptions.HTTPError: 404 Client Error: Not Found for url: https://storage.googleapis.com/wandb-production.appspot.com/ada4321/DiffHPE/uq8ma9hv/wandb-summary.json?Expires=1689072256&GoogleAccessId=gorilla-files-url-signer-man%40wandb-production.iam.gserviceaccount.com&Signature=UB1f2XgcfImp4Bb5J43CNxQ%2BawvjcZ78oHHBrClGQPD63aM6hmChNhAy1oHnvbeM2IZkiUdvay1IzETWdTMY7JrbgkXr3%2FzAP1%2Bjr0z%2BrVNiyP6ICZvrnWIzFUZIm7N5cufA10WOJ0gW5bVndpsXowQ3ovO8A9QZCy36r8UTJvV5AKw6X6PLbOKDEGtw6RLGckEBOx45PMA4XYQABTJWJeQSxzgiNoc5whxQQIIahgPjq9byZNNTOs5AFInNOsXSPNgtqYz0DcDdVqwlg2IOwnJoyWi%2B98Y6I%2FVMb9%2FNAxGUz6PLdYaDCnt%2FiGQzR3OWuf5kY1zssOXBVhV%2BO8Opzg%3D%3D

During handling of the above exception, another exception occurred:

Traceback (most recent call last):
  File "/home/zhuhe/.conda/envs/diffhpe/lib/python3.9/site-packages/wandb/filesync/upload_job.py", line 127, in push
    self._api.upload_file_retry(
  File "/home/zhuhe/.conda/envs/diffhpe/lib/python3.9/site-packages/wandb/apis/normalize.py", line 51, in wrapper
    raise CommError(message, error)
wandb.errors.CommError: <Response [404]>
2023-07-10 18:44:17,543 DEBUG   HandlerThread:20949 [handler.py:handle_request():144] handle_request: keepalive
2023-07-10 18:44:18,449 ERROR   Thread-11 :20949 [step_upload.py:_handle_event():200] Failed to upload file: /home/zhuhe/HPE-with-Diffusion/wandb/run-20230710_184356-uq8ma9hv/files/requirements.txt
Traceback (most recent call last):
  File "/home/zhuhe/.conda/envs/diffhpe/lib/python3.9/site-packages/wandb/apis/normalize.py", line 41, in wrapper
    return func(*args, **kwargs)
  File "/home/zhuhe/.conda/envs/diffhpe/lib/python3.9/site-packages/wandb/sdk/lib/retry.py", line 212, in wrapped_fn
    return retrier(*args, **kargs)
  File "/home/zhuhe/.conda/envs/diffhpe/lib/python3.9/site-packages/wandb/sdk/lib/retry.py", line 131, in __call__
    result = self._call_fn(*args, **kwargs)
  File "/home/zhuhe/.conda/envs/diffhpe/lib/python3.9/site-packages/wandb/sdk/internal/internal_api.py", line 2218, in upload_file
    wandb._sentry.reraise(e)
  File "/home/zhuhe/.conda/envs/diffhpe/lib/python3.9/site-packages/wandb/analytics/sentry.py", line 146, in reraise
    raise exc.with_traceback(sys.exc_info()[2])
  File "/home/zhuhe/.conda/envs/diffhpe/lib/python3.9/site-packages/wandb/sdk/internal/internal_api.py", line 2190, in upload_file
    response.raise_for_status()
  File "/home/zhuhe/.conda/envs/diffhpe/lib/python3.9/site-packages/requests/models.py", line 1021, in raise_for_status
    raise HTTPError(http_error_msg, response=self)
requests.exceptions.HTTPError: 404 Client Error: Not Found for url: https://storage.googleapis.com/wandb-production.appspot.com/ada4321/DiffHPE/uq8ma9hv/requirements.txt?Expires=1689072255&GoogleAccessId=gorilla-files-url-signer-man%40wandb-production.iam.gserviceaccount.com&Signature=rBkrnoyd1C7kmPLWvAYRg96atmkn5jXa%2BtGoGLGPzZ7%2FnMtHm4kXMSk9yFvo5IRYnJawri%2BnSHjojBxO0fhn6oabC3VHTChlEiDmKexefd2vfbyg%2FwngKGZRo4F88PwyVOCXfuXAOoRfrFEZFc79CJGzl%2FRMMfpVY03sFIe9aB3RjOGmA%2FxNaPsJyZbt%2FEFgjCoyl1yfkuBzqiEknO0Cc%2FSe7bd%2FyYWgX3PYU2PxOeq7bLL3OWq9Oo1wwUmW6hqNEsrNo9stdmFpag4MShsWxAsYIewuuw1Lun7Emhvp0nuKxdcMPX1zZSj6dXdM5CcE1QIkP4Gv4Gt9NQx7%2Bu5R%2FQ%3D%3D

During handling of the above exception, another exception occurred:

Traceback (most recent call last):
  File "/home/zhuhe/.conda/envs/diffhpe/lib/python3.9/concurrent/futures/thread.py", line 58, in run
    result = self.fn(*self.args, **self.kwargs)
  File "/home/zhuhe/.conda/envs/diffhpe/lib/python3.9/site-packages/wandb/filesync/step_upload.py", line 288, in run_and_notify
    self._do_upload_sync(event)
  File "/home/zhuhe/.conda/envs/diffhpe/lib/python3.9/site-packages/wandb/filesync/step_upload.py", line 330, in _do_upload_sync
    job.run()
  File "/home/zhuhe/.conda/envs/diffhpe/lib/python3.9/site-packages/wandb/filesync/upload_job.py", line 57, in run
    self.push()
  File "/home/zhuhe/.conda/envs/diffhpe/lib/python3.9/site-packages/wandb/filesync/upload_job.py", line 127, in push
    self._api.upload_file_retry(
  File "/home/zhuhe/.conda/envs/diffhpe/lib/python3.9/site-packages/wandb/apis/normalize.py", line 51, in wrapper
    raise CommError(message, error)
wandb.errors.CommError: <Response [404]>
2023-07-10 18:44:18,449 ERROR   Thread-11 :20949 [step_upload.py:_handle_event():200] Failed to upload file: /home/zhuhe/HPE-with-Diffusion/wandb/run-20230710_184356-uq8ma9hv/files/conda-environment.yaml
Traceback (most recent call last):
  File "/home/zhuhe/.conda/envs/diffhpe/lib/python3.9/site-packages/wandb/apis/normalize.py", line 41, in wrapper
    return func(*args, **kwargs)
  File "/home/zhuhe/.conda/envs/diffhpe/lib/python3.9/site-packages/wandb/sdk/lib/retry.py", line 212, in wrapped_fn
    return retrier(*args, **kargs)
  File "/home/zhuhe/.conda/envs/diffhpe/lib/python3.9/site-packages/wandb/sdk/lib/retry.py", line 131, in __call__
    result = self._call_fn(*args, **kwargs)
  File "/home/zhuhe/.conda/envs/diffhpe/lib/python3.9/site-packages/wandb/sdk/internal/internal_api.py", line 2218, in upload_file
    wandb._sentry.reraise(e)
  File "/home/zhuhe/.conda/envs/diffhpe/lib/python3.9/site-packages/wandb/analytics/sentry.py", line 146, in reraise
    raise exc.with_traceback(sys.exc_info()[2])
  File "/home/zhuhe/.conda/envs/diffhpe/lib/python3.9/site-packages/wandb/sdk/internal/internal_api.py", line 2190, in upload_file
    response.raise_for_status()
  File "/home/zhuhe/.conda/envs/diffhpe/lib/python3.9/site-packages/requests/models.py", line 1021, in raise_for_status
    raise HTTPError(http_error_msg, response=self)
requests.exceptions.HTTPError: 404 Client Error: Not Found for url: https://storage.googleapis.com/wandb-production.appspot.com/ada4321/DiffHPE/uq8ma9hv/conda-environment.yaml?Expires=1689072256&GoogleAccessId=gorilla-files-url-signer-man%40wandb-production.iam.gserviceaccount.com&Signature=SkN9GityVHopFSUQsCUMuBltu0BqhFlENVKrED6U380XcAZdU1pMTLwJk09MaIYw2P2OgN4xvv8z9%2FEGmswLvrAZdpUxG2mLHHY4fC1ryOgQ8kdLUth8R8JzTtwnq1tWpyuFlq1JjevY0Cw3Rsqmqmh7BXQPOmAJt1SQOEIHZAG24wVy9hMBwAAzXzEjUFGCLnMW%2BcYKriWcUPdACbYceNv2LMLAzu1KT%2FM9ne9tKryLkvMf9Fs6hMmdM4eNWMA2rSvrxicJvl3QJEyxNcnRlJkxgJ8Lq0Uyg%2Fav3XmeBgignT4ioTI%2BrhGoRGc8x%2BSbh7219CHO1A5%2FIieua9tdbg%3D%3D

During handling of the above exception, another exception occurred:

Traceback (most recent call last):
  File "/home/zhuhe/.conda/envs/diffhpe/lib/python3.9/concurrent/futures/thread.py", line 58, in run
    result = self.fn(*self.args, **self.kwargs)
  File "/home/zhuhe/.conda/envs/diffhpe/lib/python3.9/site-packages/wandb/filesync/step_upload.py", line 288, in run_and_notify
    self._do_upload_sync(event)
  File "/home/zhuhe/.conda/envs/diffhpe/lib/python3.9/site-packages/wandb/filesync/step_upload.py", line 330, in _do_upload_sync
    job.run()
  File "/home/zhuhe/.conda/envs/diffhpe/lib/python3.9/site-packages/wandb/filesync/upload_job.py", line 57, in run
    self.push()
  File "/home/zhuhe/.conda/envs/diffhpe/lib/python3.9/site-packages/wandb/filesync/upload_job.py", line 127, in push
    self._api.upload_file_retry(
  File "/home/zhuhe/.conda/envs/diffhpe/lib/python3.9/site-packages/wandb/apis/normalize.py", line 51, in wrapper
    raise CommError(message, error)
wandb.errors.CommError: <Response [404]>
2023-07-10 18:44:18,449 ERROR   Thread-11 :20949 [step_upload.py:_handle_event():200] Failed to upload file: /home/zhuhe/HPE-with-Diffusion/wandb/run-20230710_184356-uq8ma9hv/files/output.log
Traceback (most recent call last):
  File "/home/zhuhe/.conda/envs/diffhpe/lib/python3.9/site-packages/wandb/apis/normalize.py", line 41, in wrapper
    return func(*args, **kwargs)
  File "/home/zhuhe/.conda/envs/diffhpe/lib/python3.9/site-packages/wandb/sdk/lib/retry.py", line 212, in wrapped_fn
    return retrier(*args, **kargs)
  File "/home/zhuhe/.conda/envs/diffhpe/lib/python3.9/site-packages/wandb/sdk/lib/retry.py", line 131, in __call__
    result = self._call_fn(*args, **kwargs)
  File "/home/zhuhe/.conda/envs/diffhpe/lib/python3.9/site-packages/wandb/sdk/internal/internal_api.py", line 2218, in upload_file
    wandb._sentry.reraise(e)
  File "/home/zhuhe/.conda/envs/diffhpe/lib/python3.9/site-packages/wandb/analytics/sentry.py", line 146, in reraise
    raise exc.with_traceback(sys.exc_info()[2])
  File "/home/zhuhe/.conda/envs/diffhpe/lib/python3.9/site-packages/wandb/sdk/internal/internal_api.py", line 2190, in upload_file
    response.raise_for_status()
  File "/home/zhuhe/.conda/envs/diffhpe/lib/python3.9/site-packages/requests/models.py", line 1021, in raise_for_status
    raise HTTPError(http_error_msg, response=self)
requests.exceptions.HTTPError: 404 Client Error: Not Found for url: https://storage.googleapis.com/wandb-production.appspot.com/ada4321/DiffHPE/uq8ma9hv/output.log?Expires=1689072256&GoogleAccessId=gorilla-files-url-signer-man%40wandb-production.iam.gserviceaccount.com&Signature=DR2gxug%2FY24enTkNDQRLaffQyzUKma2duwF5zP3BX43P1ejS42aEZd8fyRAWY1EHtPwrfhyrSAZEWI5PmHgh39%2FO%2BQUsPqtzXyADdb6Bmw69IEXjMTxzYujfPJrphjOLL7ixR1esfwMFrZvj0j93ldbiDLScfXIDBKJTC1Med247AiiyrBdJyaevCwVRi7Sr4usqJ7z65gEA8KfDpoBLofERDkZihXeoxmFezwXmuvA4VRkm2m7Kg7V2AhOiPH9POe4SrJ0YAfN%2FII1fuvKPxx%2BzGW09SSCE3we2yDypumFeJvXXugqPW9HY4OWuDU7qtAFurImgMoqMN7c6nuXLwg%3D%3D

During handling of the above exception, another exception occurred:

Traceback (most recent call last):
  File "/home/zhuhe/.conda/envs/diffhpe/lib/python3.9/concurrent/futures/thread.py", line 58, in run
    result = self.fn(*self.args, **self.kwargs)
  File "/home/zhuhe/.conda/envs/diffhpe/lib/python3.9/site-packages/wandb/filesync/step_upload.py", line 288, in run_and_notify
    self._do_upload_sync(event)
  File "/home/zhuhe/.conda/envs/diffhpe/lib/python3.9/site-packages/wandb/filesync/step_upload.py", line 330, in _do_upload_sync
    job.run()
  File "/home/zhuhe/.conda/envs/diffhpe/lib/python3.9/site-packages/wandb/filesync/upload_job.py", line 57, in run
    self.push()
  File "/home/zhuhe/.conda/envs/diffhpe/lib/python3.9/site-packages/wandb/filesync/upload_job.py", line 127, in push
    self._api.upload_file_retry(
  File "/home/zhuhe/.conda/envs/diffhpe/lib/python3.9/site-packages/wandb/apis/normalize.py", line 51, in wrapper
    raise CommError(message, error)
wandb.errors.CommError: <Response [404]>
2023-07-10 18:44:18,449 ERROR   Thread-11 :20949 [step_upload.py:_handle_event():200] Failed to upload file: /home/zhuhe/HPE-with-Diffusion/wandb/run-20230710_184356-uq8ma9hv/files/wandb-summary.json
Traceback (most recent call last):
  File "/home/zhuhe/.conda/envs/diffhpe/lib/python3.9/site-packages/wandb/apis/normalize.py", line 41, in wrapper
    return func(*args, **kwargs)
  File "/home/zhuhe/.conda/envs/diffhpe/lib/python3.9/site-packages/wandb/sdk/lib/retry.py", line 212, in wrapped_fn
    return retrier(*args, **kargs)
  File "/home/zhuhe/.conda/envs/diffhpe/lib/python3.9/site-packages/wandb/sdk/lib/retry.py", line 131, in __call__
    result = self._call_fn(*args, **kwargs)
  File "/home/zhuhe/.conda/envs/diffhpe/lib/python3.9/site-packages/wandb/sdk/internal/internal_api.py", line 2218, in upload_file
    wandb._sentry.reraise(e)
  File "/home/zhuhe/.conda/envs/diffhpe/lib/python3.9/site-packages/wandb/analytics/sentry.py", line 146, in reraise
    raise exc.with_traceback(sys.exc_info()[2])
  File "/home/zhuhe/.conda/envs/diffhpe/lib/python3.9/site-packages/wandb/sdk/internal/internal_api.py", line 2190, in upload_file
    response.raise_for_status()
  File "/home/zhuhe/.conda/envs/diffhpe/lib/python3.9/site-packages/requests/models.py", line 1021, in raise_for_status
    raise HTTPError(http_error_msg, response=self)
requests.exceptions.HTTPError: 404 Client Error: Not Found for url: https://storage.googleapis.com/wandb-production.appspot.com/ada4321/DiffHPE/uq8ma9hv/wandb-summary.json?Expires=1689072256&GoogleAccessId=gorilla-files-url-signer-man%40wandb-production.iam.gserviceaccount.com&Signature=UB1f2XgcfImp4Bb5J43CNxQ%2BawvjcZ78oHHBrClGQPD63aM6hmChNhAy1oHnvbeM2IZkiUdvay1IzETWdTMY7JrbgkXr3%2FzAP1%2Bjr0z%2BrVNiyP6ICZvrnWIzFUZIm7N5cufA10WOJ0gW5bVndpsXowQ3ovO8A9QZCy36r8UTJvV5AKw6X6PLbOKDEGtw6RLGckEBOx45PMA4XYQABTJWJeQSxzgiNoc5whxQQIIahgPjq9byZNNTOs5AFInNOsXSPNgtqYz0DcDdVqwlg2IOwnJoyWi%2B98Y6I%2FVMb9%2FNAxGUz6PLdYaDCnt%2FiGQzR3OWuf5kY1zssOXBVhV%2BO8Opzg%3D%3D

During handling of the above exception, another exception occurred:

Traceback (most recent call last):
  File "/home/zhuhe/.conda/envs/diffhpe/lib/python3.9/concurrent/futures/thread.py", line 58, in run
    result = self.fn(*self.args, **self.kwargs)
  File "/home/zhuhe/.conda/envs/diffhpe/lib/python3.9/site-packages/wandb/filesync/step_upload.py", line 288, in run_and_notify
    self._do_upload_sync(event)
  File "/home/zhuhe/.conda/envs/diffhpe/lib/python3.9/site-packages/wandb/filesync/step_upload.py", line 330, in _do_upload_sync
    job.run()
  File "/home/zhuhe/.conda/envs/diffhpe/lib/python3.9/site-packages/wandb/filesync/upload_job.py", line 57, in run
    self.push()
  File "/home/zhuhe/.conda/envs/diffhpe/lib/python3.9/site-packages/wandb/filesync/upload_job.py", line 127, in push
    self._api.upload_file_retry(
  File "/home/zhuhe/.conda/envs/diffhpe/lib/python3.9/site-packages/wandb/apis/normalize.py", line 51, in wrapper
    raise CommError(message, error)
wandb.errors.CommError: <Response [404]>
2023-07-10 18:44:18,449 ERROR   Thread-11 :20949 [step_upload.py:_handle_event():200] Failed to upload file: /home/zhuhe/HPE-with-Diffusion/wandb/run-20230710_184356-uq8ma9hv/files/config.yaml
Traceback (most recent call last):
  File "/home/zhuhe/.conda/envs/diffhpe/lib/python3.9/site-packages/wandb/apis/normalize.py", line 41, in wrapper
    return func(*args, **kwargs)
  File "/home/zhuhe/.conda/envs/diffhpe/lib/python3.9/site-packages/wandb/sdk/lib/retry.py", line 212, in wrapped_fn
    return retrier(*args, **kargs)
  File "/home/zhuhe/.conda/envs/diffhpe/lib/python3.9/site-packages/wandb/sdk/lib/retry.py", line 131, in __call__
    result = self._call_fn(*args, **kwargs)
  File "/home/zhuhe/.conda/envs/diffhpe/lib/python3.9/site-packages/wandb/sdk/internal/internal_api.py", line 2218, in upload_file
    wandb._sentry.reraise(e)
  File "/home/zhuhe/.conda/envs/diffhpe/lib/python3.9/site-packages/wandb/analytics/sentry.py", line 146, in reraise
    raise exc.with_traceback(sys.exc_info()[2])
  File "/home/zhuhe/.conda/envs/diffhpe/lib/python3.9/site-packages/wandb/sdk/internal/internal_api.py", line 2190, in upload_file
    response.raise_for_status()
  File "/home/zhuhe/.conda/envs/diffhpe/lib/python3.9/site-packages/requests/models.py", line 1021, in raise_for_status
    raise HTTPError(http_error_msg, response=self)
requests.exceptions.HTTPError: 404 Client Error: Not Found for url: https://storage.googleapis.com/wandb-production.appspot.com/ada4321/DiffHPE/uq8ma9hv/config.yaml?Expires=1689072255&GoogleAccessId=gorilla-files-url-signer-man%40wandb-production.iam.gserviceaccount.com&Signature=wimTKfPPEzOrQ%2FmftwijPp8P3D%2Fpgfm%2FG4WkbmHSd0mJbDVtiRViAGDOo%2BfHVRQtWe%2FapVmkWZvppF%2BqWGaIl%2F1wlmcs1Z913t7jrOe9b5gPObcwn633sK8NzhcTi%2FJux8v%2FeHtpCzxs9uG%2Fgdqtnx6WNUPGbb6cqGplmIVMvi58AFfpHN10O9WyuhavGmAl6xxYQfm6qP9zHYjl3NFMaHE7Dotm53F92yb7Hl%2BesupkyqzFee9ujSAmtzT9OffWGyZU2txj07N%2BD28om7zgm%2B62fCNxPLuMhS1eUjw%2FdmPxpzG5owX74w%2FyMl8pVP2ntqzdI1DhDwlIEzKDVxB8cQ%3D%3D

During handling of the above exception, another exception occurred:

Traceback (most recent call last):
  File "/home/zhuhe/.conda/envs/diffhpe/lib/python3.9/concurrent/futures/thread.py", line 58, in run
    result = self.fn(*self.args, **self.kwargs)
  File "/home/zhuhe/.conda/envs/diffhpe/lib/python3.9/site-packages/wandb/filesync/step_upload.py", line 288, in run_and_notify
    self._do_upload_sync(event)
  File "/home/zhuhe/.conda/envs/diffhpe/lib/python3.9/site-packages/wandb/filesync/step_upload.py", line 330, in _do_upload_sync
    job.run()
  File "/home/zhuhe/.conda/envs/diffhpe/lib/python3.9/site-packages/wandb/filesync/upload_job.py", line 57, in run
    self.push()
  File "/home/zhuhe/.conda/envs/diffhpe/lib/python3.9/site-packages/wandb/filesync/upload_job.py", line 127, in push
    self._api.upload_file_retry(
  File "/home/zhuhe/.conda/envs/diffhpe/lib/python3.9/site-packages/wandb/apis/normalize.py", line 51, in wrapper
    raise CommError(message, error)
wandb.errors.CommError: <Response [404]>
2023-07-10 18:44:18,650 INFO    Thread-11 :20949 [sender.py:transition_state():602] send defer: 11
2023-07-10 18:44:18,650 DEBUG   HandlerThread:20949 [handler.py:handle_request():144] handle_request: defer
2023-07-10 18:44:18,650 INFO    HandlerThread:20949 [handler.py:handle_request_defer():170] handle defer: 11
2023-07-10 18:44:18,650 DEBUG   SenderThread:20949 [sender.py:send_request():396] send_request: defer
2023-07-10 18:44:18,650 INFO    SenderThread:20949 [sender.py:send_request_defer():598] handle sender defer: 11
2023-07-10 18:44:18,650 INFO    SenderThread:20949 [file_pusher.py:join():164] waiting for file pusher
2023-07-10 18:44:18,651 INFO    SenderThread:20949 [sender.py:transition_state():602] send defer: 12
2023-07-10 18:44:18,651 DEBUG   HandlerThread:20949 [handler.py:handle_request():144] handle_request: defer
2023-07-10 18:44:18,651 INFO    HandlerThread:20949 [handler.py:handle_request_defer():170] handle defer: 12
2023-07-10 18:44:18,651 DEBUG   SenderThread:20949 [sender.py:send_request():396] send_request: defer
2023-07-10 18:44:18,651 INFO    SenderThread:20949 [sender.py:send_request_defer():598] handle sender defer: 12
2023-07-10 18:44:18,896 INFO    SenderThread:20949 [sender.py:transition_state():602] send defer: 13
2023-07-10 18:44:18,897 DEBUG   HandlerThread:20949 [handler.py:handle_request():144] handle_request: defer
2023-07-10 18:44:18,897 INFO    HandlerThread:20949 [handler.py:handle_request_defer():170] handle defer: 13
2023-07-10 18:44:18,897 DEBUG   SenderThread:20949 [sender.py:send_request():396] send_request: defer
2023-07-10 18:44:18,897 INFO    SenderThread:20949 [sender.py:send_request_defer():598] handle sender defer: 13
2023-07-10 18:44:18,897 INFO    SenderThread:20949 [sender.py:transition_state():602] send defer: 14
2023-07-10 18:44:18,897 DEBUG   HandlerThread:20949 [handler.py:handle_request():144] handle_request: defer
2023-07-10 18:44:18,898 INFO    HandlerThread:20949 [handler.py:handle_request_defer():170] handle defer: 14
2023-07-10 18:44:18,898 DEBUG   SenderThread:20949 [sender.py:send():369] send: final
2023-07-10 18:44:18,898 DEBUG   SenderThread:20949 [sender.py:send():369] send: footer
2023-07-10 18:44:18,898 DEBUG   SenderThread:20949 [sender.py:send_request():396] send_request: defer
2023-07-10 18:44:18,898 INFO    SenderThread:20949 [sender.py:send_request_defer():598] handle sender defer: 14
2023-07-10 18:44:18,898 DEBUG   HandlerThread:20949 [handler.py:handle_request():144] handle_request: poll_exit
2023-07-10 18:44:18,899 DEBUG   HandlerThread:20949 [handler.py:handle_request():144] handle_request: server_info
2023-07-10 18:44:18,899 DEBUG   HandlerThread:20949 [handler.py:handle_request():144] handle_request: get_summary
2023-07-10 18:44:18,899 DEBUG   SenderThread:20949 [sender.py:send_request():396] send_request: poll_exit
2023-07-10 18:44:18,899 DEBUG   SenderThread:20949 [sender.py:send_request():396] send_request: server_info
2023-07-10 18:44:18,900 DEBUG   HandlerThread:20949 [handler.py:handle_request():144] handle_request: sampled_history
2023-07-10 18:44:19,378 INFO    MainThread:20949 [wandb_run.py:_footer_history_summary_info():3467] rendering history
2023-07-10 18:44:19,378 INFO    MainThread:20949 [wandb_run.py:_footer_history_summary_info():3499] rendering summary
2023-07-10 18:44:19,378 INFO    MainThread:20949 [wandb_run.py:_footer_sync_info():3426] logging synced files
2023-07-10 18:44:19,379 DEBUG   HandlerThread:20949 [handler.py:handle_request():144] handle_request: shutdown
2023-07-10 18:44:19,379 INFO    HandlerThread:20949 [handler.py:finish():854] shutting down handler
2023-07-10 18:44:19,899 INFO    WriterThread:20949 [datastore.py:close():298] close: /home/zhuhe/HPE-with-Diffusion/wandb/run-20230710_184356-uq8ma9hv/run-uq8ma9hv.wandb
2023-07-10 18:44:20,378 INFO    SenderThread:20949 [sender.py:finish():1526] shutting down sender
2023-07-10 18:44:20,378 INFO    SenderThread:20949 [file_pusher.py:finish():159] shutting down file pusher
2023-07-10 18:44:20,378 INFO    SenderThread:20949 [file_pusher.py:join():164] waiting for file pusher
