2023-07-10 18:29:58,387 INFO    StreamThr :16893 [internal.py:wandb_internal():86] W&B internal server running at pid: 16893, started at: 2023-07-10 18:29:58.386974
2023-07-10 18:29:58,388 DEBUG   HandlerThread:16893 [handler.py:handle_request():144] handle_request: status
2023-07-10 18:29:58,389 INFO    WriterThread:16893 [datastore.py:open_for_write():85] open: /home/zhuhe/HPE-with-Diffusion/wandb/run-20230710_182958-eguvwkcw/run-eguvwkcw.wandb
2023-07-10 18:29:58,389 DEBUG   SenderThread:16893 [sender.py:send():369] send: header
2023-07-10 18:29:58,389 DEBUG   SenderThread:16893 [sender.py:send():369] send: run
2023-07-10 18:29:59,210 INFO    SenderThread:16893 [dir_watcher.py:__init__():211] watching files in: /home/zhuhe/HPE-with-Diffusion/wandb/run-20230710_182958-eguvwkcw/files
2023-07-10 18:29:59,210 INFO    SenderThread:16893 [sender.py:_start_run_threads():1100] run started: eguvwkcw with start time 1688984998.386685
2023-07-10 18:29:59,210 DEBUG   SenderThread:16893 [sender.py:send_request():396] send_request: summary_record
2023-07-10 18:29:59,210 INFO    SenderThread:16893 [sender.py:_save_file():1354] saving file wandb-summary.json with policy end
2023-07-10 18:29:59,212 DEBUG   HandlerThread:16893 [handler.py:handle_request():144] handle_request: check_version
2023-07-10 18:29:59,212 DEBUG   SenderThread:16893 [sender.py:send_request():396] send_request: check_version
2023-07-10 18:29:59,390 DEBUG   HandlerThread:16893 [handler.py:handle_request():144] handle_request: run_start
2023-07-10 18:29:59,396 DEBUG   HandlerThread:16893 [system_info.py:__init__():31] System info init
2023-07-10 18:29:59,396 DEBUG   HandlerThread:16893 [system_info.py:__init__():46] System info init done
2023-07-10 18:29:59,396 INFO    HandlerThread:16893 [system_monitor.py:start():181] Starting system monitor
2023-07-10 18:29:59,396 INFO    SystemMonitor:16893 [system_monitor.py:_start():145] Starting system asset monitoring threads
2023-07-10 18:29:59,397 INFO    HandlerThread:16893 [system_monitor.py:probe():201] Collecting system info
2023-07-10 18:29:59,397 INFO    SystemMonitor:16893 [interfaces.py:start():190] Started cpu monitoring
2023-07-10 18:29:59,398 INFO    SystemMonitor:16893 [interfaces.py:start():190] Started disk monitoring
2023-07-10 18:29:59,398 INFO    SystemMonitor:16893 [interfaces.py:start():190] Started gpu monitoring
2023-07-10 18:29:59,398 INFO    SystemMonitor:16893 [interfaces.py:start():190] Started memory monitoring
2023-07-10 18:29:59,399 INFO    SystemMonitor:16893 [interfaces.py:start():190] Started network monitoring
2023-07-10 18:29:59,409 DEBUG   HandlerThread:16893 [system_info.py:probe():195] Probing system
2023-07-10 18:29:59,412 DEBUG   HandlerThread:16893 [gitlib.py:_init_repo():53] git repository is invalid
2023-07-10 18:29:59,412 DEBUG   HandlerThread:16893 [system_info.py:probe():240] Probing system done
2023-07-10 18:29:59,412 DEBUG   HandlerThread:16893 [system_monitor.py:probe():210] {'os': 'Linux-5.19.0-46-generic-x86_64-with-glibc2.35', 'python': '3.9.16', 'heartbeatAt': '2023-07-10T10:29:59.409544', 'startedAt': '2023-07-10T10:29:58.383842', 'docker': None, 'cuda': None, 'args': ('--phase', 'train', '--gpu_ids', '1'), 'state': 'running', 'program': '/home/zhuhe/HPE-with-Diffusion/main.py', 'codePath': 'main.py', 'host': '415-2', 'username': 'zhuhe', 'executable': '/home/zhuhe/.conda/envs/diffhpe/bin/python', 'cpu_count': 16, 'cpu_count_logical': 24, 'cpu_freq': {'current': 3171.7019999999998, 'min': 800.0, 'max': 4783.333333333333}, 'cpu_freq_per_core': [{'current': 5100.0, 'min': 800.0, 'max': 5100.0}, {'current': 5100.0, 'min': 800.0, 'max': 5100.0}, {'current': 5091.904, 'min': 800.0, 'max': 5100.0}, {'current': 5100.0, 'min': 800.0, 'max': 5100.0}, {'current': 2100.0, 'min': 800.0, 'max': 5100.0}, {'current': 5100.054, 'min': 800.0, 'max': 5100.0}, {'current': 5095.061, 'min': 800.0, 'max': 5100.0}, {'current': 2100.0, 'min': 800.0, 'max': 5100.0}, {'current': 5098.753, 'min': 800.0, 'max': 5200.0}, {'current': 2100.0, 'min': 800.0, 'max': 5200.0}, {'current': 5100.0, 'min': 800.0, 'max': 5200.0}, {'current': 2100.0, 'min': 800.0, 'max': 5200.0}, {'current': 2100.0, 'min': 800.0, 'max': 5100.0}, {'current': 5100.0, 'min': 800.0, 'max': 5100.0}, {'current': 5100.0, 'min': 800.0, 'max': 5100.0}, {'current': 2100.0, 'min': 800.0, 'max': 5100.0}, {'current': 3756.262, 'min': 800.0, 'max': 4100.0}, {'current': 2100.0, 'min': 800.0, 'max': 4100.0}, {'current': 2100.0, 'min': 800.0, 'max': 4100.0}, {'current': 2100.0, 'min': 800.0, 'max': 4100.0}, {'current': 2100.0, 'min': 800.0, 'max': 4100.0}, {'current': 2100.0, 'min': 800.0, 'max': 4100.0}, {'current': 2100.0, 'min': 800.0, 'max': 4100.0}, {'current': 2100.0, 'min': 800.0, 'max': 4100.0}], 'disk': {'total': 93.31179428100586, 'used': 0.01787567138671875}, 'gpu': 'NVIDIA GeForce RTX 3090', 'gpu_count': 2, 'gpu_devices': [{'name': 'NVIDIA GeForce RTX 3090', 'memory_total': 25769803776}, {'name': 'NVIDIA GeForce RTX 3090', 'memory_total': 25769803776}], 'memory': {'total': 31.185558319091797}}
2023-07-10 18:29:59,412 INFO    HandlerThread:16893 [system_monitor.py:probe():211] Finished collecting system info
2023-07-10 18:29:59,412 INFO    HandlerThread:16893 [system_monitor.py:probe():214] Publishing system info
2023-07-10 18:29:59,413 DEBUG   HandlerThread:16893 [system_info.py:_save_pip():51] Saving list of pip packages installed into the current environment
2023-07-10 18:29:59,413 DEBUG   HandlerThread:16893 [system_info.py:_save_pip():67] Saving pip packages done
2023-07-10 18:29:59,413 DEBUG   HandlerThread:16893 [system_info.py:_save_conda():74] Saving list of conda packages installed into the current environment
2023-07-10 18:30:00,193 DEBUG   HandlerThread:16893 [system_info.py:_save_conda():86] Saving conda packages done
2023-07-10 18:30:00,194 INFO    HandlerThread:16893 [system_monitor.py:probe():216] Finished publishing system info
2023-07-10 18:30:00,195 DEBUG   SenderThread:16893 [sender.py:send():369] send: files
2023-07-10 18:30:00,195 INFO    SenderThread:16893 [sender.py:_save_file():1354] saving file wandb-metadata.json with policy now
2023-07-10 18:30:00,198 DEBUG   HandlerThread:16893 [handler.py:handle_request():144] handle_request: stop_status
2023-07-10 18:30:00,198 DEBUG   SenderThread:16893 [sender.py:send_request():396] send_request: stop_status
2023-07-10 18:30:00,211 INFO    Thread-12 :16893 [dir_watcher.py:_on_file_created():272] file/dir created: /home/zhuhe/HPE-with-Diffusion/wandb/run-20230710_182958-eguvwkcw/files/conda-environment.yaml
2023-07-10 18:30:00,211 INFO    Thread-12 :16893 [dir_watcher.py:_on_file_created():272] file/dir created: /home/zhuhe/HPE-with-Diffusion/wandb/run-20230710_182958-eguvwkcw/files/requirements.txt
2023-07-10 18:30:00,211 INFO    Thread-12 :16893 [dir_watcher.py:_on_file_created():272] file/dir created: /home/zhuhe/HPE-with-Diffusion/wandb/run-20230710_182958-eguvwkcw/files/wandb-metadata.json
2023-07-10 18:30:00,211 INFO    Thread-12 :16893 [dir_watcher.py:_on_file_created():272] file/dir created: /home/zhuhe/HPE-with-Diffusion/wandb/run-20230710_182958-eguvwkcw/files/wandb-summary.json
2023-07-10 18:30:00,652 ERROR   wandb-upload_0:16893 [internal_api.py:upload_file():2192] upload_file exception https://storage.googleapis.com/wandb-production.appspot.com/ada4321/DiffHPE/eguvwkcw/wandb-metadata.json?Expires=1689071400&GoogleAccessId=gorilla-files-url-signer-man%40wandb-production.iam.gserviceaccount.com&Signature=GmEfttA99PDCptcaAcXAqSbsTljCQUfoG4zlFWgZ8zOO5IsvB%2BeIEYv8Ym5psrMsuYTYjlP3nozb1IRFP8nbuxCUXa%2F38WQOLFQPrkacc0JapEhIuwX70IUaIcISVl5q9RDZTRO2vSEpwjFm2Lc33T96HQCxm8Yv44%2Btok71DqB8IXONp1lSLHTSwRgoNFmt2I4yrcZl2oFXnPHgPUqCnBXPuvtdln5EI7z5kAaoEo3eVdxq9%2BYKju4IrGXMJDeIK15g0GINnEsbYGXTDCu3GgImkcDoFBPZswfQwfJQ%2FRcUhiAgcYg2nbpRzJHKY5EFEjM7qKaM1brKCn9KgDtJLg%3D%3D: 404 Client Error: Not Found for url: https://storage.googleapis.com/wandb-production.appspot.com/ada4321/DiffHPE/eguvwkcw/wandb-metadata.json?Expires=1689071400&GoogleAccessId=gorilla-files-url-signer-man%40wandb-production.iam.gserviceaccount.com&Signature=GmEfttA99PDCptcaAcXAqSbsTljCQUfoG4zlFWgZ8zOO5IsvB%2BeIEYv8Ym5psrMsuYTYjlP3nozb1IRFP8nbuxCUXa%2F38WQOLFQPrkacc0JapEhIuwX70IUaIcISVl5q9RDZTRO2vSEpwjFm2Lc33T96HQCxm8Yv44%2Btok71DqB8IXONp1lSLHTSwRgoNFmt2I4yrcZl2oFXnPHgPUqCnBXPuvtdln5EI7z5kAaoEo3eVdxq9%2BYKju4IrGXMJDeIK15g0GINnEsbYGXTDCu3GgImkcDoFBPZswfQwfJQ%2FRcUhiAgcYg2nbpRzJHKY5EFEjM7qKaM1brKCn9KgDtJLg%3D%3D
2023-07-10 18:30:00,652 ERROR   wandb-upload_0:16893 [internal_api.py:upload_file():2194] upload_file request headers: {'User-Agent': 'python-requests/2.31.0', 'Accept-Encoding': 'gzip, deflate', 'Accept': '*/*', 'Connection': 'keep-alive', 'Content-Length': '3689'}
2023-07-10 18:30:00,653 ERROR   wandb-upload_0:16893 [internal_api.py:upload_file():2196] upload_file response body: b'<!DOCTYPE html>\n<html lang=en>\n  <meta charset=utf-8>\n  <meta name=viewport content="initial-scale=1, minimum-scale=1, width=device-width">\n  <title>Error 404 (Not Found)!!1</title>\n  <style>\n    *{margin:0;padding:0}html,code{font:15px/22px arial,sans-serif}html{background:#fff;color:#222;padding:15px}body{margin:7% auto 0;max-width:390px;min-height:180px;padding:30px 0 15px}* > body{background:url(//www.google.com/images/errors/robot.png) 100% 5px no-repeat;padding-right:205px}p{margin:11px 0 22px;overflow:hidden}ins{color:#777;text-decoration:none}a img{border:0}@media screen and (max-width:772px){body{background:none;margin-top:0;max-width:none;padding-right:0}}#logo{background:url(//www.google.com/images/branding/googlelogo/1x/googlelogo_color_150x54dp.png) no-repeat;margin-left:-5px}@media only screen and (min-resolution:192dpi){#logo{background:url(//www.google.com/images/branding/googlelogo/2x/googlelogo_color_150x54dp.png) no-repeat 0% 0%/100% 100%;-moz-border-image:url(//www.google.com/images/branding/googlelogo/2x/googlelogo_color_150x54dp.png) 0}}@media only screen and (-webkit-min-device-pixel-ratio:2){#logo{background:url(//www.google.com/images/branding/googlelogo/2x/googlelogo_color_150x54dp.png) no-repeat;-webkit-background-size:100% 100%}}#logo{display:inline-block;height:54px;width:150px}\n  </style>\n  <a href=//www.google.com/><span id=logo aria-label=Google></span></a>\n  <p><b>404.</b> <ins>That\xe2\x80\x99s an error.</ins>\n  <p>The requested URL <code>/wandb-production.appspot.com/ada4321/DiffHPE/eguvwkcw/wandb-metadata.json</code> was not found on this server.  <ins>That\xe2\x80\x99s all we know.</ins>\n'
2023-07-10 18:30:00,775 DEBUG   SenderThread:16893 [sender.py:send():369] send: telemetry
2023-07-10 18:30:01,211 INFO    Thread-12 :16893 [dir_watcher.py:_on_file_created():272] file/dir created: /home/zhuhe/HPE-with-Diffusion/wandb/run-20230710_182958-eguvwkcw/files/output.log
2023-07-10 18:30:02,168 ERROR   wandb-upload_0:16893 [upload_job.py:push():136] Failed to upload file: /tmp/tmpfgvqaqmkwandb/7hb4no01-wandb-metadata.json
Traceback (most recent call last):
  File "/home/zhuhe/.conda/envs/diffhpe/lib/python3.9/site-packages/wandb/apis/normalize.py", line 41, in wrapper
    return func(*args, **kwargs)
  File "/home/zhuhe/.conda/envs/diffhpe/lib/python3.9/site-packages/wandb/sdk/lib/retry.py", line 212, in wrapped_fn
    return retrier(*args, **kargs)
  File "/home/zhuhe/.conda/envs/diffhpe/lib/python3.9/site-packages/wandb/sdk/lib/retry.py", line 131, in __call__
    result = self._call_fn(*args, **kwargs)
  File "/home/zhuhe/.conda/envs/diffhpe/lib/python3.9/site-packages/wandb/sdk/internal/internal_api.py", line 2218, in upload_file
    wandb._sentry.reraise(e)
  File "/home/zhuhe/.conda/envs/diffhpe/lib/python3.9/site-packages/wandb/analytics/sentry.py", line 146, in reraise
    raise exc.with_traceback(sys.exc_info()[2])
  File "/home/zhuhe/.conda/envs/diffhpe/lib/python3.9/site-packages/wandb/sdk/internal/internal_api.py", line 2190, in upload_file
    response.raise_for_status()
  File "/home/zhuhe/.conda/envs/diffhpe/lib/python3.9/site-packages/requests/models.py", line 1021, in raise_for_status
    raise HTTPError(http_error_msg, response=self)
requests.exceptions.HTTPError: 404 Client Error: Not Found for url: https://storage.googleapis.com/wandb-production.appspot.com/ada4321/DiffHPE/eguvwkcw/wandb-metadata.json?Expires=1689071400&GoogleAccessId=gorilla-files-url-signer-man%40wandb-production.iam.gserviceaccount.com&Signature=GmEfttA99PDCptcaAcXAqSbsTljCQUfoG4zlFWgZ8zOO5IsvB%2BeIEYv8Ym5psrMsuYTYjlP3nozb1IRFP8nbuxCUXa%2F38WQOLFQPrkacc0JapEhIuwX70IUaIcISVl5q9RDZTRO2vSEpwjFm2Lc33T96HQCxm8Yv44%2Btok71DqB8IXONp1lSLHTSwRgoNFmt2I4yrcZl2oFXnPHgPUqCnBXPuvtdln5EI7z5kAaoEo3eVdxq9%2BYKju4IrGXMJDeIK15g0GINnEsbYGXTDCu3GgImkcDoFBPZswfQwfJQ%2FRcUhiAgcYg2nbpRzJHKY5EFEjM7qKaM1brKCn9KgDtJLg%3D%3D

During handling of the above exception, another exception occurred:

Traceback (most recent call last):
  File "/home/zhuhe/.conda/envs/diffhpe/lib/python3.9/site-packages/wandb/filesync/upload_job.py", line 127, in push
    self._api.upload_file_retry(
  File "/home/zhuhe/.conda/envs/diffhpe/lib/python3.9/site-packages/wandb/apis/normalize.py", line 51, in wrapper
    raise CommError(message, error)
wandb.errors.CommError: <Response [404]>
2023-07-10 18:30:02,383 ERROR   Thread-11 :16893 [step_upload.py:_handle_event():200] Failed to upload file: /tmp/tmpfgvqaqmkwandb/7hb4no01-wandb-metadata.json
Traceback (most recent call last):
  File "/home/zhuhe/.conda/envs/diffhpe/lib/python3.9/site-packages/wandb/apis/normalize.py", line 41, in wrapper
    return func(*args, **kwargs)
  File "/home/zhuhe/.conda/envs/diffhpe/lib/python3.9/site-packages/wandb/sdk/lib/retry.py", line 212, in wrapped_fn
    return retrier(*args, **kargs)
  File "/home/zhuhe/.conda/envs/diffhpe/lib/python3.9/site-packages/wandb/sdk/lib/retry.py", line 131, in __call__
    result = self._call_fn(*args, **kwargs)
  File "/home/zhuhe/.conda/envs/diffhpe/lib/python3.9/site-packages/wandb/sdk/internal/internal_api.py", line 2218, in upload_file
    wandb._sentry.reraise(e)
  File "/home/zhuhe/.conda/envs/diffhpe/lib/python3.9/site-packages/wandb/analytics/sentry.py", line 146, in reraise
    raise exc.with_traceback(sys.exc_info()[2])
  File "/home/zhuhe/.conda/envs/diffhpe/lib/python3.9/site-packages/wandb/sdk/internal/internal_api.py", line 2190, in upload_file
    response.raise_for_status()
  File "/home/zhuhe/.conda/envs/diffhpe/lib/python3.9/site-packages/requests/models.py", line 1021, in raise_for_status
    raise HTTPError(http_error_msg, response=self)
requests.exceptions.HTTPError: 404 Client Error: Not Found for url: https://storage.googleapis.com/wandb-production.appspot.com/ada4321/DiffHPE/eguvwkcw/wandb-metadata.json?Expires=1689071400&GoogleAccessId=gorilla-files-url-signer-man%40wandb-production.iam.gserviceaccount.com&Signature=GmEfttA99PDCptcaAcXAqSbsTljCQUfoG4zlFWgZ8zOO5IsvB%2BeIEYv8Ym5psrMsuYTYjlP3nozb1IRFP8nbuxCUXa%2F38WQOLFQPrkacc0JapEhIuwX70IUaIcISVl5q9RDZTRO2vSEpwjFm2Lc33T96HQCxm8Yv44%2Btok71DqB8IXONp1lSLHTSwRgoNFmt2I4yrcZl2oFXnPHgPUqCnBXPuvtdln5EI7z5kAaoEo3eVdxq9%2BYKju4IrGXMJDeIK15g0GINnEsbYGXTDCu3GgImkcDoFBPZswfQwfJQ%2FRcUhiAgcYg2nbpRzJHKY5EFEjM7qKaM1brKCn9KgDtJLg%3D%3D

During handling of the above exception, another exception occurred:

Traceback (most recent call last):
  File "/home/zhuhe/.conda/envs/diffhpe/lib/python3.9/concurrent/futures/thread.py", line 58, in run
    result = self.fn(*self.args, **self.kwargs)
  File "/home/zhuhe/.conda/envs/diffhpe/lib/python3.9/site-packages/wandb/filesync/step_upload.py", line 288, in run_and_notify
    self._do_upload_sync(event)
  File "/home/zhuhe/.conda/envs/diffhpe/lib/python3.9/site-packages/wandb/filesync/step_upload.py", line 330, in _do_upload_sync
    job.run()
  File "/home/zhuhe/.conda/envs/diffhpe/lib/python3.9/site-packages/wandb/filesync/upload_job.py", line 57, in run
    self.push()
  File "/home/zhuhe/.conda/envs/diffhpe/lib/python3.9/site-packages/wandb/filesync/upload_job.py", line 127, in push
    self._api.upload_file_retry(
  File "/home/zhuhe/.conda/envs/diffhpe/lib/python3.9/site-packages/wandb/apis/normalize.py", line 51, in wrapper
    raise CommError(message, error)
wandb.errors.CommError: <Response [404]>
2023-07-10 18:30:03,211 INFO    Thread-12 :16893 [dir_watcher.py:_on_file_modified():289] file/dir modified: /home/zhuhe/HPE-with-Diffusion/wandb/run-20230710_182958-eguvwkcw/files/output.log
2023-07-10 18:30:03,681 DEBUG   HandlerThread:16893 [handler.py:handle_request():144] handle_request: status_report
2023-07-10 18:30:05,212 INFO    Thread-12 :16893 [dir_watcher.py:_on_file_modified():289] file/dir modified: /home/zhuhe/HPE-with-Diffusion/wandb/run-20230710_182958-eguvwkcw/files/output.log
2023-07-10 18:30:07,951 DEBUG   SenderThread:16893 [sender.py:send():369] send: telemetry
2023-07-10 18:30:09,011 DEBUG   HandlerThread:16893 [handler.py:handle_request():144] handle_request: status_report
2023-07-10 18:30:09,213 INFO    Thread-12 :16893 [dir_watcher.py:_on_file_modified():289] file/dir modified: /home/zhuhe/HPE-with-Diffusion/wandb/run-20230710_182958-eguvwkcw/files/output.log
2023-07-10 18:30:11,637 DEBUG   SenderThread:16893 [sender.py:send():369] send: exit
2023-07-10 18:30:11,637 INFO    SenderThread:16893 [sender.py:send_exit():574] handling exit code: 1
2023-07-10 18:30:11,637 INFO    SenderThread:16893 [sender.py:send_exit():576] handling runtime: 12
2023-07-10 18:30:11,637 INFO    SenderThread:16893 [sender.py:_save_file():1354] saving file wandb-summary.json with policy end
2023-07-10 18:30:11,637 INFO    SenderThread:16893 [sender.py:send_exit():582] send defer
2023-07-10 18:30:11,637 DEBUG   HandlerThread:16893 [handler.py:handle_request():144] handle_request: defer
2023-07-10 18:30:11,637 INFO    HandlerThread:16893 [handler.py:handle_request_defer():170] handle defer: 0
2023-07-10 18:30:11,637 DEBUG   SenderThread:16893 [sender.py:send_request():396] send_request: defer
2023-07-10 18:30:11,637 INFO    SenderThread:16893 [sender.py:send_request_defer():598] handle sender defer: 0
2023-07-10 18:30:11,637 INFO    SenderThread:16893 [sender.py:transition_state():602] send defer: 1
2023-07-10 18:30:11,637 DEBUG   HandlerThread:16893 [handler.py:handle_request():144] handle_request: defer
2023-07-10 18:30:11,637 INFO    HandlerThread:16893 [handler.py:handle_request_defer():170] handle defer: 1
2023-07-10 18:30:11,637 DEBUG   SenderThread:16893 [sender.py:send_request():396] send_request: defer
2023-07-10 18:30:11,637 INFO    SenderThread:16893 [sender.py:send_request_defer():598] handle sender defer: 1
2023-07-10 18:30:11,637 INFO    SenderThread:16893 [sender.py:transition_state():602] send defer: 2
2023-07-10 18:30:11,637 DEBUG   HandlerThread:16893 [handler.py:handle_request():144] handle_request: defer
2023-07-10 18:30:11,637 INFO    HandlerThread:16893 [handler.py:handle_request_defer():170] handle defer: 2
2023-07-10 18:30:11,638 INFO    HandlerThread:16893 [system_monitor.py:finish():190] Stopping system monitor
2023-07-10 18:30:11,638 DEBUG   SystemMonitor:16893 [system_monitor.py:_start():159] Starting system metrics aggregation loop
2023-07-10 18:30:11,638 INFO    HandlerThread:16893 [interfaces.py:finish():202] Joined cpu monitor
2023-07-10 18:30:11,638 DEBUG   SystemMonitor:16893 [system_monitor.py:_start():166] Finished system metrics aggregation loop
2023-07-10 18:30:11,638 INFO    HandlerThread:16893 [interfaces.py:finish():202] Joined disk monitor
2023-07-10 18:30:11,638 DEBUG   SystemMonitor:16893 [system_monitor.py:_start():170] Publishing last batch of metrics
2023-07-10 18:30:11,679 INFO    HandlerThread:16893 [interfaces.py:finish():202] Joined gpu monitor
2023-07-10 18:30:11,679 INFO    HandlerThread:16893 [interfaces.py:finish():202] Joined memory monitor
2023-07-10 18:30:11,679 INFO    HandlerThread:16893 [interfaces.py:finish():202] Joined network monitor
2023-07-10 18:30:11,679 DEBUG   SenderThread:16893 [sender.py:send_request():396] send_request: defer
2023-07-10 18:30:11,679 INFO    SenderThread:16893 [sender.py:send_request_defer():598] handle sender defer: 2
2023-07-10 18:30:11,679 INFO    SenderThread:16893 [sender.py:transition_state():602] send defer: 3
2023-07-10 18:30:11,679 DEBUG   SenderThread:16893 [sender.py:send():369] send: stats
2023-07-10 18:30:11,680 DEBUG   HandlerThread:16893 [handler.py:handle_request():144] handle_request: defer
2023-07-10 18:30:11,680 INFO    HandlerThread:16893 [handler.py:handle_request_defer():170] handle defer: 3
2023-07-10 18:30:11,680 DEBUG   SenderThread:16893 [sender.py:send_request():396] send_request: defer
2023-07-10 18:30:11,680 INFO    SenderThread:16893 [sender.py:send_request_defer():598] handle sender defer: 3
2023-07-10 18:30:11,680 INFO    SenderThread:16893 [sender.py:transition_state():602] send defer: 4
2023-07-10 18:30:11,680 DEBUG   HandlerThread:16893 [handler.py:handle_request():144] handle_request: defer
2023-07-10 18:30:11,680 INFO    HandlerThread:16893 [handler.py:handle_request_defer():170] handle defer: 4
2023-07-10 18:30:11,680 DEBUG   SenderThread:16893 [sender.py:send_request():396] send_request: defer
2023-07-10 18:30:11,680 INFO    SenderThread:16893 [sender.py:send_request_defer():598] handle sender defer: 4
2023-07-10 18:30:11,680 INFO    SenderThread:16893 [sender.py:transition_state():602] send defer: 5
2023-07-10 18:30:11,680 DEBUG   HandlerThread:16893 [handler.py:handle_request():144] handle_request: defer
2023-07-10 18:30:11,680 INFO    HandlerThread:16893 [handler.py:handle_request_defer():170] handle defer: 5
2023-07-10 18:30:11,681 DEBUG   SenderThread:16893 [sender.py:send():369] send: summary
2023-07-10 18:30:11,681 INFO    SenderThread:16893 [sender.py:_save_file():1354] saving file wandb-summary.json with policy end
2023-07-10 18:30:11,681 DEBUG   SenderThread:16893 [sender.py:send_request():396] send_request: defer
2023-07-10 18:30:11,681 INFO    SenderThread:16893 [sender.py:send_request_defer():598] handle sender defer: 5
2023-07-10 18:30:11,681 INFO    SenderThread:16893 [sender.py:transition_state():602] send defer: 6
2023-07-10 18:30:11,681 DEBUG   HandlerThread:16893 [handler.py:handle_request():144] handle_request: defer
2023-07-10 18:30:11,681 INFO    HandlerThread:16893 [handler.py:handle_request_defer():170] handle defer: 6
2023-07-10 18:30:11,681 DEBUG   SenderThread:16893 [sender.py:send_request():396] send_request: defer
2023-07-10 18:30:11,681 INFO    SenderThread:16893 [sender.py:send_request_defer():598] handle sender defer: 6
2023-07-10 18:30:11,683 DEBUG   HandlerThread:16893 [handler.py:handle_request():144] handle_request: status_report
2023-07-10 18:30:12,013 INFO    SenderThread:16893 [sender.py:transition_state():602] send defer: 7
2023-07-10 18:30:12,013 DEBUG   HandlerThread:16893 [handler.py:handle_request():144] handle_request: defer
2023-07-10 18:30:12,013 INFO    HandlerThread:16893 [handler.py:handle_request_defer():170] handle defer: 7
2023-07-10 18:30:12,013 DEBUG   SenderThread:16893 [sender.py:send_request():396] send_request: defer
2023-07-10 18:30:12,013 INFO    SenderThread:16893 [sender.py:send_request_defer():598] handle sender defer: 7
2023-07-10 18:30:12,214 INFO    Thread-12 :16893 [dir_watcher.py:_on_file_modified():289] file/dir modified: /home/zhuhe/HPE-with-Diffusion/wandb/run-20230710_182958-eguvwkcw/files/wandb-summary.json
2023-07-10 18:30:12,215 INFO    Thread-12 :16893 [dir_watcher.py:_on_file_modified():289] file/dir modified: /home/zhuhe/HPE-with-Diffusion/wandb/run-20230710_182958-eguvwkcw/files/config.yaml
2023-07-10 18:30:12,637 DEBUG   HandlerThread:16893 [handler.py:handle_request():144] handle_request: poll_exit
2023-07-10 18:30:13,214 INFO    Thread-12 :16893 [dir_watcher.py:_on_file_modified():289] file/dir modified: /home/zhuhe/HPE-with-Diffusion/wandb/run-20230710_182958-eguvwkcw/files/output.log
2023-07-10 18:30:14,790 INFO    SenderThread:16893 [sender.py:transition_state():602] send defer: 8
2023-07-10 18:30:14,790 DEBUG   SenderThread:16893 [sender.py:send_request():396] send_request: poll_exit
2023-07-10 18:30:14,790 DEBUG   HandlerThread:16893 [handler.py:handle_request():144] handle_request: defer
2023-07-10 18:30:14,791 INFO    HandlerThread:16893 [handler.py:handle_request_defer():170] handle defer: 8
2023-07-10 18:30:14,791 DEBUG   SenderThread:16893 [sender.py:send_request():396] send_request: defer
2023-07-10 18:30:14,791 INFO    SenderThread:16893 [sender.py:send_request_defer():598] handle sender defer: 8
2023-07-10 18:30:14,791 INFO    SenderThread:16893 [job_builder.py:build():232] Attempting to build job artifact
2023-07-10 18:30:14,791 INFO    SenderThread:16893 [job_builder.py:build():266] no source found
2023-07-10 18:30:14,791 INFO    SenderThread:16893 [sender.py:transition_state():602] send defer: 9
2023-07-10 18:30:14,791 DEBUG   HandlerThread:16893 [handler.py:handle_request():144] handle_request: defer
2023-07-10 18:30:14,791 INFO    HandlerThread:16893 [handler.py:handle_request_defer():170] handle defer: 9
2023-07-10 18:30:14,791 DEBUG   SenderThread:16893 [sender.py:send_request():396] send_request: defer
2023-07-10 18:30:14,791 INFO    SenderThread:16893 [sender.py:send_request_defer():598] handle sender defer: 9
2023-07-10 18:30:14,791 INFO    SenderThread:16893 [dir_watcher.py:finish():359] shutting down directory watcher
2023-07-10 18:30:15,215 INFO    Thread-12 :16893 [dir_watcher.py:_on_file_modified():289] file/dir modified: /home/zhuhe/HPE-with-Diffusion/wandb/run-20230710_182958-eguvwkcw/files/output.log
2023-07-10 18:30:15,215 INFO    SenderThread:16893 [dir_watcher.py:finish():389] scan: /home/zhuhe/HPE-with-Diffusion/wandb/run-20230710_182958-eguvwkcw/files
2023-07-10 18:30:15,216 INFO    SenderThread:16893 [dir_watcher.py:finish():403] scan save: /home/zhuhe/HPE-with-Diffusion/wandb/run-20230710_182958-eguvwkcw/files/wandb-metadata.json wandb-metadata.json
2023-07-10 18:30:15,216 INFO    SenderThread:16893 [dir_watcher.py:finish():403] scan save: /home/zhuhe/HPE-with-Diffusion/wandb/run-20230710_182958-eguvwkcw/files/config.yaml config.yaml
2023-07-10 18:30:15,216 INFO    SenderThread:16893 [dir_watcher.py:finish():403] scan save: /home/zhuhe/HPE-with-Diffusion/wandb/run-20230710_182958-eguvwkcw/files/requirements.txt requirements.txt
2023-07-10 18:30:15,216 INFO    SenderThread:16893 [dir_watcher.py:finish():403] scan save: /home/zhuhe/HPE-with-Diffusion/wandb/run-20230710_182958-eguvwkcw/files/wandb-summary.json wandb-summary.json
2023-07-10 18:30:15,216 INFO    SenderThread:16893 [dir_watcher.py:finish():403] scan save: /home/zhuhe/HPE-with-Diffusion/wandb/run-20230710_182958-eguvwkcw/files/conda-environment.yaml conda-environment.yaml
2023-07-10 18:30:15,216 INFO    SenderThread:16893 [dir_watcher.py:finish():403] scan save: /home/zhuhe/HPE-with-Diffusion/wandb/run-20230710_182958-eguvwkcw/files/output.log output.log
2023-07-10 18:30:15,216 INFO    SenderThread:16893 [sender.py:transition_state():602] send defer: 10
2023-07-10 18:30:15,216 DEBUG   HandlerThread:16893 [handler.py:handle_request():144] handle_request: defer
2023-07-10 18:30:15,216 INFO    HandlerThread:16893 [handler.py:handle_request_defer():170] handle defer: 10
2023-07-10 18:30:15,216 DEBUG   SenderThread:16893 [sender.py:send_request():396] send_request: defer
2023-07-10 18:30:15,217 INFO    SenderThread:16893 [sender.py:send_request_defer():598] handle sender defer: 10
2023-07-10 18:30:15,217 INFO    SenderThread:16893 [file_pusher.py:finish():159] shutting down file pusher
2023-07-10 18:30:15,676 ERROR   wandb-upload_0:16893 [internal_api.py:upload_file():2192] upload_file exception https://storage.googleapis.com/wandb-production.appspot.com/ada4321/DiffHPE/eguvwkcw/wandb-summary.json?Expires=1689071415&GoogleAccessId=gorilla-files-url-signer-man%40wandb-production.iam.gserviceaccount.com&Signature=hTyTr0f5rBZflRZmlLN%2BRd8y%2BctPVknjcHqxk%2FK2zzT%2BzTZBP5qNPi8KOVAc4RPBINrpTPQiflJ4oBxuJ%2F7vUFZjVKmGDBMMa2hKWMjYdXjRB2E06qRRUZrRLaS3xnUCTZLzbaKJJQeRPE77CLx0ZYrwb6S5I2cyIEKscg8NJHwe2XZ4apjhdrwKNtN%2BV9ekXemtucQYXk5N33YssCxPB8V6Rn09KjAJaSy%2FeVesdT%2BIRZDIQkkLZEGC1sYs8pU9Tekzx7%2FPZ9GOvXbE9T%2B%2F0QCICDzSSOs2w9y7J%2FhWYiwodb2rfxIMZXlNer3C%2B8u4oZtSmVbYcysowdMv3aGcIw%3D%3D: 404 Client Error: Not Found for url: https://storage.googleapis.com/wandb-production.appspot.com/ada4321/DiffHPE/eguvwkcw/wandb-summary.json?Expires=1689071415&GoogleAccessId=gorilla-files-url-signer-man%40wandb-production.iam.gserviceaccount.com&Signature=hTyTr0f5rBZflRZmlLN%2BRd8y%2BctPVknjcHqxk%2FK2zzT%2BzTZBP5qNPi8KOVAc4RPBINrpTPQiflJ4oBxuJ%2F7vUFZjVKmGDBMMa2hKWMjYdXjRB2E06qRRUZrRLaS3xnUCTZLzbaKJJQeRPE77CLx0ZYrwb6S5I2cyIEKscg8NJHwe2XZ4apjhdrwKNtN%2BV9ekXemtucQYXk5N33YssCxPB8V6Rn09KjAJaSy%2FeVesdT%2BIRZDIQkkLZEGC1sYs8pU9Tekzx7%2FPZ9GOvXbE9T%2B%2F0QCICDzSSOs2w9y7J%2FhWYiwodb2rfxIMZXlNer3C%2B8u4oZtSmVbYcysowdMv3aGcIw%3D%3D
2023-07-10 18:30:15,676 ERROR   wandb-upload_0:16893 [internal_api.py:upload_file():2194] upload_file request headers: {'User-Agent': 'python-requests/2.31.0', 'Accept-Encoding': 'gzip, deflate', 'Accept': '*/*', 'Connection': 'keep-alive', 'Content-Length': '27'}
2023-07-10 18:30:15,676 ERROR   wandb-upload_0:16893 [internal_api.py:upload_file():2196] upload_file response body: b'<!DOCTYPE html>\n<html lang=en>\n  <meta charset=utf-8>\n  <meta name=viewport content="initial-scale=1, minimum-scale=1, width=device-width">\n  <title>Error 404 (Not Found)!!1</title>\n  <style>\n    *{margin:0;padding:0}html,code{font:15px/22px arial,sans-serif}html{background:#fff;color:#222;padding:15px}body{margin:7% auto 0;max-width:390px;min-height:180px;padding:30px 0 15px}* > body{background:url(//www.google.com/images/errors/robot.png) 100% 5px no-repeat;padding-right:205px}p{margin:11px 0 22px;overflow:hidden}ins{color:#777;text-decoration:none}a img{border:0}@media screen and (max-width:772px){body{background:none;margin-top:0;max-width:none;padding-right:0}}#logo{background:url(//www.google.com/images/branding/googlelogo/1x/googlelogo_color_150x54dp.png) no-repeat;margin-left:-5px}@media only screen and (min-resolution:192dpi){#logo{background:url(//www.google.com/images/branding/googlelogo/2x/googlelogo_color_150x54dp.png) no-repeat 0% 0%/100% 100%;-moz-border-image:url(//www.google.com/images/branding/googlelogo/2x/googlelogo_color_150x54dp.png) 0}}@media only screen and (-webkit-min-device-pixel-ratio:2){#logo{background:url(//www.google.com/images/branding/googlelogo/2x/googlelogo_color_150x54dp.png) no-repeat;-webkit-background-size:100% 100%}}#logo{display:inline-block;height:54px;width:150px}\n  </style>\n  <a href=//www.google.com/><span id=logo aria-label=Google></span></a>\n  <p><b>404.</b> <ins>That\xe2\x80\x99s an error.</ins>\n  <p>The requested URL <code>/wandb-production.appspot.com/ada4321/DiffHPE/eguvwkcw/wandb-summary.json</code> was not found on this server.  <ins>That\xe2\x80\x99s all we know.</ins>\n'
2023-07-10 18:30:15,687 ERROR   wandb-upload_1:16893 [internal_api.py:upload_file():2192] upload_file exception https://storage.googleapis.com/wandb-production.appspot.com/ada4321/DiffHPE/eguvwkcw/config.yaml?Expires=1689071415&GoogleAccessId=gorilla-files-url-signer-man%40wandb-production.iam.gserviceaccount.com&Signature=GiIE5lSz2LoJWHvTzAgT4pcCU4h%2BkvQ1eGpPe4mm%2B%2BeWw70mmd%2Blj3USR6REefSg5dEmEwFtjM%2FdA3B8ubBoSHQMcUMMWlJfD88UvvU1rPe2aqFeGaHYJ3JYgdfcWibVqtCidd%2FHYmZAjnOZ6A5T099EQw53Lefh0PnzvUJiJA0HamDLXEBIjohXjzLjSnAg7JwYA3fEnf2vmnA9XVkwa0zkaiUWyqAB7z3NT82FEMwhRD7z5Fti503gQPM2krR03TwUVg0h6x32Q4d1TTtMIXHWQ%2BK1mxa3ADLo2SMC7BO098D2DeekMDGUpfXzGIZ%2F1XMcIcnUFvbC5SIL0afW4w%3D%3D: 404 Client Error: Not Found for url: https://storage.googleapis.com/wandb-production.appspot.com/ada4321/DiffHPE/eguvwkcw/config.yaml?Expires=1689071415&GoogleAccessId=gorilla-files-url-signer-man%40wandb-production.iam.gserviceaccount.com&Signature=GiIE5lSz2LoJWHvTzAgT4pcCU4h%2BkvQ1eGpPe4mm%2B%2BeWw70mmd%2Blj3USR6REefSg5dEmEwFtjM%2FdA3B8ubBoSHQMcUMMWlJfD88UvvU1rPe2aqFeGaHYJ3JYgdfcWibVqtCidd%2FHYmZAjnOZ6A5T099EQw53Lefh0PnzvUJiJA0HamDLXEBIjohXjzLjSnAg7JwYA3fEnf2vmnA9XVkwa0zkaiUWyqAB7z3NT82FEMwhRD7z5Fti503gQPM2krR03TwUVg0h6x32Q4d1TTtMIXHWQ%2BK1mxa3ADLo2SMC7BO098D2DeekMDGUpfXzGIZ%2F1XMcIcnUFvbC5SIL0afW4w%3D%3D
2023-07-10 18:30:15,687 ERROR   wandb-upload_1:16893 [internal_api.py:upload_file():2194] upload_file request headers: {'User-Agent': 'python-requests/2.31.0', 'Accept-Encoding': 'gzip, deflate', 'Accept': '*/*', 'Connection': 'keep-alive', 'Content-Length': '525'}
2023-07-10 18:30:15,687 ERROR   wandb-upload_1:16893 [internal_api.py:upload_file():2196] upload_file response body: b'<!DOCTYPE html>\n<html lang=en>\n  <meta charset=utf-8>\n  <meta name=viewport content="initial-scale=1, minimum-scale=1, width=device-width">\n  <title>Error 404 (Not Found)!!1</title>\n  <style>\n    *{margin:0;padding:0}html,code{font:15px/22px arial,sans-serif}html{background:#fff;color:#222;padding:15px}body{margin:7% auto 0;max-width:390px;min-height:180px;padding:30px 0 15px}* > body{background:url(//www.google.com/images/errors/robot.png) 100% 5px no-repeat;padding-right:205px}p{margin:11px 0 22px;overflow:hidden}ins{color:#777;text-decoration:none}a img{border:0}@media screen and (max-width:772px){body{background:none;margin-top:0;max-width:none;padding-right:0}}#logo{background:url(//www.google.com/images/branding/googlelogo/1x/googlelogo_color_150x54dp.png) no-repeat;margin-left:-5px}@media only screen and (min-resolution:192dpi){#logo{background:url(//www.google.com/images/branding/googlelogo/2x/googlelogo_color_150x54dp.png) no-repeat 0% 0%/100% 100%;-moz-border-image:url(//www.google.com/images/branding/googlelogo/2x/googlelogo_color_150x54dp.png) 0}}@media only screen and (-webkit-min-device-pixel-ratio:2){#logo{background:url(//www.google.com/images/branding/googlelogo/2x/googlelogo_color_150x54dp.png) no-repeat;-webkit-background-size:100% 100%}}#logo{display:inline-block;height:54px;width:150px}\n  </style>\n  <a href=//www.google.com/><span id=logo aria-label=Google></span></a>\n  <p><b>404.</b> <ins>That\xe2\x80\x99s an error.</ins>\n  <p>The requested URL <code>/wandb-production.appspot.com/ada4321/DiffHPE/eguvwkcw/config.yaml</code> was not found on this server.  <ins>That\xe2\x80\x99s all we know.</ins>\n'
2023-07-10 18:30:16,025 ERROR   wandb-upload_2:16893 [internal_api.py:upload_file():2192] upload_file exception https://storage.googleapis.com/wandb-production.appspot.com/ada4321/DiffHPE/eguvwkcw/requirements.txt?Expires=1689071415&GoogleAccessId=gorilla-files-url-signer-man%40wandb-production.iam.gserviceaccount.com&Signature=LIKqGS%2BrutnqfCwaKHFLWVxevLzs78meHoLNHz0bAqd9wV2IxpVN8BTCFrzM1mbjt%2Ft8epQ74pN0oQg0XyDwTe%2BcqPUAhmk9hWltNeWKFICmbCmUEjfwiZSlmbdQkyO84queGJxWESvTRWpeijzmz8nLn2zvFmMd3KxyAXZg3Ma6nb3bhcGw3Tr9pcDrQaU5rMJMQD8F458T4kuc88WPzVrx%2FfhW9l7s6t94ubCU0OhYFFpuL08ZLLv2sN%2BEhvgEXjQUMiY14yq%2FzP1uHfHDPtGpiz6TXpjIWEoIaDCRkgfKnTR2TUCyAfN0O6Z%2BwGQaikAmS%2BbiHGkAyTM%2Bf8fMeQ%3D%3D: 404 Client Error: Not Found for url: https://storage.googleapis.com/wandb-production.appspot.com/ada4321/DiffHPE/eguvwkcw/requirements.txt?Expires=1689071415&GoogleAccessId=gorilla-files-url-signer-man%40wandb-production.iam.gserviceaccount.com&Signature=LIKqGS%2BrutnqfCwaKHFLWVxevLzs78meHoLNHz0bAqd9wV2IxpVN8BTCFrzM1mbjt%2Ft8epQ74pN0oQg0XyDwTe%2BcqPUAhmk9hWltNeWKFICmbCmUEjfwiZSlmbdQkyO84queGJxWESvTRWpeijzmz8nLn2zvFmMd3KxyAXZg3Ma6nb3bhcGw3Tr9pcDrQaU5rMJMQD8F458T4kuc88WPzVrx%2FfhW9l7s6t94ubCU0OhYFFpuL08ZLLv2sN%2BEhvgEXjQUMiY14yq%2FzP1uHfHDPtGpiz6TXpjIWEoIaDCRkgfKnTR2TUCyAfN0O6Z%2BwGQaikAmS%2BbiHGkAyTM%2Bf8fMeQ%3D%3D
2023-07-10 18:30:16,025 ERROR   wandb-upload_2:16893 [internal_api.py:upload_file():2194] upload_file request headers: {'User-Agent': 'python-requests/2.31.0', 'Accept-Encoding': 'gzip, deflate', 'Accept': '*/*', 'Connection': 'keep-alive', 'Content-Length': '926'}
2023-07-10 18:30:16,025 ERROR   wandb-upload_2:16893 [internal_api.py:upload_file():2196] upload_file response body: b'<!DOCTYPE html>\n<html lang=en>\n  <meta charset=utf-8>\n  <meta name=viewport content="initial-scale=1, minimum-scale=1, width=device-width">\n  <title>Error 404 (Not Found)!!1</title>\n  <style>\n    *{margin:0;padding:0}html,code{font:15px/22px arial,sans-serif}html{background:#fff;color:#222;padding:15px}body{margin:7% auto 0;max-width:390px;min-height:180px;padding:30px 0 15px}* > body{background:url(//www.google.com/images/errors/robot.png) 100% 5px no-repeat;padding-right:205px}p{margin:11px 0 22px;overflow:hidden}ins{color:#777;text-decoration:none}a img{border:0}@media screen and (max-width:772px){body{background:none;margin-top:0;max-width:none;padding-right:0}}#logo{background:url(//www.google.com/images/branding/googlelogo/1x/googlelogo_color_150x54dp.png) no-repeat;margin-left:-5px}@media only screen and (min-resolution:192dpi){#logo{background:url(//www.google.com/images/branding/googlelogo/2x/googlelogo_color_150x54dp.png) no-repeat 0% 0%/100% 100%;-moz-border-image:url(//www.google.com/images/branding/googlelogo/2x/googlelogo_color_150x54dp.png) 0}}@media only screen and (-webkit-min-device-pixel-ratio:2){#logo{background:url(//www.google.com/images/branding/googlelogo/2x/googlelogo_color_150x54dp.png) no-repeat;-webkit-background-size:100% 100%}}#logo{display:inline-block;height:54px;width:150px}\n  </style>\n  <a href=//www.google.com/><span id=logo aria-label=Google></span></a>\n  <p><b>404.</b> <ins>That\xe2\x80\x99s an error.</ins>\n  <p>The requested URL <code>/wandb-production.appspot.com/ada4321/DiffHPE/eguvwkcw/requirements.txt</code> was not found on this server.  <ins>That\xe2\x80\x99s all we know.</ins>\n'
2023-07-10 18:30:16,060 ERROR   wandb-upload_3:16893 [internal_api.py:upload_file():2192] upload_file exception https://storage.googleapis.com/wandb-production.appspot.com/ada4321/DiffHPE/eguvwkcw/conda-environment.yaml?Expires=1689071415&GoogleAccessId=gorilla-files-url-signer-man%40wandb-production.iam.gserviceaccount.com&Signature=K7xFpxu42oi94jkoRJXCHh5gGVgX3iexKDk0IzUUsAspc%2BVElhdT63W3XhXzpyzVgBBZRmnL43O8LXG6rs%2BrExu%2B66WbWbGcjjlGK0iX%2BJA959jvkBZfg2exBJfJ9WqGCcOPplaMcN12CZ8MZsrSBFJp%2FGQRYN8V29XBslJa6vT5rkVsxVOqaKAQbyBiDWTTcbE%2FdWxvQ42%2FyXUvcJf7NKrXEIIHlowp7a97dO48wJqHuLmtemaU8Pdw6FilWx0EsWjcMRzg91fol36w5nL6H3IHki%2F4WWxxbgohTRli6J08xTsZhAYSF59CoTXIRwB3YocaiiTqCe00%2FM3FamYYxA%3D%3D: 404 Client Error: Not Found for url: https://storage.googleapis.com/wandb-production.appspot.com/ada4321/DiffHPE/eguvwkcw/conda-environment.yaml?Expires=1689071415&GoogleAccessId=gorilla-files-url-signer-man%40wandb-production.iam.gserviceaccount.com&Signature=K7xFpxu42oi94jkoRJXCHh5gGVgX3iexKDk0IzUUsAspc%2BVElhdT63W3XhXzpyzVgBBZRmnL43O8LXG6rs%2BrExu%2B66WbWbGcjjlGK0iX%2BJA959jvkBZfg2exBJfJ9WqGCcOPplaMcN12CZ8MZsrSBFJp%2FGQRYN8V29XBslJa6vT5rkVsxVOqaKAQbyBiDWTTcbE%2FdWxvQ42%2FyXUvcJf7NKrXEIIHlowp7a97dO48wJqHuLmtemaU8Pdw6FilWx0EsWjcMRzg91fol36w5nL6H3IHki%2F4WWxxbgohTRli6J08xTsZhAYSF59CoTXIRwB3YocaiiTqCe00%2FM3FamYYxA%3D%3D
2023-07-10 18:30:16,060 ERROR   wandb-upload_3:16893 [internal_api.py:upload_file():2194] upload_file request headers: {'User-Agent': 'python-requests/2.31.0', 'Accept-Encoding': 'gzip, deflate', 'Accept': '*/*', 'Connection': 'keep-alive', 'Content-Length': '1925'}
2023-07-10 18:30:16,060 ERROR   wandb-upload_3:16893 [internal_api.py:upload_file():2196] upload_file response body: b'<!DOCTYPE html>\n<html lang=en>\n  <meta charset=utf-8>\n  <meta name=viewport content="initial-scale=1, minimum-scale=1, width=device-width">\n  <title>Error 404 (Not Found)!!1</title>\n  <style>\n    *{margin:0;padding:0}html,code{font:15px/22px arial,sans-serif}html{background:#fff;color:#222;padding:15px}body{margin:7% auto 0;max-width:390px;min-height:180px;padding:30px 0 15px}* > body{background:url(//www.google.com/images/errors/robot.png) 100% 5px no-repeat;padding-right:205px}p{margin:11px 0 22px;overflow:hidden}ins{color:#777;text-decoration:none}a img{border:0}@media screen and (max-width:772px){body{background:none;margin-top:0;max-width:none;padding-right:0}}#logo{background:url(//www.google.com/images/branding/googlelogo/1x/googlelogo_color_150x54dp.png) no-repeat;margin-left:-5px}@media only screen and (min-resolution:192dpi){#logo{background:url(//www.google.com/images/branding/googlelogo/2x/googlelogo_color_150x54dp.png) no-repeat 0% 0%/100% 100%;-moz-border-image:url(//www.google.com/images/branding/googlelogo/2x/googlelogo_color_150x54dp.png) 0}}@media only screen and (-webkit-min-device-pixel-ratio:2){#logo{background:url(//www.google.com/images/branding/googlelogo/2x/googlelogo_color_150x54dp.png) no-repeat;-webkit-background-size:100% 100%}}#logo{display:inline-block;height:54px;width:150px}\n  </style>\n  <a href=//www.google.com/><span id=logo aria-label=Google></span></a>\n  <p><b>404.</b> <ins>That\xe2\x80\x99s an error.</ins>\n  <p>The requested URL <code>/wandb-production.appspot.com/ada4321/DiffHPE/eguvwkcw/conda-environment.yaml</code> was not found on this server.  <ins>That\xe2\x80\x99s all we know.</ins>\n'
2023-07-10 18:30:16,069 ERROR   wandb-upload_4:16893 [internal_api.py:upload_file():2192] upload_file exception https://storage.googleapis.com/wandb-production.appspot.com/ada4321/DiffHPE/eguvwkcw/output.log?Expires=1689071415&GoogleAccessId=gorilla-files-url-signer-man%40wandb-production.iam.gserviceaccount.com&Signature=pVnEdWJDY650h0ONXLdo8DnD2bvIEsBy7pqMZEjXPefOsXDQqW2xgFpiKS6%2FXsT8GsJEokhmcQtrZOc14kvKv29P0NgPbCTNVU%2BFFYZYPNA9Y8dtd5mVwAmiKjJsdbFxFtjmyx5TM9UPVneGJqBmznkCnQLKqQmg%2BKU8tTO3kCk%2BeoxPYF9O259YwdX1lifgVmkKB%2BgrmdIJGFKmBqALM973btMfj6%2F7SCXBERLQSymupGsDBxqtJb%2FaFMMNOrpo3D1nxJZxmAzyj8oae4DpRrkdgxpVkzTaAfVPUaXGbLgB1Hm4iZd96%2F04nS2V3BynqMlbDrc6MyH14Klm9NN%2BAQ%3D%3D: 404 Client Error: Not Found for url: https://storage.googleapis.com/wandb-production.appspot.com/ada4321/DiffHPE/eguvwkcw/output.log?Expires=1689071415&GoogleAccessId=gorilla-files-url-signer-man%40wandb-production.iam.gserviceaccount.com&Signature=pVnEdWJDY650h0ONXLdo8DnD2bvIEsBy7pqMZEjXPefOsXDQqW2xgFpiKS6%2FXsT8GsJEokhmcQtrZOc14kvKv29P0NgPbCTNVU%2BFFYZYPNA9Y8dtd5mVwAmiKjJsdbFxFtjmyx5TM9UPVneGJqBmznkCnQLKqQmg%2BKU8tTO3kCk%2BeoxPYF9O259YwdX1lifgVmkKB%2BgrmdIJGFKmBqALM973btMfj6%2F7SCXBERLQSymupGsDBxqtJb%2FaFMMNOrpo3D1nxJZxmAzyj8oae4DpRrkdgxpVkzTaAfVPUaXGbLgB1Hm4iZd96%2F04nS2V3BynqMlbDrc6MyH14Klm9NN%2BAQ%3D%3D
2023-07-10 18:30:16,069 ERROR   wandb-upload_4:16893 [internal_api.py:upload_file():2194] upload_file request headers: {'User-Agent': 'python-requests/2.31.0', 'Accept-Encoding': 'gzip, deflate', 'Accept': '*/*', 'Connection': 'keep-alive', 'Content-Length': '27216'}
2023-07-10 18:30:16,069 ERROR   wandb-upload_4:16893 [internal_api.py:upload_file():2196] upload_file response body: b'<!DOCTYPE html>\n<html lang=en>\n  <meta charset=utf-8>\n  <meta name=viewport content="initial-scale=1, minimum-scale=1, width=device-width">\n  <title>Error 404 (Not Found)!!1</title>\n  <style>\n    *{margin:0;padding:0}html,code{font:15px/22px arial,sans-serif}html{background:#fff;color:#222;padding:15px}body{margin:7% auto 0;max-width:390px;min-height:180px;padding:30px 0 15px}* > body{background:url(//www.google.com/images/errors/robot.png) 100% 5px no-repeat;padding-right:205px}p{margin:11px 0 22px;overflow:hidden}ins{color:#777;text-decoration:none}a img{border:0}@media screen and (max-width:772px){body{background:none;margin-top:0;max-width:none;padding-right:0}}#logo{background:url(//www.google.com/images/branding/googlelogo/1x/googlelogo_color_150x54dp.png) no-repeat;margin-left:-5px}@media only screen and (min-resolution:192dpi){#logo{background:url(//www.google.com/images/branding/googlelogo/2x/googlelogo_color_150x54dp.png) no-repeat 0% 0%/100% 100%;-moz-border-image:url(//www.google.com/images/branding/googlelogo/2x/googlelogo_color_150x54dp.png) 0}}@media only screen and (-webkit-min-device-pixel-ratio:2){#logo{background:url(//www.google.com/images/branding/googlelogo/2x/googlelogo_color_150x54dp.png) no-repeat;-webkit-background-size:100% 100%}}#logo{display:inline-block;height:54px;width:150px}\n  </style>\n  <a href=//www.google.com/><span id=logo aria-label=Google></span></a>\n  <p><b>404.</b> <ins>That\xe2\x80\x99s an error.</ins>\n  <p>The requested URL <code>/wandb-production.appspot.com/ada4321/DiffHPE/eguvwkcw/output.log</code> was not found on this server.  <ins>That\xe2\x80\x99s all we know.</ins>\n'
2023-07-10 18:30:16,737 ERROR   wandb-upload_0:16893 [upload_job.py:push():136] Failed to upload file: /home/zhuhe/HPE-with-Diffusion/wandb/run-20230710_182958-eguvwkcw/files/wandb-summary.json
Traceback (most recent call last):
  File "/home/zhuhe/.conda/envs/diffhpe/lib/python3.9/site-packages/wandb/apis/normalize.py", line 41, in wrapper
    return func(*args, **kwargs)
  File "/home/zhuhe/.conda/envs/diffhpe/lib/python3.9/site-packages/wandb/sdk/lib/retry.py", line 212, in wrapped_fn
    return retrier(*args, **kargs)
  File "/home/zhuhe/.conda/envs/diffhpe/lib/python3.9/site-packages/wandb/sdk/lib/retry.py", line 131, in __call__
    result = self._call_fn(*args, **kwargs)
  File "/home/zhuhe/.conda/envs/diffhpe/lib/python3.9/site-packages/wandb/sdk/internal/internal_api.py", line 2218, in upload_file
    wandb._sentry.reraise(e)
  File "/home/zhuhe/.conda/envs/diffhpe/lib/python3.9/site-packages/wandb/analytics/sentry.py", line 146, in reraise
    raise exc.with_traceback(sys.exc_info()[2])
  File "/home/zhuhe/.conda/envs/diffhpe/lib/python3.9/site-packages/wandb/sdk/internal/internal_api.py", line 2190, in upload_file
    response.raise_for_status()
  File "/home/zhuhe/.conda/envs/diffhpe/lib/python3.9/site-packages/requests/models.py", line 1021, in raise_for_status
    raise HTTPError(http_error_msg, response=self)
requests.exceptions.HTTPError: 404 Client Error: Not Found for url: https://storage.googleapis.com/wandb-production.appspot.com/ada4321/DiffHPE/eguvwkcw/wandb-summary.json?Expires=1689071415&GoogleAccessId=gorilla-files-url-signer-man%40wandb-production.iam.gserviceaccount.com&Signature=hTyTr0f5rBZflRZmlLN%2BRd8y%2BctPVknjcHqxk%2FK2zzT%2BzTZBP5qNPi8KOVAc4RPBINrpTPQiflJ4oBxuJ%2F7vUFZjVKmGDBMMa2hKWMjYdXjRB2E06qRRUZrRLaS3xnUCTZLzbaKJJQeRPE77CLx0ZYrwb6S5I2cyIEKscg8NJHwe2XZ4apjhdrwKNtN%2BV9ekXemtucQYXk5N33YssCxPB8V6Rn09KjAJaSy%2FeVesdT%2BIRZDIQkkLZEGC1sYs8pU9Tekzx7%2FPZ9GOvXbE9T%2B%2F0QCICDzSSOs2w9y7J%2FhWYiwodb2rfxIMZXlNer3C%2B8u4oZtSmVbYcysowdMv3aGcIw%3D%3D

During handling of the above exception, another exception occurred:

Traceback (most recent call last):
  File "/home/zhuhe/.conda/envs/diffhpe/lib/python3.9/site-packages/wandb/filesync/upload_job.py", line 127, in push
    self._api.upload_file_retry(
  File "/home/zhuhe/.conda/envs/diffhpe/lib/python3.9/site-packages/wandb/apis/normalize.py", line 51, in wrapper
    raise CommError(message, error)
wandb.errors.CommError: <Response [404]>
2023-07-10 18:30:16,737 ERROR   wandb-upload_1:16893 [upload_job.py:push():136] Failed to upload file: /home/zhuhe/HPE-with-Diffusion/wandb/run-20230710_182958-eguvwkcw/files/config.yaml
Traceback (most recent call last):
  File "/home/zhuhe/.conda/envs/diffhpe/lib/python3.9/site-packages/wandb/apis/normalize.py", line 41, in wrapper
    return func(*args, **kwargs)
  File "/home/zhuhe/.conda/envs/diffhpe/lib/python3.9/site-packages/wandb/sdk/lib/retry.py", line 212, in wrapped_fn
    return retrier(*args, **kargs)
  File "/home/zhuhe/.conda/envs/diffhpe/lib/python3.9/site-packages/wandb/sdk/lib/retry.py", line 131, in __call__
    result = self._call_fn(*args, **kwargs)
  File "/home/zhuhe/.conda/envs/diffhpe/lib/python3.9/site-packages/wandb/sdk/internal/internal_api.py", line 2218, in upload_file
    wandb._sentry.reraise(e)
  File "/home/zhuhe/.conda/envs/diffhpe/lib/python3.9/site-packages/wandb/analytics/sentry.py", line 146, in reraise
    raise exc.with_traceback(sys.exc_info()[2])
  File "/home/zhuhe/.conda/envs/diffhpe/lib/python3.9/site-packages/wandb/sdk/internal/internal_api.py", line 2190, in upload_file
    response.raise_for_status()
  File "/home/zhuhe/.conda/envs/diffhpe/lib/python3.9/site-packages/requests/models.py", line 1021, in raise_for_status
    raise HTTPError(http_error_msg, response=self)
requests.exceptions.HTTPError: 404 Client Error: Not Found for url: https://storage.googleapis.com/wandb-production.appspot.com/ada4321/DiffHPE/eguvwkcw/config.yaml?Expires=1689071415&GoogleAccessId=gorilla-files-url-signer-man%40wandb-production.iam.gserviceaccount.com&Signature=GiIE5lSz2LoJWHvTzAgT4pcCU4h%2BkvQ1eGpPe4mm%2B%2BeWw70mmd%2Blj3USR6REefSg5dEmEwFtjM%2FdA3B8ubBoSHQMcUMMWlJfD88UvvU1rPe2aqFeGaHYJ3JYgdfcWibVqtCidd%2FHYmZAjnOZ6A5T099EQw53Lefh0PnzvUJiJA0HamDLXEBIjohXjzLjSnAg7JwYA3fEnf2vmnA9XVkwa0zkaiUWyqAB7z3NT82FEMwhRD7z5Fti503gQPM2krR03TwUVg0h6x32Q4d1TTtMIXHWQ%2BK1mxa3ADLo2SMC7BO098D2DeekMDGUpfXzGIZ%2F1XMcIcnUFvbC5SIL0afW4w%3D%3D

During handling of the above exception, another exception occurred:

Traceback (most recent call last):
  File "/home/zhuhe/.conda/envs/diffhpe/lib/python3.9/site-packages/wandb/filesync/upload_job.py", line 127, in push
    self._api.upload_file_retry(
  File "/home/zhuhe/.conda/envs/diffhpe/lib/python3.9/site-packages/wandb/apis/normalize.py", line 51, in wrapper
    raise CommError(message, error)
wandb.errors.CommError: <Response [404]>
2023-07-10 18:30:16,738 ERROR   wandb-upload_2:16893 [upload_job.py:push():136] Failed to upload file: /home/zhuhe/HPE-with-Diffusion/wandb/run-20230710_182958-eguvwkcw/files/requirements.txt
Traceback (most recent call last):
  File "/home/zhuhe/.conda/envs/diffhpe/lib/python3.9/site-packages/wandb/apis/normalize.py", line 41, in wrapper
    return func(*args, **kwargs)
  File "/home/zhuhe/.conda/envs/diffhpe/lib/python3.9/site-packages/wandb/sdk/lib/retry.py", line 212, in wrapped_fn
    return retrier(*args, **kargs)
  File "/home/zhuhe/.conda/envs/diffhpe/lib/python3.9/site-packages/wandb/sdk/lib/retry.py", line 131, in __call__
    result = self._call_fn(*args, **kwargs)
  File "/home/zhuhe/.conda/envs/diffhpe/lib/python3.9/site-packages/wandb/sdk/internal/internal_api.py", line 2218, in upload_file
    wandb._sentry.reraise(e)
  File "/home/zhuhe/.conda/envs/diffhpe/lib/python3.9/site-packages/wandb/analytics/sentry.py", line 146, in reraise
    raise exc.with_traceback(sys.exc_info()[2])
  File "/home/zhuhe/.conda/envs/diffhpe/lib/python3.9/site-packages/wandb/sdk/internal/internal_api.py", line 2190, in upload_file
    response.raise_for_status()
  File "/home/zhuhe/.conda/envs/diffhpe/lib/python3.9/site-packages/requests/models.py", line 1021, in raise_for_status
    raise HTTPError(http_error_msg, response=self)
requests.exceptions.HTTPError: 404 Client Error: Not Found for url: https://storage.googleapis.com/wandb-production.appspot.com/ada4321/DiffHPE/eguvwkcw/requirements.txt?Expires=1689071415&GoogleAccessId=gorilla-files-url-signer-man%40wandb-production.iam.gserviceaccount.com&Signature=LIKqGS%2BrutnqfCwaKHFLWVxevLzs78meHoLNHz0bAqd9wV2IxpVN8BTCFrzM1mbjt%2Ft8epQ74pN0oQg0XyDwTe%2BcqPUAhmk9hWltNeWKFICmbCmUEjfwiZSlmbdQkyO84queGJxWESvTRWpeijzmz8nLn2zvFmMd3KxyAXZg3Ma6nb3bhcGw3Tr9pcDrQaU5rMJMQD8F458T4kuc88WPzVrx%2FfhW9l7s6t94ubCU0OhYFFpuL08ZLLv2sN%2BEhvgEXjQUMiY14yq%2FzP1uHfHDPtGpiz6TXpjIWEoIaDCRkgfKnTR2TUCyAfN0O6Z%2BwGQaikAmS%2BbiHGkAyTM%2Bf8fMeQ%3D%3D

During handling of the above exception, another exception occurred:

Traceback (most recent call last):
  File "/home/zhuhe/.conda/envs/diffhpe/lib/python3.9/site-packages/wandb/filesync/upload_job.py", line 127, in push
    self._api.upload_file_retry(
  File "/home/zhuhe/.conda/envs/diffhpe/lib/python3.9/site-packages/wandb/apis/normalize.py", line 51, in wrapper
    raise CommError(message, error)
wandb.errors.CommError: <Response [404]>
2023-07-10 18:30:16,738 ERROR   wandb-upload_4:16893 [upload_job.py:push():136] Failed to upload file: /home/zhuhe/HPE-with-Diffusion/wandb/run-20230710_182958-eguvwkcw/files/output.log
Traceback (most recent call last):
  File "/home/zhuhe/.conda/envs/diffhpe/lib/python3.9/site-packages/wandb/apis/normalize.py", line 41, in wrapper
    return func(*args, **kwargs)
  File "/home/zhuhe/.conda/envs/diffhpe/lib/python3.9/site-packages/wandb/sdk/lib/retry.py", line 212, in wrapped_fn
    return retrier(*args, **kargs)
  File "/home/zhuhe/.conda/envs/diffhpe/lib/python3.9/site-packages/wandb/sdk/lib/retry.py", line 131, in __call__
    result = self._call_fn(*args, **kwargs)
  File "/home/zhuhe/.conda/envs/diffhpe/lib/python3.9/site-packages/wandb/sdk/internal/internal_api.py", line 2218, in upload_file
    wandb._sentry.reraise(e)
  File "/home/zhuhe/.conda/envs/diffhpe/lib/python3.9/site-packages/wandb/analytics/sentry.py", line 146, in reraise
    raise exc.with_traceback(sys.exc_info()[2])
  File "/home/zhuhe/.conda/envs/diffhpe/lib/python3.9/site-packages/wandb/sdk/internal/internal_api.py", line 2190, in upload_file
    response.raise_for_status()
  File "/home/zhuhe/.conda/envs/diffhpe/lib/python3.9/site-packages/requests/models.py", line 1021, in raise_for_status
    raise HTTPError(http_error_msg, response=self)
requests.exceptions.HTTPError: 404 Client Error: Not Found for url: https://storage.googleapis.com/wandb-production.appspot.com/ada4321/DiffHPE/eguvwkcw/output.log?Expires=1689071415&GoogleAccessId=gorilla-files-url-signer-man%40wandb-production.iam.gserviceaccount.com&Signature=pVnEdWJDY650h0ONXLdo8DnD2bvIEsBy7pqMZEjXPefOsXDQqW2xgFpiKS6%2FXsT8GsJEokhmcQtrZOc14kvKv29P0NgPbCTNVU%2BFFYZYPNA9Y8dtd5mVwAmiKjJsdbFxFtjmyx5TM9UPVneGJqBmznkCnQLKqQmg%2BKU8tTO3kCk%2BeoxPYF9O259YwdX1lifgVmkKB%2BgrmdIJGFKmBqALM973btMfj6%2F7SCXBERLQSymupGsDBxqtJb%2FaFMMNOrpo3D1nxJZxmAzyj8oae4DpRrkdgxpVkzTaAfVPUaXGbLgB1Hm4iZd96%2F04nS2V3BynqMlbDrc6MyH14Klm9NN%2BAQ%3D%3D

During handling of the above exception, another exception occurred:

Traceback (most recent call last):
  File "/home/zhuhe/.conda/envs/diffhpe/lib/python3.9/site-packages/wandb/filesync/upload_job.py", line 127, in push
    self._api.upload_file_retry(
  File "/home/zhuhe/.conda/envs/diffhpe/lib/python3.9/site-packages/wandb/apis/normalize.py", line 51, in wrapper
    raise CommError(message, error)
wandb.errors.CommError: <Response [404]>
2023-07-10 18:30:16,738 ERROR   wandb-upload_3:16893 [upload_job.py:push():136] Failed to upload file: /home/zhuhe/HPE-with-Diffusion/wandb/run-20230710_182958-eguvwkcw/files/conda-environment.yaml
Traceback (most recent call last):
  File "/home/zhuhe/.conda/envs/diffhpe/lib/python3.9/site-packages/wandb/apis/normalize.py", line 41, in wrapper
    return func(*args, **kwargs)
  File "/home/zhuhe/.conda/envs/diffhpe/lib/python3.9/site-packages/wandb/sdk/lib/retry.py", line 212, in wrapped_fn
    return retrier(*args, **kargs)
  File "/home/zhuhe/.conda/envs/diffhpe/lib/python3.9/site-packages/wandb/sdk/lib/retry.py", line 131, in __call__
    result = self._call_fn(*args, **kwargs)
  File "/home/zhuhe/.conda/envs/diffhpe/lib/python3.9/site-packages/wandb/sdk/internal/internal_api.py", line 2218, in upload_file
    wandb._sentry.reraise(e)
  File "/home/zhuhe/.conda/envs/diffhpe/lib/python3.9/site-packages/wandb/analytics/sentry.py", line 146, in reraise
    raise exc.with_traceback(sys.exc_info()[2])
  File "/home/zhuhe/.conda/envs/diffhpe/lib/python3.9/site-packages/wandb/sdk/internal/internal_api.py", line 2190, in upload_file
    response.raise_for_status()
  File "/home/zhuhe/.conda/envs/diffhpe/lib/python3.9/site-packages/requests/models.py", line 1021, in raise_for_status
    raise HTTPError(http_error_msg, response=self)
requests.exceptions.HTTPError: 404 Client Error: Not Found for url: https://storage.googleapis.com/wandb-production.appspot.com/ada4321/DiffHPE/eguvwkcw/conda-environment.yaml?Expires=1689071415&GoogleAccessId=gorilla-files-url-signer-man%40wandb-production.iam.gserviceaccount.com&Signature=K7xFpxu42oi94jkoRJXCHh5gGVgX3iexKDk0IzUUsAspc%2BVElhdT63W3XhXzpyzVgBBZRmnL43O8LXG6rs%2BrExu%2B66WbWbGcjjlGK0iX%2BJA959jvkBZfg2exBJfJ9WqGCcOPplaMcN12CZ8MZsrSBFJp%2FGQRYN8V29XBslJa6vT5rkVsxVOqaKAQbyBiDWTTcbE%2FdWxvQ42%2FyXUvcJf7NKrXEIIHlowp7a97dO48wJqHuLmtemaU8Pdw6FilWx0EsWjcMRzg91fol36w5nL6H3IHki%2F4WWxxbgohTRli6J08xTsZhAYSF59CoTXIRwB3YocaiiTqCe00%2FM3FamYYxA%3D%3D

During handling of the above exception, another exception occurred:

Traceback (most recent call last):
  File "/home/zhuhe/.conda/envs/diffhpe/lib/python3.9/site-packages/wandb/filesync/upload_job.py", line 127, in push
    self._api.upload_file_retry(
  File "/home/zhuhe/.conda/envs/diffhpe/lib/python3.9/site-packages/wandb/apis/normalize.py", line 51, in wrapper
    raise CommError(message, error)
wandb.errors.CommError: <Response [404]>
2023-07-10 18:30:17,638 DEBUG   HandlerThread:16893 [handler.py:handle_request():144] handle_request: keepalive
2023-07-10 18:30:17,803 ERROR   Thread-11 :16893 [step_upload.py:_handle_event():200] Failed to upload file: /home/zhuhe/HPE-with-Diffusion/wandb/run-20230710_182958-eguvwkcw/files/wandb-summary.json
Traceback (most recent call last):
  File "/home/zhuhe/.conda/envs/diffhpe/lib/python3.9/site-packages/wandb/apis/normalize.py", line 41, in wrapper
    return func(*args, **kwargs)
  File "/home/zhuhe/.conda/envs/diffhpe/lib/python3.9/site-packages/wandb/sdk/lib/retry.py", line 212, in wrapped_fn
    return retrier(*args, **kargs)
  File "/home/zhuhe/.conda/envs/diffhpe/lib/python3.9/site-packages/wandb/sdk/lib/retry.py", line 131, in __call__
    result = self._call_fn(*args, **kwargs)
  File "/home/zhuhe/.conda/envs/diffhpe/lib/python3.9/site-packages/wandb/sdk/internal/internal_api.py", line 2218, in upload_file
    wandb._sentry.reraise(e)
  File "/home/zhuhe/.conda/envs/diffhpe/lib/python3.9/site-packages/wandb/analytics/sentry.py", line 146, in reraise
    raise exc.with_traceback(sys.exc_info()[2])
  File "/home/zhuhe/.conda/envs/diffhpe/lib/python3.9/site-packages/wandb/sdk/internal/internal_api.py", line 2190, in upload_file
    response.raise_for_status()
  File "/home/zhuhe/.conda/envs/diffhpe/lib/python3.9/site-packages/requests/models.py", line 1021, in raise_for_status
    raise HTTPError(http_error_msg, response=self)
requests.exceptions.HTTPError: 404 Client Error: Not Found for url: https://storage.googleapis.com/wandb-production.appspot.com/ada4321/DiffHPE/eguvwkcw/wandb-summary.json?Expires=1689071415&GoogleAccessId=gorilla-files-url-signer-man%40wandb-production.iam.gserviceaccount.com&Signature=hTyTr0f5rBZflRZmlLN%2BRd8y%2BctPVknjcHqxk%2FK2zzT%2BzTZBP5qNPi8KOVAc4RPBINrpTPQiflJ4oBxuJ%2F7vUFZjVKmGDBMMa2hKWMjYdXjRB2E06qRRUZrRLaS3xnUCTZLzbaKJJQeRPE77CLx0ZYrwb6S5I2cyIEKscg8NJHwe2XZ4apjhdrwKNtN%2BV9ekXemtucQYXk5N33YssCxPB8V6Rn09KjAJaSy%2FeVesdT%2BIRZDIQkkLZEGC1sYs8pU9Tekzx7%2FPZ9GOvXbE9T%2B%2F0QCICDzSSOs2w9y7J%2FhWYiwodb2rfxIMZXlNer3C%2B8u4oZtSmVbYcysowdMv3aGcIw%3D%3D

During handling of the above exception, another exception occurred:

Traceback (most recent call last):
  File "/home/zhuhe/.conda/envs/diffhpe/lib/python3.9/concurrent/futures/thread.py", line 58, in run
    result = self.fn(*self.args, **self.kwargs)
  File "/home/zhuhe/.conda/envs/diffhpe/lib/python3.9/site-packages/wandb/filesync/step_upload.py", line 288, in run_and_notify
    self._do_upload_sync(event)
  File "/home/zhuhe/.conda/envs/diffhpe/lib/python3.9/site-packages/wandb/filesync/step_upload.py", line 330, in _do_upload_sync
    job.run()
  File "/home/zhuhe/.conda/envs/diffhpe/lib/python3.9/site-packages/wandb/filesync/upload_job.py", line 57, in run
    self.push()
  File "/home/zhuhe/.conda/envs/diffhpe/lib/python3.9/site-packages/wandb/filesync/upload_job.py", line 127, in push
    self._api.upload_file_retry(
  File "/home/zhuhe/.conda/envs/diffhpe/lib/python3.9/site-packages/wandb/apis/normalize.py", line 51, in wrapper
    raise CommError(message, error)
wandb.errors.CommError: <Response [404]>
2023-07-10 18:30:17,803 ERROR   Thread-11 :16893 [step_upload.py:_handle_event():200] Failed to upload file: /home/zhuhe/HPE-with-Diffusion/wandb/run-20230710_182958-eguvwkcw/files/requirements.txt
Traceback (most recent call last):
  File "/home/zhuhe/.conda/envs/diffhpe/lib/python3.9/site-packages/wandb/apis/normalize.py", line 41, in wrapper
    return func(*args, **kwargs)
  File "/home/zhuhe/.conda/envs/diffhpe/lib/python3.9/site-packages/wandb/sdk/lib/retry.py", line 212, in wrapped_fn
    return retrier(*args, **kargs)
  File "/home/zhuhe/.conda/envs/diffhpe/lib/python3.9/site-packages/wandb/sdk/lib/retry.py", line 131, in __call__
    result = self._call_fn(*args, **kwargs)
  File "/home/zhuhe/.conda/envs/diffhpe/lib/python3.9/site-packages/wandb/sdk/internal/internal_api.py", line 2218, in upload_file
    wandb._sentry.reraise(e)
  File "/home/zhuhe/.conda/envs/diffhpe/lib/python3.9/site-packages/wandb/analytics/sentry.py", line 146, in reraise
    raise exc.with_traceback(sys.exc_info()[2])
  File "/home/zhuhe/.conda/envs/diffhpe/lib/python3.9/site-packages/wandb/sdk/internal/internal_api.py", line 2190, in upload_file
    response.raise_for_status()
  File "/home/zhuhe/.conda/envs/diffhpe/lib/python3.9/site-packages/requests/models.py", line 1021, in raise_for_status
    raise HTTPError(http_error_msg, response=self)
requests.exceptions.HTTPError: 404 Client Error: Not Found for url: https://storage.googleapis.com/wandb-production.appspot.com/ada4321/DiffHPE/eguvwkcw/requirements.txt?Expires=1689071415&GoogleAccessId=gorilla-files-url-signer-man%40wandb-production.iam.gserviceaccount.com&Signature=LIKqGS%2BrutnqfCwaKHFLWVxevLzs78meHoLNHz0bAqd9wV2IxpVN8BTCFrzM1mbjt%2Ft8epQ74pN0oQg0XyDwTe%2BcqPUAhmk9hWltNeWKFICmbCmUEjfwiZSlmbdQkyO84queGJxWESvTRWpeijzmz8nLn2zvFmMd3KxyAXZg3Ma6nb3bhcGw3Tr9pcDrQaU5rMJMQD8F458T4kuc88WPzVrx%2FfhW9l7s6t94ubCU0OhYFFpuL08ZLLv2sN%2BEhvgEXjQUMiY14yq%2FzP1uHfHDPtGpiz6TXpjIWEoIaDCRkgfKnTR2TUCyAfN0O6Z%2BwGQaikAmS%2BbiHGkAyTM%2Bf8fMeQ%3D%3D

During handling of the above exception, another exception occurred:

Traceback (most recent call last):
  File "/home/zhuhe/.conda/envs/diffhpe/lib/python3.9/concurrent/futures/thread.py", line 58, in run
    result = self.fn(*self.args, **self.kwargs)
  File "/home/zhuhe/.conda/envs/diffhpe/lib/python3.9/site-packages/wandb/filesync/step_upload.py", line 288, in run_and_notify
    self._do_upload_sync(event)
  File "/home/zhuhe/.conda/envs/diffhpe/lib/python3.9/site-packages/wandb/filesync/step_upload.py", line 330, in _do_upload_sync
    job.run()
  File "/home/zhuhe/.conda/envs/diffhpe/lib/python3.9/site-packages/wandb/filesync/upload_job.py", line 57, in run
    self.push()
  File "/home/zhuhe/.conda/envs/diffhpe/lib/python3.9/site-packages/wandb/filesync/upload_job.py", line 127, in push
    self._api.upload_file_retry(
  File "/home/zhuhe/.conda/envs/diffhpe/lib/python3.9/site-packages/wandb/apis/normalize.py", line 51, in wrapper
    raise CommError(message, error)
wandb.errors.CommError: <Response [404]>
2023-07-10 18:30:17,804 ERROR   Thread-11 :16893 [step_upload.py:_handle_event():200] Failed to upload file: /home/zhuhe/HPE-with-Diffusion/wandb/run-20230710_182958-eguvwkcw/files/config.yaml
Traceback (most recent call last):
  File "/home/zhuhe/.conda/envs/diffhpe/lib/python3.9/site-packages/wandb/apis/normalize.py", line 41, in wrapper
    return func(*args, **kwargs)
  File "/home/zhuhe/.conda/envs/diffhpe/lib/python3.9/site-packages/wandb/sdk/lib/retry.py", line 212, in wrapped_fn
    return retrier(*args, **kargs)
  File "/home/zhuhe/.conda/envs/diffhpe/lib/python3.9/site-packages/wandb/sdk/lib/retry.py", line 131, in __call__
    result = self._call_fn(*args, **kwargs)
  File "/home/zhuhe/.conda/envs/diffhpe/lib/python3.9/site-packages/wandb/sdk/internal/internal_api.py", line 2218, in upload_file
    wandb._sentry.reraise(e)
  File "/home/zhuhe/.conda/envs/diffhpe/lib/python3.9/site-packages/wandb/analytics/sentry.py", line 146, in reraise
    raise exc.with_traceback(sys.exc_info()[2])
  File "/home/zhuhe/.conda/envs/diffhpe/lib/python3.9/site-packages/wandb/sdk/internal/internal_api.py", line 2190, in upload_file
    response.raise_for_status()
  File "/home/zhuhe/.conda/envs/diffhpe/lib/python3.9/site-packages/requests/models.py", line 1021, in raise_for_status
    raise HTTPError(http_error_msg, response=self)
requests.exceptions.HTTPError: 404 Client Error: Not Found for url: https://storage.googleapis.com/wandb-production.appspot.com/ada4321/DiffHPE/eguvwkcw/config.yaml?Expires=1689071415&GoogleAccessId=gorilla-files-url-signer-man%40wandb-production.iam.gserviceaccount.com&Signature=GiIE5lSz2LoJWHvTzAgT4pcCU4h%2BkvQ1eGpPe4mm%2B%2BeWw70mmd%2Blj3USR6REefSg5dEmEwFtjM%2FdA3B8ubBoSHQMcUMMWlJfD88UvvU1rPe2aqFeGaHYJ3JYgdfcWibVqtCidd%2FHYmZAjnOZ6A5T099EQw53Lefh0PnzvUJiJA0HamDLXEBIjohXjzLjSnAg7JwYA3fEnf2vmnA9XVkwa0zkaiUWyqAB7z3NT82FEMwhRD7z5Fti503gQPM2krR03TwUVg0h6x32Q4d1TTtMIXHWQ%2BK1mxa3ADLo2SMC7BO098D2DeekMDGUpfXzGIZ%2F1XMcIcnUFvbC5SIL0afW4w%3D%3D

During handling of the above exception, another exception occurred:

Traceback (most recent call last):
  File "/home/zhuhe/.conda/envs/diffhpe/lib/python3.9/concurrent/futures/thread.py", line 58, in run
    result = self.fn(*self.args, **self.kwargs)
  File "/home/zhuhe/.conda/envs/diffhpe/lib/python3.9/site-packages/wandb/filesync/step_upload.py", line 288, in run_and_notify
    self._do_upload_sync(event)
  File "/home/zhuhe/.conda/envs/diffhpe/lib/python3.9/site-packages/wandb/filesync/step_upload.py", line 330, in _do_upload_sync
    job.run()
  File "/home/zhuhe/.conda/envs/diffhpe/lib/python3.9/site-packages/wandb/filesync/upload_job.py", line 57, in run
    self.push()
  File "/home/zhuhe/.conda/envs/diffhpe/lib/python3.9/site-packages/wandb/filesync/upload_job.py", line 127, in push
    self._api.upload_file_retry(
  File "/home/zhuhe/.conda/envs/diffhpe/lib/python3.9/site-packages/wandb/apis/normalize.py", line 51, in wrapper
    raise CommError(message, error)
wandb.errors.CommError: <Response [404]>
2023-07-10 18:30:17,804 ERROR   Thread-11 :16893 [step_upload.py:_handle_event():200] Failed to upload file: /home/zhuhe/HPE-with-Diffusion/wandb/run-20230710_182958-eguvwkcw/files/output.log
Traceback (most recent call last):
  File "/home/zhuhe/.conda/envs/diffhpe/lib/python3.9/site-packages/wandb/apis/normalize.py", line 41, in wrapper
    return func(*args, **kwargs)
  File "/home/zhuhe/.conda/envs/diffhpe/lib/python3.9/site-packages/wandb/sdk/lib/retry.py", line 212, in wrapped_fn
    return retrier(*args, **kargs)
  File "/home/zhuhe/.conda/envs/diffhpe/lib/python3.9/site-packages/wandb/sdk/lib/retry.py", line 131, in __call__
    result = self._call_fn(*args, **kwargs)
  File "/home/zhuhe/.conda/envs/diffhpe/lib/python3.9/site-packages/wandb/sdk/internal/internal_api.py", line 2218, in upload_file
    wandb._sentry.reraise(e)
  File "/home/zhuhe/.conda/envs/diffhpe/lib/python3.9/site-packages/wandb/analytics/sentry.py", line 146, in reraise
    raise exc.with_traceback(sys.exc_info()[2])
  File "/home/zhuhe/.conda/envs/diffhpe/lib/python3.9/site-packages/wandb/sdk/internal/internal_api.py", line 2190, in upload_file
    response.raise_for_status()
  File "/home/zhuhe/.conda/envs/diffhpe/lib/python3.9/site-packages/requests/models.py", line 1021, in raise_for_status
    raise HTTPError(http_error_msg, response=self)
requests.exceptions.HTTPError: 404 Client Error: Not Found for url: https://storage.googleapis.com/wandb-production.appspot.com/ada4321/DiffHPE/eguvwkcw/output.log?Expires=1689071415&GoogleAccessId=gorilla-files-url-signer-man%40wandb-production.iam.gserviceaccount.com&Signature=pVnEdWJDY650h0ONXLdo8DnD2bvIEsBy7pqMZEjXPefOsXDQqW2xgFpiKS6%2FXsT8GsJEokhmcQtrZOc14kvKv29P0NgPbCTNVU%2BFFYZYPNA9Y8dtd5mVwAmiKjJsdbFxFtjmyx5TM9UPVneGJqBmznkCnQLKqQmg%2BKU8tTO3kCk%2BeoxPYF9O259YwdX1lifgVmkKB%2BgrmdIJGFKmBqALM973btMfj6%2F7SCXBERLQSymupGsDBxqtJb%2FaFMMNOrpo3D1nxJZxmAzyj8oae4DpRrkdgxpVkzTaAfVPUaXGbLgB1Hm4iZd96%2F04nS2V3BynqMlbDrc6MyH14Klm9NN%2BAQ%3D%3D

During handling of the above exception, another exception occurred:

Traceback (most recent call last):
  File "/home/zhuhe/.conda/envs/diffhpe/lib/python3.9/concurrent/futures/thread.py", line 58, in run
    result = self.fn(*self.args, **self.kwargs)
  File "/home/zhuhe/.conda/envs/diffhpe/lib/python3.9/site-packages/wandb/filesync/step_upload.py", line 288, in run_and_notify
    self._do_upload_sync(event)
  File "/home/zhuhe/.conda/envs/diffhpe/lib/python3.9/site-packages/wandb/filesync/step_upload.py", line 330, in _do_upload_sync
    job.run()
  File "/home/zhuhe/.conda/envs/diffhpe/lib/python3.9/site-packages/wandb/filesync/upload_job.py", line 57, in run
    self.push()
  File "/home/zhuhe/.conda/envs/diffhpe/lib/python3.9/site-packages/wandb/filesync/upload_job.py", line 127, in push
    self._api.upload_file_retry(
  File "/home/zhuhe/.conda/envs/diffhpe/lib/python3.9/site-packages/wandb/apis/normalize.py", line 51, in wrapper
    raise CommError(message, error)
wandb.errors.CommError: <Response [404]>
2023-07-10 18:30:17,804 ERROR   Thread-11 :16893 [step_upload.py:_handle_event():200] Failed to upload file: /home/zhuhe/HPE-with-Diffusion/wandb/run-20230710_182958-eguvwkcw/files/conda-environment.yaml
Traceback (most recent call last):
  File "/home/zhuhe/.conda/envs/diffhpe/lib/python3.9/site-packages/wandb/apis/normalize.py", line 41, in wrapper
    return func(*args, **kwargs)
  File "/home/zhuhe/.conda/envs/diffhpe/lib/python3.9/site-packages/wandb/sdk/lib/retry.py", line 212, in wrapped_fn
    return retrier(*args, **kargs)
  File "/home/zhuhe/.conda/envs/diffhpe/lib/python3.9/site-packages/wandb/sdk/lib/retry.py", line 131, in __call__
    result = self._call_fn(*args, **kwargs)
  File "/home/zhuhe/.conda/envs/diffhpe/lib/python3.9/site-packages/wandb/sdk/internal/internal_api.py", line 2218, in upload_file
    wandb._sentry.reraise(e)
  File "/home/zhuhe/.conda/envs/diffhpe/lib/python3.9/site-packages/wandb/analytics/sentry.py", line 146, in reraise
    raise exc.with_traceback(sys.exc_info()[2])
  File "/home/zhuhe/.conda/envs/diffhpe/lib/python3.9/site-packages/wandb/sdk/internal/internal_api.py", line 2190, in upload_file
    response.raise_for_status()
  File "/home/zhuhe/.conda/envs/diffhpe/lib/python3.9/site-packages/requests/models.py", line 1021, in raise_for_status
    raise HTTPError(http_error_msg, response=self)
requests.exceptions.HTTPError: 404 Client Error: Not Found for url: https://storage.googleapis.com/wandb-production.appspot.com/ada4321/DiffHPE/eguvwkcw/conda-environment.yaml?Expires=1689071415&GoogleAccessId=gorilla-files-url-signer-man%40wandb-production.iam.gserviceaccount.com&Signature=K7xFpxu42oi94jkoRJXCHh5gGVgX3iexKDk0IzUUsAspc%2BVElhdT63W3XhXzpyzVgBBZRmnL43O8LXG6rs%2BrExu%2B66WbWbGcjjlGK0iX%2BJA959jvkBZfg2exBJfJ9WqGCcOPplaMcN12CZ8MZsrSBFJp%2FGQRYN8V29XBslJa6vT5rkVsxVOqaKAQbyBiDWTTcbE%2FdWxvQ42%2FyXUvcJf7NKrXEIIHlowp7a97dO48wJqHuLmtemaU8Pdw6FilWx0EsWjcMRzg91fol36w5nL6H3IHki%2F4WWxxbgohTRli6J08xTsZhAYSF59CoTXIRwB3YocaiiTqCe00%2FM3FamYYxA%3D%3D

During handling of the above exception, another exception occurred:

Traceback (most recent call last):
  File "/home/zhuhe/.conda/envs/diffhpe/lib/python3.9/concurrent/futures/thread.py", line 58, in run
    result = self.fn(*self.args, **self.kwargs)
  File "/home/zhuhe/.conda/envs/diffhpe/lib/python3.9/site-packages/wandb/filesync/step_upload.py", line 288, in run_and_notify
    self._do_upload_sync(event)
  File "/home/zhuhe/.conda/envs/diffhpe/lib/python3.9/site-packages/wandb/filesync/step_upload.py", line 330, in _do_upload_sync
    job.run()
  File "/home/zhuhe/.conda/envs/diffhpe/lib/python3.9/site-packages/wandb/filesync/upload_job.py", line 57, in run
    self.push()
  File "/home/zhuhe/.conda/envs/diffhpe/lib/python3.9/site-packages/wandb/filesync/upload_job.py", line 127, in push
    self._api.upload_file_retry(
  File "/home/zhuhe/.conda/envs/diffhpe/lib/python3.9/site-packages/wandb/apis/normalize.py", line 51, in wrapper
    raise CommError(message, error)
wandb.errors.CommError: <Response [404]>
2023-07-10 18:30:18,005 INFO    Thread-11 :16893 [sender.py:transition_state():602] send defer: 11
2023-07-10 18:30:18,005 DEBUG   HandlerThread:16893 [handler.py:handle_request():144] handle_request: defer
2023-07-10 18:30:18,005 INFO    HandlerThread:16893 [handler.py:handle_request_defer():170] handle defer: 11
2023-07-10 18:30:18,005 DEBUG   SenderThread:16893 [sender.py:send_request():396] send_request: defer
2023-07-10 18:30:18,005 INFO    SenderThread:16893 [sender.py:send_request_defer():598] handle sender defer: 11
2023-07-10 18:30:18,005 INFO    SenderThread:16893 [file_pusher.py:join():164] waiting for file pusher
2023-07-10 18:30:18,005 INFO    SenderThread:16893 [sender.py:transition_state():602] send defer: 12
2023-07-10 18:30:18,006 DEBUG   HandlerThread:16893 [handler.py:handle_request():144] handle_request: defer
2023-07-10 18:30:18,006 INFO    HandlerThread:16893 [handler.py:handle_request_defer():170] handle defer: 12
2023-07-10 18:30:18,006 DEBUG   SenderThread:16893 [sender.py:send_request():396] send_request: defer
2023-07-10 18:30:18,006 INFO    SenderThread:16893 [sender.py:send_request_defer():598] handle sender defer: 12
2023-07-10 18:30:18,291 INFO    SenderThread:16893 [sender.py:transition_state():602] send defer: 13
2023-07-10 18:30:18,292 DEBUG   HandlerThread:16893 [handler.py:handle_request():144] handle_request: defer
2023-07-10 18:30:18,292 INFO    HandlerThread:16893 [handler.py:handle_request_defer():170] handle defer: 13
2023-07-10 18:30:18,292 DEBUG   SenderThread:16893 [sender.py:send_request():396] send_request: defer
2023-07-10 18:30:18,292 INFO    SenderThread:16893 [sender.py:send_request_defer():598] handle sender defer: 13
2023-07-10 18:30:18,292 INFO    SenderThread:16893 [sender.py:transition_state():602] send defer: 14
2023-07-10 18:30:18,292 DEBUG   HandlerThread:16893 [handler.py:handle_request():144] handle_request: defer
2023-07-10 18:30:18,292 INFO    HandlerThread:16893 [handler.py:handle_request_defer():170] handle defer: 14
2023-07-10 18:30:18,292 DEBUG   SenderThread:16893 [sender.py:send():369] send: final
2023-07-10 18:30:18,292 DEBUG   SenderThread:16893 [sender.py:send():369] send: footer
2023-07-10 18:30:18,292 DEBUG   SenderThread:16893 [sender.py:send_request():396] send_request: defer
2023-07-10 18:30:18,292 INFO    SenderThread:16893 [sender.py:send_request_defer():598] handle sender defer: 14
2023-07-10 18:30:18,293 DEBUG   HandlerThread:16893 [handler.py:handle_request():144] handle_request: poll_exit
2023-07-10 18:30:18,293 DEBUG   HandlerThread:16893 [handler.py:handle_request():144] handle_request: server_info
2023-07-10 18:30:18,293 DEBUG   HandlerThread:16893 [handler.py:handle_request():144] handle_request: get_summary
2023-07-10 18:30:18,293 DEBUG   HandlerThread:16893 [handler.py:handle_request():144] handle_request: sampled_history
2023-07-10 18:30:18,293 DEBUG   SenderThread:16893 [sender.py:send_request():396] send_request: poll_exit
2023-07-10 18:30:18,293 DEBUG   SenderThread:16893 [sender.py:send_request():396] send_request: server_info
2023-07-10 18:30:18,735 INFO    MainThread:16893 [wandb_run.py:_footer_history_summary_info():3467] rendering history
2023-07-10 18:30:18,735 INFO    MainThread:16893 [wandb_run.py:_footer_history_summary_info():3499] rendering summary
2023-07-10 18:30:18,735 INFO    MainThread:16893 [wandb_run.py:_footer_sync_info():3426] logging synced files
2023-07-10 18:30:18,736 DEBUG   HandlerThread:16893 [handler.py:handle_request():144] handle_request: shutdown
2023-07-10 18:30:18,736 INFO    HandlerThread:16893 [handler.py:finish():854] shutting down handler
2023-07-10 18:30:19,293 INFO    WriterThread:16893 [datastore.py:close():298] close: /home/zhuhe/HPE-with-Diffusion/wandb/run-20230710_182958-eguvwkcw/run-eguvwkcw.wandb
2023-07-10 18:30:19,735 INFO    SenderThread:16893 [sender.py:finish():1526] shutting down sender
2023-07-10 18:30:19,735 INFO    SenderThread:16893 [file_pusher.py:finish():159] shutting down file pusher
2023-07-10 18:30:19,735 INFO    SenderThread:16893 [file_pusher.py:join():164] waiting for file pusher
