2023-07-10 14:50:26,655 INFO    StreamThr :31569 [internal.py:wandb_internal():86] W&B internal server running at pid: 31569, started at: 2023-07-10 14:50:26.655593
2023-07-10 14:50:26,656 DEBUG   HandlerThread:31569 [handler.py:handle_request():144] handle_request: status
2023-07-10 14:50:26,657 INFO    WriterThread:31569 [datastore.py:open_for_write():85] open: /home/zhuhe/HPE-with-Diffusion/wandb/run-20230710_145026-td4d0m1u/run-td4d0m1u.wandb
2023-07-10 14:50:26,657 DEBUG   SenderThread:31569 [sender.py:send():369] send: header
2023-07-10 14:50:26,657 DEBUG   SenderThread:31569 [sender.py:send():369] send: run
2023-07-10 14:50:27,727 INFO    SenderThread:31569 [dir_watcher.py:__init__():211] watching files in: /home/zhuhe/HPE-with-Diffusion/wandb/run-20230710_145026-td4d0m1u/files
2023-07-10 14:50:27,727 INFO    SenderThread:31569 [sender.py:_start_run_threads():1100] run started: td4d0m1u with start time 1688971826.655303
2023-07-10 14:50:27,728 DEBUG   SenderThread:31569 [sender.py:send_request():396] send_request: summary_record
2023-07-10 14:50:27,728 INFO    SenderThread:31569 [sender.py:_save_file():1354] saving file wandb-summary.json with policy end
2023-07-10 14:50:27,731 DEBUG   HandlerThread:31569 [handler.py:handle_request():144] handle_request: check_version
2023-07-10 14:50:27,731 DEBUG   SenderThread:31569 [sender.py:send_request():396] send_request: check_version
2023-07-10 14:50:27,909 DEBUG   HandlerThread:31569 [handler.py:handle_request():144] handle_request: run_start
2023-07-10 14:50:27,914 DEBUG   HandlerThread:31569 [system_info.py:__init__():31] System info init
2023-07-10 14:50:27,914 DEBUG   HandlerThread:31569 [system_info.py:__init__():46] System info init done
2023-07-10 14:50:27,914 INFO    HandlerThread:31569 [system_monitor.py:start():181] Starting system monitor
2023-07-10 14:50:27,914 INFO    SystemMonitor:31569 [system_monitor.py:_start():145] Starting system asset monitoring threads
2023-07-10 14:50:27,914 INFO    SystemMonitor:31569 [interfaces.py:start():190] Started cpu monitoring
2023-07-10 14:50:27,914 INFO    SystemMonitor:31569 [interfaces.py:start():190] Started disk monitoring
2023-07-10 14:50:27,915 INFO    HandlerThread:31569 [system_monitor.py:probe():201] Collecting system info
2023-07-10 14:50:27,915 INFO    SystemMonitor:31569 [interfaces.py:start():190] Started gpu monitoring
2023-07-10 14:50:27,916 INFO    SystemMonitor:31569 [interfaces.py:start():190] Started memory monitoring
2023-07-10 14:50:27,916 INFO    SystemMonitor:31569 [interfaces.py:start():190] Started network monitoring
2023-07-10 14:50:27,930 DEBUG   HandlerThread:31569 [system_info.py:probe():195] Probing system
2023-07-10 14:50:27,932 DEBUG   HandlerThread:31569 [gitlib.py:_init_repo():53] git repository is invalid
2023-07-10 14:50:27,933 DEBUG   HandlerThread:31569 [system_info.py:probe():240] Probing system done
2023-07-10 14:50:27,933 DEBUG   HandlerThread:31569 [system_monitor.py:probe():210] {'os': 'Linux-5.19.0-46-generic-x86_64-with-glibc2.35', 'python': '3.9.16', 'heartbeatAt': '2023-07-10T06:50:27.930760', 'startedAt': '2023-07-10T06:50:26.651974', 'docker': None, 'cuda': None, 'args': ('--phase', 'train', '--gpu_ids', '1'), 'state': 'running', 'program': '/home/zhuhe/HPE-with-Diffusion/main.py', 'codePath': 'main.py', 'host': '415-2', 'username': 'zhuhe', 'executable': '/home/zhuhe/.conda/envs/diffhpe/bin/python', 'cpu_count': 16, 'cpu_count_logical': 24, 'cpu_freq': {'current': 4242.644874999999, 'min': 800.0, 'max': 4783.333333333333}, 'cpu_freq_per_core': [{'current': 4427.424, 'min': 800.0, 'max': 5100.0}, {'current': 4871.998, 'min': 800.0, 'max': 5100.0}, {'current': 5099.987, 'min': 800.0, 'max': 5100.0}, {'current': 4995.827, 'min': 800.0, 'max': 5100.0}, {'current': 5036.541, 'min': 800.0, 'max': 5100.0}, {'current': 4992.699, 'min': 800.0, 'max': 5100.0}, {'current': 5069.251, 'min': 800.0, 'max': 5100.0}, {'current': 4454.672, 'min': 800.0, 'max': 5100.0}, {'current': 5011.694, 'min': 800.0, 'max': 5200.0}, {'current': 5111.068, 'min': 800.0, 'max': 5200.0}, {'current': 5103.529, 'min': 800.0, 'max': 5200.0}, {'current': 2100.0, 'min': 800.0, 'max': 5200.0}, {'current': 4908.958, 'min': 800.0, 'max': 5100.0}, {'current': 5086.507, 'min': 800.0, 'max': 5100.0}, {'current': 5042.742, 'min': 800.0, 'max': 5100.0}, {'current': 2100.0, 'min': 800.0, 'max': 5100.0}, {'current': 3757.079, 'min': 800.0, 'max': 4100.0}, {'current': 3757.079, 'min': 800.0, 'max': 4100.0}, {'current': 3757.048, 'min': 800.0, 'max': 4100.0}, {'current': 3757.055, 'min': 800.0, 'max': 4100.0}, {'current': 3757.05, 'min': 800.0, 'max': 4100.0}, {'current': 3757.069, 'min': 800.0, 'max': 4100.0}, {'current': 3757.057, 'min': 800.0, 'max': 4100.0}, {'current': 3757.036, 'min': 800.0, 'max': 4100.0}], 'disk': {'total': 93.31179428100586, 'used': 0.017879486083984375}, 'gpu': 'NVIDIA GeForce RTX 3090', 'gpu_count': 2, 'gpu_devices': [{'name': 'NVIDIA GeForce RTX 3090', 'memory_total': 25769803776}, {'name': 'NVIDIA GeForce RTX 3090', 'memory_total': 25769803776}], 'memory': {'total': 31.185562133789062}}
2023-07-10 14:50:27,933 INFO    HandlerThread:31569 [system_monitor.py:probe():211] Finished collecting system info
2023-07-10 14:50:27,933 INFO    HandlerThread:31569 [system_monitor.py:probe():214] Publishing system info
2023-07-10 14:50:27,933 DEBUG   HandlerThread:31569 [system_info.py:_save_pip():51] Saving list of pip packages installed into the current environment
2023-07-10 14:50:27,933 DEBUG   HandlerThread:31569 [system_info.py:_save_pip():67] Saving pip packages done
2023-07-10 14:50:27,933 DEBUG   HandlerThread:31569 [system_info.py:_save_conda():74] Saving list of conda packages installed into the current environment
2023-07-10 14:50:28,724 DEBUG   HandlerThread:31569 [system_info.py:_save_conda():86] Saving conda packages done
2023-07-10 14:50:28,724 INFO    HandlerThread:31569 [system_monitor.py:probe():216] Finished publishing system info
2023-07-10 14:50:28,726 DEBUG   SenderThread:31569 [sender.py:send():369] send: files
2023-07-10 14:50:28,726 INFO    SenderThread:31569 [sender.py:_save_file():1354] saving file wandb-metadata.json with policy now
2023-07-10 14:50:28,728 DEBUG   HandlerThread:31569 [handler.py:handle_request():144] handle_request: stop_status
2023-07-10 14:50:28,728 DEBUG   SenderThread:31569 [sender.py:send_request():396] send_request: stop_status
2023-07-10 14:50:28,731 INFO    Thread-12 :31569 [dir_watcher.py:_on_file_created():272] file/dir created: /home/zhuhe/HPE-with-Diffusion/wandb/run-20230710_145026-td4d0m1u/files/wandb-metadata.json
2023-07-10 14:50:28,731 INFO    Thread-12 :31569 [dir_watcher.py:_on_file_created():272] file/dir created: /home/zhuhe/HPE-with-Diffusion/wandb/run-20230710_145026-td4d0m1u/files/requirements.txt
2023-07-10 14:50:28,731 INFO    Thread-12 :31569 [dir_watcher.py:_on_file_created():272] file/dir created: /home/zhuhe/HPE-with-Diffusion/wandb/run-20230710_145026-td4d0m1u/files/conda-environment.yaml
2023-07-10 14:50:28,731 INFO    Thread-12 :31569 [dir_watcher.py:_on_file_created():272] file/dir created: /home/zhuhe/HPE-with-Diffusion/wandb/run-20230710_145026-td4d0m1u/files/wandb-summary.json
2023-07-10 14:50:29,236 ERROR   wandb-upload_0:31569 [internal_api.py:upload_file():2192] upload_file exception https://storage.googleapis.com/wandb-production.appspot.com/ada4321/DiffHPE/td4d0m1u/wandb-metadata.json?Expires=1689058228&GoogleAccessId=gorilla-files-url-signer-man%40wandb-production.iam.gserviceaccount.com&Signature=YKNuWxQQzBHD8PFfJAbBQ4BKI0shddFuKZ4KjUt8wxFeElSLnfOgwIJ8GpL0tfd5CoRY3j6zayyraJ0mZR5VLxwlBRO9dawyJFaztK9oNYM53fmtI%2FSyNqikRRfZg%2FomYHjrfrnp6Z6BXsdss6HSJYivZbXmlMJVrXAZ8%2F9rVil5xJtDv73SbF7lITxuOTjjOXQUVvho8a8nW74NwGzA4V4pGQIC454%2FxyrbPfpFJLFmgOCGZ132xrdrQCHvccKm8NmnLAhBzWXfpaQzjHQpYaNI7hUY1QAXLsf1DgSi1ts%2FufDEBGjFttM%2BEqI2ibp2WCQpwCrUlFZZb7v0ttGNNw%3D%3D: 404 Client Error: Not Found for url: https://storage.googleapis.com/wandb-production.appspot.com/ada4321/DiffHPE/td4d0m1u/wandb-metadata.json?Expires=1689058228&GoogleAccessId=gorilla-files-url-signer-man%40wandb-production.iam.gserviceaccount.com&Signature=YKNuWxQQzBHD8PFfJAbBQ4BKI0shddFuKZ4KjUt8wxFeElSLnfOgwIJ8GpL0tfd5CoRY3j6zayyraJ0mZR5VLxwlBRO9dawyJFaztK9oNYM53fmtI%2FSyNqikRRfZg%2FomYHjrfrnp6Z6BXsdss6HSJYivZbXmlMJVrXAZ8%2F9rVil5xJtDv73SbF7lITxuOTjjOXQUVvho8a8nW74NwGzA4V4pGQIC454%2FxyrbPfpFJLFmgOCGZ132xrdrQCHvccKm8NmnLAhBzWXfpaQzjHQpYaNI7hUY1QAXLsf1DgSi1ts%2FufDEBGjFttM%2BEqI2ibp2WCQpwCrUlFZZb7v0ttGNNw%3D%3D
2023-07-10 14:50:29,236 ERROR   wandb-upload_0:31569 [internal_api.py:upload_file():2194] upload_file request headers: {'User-Agent': 'python-requests/2.31.0', 'Accept-Encoding': 'gzip, deflate', 'Accept': '*/*', 'Connection': 'keep-alive', 'Content-Length': '3722'}
2023-07-10 14:50:29,236 ERROR   wandb-upload_0:31569 [internal_api.py:upload_file():2196] upload_file response body: b'<!DOCTYPE html>\n<html lang=en>\n  <meta charset=utf-8>\n  <meta name=viewport content="initial-scale=1, minimum-scale=1, width=device-width">\n  <title>Error 404 (Not Found)!!1</title>\n  <style>\n    *{margin:0;padding:0}html,code{font:15px/22px arial,sans-serif}html{background:#fff;color:#222;padding:15px}body{margin:7% auto 0;max-width:390px;min-height:180px;padding:30px 0 15px}* > body{background:url(//www.google.com/images/errors/robot.png) 100% 5px no-repeat;padding-right:205px}p{margin:11px 0 22px;overflow:hidden}ins{color:#777;text-decoration:none}a img{border:0}@media screen and (max-width:772px){body{background:none;margin-top:0;max-width:none;padding-right:0}}#logo{background:url(//www.google.com/images/branding/googlelogo/1x/googlelogo_color_150x54dp.png) no-repeat;margin-left:-5px}@media only screen and (min-resolution:192dpi){#logo{background:url(//www.google.com/images/branding/googlelogo/2x/googlelogo_color_150x54dp.png) no-repeat 0% 0%/100% 100%;-moz-border-image:url(//www.google.com/images/branding/googlelogo/2x/googlelogo_color_150x54dp.png) 0}}@media only screen and (-webkit-min-device-pixel-ratio:2){#logo{background:url(//www.google.com/images/branding/googlelogo/2x/googlelogo_color_150x54dp.png) no-repeat;-webkit-background-size:100% 100%}}#logo{display:inline-block;height:54px;width:150px}\n  </style>\n  <a href=//www.google.com/><span id=logo aria-label=Google></span></a>\n  <p><b>404.</b> <ins>That\xe2\x80\x99s an error.</ins>\n  <p>The requested URL <code>/wandb-production.appspot.com/ada4321/DiffHPE/td4d0m1u/wandb-metadata.json</code> was not found on this server.  <ins>That\xe2\x80\x99s all we know.</ins>\n'
2023-07-10 14:50:29,305 DEBUG   SenderThread:31569 [sender.py:send():369] send: telemetry
2023-07-10 14:50:29,306 DEBUG   SenderThread:31569 [sender.py:send():369] send: exit
2023-07-10 14:50:29,306 INFO    SenderThread:31569 [sender.py:send_exit():574] handling exit code: 1
2023-07-10 14:50:29,306 INFO    SenderThread:31569 [sender.py:send_exit():576] handling runtime: 0
2023-07-10 14:50:29,306 INFO    SenderThread:31569 [sender.py:_save_file():1354] saving file wandb-summary.json with policy end
2023-07-10 14:50:29,306 INFO    SenderThread:31569 [sender.py:send_exit():582] send defer
2023-07-10 14:50:29,306 DEBUG   HandlerThread:31569 [handler.py:handle_request():144] handle_request: defer
2023-07-10 14:50:29,306 INFO    HandlerThread:31569 [handler.py:handle_request_defer():170] handle defer: 0
2023-07-10 14:50:29,306 DEBUG   SenderThread:31569 [sender.py:send_request():396] send_request: defer
2023-07-10 14:50:29,306 INFO    SenderThread:31569 [sender.py:send_request_defer():598] handle sender defer: 0
2023-07-10 14:50:29,306 INFO    SenderThread:31569 [sender.py:transition_state():602] send defer: 1
2023-07-10 14:50:29,306 DEBUG   HandlerThread:31569 [handler.py:handle_request():144] handle_request: defer
2023-07-10 14:50:29,306 INFO    HandlerThread:31569 [handler.py:handle_request_defer():170] handle defer: 1
2023-07-10 14:50:29,307 DEBUG   SenderThread:31569 [sender.py:send_request():396] send_request: defer
2023-07-10 14:50:29,307 INFO    SenderThread:31569 [sender.py:send_request_defer():598] handle sender defer: 1
2023-07-10 14:50:29,307 INFO    SenderThread:31569 [sender.py:transition_state():602] send defer: 2
2023-07-10 14:50:29,307 DEBUG   HandlerThread:31569 [handler.py:handle_request():144] handle_request: defer
2023-07-10 14:50:29,307 INFO    HandlerThread:31569 [handler.py:handle_request_defer():170] handle defer: 2
2023-07-10 14:50:29,307 INFO    HandlerThread:31569 [system_monitor.py:finish():190] Stopping system monitor
2023-07-10 14:50:29,307 DEBUG   SystemMonitor:31569 [system_monitor.py:_start():159] Starting system metrics aggregation loop
2023-07-10 14:50:29,307 DEBUG   SystemMonitor:31569 [system_monitor.py:_start():166] Finished system metrics aggregation loop
2023-07-10 14:50:29,307 DEBUG   SystemMonitor:31569 [system_monitor.py:_start():170] Publishing last batch of metrics
2023-07-10 14:50:29,308 INFO    HandlerThread:31569 [interfaces.py:finish():202] Joined cpu monitor
2023-07-10 14:50:29,308 INFO    HandlerThread:31569 [interfaces.py:finish():202] Joined disk monitor
2023-07-10 14:50:29,353 INFO    HandlerThread:31569 [interfaces.py:finish():202] Joined gpu monitor
2023-07-10 14:50:29,353 INFO    HandlerThread:31569 [interfaces.py:finish():202] Joined memory monitor
2023-07-10 14:50:29,353 INFO    HandlerThread:31569 [interfaces.py:finish():202] Joined network monitor
2023-07-10 14:50:29,354 DEBUG   SenderThread:31569 [sender.py:send_request():396] send_request: defer
2023-07-10 14:50:29,354 INFO    SenderThread:31569 [sender.py:send_request_defer():598] handle sender defer: 2
2023-07-10 14:50:29,354 INFO    SenderThread:31569 [sender.py:transition_state():602] send defer: 3
2023-07-10 14:50:29,354 DEBUG   SenderThread:31569 [sender.py:send():369] send: stats
2023-07-10 14:50:29,354 DEBUG   HandlerThread:31569 [handler.py:handle_request():144] handle_request: defer
2023-07-10 14:50:29,354 INFO    HandlerThread:31569 [handler.py:handle_request_defer():170] handle defer: 3
2023-07-10 14:50:29,354 DEBUG   SenderThread:31569 [sender.py:send_request():396] send_request: defer
2023-07-10 14:50:29,354 INFO    SenderThread:31569 [sender.py:send_request_defer():598] handle sender defer: 3
2023-07-10 14:50:29,354 INFO    SenderThread:31569 [sender.py:transition_state():602] send defer: 4
2023-07-10 14:50:29,355 DEBUG   HandlerThread:31569 [handler.py:handle_request():144] handle_request: defer
2023-07-10 14:50:29,355 INFO    HandlerThread:31569 [handler.py:handle_request_defer():170] handle defer: 4
2023-07-10 14:50:29,355 DEBUG   SenderThread:31569 [sender.py:send_request():396] send_request: defer
2023-07-10 14:50:29,355 INFO    SenderThread:31569 [sender.py:send_request_defer():598] handle sender defer: 4
2023-07-10 14:50:29,355 INFO    SenderThread:31569 [sender.py:transition_state():602] send defer: 5
2023-07-10 14:50:29,355 DEBUG   HandlerThread:31569 [handler.py:handle_request():144] handle_request: defer
2023-07-10 14:50:29,355 INFO    HandlerThread:31569 [handler.py:handle_request_defer():170] handle defer: 5
2023-07-10 14:50:29,355 DEBUG   SenderThread:31569 [sender.py:send():369] send: summary
2023-07-10 14:50:29,355 INFO    SenderThread:31569 [sender.py:_save_file():1354] saving file wandb-summary.json with policy end
2023-07-10 14:50:29,355 DEBUG   SenderThread:31569 [sender.py:send_request():396] send_request: defer
2023-07-10 14:50:29,356 INFO    SenderThread:31569 [sender.py:send_request_defer():598] handle sender defer: 5
2023-07-10 14:50:29,356 INFO    SenderThread:31569 [sender.py:transition_state():602] send defer: 6
2023-07-10 14:50:29,356 DEBUG   HandlerThread:31569 [handler.py:handle_request():144] handle_request: defer
2023-07-10 14:50:29,356 INFO    HandlerThread:31569 [handler.py:handle_request_defer():170] handle defer: 6
2023-07-10 14:50:29,356 DEBUG   SenderThread:31569 [sender.py:send_request():396] send_request: defer
2023-07-10 14:50:29,356 INFO    SenderThread:31569 [sender.py:send_request_defer():598] handle sender defer: 6
2023-07-10 14:50:29,357 DEBUG   HandlerThread:31569 [handler.py:handle_request():144] handle_request: status_report
2023-07-10 14:50:29,700 INFO    SenderThread:31569 [sender.py:transition_state():602] send defer: 7
2023-07-10 14:50:29,700 DEBUG   HandlerThread:31569 [handler.py:handle_request():144] handle_request: defer
2023-07-10 14:50:29,700 INFO    HandlerThread:31569 [handler.py:handle_request_defer():170] handle defer: 7
2023-07-10 14:50:29,700 DEBUG   SenderThread:31569 [sender.py:send_request():396] send_request: defer
2023-07-10 14:50:29,700 INFO    SenderThread:31569 [sender.py:send_request_defer():598] handle sender defer: 7
2023-07-10 14:50:29,730 INFO    Thread-12 :31569 [dir_watcher.py:_on_file_modified():289] file/dir modified: /home/zhuhe/HPE-with-Diffusion/wandb/run-20230710_145026-td4d0m1u/files/config.yaml
2023-07-10 14:50:29,730 INFO    Thread-12 :31569 [dir_watcher.py:_on_file_modified():289] file/dir modified: /home/zhuhe/HPE-with-Diffusion/wandb/run-20230710_145026-td4d0m1u/files/wandb-summary.json
2023-07-10 14:50:29,730 INFO    Thread-12 :31569 [dir_watcher.py:_on_file_created():272] file/dir created: /home/zhuhe/HPE-with-Diffusion/wandb/run-20230710_145026-td4d0m1u/files/output.log
2023-07-10 14:50:29,731 DEBUG   HandlerThread:31569 [handler.py:handle_request():144] handle_request: poll_exit
2023-07-10 14:50:29,823 ERROR   wandb-upload_0:31569 [upload_job.py:push():136] Failed to upload file: /tmp/tmpdkj3ah54wandb/ou620m9w-wandb-metadata.json
Traceback (most recent call last):
  File "/home/zhuhe/.conda/envs/diffhpe/lib/python3.9/site-packages/wandb/apis/normalize.py", line 41, in wrapper
    return func(*args, **kwargs)
  File "/home/zhuhe/.conda/envs/diffhpe/lib/python3.9/site-packages/wandb/sdk/lib/retry.py", line 212, in wrapped_fn
    return retrier(*args, **kargs)
  File "/home/zhuhe/.conda/envs/diffhpe/lib/python3.9/site-packages/wandb/sdk/lib/retry.py", line 131, in __call__
    result = self._call_fn(*args, **kwargs)
  File "/home/zhuhe/.conda/envs/diffhpe/lib/python3.9/site-packages/wandb/sdk/internal/internal_api.py", line 2218, in upload_file
    wandb._sentry.reraise(e)
  File "/home/zhuhe/.conda/envs/diffhpe/lib/python3.9/site-packages/wandb/analytics/sentry.py", line 146, in reraise
    raise exc.with_traceback(sys.exc_info()[2])
  File "/home/zhuhe/.conda/envs/diffhpe/lib/python3.9/site-packages/wandb/sdk/internal/internal_api.py", line 2190, in upload_file
    response.raise_for_status()
  File "/home/zhuhe/.conda/envs/diffhpe/lib/python3.9/site-packages/requests/models.py", line 1021, in raise_for_status
    raise HTTPError(http_error_msg, response=self)
requests.exceptions.HTTPError: 404 Client Error: Not Found for url: https://storage.googleapis.com/wandb-production.appspot.com/ada4321/DiffHPE/td4d0m1u/wandb-metadata.json?Expires=1689058228&GoogleAccessId=gorilla-files-url-signer-man%40wandb-production.iam.gserviceaccount.com&Signature=YKNuWxQQzBHD8PFfJAbBQ4BKI0shddFuKZ4KjUt8wxFeElSLnfOgwIJ8GpL0tfd5CoRY3j6zayyraJ0mZR5VLxwlBRO9dawyJFaztK9oNYM53fmtI%2FSyNqikRRfZg%2FomYHjrfrnp6Z6BXsdss6HSJYivZbXmlMJVrXAZ8%2F9rVil5xJtDv73SbF7lITxuOTjjOXQUVvho8a8nW74NwGzA4V4pGQIC454%2FxyrbPfpFJLFmgOCGZ132xrdrQCHvccKm8NmnLAhBzWXfpaQzjHQpYaNI7hUY1QAXLsf1DgSi1ts%2FufDEBGjFttM%2BEqI2ibp2WCQpwCrUlFZZb7v0ttGNNw%3D%3D

During handling of the above exception, another exception occurred:

Traceback (most recent call last):
  File "/home/zhuhe/.conda/envs/diffhpe/lib/python3.9/site-packages/wandb/filesync/upload_job.py", line 127, in push
    self._api.upload_file_retry(
  File "/home/zhuhe/.conda/envs/diffhpe/lib/python3.9/site-packages/wandb/apis/normalize.py", line 51, in wrapper
    raise CommError(message, error)
wandb.errors.CommError: <Response [404]>
2023-07-10 14:50:30,039 ERROR   Thread-11 :31569 [step_upload.py:_handle_event():200] Failed to upload file: /tmp/tmpdkj3ah54wandb/ou620m9w-wandb-metadata.json
Traceback (most recent call last):
  File "/home/zhuhe/.conda/envs/diffhpe/lib/python3.9/site-packages/wandb/apis/normalize.py", line 41, in wrapper
    return func(*args, **kwargs)
  File "/home/zhuhe/.conda/envs/diffhpe/lib/python3.9/site-packages/wandb/sdk/lib/retry.py", line 212, in wrapped_fn
    return retrier(*args, **kargs)
  File "/home/zhuhe/.conda/envs/diffhpe/lib/python3.9/site-packages/wandb/sdk/lib/retry.py", line 131, in __call__
    result = self._call_fn(*args, **kwargs)
  File "/home/zhuhe/.conda/envs/diffhpe/lib/python3.9/site-packages/wandb/sdk/internal/internal_api.py", line 2218, in upload_file
    wandb._sentry.reraise(e)
  File "/home/zhuhe/.conda/envs/diffhpe/lib/python3.9/site-packages/wandb/analytics/sentry.py", line 146, in reraise
    raise exc.with_traceback(sys.exc_info()[2])
  File "/home/zhuhe/.conda/envs/diffhpe/lib/python3.9/site-packages/wandb/sdk/internal/internal_api.py", line 2190, in upload_file
    response.raise_for_status()
  File "/home/zhuhe/.conda/envs/diffhpe/lib/python3.9/site-packages/requests/models.py", line 1021, in raise_for_status
    raise HTTPError(http_error_msg, response=self)
requests.exceptions.HTTPError: 404 Client Error: Not Found for url: https://storage.googleapis.com/wandb-production.appspot.com/ada4321/DiffHPE/td4d0m1u/wandb-metadata.json?Expires=1689058228&GoogleAccessId=gorilla-files-url-signer-man%40wandb-production.iam.gserviceaccount.com&Signature=YKNuWxQQzBHD8PFfJAbBQ4BKI0shddFuKZ4KjUt8wxFeElSLnfOgwIJ8GpL0tfd5CoRY3j6zayyraJ0mZR5VLxwlBRO9dawyJFaztK9oNYM53fmtI%2FSyNqikRRfZg%2FomYHjrfrnp6Z6BXsdss6HSJYivZbXmlMJVrXAZ8%2F9rVil5xJtDv73SbF7lITxuOTjjOXQUVvho8a8nW74NwGzA4V4pGQIC454%2FxyrbPfpFJLFmgOCGZ132xrdrQCHvccKm8NmnLAhBzWXfpaQzjHQpYaNI7hUY1QAXLsf1DgSi1ts%2FufDEBGjFttM%2BEqI2ibp2WCQpwCrUlFZZb7v0ttGNNw%3D%3D

During handling of the above exception, another exception occurred:

Traceback (most recent call last):
  File "/home/zhuhe/.conda/envs/diffhpe/lib/python3.9/concurrent/futures/thread.py", line 58, in run
    result = self.fn(*self.args, **self.kwargs)
  File "/home/zhuhe/.conda/envs/diffhpe/lib/python3.9/site-packages/wandb/filesync/step_upload.py", line 288, in run_and_notify
    self._do_upload_sync(event)
  File "/home/zhuhe/.conda/envs/diffhpe/lib/python3.9/site-packages/wandb/filesync/step_upload.py", line 330, in _do_upload_sync
    job.run()
  File "/home/zhuhe/.conda/envs/diffhpe/lib/python3.9/site-packages/wandb/filesync/upload_job.py", line 57, in run
    self.push()
  File "/home/zhuhe/.conda/envs/diffhpe/lib/python3.9/site-packages/wandb/filesync/upload_job.py", line 127, in push
    self._api.upload_file_retry(
  File "/home/zhuhe/.conda/envs/diffhpe/lib/python3.9/site-packages/wandb/apis/normalize.py", line 51, in wrapper
    raise CommError(message, error)
wandb.errors.CommError: <Response [404]>
2023-07-10 14:50:31,311 INFO    SenderThread:31569 [sender.py:transition_state():602] send defer: 8
2023-07-10 14:50:31,311 DEBUG   SenderThread:31569 [sender.py:send_request():396] send_request: poll_exit
2023-07-10 14:50:31,311 DEBUG   HandlerThread:31569 [handler.py:handle_request():144] handle_request: defer
2023-07-10 14:50:31,311 INFO    HandlerThread:31569 [handler.py:handle_request_defer():170] handle defer: 8
2023-07-10 14:50:31,312 DEBUG   SenderThread:31569 [sender.py:send_request():396] send_request: defer
2023-07-10 14:50:31,312 INFO    SenderThread:31569 [sender.py:send_request_defer():598] handle sender defer: 8
2023-07-10 14:50:31,312 INFO    SenderThread:31569 [job_builder.py:build():232] Attempting to build job artifact
2023-07-10 14:50:31,312 INFO    SenderThread:31569 [job_builder.py:build():266] no source found
2023-07-10 14:50:31,312 INFO    SenderThread:31569 [sender.py:transition_state():602] send defer: 9
2023-07-10 14:50:31,312 DEBUG   HandlerThread:31569 [handler.py:handle_request():144] handle_request: defer
2023-07-10 14:50:31,312 INFO    HandlerThread:31569 [handler.py:handle_request_defer():170] handle defer: 9
2023-07-10 14:50:31,312 DEBUG   SenderThread:31569 [sender.py:send_request():396] send_request: defer
2023-07-10 14:50:31,312 INFO    SenderThread:31569 [sender.py:send_request_defer():598] handle sender defer: 9
2023-07-10 14:50:31,312 INFO    SenderThread:31569 [dir_watcher.py:finish():359] shutting down directory watcher
2023-07-10 14:50:31,730 INFO    Thread-12 :31569 [dir_watcher.py:_on_file_modified():289] file/dir modified: /home/zhuhe/HPE-with-Diffusion/wandb/run-20230710_145026-td4d0m1u/files/output.log
2023-07-10 14:50:31,731 INFO    SenderThread:31569 [dir_watcher.py:finish():389] scan: /home/zhuhe/HPE-with-Diffusion/wandb/run-20230710_145026-td4d0m1u/files
2023-07-10 14:50:31,731 INFO    SenderThread:31569 [dir_watcher.py:finish():403] scan save: /home/zhuhe/HPE-with-Diffusion/wandb/run-20230710_145026-td4d0m1u/files/wandb-metadata.json wandb-metadata.json
2023-07-10 14:50:31,731 INFO    SenderThread:31569 [dir_watcher.py:finish():403] scan save: /home/zhuhe/HPE-with-Diffusion/wandb/run-20230710_145026-td4d0m1u/files/config.yaml config.yaml
2023-07-10 14:50:31,731 INFO    SenderThread:31569 [dir_watcher.py:finish():403] scan save: /home/zhuhe/HPE-with-Diffusion/wandb/run-20230710_145026-td4d0m1u/files/requirements.txt requirements.txt
2023-07-10 14:50:31,731 INFO    SenderThread:31569 [dir_watcher.py:finish():403] scan save: /home/zhuhe/HPE-with-Diffusion/wandb/run-20230710_145026-td4d0m1u/files/wandb-summary.json wandb-summary.json
2023-07-10 14:50:31,731 INFO    SenderThread:31569 [dir_watcher.py:finish():403] scan save: /home/zhuhe/HPE-with-Diffusion/wandb/run-20230710_145026-td4d0m1u/files/conda-environment.yaml conda-environment.yaml
2023-07-10 14:50:31,731 INFO    SenderThread:31569 [dir_watcher.py:finish():403] scan save: /home/zhuhe/HPE-with-Diffusion/wandb/run-20230710_145026-td4d0m1u/files/output.log output.log
2023-07-10 14:50:31,731 INFO    SenderThread:31569 [sender.py:transition_state():602] send defer: 10
2023-07-10 14:50:31,731 DEBUG   HandlerThread:31569 [handler.py:handle_request():144] handle_request: defer
2023-07-10 14:50:31,731 INFO    HandlerThread:31569 [handler.py:handle_request_defer():170] handle defer: 10
2023-07-10 14:50:31,734 DEBUG   SenderThread:31569 [sender.py:send_request():396] send_request: defer
2023-07-10 14:50:31,734 INFO    SenderThread:31569 [sender.py:send_request_defer():598] handle sender defer: 10
2023-07-10 14:50:31,734 INFO    SenderThread:31569 [file_pusher.py:finish():159] shutting down file pusher
2023-07-10 14:50:32,177 ERROR   wandb-upload_1:31569 [internal_api.py:upload_file():2192] upload_file exception https://storage.googleapis.com/wandb-production.appspot.com/ada4321/DiffHPE/td4d0m1u/config.yaml?Expires=1689058231&GoogleAccessId=gorilla-files-url-signer-man%40wandb-production.iam.gserviceaccount.com&Signature=dJNzcVKIYFjh0l6u11KnfUlSRfRlc0GbtRFA0AbPj0qunhqARRPIVZ%2FHRVwA0MpYuKKnyBZFS9ttGg3YUI%2BfkkxcH%2BGySnfCuIG%2FI5IySzIIhccR9Jty8MAd%2Bn8jWBGWBZYQCbEcEJP0koudtW7XabzceaRoZfmZ7dFIGgVQg7WV02jbPulS8PYyLyyCKkfnGsnhV5h%2B55CYk%2B7dDAKSayujC0zEL11jGjWRP9ET2N%2BJ%2FRmZYyrhvqnQVfeGy8jsOOQLr3npQDs%2ByDxAklhKvGa5xZhDXpfWkKdrw3tUzHOAmL%2BJI1TBkaSr3ksJ8xZs4hIM2whdjEFOW16FGFnvVA%3D%3D: 404 Client Error: Not Found for url: https://storage.googleapis.com/wandb-production.appspot.com/ada4321/DiffHPE/td4d0m1u/config.yaml?Expires=1689058231&GoogleAccessId=gorilla-files-url-signer-man%40wandb-production.iam.gserviceaccount.com&Signature=dJNzcVKIYFjh0l6u11KnfUlSRfRlc0GbtRFA0AbPj0qunhqARRPIVZ%2FHRVwA0MpYuKKnyBZFS9ttGg3YUI%2BfkkxcH%2BGySnfCuIG%2FI5IySzIIhccR9Jty8MAd%2Bn8jWBGWBZYQCbEcEJP0koudtW7XabzceaRoZfmZ7dFIGgVQg7WV02jbPulS8PYyLyyCKkfnGsnhV5h%2B55CYk%2B7dDAKSayujC0zEL11jGjWRP9ET2N%2BJ%2FRmZYyrhvqnQVfeGy8jsOOQLr3npQDs%2ByDxAklhKvGa5xZhDXpfWkKdrw3tUzHOAmL%2BJI1TBkaSr3ksJ8xZs4hIM2whdjEFOW16FGFnvVA%3D%3D
2023-07-10 14:50:32,177 ERROR   wandb-upload_1:31569 [internal_api.py:upload_file():2194] upload_file request headers: {'User-Agent': 'python-requests/2.31.0', 'Accept-Encoding': 'gzip, deflate', 'Accept': '*/*', 'Connection': 'keep-alive', 'Content-Length': '514'}
2023-07-10 14:50:32,177 ERROR   wandb-upload_1:31569 [internal_api.py:upload_file():2196] upload_file response body: b'<!DOCTYPE html>\n<html lang=en>\n  <meta charset=utf-8>\n  <meta name=viewport content="initial-scale=1, minimum-scale=1, width=device-width">\n  <title>Error 404 (Not Found)!!1</title>\n  <style>\n    *{margin:0;padding:0}html,code{font:15px/22px arial,sans-serif}html{background:#fff;color:#222;padding:15px}body{margin:7% auto 0;max-width:390px;min-height:180px;padding:30px 0 15px}* > body{background:url(//www.google.com/images/errors/robot.png) 100% 5px no-repeat;padding-right:205px}p{margin:11px 0 22px;overflow:hidden}ins{color:#777;text-decoration:none}a img{border:0}@media screen and (max-width:772px){body{background:none;margin-top:0;max-width:none;padding-right:0}}#logo{background:url(//www.google.com/images/branding/googlelogo/1x/googlelogo_color_150x54dp.png) no-repeat;margin-left:-5px}@media only screen and (min-resolution:192dpi){#logo{background:url(//www.google.com/images/branding/googlelogo/2x/googlelogo_color_150x54dp.png) no-repeat 0% 0%/100% 100%;-moz-border-image:url(//www.google.com/images/branding/googlelogo/2x/googlelogo_color_150x54dp.png) 0}}@media only screen and (-webkit-min-device-pixel-ratio:2){#logo{background:url(//www.google.com/images/branding/googlelogo/2x/googlelogo_color_150x54dp.png) no-repeat;-webkit-background-size:100% 100%}}#logo{display:inline-block;height:54px;width:150px}\n  </style>\n  <a href=//www.google.com/><span id=logo aria-label=Google></span></a>\n  <p><b>404.</b> <ins>That\xe2\x80\x99s an error.</ins>\n  <p>The requested URL <code>/wandb-production.appspot.com/ada4321/DiffHPE/td4d0m1u/config.yaml</code> was not found on this server.  <ins>That\xe2\x80\x99s all we know.</ins>\n'
2023-07-10 14:50:32,222 ERROR   wandb-upload_0:31569 [internal_api.py:upload_file():2192] upload_file exception https://storage.googleapis.com/wandb-production.appspot.com/ada4321/DiffHPE/td4d0m1u/requirements.txt?Expires=1689058231&GoogleAccessId=gorilla-files-url-signer-man%40wandb-production.iam.gserviceaccount.com&Signature=o22EGwF5VHWcXI3c2I1e%2Ft45ww8nvnIXiDWvOD4kQDe4KVVMReFr%2BrkkLP8gODT0aVFqTVXE%2F5KNN8aH3e5x6hXoftjZRW9TvcKvqa2bPRoWtQzO%2FbiEDC8xA086NkPu8LEvlbAsflvfzQe0j0Qib0kTJyGRX9we%2Flgci9HGoqgzgu1qnq8x72hFWzLqZvxKQ9AWyS9oMEm%2Bp%2FhY%2FEnJzJTPQ7RvtKDVdD31gZcG2KC0TKbZytVxHwGbTXSIlSS3yGa3AvSz08CGEAMns%2BV8i6pMdUWRKBUjCqumy4VI3D34lAEWykUxGh6QmHyoDr4IlE%2F5XzoCG5aC6TjGkY%2Bp2Q%3D%3D: 404 Client Error: Not Found for url: https://storage.googleapis.com/wandb-production.appspot.com/ada4321/DiffHPE/td4d0m1u/requirements.txt?Expires=1689058231&GoogleAccessId=gorilla-files-url-signer-man%40wandb-production.iam.gserviceaccount.com&Signature=o22EGwF5VHWcXI3c2I1e%2Ft45ww8nvnIXiDWvOD4kQDe4KVVMReFr%2BrkkLP8gODT0aVFqTVXE%2F5KNN8aH3e5x6hXoftjZRW9TvcKvqa2bPRoWtQzO%2FbiEDC8xA086NkPu8LEvlbAsflvfzQe0j0Qib0kTJyGRX9we%2Flgci9HGoqgzgu1qnq8x72hFWzLqZvxKQ9AWyS9oMEm%2Bp%2FhY%2FEnJzJTPQ7RvtKDVdD31gZcG2KC0TKbZytVxHwGbTXSIlSS3yGa3AvSz08CGEAMns%2BV8i6pMdUWRKBUjCqumy4VI3D34lAEWykUxGh6QmHyoDr4IlE%2F5XzoCG5aC6TjGkY%2Bp2Q%3D%3D
2023-07-10 14:50:32,222 ERROR   wandb-upload_0:31569 [internal_api.py:upload_file():2194] upload_file request headers: {'User-Agent': 'python-requests/2.31.0', 'Accept-Encoding': 'gzip, deflate', 'Accept': '*/*', 'Connection': 'keep-alive', 'Content-Length': '910'}
2023-07-10 14:50:32,222 ERROR   wandb-upload_0:31569 [internal_api.py:upload_file():2196] upload_file response body: b'<!DOCTYPE html>\n<html lang=en>\n  <meta charset=utf-8>\n  <meta name=viewport content="initial-scale=1, minimum-scale=1, width=device-width">\n  <title>Error 404 (Not Found)!!1</title>\n  <style>\n    *{margin:0;padding:0}html,code{font:15px/22px arial,sans-serif}html{background:#fff;color:#222;padding:15px}body{margin:7% auto 0;max-width:390px;min-height:180px;padding:30px 0 15px}* > body{background:url(//www.google.com/images/errors/robot.png) 100% 5px no-repeat;padding-right:205px}p{margin:11px 0 22px;overflow:hidden}ins{color:#777;text-decoration:none}a img{border:0}@media screen and (max-width:772px){body{background:none;margin-top:0;max-width:none;padding-right:0}}#logo{background:url(//www.google.com/images/branding/googlelogo/1x/googlelogo_color_150x54dp.png) no-repeat;margin-left:-5px}@media only screen and (min-resolution:192dpi){#logo{background:url(//www.google.com/images/branding/googlelogo/2x/googlelogo_color_150x54dp.png) no-repeat 0% 0%/100% 100%;-moz-border-image:url(//www.google.com/images/branding/googlelogo/2x/googlelogo_color_150x54dp.png) 0}}@media only screen and (-webkit-min-device-pixel-ratio:2){#logo{background:url(//www.google.com/images/branding/googlelogo/2x/googlelogo_color_150x54dp.png) no-repeat;-webkit-background-size:100% 100%}}#logo{display:inline-block;height:54px;width:150px}\n  </style>\n  <a href=//www.google.com/><span id=logo aria-label=Google></span></a>\n  <p><b>404.</b> <ins>That\xe2\x80\x99s an error.</ins>\n  <p>The requested URL <code>/wandb-production.appspot.com/ada4321/DiffHPE/td4d0m1u/requirements.txt</code> was not found on this server.  <ins>That\xe2\x80\x99s all we know.</ins>\n'
2023-07-10 14:50:32,526 ERROR   wandb-upload_3:31569 [internal_api.py:upload_file():2192] upload_file exception https://storage.googleapis.com/wandb-production.appspot.com/ada4321/DiffHPE/td4d0m1u/conda-environment.yaml?Expires=1689058232&GoogleAccessId=gorilla-files-url-signer-man%40wandb-production.iam.gserviceaccount.com&Signature=Rg94Ka86S%2BCOrb3U5eFBQEA91Bcr2NsjBWxbaPCNKhXqvL5HhG%2Fm5u68R28PS6wpR9r2Dek%2F%2B5%2FFyKblTYhrccyMu%2FMU2O2TE91yBcvt07peOKMPLgbfP8xP7eb6vCbluyYn92OyUjadWsFeMYiLRo58Wj2ldM9HetxkXxnadjH7CUgIDXmsDWbOo27IiGgodnmpfmXlS01hQ2DJYFCS3fcTmQVEXSX5YcbEya0ndDvUPrhSXMi1fOeSOZjtRChajISzjvIL0i%2FEFAcfSwKCdWIAM%2F%2BhxU1ZNeXM%2FyfTn94CwmWd8d4aLT5DMtlzpxwEfLv0WRblqmPxD0yomiJtcw%3D%3D: 404 Client Error: Not Found for url: https://storage.googleapis.com/wandb-production.appspot.com/ada4321/DiffHPE/td4d0m1u/conda-environment.yaml?Expires=1689058232&GoogleAccessId=gorilla-files-url-signer-man%40wandb-production.iam.gserviceaccount.com&Signature=Rg94Ka86S%2BCOrb3U5eFBQEA91Bcr2NsjBWxbaPCNKhXqvL5HhG%2Fm5u68R28PS6wpR9r2Dek%2F%2B5%2FFyKblTYhrccyMu%2FMU2O2TE91yBcvt07peOKMPLgbfP8xP7eb6vCbluyYn92OyUjadWsFeMYiLRo58Wj2ldM9HetxkXxnadjH7CUgIDXmsDWbOo27IiGgodnmpfmXlS01hQ2DJYFCS3fcTmQVEXSX5YcbEya0ndDvUPrhSXMi1fOeSOZjtRChajISzjvIL0i%2FEFAcfSwKCdWIAM%2F%2BhxU1ZNeXM%2FyfTn94CwmWd8d4aLT5DMtlzpxwEfLv0WRblqmPxD0yomiJtcw%3D%3D
2023-07-10 14:50:32,526 ERROR   wandb-upload_3:31569 [internal_api.py:upload_file():2194] upload_file request headers: {'User-Agent': 'python-requests/2.31.0', 'Accept-Encoding': 'gzip, deflate', 'Accept': '*/*', 'Connection': 'keep-alive', 'Content-Length': '1903'}
2023-07-10 14:50:32,526 ERROR   wandb-upload_3:31569 [internal_api.py:upload_file():2196] upload_file response body: b'<!DOCTYPE html>\n<html lang=en>\n  <meta charset=utf-8>\n  <meta name=viewport content="initial-scale=1, minimum-scale=1, width=device-width">\n  <title>Error 404 (Not Found)!!1</title>\n  <style>\n    *{margin:0;padding:0}html,code{font:15px/22px arial,sans-serif}html{background:#fff;color:#222;padding:15px}body{margin:7% auto 0;max-width:390px;min-height:180px;padding:30px 0 15px}* > body{background:url(//www.google.com/images/errors/robot.png) 100% 5px no-repeat;padding-right:205px}p{margin:11px 0 22px;overflow:hidden}ins{color:#777;text-decoration:none}a img{border:0}@media screen and (max-width:772px){body{background:none;margin-top:0;max-width:none;padding-right:0}}#logo{background:url(//www.google.com/images/branding/googlelogo/1x/googlelogo_color_150x54dp.png) no-repeat;margin-left:-5px}@media only screen and (min-resolution:192dpi){#logo{background:url(//www.google.com/images/branding/googlelogo/2x/googlelogo_color_150x54dp.png) no-repeat 0% 0%/100% 100%;-moz-border-image:url(//www.google.com/images/branding/googlelogo/2x/googlelogo_color_150x54dp.png) 0}}@media only screen and (-webkit-min-device-pixel-ratio:2){#logo{background:url(//www.google.com/images/branding/googlelogo/2x/googlelogo_color_150x54dp.png) no-repeat;-webkit-background-size:100% 100%}}#logo{display:inline-block;height:54px;width:150px}\n  </style>\n  <a href=//www.google.com/><span id=logo aria-label=Google></span></a>\n  <p><b>404.</b> <ins>That\xe2\x80\x99s an error.</ins>\n  <p>The requested URL <code>/wandb-production.appspot.com/ada4321/DiffHPE/td4d0m1u/conda-environment.yaml</code> was not found on this server.  <ins>That\xe2\x80\x99s all we know.</ins>\n'
2023-07-10 14:50:32,566 ERROR   wandb-upload_4:31569 [internal_api.py:upload_file():2192] upload_file exception https://storage.googleapis.com/wandb-production.appspot.com/ada4321/DiffHPE/td4d0m1u/output.log?Expires=1689058232&GoogleAccessId=gorilla-files-url-signer-man%40wandb-production.iam.gserviceaccount.com&Signature=guHW9nldUaV0abWasAuAEEbM9sziAn0ljOdBVUVe16Nfx%2F4JSfcHjrBsIB2FJdA6zkTVSIRFAWh%2Fe9Ni%2Fal3Skrgn2G1zIi4XeK10jxYnV3HStwa0gMeKJUMoO64TDa%2FNDzij0pjOhqS5HyuwaPtwpPYtajZSGPdHgTWhAvDHjKdvHw7GoJkeAU10UNJG%2FUbs0Ozs1RJsy7Y6BU153JfuxTanFlFA1Zm7WPZszAfKHbqAuOg4TvmXaJjO1gKbT8Lm1j%2FpyS8U2ntyb8Vtwlwc4RJNuDREC5SV%2FtCWbECqgGGnc%2F6Skxds%2FYWdfB8Y2CNr17Vsm9tpjWf9UTLdiXatA%3D%3D: 404 Client Error: Not Found for url: https://storage.googleapis.com/wandb-production.appspot.com/ada4321/DiffHPE/td4d0m1u/output.log?Expires=1689058232&GoogleAccessId=gorilla-files-url-signer-man%40wandb-production.iam.gserviceaccount.com&Signature=guHW9nldUaV0abWasAuAEEbM9sziAn0ljOdBVUVe16Nfx%2F4JSfcHjrBsIB2FJdA6zkTVSIRFAWh%2Fe9Ni%2Fal3Skrgn2G1zIi4XeK10jxYnV3HStwa0gMeKJUMoO64TDa%2FNDzij0pjOhqS5HyuwaPtwpPYtajZSGPdHgTWhAvDHjKdvHw7GoJkeAU10UNJG%2FUbs0Ozs1RJsy7Y6BU153JfuxTanFlFA1Zm7WPZszAfKHbqAuOg4TvmXaJjO1gKbT8Lm1j%2FpyS8U2ntyb8Vtwlwc4RJNuDREC5SV%2FtCWbECqgGGnc%2F6Skxds%2FYWdfB8Y2CNr17Vsm9tpjWf9UTLdiXatA%3D%3D
2023-07-10 14:50:32,566 ERROR   wandb-upload_4:31569 [internal_api.py:upload_file():2194] upload_file request headers: {'User-Agent': 'python-requests/2.31.0', 'Accept-Encoding': 'gzip, deflate', 'Accept': '*/*', 'Connection': 'keep-alive', 'Content-Length': '2659'}
2023-07-10 14:50:32,566 ERROR   wandb-upload_4:31569 [internal_api.py:upload_file():2196] upload_file response body: b'<!DOCTYPE html>\n<html lang=en>\n  <meta charset=utf-8>\n  <meta name=viewport content="initial-scale=1, minimum-scale=1, width=device-width">\n  <title>Error 404 (Not Found)!!1</title>\n  <style>\n    *{margin:0;padding:0}html,code{font:15px/22px arial,sans-serif}html{background:#fff;color:#222;padding:15px}body{margin:7% auto 0;max-width:390px;min-height:180px;padding:30px 0 15px}* > body{background:url(//www.google.com/images/errors/robot.png) 100% 5px no-repeat;padding-right:205px}p{margin:11px 0 22px;overflow:hidden}ins{color:#777;text-decoration:none}a img{border:0}@media screen and (max-width:772px){body{background:none;margin-top:0;max-width:none;padding-right:0}}#logo{background:url(//www.google.com/images/branding/googlelogo/1x/googlelogo_color_150x54dp.png) no-repeat;margin-left:-5px}@media only screen and (min-resolution:192dpi){#logo{background:url(//www.google.com/images/branding/googlelogo/2x/googlelogo_color_150x54dp.png) no-repeat 0% 0%/100% 100%;-moz-border-image:url(//www.google.com/images/branding/googlelogo/2x/googlelogo_color_150x54dp.png) 0}}@media only screen and (-webkit-min-device-pixel-ratio:2){#logo{background:url(//www.google.com/images/branding/googlelogo/2x/googlelogo_color_150x54dp.png) no-repeat;-webkit-background-size:100% 100%}}#logo{display:inline-block;height:54px;width:150px}\n  </style>\n  <a href=//www.google.com/><span id=logo aria-label=Google></span></a>\n  <p><b>404.</b> <ins>That\xe2\x80\x99s an error.</ins>\n  <p>The requested URL <code>/wandb-production.appspot.com/ada4321/DiffHPE/td4d0m1u/output.log</code> was not found on this server.  <ins>That\xe2\x80\x99s all we know.</ins>\n'
2023-07-10 14:50:32,613 ERROR   wandb-upload_2:31569 [internal_api.py:upload_file():2192] upload_file exception https://storage.googleapis.com/wandb-production.appspot.com/ada4321/DiffHPE/td4d0m1u/wandb-summary.json?Expires=1689058232&GoogleAccessId=gorilla-files-url-signer-man%40wandb-production.iam.gserviceaccount.com&Signature=HlNJIOXQs3w1dSCFvdUlqb0c6qj4i2E81JVj2p3QfTUO7eSX8hg4o7Vla5519q7FZeZiXDrOnlVsXmRpcEHmGbuYohVBI13QFKIjxO6OihnW7fku4shwHXOmUOuufGlzqgfhJI2aGN8qeY4MtFWmKz08kM794NdXDte9YKNInP9btW3mrkF%2FCMHwC9M%2FU3Ou5FCc6RgaKF9cNbNDBBEyo%2BZ3WqmqTFrkC%2BXln7RS2zT5%2Fv%2BJJS2hLJflESYUzZRCdN90f3l4ReaXS9mrEX4%2FGvUNZoj0lnJNR9Wx1OZuW%2FcvrhNc2YZ8zjROspqGoTxCVwvsgFgU8bLnMRj5seRD3w%3D%3D: 404 Client Error: Not Found for url: https://storage.googleapis.com/wandb-production.appspot.com/ada4321/DiffHPE/td4d0m1u/wandb-summary.json?Expires=1689058232&GoogleAccessId=gorilla-files-url-signer-man%40wandb-production.iam.gserviceaccount.com&Signature=HlNJIOXQs3w1dSCFvdUlqb0c6qj4i2E81JVj2p3QfTUO7eSX8hg4o7Vla5519q7FZeZiXDrOnlVsXmRpcEHmGbuYohVBI13QFKIjxO6OihnW7fku4shwHXOmUOuufGlzqgfhJI2aGN8qeY4MtFWmKz08kM794NdXDte9YKNInP9btW3mrkF%2FCMHwC9M%2FU3Ou5FCc6RgaKF9cNbNDBBEyo%2BZ3WqmqTFrkC%2BXln7RS2zT5%2Fv%2BJJS2hLJflESYUzZRCdN90f3l4ReaXS9mrEX4%2FGvUNZoj0lnJNR9Wx1OZuW%2FcvrhNc2YZ8zjROspqGoTxCVwvsgFgU8bLnMRj5seRD3w%3D%3D
2023-07-10 14:50:32,613 ERROR   wandb-upload_2:31569 [internal_api.py:upload_file():2194] upload_file request headers: {'User-Agent': 'python-requests/2.31.0', 'Accept-Encoding': 'gzip, deflate', 'Accept': '*/*', 'Connection': 'keep-alive', 'Content-Length': '26'}
2023-07-10 14:50:32,613 ERROR   wandb-upload_2:31569 [internal_api.py:upload_file():2196] upload_file response body: b'<!DOCTYPE html>\n<html lang=en>\n  <meta charset=utf-8>\n  <meta name=viewport content="initial-scale=1, minimum-scale=1, width=device-width">\n  <title>Error 404 (Not Found)!!1</title>\n  <style>\n    *{margin:0;padding:0}html,code{font:15px/22px arial,sans-serif}html{background:#fff;color:#222;padding:15px}body{margin:7% auto 0;max-width:390px;min-height:180px;padding:30px 0 15px}* > body{background:url(//www.google.com/images/errors/robot.png) 100% 5px no-repeat;padding-right:205px}p{margin:11px 0 22px;overflow:hidden}ins{color:#777;text-decoration:none}a img{border:0}@media screen and (max-width:772px){body{background:none;margin-top:0;max-width:none;padding-right:0}}#logo{background:url(//www.google.com/images/branding/googlelogo/1x/googlelogo_color_150x54dp.png) no-repeat;margin-left:-5px}@media only screen and (min-resolution:192dpi){#logo{background:url(//www.google.com/images/branding/googlelogo/2x/googlelogo_color_150x54dp.png) no-repeat 0% 0%/100% 100%;-moz-border-image:url(//www.google.com/images/branding/googlelogo/2x/googlelogo_color_150x54dp.png) 0}}@media only screen and (-webkit-min-device-pixel-ratio:2){#logo{background:url(//www.google.com/images/branding/googlelogo/2x/googlelogo_color_150x54dp.png) no-repeat;-webkit-background-size:100% 100%}}#logo{display:inline-block;height:54px;width:150px}\n  </style>\n  <a href=//www.google.com/><span id=logo aria-label=Google></span></a>\n  <p><b>404.</b> <ins>That\xe2\x80\x99s an error.</ins>\n  <p>The requested URL <code>/wandb-production.appspot.com/ada4321/DiffHPE/td4d0m1u/wandb-summary.json</code> was not found on this server.  <ins>That\xe2\x80\x99s all we know.</ins>\n'
2023-07-10 14:50:33,240 ERROR   wandb-upload_1:31569 [upload_job.py:push():136] Failed to upload file: /home/zhuhe/HPE-with-Diffusion/wandb/run-20230710_145026-td4d0m1u/files/config.yaml
Traceback (most recent call last):
  File "/home/zhuhe/.conda/envs/diffhpe/lib/python3.9/site-packages/wandb/apis/normalize.py", line 41, in wrapper
    return func(*args, **kwargs)
  File "/home/zhuhe/.conda/envs/diffhpe/lib/python3.9/site-packages/wandb/sdk/lib/retry.py", line 212, in wrapped_fn
    return retrier(*args, **kargs)
  File "/home/zhuhe/.conda/envs/diffhpe/lib/python3.9/site-packages/wandb/sdk/lib/retry.py", line 131, in __call__
    result = self._call_fn(*args, **kwargs)
  File "/home/zhuhe/.conda/envs/diffhpe/lib/python3.9/site-packages/wandb/sdk/internal/internal_api.py", line 2218, in upload_file
    wandb._sentry.reraise(e)
  File "/home/zhuhe/.conda/envs/diffhpe/lib/python3.9/site-packages/wandb/analytics/sentry.py", line 146, in reraise
    raise exc.with_traceback(sys.exc_info()[2])
  File "/home/zhuhe/.conda/envs/diffhpe/lib/python3.9/site-packages/wandb/sdk/internal/internal_api.py", line 2190, in upload_file
    response.raise_for_status()
  File "/home/zhuhe/.conda/envs/diffhpe/lib/python3.9/site-packages/requests/models.py", line 1021, in raise_for_status
    raise HTTPError(http_error_msg, response=self)
requests.exceptions.HTTPError: 404 Client Error: Not Found for url: https://storage.googleapis.com/wandb-production.appspot.com/ada4321/DiffHPE/td4d0m1u/config.yaml?Expires=1689058231&GoogleAccessId=gorilla-files-url-signer-man%40wandb-production.iam.gserviceaccount.com&Signature=dJNzcVKIYFjh0l6u11KnfUlSRfRlc0GbtRFA0AbPj0qunhqARRPIVZ%2FHRVwA0MpYuKKnyBZFS9ttGg3YUI%2BfkkxcH%2BGySnfCuIG%2FI5IySzIIhccR9Jty8MAd%2Bn8jWBGWBZYQCbEcEJP0koudtW7XabzceaRoZfmZ7dFIGgVQg7WV02jbPulS8PYyLyyCKkfnGsnhV5h%2B55CYk%2B7dDAKSayujC0zEL11jGjWRP9ET2N%2BJ%2FRmZYyrhvqnQVfeGy8jsOOQLr3npQDs%2ByDxAklhKvGa5xZhDXpfWkKdrw3tUzHOAmL%2BJI1TBkaSr3ksJ8xZs4hIM2whdjEFOW16FGFnvVA%3D%3D

During handling of the above exception, another exception occurred:

Traceback (most recent call last):
  File "/home/zhuhe/.conda/envs/diffhpe/lib/python3.9/site-packages/wandb/filesync/upload_job.py", line 127, in push
    self._api.upload_file_retry(
  File "/home/zhuhe/.conda/envs/diffhpe/lib/python3.9/site-packages/wandb/apis/normalize.py", line 51, in wrapper
    raise CommError(message, error)
wandb.errors.CommError: <Response [404]>
2023-07-10 14:50:33,240 ERROR   wandb-upload_0:31569 [upload_job.py:push():136] Failed to upload file: /home/zhuhe/HPE-with-Diffusion/wandb/run-20230710_145026-td4d0m1u/files/requirements.txt
Traceback (most recent call last):
  File "/home/zhuhe/.conda/envs/diffhpe/lib/python3.9/site-packages/wandb/apis/normalize.py", line 41, in wrapper
    return func(*args, **kwargs)
  File "/home/zhuhe/.conda/envs/diffhpe/lib/python3.9/site-packages/wandb/sdk/lib/retry.py", line 212, in wrapped_fn
    return retrier(*args, **kargs)
  File "/home/zhuhe/.conda/envs/diffhpe/lib/python3.9/site-packages/wandb/sdk/lib/retry.py", line 131, in __call__
    result = self._call_fn(*args, **kwargs)
  File "/home/zhuhe/.conda/envs/diffhpe/lib/python3.9/site-packages/wandb/sdk/internal/internal_api.py", line 2218, in upload_file
    wandb._sentry.reraise(e)
  File "/home/zhuhe/.conda/envs/diffhpe/lib/python3.9/site-packages/wandb/analytics/sentry.py", line 146, in reraise
    raise exc.with_traceback(sys.exc_info()[2])
  File "/home/zhuhe/.conda/envs/diffhpe/lib/python3.9/site-packages/wandb/sdk/internal/internal_api.py", line 2190, in upload_file
    response.raise_for_status()
  File "/home/zhuhe/.conda/envs/diffhpe/lib/python3.9/site-packages/requests/models.py", line 1021, in raise_for_status
    raise HTTPError(http_error_msg, response=self)
requests.exceptions.HTTPError: 404 Client Error: Not Found for url: https://storage.googleapis.com/wandb-production.appspot.com/ada4321/DiffHPE/td4d0m1u/requirements.txt?Expires=1689058231&GoogleAccessId=gorilla-files-url-signer-man%40wandb-production.iam.gserviceaccount.com&Signature=o22EGwF5VHWcXI3c2I1e%2Ft45ww8nvnIXiDWvOD4kQDe4KVVMReFr%2BrkkLP8gODT0aVFqTVXE%2F5KNN8aH3e5x6hXoftjZRW9TvcKvqa2bPRoWtQzO%2FbiEDC8xA086NkPu8LEvlbAsflvfzQe0j0Qib0kTJyGRX9we%2Flgci9HGoqgzgu1qnq8x72hFWzLqZvxKQ9AWyS9oMEm%2Bp%2FhY%2FEnJzJTPQ7RvtKDVdD31gZcG2KC0TKbZytVxHwGbTXSIlSS3yGa3AvSz08CGEAMns%2BV8i6pMdUWRKBUjCqumy4VI3D34lAEWykUxGh6QmHyoDr4IlE%2F5XzoCG5aC6TjGkY%2Bp2Q%3D%3D

During handling of the above exception, another exception occurred:

Traceback (most recent call last):
  File "/home/zhuhe/.conda/envs/diffhpe/lib/python3.9/site-packages/wandb/filesync/upload_job.py", line 127, in push
    self._api.upload_file_retry(
  File "/home/zhuhe/.conda/envs/diffhpe/lib/python3.9/site-packages/wandb/apis/normalize.py", line 51, in wrapper
    raise CommError(message, error)
wandb.errors.CommError: <Response [404]>
2023-07-10 14:50:33,240 ERROR   wandb-upload_3:31569 [upload_job.py:push():136] Failed to upload file: /home/zhuhe/HPE-with-Diffusion/wandb/run-20230710_145026-td4d0m1u/files/conda-environment.yaml
Traceback (most recent call last):
  File "/home/zhuhe/.conda/envs/diffhpe/lib/python3.9/site-packages/wandb/apis/normalize.py", line 41, in wrapper
    return func(*args, **kwargs)
  File "/home/zhuhe/.conda/envs/diffhpe/lib/python3.9/site-packages/wandb/sdk/lib/retry.py", line 212, in wrapped_fn
    return retrier(*args, **kargs)
  File "/home/zhuhe/.conda/envs/diffhpe/lib/python3.9/site-packages/wandb/sdk/lib/retry.py", line 131, in __call__
    result = self._call_fn(*args, **kwargs)
  File "/home/zhuhe/.conda/envs/diffhpe/lib/python3.9/site-packages/wandb/sdk/internal/internal_api.py", line 2218, in upload_file
    wandb._sentry.reraise(e)
  File "/home/zhuhe/.conda/envs/diffhpe/lib/python3.9/site-packages/wandb/analytics/sentry.py", line 146, in reraise
    raise exc.with_traceback(sys.exc_info()[2])
  File "/home/zhuhe/.conda/envs/diffhpe/lib/python3.9/site-packages/wandb/sdk/internal/internal_api.py", line 2190, in upload_file
    response.raise_for_status()
  File "/home/zhuhe/.conda/envs/diffhpe/lib/python3.9/site-packages/requests/models.py", line 1021, in raise_for_status
    raise HTTPError(http_error_msg, response=self)
requests.exceptions.HTTPError: 404 Client Error: Not Found for url: https://storage.googleapis.com/wandb-production.appspot.com/ada4321/DiffHPE/td4d0m1u/conda-environment.yaml?Expires=1689058232&GoogleAccessId=gorilla-files-url-signer-man%40wandb-production.iam.gserviceaccount.com&Signature=Rg94Ka86S%2BCOrb3U5eFBQEA91Bcr2NsjBWxbaPCNKhXqvL5HhG%2Fm5u68R28PS6wpR9r2Dek%2F%2B5%2FFyKblTYhrccyMu%2FMU2O2TE91yBcvt07peOKMPLgbfP8xP7eb6vCbluyYn92OyUjadWsFeMYiLRo58Wj2ldM9HetxkXxnadjH7CUgIDXmsDWbOo27IiGgodnmpfmXlS01hQ2DJYFCS3fcTmQVEXSX5YcbEya0ndDvUPrhSXMi1fOeSOZjtRChajISzjvIL0i%2FEFAcfSwKCdWIAM%2F%2BhxU1ZNeXM%2FyfTn94CwmWd8d4aLT5DMtlzpxwEfLv0WRblqmPxD0yomiJtcw%3D%3D

During handling of the above exception, another exception occurred:

Traceback (most recent call last):
  File "/home/zhuhe/.conda/envs/diffhpe/lib/python3.9/site-packages/wandb/filesync/upload_job.py", line 127, in push
    self._api.upload_file_retry(
  File "/home/zhuhe/.conda/envs/diffhpe/lib/python3.9/site-packages/wandb/apis/normalize.py", line 51, in wrapper
    raise CommError(message, error)
wandb.errors.CommError: <Response [404]>
2023-07-10 14:50:33,241 ERROR   wandb-upload_4:31569 [upload_job.py:push():136] Failed to upload file: /home/zhuhe/HPE-with-Diffusion/wandb/run-20230710_145026-td4d0m1u/files/output.log
Traceback (most recent call last):
  File "/home/zhuhe/.conda/envs/diffhpe/lib/python3.9/site-packages/wandb/apis/normalize.py", line 41, in wrapper
    return func(*args, **kwargs)
  File "/home/zhuhe/.conda/envs/diffhpe/lib/python3.9/site-packages/wandb/sdk/lib/retry.py", line 212, in wrapped_fn
    return retrier(*args, **kargs)
  File "/home/zhuhe/.conda/envs/diffhpe/lib/python3.9/site-packages/wandb/sdk/lib/retry.py", line 131, in __call__
    result = self._call_fn(*args, **kwargs)
  File "/home/zhuhe/.conda/envs/diffhpe/lib/python3.9/site-packages/wandb/sdk/internal/internal_api.py", line 2218, in upload_file
    wandb._sentry.reraise(e)
  File "/home/zhuhe/.conda/envs/diffhpe/lib/python3.9/site-packages/wandb/analytics/sentry.py", line 146, in reraise
    raise exc.with_traceback(sys.exc_info()[2])
  File "/home/zhuhe/.conda/envs/diffhpe/lib/python3.9/site-packages/wandb/sdk/internal/internal_api.py", line 2190, in upload_file
    response.raise_for_status()
  File "/home/zhuhe/.conda/envs/diffhpe/lib/python3.9/site-packages/requests/models.py", line 1021, in raise_for_status
    raise HTTPError(http_error_msg, response=self)
requests.exceptions.HTTPError: 404 Client Error: Not Found for url: https://storage.googleapis.com/wandb-production.appspot.com/ada4321/DiffHPE/td4d0m1u/output.log?Expires=1689058232&GoogleAccessId=gorilla-files-url-signer-man%40wandb-production.iam.gserviceaccount.com&Signature=guHW9nldUaV0abWasAuAEEbM9sziAn0ljOdBVUVe16Nfx%2F4JSfcHjrBsIB2FJdA6zkTVSIRFAWh%2Fe9Ni%2Fal3Skrgn2G1zIi4XeK10jxYnV3HStwa0gMeKJUMoO64TDa%2FNDzij0pjOhqS5HyuwaPtwpPYtajZSGPdHgTWhAvDHjKdvHw7GoJkeAU10UNJG%2FUbs0Ozs1RJsy7Y6BU153JfuxTanFlFA1Zm7WPZszAfKHbqAuOg4TvmXaJjO1gKbT8Lm1j%2FpyS8U2ntyb8Vtwlwc4RJNuDREC5SV%2FtCWbECqgGGnc%2F6Skxds%2FYWdfB8Y2CNr17Vsm9tpjWf9UTLdiXatA%3D%3D

During handling of the above exception, another exception occurred:

Traceback (most recent call last):
  File "/home/zhuhe/.conda/envs/diffhpe/lib/python3.9/site-packages/wandb/filesync/upload_job.py", line 127, in push
    self._api.upload_file_retry(
  File "/home/zhuhe/.conda/envs/diffhpe/lib/python3.9/site-packages/wandb/apis/normalize.py", line 51, in wrapper
    raise CommError(message, error)
wandb.errors.CommError: <Response [404]>
2023-07-10 14:50:33,241 ERROR   wandb-upload_2:31569 [upload_job.py:push():136] Failed to upload file: /home/zhuhe/HPE-with-Diffusion/wandb/run-20230710_145026-td4d0m1u/files/wandb-summary.json
Traceback (most recent call last):
  File "/home/zhuhe/.conda/envs/diffhpe/lib/python3.9/site-packages/wandb/apis/normalize.py", line 41, in wrapper
    return func(*args, **kwargs)
  File "/home/zhuhe/.conda/envs/diffhpe/lib/python3.9/site-packages/wandb/sdk/lib/retry.py", line 212, in wrapped_fn
    return retrier(*args, **kargs)
  File "/home/zhuhe/.conda/envs/diffhpe/lib/python3.9/site-packages/wandb/sdk/lib/retry.py", line 131, in __call__
    result = self._call_fn(*args, **kwargs)
  File "/home/zhuhe/.conda/envs/diffhpe/lib/python3.9/site-packages/wandb/sdk/internal/internal_api.py", line 2218, in upload_file
    wandb._sentry.reraise(e)
  File "/home/zhuhe/.conda/envs/diffhpe/lib/python3.9/site-packages/wandb/analytics/sentry.py", line 146, in reraise
    raise exc.with_traceback(sys.exc_info()[2])
  File "/home/zhuhe/.conda/envs/diffhpe/lib/python3.9/site-packages/wandb/sdk/internal/internal_api.py", line 2190, in upload_file
    response.raise_for_status()
  File "/home/zhuhe/.conda/envs/diffhpe/lib/python3.9/site-packages/requests/models.py", line 1021, in raise_for_status
    raise HTTPError(http_error_msg, response=self)
requests.exceptions.HTTPError: 404 Client Error: Not Found for url: https://storage.googleapis.com/wandb-production.appspot.com/ada4321/DiffHPE/td4d0m1u/wandb-summary.json?Expires=1689058232&GoogleAccessId=gorilla-files-url-signer-man%40wandb-production.iam.gserviceaccount.com&Signature=HlNJIOXQs3w1dSCFvdUlqb0c6qj4i2E81JVj2p3QfTUO7eSX8hg4o7Vla5519q7FZeZiXDrOnlVsXmRpcEHmGbuYohVBI13QFKIjxO6OihnW7fku4shwHXOmUOuufGlzqgfhJI2aGN8qeY4MtFWmKz08kM794NdXDte9YKNInP9btW3mrkF%2FCMHwC9M%2FU3Ou5FCc6RgaKF9cNbNDBBEyo%2BZ3WqmqTFrkC%2BXln7RS2zT5%2Fv%2BJJS2hLJflESYUzZRCdN90f3l4ReaXS9mrEX4%2FGvUNZoj0lnJNR9Wx1OZuW%2FcvrhNc2YZ8zjROspqGoTxCVwvsgFgU8bLnMRj5seRD3w%3D%3D

During handling of the above exception, another exception occurred:

Traceback (most recent call last):
  File "/home/zhuhe/.conda/envs/diffhpe/lib/python3.9/site-packages/wandb/filesync/upload_job.py", line 127, in push
    self._api.upload_file_retry(
  File "/home/zhuhe/.conda/envs/diffhpe/lib/python3.9/site-packages/wandb/apis/normalize.py", line 51, in wrapper
    raise CommError(message, error)
wandb.errors.CommError: <Response [404]>
2023-07-10 14:50:34,315 ERROR   Thread-11 :31569 [step_upload.py:_handle_event():200] Failed to upload file: /home/zhuhe/HPE-with-Diffusion/wandb/run-20230710_145026-td4d0m1u/files/config.yaml
Traceback (most recent call last):
  File "/home/zhuhe/.conda/envs/diffhpe/lib/python3.9/site-packages/wandb/apis/normalize.py", line 41, in wrapper
    return func(*args, **kwargs)
  File "/home/zhuhe/.conda/envs/diffhpe/lib/python3.9/site-packages/wandb/sdk/lib/retry.py", line 212, in wrapped_fn
    return retrier(*args, **kargs)
  File "/home/zhuhe/.conda/envs/diffhpe/lib/python3.9/site-packages/wandb/sdk/lib/retry.py", line 131, in __call__
    result = self._call_fn(*args, **kwargs)
  File "/home/zhuhe/.conda/envs/diffhpe/lib/python3.9/site-packages/wandb/sdk/internal/internal_api.py", line 2218, in upload_file
    wandb._sentry.reraise(e)
  File "/home/zhuhe/.conda/envs/diffhpe/lib/python3.9/site-packages/wandb/analytics/sentry.py", line 146, in reraise
    raise exc.with_traceback(sys.exc_info()[2])
  File "/home/zhuhe/.conda/envs/diffhpe/lib/python3.9/site-packages/wandb/sdk/internal/internal_api.py", line 2190, in upload_file
    response.raise_for_status()
  File "/home/zhuhe/.conda/envs/diffhpe/lib/python3.9/site-packages/requests/models.py", line 1021, in raise_for_status
    raise HTTPError(http_error_msg, response=self)
requests.exceptions.HTTPError: 404 Client Error: Not Found for url: https://storage.googleapis.com/wandb-production.appspot.com/ada4321/DiffHPE/td4d0m1u/config.yaml?Expires=1689058231&GoogleAccessId=gorilla-files-url-signer-man%40wandb-production.iam.gserviceaccount.com&Signature=dJNzcVKIYFjh0l6u11KnfUlSRfRlc0GbtRFA0AbPj0qunhqARRPIVZ%2FHRVwA0MpYuKKnyBZFS9ttGg3YUI%2BfkkxcH%2BGySnfCuIG%2FI5IySzIIhccR9Jty8MAd%2Bn8jWBGWBZYQCbEcEJP0koudtW7XabzceaRoZfmZ7dFIGgVQg7WV02jbPulS8PYyLyyCKkfnGsnhV5h%2B55CYk%2B7dDAKSayujC0zEL11jGjWRP9ET2N%2BJ%2FRmZYyrhvqnQVfeGy8jsOOQLr3npQDs%2ByDxAklhKvGa5xZhDXpfWkKdrw3tUzHOAmL%2BJI1TBkaSr3ksJ8xZs4hIM2whdjEFOW16FGFnvVA%3D%3D

During handling of the above exception, another exception occurred:

Traceback (most recent call last):
  File "/home/zhuhe/.conda/envs/diffhpe/lib/python3.9/concurrent/futures/thread.py", line 58, in run
    result = self.fn(*self.args, **self.kwargs)
  File "/home/zhuhe/.conda/envs/diffhpe/lib/python3.9/site-packages/wandb/filesync/step_upload.py", line 288, in run_and_notify
    self._do_upload_sync(event)
  File "/home/zhuhe/.conda/envs/diffhpe/lib/python3.9/site-packages/wandb/filesync/step_upload.py", line 330, in _do_upload_sync
    job.run()
  File "/home/zhuhe/.conda/envs/diffhpe/lib/python3.9/site-packages/wandb/filesync/upload_job.py", line 57, in run
    self.push()
  File "/home/zhuhe/.conda/envs/diffhpe/lib/python3.9/site-packages/wandb/filesync/upload_job.py", line 127, in push
    self._api.upload_file_retry(
  File "/home/zhuhe/.conda/envs/diffhpe/lib/python3.9/site-packages/wandb/apis/normalize.py", line 51, in wrapper
    raise CommError(message, error)
wandb.errors.CommError: <Response [404]>
2023-07-10 14:50:34,316 ERROR   Thread-11 :31569 [step_upload.py:_handle_event():200] Failed to upload file: /home/zhuhe/HPE-with-Diffusion/wandb/run-20230710_145026-td4d0m1u/files/output.log
Traceback (most recent call last):
  File "/home/zhuhe/.conda/envs/diffhpe/lib/python3.9/site-packages/wandb/apis/normalize.py", line 41, in wrapper
    return func(*args, **kwargs)
  File "/home/zhuhe/.conda/envs/diffhpe/lib/python3.9/site-packages/wandb/sdk/lib/retry.py", line 212, in wrapped_fn
    return retrier(*args, **kargs)
  File "/home/zhuhe/.conda/envs/diffhpe/lib/python3.9/site-packages/wandb/sdk/lib/retry.py", line 131, in __call__
    result = self._call_fn(*args, **kwargs)
  File "/home/zhuhe/.conda/envs/diffhpe/lib/python3.9/site-packages/wandb/sdk/internal/internal_api.py", line 2218, in upload_file
    wandb._sentry.reraise(e)
  File "/home/zhuhe/.conda/envs/diffhpe/lib/python3.9/site-packages/wandb/analytics/sentry.py", line 146, in reraise
    raise exc.with_traceback(sys.exc_info()[2])
  File "/home/zhuhe/.conda/envs/diffhpe/lib/python3.9/site-packages/wandb/sdk/internal/internal_api.py", line 2190, in upload_file
    response.raise_for_status()
  File "/home/zhuhe/.conda/envs/diffhpe/lib/python3.9/site-packages/requests/models.py", line 1021, in raise_for_status
    raise HTTPError(http_error_msg, response=self)
requests.exceptions.HTTPError: 404 Client Error: Not Found for url: https://storage.googleapis.com/wandb-production.appspot.com/ada4321/DiffHPE/td4d0m1u/output.log?Expires=1689058232&GoogleAccessId=gorilla-files-url-signer-man%40wandb-production.iam.gserviceaccount.com&Signature=guHW9nldUaV0abWasAuAEEbM9sziAn0ljOdBVUVe16Nfx%2F4JSfcHjrBsIB2FJdA6zkTVSIRFAWh%2Fe9Ni%2Fal3Skrgn2G1zIi4XeK10jxYnV3HStwa0gMeKJUMoO64TDa%2FNDzij0pjOhqS5HyuwaPtwpPYtajZSGPdHgTWhAvDHjKdvHw7GoJkeAU10UNJG%2FUbs0Ozs1RJsy7Y6BU153JfuxTanFlFA1Zm7WPZszAfKHbqAuOg4TvmXaJjO1gKbT8Lm1j%2FpyS8U2ntyb8Vtwlwc4RJNuDREC5SV%2FtCWbECqgGGnc%2F6Skxds%2FYWdfB8Y2CNr17Vsm9tpjWf9UTLdiXatA%3D%3D

During handling of the above exception, another exception occurred:

Traceback (most recent call last):
  File "/home/zhuhe/.conda/envs/diffhpe/lib/python3.9/concurrent/futures/thread.py", line 58, in run
    result = self.fn(*self.args, **self.kwargs)
  File "/home/zhuhe/.conda/envs/diffhpe/lib/python3.9/site-packages/wandb/filesync/step_upload.py", line 288, in run_and_notify
    self._do_upload_sync(event)
  File "/home/zhuhe/.conda/envs/diffhpe/lib/python3.9/site-packages/wandb/filesync/step_upload.py", line 330, in _do_upload_sync
    job.run()
  File "/home/zhuhe/.conda/envs/diffhpe/lib/python3.9/site-packages/wandb/filesync/upload_job.py", line 57, in run
    self.push()
  File "/home/zhuhe/.conda/envs/diffhpe/lib/python3.9/site-packages/wandb/filesync/upload_job.py", line 127, in push
    self._api.upload_file_retry(
  File "/home/zhuhe/.conda/envs/diffhpe/lib/python3.9/site-packages/wandb/apis/normalize.py", line 51, in wrapper
    raise CommError(message, error)
wandb.errors.CommError: <Response [404]>
2023-07-10 14:50:34,316 ERROR   Thread-11 :31569 [step_upload.py:_handle_event():200] Failed to upload file: /home/zhuhe/HPE-with-Diffusion/wandb/run-20230710_145026-td4d0m1u/files/wandb-summary.json
Traceback (most recent call last):
  File "/home/zhuhe/.conda/envs/diffhpe/lib/python3.9/site-packages/wandb/apis/normalize.py", line 41, in wrapper
    return func(*args, **kwargs)
  File "/home/zhuhe/.conda/envs/diffhpe/lib/python3.9/site-packages/wandb/sdk/lib/retry.py", line 212, in wrapped_fn
    return retrier(*args, **kargs)
  File "/home/zhuhe/.conda/envs/diffhpe/lib/python3.9/site-packages/wandb/sdk/lib/retry.py", line 131, in __call__
    result = self._call_fn(*args, **kwargs)
  File "/home/zhuhe/.conda/envs/diffhpe/lib/python3.9/site-packages/wandb/sdk/internal/internal_api.py", line 2218, in upload_file
    wandb._sentry.reraise(e)
  File "/home/zhuhe/.conda/envs/diffhpe/lib/python3.9/site-packages/wandb/analytics/sentry.py", line 146, in reraise
    raise exc.with_traceback(sys.exc_info()[2])
  File "/home/zhuhe/.conda/envs/diffhpe/lib/python3.9/site-packages/wandb/sdk/internal/internal_api.py", line 2190, in upload_file
    response.raise_for_status()
  File "/home/zhuhe/.conda/envs/diffhpe/lib/python3.9/site-packages/requests/models.py", line 1021, in raise_for_status
    raise HTTPError(http_error_msg, response=self)
requests.exceptions.HTTPError: 404 Client Error: Not Found for url: https://storage.googleapis.com/wandb-production.appspot.com/ada4321/DiffHPE/td4d0m1u/wandb-summary.json?Expires=1689058232&GoogleAccessId=gorilla-files-url-signer-man%40wandb-production.iam.gserviceaccount.com&Signature=HlNJIOXQs3w1dSCFvdUlqb0c6qj4i2E81JVj2p3QfTUO7eSX8hg4o7Vla5519q7FZeZiXDrOnlVsXmRpcEHmGbuYohVBI13QFKIjxO6OihnW7fku4shwHXOmUOuufGlzqgfhJI2aGN8qeY4MtFWmKz08kM794NdXDte9YKNInP9btW3mrkF%2FCMHwC9M%2FU3Ou5FCc6RgaKF9cNbNDBBEyo%2BZ3WqmqTFrkC%2BXln7RS2zT5%2Fv%2BJJS2hLJflESYUzZRCdN90f3l4ReaXS9mrEX4%2FGvUNZoj0lnJNR9Wx1OZuW%2FcvrhNc2YZ8zjROspqGoTxCVwvsgFgU8bLnMRj5seRD3w%3D%3D

During handling of the above exception, another exception occurred:

Traceback (most recent call last):
  File "/home/zhuhe/.conda/envs/diffhpe/lib/python3.9/concurrent/futures/thread.py", line 58, in run
    result = self.fn(*self.args, **self.kwargs)
  File "/home/zhuhe/.conda/envs/diffhpe/lib/python3.9/site-packages/wandb/filesync/step_upload.py", line 288, in run_and_notify
    self._do_upload_sync(event)
  File "/home/zhuhe/.conda/envs/diffhpe/lib/python3.9/site-packages/wandb/filesync/step_upload.py", line 330, in _do_upload_sync
    job.run()
  File "/home/zhuhe/.conda/envs/diffhpe/lib/python3.9/site-packages/wandb/filesync/upload_job.py", line 57, in run
    self.push()
  File "/home/zhuhe/.conda/envs/diffhpe/lib/python3.9/site-packages/wandb/filesync/upload_job.py", line 127, in push
    self._api.upload_file_retry(
  File "/home/zhuhe/.conda/envs/diffhpe/lib/python3.9/site-packages/wandb/apis/normalize.py", line 51, in wrapper
    raise CommError(message, error)
wandb.errors.CommError: <Response [404]>
2023-07-10 14:50:34,316 ERROR   Thread-11 :31569 [step_upload.py:_handle_event():200] Failed to upload file: /home/zhuhe/HPE-with-Diffusion/wandb/run-20230710_145026-td4d0m1u/files/requirements.txt
Traceback (most recent call last):
  File "/home/zhuhe/.conda/envs/diffhpe/lib/python3.9/site-packages/wandb/apis/normalize.py", line 41, in wrapper
    return func(*args, **kwargs)
  File "/home/zhuhe/.conda/envs/diffhpe/lib/python3.9/site-packages/wandb/sdk/lib/retry.py", line 212, in wrapped_fn
    return retrier(*args, **kargs)
  File "/home/zhuhe/.conda/envs/diffhpe/lib/python3.9/site-packages/wandb/sdk/lib/retry.py", line 131, in __call__
    result = self._call_fn(*args, **kwargs)
  File "/home/zhuhe/.conda/envs/diffhpe/lib/python3.9/site-packages/wandb/sdk/internal/internal_api.py", line 2218, in upload_file
    wandb._sentry.reraise(e)
  File "/home/zhuhe/.conda/envs/diffhpe/lib/python3.9/site-packages/wandb/analytics/sentry.py", line 146, in reraise
    raise exc.with_traceback(sys.exc_info()[2])
  File "/home/zhuhe/.conda/envs/diffhpe/lib/python3.9/site-packages/wandb/sdk/internal/internal_api.py", line 2190, in upload_file
    response.raise_for_status()
  File "/home/zhuhe/.conda/envs/diffhpe/lib/python3.9/site-packages/requests/models.py", line 1021, in raise_for_status
    raise HTTPError(http_error_msg, response=self)
requests.exceptions.HTTPError: 404 Client Error: Not Found for url: https://storage.googleapis.com/wandb-production.appspot.com/ada4321/DiffHPE/td4d0m1u/requirements.txt?Expires=1689058231&GoogleAccessId=gorilla-files-url-signer-man%40wandb-production.iam.gserviceaccount.com&Signature=o22EGwF5VHWcXI3c2I1e%2Ft45ww8nvnIXiDWvOD4kQDe4KVVMReFr%2BrkkLP8gODT0aVFqTVXE%2F5KNN8aH3e5x6hXoftjZRW9TvcKvqa2bPRoWtQzO%2FbiEDC8xA086NkPu8LEvlbAsflvfzQe0j0Qib0kTJyGRX9we%2Flgci9HGoqgzgu1qnq8x72hFWzLqZvxKQ9AWyS9oMEm%2Bp%2FhY%2FEnJzJTPQ7RvtKDVdD31gZcG2KC0TKbZytVxHwGbTXSIlSS3yGa3AvSz08CGEAMns%2BV8i6pMdUWRKBUjCqumy4VI3D34lAEWykUxGh6QmHyoDr4IlE%2F5XzoCG5aC6TjGkY%2Bp2Q%3D%3D

During handling of the above exception, another exception occurred:

Traceback (most recent call last):
  File "/home/zhuhe/.conda/envs/diffhpe/lib/python3.9/concurrent/futures/thread.py", line 58, in run
    result = self.fn(*self.args, **self.kwargs)
  File "/home/zhuhe/.conda/envs/diffhpe/lib/python3.9/site-packages/wandb/filesync/step_upload.py", line 288, in run_and_notify
    self._do_upload_sync(event)
  File "/home/zhuhe/.conda/envs/diffhpe/lib/python3.9/site-packages/wandb/filesync/step_upload.py", line 330, in _do_upload_sync
    job.run()
  File "/home/zhuhe/.conda/envs/diffhpe/lib/python3.9/site-packages/wandb/filesync/upload_job.py", line 57, in run
    self.push()
  File "/home/zhuhe/.conda/envs/diffhpe/lib/python3.9/site-packages/wandb/filesync/upload_job.py", line 127, in push
    self._api.upload_file_retry(
  File "/home/zhuhe/.conda/envs/diffhpe/lib/python3.9/site-packages/wandb/apis/normalize.py", line 51, in wrapper
    raise CommError(message, error)
wandb.errors.CommError: <Response [404]>
2023-07-10 14:50:34,316 ERROR   Thread-11 :31569 [step_upload.py:_handle_event():200] Failed to upload file: /home/zhuhe/HPE-with-Diffusion/wandb/run-20230710_145026-td4d0m1u/files/conda-environment.yaml
Traceback (most recent call last):
  File "/home/zhuhe/.conda/envs/diffhpe/lib/python3.9/site-packages/wandb/apis/normalize.py", line 41, in wrapper
    return func(*args, **kwargs)
  File "/home/zhuhe/.conda/envs/diffhpe/lib/python3.9/site-packages/wandb/sdk/lib/retry.py", line 212, in wrapped_fn
    return retrier(*args, **kargs)
  File "/home/zhuhe/.conda/envs/diffhpe/lib/python3.9/site-packages/wandb/sdk/lib/retry.py", line 131, in __call__
    result = self._call_fn(*args, **kwargs)
  File "/home/zhuhe/.conda/envs/diffhpe/lib/python3.9/site-packages/wandb/sdk/internal/internal_api.py", line 2218, in upload_file
    wandb._sentry.reraise(e)
  File "/home/zhuhe/.conda/envs/diffhpe/lib/python3.9/site-packages/wandb/analytics/sentry.py", line 146, in reraise
    raise exc.with_traceback(sys.exc_info()[2])
  File "/home/zhuhe/.conda/envs/diffhpe/lib/python3.9/site-packages/wandb/sdk/internal/internal_api.py", line 2190, in upload_file
    response.raise_for_status()
  File "/home/zhuhe/.conda/envs/diffhpe/lib/python3.9/site-packages/requests/models.py", line 1021, in raise_for_status
    raise HTTPError(http_error_msg, response=self)
requests.exceptions.HTTPError: 404 Client Error: Not Found for url: https://storage.googleapis.com/wandb-production.appspot.com/ada4321/DiffHPE/td4d0m1u/conda-environment.yaml?Expires=1689058232&GoogleAccessId=gorilla-files-url-signer-man%40wandb-production.iam.gserviceaccount.com&Signature=Rg94Ka86S%2BCOrb3U5eFBQEA91Bcr2NsjBWxbaPCNKhXqvL5HhG%2Fm5u68R28PS6wpR9r2Dek%2F%2B5%2FFyKblTYhrccyMu%2FMU2O2TE91yBcvt07peOKMPLgbfP8xP7eb6vCbluyYn92OyUjadWsFeMYiLRo58Wj2ldM9HetxkXxnadjH7CUgIDXmsDWbOo27IiGgodnmpfmXlS01hQ2DJYFCS3fcTmQVEXSX5YcbEya0ndDvUPrhSXMi1fOeSOZjtRChajISzjvIL0i%2FEFAcfSwKCdWIAM%2F%2BhxU1ZNeXM%2FyfTn94CwmWd8d4aLT5DMtlzpxwEfLv0WRblqmPxD0yomiJtcw%3D%3D

During handling of the above exception, another exception occurred:

Traceback (most recent call last):
  File "/home/zhuhe/.conda/envs/diffhpe/lib/python3.9/concurrent/futures/thread.py", line 58, in run
    result = self.fn(*self.args, **self.kwargs)
  File "/home/zhuhe/.conda/envs/diffhpe/lib/python3.9/site-packages/wandb/filesync/step_upload.py", line 288, in run_and_notify
    self._do_upload_sync(event)
  File "/home/zhuhe/.conda/envs/diffhpe/lib/python3.9/site-packages/wandb/filesync/step_upload.py", line 330, in _do_upload_sync
    job.run()
  File "/home/zhuhe/.conda/envs/diffhpe/lib/python3.9/site-packages/wandb/filesync/upload_job.py", line 57, in run
    self.push()
  File "/home/zhuhe/.conda/envs/diffhpe/lib/python3.9/site-packages/wandb/filesync/upload_job.py", line 127, in push
    self._api.upload_file_retry(
  File "/home/zhuhe/.conda/envs/diffhpe/lib/python3.9/site-packages/wandb/apis/normalize.py", line 51, in wrapper
    raise CommError(message, error)
wandb.errors.CommError: <Response [404]>
2023-07-10 14:50:34,516 INFO    Thread-11 :31569 [sender.py:transition_state():602] send defer: 11
2023-07-10 14:50:34,517 DEBUG   HandlerThread:31569 [handler.py:handle_request():144] handle_request: defer
2023-07-10 14:50:34,517 INFO    HandlerThread:31569 [handler.py:handle_request_defer():170] handle defer: 11
2023-07-10 14:50:34,517 DEBUG   SenderThread:31569 [sender.py:send_request():396] send_request: defer
2023-07-10 14:50:34,517 INFO    SenderThread:31569 [sender.py:send_request_defer():598] handle sender defer: 11
2023-07-10 14:50:34,517 INFO    SenderThread:31569 [file_pusher.py:join():164] waiting for file pusher
2023-07-10 14:50:34,517 INFO    SenderThread:31569 [sender.py:transition_state():602] send defer: 12
2023-07-10 14:50:34,517 DEBUG   HandlerThread:31569 [handler.py:handle_request():144] handle_request: defer
2023-07-10 14:50:34,517 INFO    HandlerThread:31569 [handler.py:handle_request_defer():170] handle defer: 12
2023-07-10 14:50:34,517 DEBUG   SenderThread:31569 [sender.py:send_request():396] send_request: defer
2023-07-10 14:50:34,517 INFO    SenderThread:31569 [sender.py:send_request_defer():598] handle sender defer: 12
2023-07-10 14:50:34,735 DEBUG   HandlerThread:31569 [handler.py:handle_request():144] handle_request: keepalive
2023-07-10 14:50:34,828 INFO    SenderThread:31569 [sender.py:transition_state():602] send defer: 13
2023-07-10 14:50:34,828 DEBUG   HandlerThread:31569 [handler.py:handle_request():144] handle_request: defer
2023-07-10 14:50:34,828 INFO    HandlerThread:31569 [handler.py:handle_request_defer():170] handle defer: 13
2023-07-10 14:50:34,829 DEBUG   SenderThread:31569 [sender.py:send_request():396] send_request: defer
2023-07-10 14:50:34,829 INFO    SenderThread:31569 [sender.py:send_request_defer():598] handle sender defer: 13
2023-07-10 14:50:34,829 INFO    SenderThread:31569 [sender.py:transition_state():602] send defer: 14
2023-07-10 14:50:34,829 DEBUG   HandlerThread:31569 [handler.py:handle_request():144] handle_request: defer
2023-07-10 14:50:34,829 INFO    HandlerThread:31569 [handler.py:handle_request_defer():170] handle defer: 14
2023-07-10 14:50:34,829 DEBUG   SenderThread:31569 [sender.py:send():369] send: final
2023-07-10 14:50:34,829 DEBUG   SenderThread:31569 [sender.py:send():369] send: footer
2023-07-10 14:50:34,829 DEBUG   SenderThread:31569 [sender.py:send_request():396] send_request: defer
2023-07-10 14:50:34,829 INFO    SenderThread:31569 [sender.py:send_request_defer():598] handle sender defer: 14
2023-07-10 14:50:34,829 DEBUG   HandlerThread:31569 [handler.py:handle_request():144] handle_request: poll_exit
2023-07-10 14:50:34,830 DEBUG   HandlerThread:31569 [handler.py:handle_request():144] handle_request: server_info
2023-07-10 14:50:34,830 DEBUG   SenderThread:31569 [sender.py:send_request():396] send_request: poll_exit
2023-07-10 14:50:34,830 DEBUG   SenderThread:31569 [sender.py:send_request():396] send_request: server_info
2023-07-10 14:50:34,831 DEBUG   HandlerThread:31569 [handler.py:handle_request():144] handle_request: get_summary
2023-07-10 14:50:34,831 DEBUG   HandlerThread:31569 [handler.py:handle_request():144] handle_request: sampled_history
2023-07-10 14:50:35,322 INFO    MainThread:31569 [wandb_run.py:_footer_history_summary_info():3467] rendering history
2023-07-10 14:50:35,322 INFO    MainThread:31569 [wandb_run.py:_footer_history_summary_info():3499] rendering summary
2023-07-10 14:50:35,322 INFO    MainThread:31569 [wandb_run.py:_footer_sync_info():3426] logging synced files
2023-07-10 14:50:35,322 DEBUG   HandlerThread:31569 [handler.py:handle_request():144] handle_request: shutdown
2023-07-10 14:50:35,322 INFO    HandlerThread:31569 [handler.py:finish():854] shutting down handler
2023-07-10 14:50:35,830 INFO    WriterThread:31569 [datastore.py:close():298] close: /home/zhuhe/HPE-with-Diffusion/wandb/run-20230710_145026-td4d0m1u/run-td4d0m1u.wandb
2023-07-10 14:50:36,321 INFO    SenderThread:31569 [sender.py:finish():1526] shutting down sender
2023-07-10 14:50:36,322 INFO    SenderThread:31569 [file_pusher.py:finish():159] shutting down file pusher
2023-07-10 14:50:36,322 INFO    SenderThread:31569 [file_pusher.py:join():164] waiting for file pusher
