2023-07-10 15:40:13,834 INFO    StreamThr :46331 [internal.py:wandb_internal():86] W&B internal server running at pid: 46331, started at: 2023-07-10 15:40:13.833890
2023-07-10 15:40:13,836 DEBUG   HandlerThread:46331 [handler.py:handle_request():144] handle_request: status
2023-07-10 15:40:13,836 INFO    WriterThread:46331 [datastore.py:open_for_write():85] open: /home/zhuhe/HPE-with-Diffusion/wandb/run-20230710_154013-pkixnjxi/run-pkixnjxi.wandb
2023-07-10 15:40:13,836 DEBUG   SenderThread:46331 [sender.py:send():369] send: header
2023-07-10 15:40:13,837 DEBUG   SenderThread:46331 [sender.py:send():369] send: run
2023-07-10 15:40:14,791 INFO    SenderThread:46331 [dir_watcher.py:__init__():211] watching files in: /home/zhuhe/HPE-with-Diffusion/wandb/run-20230710_154013-pkixnjxi/files
2023-07-10 15:40:14,791 INFO    SenderThread:46331 [sender.py:_start_run_threads():1100] run started: pkixnjxi with start time 1688974813.833552
2023-07-10 15:40:14,792 DEBUG   SenderThread:46331 [sender.py:send_request():396] send_request: summary_record
2023-07-10 15:40:14,792 INFO    SenderThread:46331 [sender.py:_save_file():1354] saving file wandb-summary.json with policy end
2023-07-10 15:40:14,795 DEBUG   HandlerThread:46331 [handler.py:handle_request():144] handle_request: check_version
2023-07-10 15:40:14,796 DEBUG   SenderThread:46331 [sender.py:send_request():396] send_request: check_version
2023-07-10 15:40:14,984 DEBUG   HandlerThread:46331 [handler.py:handle_request():144] handle_request: run_start
2023-07-10 15:40:14,988 DEBUG   HandlerThread:46331 [system_info.py:__init__():31] System info init
2023-07-10 15:40:14,988 DEBUG   HandlerThread:46331 [system_info.py:__init__():46] System info init done
2023-07-10 15:40:14,988 INFO    HandlerThread:46331 [system_monitor.py:start():181] Starting system monitor
2023-07-10 15:40:14,988 INFO    SystemMonitor:46331 [system_monitor.py:_start():145] Starting system asset monitoring threads
2023-07-10 15:40:14,989 INFO    HandlerThread:46331 [system_monitor.py:probe():201] Collecting system info
2023-07-10 15:40:14,989 INFO    SystemMonitor:46331 [interfaces.py:start():190] Started cpu monitoring
2023-07-10 15:40:14,989 INFO    SystemMonitor:46331 [interfaces.py:start():190] Started disk monitoring
2023-07-10 15:40:14,990 INFO    SystemMonitor:46331 [interfaces.py:start():190] Started gpu monitoring
2023-07-10 15:40:14,990 INFO    SystemMonitor:46331 [interfaces.py:start():190] Started memory monitoring
2023-07-10 15:40:14,991 INFO    SystemMonitor:46331 [interfaces.py:start():190] Started network monitoring
2023-07-10 15:40:15,005 DEBUG   HandlerThread:46331 [system_info.py:probe():195] Probing system
2023-07-10 15:40:15,008 DEBUG   HandlerThread:46331 [gitlib.py:_init_repo():53] git repository is invalid
2023-07-10 15:40:15,008 DEBUG   HandlerThread:46331 [system_info.py:probe():240] Probing system done
2023-07-10 15:40:15,008 DEBUG   HandlerThread:46331 [system_monitor.py:probe():210] {'os': 'Linux-5.19.0-46-generic-x86_64-with-glibc2.35', 'python': '3.9.16', 'heartbeatAt': '2023-07-10T07:40:15.005617', 'startedAt': '2023-07-10T07:40:13.830209', 'docker': None, 'cuda': None, 'args': ('--phase', 'train', '--gpu_ids', '1'), 'state': 'running', 'program': '/home/zhuhe/HPE-with-Diffusion/main.py', 'codePath': 'main.py', 'host': '415-2', 'username': 'zhuhe', 'executable': '/home/zhuhe/.conda/envs/diffhpe/bin/python', 'cpu_count': 16, 'cpu_count_logical': 24, 'cpu_freq': {'current': 4622.260833333334, 'min': 800.0, 'max': 4783.333333333333}, 'cpu_freq_per_core': [{'current': 5100.0, 'min': 800.0, 'max': 5100.0}, {'current': 5099.934, 'min': 800.0, 'max': 5100.0}, {'current': 5100.0, 'min': 800.0, 'max': 5100.0}, {'current': 5100.0, 'min': 800.0, 'max': 5100.0}, {'current': 5060.07, 'min': 800.0, 'max': 5100.0}, {'current': 5100.0, 'min': 800.0, 'max': 5100.0}, {'current': 5099.987, 'min': 800.0, 'max': 5100.0}, {'current': 5100.0, 'min': 800.0, 'max': 5100.0}, {'current': 5100.0, 'min': 800.0, 'max': 5200.0}, {'current': 5100.0, 'min': 800.0, 'max': 5200.0}, {'current': 5100.0, 'min': 800.0, 'max': 5200.0}, {'current': 5100.0, 'min': 800.0, 'max': 5200.0}, {'current': 5100.0, 'min': 800.0, 'max': 5100.0}, {'current': 5099.966, 'min': 800.0, 'max': 5100.0}, {'current': 5100.0, 'min': 800.0, 'max': 5100.0}, {'current': 5100.0, 'min': 800.0, 'max': 5100.0}, {'current': 3700.019, 'min': 800.0, 'max': 4100.0}, {'current': 3700.025, 'min': 800.0, 'max': 4100.0}, {'current': 3700.03, 'min': 800.0, 'max': 4100.0}, {'current': 3699.992, 'min': 800.0, 'max': 4100.0}, {'current': 3700.01, 'min': 800.0, 'max': 4100.0}, {'current': 3699.994, 'min': 800.0, 'max': 4100.0}, {'current': 3700.038, 'min': 800.0, 'max': 4100.0}, {'current': 3700.034, 'min': 800.0, 'max': 4100.0}], 'disk': {'total': 93.31179428100586, 'used': 0.01844024658203125}, 'gpu': 'NVIDIA GeForce RTX 3090', 'gpu_count': 2, 'gpu_devices': [{'name': 'NVIDIA GeForce RTX 3090', 'memory_total': 25769803776}, {'name': 'NVIDIA GeForce RTX 3090', 'memory_total': 25769803776}], 'memory': {'total': 31.185562133789062}}
2023-07-10 15:40:15,008 INFO    HandlerThread:46331 [system_monitor.py:probe():211] Finished collecting system info
2023-07-10 15:40:15,008 INFO    HandlerThread:46331 [system_monitor.py:probe():214] Publishing system info
2023-07-10 15:40:15,008 DEBUG   HandlerThread:46331 [system_info.py:_save_pip():51] Saving list of pip packages installed into the current environment
2023-07-10 15:40:15,009 DEBUG   HandlerThread:46331 [system_info.py:_save_pip():67] Saving pip packages done
2023-07-10 15:40:15,009 DEBUG   HandlerThread:46331 [system_info.py:_save_conda():74] Saving list of conda packages installed into the current environment
2023-07-10 15:40:15,793 INFO    Thread-12 :46331 [dir_watcher.py:_on_file_created():272] file/dir created: /home/zhuhe/HPE-with-Diffusion/wandb/run-20230710_154013-pkixnjxi/files/requirements.txt
2023-07-10 15:40:15,793 INFO    Thread-12 :46331 [dir_watcher.py:_on_file_created():272] file/dir created: /home/zhuhe/HPE-with-Diffusion/wandb/run-20230710_154013-pkixnjxi/files/conda-environment.yaml
2023-07-10 15:40:15,794 INFO    Thread-12 :46331 [dir_watcher.py:_on_file_created():272] file/dir created: /home/zhuhe/HPE-with-Diffusion/wandb/run-20230710_154013-pkixnjxi/files/wandb-summary.json
2023-07-10 15:40:15,868 DEBUG   HandlerThread:46331 [system_info.py:_save_conda():86] Saving conda packages done
2023-07-10 15:40:15,869 INFO    HandlerThread:46331 [system_monitor.py:probe():216] Finished publishing system info
2023-07-10 15:40:15,870 DEBUG   SenderThread:46331 [sender.py:send():369] send: files
2023-07-10 15:40:15,870 INFO    SenderThread:46331 [sender.py:_save_file():1354] saving file wandb-metadata.json with policy now
2023-07-10 15:40:15,873 DEBUG   HandlerThread:46331 [handler.py:handle_request():144] handle_request: stop_status
2023-07-10 15:40:15,873 DEBUG   SenderThread:46331 [sender.py:send_request():396] send_request: stop_status
2023-07-10 15:40:16,322 ERROR   wandb-upload_0:46331 [internal_api.py:upload_file():2192] upload_file exception https://storage.googleapis.com/wandb-production.appspot.com/ada4321/DiffHPE/pkixnjxi/wandb-metadata.json?Expires=1689061216&GoogleAccessId=gorilla-files-url-signer-man%40wandb-production.iam.gserviceaccount.com&Signature=efiM4BpdTqWCUmUolI%2FcZxkX8tm2546oT1tYEbw1NUypsFr34ap3luf9wd5vkdDnBBW0LCpmeBsPnKuGvLCyMFlXZBZfLdMrlgm%2FxSMp4osasAyG28FYcqY3b9IdGEXloHpBqErckBUc4ocNwze1p5bC586Iy29Ld9jBlQ%2FB7UcXf0RUlS2a8h%2B79aD5bqymzS5t0leqWe9LF7LzN4OLb%2FIuZ2m%2BdrhkBP9Znz20qh24ZaMfz%2BNngqmEuMPoUxcOMgzsBbW4qBNN0NWI92QRI5Y1CT6NX5wVflsuoSfWq5CJIlCeyS3gER9ij1FmJ0l2BxdbgwSNNDFJtc1EzZBWSA%3D%3D: 404 Client Error: Not Found for url: https://storage.googleapis.com/wandb-production.appspot.com/ada4321/DiffHPE/pkixnjxi/wandb-metadata.json?Expires=1689061216&GoogleAccessId=gorilla-files-url-signer-man%40wandb-production.iam.gserviceaccount.com&Signature=efiM4BpdTqWCUmUolI%2FcZxkX8tm2546oT1tYEbw1NUypsFr34ap3luf9wd5vkdDnBBW0LCpmeBsPnKuGvLCyMFlXZBZfLdMrlgm%2FxSMp4osasAyG28FYcqY3b9IdGEXloHpBqErckBUc4ocNwze1p5bC586Iy29Ld9jBlQ%2FB7UcXf0RUlS2a8h%2B79aD5bqymzS5t0leqWe9LF7LzN4OLb%2FIuZ2m%2BdrhkBP9Znz20qh24ZaMfz%2BNngqmEuMPoUxcOMgzsBbW4qBNN0NWI92QRI5Y1CT6NX5wVflsuoSfWq5CJIlCeyS3gER9ij1FmJ0l2BxdbgwSNNDFJtc1EzZBWSA%3D%3D
2023-07-10 15:40:16,322 ERROR   wandb-upload_0:46331 [internal_api.py:upload_file():2194] upload_file request headers: {'User-Agent': 'python-requests/2.31.0', 'Accept-Encoding': 'gzip, deflate', 'Accept': '*/*', 'Connection': 'keep-alive', 'Content-Length': '3699'}
2023-07-10 15:40:16,322 ERROR   wandb-upload_0:46331 [internal_api.py:upload_file():2196] upload_file response body: b'<!DOCTYPE html>\n<html lang=en>\n  <meta charset=utf-8>\n  <meta name=viewport content="initial-scale=1, minimum-scale=1, width=device-width">\n  <title>Error 404 (Not Found)!!1</title>\n  <style>\n    *{margin:0;padding:0}html,code{font:15px/22px arial,sans-serif}html{background:#fff;color:#222;padding:15px}body{margin:7% auto 0;max-width:390px;min-height:180px;padding:30px 0 15px}* > body{background:url(//www.google.com/images/errors/robot.png) 100% 5px no-repeat;padding-right:205px}p{margin:11px 0 22px;overflow:hidden}ins{color:#777;text-decoration:none}a img{border:0}@media screen and (max-width:772px){body{background:none;margin-top:0;max-width:none;padding-right:0}}#logo{background:url(//www.google.com/images/branding/googlelogo/1x/googlelogo_color_150x54dp.png) no-repeat;margin-left:-5px}@media only screen and (min-resolution:192dpi){#logo{background:url(//www.google.com/images/branding/googlelogo/2x/googlelogo_color_150x54dp.png) no-repeat 0% 0%/100% 100%;-moz-border-image:url(//www.google.com/images/branding/googlelogo/2x/googlelogo_color_150x54dp.png) 0}}@media only screen and (-webkit-min-device-pixel-ratio:2){#logo{background:url(//www.google.com/images/branding/googlelogo/2x/googlelogo_color_150x54dp.png) no-repeat;-webkit-background-size:100% 100%}}#logo{display:inline-block;height:54px;width:150px}\n  </style>\n  <a href=//www.google.com/><span id=logo aria-label=Google></span></a>\n  <p><b>404.</b> <ins>That\xe2\x80\x99s an error.</ins>\n  <p>The requested URL <code>/wandb-production.appspot.com/ada4321/DiffHPE/pkixnjxi/wandb-metadata.json</code> was not found on this server.  <ins>That\xe2\x80\x99s all we know.</ins>\n'
2023-07-10 15:40:16,488 DEBUG   SenderThread:46331 [sender.py:send():369] send: telemetry
2023-07-10 15:40:16,792 INFO    Thread-12 :46331 [dir_watcher.py:_on_file_created():272] file/dir created: /home/zhuhe/HPE-with-Diffusion/wandb/run-20230710_154013-pkixnjxi/files/output.log
2023-07-10 15:40:16,792 INFO    Thread-12 :46331 [dir_watcher.py:_on_file_created():272] file/dir created: /home/zhuhe/HPE-with-Diffusion/wandb/run-20230710_154013-pkixnjxi/files/wandb-metadata.json
2023-07-10 15:40:16,848 ERROR   wandb-upload_0:46331 [upload_job.py:push():136] Failed to upload file: /tmp/tmplaolxvxlwandb/zy1y5wes-wandb-metadata.json
Traceback (most recent call last):
  File "/home/zhuhe/.conda/envs/diffhpe/lib/python3.9/site-packages/wandb/apis/normalize.py", line 41, in wrapper
    return func(*args, **kwargs)
  File "/home/zhuhe/.conda/envs/diffhpe/lib/python3.9/site-packages/wandb/sdk/lib/retry.py", line 212, in wrapped_fn
    return retrier(*args, **kargs)
  File "/home/zhuhe/.conda/envs/diffhpe/lib/python3.9/site-packages/wandb/sdk/lib/retry.py", line 131, in __call__
    result = self._call_fn(*args, **kwargs)
  File "/home/zhuhe/.conda/envs/diffhpe/lib/python3.9/site-packages/wandb/sdk/internal/internal_api.py", line 2218, in upload_file
    wandb._sentry.reraise(e)
  File "/home/zhuhe/.conda/envs/diffhpe/lib/python3.9/site-packages/wandb/analytics/sentry.py", line 146, in reraise
    raise exc.with_traceback(sys.exc_info()[2])
  File "/home/zhuhe/.conda/envs/diffhpe/lib/python3.9/site-packages/wandb/sdk/internal/internal_api.py", line 2190, in upload_file
    response.raise_for_status()
  File "/home/zhuhe/.conda/envs/diffhpe/lib/python3.9/site-packages/requests/models.py", line 1021, in raise_for_status
    raise HTTPError(http_error_msg, response=self)
requests.exceptions.HTTPError: 404 Client Error: Not Found for url: https://storage.googleapis.com/wandb-production.appspot.com/ada4321/DiffHPE/pkixnjxi/wandb-metadata.json?Expires=1689061216&GoogleAccessId=gorilla-files-url-signer-man%40wandb-production.iam.gserviceaccount.com&Signature=efiM4BpdTqWCUmUolI%2FcZxkX8tm2546oT1tYEbw1NUypsFr34ap3luf9wd5vkdDnBBW0LCpmeBsPnKuGvLCyMFlXZBZfLdMrlgm%2FxSMp4osasAyG28FYcqY3b9IdGEXloHpBqErckBUc4ocNwze1p5bC586Iy29Ld9jBlQ%2FB7UcXf0RUlS2a8h%2B79aD5bqymzS5t0leqWe9LF7LzN4OLb%2FIuZ2m%2BdrhkBP9Znz20qh24ZaMfz%2BNngqmEuMPoUxcOMgzsBbW4qBNN0NWI92QRI5Y1CT6NX5wVflsuoSfWq5CJIlCeyS3gER9ij1FmJ0l2BxdbgwSNNDFJtc1EzZBWSA%3D%3D

During handling of the above exception, another exception occurred:

Traceback (most recent call last):
  File "/home/zhuhe/.conda/envs/diffhpe/lib/python3.9/site-packages/wandb/filesync/upload_job.py", line 127, in push
    self._api.upload_file_retry(
  File "/home/zhuhe/.conda/envs/diffhpe/lib/python3.9/site-packages/wandb/apis/normalize.py", line 51, in wrapper
    raise CommError(message, error)
wandb.errors.CommError: <Response [404]>
2023-07-10 15:40:17,054 ERROR   Thread-11 :46331 [step_upload.py:_handle_event():200] Failed to upload file: /tmp/tmplaolxvxlwandb/zy1y5wes-wandb-metadata.json
Traceback (most recent call last):
  File "/home/zhuhe/.conda/envs/diffhpe/lib/python3.9/site-packages/wandb/apis/normalize.py", line 41, in wrapper
    return func(*args, **kwargs)
  File "/home/zhuhe/.conda/envs/diffhpe/lib/python3.9/site-packages/wandb/sdk/lib/retry.py", line 212, in wrapped_fn
    return retrier(*args, **kargs)
  File "/home/zhuhe/.conda/envs/diffhpe/lib/python3.9/site-packages/wandb/sdk/lib/retry.py", line 131, in __call__
    result = self._call_fn(*args, **kwargs)
  File "/home/zhuhe/.conda/envs/diffhpe/lib/python3.9/site-packages/wandb/sdk/internal/internal_api.py", line 2218, in upload_file
    wandb._sentry.reraise(e)
  File "/home/zhuhe/.conda/envs/diffhpe/lib/python3.9/site-packages/wandb/analytics/sentry.py", line 146, in reraise
    raise exc.with_traceback(sys.exc_info()[2])
  File "/home/zhuhe/.conda/envs/diffhpe/lib/python3.9/site-packages/wandb/sdk/internal/internal_api.py", line 2190, in upload_file
    response.raise_for_status()
  File "/home/zhuhe/.conda/envs/diffhpe/lib/python3.9/site-packages/requests/models.py", line 1021, in raise_for_status
    raise HTTPError(http_error_msg, response=self)
requests.exceptions.HTTPError: 404 Client Error: Not Found for url: https://storage.googleapis.com/wandb-production.appspot.com/ada4321/DiffHPE/pkixnjxi/wandb-metadata.json?Expires=1689061216&GoogleAccessId=gorilla-files-url-signer-man%40wandb-production.iam.gserviceaccount.com&Signature=efiM4BpdTqWCUmUolI%2FcZxkX8tm2546oT1tYEbw1NUypsFr34ap3luf9wd5vkdDnBBW0LCpmeBsPnKuGvLCyMFlXZBZfLdMrlgm%2FxSMp4osasAyG28FYcqY3b9IdGEXloHpBqErckBUc4ocNwze1p5bC586Iy29Ld9jBlQ%2FB7UcXf0RUlS2a8h%2B79aD5bqymzS5t0leqWe9LF7LzN4OLb%2FIuZ2m%2BdrhkBP9Znz20qh24ZaMfz%2BNngqmEuMPoUxcOMgzsBbW4qBNN0NWI92QRI5Y1CT6NX5wVflsuoSfWq5CJIlCeyS3gER9ij1FmJ0l2BxdbgwSNNDFJtc1EzZBWSA%3D%3D

During handling of the above exception, another exception occurred:

Traceback (most recent call last):
  File "/home/zhuhe/.conda/envs/diffhpe/lib/python3.9/concurrent/futures/thread.py", line 58, in run
    result = self.fn(*self.args, **self.kwargs)
  File "/home/zhuhe/.conda/envs/diffhpe/lib/python3.9/site-packages/wandb/filesync/step_upload.py", line 288, in run_and_notify
    self._do_upload_sync(event)
  File "/home/zhuhe/.conda/envs/diffhpe/lib/python3.9/site-packages/wandb/filesync/step_upload.py", line 330, in _do_upload_sync
    job.run()
  File "/home/zhuhe/.conda/envs/diffhpe/lib/python3.9/site-packages/wandb/filesync/upload_job.py", line 57, in run
    self.push()
  File "/home/zhuhe/.conda/envs/diffhpe/lib/python3.9/site-packages/wandb/filesync/upload_job.py", line 127, in push
    self._api.upload_file_retry(
  File "/home/zhuhe/.conda/envs/diffhpe/lib/python3.9/site-packages/wandb/apis/normalize.py", line 51, in wrapper
    raise CommError(message, error)
wandb.errors.CommError: <Response [404]>
2023-07-10 15:40:18,793 INFO    Thread-12 :46331 [dir_watcher.py:_on_file_modified():289] file/dir modified: /home/zhuhe/HPE-with-Diffusion/wandb/run-20230710_154013-pkixnjxi/files/output.log
2023-07-10 15:40:19,406 DEBUG   HandlerThread:46331 [handler.py:handle_request():144] handle_request: status_report
2023-07-10 15:40:20,793 INFO    Thread-12 :46331 [dir_watcher.py:_on_file_modified():289] file/dir modified: /home/zhuhe/HPE-with-Diffusion/wandb/run-20230710_154013-pkixnjxi/files/output.log
2023-07-10 15:40:24,294 DEBUG   SenderThread:46331 [sender.py:send():369] send: exit
2023-07-10 15:40:24,294 INFO    SenderThread:46331 [sender.py:send_exit():574] handling exit code: 1
2023-07-10 15:40:24,294 INFO    SenderThread:46331 [sender.py:send_exit():576] handling runtime: 9
2023-07-10 15:40:24,294 INFO    SenderThread:46331 [sender.py:_save_file():1354] saving file wandb-summary.json with policy end
2023-07-10 15:40:24,294 INFO    SenderThread:46331 [sender.py:send_exit():582] send defer
2023-07-10 15:40:24,294 DEBUG   HandlerThread:46331 [handler.py:handle_request():144] handle_request: defer
2023-07-10 15:40:24,294 INFO    HandlerThread:46331 [handler.py:handle_request_defer():170] handle defer: 0
2023-07-10 15:40:24,295 DEBUG   SenderThread:46331 [sender.py:send_request():396] send_request: defer
2023-07-10 15:40:24,295 INFO    SenderThread:46331 [sender.py:send_request_defer():598] handle sender defer: 0
2023-07-10 15:40:24,295 INFO    SenderThread:46331 [sender.py:transition_state():602] send defer: 1
2023-07-10 15:40:24,295 DEBUG   HandlerThread:46331 [handler.py:handle_request():144] handle_request: defer
2023-07-10 15:40:24,295 INFO    HandlerThread:46331 [handler.py:handle_request_defer():170] handle defer: 1
2023-07-10 15:40:24,295 DEBUG   SenderThread:46331 [sender.py:send_request():396] send_request: defer
2023-07-10 15:40:24,295 INFO    SenderThread:46331 [sender.py:send_request_defer():598] handle sender defer: 1
2023-07-10 15:40:24,295 INFO    SenderThread:46331 [sender.py:transition_state():602] send defer: 2
2023-07-10 15:40:24,295 DEBUG   HandlerThread:46331 [handler.py:handle_request():144] handle_request: defer
2023-07-10 15:40:24,295 INFO    HandlerThread:46331 [handler.py:handle_request_defer():170] handle defer: 2
2023-07-10 15:40:24,295 INFO    HandlerThread:46331 [system_monitor.py:finish():190] Stopping system monitor
2023-07-10 15:40:24,295 DEBUG   SystemMonitor:46331 [system_monitor.py:_start():159] Starting system metrics aggregation loop
2023-07-10 15:40:24,295 DEBUG   SystemMonitor:46331 [system_monitor.py:_start():166] Finished system metrics aggregation loop
2023-07-10 15:40:24,295 DEBUG   SystemMonitor:46331 [system_monitor.py:_start():170] Publishing last batch of metrics
2023-07-10 15:40:24,296 INFO    HandlerThread:46331 [interfaces.py:finish():202] Joined cpu monitor
2023-07-10 15:40:24,296 INFO    HandlerThread:46331 [interfaces.py:finish():202] Joined disk monitor
2023-07-10 15:40:24,360 INFO    HandlerThread:46331 [interfaces.py:finish():202] Joined gpu monitor
2023-07-10 15:40:24,360 INFO    HandlerThread:46331 [interfaces.py:finish():202] Joined memory monitor
2023-07-10 15:40:24,360 INFO    HandlerThread:46331 [interfaces.py:finish():202] Joined network monitor
2023-07-10 15:40:24,360 DEBUG   SenderThread:46331 [sender.py:send_request():396] send_request: defer
2023-07-10 15:40:24,360 INFO    SenderThread:46331 [sender.py:send_request_defer():598] handle sender defer: 2
2023-07-10 15:40:24,360 INFO    SenderThread:46331 [sender.py:transition_state():602] send defer: 3
2023-07-10 15:40:24,360 DEBUG   SenderThread:46331 [sender.py:send():369] send: stats
2023-07-10 15:40:24,361 DEBUG   HandlerThread:46331 [handler.py:handle_request():144] handle_request: defer
2023-07-10 15:40:24,361 INFO    HandlerThread:46331 [handler.py:handle_request_defer():170] handle defer: 3
2023-07-10 15:40:24,361 DEBUG   SenderThread:46331 [sender.py:send_request():396] send_request: defer
2023-07-10 15:40:24,361 INFO    SenderThread:46331 [sender.py:send_request_defer():598] handle sender defer: 3
2023-07-10 15:40:24,361 INFO    SenderThread:46331 [sender.py:transition_state():602] send defer: 4
2023-07-10 15:40:24,361 DEBUG   HandlerThread:46331 [handler.py:handle_request():144] handle_request: defer
2023-07-10 15:40:24,361 INFO    HandlerThread:46331 [handler.py:handle_request_defer():170] handle defer: 4
2023-07-10 15:40:24,361 DEBUG   SenderThread:46331 [sender.py:send_request():396] send_request: defer
2023-07-10 15:40:24,361 INFO    SenderThread:46331 [sender.py:send_request_defer():598] handle sender defer: 4
2023-07-10 15:40:24,361 INFO    SenderThread:46331 [sender.py:transition_state():602] send defer: 5
2023-07-10 15:40:24,361 DEBUG   HandlerThread:46331 [handler.py:handle_request():144] handle_request: defer
2023-07-10 15:40:24,361 INFO    HandlerThread:46331 [handler.py:handle_request_defer():170] handle defer: 5
2023-07-10 15:40:24,362 DEBUG   SenderThread:46331 [sender.py:send():369] send: summary
2023-07-10 15:40:24,362 INFO    SenderThread:46331 [sender.py:_save_file():1354] saving file wandb-summary.json with policy end
2023-07-10 15:40:24,362 DEBUG   SenderThread:46331 [sender.py:send_request():396] send_request: defer
2023-07-10 15:40:24,362 INFO    SenderThread:46331 [sender.py:send_request_defer():598] handle sender defer: 5
2023-07-10 15:40:24,362 INFO    SenderThread:46331 [sender.py:transition_state():602] send defer: 6
2023-07-10 15:40:24,363 DEBUG   HandlerThread:46331 [handler.py:handle_request():144] handle_request: defer
2023-07-10 15:40:24,363 INFO    HandlerThread:46331 [handler.py:handle_request_defer():170] handle defer: 6
2023-07-10 15:40:24,363 DEBUG   SenderThread:46331 [sender.py:send_request():396] send_request: defer
2023-07-10 15:40:24,363 INFO    SenderThread:46331 [sender.py:send_request_defer():598] handle sender defer: 6
2023-07-10 15:40:24,365 DEBUG   HandlerThread:46331 [handler.py:handle_request():144] handle_request: status_report
2023-07-10 15:40:24,661 INFO    SenderThread:46331 [sender.py:transition_state():602] send defer: 7
2023-07-10 15:40:24,661 DEBUG   HandlerThread:46331 [handler.py:handle_request():144] handle_request: defer
2023-07-10 15:40:24,661 INFO    HandlerThread:46331 [handler.py:handle_request_defer():170] handle defer: 7
2023-07-10 15:40:24,661 DEBUG   SenderThread:46331 [sender.py:send_request():396] send_request: defer
2023-07-10 15:40:24,661 INFO    SenderThread:46331 [sender.py:send_request_defer():598] handle sender defer: 7
2023-07-10 15:40:24,794 INFO    Thread-12 :46331 [dir_watcher.py:_on_file_modified():289] file/dir modified: /home/zhuhe/HPE-with-Diffusion/wandb/run-20230710_154013-pkixnjxi/files/config.yaml
2023-07-10 15:40:24,794 INFO    Thread-12 :46331 [dir_watcher.py:_on_file_modified():289] file/dir modified: /home/zhuhe/HPE-with-Diffusion/wandb/run-20230710_154013-pkixnjxi/files/output.log
2023-07-10 15:40:24,794 INFO    Thread-12 :46331 [dir_watcher.py:_on_file_modified():289] file/dir modified: /home/zhuhe/HPE-with-Diffusion/wandb/run-20230710_154013-pkixnjxi/files/wandb-summary.json
2023-07-10 15:40:25,294 DEBUG   HandlerThread:46331 [handler.py:handle_request():144] handle_request: poll_exit
2023-07-10 15:40:26,795 INFO    Thread-12 :46331 [dir_watcher.py:_on_file_modified():289] file/dir modified: /home/zhuhe/HPE-with-Diffusion/wandb/run-20230710_154013-pkixnjxi/files/output.log
2023-07-10 15:40:28,503 INFO    SenderThread:46331 [sender.py:transition_state():602] send defer: 8
2023-07-10 15:40:28,503 DEBUG   SenderThread:46331 [sender.py:send_request():396] send_request: poll_exit
2023-07-10 15:40:28,504 DEBUG   HandlerThread:46331 [handler.py:handle_request():144] handle_request: defer
2023-07-10 15:40:28,504 INFO    HandlerThread:46331 [handler.py:handle_request_defer():170] handle defer: 8
2023-07-10 15:40:28,504 DEBUG   SenderThread:46331 [sender.py:send_request():396] send_request: defer
2023-07-10 15:40:28,504 INFO    SenderThread:46331 [sender.py:send_request_defer():598] handle sender defer: 8
2023-07-10 15:40:28,504 INFO    SenderThread:46331 [job_builder.py:build():232] Attempting to build job artifact
2023-07-10 15:40:28,504 INFO    SenderThread:46331 [job_builder.py:build():266] no source found
2023-07-10 15:40:28,504 INFO    SenderThread:46331 [sender.py:transition_state():602] send defer: 9
2023-07-10 15:40:28,504 DEBUG   HandlerThread:46331 [handler.py:handle_request():144] handle_request: defer
2023-07-10 15:40:28,505 INFO    HandlerThread:46331 [handler.py:handle_request_defer():170] handle defer: 9
2023-07-10 15:40:28,505 DEBUG   SenderThread:46331 [sender.py:send_request():396] send_request: defer
2023-07-10 15:40:28,505 INFO    SenderThread:46331 [sender.py:send_request_defer():598] handle sender defer: 9
2023-07-10 15:40:28,505 INFO    SenderThread:46331 [dir_watcher.py:finish():359] shutting down directory watcher
2023-07-10 15:40:28,796 INFO    SenderThread:46331 [dir_watcher.py:_on_file_modified():289] file/dir modified: /home/zhuhe/HPE-with-Diffusion/wandb/run-20230710_154013-pkixnjxi/files/output.log
2023-07-10 15:40:28,796 INFO    SenderThread:46331 [dir_watcher.py:finish():389] scan: /home/zhuhe/HPE-with-Diffusion/wandb/run-20230710_154013-pkixnjxi/files
2023-07-10 15:40:28,796 INFO    SenderThread:46331 [dir_watcher.py:finish():403] scan save: /home/zhuhe/HPE-with-Diffusion/wandb/run-20230710_154013-pkixnjxi/files/wandb-metadata.json wandb-metadata.json
2023-07-10 15:40:28,796 INFO    SenderThread:46331 [dir_watcher.py:finish():403] scan save: /home/zhuhe/HPE-with-Diffusion/wandb/run-20230710_154013-pkixnjxi/files/config.yaml config.yaml
2023-07-10 15:40:28,796 INFO    SenderThread:46331 [dir_watcher.py:finish():403] scan save: /home/zhuhe/HPE-with-Diffusion/wandb/run-20230710_154013-pkixnjxi/files/requirements.txt requirements.txt
2023-07-10 15:40:28,796 INFO    SenderThread:46331 [dir_watcher.py:finish():403] scan save: /home/zhuhe/HPE-with-Diffusion/wandb/run-20230710_154013-pkixnjxi/files/wandb-summary.json wandb-summary.json
2023-07-10 15:40:28,796 INFO    SenderThread:46331 [dir_watcher.py:finish():403] scan save: /home/zhuhe/HPE-with-Diffusion/wandb/run-20230710_154013-pkixnjxi/files/conda-environment.yaml conda-environment.yaml
2023-07-10 15:40:28,797 INFO    SenderThread:46331 [dir_watcher.py:finish():403] scan save: /home/zhuhe/HPE-with-Diffusion/wandb/run-20230710_154013-pkixnjxi/files/output.log output.log
2023-07-10 15:40:28,797 INFO    SenderThread:46331 [sender.py:transition_state():602] send defer: 10
2023-07-10 15:40:28,798 DEBUG   HandlerThread:46331 [handler.py:handle_request():144] handle_request: defer
2023-07-10 15:40:28,798 INFO    HandlerThread:46331 [handler.py:handle_request_defer():170] handle defer: 10
2023-07-10 15:40:28,800 DEBUG   SenderThread:46331 [sender.py:send_request():396] send_request: defer
2023-07-10 15:40:28,800 INFO    SenderThread:46331 [sender.py:send_request_defer():598] handle sender defer: 10
2023-07-10 15:40:28,802 INFO    SenderThread:46331 [file_pusher.py:finish():159] shutting down file pusher
2023-07-10 15:40:29,271 ERROR   wandb-upload_1:46331 [internal_api.py:upload_file():2192] upload_file exception https://storage.googleapis.com/wandb-production.appspot.com/ada4321/DiffHPE/pkixnjxi/requirements.txt?Expires=1689061228&GoogleAccessId=gorilla-files-url-signer-man%40wandb-production.iam.gserviceaccount.com&Signature=NAQxJirGwvyXfc0cRoJ4MtKRnTUacTIEIlENB0A%2FMtrAKDYacn35gP3F7M8rBeyjUzuq9NRzpS%2FFPvqgBD5L4RVCWu1UYKway%2BaFAm%2BjyThjc0ruJSlnXMiTyXnvKtbTI1%2BlOk8VhAXeq5ZB96DLJUZI9tOSaxe6IdJgg1YPNu%2BBBrmVxWEw9ow6g%2FYDKP%2BBnvHHSO0oqj4IoDZmkaDUQ5t9CzGnyJHL6pC0vw%2FZURQsLTWRU7XCnniziz8q5HTefNgHFyekq75tokXXNYF2YyKPzyCzB17DB6WhUcU2HM5R35OC9HAQzNDwZaq%2FnS%2FiS3GE394L50uzz%2FHp3UQrdg%3D%3D: 404 Client Error: Not Found for url: https://storage.googleapis.com/wandb-production.appspot.com/ada4321/DiffHPE/pkixnjxi/requirements.txt?Expires=1689061228&GoogleAccessId=gorilla-files-url-signer-man%40wandb-production.iam.gserviceaccount.com&Signature=NAQxJirGwvyXfc0cRoJ4MtKRnTUacTIEIlENB0A%2FMtrAKDYacn35gP3F7M8rBeyjUzuq9NRzpS%2FFPvqgBD5L4RVCWu1UYKway%2BaFAm%2BjyThjc0ruJSlnXMiTyXnvKtbTI1%2BlOk8VhAXeq5ZB96DLJUZI9tOSaxe6IdJgg1YPNu%2BBBrmVxWEw9ow6g%2FYDKP%2BBnvHHSO0oqj4IoDZmkaDUQ5t9CzGnyJHL6pC0vw%2FZURQsLTWRU7XCnniziz8q5HTefNgHFyekq75tokXXNYF2YyKPzyCzB17DB6WhUcU2HM5R35OC9HAQzNDwZaq%2FnS%2FiS3GE394L50uzz%2FHp3UQrdg%3D%3D
2023-07-10 15:40:29,271 ERROR   wandb-upload_1:46331 [internal_api.py:upload_file():2194] upload_file request headers: {'User-Agent': 'python-requests/2.31.0', 'Accept-Encoding': 'gzip, deflate', 'Accept': '*/*', 'Connection': 'keep-alive', 'Content-Length': '910'}
2023-07-10 15:40:29,271 ERROR   wandb-upload_1:46331 [internal_api.py:upload_file():2196] upload_file response body: b'<!DOCTYPE html>\n<html lang=en>\n  <meta charset=utf-8>\n  <meta name=viewport content="initial-scale=1, minimum-scale=1, width=device-width">\n  <title>Error 404 (Not Found)!!1</title>\n  <style>\n    *{margin:0;padding:0}html,code{font:15px/22px arial,sans-serif}html{background:#fff;color:#222;padding:15px}body{margin:7% auto 0;max-width:390px;min-height:180px;padding:30px 0 15px}* > body{background:url(//www.google.com/images/errors/robot.png) 100% 5px no-repeat;padding-right:205px}p{margin:11px 0 22px;overflow:hidden}ins{color:#777;text-decoration:none}a img{border:0}@media screen and (max-width:772px){body{background:none;margin-top:0;max-width:none;padding-right:0}}#logo{background:url(//www.google.com/images/branding/googlelogo/1x/googlelogo_color_150x54dp.png) no-repeat;margin-left:-5px}@media only screen and (min-resolution:192dpi){#logo{background:url(//www.google.com/images/branding/googlelogo/2x/googlelogo_color_150x54dp.png) no-repeat 0% 0%/100% 100%;-moz-border-image:url(//www.google.com/images/branding/googlelogo/2x/googlelogo_color_150x54dp.png) 0}}@media only screen and (-webkit-min-device-pixel-ratio:2){#logo{background:url(//www.google.com/images/branding/googlelogo/2x/googlelogo_color_150x54dp.png) no-repeat;-webkit-background-size:100% 100%}}#logo{display:inline-block;height:54px;width:150px}\n  </style>\n  <a href=//www.google.com/><span id=logo aria-label=Google></span></a>\n  <p><b>404.</b> <ins>That\xe2\x80\x99s an error.</ins>\n  <p>The requested URL <code>/wandb-production.appspot.com/ada4321/DiffHPE/pkixnjxi/requirements.txt</code> was not found on this server.  <ins>That\xe2\x80\x99s all we know.</ins>\n'
2023-07-10 15:40:29,290 ERROR   wandb-upload_0:46331 [internal_api.py:upload_file():2192] upload_file exception https://storage.googleapis.com/wandb-production.appspot.com/ada4321/DiffHPE/pkixnjxi/config.yaml?Expires=1689061228&GoogleAccessId=gorilla-files-url-signer-man%40wandb-production.iam.gserviceaccount.com&Signature=CCy%2BDpz1J5Rm2wL8Sshp7v53mVLSAsQsqvt8vasdrHHD1UQSJdw8cuuzENi1r2s%2FlLqa6w9n16l2XLzLDx8N%2BDF30bEIGvUZ3iyAxvXagpUKXcEy3BnKhlxnHgiB%2F0T0VDYaJXvn4KGlBVnhlJKfgpjnTVr%2BQjdXnyE%2FbX94wIomGhbCbXKN2Oad0XGQXB94PLrnmatGGsrfqKGAwvqsTKwEad8OW2vH1E7U9qYjDsVCvL4L9HRlxU4pTy9RdFghTMtdgZDptHk3f6Rxh547u4cuKC1qIQiS%2FJBj5sW2doNjyap%2F5j%2FfzdPbWFq1lIIyy49LqHDu884KxqH5lqmVhg%3D%3D: 404 Client Error: Not Found for url: https://storage.googleapis.com/wandb-production.appspot.com/ada4321/DiffHPE/pkixnjxi/config.yaml?Expires=1689061228&GoogleAccessId=gorilla-files-url-signer-man%40wandb-production.iam.gserviceaccount.com&Signature=CCy%2BDpz1J5Rm2wL8Sshp7v53mVLSAsQsqvt8vasdrHHD1UQSJdw8cuuzENi1r2s%2FlLqa6w9n16l2XLzLDx8N%2BDF30bEIGvUZ3iyAxvXagpUKXcEy3BnKhlxnHgiB%2F0T0VDYaJXvn4KGlBVnhlJKfgpjnTVr%2BQjdXnyE%2FbX94wIomGhbCbXKN2Oad0XGQXB94PLrnmatGGsrfqKGAwvqsTKwEad8OW2vH1E7U9qYjDsVCvL4L9HRlxU4pTy9RdFghTMtdgZDptHk3f6Rxh547u4cuKC1qIQiS%2FJBj5sW2doNjyap%2F5j%2FfzdPbWFq1lIIyy49LqHDu884KxqH5lqmVhg%3D%3D
2023-07-10 15:40:29,290 ERROR   wandb-upload_0:46331 [internal_api.py:upload_file():2194] upload_file request headers: {'User-Agent': 'python-requests/2.31.0', 'Accept-Encoding': 'gzip, deflate', 'Accept': '*/*', 'Connection': 'keep-alive', 'Content-Length': '514'}
2023-07-10 15:40:29,290 ERROR   wandb-upload_0:46331 [internal_api.py:upload_file():2196] upload_file response body: b'<!DOCTYPE html>\n<html lang=en>\n  <meta charset=utf-8>\n  <meta name=viewport content="initial-scale=1, minimum-scale=1, width=device-width">\n  <title>Error 404 (Not Found)!!1</title>\n  <style>\n    *{margin:0;padding:0}html,code{font:15px/22px arial,sans-serif}html{background:#fff;color:#222;padding:15px}body{margin:7% auto 0;max-width:390px;min-height:180px;padding:30px 0 15px}* > body{background:url(//www.google.com/images/errors/robot.png) 100% 5px no-repeat;padding-right:205px}p{margin:11px 0 22px;overflow:hidden}ins{color:#777;text-decoration:none}a img{border:0}@media screen and (max-width:772px){body{background:none;margin-top:0;max-width:none;padding-right:0}}#logo{background:url(//www.google.com/images/branding/googlelogo/1x/googlelogo_color_150x54dp.png) no-repeat;margin-left:-5px}@media only screen and (min-resolution:192dpi){#logo{background:url(//www.google.com/images/branding/googlelogo/2x/googlelogo_color_150x54dp.png) no-repeat 0% 0%/100% 100%;-moz-border-image:url(//www.google.com/images/branding/googlelogo/2x/googlelogo_color_150x54dp.png) 0}}@media only screen and (-webkit-min-device-pixel-ratio:2){#logo{background:url(//www.google.com/images/branding/googlelogo/2x/googlelogo_color_150x54dp.png) no-repeat;-webkit-background-size:100% 100%}}#logo{display:inline-block;height:54px;width:150px}\n  </style>\n  <a href=//www.google.com/><span id=logo aria-label=Google></span></a>\n  <p><b>404.</b> <ins>That\xe2\x80\x99s an error.</ins>\n  <p>The requested URL <code>/wandb-production.appspot.com/ada4321/DiffHPE/pkixnjxi/config.yaml</code> was not found on this server.  <ins>That\xe2\x80\x99s all we know.</ins>\n'
2023-07-10 15:40:29,602 ERROR   wandb-upload_4:46331 [internal_api.py:upload_file():2192] upload_file exception https://storage.googleapis.com/wandb-production.appspot.com/ada4321/DiffHPE/pkixnjxi/output.log?Expires=1689061229&GoogleAccessId=gorilla-files-url-signer-man%40wandb-production.iam.gserviceaccount.com&Signature=CELGy3w3%2FODelBcq4pVFKFdcwP83Fgf%2BIxXRphdVSHwrH1CxrJ4Wxzcri%2F7tIfxbpImwJ%2Bkxs5g4kxPN52cEWCiYkz3u3bCi%2BGz6UVrnbuA%2Banl25ffm3RLEW%2BSkVj%2BtoaX1VpgeiDGVuNaDzbjjGeDjNxuv3amBOL7811HoEaDAWVckyfSQNsoWHDhlwiiNuyNLzzUtyia7sBBUJs1vb0rR%2FsAjpDjFy%2FgeIbrKNKLk6aoxsXQTUa1gDs82Q6h86B3KAXt%2FRfmHFK6O%2F8YmedLu171RtuEqRoBIDeuevU%2FtmzbMr%2FvAIpzU9wRV7xBVEmswXg9AdNLRw5sVYTFd0A%3D%3D: 404 Client Error: Not Found for url: https://storage.googleapis.com/wandb-production.appspot.com/ada4321/DiffHPE/pkixnjxi/output.log?Expires=1689061229&GoogleAccessId=gorilla-files-url-signer-man%40wandb-production.iam.gserviceaccount.com&Signature=CELGy3w3%2FODelBcq4pVFKFdcwP83Fgf%2BIxXRphdVSHwrH1CxrJ4Wxzcri%2F7tIfxbpImwJ%2Bkxs5g4kxPN52cEWCiYkz3u3bCi%2BGz6UVrnbuA%2Banl25ffm3RLEW%2BSkVj%2BtoaX1VpgeiDGVuNaDzbjjGeDjNxuv3amBOL7811HoEaDAWVckyfSQNsoWHDhlwiiNuyNLzzUtyia7sBBUJs1vb0rR%2FsAjpDjFy%2FgeIbrKNKLk6aoxsXQTUa1gDs82Q6h86B3KAXt%2FRfmHFK6O%2F8YmedLu171RtuEqRoBIDeuevU%2FtmzbMr%2FvAIpzU9wRV7xBVEmswXg9AdNLRw5sVYTFd0A%3D%3D
2023-07-10 15:40:29,602 ERROR   wandb-upload_4:46331 [internal_api.py:upload_file():2194] upload_file request headers: {'User-Agent': 'python-requests/2.31.0', 'Accept-Encoding': 'gzip, deflate', 'Accept': '*/*', 'Connection': 'keep-alive', 'Content-Length': '3209'}
2023-07-10 15:40:29,602 ERROR   wandb-upload_4:46331 [internal_api.py:upload_file():2196] upload_file response body: b'<!DOCTYPE html>\n<html lang=en>\n  <meta charset=utf-8>\n  <meta name=viewport content="initial-scale=1, minimum-scale=1, width=device-width">\n  <title>Error 404 (Not Found)!!1</title>\n  <style>\n    *{margin:0;padding:0}html,code{font:15px/22px arial,sans-serif}html{background:#fff;color:#222;padding:15px}body{margin:7% auto 0;max-width:390px;min-height:180px;padding:30px 0 15px}* > body{background:url(//www.google.com/images/errors/robot.png) 100% 5px no-repeat;padding-right:205px}p{margin:11px 0 22px;overflow:hidden}ins{color:#777;text-decoration:none}a img{border:0}@media screen and (max-width:772px){body{background:none;margin-top:0;max-width:none;padding-right:0}}#logo{background:url(//www.google.com/images/branding/googlelogo/1x/googlelogo_color_150x54dp.png) no-repeat;margin-left:-5px}@media only screen and (min-resolution:192dpi){#logo{background:url(//www.google.com/images/branding/googlelogo/2x/googlelogo_color_150x54dp.png) no-repeat 0% 0%/100% 100%;-moz-border-image:url(//www.google.com/images/branding/googlelogo/2x/googlelogo_color_150x54dp.png) 0}}@media only screen and (-webkit-min-device-pixel-ratio:2){#logo{background:url(//www.google.com/images/branding/googlelogo/2x/googlelogo_color_150x54dp.png) no-repeat;-webkit-background-size:100% 100%}}#logo{display:inline-block;height:54px;width:150px}\n  </style>\n  <a href=//www.google.com/><span id=logo aria-label=Google></span></a>\n  <p><b>404.</b> <ins>That\xe2\x80\x99s an error.</ins>\n  <p>The requested URL <code>/wandb-production.appspot.com/ada4321/DiffHPE/pkixnjxi/output.log</code> was not found on this server.  <ins>That\xe2\x80\x99s all we know.</ins>\n'
2023-07-10 15:40:29,617 ERROR   wandb-upload_2:46331 [internal_api.py:upload_file():2192] upload_file exception https://storage.googleapis.com/wandb-production.appspot.com/ada4321/DiffHPE/pkixnjxi/wandb-summary.json?Expires=1689061229&GoogleAccessId=gorilla-files-url-signer-man%40wandb-production.iam.gserviceaccount.com&Signature=Xtc6kE77yrWPdQJmE1nLGLqf3%2Bp18yw6DtHbeYHRtI4QWV8Jl2HgvpctoCc1miFdBOgBb1O4v7HeYH04OnoXGxFQFSEbSNn%2B0CD86%2B8ugi9fm2YYQ3FryZWMaod6xQuoY2z5%2FuxKMjjinDxAf%2FmBv7YL4H9rz8pKg8rF8f6FYof6tjv5EDSmB7j94tQIrDZjDPcVHzJiMKxXUAYKOtWFQitjNoVeJdm4QI2sNFv7308Tvgmr%2B2KpDMtQB4%2BHtdEGcogG0xHjqt%2Bo39LbsH8XptUsoMJMrN7ji23n3mmXMGNh0oDOFs%2BbiJ5CAwQhVj%2BAkiWt0vsH4FXYMJluCFU%2Fyw%3D%3D: 404 Client Error: Not Found for url: https://storage.googleapis.com/wandb-production.appspot.com/ada4321/DiffHPE/pkixnjxi/wandb-summary.json?Expires=1689061229&GoogleAccessId=gorilla-files-url-signer-man%40wandb-production.iam.gserviceaccount.com&Signature=Xtc6kE77yrWPdQJmE1nLGLqf3%2Bp18yw6DtHbeYHRtI4QWV8Jl2HgvpctoCc1miFdBOgBb1O4v7HeYH04OnoXGxFQFSEbSNn%2B0CD86%2B8ugi9fm2YYQ3FryZWMaod6xQuoY2z5%2FuxKMjjinDxAf%2FmBv7YL4H9rz8pKg8rF8f6FYof6tjv5EDSmB7j94tQIrDZjDPcVHzJiMKxXUAYKOtWFQitjNoVeJdm4QI2sNFv7308Tvgmr%2B2KpDMtQB4%2BHtdEGcogG0xHjqt%2Bo39LbsH8XptUsoMJMrN7ji23n3mmXMGNh0oDOFs%2BbiJ5CAwQhVj%2BAkiWt0vsH4FXYMJluCFU%2Fyw%3D%3D
2023-07-10 15:40:29,617 ERROR   wandb-upload_2:46331 [internal_api.py:upload_file():2194] upload_file request headers: {'User-Agent': 'python-requests/2.31.0', 'Accept-Encoding': 'gzip, deflate', 'Accept': '*/*', 'Connection': 'keep-alive', 'Content-Length': '26'}
2023-07-10 15:40:29,617 ERROR   wandb-upload_2:46331 [internal_api.py:upload_file():2196] upload_file response body: b'<!DOCTYPE html>\n<html lang=en>\n  <meta charset=utf-8>\n  <meta name=viewport content="initial-scale=1, minimum-scale=1, width=device-width">\n  <title>Error 404 (Not Found)!!1</title>\n  <style>\n    *{margin:0;padding:0}html,code{font:15px/22px arial,sans-serif}html{background:#fff;color:#222;padding:15px}body{margin:7% auto 0;max-width:390px;min-height:180px;padding:30px 0 15px}* > body{background:url(//www.google.com/images/errors/robot.png) 100% 5px no-repeat;padding-right:205px}p{margin:11px 0 22px;overflow:hidden}ins{color:#777;text-decoration:none}a img{border:0}@media screen and (max-width:772px){body{background:none;margin-top:0;max-width:none;padding-right:0}}#logo{background:url(//www.google.com/images/branding/googlelogo/1x/googlelogo_color_150x54dp.png) no-repeat;margin-left:-5px}@media only screen and (min-resolution:192dpi){#logo{background:url(//www.google.com/images/branding/googlelogo/2x/googlelogo_color_150x54dp.png) no-repeat 0% 0%/100% 100%;-moz-border-image:url(//www.google.com/images/branding/googlelogo/2x/googlelogo_color_150x54dp.png) 0}}@media only screen and (-webkit-min-device-pixel-ratio:2){#logo{background:url(//www.google.com/images/branding/googlelogo/2x/googlelogo_color_150x54dp.png) no-repeat;-webkit-background-size:100% 100%}}#logo{display:inline-block;height:54px;width:150px}\n  </style>\n  <a href=//www.google.com/><span id=logo aria-label=Google></span></a>\n  <p><b>404.</b> <ins>That\xe2\x80\x99s an error.</ins>\n  <p>The requested URL <code>/wandb-production.appspot.com/ada4321/DiffHPE/pkixnjxi/wandb-summary.json</code> was not found on this server.  <ins>That\xe2\x80\x99s all we know.</ins>\n'
2023-07-10 15:40:29,648 ERROR   wandb-upload_3:46331 [internal_api.py:upload_file():2192] upload_file exception https://storage.googleapis.com/wandb-production.appspot.com/ada4321/DiffHPE/pkixnjxi/conda-environment.yaml?Expires=1689061229&GoogleAccessId=gorilla-files-url-signer-man%40wandb-production.iam.gserviceaccount.com&Signature=nF7qXX909GLTpzSsG1YwrrSTyH0wwfr%2B81vme%2BKpN6S%2FBal8%2FXwi5sOjXHsUYKq3GiTZqJENwbmW7VeVhlGFP6hgjYy38wuERCxzx%2FcS1EoJYn5EuTleQf0sq1XNWh%2Fid8Q%2B8PoTSBn4O%2BnqLIJGh13vaev5ZvOLbMvo1rjuHxzZjUl8ey3dWnLsQJGSTHc4VwUyPVWgf6Oko0R%2Fev%2By7xf4fMgmyykuIovHb9EGA8dB4jjzHRO3kCO%2BAvqZ48CJP8Z6yoM%2BcX8ihG6sADmYRSRWQ2tzjj0O6tUf5CKGjddyzrJrHkxLjrTwqbd%2FWlQGajouxnSqnIZd2YGHeRi96g%3D%3D: 404 Client Error: Not Found for url: https://storage.googleapis.com/wandb-production.appspot.com/ada4321/DiffHPE/pkixnjxi/conda-environment.yaml?Expires=1689061229&GoogleAccessId=gorilla-files-url-signer-man%40wandb-production.iam.gserviceaccount.com&Signature=nF7qXX909GLTpzSsG1YwrrSTyH0wwfr%2B81vme%2BKpN6S%2FBal8%2FXwi5sOjXHsUYKq3GiTZqJENwbmW7VeVhlGFP6hgjYy38wuERCxzx%2FcS1EoJYn5EuTleQf0sq1XNWh%2Fid8Q%2B8PoTSBn4O%2BnqLIJGh13vaev5ZvOLbMvo1rjuHxzZjUl8ey3dWnLsQJGSTHc4VwUyPVWgf6Oko0R%2Fev%2By7xf4fMgmyykuIovHb9EGA8dB4jjzHRO3kCO%2BAvqZ48CJP8Z6yoM%2BcX8ihG6sADmYRSRWQ2tzjj0O6tUf5CKGjddyzrJrHkxLjrTwqbd%2FWlQGajouxnSqnIZd2YGHeRi96g%3D%3D
2023-07-10 15:40:29,649 ERROR   wandb-upload_3:46331 [internal_api.py:upload_file():2194] upload_file request headers: {'User-Agent': 'python-requests/2.31.0', 'Accept-Encoding': 'gzip, deflate', 'Accept': '*/*', 'Connection': 'keep-alive', 'Content-Length': '1903'}
2023-07-10 15:40:29,649 ERROR   wandb-upload_3:46331 [internal_api.py:upload_file():2196] upload_file response body: b'<!DOCTYPE html>\n<html lang=en>\n  <meta charset=utf-8>\n  <meta name=viewport content="initial-scale=1, minimum-scale=1, width=device-width">\n  <title>Error 404 (Not Found)!!1</title>\n  <style>\n    *{margin:0;padding:0}html,code{font:15px/22px arial,sans-serif}html{background:#fff;color:#222;padding:15px}body{margin:7% auto 0;max-width:390px;min-height:180px;padding:30px 0 15px}* > body{background:url(//www.google.com/images/errors/robot.png) 100% 5px no-repeat;padding-right:205px}p{margin:11px 0 22px;overflow:hidden}ins{color:#777;text-decoration:none}a img{border:0}@media screen and (max-width:772px){body{background:none;margin-top:0;max-width:none;padding-right:0}}#logo{background:url(//www.google.com/images/branding/googlelogo/1x/googlelogo_color_150x54dp.png) no-repeat;margin-left:-5px}@media only screen and (min-resolution:192dpi){#logo{background:url(//www.google.com/images/branding/googlelogo/2x/googlelogo_color_150x54dp.png) no-repeat 0% 0%/100% 100%;-moz-border-image:url(//www.google.com/images/branding/googlelogo/2x/googlelogo_color_150x54dp.png) 0}}@media only screen and (-webkit-min-device-pixel-ratio:2){#logo{background:url(//www.google.com/images/branding/googlelogo/2x/googlelogo_color_150x54dp.png) no-repeat;-webkit-background-size:100% 100%}}#logo{display:inline-block;height:54px;width:150px}\n  </style>\n  <a href=//www.google.com/><span id=logo aria-label=Google></span></a>\n  <p><b>404.</b> <ins>That\xe2\x80\x99s an error.</ins>\n  <p>The requested URL <code>/wandb-production.appspot.com/ada4321/DiffHPE/pkixnjxi/conda-environment.yaml</code> was not found on this server.  <ins>That\xe2\x80\x99s all we know.</ins>\n'
2023-07-10 15:40:29,802 DEBUG   HandlerThread:46331 [handler.py:handle_request():144] handle_request: status_report
2023-07-10 15:40:30,285 ERROR   wandb-upload_1:46331 [upload_job.py:push():136] Failed to upload file: /home/zhuhe/HPE-with-Diffusion/wandb/run-20230710_154013-pkixnjxi/files/requirements.txt
Traceback (most recent call last):
  File "/home/zhuhe/.conda/envs/diffhpe/lib/python3.9/site-packages/wandb/apis/normalize.py", line 41, in wrapper
    return func(*args, **kwargs)
  File "/home/zhuhe/.conda/envs/diffhpe/lib/python3.9/site-packages/wandb/sdk/lib/retry.py", line 212, in wrapped_fn
    return retrier(*args, **kargs)
  File "/home/zhuhe/.conda/envs/diffhpe/lib/python3.9/site-packages/wandb/sdk/lib/retry.py", line 131, in __call__
    result = self._call_fn(*args, **kwargs)
  File "/home/zhuhe/.conda/envs/diffhpe/lib/python3.9/site-packages/wandb/sdk/internal/internal_api.py", line 2218, in upload_file
    wandb._sentry.reraise(e)
  File "/home/zhuhe/.conda/envs/diffhpe/lib/python3.9/site-packages/wandb/analytics/sentry.py", line 146, in reraise
    raise exc.with_traceback(sys.exc_info()[2])
  File "/home/zhuhe/.conda/envs/diffhpe/lib/python3.9/site-packages/wandb/sdk/internal/internal_api.py", line 2190, in upload_file
    response.raise_for_status()
  File "/home/zhuhe/.conda/envs/diffhpe/lib/python3.9/site-packages/requests/models.py", line 1021, in raise_for_status
    raise HTTPError(http_error_msg, response=self)
requests.exceptions.HTTPError: 404 Client Error: Not Found for url: https://storage.googleapis.com/wandb-production.appspot.com/ada4321/DiffHPE/pkixnjxi/requirements.txt?Expires=1689061228&GoogleAccessId=gorilla-files-url-signer-man%40wandb-production.iam.gserviceaccount.com&Signature=NAQxJirGwvyXfc0cRoJ4MtKRnTUacTIEIlENB0A%2FMtrAKDYacn35gP3F7M8rBeyjUzuq9NRzpS%2FFPvqgBD5L4RVCWu1UYKway%2BaFAm%2BjyThjc0ruJSlnXMiTyXnvKtbTI1%2BlOk8VhAXeq5ZB96DLJUZI9tOSaxe6IdJgg1YPNu%2BBBrmVxWEw9ow6g%2FYDKP%2BBnvHHSO0oqj4IoDZmkaDUQ5t9CzGnyJHL6pC0vw%2FZURQsLTWRU7XCnniziz8q5HTefNgHFyekq75tokXXNYF2YyKPzyCzB17DB6WhUcU2HM5R35OC9HAQzNDwZaq%2FnS%2FiS3GE394L50uzz%2FHp3UQrdg%3D%3D

During handling of the above exception, another exception occurred:

Traceback (most recent call last):
  File "/home/zhuhe/.conda/envs/diffhpe/lib/python3.9/site-packages/wandb/filesync/upload_job.py", line 127, in push
    self._api.upload_file_retry(
  File "/home/zhuhe/.conda/envs/diffhpe/lib/python3.9/site-packages/wandb/apis/normalize.py", line 51, in wrapper
    raise CommError(message, error)
wandb.errors.CommError: <Response [404]>
2023-07-10 15:40:30,286 ERROR   wandb-upload_0:46331 [upload_job.py:push():136] Failed to upload file: /home/zhuhe/HPE-with-Diffusion/wandb/run-20230710_154013-pkixnjxi/files/config.yaml
Traceback (most recent call last):
  File "/home/zhuhe/.conda/envs/diffhpe/lib/python3.9/site-packages/wandb/apis/normalize.py", line 41, in wrapper
    return func(*args, **kwargs)
  File "/home/zhuhe/.conda/envs/diffhpe/lib/python3.9/site-packages/wandb/sdk/lib/retry.py", line 212, in wrapped_fn
    return retrier(*args, **kargs)
  File "/home/zhuhe/.conda/envs/diffhpe/lib/python3.9/site-packages/wandb/sdk/lib/retry.py", line 131, in __call__
    result = self._call_fn(*args, **kwargs)
  File "/home/zhuhe/.conda/envs/diffhpe/lib/python3.9/site-packages/wandb/sdk/internal/internal_api.py", line 2218, in upload_file
    wandb._sentry.reraise(e)
  File "/home/zhuhe/.conda/envs/diffhpe/lib/python3.9/site-packages/wandb/analytics/sentry.py", line 146, in reraise
    raise exc.with_traceback(sys.exc_info()[2])
  File "/home/zhuhe/.conda/envs/diffhpe/lib/python3.9/site-packages/wandb/sdk/internal/internal_api.py", line 2190, in upload_file
    response.raise_for_status()
  File "/home/zhuhe/.conda/envs/diffhpe/lib/python3.9/site-packages/requests/models.py", line 1021, in raise_for_status
    raise HTTPError(http_error_msg, response=self)
requests.exceptions.HTTPError: 404 Client Error: Not Found for url: https://storage.googleapis.com/wandb-production.appspot.com/ada4321/DiffHPE/pkixnjxi/config.yaml?Expires=1689061228&GoogleAccessId=gorilla-files-url-signer-man%40wandb-production.iam.gserviceaccount.com&Signature=CCy%2BDpz1J5Rm2wL8Sshp7v53mVLSAsQsqvt8vasdrHHD1UQSJdw8cuuzENi1r2s%2FlLqa6w9n16l2XLzLDx8N%2BDF30bEIGvUZ3iyAxvXagpUKXcEy3BnKhlxnHgiB%2F0T0VDYaJXvn4KGlBVnhlJKfgpjnTVr%2BQjdXnyE%2FbX94wIomGhbCbXKN2Oad0XGQXB94PLrnmatGGsrfqKGAwvqsTKwEad8OW2vH1E7U9qYjDsVCvL4L9HRlxU4pTy9RdFghTMtdgZDptHk3f6Rxh547u4cuKC1qIQiS%2FJBj5sW2doNjyap%2F5j%2FfzdPbWFq1lIIyy49LqHDu884KxqH5lqmVhg%3D%3D

During handling of the above exception, another exception occurred:

Traceback (most recent call last):
  File "/home/zhuhe/.conda/envs/diffhpe/lib/python3.9/site-packages/wandb/filesync/upload_job.py", line 127, in push
    self._api.upload_file_retry(
  File "/home/zhuhe/.conda/envs/diffhpe/lib/python3.9/site-packages/wandb/apis/normalize.py", line 51, in wrapper
    raise CommError(message, error)
wandb.errors.CommError: <Response [404]>
2023-07-10 15:40:30,286 ERROR   wandb-upload_2:46331 [upload_job.py:push():136] Failed to upload file: /home/zhuhe/HPE-with-Diffusion/wandb/run-20230710_154013-pkixnjxi/files/wandb-summary.json
Traceback (most recent call last):
  File "/home/zhuhe/.conda/envs/diffhpe/lib/python3.9/site-packages/wandb/apis/normalize.py", line 41, in wrapper
    return func(*args, **kwargs)
  File "/home/zhuhe/.conda/envs/diffhpe/lib/python3.9/site-packages/wandb/sdk/lib/retry.py", line 212, in wrapped_fn
    return retrier(*args, **kargs)
  File "/home/zhuhe/.conda/envs/diffhpe/lib/python3.9/site-packages/wandb/sdk/lib/retry.py", line 131, in __call__
    result = self._call_fn(*args, **kwargs)
  File "/home/zhuhe/.conda/envs/diffhpe/lib/python3.9/site-packages/wandb/sdk/internal/internal_api.py", line 2218, in upload_file
    wandb._sentry.reraise(e)
  File "/home/zhuhe/.conda/envs/diffhpe/lib/python3.9/site-packages/wandb/analytics/sentry.py", line 146, in reraise
    raise exc.with_traceback(sys.exc_info()[2])
  File "/home/zhuhe/.conda/envs/diffhpe/lib/python3.9/site-packages/wandb/sdk/internal/internal_api.py", line 2190, in upload_file
    response.raise_for_status()
  File "/home/zhuhe/.conda/envs/diffhpe/lib/python3.9/site-packages/requests/models.py", line 1021, in raise_for_status
    raise HTTPError(http_error_msg, response=self)
requests.exceptions.HTTPError: 404 Client Error: Not Found for url: https://storage.googleapis.com/wandb-production.appspot.com/ada4321/DiffHPE/pkixnjxi/wandb-summary.json?Expires=1689061229&GoogleAccessId=gorilla-files-url-signer-man%40wandb-production.iam.gserviceaccount.com&Signature=Xtc6kE77yrWPdQJmE1nLGLqf3%2Bp18yw6DtHbeYHRtI4QWV8Jl2HgvpctoCc1miFdBOgBb1O4v7HeYH04OnoXGxFQFSEbSNn%2B0CD86%2B8ugi9fm2YYQ3FryZWMaod6xQuoY2z5%2FuxKMjjinDxAf%2FmBv7YL4H9rz8pKg8rF8f6FYof6tjv5EDSmB7j94tQIrDZjDPcVHzJiMKxXUAYKOtWFQitjNoVeJdm4QI2sNFv7308Tvgmr%2B2KpDMtQB4%2BHtdEGcogG0xHjqt%2Bo39LbsH8XptUsoMJMrN7ji23n3mmXMGNh0oDOFs%2BbiJ5CAwQhVj%2BAkiWt0vsH4FXYMJluCFU%2Fyw%3D%3D

During handling of the above exception, another exception occurred:

Traceback (most recent call last):
  File "/home/zhuhe/.conda/envs/diffhpe/lib/python3.9/site-packages/wandb/filesync/upload_job.py", line 127, in push
    self._api.upload_file_retry(
  File "/home/zhuhe/.conda/envs/diffhpe/lib/python3.9/site-packages/wandb/apis/normalize.py", line 51, in wrapper
    raise CommError(message, error)
wandb.errors.CommError: <Response [404]>
2023-07-10 15:40:30,286 ERROR   wandb-upload_4:46331 [upload_job.py:push():136] Failed to upload file: /home/zhuhe/HPE-with-Diffusion/wandb/run-20230710_154013-pkixnjxi/files/output.log
Traceback (most recent call last):
  File "/home/zhuhe/.conda/envs/diffhpe/lib/python3.9/site-packages/wandb/apis/normalize.py", line 41, in wrapper
    return func(*args, **kwargs)
  File "/home/zhuhe/.conda/envs/diffhpe/lib/python3.9/site-packages/wandb/sdk/lib/retry.py", line 212, in wrapped_fn
    return retrier(*args, **kargs)
  File "/home/zhuhe/.conda/envs/diffhpe/lib/python3.9/site-packages/wandb/sdk/lib/retry.py", line 131, in __call__
    result = self._call_fn(*args, **kwargs)
  File "/home/zhuhe/.conda/envs/diffhpe/lib/python3.9/site-packages/wandb/sdk/internal/internal_api.py", line 2218, in upload_file
    wandb._sentry.reraise(e)
  File "/home/zhuhe/.conda/envs/diffhpe/lib/python3.9/site-packages/wandb/analytics/sentry.py", line 146, in reraise
    raise exc.with_traceback(sys.exc_info()[2])
  File "/home/zhuhe/.conda/envs/diffhpe/lib/python3.9/site-packages/wandb/sdk/internal/internal_api.py", line 2190, in upload_file
    response.raise_for_status()
  File "/home/zhuhe/.conda/envs/diffhpe/lib/python3.9/site-packages/requests/models.py", line 1021, in raise_for_status
    raise HTTPError(http_error_msg, response=self)
requests.exceptions.HTTPError: 404 Client Error: Not Found for url: https://storage.googleapis.com/wandb-production.appspot.com/ada4321/DiffHPE/pkixnjxi/output.log?Expires=1689061229&GoogleAccessId=gorilla-files-url-signer-man%40wandb-production.iam.gserviceaccount.com&Signature=CELGy3w3%2FODelBcq4pVFKFdcwP83Fgf%2BIxXRphdVSHwrH1CxrJ4Wxzcri%2F7tIfxbpImwJ%2Bkxs5g4kxPN52cEWCiYkz3u3bCi%2BGz6UVrnbuA%2Banl25ffm3RLEW%2BSkVj%2BtoaX1VpgeiDGVuNaDzbjjGeDjNxuv3amBOL7811HoEaDAWVckyfSQNsoWHDhlwiiNuyNLzzUtyia7sBBUJs1vb0rR%2FsAjpDjFy%2FgeIbrKNKLk6aoxsXQTUa1gDs82Q6h86B3KAXt%2FRfmHFK6O%2F8YmedLu171RtuEqRoBIDeuevU%2FtmzbMr%2FvAIpzU9wRV7xBVEmswXg9AdNLRw5sVYTFd0A%3D%3D

During handling of the above exception, another exception occurred:

Traceback (most recent call last):
  File "/home/zhuhe/.conda/envs/diffhpe/lib/python3.9/site-packages/wandb/filesync/upload_job.py", line 127, in push
    self._api.upload_file_retry(
  File "/home/zhuhe/.conda/envs/diffhpe/lib/python3.9/site-packages/wandb/apis/normalize.py", line 51, in wrapper
    raise CommError(message, error)
wandb.errors.CommError: <Response [404]>
2023-07-10 15:40:30,287 ERROR   wandb-upload_3:46331 [upload_job.py:push():136] Failed to upload file: /home/zhuhe/HPE-with-Diffusion/wandb/run-20230710_154013-pkixnjxi/files/conda-environment.yaml
Traceback (most recent call last):
  File "/home/zhuhe/.conda/envs/diffhpe/lib/python3.9/site-packages/wandb/apis/normalize.py", line 41, in wrapper
    return func(*args, **kwargs)
  File "/home/zhuhe/.conda/envs/diffhpe/lib/python3.9/site-packages/wandb/sdk/lib/retry.py", line 212, in wrapped_fn
    return retrier(*args, **kargs)
  File "/home/zhuhe/.conda/envs/diffhpe/lib/python3.9/site-packages/wandb/sdk/lib/retry.py", line 131, in __call__
    result = self._call_fn(*args, **kwargs)
  File "/home/zhuhe/.conda/envs/diffhpe/lib/python3.9/site-packages/wandb/sdk/internal/internal_api.py", line 2218, in upload_file
    wandb._sentry.reraise(e)
  File "/home/zhuhe/.conda/envs/diffhpe/lib/python3.9/site-packages/wandb/analytics/sentry.py", line 146, in reraise
    raise exc.with_traceback(sys.exc_info()[2])
  File "/home/zhuhe/.conda/envs/diffhpe/lib/python3.9/site-packages/wandb/sdk/internal/internal_api.py", line 2190, in upload_file
    response.raise_for_status()
  File "/home/zhuhe/.conda/envs/diffhpe/lib/python3.9/site-packages/requests/models.py", line 1021, in raise_for_status
    raise HTTPError(http_error_msg, response=self)
requests.exceptions.HTTPError: 404 Client Error: Not Found for url: https://storage.googleapis.com/wandb-production.appspot.com/ada4321/DiffHPE/pkixnjxi/conda-environment.yaml?Expires=1689061229&GoogleAccessId=gorilla-files-url-signer-man%40wandb-production.iam.gserviceaccount.com&Signature=nF7qXX909GLTpzSsG1YwrrSTyH0wwfr%2B81vme%2BKpN6S%2FBal8%2FXwi5sOjXHsUYKq3GiTZqJENwbmW7VeVhlGFP6hgjYy38wuERCxzx%2FcS1EoJYn5EuTleQf0sq1XNWh%2Fid8Q%2B8PoTSBn4O%2BnqLIJGh13vaev5ZvOLbMvo1rjuHxzZjUl8ey3dWnLsQJGSTHc4VwUyPVWgf6Oko0R%2Fev%2By7xf4fMgmyykuIovHb9EGA8dB4jjzHRO3kCO%2BAvqZ48CJP8Z6yoM%2BcX8ihG6sADmYRSRWQ2tzjj0O6tUf5CKGjddyzrJrHkxLjrTwqbd%2FWlQGajouxnSqnIZd2YGHeRi96g%3D%3D

During handling of the above exception, another exception occurred:

Traceback (most recent call last):
  File "/home/zhuhe/.conda/envs/diffhpe/lib/python3.9/site-packages/wandb/filesync/upload_job.py", line 127, in push
    self._api.upload_file_retry(
  File "/home/zhuhe/.conda/envs/diffhpe/lib/python3.9/site-packages/wandb/apis/normalize.py", line 51, in wrapper
    raise CommError(message, error)
wandb.errors.CommError: <Response [404]>
2023-07-10 15:40:30,296 DEBUG   HandlerThread:46331 [handler.py:handle_request():144] handle_request: keepalive
2023-07-10 15:40:31,304 ERROR   Thread-11 :46331 [step_upload.py:_handle_event():200] Failed to upload file: /home/zhuhe/HPE-with-Diffusion/wandb/run-20230710_154013-pkixnjxi/files/config.yaml
Traceback (most recent call last):
  File "/home/zhuhe/.conda/envs/diffhpe/lib/python3.9/site-packages/wandb/apis/normalize.py", line 41, in wrapper
    return func(*args, **kwargs)
  File "/home/zhuhe/.conda/envs/diffhpe/lib/python3.9/site-packages/wandb/sdk/lib/retry.py", line 212, in wrapped_fn
    return retrier(*args, **kargs)
  File "/home/zhuhe/.conda/envs/diffhpe/lib/python3.9/site-packages/wandb/sdk/lib/retry.py", line 131, in __call__
    result = self._call_fn(*args, **kwargs)
  File "/home/zhuhe/.conda/envs/diffhpe/lib/python3.9/site-packages/wandb/sdk/internal/internal_api.py", line 2218, in upload_file
    wandb._sentry.reraise(e)
  File "/home/zhuhe/.conda/envs/diffhpe/lib/python3.9/site-packages/wandb/analytics/sentry.py", line 146, in reraise
    raise exc.with_traceback(sys.exc_info()[2])
  File "/home/zhuhe/.conda/envs/diffhpe/lib/python3.9/site-packages/wandb/sdk/internal/internal_api.py", line 2190, in upload_file
    response.raise_for_status()
  File "/home/zhuhe/.conda/envs/diffhpe/lib/python3.9/site-packages/requests/models.py", line 1021, in raise_for_status
    raise HTTPError(http_error_msg, response=self)
requests.exceptions.HTTPError: 404 Client Error: Not Found for url: https://storage.googleapis.com/wandb-production.appspot.com/ada4321/DiffHPE/pkixnjxi/config.yaml?Expires=1689061228&GoogleAccessId=gorilla-files-url-signer-man%40wandb-production.iam.gserviceaccount.com&Signature=CCy%2BDpz1J5Rm2wL8Sshp7v53mVLSAsQsqvt8vasdrHHD1UQSJdw8cuuzENi1r2s%2FlLqa6w9n16l2XLzLDx8N%2BDF30bEIGvUZ3iyAxvXagpUKXcEy3BnKhlxnHgiB%2F0T0VDYaJXvn4KGlBVnhlJKfgpjnTVr%2BQjdXnyE%2FbX94wIomGhbCbXKN2Oad0XGQXB94PLrnmatGGsrfqKGAwvqsTKwEad8OW2vH1E7U9qYjDsVCvL4L9HRlxU4pTy9RdFghTMtdgZDptHk3f6Rxh547u4cuKC1qIQiS%2FJBj5sW2doNjyap%2F5j%2FfzdPbWFq1lIIyy49LqHDu884KxqH5lqmVhg%3D%3D

During handling of the above exception, another exception occurred:

Traceback (most recent call last):
  File "/home/zhuhe/.conda/envs/diffhpe/lib/python3.9/concurrent/futures/thread.py", line 58, in run
    result = self.fn(*self.args, **self.kwargs)
  File "/home/zhuhe/.conda/envs/diffhpe/lib/python3.9/site-packages/wandb/filesync/step_upload.py", line 288, in run_and_notify
    self._do_upload_sync(event)
  File "/home/zhuhe/.conda/envs/diffhpe/lib/python3.9/site-packages/wandb/filesync/step_upload.py", line 330, in _do_upload_sync
    job.run()
  File "/home/zhuhe/.conda/envs/diffhpe/lib/python3.9/site-packages/wandb/filesync/upload_job.py", line 57, in run
    self.push()
  File "/home/zhuhe/.conda/envs/diffhpe/lib/python3.9/site-packages/wandb/filesync/upload_job.py", line 127, in push
    self._api.upload_file_retry(
  File "/home/zhuhe/.conda/envs/diffhpe/lib/python3.9/site-packages/wandb/apis/normalize.py", line 51, in wrapper
    raise CommError(message, error)
wandb.errors.CommError: <Response [404]>
2023-07-10 15:40:31,305 ERROR   Thread-11 :46331 [step_upload.py:_handle_event():200] Failed to upload file: /home/zhuhe/HPE-with-Diffusion/wandb/run-20230710_154013-pkixnjxi/files/requirements.txt
Traceback (most recent call last):
  File "/home/zhuhe/.conda/envs/diffhpe/lib/python3.9/site-packages/wandb/apis/normalize.py", line 41, in wrapper
    return func(*args, **kwargs)
  File "/home/zhuhe/.conda/envs/diffhpe/lib/python3.9/site-packages/wandb/sdk/lib/retry.py", line 212, in wrapped_fn
    return retrier(*args, **kargs)
  File "/home/zhuhe/.conda/envs/diffhpe/lib/python3.9/site-packages/wandb/sdk/lib/retry.py", line 131, in __call__
    result = self._call_fn(*args, **kwargs)
  File "/home/zhuhe/.conda/envs/diffhpe/lib/python3.9/site-packages/wandb/sdk/internal/internal_api.py", line 2218, in upload_file
    wandb._sentry.reraise(e)
  File "/home/zhuhe/.conda/envs/diffhpe/lib/python3.9/site-packages/wandb/analytics/sentry.py", line 146, in reraise
    raise exc.with_traceback(sys.exc_info()[2])
  File "/home/zhuhe/.conda/envs/diffhpe/lib/python3.9/site-packages/wandb/sdk/internal/internal_api.py", line 2190, in upload_file
    response.raise_for_status()
  File "/home/zhuhe/.conda/envs/diffhpe/lib/python3.9/site-packages/requests/models.py", line 1021, in raise_for_status
    raise HTTPError(http_error_msg, response=self)
requests.exceptions.HTTPError: 404 Client Error: Not Found for url: https://storage.googleapis.com/wandb-production.appspot.com/ada4321/DiffHPE/pkixnjxi/requirements.txt?Expires=1689061228&GoogleAccessId=gorilla-files-url-signer-man%40wandb-production.iam.gserviceaccount.com&Signature=NAQxJirGwvyXfc0cRoJ4MtKRnTUacTIEIlENB0A%2FMtrAKDYacn35gP3F7M8rBeyjUzuq9NRzpS%2FFPvqgBD5L4RVCWu1UYKway%2BaFAm%2BjyThjc0ruJSlnXMiTyXnvKtbTI1%2BlOk8VhAXeq5ZB96DLJUZI9tOSaxe6IdJgg1YPNu%2BBBrmVxWEw9ow6g%2FYDKP%2BBnvHHSO0oqj4IoDZmkaDUQ5t9CzGnyJHL6pC0vw%2FZURQsLTWRU7XCnniziz8q5HTefNgHFyekq75tokXXNYF2YyKPzyCzB17DB6WhUcU2HM5R35OC9HAQzNDwZaq%2FnS%2FiS3GE394L50uzz%2FHp3UQrdg%3D%3D

During handling of the above exception, another exception occurred:

Traceback (most recent call last):
  File "/home/zhuhe/.conda/envs/diffhpe/lib/python3.9/concurrent/futures/thread.py", line 58, in run
    result = self.fn(*self.args, **self.kwargs)
  File "/home/zhuhe/.conda/envs/diffhpe/lib/python3.9/site-packages/wandb/filesync/step_upload.py", line 288, in run_and_notify
    self._do_upload_sync(event)
  File "/home/zhuhe/.conda/envs/diffhpe/lib/python3.9/site-packages/wandb/filesync/step_upload.py", line 330, in _do_upload_sync
    job.run()
  File "/home/zhuhe/.conda/envs/diffhpe/lib/python3.9/site-packages/wandb/filesync/upload_job.py", line 57, in run
    self.push()
  File "/home/zhuhe/.conda/envs/diffhpe/lib/python3.9/site-packages/wandb/filesync/upload_job.py", line 127, in push
    self._api.upload_file_retry(
  File "/home/zhuhe/.conda/envs/diffhpe/lib/python3.9/site-packages/wandb/apis/normalize.py", line 51, in wrapper
    raise CommError(message, error)
wandb.errors.CommError: <Response [404]>
2023-07-10 15:40:31,305 ERROR   Thread-11 :46331 [step_upload.py:_handle_event():200] Failed to upload file: /home/zhuhe/HPE-with-Diffusion/wandb/run-20230710_154013-pkixnjxi/files/wandb-summary.json
Traceback (most recent call last):
  File "/home/zhuhe/.conda/envs/diffhpe/lib/python3.9/site-packages/wandb/apis/normalize.py", line 41, in wrapper
    return func(*args, **kwargs)
  File "/home/zhuhe/.conda/envs/diffhpe/lib/python3.9/site-packages/wandb/sdk/lib/retry.py", line 212, in wrapped_fn
    return retrier(*args, **kargs)
  File "/home/zhuhe/.conda/envs/diffhpe/lib/python3.9/site-packages/wandb/sdk/lib/retry.py", line 131, in __call__
    result = self._call_fn(*args, **kwargs)
  File "/home/zhuhe/.conda/envs/diffhpe/lib/python3.9/site-packages/wandb/sdk/internal/internal_api.py", line 2218, in upload_file
    wandb._sentry.reraise(e)
  File "/home/zhuhe/.conda/envs/diffhpe/lib/python3.9/site-packages/wandb/analytics/sentry.py", line 146, in reraise
    raise exc.with_traceback(sys.exc_info()[2])
  File "/home/zhuhe/.conda/envs/diffhpe/lib/python3.9/site-packages/wandb/sdk/internal/internal_api.py", line 2190, in upload_file
    response.raise_for_status()
  File "/home/zhuhe/.conda/envs/diffhpe/lib/python3.9/site-packages/requests/models.py", line 1021, in raise_for_status
    raise HTTPError(http_error_msg, response=self)
requests.exceptions.HTTPError: 404 Client Error: Not Found for url: https://storage.googleapis.com/wandb-production.appspot.com/ada4321/DiffHPE/pkixnjxi/wandb-summary.json?Expires=1689061229&GoogleAccessId=gorilla-files-url-signer-man%40wandb-production.iam.gserviceaccount.com&Signature=Xtc6kE77yrWPdQJmE1nLGLqf3%2Bp18yw6DtHbeYHRtI4QWV8Jl2HgvpctoCc1miFdBOgBb1O4v7HeYH04OnoXGxFQFSEbSNn%2B0CD86%2B8ugi9fm2YYQ3FryZWMaod6xQuoY2z5%2FuxKMjjinDxAf%2FmBv7YL4H9rz8pKg8rF8f6FYof6tjv5EDSmB7j94tQIrDZjDPcVHzJiMKxXUAYKOtWFQitjNoVeJdm4QI2sNFv7308Tvgmr%2B2KpDMtQB4%2BHtdEGcogG0xHjqt%2Bo39LbsH8XptUsoMJMrN7ji23n3mmXMGNh0oDOFs%2BbiJ5CAwQhVj%2BAkiWt0vsH4FXYMJluCFU%2Fyw%3D%3D

During handling of the above exception, another exception occurred:

Traceback (most recent call last):
  File "/home/zhuhe/.conda/envs/diffhpe/lib/python3.9/concurrent/futures/thread.py", line 58, in run
    result = self.fn(*self.args, **self.kwargs)
  File "/home/zhuhe/.conda/envs/diffhpe/lib/python3.9/site-packages/wandb/filesync/step_upload.py", line 288, in run_and_notify
    self._do_upload_sync(event)
  File "/home/zhuhe/.conda/envs/diffhpe/lib/python3.9/site-packages/wandb/filesync/step_upload.py", line 330, in _do_upload_sync
    job.run()
  File "/home/zhuhe/.conda/envs/diffhpe/lib/python3.9/site-packages/wandb/filesync/upload_job.py", line 57, in run
    self.push()
  File "/home/zhuhe/.conda/envs/diffhpe/lib/python3.9/site-packages/wandb/filesync/upload_job.py", line 127, in push
    self._api.upload_file_retry(
  File "/home/zhuhe/.conda/envs/diffhpe/lib/python3.9/site-packages/wandb/apis/normalize.py", line 51, in wrapper
    raise CommError(message, error)
wandb.errors.CommError: <Response [404]>
2023-07-10 15:40:31,306 ERROR   Thread-11 :46331 [step_upload.py:_handle_event():200] Failed to upload file: /home/zhuhe/HPE-with-Diffusion/wandb/run-20230710_154013-pkixnjxi/files/output.log
Traceback (most recent call last):
  File "/home/zhuhe/.conda/envs/diffhpe/lib/python3.9/site-packages/wandb/apis/normalize.py", line 41, in wrapper
    return func(*args, **kwargs)
  File "/home/zhuhe/.conda/envs/diffhpe/lib/python3.9/site-packages/wandb/sdk/lib/retry.py", line 212, in wrapped_fn
    return retrier(*args, **kargs)
  File "/home/zhuhe/.conda/envs/diffhpe/lib/python3.9/site-packages/wandb/sdk/lib/retry.py", line 131, in __call__
    result = self._call_fn(*args, **kwargs)
  File "/home/zhuhe/.conda/envs/diffhpe/lib/python3.9/site-packages/wandb/sdk/internal/internal_api.py", line 2218, in upload_file
    wandb._sentry.reraise(e)
  File "/home/zhuhe/.conda/envs/diffhpe/lib/python3.9/site-packages/wandb/analytics/sentry.py", line 146, in reraise
    raise exc.with_traceback(sys.exc_info()[2])
  File "/home/zhuhe/.conda/envs/diffhpe/lib/python3.9/site-packages/wandb/sdk/internal/internal_api.py", line 2190, in upload_file
    response.raise_for_status()
  File "/home/zhuhe/.conda/envs/diffhpe/lib/python3.9/site-packages/requests/models.py", line 1021, in raise_for_status
    raise HTTPError(http_error_msg, response=self)
requests.exceptions.HTTPError: 404 Client Error: Not Found for url: https://storage.googleapis.com/wandb-production.appspot.com/ada4321/DiffHPE/pkixnjxi/output.log?Expires=1689061229&GoogleAccessId=gorilla-files-url-signer-man%40wandb-production.iam.gserviceaccount.com&Signature=CELGy3w3%2FODelBcq4pVFKFdcwP83Fgf%2BIxXRphdVSHwrH1CxrJ4Wxzcri%2F7tIfxbpImwJ%2Bkxs5g4kxPN52cEWCiYkz3u3bCi%2BGz6UVrnbuA%2Banl25ffm3RLEW%2BSkVj%2BtoaX1VpgeiDGVuNaDzbjjGeDjNxuv3amBOL7811HoEaDAWVckyfSQNsoWHDhlwiiNuyNLzzUtyia7sBBUJs1vb0rR%2FsAjpDjFy%2FgeIbrKNKLk6aoxsXQTUa1gDs82Q6h86B3KAXt%2FRfmHFK6O%2F8YmedLu171RtuEqRoBIDeuevU%2FtmzbMr%2FvAIpzU9wRV7xBVEmswXg9AdNLRw5sVYTFd0A%3D%3D

During handling of the above exception, another exception occurred:

Traceback (most recent call last):
  File "/home/zhuhe/.conda/envs/diffhpe/lib/python3.9/concurrent/futures/thread.py", line 58, in run
    result = self.fn(*self.args, **self.kwargs)
  File "/home/zhuhe/.conda/envs/diffhpe/lib/python3.9/site-packages/wandb/filesync/step_upload.py", line 288, in run_and_notify
    self._do_upload_sync(event)
  File "/home/zhuhe/.conda/envs/diffhpe/lib/python3.9/site-packages/wandb/filesync/step_upload.py", line 330, in _do_upload_sync
    job.run()
  File "/home/zhuhe/.conda/envs/diffhpe/lib/python3.9/site-packages/wandb/filesync/upload_job.py", line 57, in run
    self.push()
  File "/home/zhuhe/.conda/envs/diffhpe/lib/python3.9/site-packages/wandb/filesync/upload_job.py", line 127, in push
    self._api.upload_file_retry(
  File "/home/zhuhe/.conda/envs/diffhpe/lib/python3.9/site-packages/wandb/apis/normalize.py", line 51, in wrapper
    raise CommError(message, error)
wandb.errors.CommError: <Response [404]>
2023-07-10 15:40:31,306 ERROR   Thread-11 :46331 [step_upload.py:_handle_event():200] Failed to upload file: /home/zhuhe/HPE-with-Diffusion/wandb/run-20230710_154013-pkixnjxi/files/conda-environment.yaml
Traceback (most recent call last):
  File "/home/zhuhe/.conda/envs/diffhpe/lib/python3.9/site-packages/wandb/apis/normalize.py", line 41, in wrapper
    return func(*args, **kwargs)
  File "/home/zhuhe/.conda/envs/diffhpe/lib/python3.9/site-packages/wandb/sdk/lib/retry.py", line 212, in wrapped_fn
    return retrier(*args, **kargs)
  File "/home/zhuhe/.conda/envs/diffhpe/lib/python3.9/site-packages/wandb/sdk/lib/retry.py", line 131, in __call__
    result = self._call_fn(*args, **kwargs)
  File "/home/zhuhe/.conda/envs/diffhpe/lib/python3.9/site-packages/wandb/sdk/internal/internal_api.py", line 2218, in upload_file
    wandb._sentry.reraise(e)
  File "/home/zhuhe/.conda/envs/diffhpe/lib/python3.9/site-packages/wandb/analytics/sentry.py", line 146, in reraise
    raise exc.with_traceback(sys.exc_info()[2])
  File "/home/zhuhe/.conda/envs/diffhpe/lib/python3.9/site-packages/wandb/sdk/internal/internal_api.py", line 2190, in upload_file
    response.raise_for_status()
  File "/home/zhuhe/.conda/envs/diffhpe/lib/python3.9/site-packages/requests/models.py", line 1021, in raise_for_status
    raise HTTPError(http_error_msg, response=self)
requests.exceptions.HTTPError: 404 Client Error: Not Found for url: https://storage.googleapis.com/wandb-production.appspot.com/ada4321/DiffHPE/pkixnjxi/conda-environment.yaml?Expires=1689061229&GoogleAccessId=gorilla-files-url-signer-man%40wandb-production.iam.gserviceaccount.com&Signature=nF7qXX909GLTpzSsG1YwrrSTyH0wwfr%2B81vme%2BKpN6S%2FBal8%2FXwi5sOjXHsUYKq3GiTZqJENwbmW7VeVhlGFP6hgjYy38wuERCxzx%2FcS1EoJYn5EuTleQf0sq1XNWh%2Fid8Q%2B8PoTSBn4O%2BnqLIJGh13vaev5ZvOLbMvo1rjuHxzZjUl8ey3dWnLsQJGSTHc4VwUyPVWgf6Oko0R%2Fev%2By7xf4fMgmyykuIovHb9EGA8dB4jjzHRO3kCO%2BAvqZ48CJP8Z6yoM%2BcX8ihG6sADmYRSRWQ2tzjj0O6tUf5CKGjddyzrJrHkxLjrTwqbd%2FWlQGajouxnSqnIZd2YGHeRi96g%3D%3D

During handling of the above exception, another exception occurred:

Traceback (most recent call last):
  File "/home/zhuhe/.conda/envs/diffhpe/lib/python3.9/concurrent/futures/thread.py", line 58, in run
    result = self.fn(*self.args, **self.kwargs)
  File "/home/zhuhe/.conda/envs/diffhpe/lib/python3.9/site-packages/wandb/filesync/step_upload.py", line 288, in run_and_notify
    self._do_upload_sync(event)
  File "/home/zhuhe/.conda/envs/diffhpe/lib/python3.9/site-packages/wandb/filesync/step_upload.py", line 330, in _do_upload_sync
    job.run()
  File "/home/zhuhe/.conda/envs/diffhpe/lib/python3.9/site-packages/wandb/filesync/upload_job.py", line 57, in run
    self.push()
  File "/home/zhuhe/.conda/envs/diffhpe/lib/python3.9/site-packages/wandb/filesync/upload_job.py", line 127, in push
    self._api.upload_file_retry(
  File "/home/zhuhe/.conda/envs/diffhpe/lib/python3.9/site-packages/wandb/apis/normalize.py", line 51, in wrapper
    raise CommError(message, error)
wandb.errors.CommError: <Response [404]>
2023-07-10 15:40:31,506 INFO    Thread-11 :46331 [sender.py:transition_state():602] send defer: 11
2023-07-10 15:40:31,506 DEBUG   HandlerThread:46331 [handler.py:handle_request():144] handle_request: defer
2023-07-10 15:40:31,506 INFO    HandlerThread:46331 [handler.py:handle_request_defer():170] handle defer: 11
2023-07-10 15:40:31,507 DEBUG   SenderThread:46331 [sender.py:send_request():396] send_request: defer
2023-07-10 15:40:31,507 INFO    SenderThread:46331 [sender.py:send_request_defer():598] handle sender defer: 11
2023-07-10 15:40:31,507 INFO    SenderThread:46331 [file_pusher.py:join():164] waiting for file pusher
2023-07-10 15:40:31,507 INFO    SenderThread:46331 [sender.py:transition_state():602] send defer: 12
2023-07-10 15:40:31,507 DEBUG   HandlerThread:46331 [handler.py:handle_request():144] handle_request: defer
2023-07-10 15:40:31,507 INFO    HandlerThread:46331 [handler.py:handle_request_defer():170] handle defer: 12
2023-07-10 15:40:31,507 DEBUG   SenderThread:46331 [sender.py:send_request():396] send_request: defer
2023-07-10 15:40:31,507 INFO    SenderThread:46331 [sender.py:send_request_defer():598] handle sender defer: 12
2023-07-10 15:40:31,811 INFO    SenderThread:46331 [sender.py:transition_state():602] send defer: 13
2023-07-10 15:40:31,811 DEBUG   HandlerThread:46331 [handler.py:handle_request():144] handle_request: defer
2023-07-10 15:40:31,811 INFO    HandlerThread:46331 [handler.py:handle_request_defer():170] handle defer: 13
2023-07-10 15:40:31,811 DEBUG   SenderThread:46331 [sender.py:send_request():396] send_request: defer
2023-07-10 15:40:31,812 INFO    SenderThread:46331 [sender.py:send_request_defer():598] handle sender defer: 13
2023-07-10 15:40:31,812 INFO    SenderThread:46331 [sender.py:transition_state():602] send defer: 14
2023-07-10 15:40:31,812 DEBUG   HandlerThread:46331 [handler.py:handle_request():144] handle_request: defer
2023-07-10 15:40:31,812 INFO    HandlerThread:46331 [handler.py:handle_request_defer():170] handle defer: 14
2023-07-10 15:40:31,812 DEBUG   SenderThread:46331 [sender.py:send():369] send: final
2023-07-10 15:40:31,812 DEBUG   SenderThread:46331 [sender.py:send():369] send: footer
2023-07-10 15:40:31,812 DEBUG   SenderThread:46331 [sender.py:send_request():396] send_request: defer
2023-07-10 15:40:31,812 INFO    SenderThread:46331 [sender.py:send_request_defer():598] handle sender defer: 14
2023-07-10 15:40:31,813 DEBUG   HandlerThread:46331 [handler.py:handle_request():144] handle_request: poll_exit
2023-07-10 15:40:31,813 DEBUG   HandlerThread:46331 [handler.py:handle_request():144] handle_request: server_info
2023-07-10 15:40:31,813 DEBUG   HandlerThread:46331 [handler.py:handle_request():144] handle_request: get_summary
2023-07-10 15:40:31,813 DEBUG   SenderThread:46331 [sender.py:send_request():396] send_request: poll_exit
2023-07-10 15:40:31,813 DEBUG   HandlerThread:46331 [handler.py:handle_request():144] handle_request: sampled_history
2023-07-10 15:40:31,813 DEBUG   SenderThread:46331 [sender.py:send_request():396] send_request: server_info
2023-07-10 15:40:32,271 INFO    MainThread:46331 [wandb_run.py:_footer_history_summary_info():3467] rendering history
2023-07-10 15:40:32,271 INFO    MainThread:46331 [wandb_run.py:_footer_history_summary_info():3499] rendering summary
2023-07-10 15:40:32,271 INFO    MainThread:46331 [wandb_run.py:_footer_sync_info():3426] logging synced files
2023-07-10 15:40:32,271 DEBUG   HandlerThread:46331 [handler.py:handle_request():144] handle_request: shutdown
2023-07-10 15:40:32,271 INFO    HandlerThread:46331 [handler.py:finish():854] shutting down handler
2023-07-10 15:40:32,813 INFO    WriterThread:46331 [datastore.py:close():298] close: /home/zhuhe/HPE-with-Diffusion/wandb/run-20230710_154013-pkixnjxi/run-pkixnjxi.wandb
2023-07-10 15:40:33,271 INFO    SenderThread:46331 [sender.py:finish():1526] shutting down sender
2023-07-10 15:40:33,271 INFO    SenderThread:46331 [file_pusher.py:finish():159] shutting down file pusher
2023-07-10 15:40:33,271 INFO    SenderThread:46331 [file_pusher.py:join():164] waiting for file pusher
