2023-07-10 15:01:10,335 INFO    StreamThr :33911 [internal.py:wandb_internal():86] W&B internal server running at pid: 33911, started at: 2023-07-10 15:01:10.335627
2023-07-10 15:01:10,336 DEBUG   HandlerThread:33911 [handler.py:handle_request():144] handle_request: status
2023-07-10 15:01:10,337 INFO    WriterThread:33911 [datastore.py:open_for_write():85] open: /home/zhuhe/HPE-with-Diffusion/wandb/run-20230710_150110-9b8k2jdf/run-9b8k2jdf.wandb
2023-07-10 15:01:10,338 DEBUG   SenderThread:33911 [sender.py:send():369] send: header
2023-07-10 15:01:10,338 DEBUG   SenderThread:33911 [sender.py:send():369] send: run
2023-07-10 15:01:11,153 INFO    SenderThread:33911 [dir_watcher.py:__init__():211] watching files in: /home/zhuhe/HPE-with-Diffusion/wandb/run-20230710_150110-9b8k2jdf/files
2023-07-10 15:01:11,153 INFO    SenderThread:33911 [sender.py:_start_run_threads():1100] run started: 9b8k2jdf with start time 1688972470.335322
2023-07-10 15:01:11,153 DEBUG   SenderThread:33911 [sender.py:send_request():396] send_request: summary_record
2023-07-10 15:01:11,153 INFO    SenderThread:33911 [sender.py:_save_file():1354] saving file wandb-summary.json with policy end
2023-07-10 15:01:11,156 DEBUG   HandlerThread:33911 [handler.py:handle_request():144] handle_request: check_version
2023-07-10 15:01:11,156 DEBUG   SenderThread:33911 [sender.py:send_request():396] send_request: check_version
2023-07-10 15:01:11,333 DEBUG   HandlerThread:33911 [handler.py:handle_request():144] handle_request: run_start
2023-07-10 15:01:11,338 DEBUG   HandlerThread:33911 [system_info.py:__init__():31] System info init
2023-07-10 15:01:11,338 DEBUG   HandlerThread:33911 [system_info.py:__init__():46] System info init done
2023-07-10 15:01:11,338 INFO    HandlerThread:33911 [system_monitor.py:start():181] Starting system monitor
2023-07-10 15:01:11,339 INFO    SystemMonitor:33911 [system_monitor.py:_start():145] Starting system asset monitoring threads
2023-07-10 15:01:11,339 INFO    HandlerThread:33911 [system_monitor.py:probe():201] Collecting system info
2023-07-10 15:01:11,340 INFO    SystemMonitor:33911 [interfaces.py:start():190] Started cpu monitoring
2023-07-10 15:01:11,340 INFO    SystemMonitor:33911 [interfaces.py:start():190] Started disk monitoring
2023-07-10 15:01:11,341 INFO    SystemMonitor:33911 [interfaces.py:start():190] Started gpu monitoring
2023-07-10 15:01:11,341 INFO    SystemMonitor:33911 [interfaces.py:start():190] Started memory monitoring
2023-07-10 15:01:11,341 INFO    SystemMonitor:33911 [interfaces.py:start():190] Started network monitoring
2023-07-10 15:01:11,355 DEBUG   HandlerThread:33911 [system_info.py:probe():195] Probing system
2023-07-10 15:01:11,358 DEBUG   HandlerThread:33911 [gitlib.py:_init_repo():53] git repository is invalid
2023-07-10 15:01:11,358 DEBUG   HandlerThread:33911 [system_info.py:probe():240] Probing system done
2023-07-10 15:01:11,358 DEBUG   HandlerThread:33911 [system_monitor.py:probe():210] {'os': 'Linux-5.19.0-46-generic-x86_64-with-glibc2.35', 'python': '3.9.16', 'heartbeatAt': '2023-07-10T07:01:11.355901', 'startedAt': '2023-07-10T07:01:10.332354', 'docker': None, 'cuda': None, 'args': ('--phase', 'train', '--gpu_ids', '1'), 'state': 'running', 'program': '/home/zhuhe/HPE-with-Diffusion/main.py', 'codePath': 'main.py', 'host': '415-2', 'username': 'zhuhe', 'executable': '/home/zhuhe/.conda/envs/diffhpe/bin/python', 'cpu_count': 16, 'cpu_count_logical': 24, 'cpu_freq': {'current': 4057.7845416666655, 'min': 800.0, 'max': 4783.333333333333}, 'cpu_freq_per_core': [{'current': 5067.763, 'min': 800.0, 'max': 5100.0}, {'current': 5100.012, 'min': 800.0, 'max': 5100.0}, {'current': 5100.0, 'min': 800.0, 'max': 5100.0}, {'current': 4197.187, 'min': 800.0, 'max': 5100.0}, {'current': 4778.814, 'min': 800.0, 'max': 5100.0}, {'current': 2100.0, 'min': 800.0, 'max': 5100.0}, {'current': 5078.477, 'min': 800.0, 'max': 5100.0}, {'current': 2100.0, 'min': 800.0, 'max': 5100.0}, {'current': 5100.0, 'min': 800.0, 'max': 5200.0}, {'current': 2100.0, 'min': 800.0, 'max': 5200.0}, {'current': 5127.99, 'min': 800.0, 'max': 5200.0}, {'current': 2100.0, 'min': 800.0, 'max': 5200.0}, {'current': 5048.554, 'min': 800.0, 'max': 5100.0}, {'current': 4420.276, 'min': 800.0, 'max': 5100.0}, {'current': 5065.792, 'min': 800.0, 'max': 5100.0}, {'current': 4413.829, 'min': 800.0, 'max': 5100.0}, {'current': 3699.063, 'min': 800.0, 'max': 4100.0}, {'current': 4088.0, 'min': 800.0, 'max': 4100.0}, {'current': 3783.506, 'min': 800.0, 'max': 4100.0}, {'current': 3783.52, 'min': 800.0, 'max': 4100.0}, {'current': 3783.511, 'min': 800.0, 'max': 4100.0}, {'current': 3783.518, 'min': 800.0, 'max': 4100.0}, {'current': 3783.511, 'min': 800.0, 'max': 4100.0}, {'current': 3783.506, 'min': 800.0, 'max': 4100.0}], 'disk': {'total': 93.31179428100586, 'used': 0.017879486083984375}, 'gpu': 'NVIDIA GeForce RTX 3090', 'gpu_count': 2, 'gpu_devices': [{'name': 'NVIDIA GeForce RTX 3090', 'memory_total': 25769803776}, {'name': 'NVIDIA GeForce RTX 3090', 'memory_total': 25769803776}], 'memory': {'total': 31.185562133789062}}
2023-07-10 15:01:11,358 INFO    HandlerThread:33911 [system_monitor.py:probe():211] Finished collecting system info
2023-07-10 15:01:11,358 INFO    HandlerThread:33911 [system_monitor.py:probe():214] Publishing system info
2023-07-10 15:01:11,358 DEBUG   HandlerThread:33911 [system_info.py:_save_pip():51] Saving list of pip packages installed into the current environment
2023-07-10 15:01:11,358 DEBUG   HandlerThread:33911 [system_info.py:_save_pip():67] Saving pip packages done
2023-07-10 15:01:11,358 DEBUG   HandlerThread:33911 [system_info.py:_save_conda():74] Saving list of conda packages installed into the current environment
2023-07-10 15:01:12,128 DEBUG   HandlerThread:33911 [system_info.py:_save_conda():86] Saving conda packages done
2023-07-10 15:01:12,129 INFO    HandlerThread:33911 [system_monitor.py:probe():216] Finished publishing system info
2023-07-10 15:01:12,130 DEBUG   SenderThread:33911 [sender.py:send():369] send: files
2023-07-10 15:01:12,130 INFO    SenderThread:33911 [sender.py:_save_file():1354] saving file wandb-metadata.json with policy now
2023-07-10 15:01:12,133 DEBUG   HandlerThread:33911 [handler.py:handle_request():144] handle_request: stop_status
2023-07-10 15:01:12,133 DEBUG   SenderThread:33911 [sender.py:send_request():396] send_request: stop_status
2023-07-10 15:01:12,153 INFO    Thread-12 :33911 [dir_watcher.py:_on_file_created():272] file/dir created: /home/zhuhe/HPE-with-Diffusion/wandb/run-20230710_150110-9b8k2jdf/files/wandb-metadata.json
2023-07-10 15:01:12,154 INFO    Thread-12 :33911 [dir_watcher.py:_on_file_created():272] file/dir created: /home/zhuhe/HPE-with-Diffusion/wandb/run-20230710_150110-9b8k2jdf/files/requirements.txt
2023-07-10 15:01:12,154 INFO    Thread-12 :33911 [dir_watcher.py:_on_file_created():272] file/dir created: /home/zhuhe/HPE-with-Diffusion/wandb/run-20230710_150110-9b8k2jdf/files/wandb-summary.json
2023-07-10 15:01:12,154 INFO    Thread-12 :33911 [dir_watcher.py:_on_file_created():272] file/dir created: /home/zhuhe/HPE-with-Diffusion/wandb/run-20230710_150110-9b8k2jdf/files/conda-environment.yaml
2023-07-10 15:01:12,600 ERROR   wandb-upload_0:33911 [internal_api.py:upload_file():2192] upload_file exception https://storage.googleapis.com/wandb-production.appspot.com/ada4321/DiffHPE/9b8k2jdf/wandb-metadata.json?Expires=1689058872&GoogleAccessId=gorilla-files-url-signer-man%40wandb-production.iam.gserviceaccount.com&Signature=CtWmBmoShgK1%2FonkpyW%2BTz%2BE7rb%2FWdBpVd5b4hWwU5K3NC5rqPdSCSr%2BAs4o5ckLE4TF4DgQk2FoU680BRgfz0kh0VFyYAB7mHqeeEI9Zi8WIDSFb13FC8PrCW0%2BzbM9fP6n7Yi0xYYcEPLD1p2GfPp%2FAtaLfxgyO7sZdN%2Fi49%2F7CFJHZdXbt6m0LgY7clGCcTL6e6szGNGx70vwKuCn3DGK80hMw4xxxhMox5W8EbIU2FBWciPLwK%2FC%2B5fZzPRHCzVURVwQzqUG%2BSxgFRTdhZ3nv%2FmkLztvri49qJH1sPvOk5zm%2BKJmH39mGcSwTFM45xgsBfLRlyqvHYxmWOGqtQ%3D%3D: 404 Client Error: Not Found for url: https://storage.googleapis.com/wandb-production.appspot.com/ada4321/DiffHPE/9b8k2jdf/wandb-metadata.json?Expires=1689058872&GoogleAccessId=gorilla-files-url-signer-man%40wandb-production.iam.gserviceaccount.com&Signature=CtWmBmoShgK1%2FonkpyW%2BTz%2BE7rb%2FWdBpVd5b4hWwU5K3NC5rqPdSCSr%2BAs4o5ckLE4TF4DgQk2FoU680BRgfz0kh0VFyYAB7mHqeeEI9Zi8WIDSFb13FC8PrCW0%2BzbM9fP6n7Yi0xYYcEPLD1p2GfPp%2FAtaLfxgyO7sZdN%2Fi49%2F7CFJHZdXbt6m0LgY7clGCcTL6e6szGNGx70vwKuCn3DGK80hMw4xxxhMox5W8EbIU2FBWciPLwK%2FC%2B5fZzPRHCzVURVwQzqUG%2BSxgFRTdhZ3nv%2FmkLztvri49qJH1sPvOk5zm%2BKJmH39mGcSwTFM45xgsBfLRlyqvHYxmWOGqtQ%3D%3D
2023-07-10 15:01:12,600 ERROR   wandb-upload_0:33911 [internal_api.py:upload_file():2194] upload_file request headers: {'User-Agent': 'python-requests/2.31.0', 'Accept-Encoding': 'gzip, deflate', 'Accept': '*/*', 'Connection': 'keep-alive', 'Content-Length': '3712'}
2023-07-10 15:01:12,600 ERROR   wandb-upload_0:33911 [internal_api.py:upload_file():2196] upload_file response body: b'<!DOCTYPE html>\n<html lang=en>\n  <meta charset=utf-8>\n  <meta name=viewport content="initial-scale=1, minimum-scale=1, width=device-width">\n  <title>Error 404 (Not Found)!!1</title>\n  <style>\n    *{margin:0;padding:0}html,code{font:15px/22px arial,sans-serif}html{background:#fff;color:#222;padding:15px}body{margin:7% auto 0;max-width:390px;min-height:180px;padding:30px 0 15px}* > body{background:url(//www.google.com/images/errors/robot.png) 100% 5px no-repeat;padding-right:205px}p{margin:11px 0 22px;overflow:hidden}ins{color:#777;text-decoration:none}a img{border:0}@media screen and (max-width:772px){body{background:none;margin-top:0;max-width:none;padding-right:0}}#logo{background:url(//www.google.com/images/branding/googlelogo/1x/googlelogo_color_150x54dp.png) no-repeat;margin-left:-5px}@media only screen and (min-resolution:192dpi){#logo{background:url(//www.google.com/images/branding/googlelogo/2x/googlelogo_color_150x54dp.png) no-repeat 0% 0%/100% 100%;-moz-border-image:url(//www.google.com/images/branding/googlelogo/2x/googlelogo_color_150x54dp.png) 0}}@media only screen and (-webkit-min-device-pixel-ratio:2){#logo{background:url(//www.google.com/images/branding/googlelogo/2x/googlelogo_color_150x54dp.png) no-repeat;-webkit-background-size:100% 100%}}#logo{display:inline-block;height:54px;width:150px}\n  </style>\n  <a href=//www.google.com/><span id=logo aria-label=Google></span></a>\n  <p><b>404.</b> <ins>That\xe2\x80\x99s an error.</ins>\n  <p>The requested URL <code>/wandb-production.appspot.com/ada4321/DiffHPE/9b8k2jdf/wandb-metadata.json</code> was not found on this server.  <ins>That\xe2\x80\x99s all we know.</ins>\n'
2023-07-10 15:01:12,710 DEBUG   SenderThread:33911 [sender.py:send():369] send: telemetry
2023-07-10 15:01:12,712 DEBUG   SenderThread:33911 [sender.py:send():369] send: exit
2023-07-10 15:01:12,712 INFO    SenderThread:33911 [sender.py:send_exit():574] handling exit code: 1
2023-07-10 15:01:12,712 INFO    SenderThread:33911 [sender.py:send_exit():576] handling runtime: 0
2023-07-10 15:01:12,712 INFO    SenderThread:33911 [sender.py:_save_file():1354] saving file wandb-summary.json with policy end
2023-07-10 15:01:12,712 INFO    SenderThread:33911 [sender.py:send_exit():582] send defer
2023-07-10 15:01:12,712 DEBUG   HandlerThread:33911 [handler.py:handle_request():144] handle_request: defer
2023-07-10 15:01:12,712 INFO    HandlerThread:33911 [handler.py:handle_request_defer():170] handle defer: 0
2023-07-10 15:01:12,713 DEBUG   SenderThread:33911 [sender.py:send_request():396] send_request: defer
2023-07-10 15:01:12,713 INFO    SenderThread:33911 [sender.py:send_request_defer():598] handle sender defer: 0
2023-07-10 15:01:12,713 INFO    SenderThread:33911 [sender.py:transition_state():602] send defer: 1
2023-07-10 15:01:12,713 DEBUG   HandlerThread:33911 [handler.py:handle_request():144] handle_request: defer
2023-07-10 15:01:12,713 INFO    HandlerThread:33911 [handler.py:handle_request_defer():170] handle defer: 1
2023-07-10 15:01:12,713 DEBUG   SenderThread:33911 [sender.py:send_request():396] send_request: defer
2023-07-10 15:01:12,713 INFO    SenderThread:33911 [sender.py:send_request_defer():598] handle sender defer: 1
2023-07-10 15:01:12,713 INFO    SenderThread:33911 [sender.py:transition_state():602] send defer: 2
2023-07-10 15:01:12,713 DEBUG   HandlerThread:33911 [handler.py:handle_request():144] handle_request: defer
2023-07-10 15:01:12,713 INFO    HandlerThread:33911 [handler.py:handle_request_defer():170] handle defer: 2
2023-07-10 15:01:12,713 INFO    HandlerThread:33911 [system_monitor.py:finish():190] Stopping system monitor
2023-07-10 15:01:12,713 DEBUG   SystemMonitor:33911 [system_monitor.py:_start():159] Starting system metrics aggregation loop
2023-07-10 15:01:12,714 DEBUG   SystemMonitor:33911 [system_monitor.py:_start():166] Finished system metrics aggregation loop
2023-07-10 15:01:12,714 DEBUG   SystemMonitor:33911 [system_monitor.py:_start():170] Publishing last batch of metrics
2023-07-10 15:01:12,714 INFO    HandlerThread:33911 [interfaces.py:finish():202] Joined cpu monitor
2023-07-10 15:01:12,714 INFO    HandlerThread:33911 [interfaces.py:finish():202] Joined disk monitor
2023-07-10 15:01:12,757 INFO    HandlerThread:33911 [interfaces.py:finish():202] Joined gpu monitor
2023-07-10 15:01:12,758 INFO    HandlerThread:33911 [interfaces.py:finish():202] Joined memory monitor
2023-07-10 15:01:12,758 INFO    HandlerThread:33911 [interfaces.py:finish():202] Joined network monitor
2023-07-10 15:01:12,758 DEBUG   SenderThread:33911 [sender.py:send_request():396] send_request: defer
2023-07-10 15:01:12,758 INFO    SenderThread:33911 [sender.py:send_request_defer():598] handle sender defer: 2
2023-07-10 15:01:12,758 INFO    SenderThread:33911 [sender.py:transition_state():602] send defer: 3
2023-07-10 15:01:12,758 DEBUG   SenderThread:33911 [sender.py:send():369] send: stats
2023-07-10 15:01:12,758 DEBUG   HandlerThread:33911 [handler.py:handle_request():144] handle_request: defer
2023-07-10 15:01:12,758 INFO    HandlerThread:33911 [handler.py:handle_request_defer():170] handle defer: 3
2023-07-10 15:01:12,759 DEBUG   SenderThread:33911 [sender.py:send_request():396] send_request: defer
2023-07-10 15:01:12,759 INFO    SenderThread:33911 [sender.py:send_request_defer():598] handle sender defer: 3
2023-07-10 15:01:12,759 INFO    SenderThread:33911 [sender.py:transition_state():602] send defer: 4
2023-07-10 15:01:12,759 DEBUG   HandlerThread:33911 [handler.py:handle_request():144] handle_request: defer
2023-07-10 15:01:12,759 INFO    HandlerThread:33911 [handler.py:handle_request_defer():170] handle defer: 4
2023-07-10 15:01:12,759 DEBUG   SenderThread:33911 [sender.py:send_request():396] send_request: defer
2023-07-10 15:01:12,759 INFO    SenderThread:33911 [sender.py:send_request_defer():598] handle sender defer: 4
2023-07-10 15:01:12,759 INFO    SenderThread:33911 [sender.py:transition_state():602] send defer: 5
2023-07-10 15:01:12,759 DEBUG   HandlerThread:33911 [handler.py:handle_request():144] handle_request: defer
2023-07-10 15:01:12,759 INFO    HandlerThread:33911 [handler.py:handle_request_defer():170] handle defer: 5
2023-07-10 15:01:12,759 DEBUG   SenderThread:33911 [sender.py:send():369] send: summary
2023-07-10 15:01:12,760 INFO    SenderThread:33911 [sender.py:_save_file():1354] saving file wandb-summary.json with policy end
2023-07-10 15:01:12,760 DEBUG   SenderThread:33911 [sender.py:send_request():396] send_request: defer
2023-07-10 15:01:12,760 INFO    SenderThread:33911 [sender.py:send_request_defer():598] handle sender defer: 5
2023-07-10 15:01:12,760 INFO    SenderThread:33911 [sender.py:transition_state():602] send defer: 6
2023-07-10 15:01:12,760 DEBUG   HandlerThread:33911 [handler.py:handle_request():144] handle_request: defer
2023-07-10 15:01:12,760 INFO    HandlerThread:33911 [handler.py:handle_request_defer():170] handle defer: 6
2023-07-10 15:01:12,760 DEBUG   SenderThread:33911 [sender.py:send_request():396] send_request: defer
2023-07-10 15:01:12,760 INFO    SenderThread:33911 [sender.py:send_request_defer():598] handle sender defer: 6
2023-07-10 15:01:12,761 DEBUG   HandlerThread:33911 [handler.py:handle_request():144] handle_request: status_report
2023-07-10 15:01:13,016 INFO    SenderThread:33911 [sender.py:transition_state():602] send defer: 7
2023-07-10 15:01:13,016 DEBUG   HandlerThread:33911 [handler.py:handle_request():144] handle_request: defer
2023-07-10 15:01:13,016 INFO    HandlerThread:33911 [handler.py:handle_request_defer():170] handle defer: 7
2023-07-10 15:01:13,016 DEBUG   SenderThread:33911 [sender.py:send_request():396] send_request: defer
2023-07-10 15:01:13,016 INFO    SenderThread:33911 [sender.py:send_request_defer():598] handle sender defer: 7
2023-07-10 15:01:13,136 DEBUG   HandlerThread:33911 [handler.py:handle_request():144] handle_request: poll_exit
2023-07-10 15:01:13,138 ERROR   wandb-upload_0:33911 [upload_job.py:push():136] Failed to upload file: /tmp/tmp3md2j_0nwandb/p8cfyyrq-wandb-metadata.json
Traceback (most recent call last):
  File "/home/zhuhe/.conda/envs/diffhpe/lib/python3.9/site-packages/wandb/apis/normalize.py", line 41, in wrapper
    return func(*args, **kwargs)
  File "/home/zhuhe/.conda/envs/diffhpe/lib/python3.9/site-packages/wandb/sdk/lib/retry.py", line 212, in wrapped_fn
    return retrier(*args, **kargs)
  File "/home/zhuhe/.conda/envs/diffhpe/lib/python3.9/site-packages/wandb/sdk/lib/retry.py", line 131, in __call__
    result = self._call_fn(*args, **kwargs)
  File "/home/zhuhe/.conda/envs/diffhpe/lib/python3.9/site-packages/wandb/sdk/internal/internal_api.py", line 2218, in upload_file
    wandb._sentry.reraise(e)
  File "/home/zhuhe/.conda/envs/diffhpe/lib/python3.9/site-packages/wandb/analytics/sentry.py", line 146, in reraise
    raise exc.with_traceback(sys.exc_info()[2])
  File "/home/zhuhe/.conda/envs/diffhpe/lib/python3.9/site-packages/wandb/sdk/internal/internal_api.py", line 2190, in upload_file
    response.raise_for_status()
  File "/home/zhuhe/.conda/envs/diffhpe/lib/python3.9/site-packages/requests/models.py", line 1021, in raise_for_status
    raise HTTPError(http_error_msg, response=self)
requests.exceptions.HTTPError: 404 Client Error: Not Found for url: https://storage.googleapis.com/wandb-production.appspot.com/ada4321/DiffHPE/9b8k2jdf/wandb-metadata.json?Expires=1689058872&GoogleAccessId=gorilla-files-url-signer-man%40wandb-production.iam.gserviceaccount.com&Signature=CtWmBmoShgK1%2FonkpyW%2BTz%2BE7rb%2FWdBpVd5b4hWwU5K3NC5rqPdSCSr%2BAs4o5ckLE4TF4DgQk2FoU680BRgfz0kh0VFyYAB7mHqeeEI9Zi8WIDSFb13FC8PrCW0%2BzbM9fP6n7Yi0xYYcEPLD1p2GfPp%2FAtaLfxgyO7sZdN%2Fi49%2F7CFJHZdXbt6m0LgY7clGCcTL6e6szGNGx70vwKuCn3DGK80hMw4xxxhMox5W8EbIU2FBWciPLwK%2FC%2B5fZzPRHCzVURVwQzqUG%2BSxgFRTdhZ3nv%2FmkLztvri49qJH1sPvOk5zm%2BKJmH39mGcSwTFM45xgsBfLRlyqvHYxmWOGqtQ%3D%3D

During handling of the above exception, another exception occurred:

Traceback (most recent call last):
  File "/home/zhuhe/.conda/envs/diffhpe/lib/python3.9/site-packages/wandb/filesync/upload_job.py", line 127, in push
    self._api.upload_file_retry(
  File "/home/zhuhe/.conda/envs/diffhpe/lib/python3.9/site-packages/wandb/apis/normalize.py", line 51, in wrapper
    raise CommError(message, error)
wandb.errors.CommError: <Response [404]>
2023-07-10 15:01:13,153 INFO    Thread-12 :33911 [dir_watcher.py:_on_file_modified():289] file/dir modified: /home/zhuhe/HPE-with-Diffusion/wandb/run-20230710_150110-9b8k2jdf/files/config.yaml
2023-07-10 15:01:13,153 INFO    Thread-12 :33911 [dir_watcher.py:_on_file_modified():289] file/dir modified: /home/zhuhe/HPE-with-Diffusion/wandb/run-20230710_150110-9b8k2jdf/files/wandb-summary.json
2023-07-10 15:01:13,153 INFO    Thread-12 :33911 [dir_watcher.py:_on_file_created():272] file/dir created: /home/zhuhe/HPE-with-Diffusion/wandb/run-20230710_150110-9b8k2jdf/files/output.log
2023-07-10 15:01:13,343 ERROR   Thread-11 :33911 [step_upload.py:_handle_event():200] Failed to upload file: /tmp/tmp3md2j_0nwandb/p8cfyyrq-wandb-metadata.json
Traceback (most recent call last):
  File "/home/zhuhe/.conda/envs/diffhpe/lib/python3.9/site-packages/wandb/apis/normalize.py", line 41, in wrapper
    return func(*args, **kwargs)
  File "/home/zhuhe/.conda/envs/diffhpe/lib/python3.9/site-packages/wandb/sdk/lib/retry.py", line 212, in wrapped_fn
    return retrier(*args, **kargs)
  File "/home/zhuhe/.conda/envs/diffhpe/lib/python3.9/site-packages/wandb/sdk/lib/retry.py", line 131, in __call__
    result = self._call_fn(*args, **kwargs)
  File "/home/zhuhe/.conda/envs/diffhpe/lib/python3.9/site-packages/wandb/sdk/internal/internal_api.py", line 2218, in upload_file
    wandb._sentry.reraise(e)
  File "/home/zhuhe/.conda/envs/diffhpe/lib/python3.9/site-packages/wandb/analytics/sentry.py", line 146, in reraise
    raise exc.with_traceback(sys.exc_info()[2])
  File "/home/zhuhe/.conda/envs/diffhpe/lib/python3.9/site-packages/wandb/sdk/internal/internal_api.py", line 2190, in upload_file
    response.raise_for_status()
  File "/home/zhuhe/.conda/envs/diffhpe/lib/python3.9/site-packages/requests/models.py", line 1021, in raise_for_status
    raise HTTPError(http_error_msg, response=self)
requests.exceptions.HTTPError: 404 Client Error: Not Found for url: https://storage.googleapis.com/wandb-production.appspot.com/ada4321/DiffHPE/9b8k2jdf/wandb-metadata.json?Expires=1689058872&GoogleAccessId=gorilla-files-url-signer-man%40wandb-production.iam.gserviceaccount.com&Signature=CtWmBmoShgK1%2FonkpyW%2BTz%2BE7rb%2FWdBpVd5b4hWwU5K3NC5rqPdSCSr%2BAs4o5ckLE4TF4DgQk2FoU680BRgfz0kh0VFyYAB7mHqeeEI9Zi8WIDSFb13FC8PrCW0%2BzbM9fP6n7Yi0xYYcEPLD1p2GfPp%2FAtaLfxgyO7sZdN%2Fi49%2F7CFJHZdXbt6m0LgY7clGCcTL6e6szGNGx70vwKuCn3DGK80hMw4xxxhMox5W8EbIU2FBWciPLwK%2FC%2B5fZzPRHCzVURVwQzqUG%2BSxgFRTdhZ3nv%2FmkLztvri49qJH1sPvOk5zm%2BKJmH39mGcSwTFM45xgsBfLRlyqvHYxmWOGqtQ%3D%3D

During handling of the above exception, another exception occurred:

Traceback (most recent call last):
  File "/home/zhuhe/.conda/envs/diffhpe/lib/python3.9/concurrent/futures/thread.py", line 58, in run
    result = self.fn(*self.args, **self.kwargs)
  File "/home/zhuhe/.conda/envs/diffhpe/lib/python3.9/site-packages/wandb/filesync/step_upload.py", line 288, in run_and_notify
    self._do_upload_sync(event)
  File "/home/zhuhe/.conda/envs/diffhpe/lib/python3.9/site-packages/wandb/filesync/step_upload.py", line 330, in _do_upload_sync
    job.run()
  File "/home/zhuhe/.conda/envs/diffhpe/lib/python3.9/site-packages/wandb/filesync/upload_job.py", line 57, in run
    self.push()
  File "/home/zhuhe/.conda/envs/diffhpe/lib/python3.9/site-packages/wandb/filesync/upload_job.py", line 127, in push
    self._api.upload_file_retry(
  File "/home/zhuhe/.conda/envs/diffhpe/lib/python3.9/site-packages/wandb/apis/normalize.py", line 51, in wrapper
    raise CommError(message, error)
wandb.errors.CommError: <Response [404]>
2023-07-10 15:01:15,154 INFO    Thread-12 :33911 [dir_watcher.py:_on_file_modified():289] file/dir modified: /home/zhuhe/HPE-with-Diffusion/wandb/run-20230710_150110-9b8k2jdf/files/output.log
2023-07-10 15:01:16,718 INFO    SenderThread:33911 [sender.py:transition_state():602] send defer: 8
2023-07-10 15:01:16,718 DEBUG   SenderThread:33911 [sender.py:send_request():396] send_request: poll_exit
2023-07-10 15:01:16,718 DEBUG   HandlerThread:33911 [handler.py:handle_request():144] handle_request: defer
2023-07-10 15:01:16,718 INFO    HandlerThread:33911 [handler.py:handle_request_defer():170] handle defer: 8
2023-07-10 15:01:16,718 DEBUG   SenderThread:33911 [sender.py:send_request():396] send_request: defer
2023-07-10 15:01:16,718 INFO    SenderThread:33911 [sender.py:send_request_defer():598] handle sender defer: 8
2023-07-10 15:01:16,718 INFO    SenderThread:33911 [job_builder.py:build():232] Attempting to build job artifact
2023-07-10 15:01:16,719 INFO    SenderThread:33911 [job_builder.py:build():266] no source found
2023-07-10 15:01:16,719 INFO    SenderThread:33911 [sender.py:transition_state():602] send defer: 9
2023-07-10 15:01:16,719 DEBUG   HandlerThread:33911 [handler.py:handle_request():144] handle_request: defer
2023-07-10 15:01:16,719 INFO    HandlerThread:33911 [handler.py:handle_request_defer():170] handle defer: 9
2023-07-10 15:01:16,719 DEBUG   SenderThread:33911 [sender.py:send_request():396] send_request: defer
2023-07-10 15:01:16,719 INFO    SenderThread:33911 [sender.py:send_request_defer():598] handle sender defer: 9
2023-07-10 15:01:16,719 INFO    SenderThread:33911 [dir_watcher.py:finish():359] shutting down directory watcher
2023-07-10 15:01:17,154 INFO    Thread-12 :33911 [dir_watcher.py:_on_file_modified():289] file/dir modified: /home/zhuhe/HPE-with-Diffusion/wandb/run-20230710_150110-9b8k2jdf/files/output.log
2023-07-10 15:01:17,155 INFO    SenderThread:33911 [dir_watcher.py:finish():389] scan: /home/zhuhe/HPE-with-Diffusion/wandb/run-20230710_150110-9b8k2jdf/files
2023-07-10 15:01:17,155 INFO    SenderThread:33911 [dir_watcher.py:finish():403] scan save: /home/zhuhe/HPE-with-Diffusion/wandb/run-20230710_150110-9b8k2jdf/files/wandb-metadata.json wandb-metadata.json
2023-07-10 15:01:17,155 INFO    SenderThread:33911 [dir_watcher.py:finish():403] scan save: /home/zhuhe/HPE-with-Diffusion/wandb/run-20230710_150110-9b8k2jdf/files/config.yaml config.yaml
2023-07-10 15:01:17,155 INFO    SenderThread:33911 [dir_watcher.py:finish():403] scan save: /home/zhuhe/HPE-with-Diffusion/wandb/run-20230710_150110-9b8k2jdf/files/requirements.txt requirements.txt
2023-07-10 15:01:17,155 INFO    SenderThread:33911 [dir_watcher.py:finish():403] scan save: /home/zhuhe/HPE-with-Diffusion/wandb/run-20230710_150110-9b8k2jdf/files/wandb-summary.json wandb-summary.json
2023-07-10 15:01:17,155 INFO    SenderThread:33911 [dir_watcher.py:finish():403] scan save: /home/zhuhe/HPE-with-Diffusion/wandb/run-20230710_150110-9b8k2jdf/files/conda-environment.yaml conda-environment.yaml
2023-07-10 15:01:17,155 INFO    SenderThread:33911 [dir_watcher.py:finish():403] scan save: /home/zhuhe/HPE-with-Diffusion/wandb/run-20230710_150110-9b8k2jdf/files/output.log output.log
2023-07-10 15:01:17,157 INFO    SenderThread:33911 [sender.py:transition_state():602] send defer: 10
2023-07-10 15:01:17,158 DEBUG   HandlerThread:33911 [handler.py:handle_request():144] handle_request: defer
2023-07-10 15:01:17,158 INFO    HandlerThread:33911 [handler.py:handle_request_defer():170] handle defer: 10
2023-07-10 15:01:17,161 DEBUG   SenderThread:33911 [sender.py:send_request():396] send_request: defer
2023-07-10 15:01:17,161 INFO    SenderThread:33911 [sender.py:send_request_defer():598] handle sender defer: 10
2023-07-10 15:01:17,161 INFO    SenderThread:33911 [file_pusher.py:finish():159] shutting down file pusher
2023-07-10 15:01:17,610 ERROR   wandb-upload_1:33911 [internal_api.py:upload_file():2192] upload_file exception https://storage.googleapis.com/wandb-production.appspot.com/ada4321/DiffHPE/9b8k2jdf/config.yaml?Expires=1689058877&GoogleAccessId=gorilla-files-url-signer-man%40wandb-production.iam.gserviceaccount.com&Signature=ZRGus5yWeBiofHv8kISECwHiWYjriTsIHT4iwT7YgBuLIuk6Hi%2F8aqQrGFMzuTfxdsjNx84gVzMJIJTkoSifP5Dqqfo01UaPTa9cq61h%2B3HcYK9iSv2kl1%2BnqdcPsLpPKshkOhclqbjqQrkCvGAg0UYuyeHVxXmNOku2xUWuK86PL3%2FzgJWfVEG2W82Y0D0paB%2FSNUPgEwxff4hULChoQsINKPehRbqX%2B1hDm6yTwW5sOCyeKcn4P%2B3hj31oCs5IKAgei%2B3iwrkdsdVIGHa8KtQ9vP4pZcttyYykyoxX6DLjaJWPp6PdQ%2BCvkjp9VYU2QRnXGAo0Hy0gwjUFt4TErg%3D%3D: 404 Client Error: Not Found for url: https://storage.googleapis.com/wandb-production.appspot.com/ada4321/DiffHPE/9b8k2jdf/config.yaml?Expires=1689058877&GoogleAccessId=gorilla-files-url-signer-man%40wandb-production.iam.gserviceaccount.com&Signature=ZRGus5yWeBiofHv8kISECwHiWYjriTsIHT4iwT7YgBuLIuk6Hi%2F8aqQrGFMzuTfxdsjNx84gVzMJIJTkoSifP5Dqqfo01UaPTa9cq61h%2B3HcYK9iSv2kl1%2BnqdcPsLpPKshkOhclqbjqQrkCvGAg0UYuyeHVxXmNOku2xUWuK86PL3%2FzgJWfVEG2W82Y0D0paB%2FSNUPgEwxff4hULChoQsINKPehRbqX%2B1hDm6yTwW5sOCyeKcn4P%2B3hj31oCs5IKAgei%2B3iwrkdsdVIGHa8KtQ9vP4pZcttyYykyoxX6DLjaJWPp6PdQ%2BCvkjp9VYU2QRnXGAo0Hy0gwjUFt4TErg%3D%3D
2023-07-10 15:01:17,610 ERROR   wandb-upload_1:33911 [internal_api.py:upload_file():2194] upload_file request headers: {'User-Agent': 'python-requests/2.31.0', 'Accept-Encoding': 'gzip, deflate', 'Accept': '*/*', 'Connection': 'keep-alive', 'Content-Length': '514'}
2023-07-10 15:01:17,610 ERROR   wandb-upload_1:33911 [internal_api.py:upload_file():2196] upload_file response body: b'<!DOCTYPE html>\n<html lang=en>\n  <meta charset=utf-8>\n  <meta name=viewport content="initial-scale=1, minimum-scale=1, width=device-width">\n  <title>Error 404 (Not Found)!!1</title>\n  <style>\n    *{margin:0;padding:0}html,code{font:15px/22px arial,sans-serif}html{background:#fff;color:#222;padding:15px}body{margin:7% auto 0;max-width:390px;min-height:180px;padding:30px 0 15px}* > body{background:url(//www.google.com/images/errors/robot.png) 100% 5px no-repeat;padding-right:205px}p{margin:11px 0 22px;overflow:hidden}ins{color:#777;text-decoration:none}a img{border:0}@media screen and (max-width:772px){body{background:none;margin-top:0;max-width:none;padding-right:0}}#logo{background:url(//www.google.com/images/branding/googlelogo/1x/googlelogo_color_150x54dp.png) no-repeat;margin-left:-5px}@media only screen and (min-resolution:192dpi){#logo{background:url(//www.google.com/images/branding/googlelogo/2x/googlelogo_color_150x54dp.png) no-repeat 0% 0%/100% 100%;-moz-border-image:url(//www.google.com/images/branding/googlelogo/2x/googlelogo_color_150x54dp.png) 0}}@media only screen and (-webkit-min-device-pixel-ratio:2){#logo{background:url(//www.google.com/images/branding/googlelogo/2x/googlelogo_color_150x54dp.png) no-repeat;-webkit-background-size:100% 100%}}#logo{display:inline-block;height:54px;width:150px}\n  </style>\n  <a href=//www.google.com/><span id=logo aria-label=Google></span></a>\n  <p><b>404.</b> <ins>That\xe2\x80\x99s an error.</ins>\n  <p>The requested URL <code>/wandb-production.appspot.com/ada4321/DiffHPE/9b8k2jdf/config.yaml</code> was not found on this server.  <ins>That\xe2\x80\x99s all we know.</ins>\n'
2023-07-10 15:01:17,615 ERROR   wandb-upload_2:33911 [internal_api.py:upload_file():2192] upload_file exception https://storage.googleapis.com/wandb-production.appspot.com/ada4321/DiffHPE/9b8k2jdf/requirements.txt?Expires=1689058877&GoogleAccessId=gorilla-files-url-signer-man%40wandb-production.iam.gserviceaccount.com&Signature=RQj1%2FwRpqETEWTqhx0u2%2Bp%2FHT3HWKWrcS5%2BrTBug76ClRaHPp%2F1mt6kE0kK4p2LXAIccUX8O%2BOogTwiUFRXZElemaPe%2BWGgyevyEAK68uQXea0bxxlaeiv9CIumXd%2BsrDnICUxi93jrc1k0im7c4XbZyj%2BCw2jjeKn3KEr6vKjoW4cJN7r2VMdIHuvu40qV0%2FkY0PHsI76ukjrPXj0BWjn76ZrqQhcTHi2XVBABdNoHaVqPOdIh%2Bk4vimJPhPBuVjQHoRVZsQp7YU%2F%2BqUX4QGsEK0PBuXwiLCgXs6ASpX5UDN2bCI6%2FjL%2B3EoBqggUyqcEsYjq%2BxkHNHkbeyDBrVNA%3D%3D: 404 Client Error: Not Found for url: https://storage.googleapis.com/wandb-production.appspot.com/ada4321/DiffHPE/9b8k2jdf/requirements.txt?Expires=1689058877&GoogleAccessId=gorilla-files-url-signer-man%40wandb-production.iam.gserviceaccount.com&Signature=RQj1%2FwRpqETEWTqhx0u2%2Bp%2FHT3HWKWrcS5%2BrTBug76ClRaHPp%2F1mt6kE0kK4p2LXAIccUX8O%2BOogTwiUFRXZElemaPe%2BWGgyevyEAK68uQXea0bxxlaeiv9CIumXd%2BsrDnICUxi93jrc1k0im7c4XbZyj%2BCw2jjeKn3KEr6vKjoW4cJN7r2VMdIHuvu40qV0%2FkY0PHsI76ukjrPXj0BWjn76ZrqQhcTHi2XVBABdNoHaVqPOdIh%2Bk4vimJPhPBuVjQHoRVZsQp7YU%2F%2BqUX4QGsEK0PBuXwiLCgXs6ASpX5UDN2bCI6%2FjL%2B3EoBqggUyqcEsYjq%2BxkHNHkbeyDBrVNA%3D%3D
2023-07-10 15:01:17,615 ERROR   wandb-upload_2:33911 [internal_api.py:upload_file():2194] upload_file request headers: {'User-Agent': 'python-requests/2.31.0', 'Accept-Encoding': 'gzip, deflate', 'Accept': '*/*', 'Connection': 'keep-alive', 'Content-Length': '910'}
2023-07-10 15:01:17,615 ERROR   wandb-upload_2:33911 [internal_api.py:upload_file():2196] upload_file response body: b'<!DOCTYPE html>\n<html lang=en>\n  <meta charset=utf-8>\n  <meta name=viewport content="initial-scale=1, minimum-scale=1, width=device-width">\n  <title>Error 404 (Not Found)!!1</title>\n  <style>\n    *{margin:0;padding:0}html,code{font:15px/22px arial,sans-serif}html{background:#fff;color:#222;padding:15px}body{margin:7% auto 0;max-width:390px;min-height:180px;padding:30px 0 15px}* > body{background:url(//www.google.com/images/errors/robot.png) 100% 5px no-repeat;padding-right:205px}p{margin:11px 0 22px;overflow:hidden}ins{color:#777;text-decoration:none}a img{border:0}@media screen and (max-width:772px){body{background:none;margin-top:0;max-width:none;padding-right:0}}#logo{background:url(//www.google.com/images/branding/googlelogo/1x/googlelogo_color_150x54dp.png) no-repeat;margin-left:-5px}@media only screen and (min-resolution:192dpi){#logo{background:url(//www.google.com/images/branding/googlelogo/2x/googlelogo_color_150x54dp.png) no-repeat 0% 0%/100% 100%;-moz-border-image:url(//www.google.com/images/branding/googlelogo/2x/googlelogo_color_150x54dp.png) 0}}@media only screen and (-webkit-min-device-pixel-ratio:2){#logo{background:url(//www.google.com/images/branding/googlelogo/2x/googlelogo_color_150x54dp.png) no-repeat;-webkit-background-size:100% 100%}}#logo{display:inline-block;height:54px;width:150px}\n  </style>\n  <a href=//www.google.com/><span id=logo aria-label=Google></span></a>\n  <p><b>404.</b> <ins>That\xe2\x80\x99s an error.</ins>\n  <p>The requested URL <code>/wandb-production.appspot.com/ada4321/DiffHPE/9b8k2jdf/requirements.txt</code> was not found on this server.  <ins>That\xe2\x80\x99s all we know.</ins>\n'
2023-07-10 15:01:17,936 ERROR   wandb-upload_3:33911 [internal_api.py:upload_file():2192] upload_file exception https://storage.googleapis.com/wandb-production.appspot.com/ada4321/DiffHPE/9b8k2jdf/conda-environment.yaml?Expires=1689058877&GoogleAccessId=gorilla-files-url-signer-man%40wandb-production.iam.gserviceaccount.com&Signature=jtr6diHewWP8XcCi65A9x2F5H2sDaaEiTHu%2BNOQb2N8JtQljtRIyiFE0hGXOjgntUYMSYeZgwqPKaG9ryaB08noRyX3vypzj0F67UaXrmAf2Jv8RI52z5BhZqny37c8SUEPc8qUC0w%2BffWRepyisdEWiYEFtyZHrmJOKTQ3vUjpm17BKRZCAsC5KlUBRkl1LEPkw70WNNq7Tfad2oTjFqGGwkV9E%2B30BsT7tiN4Fcw8SR0NBtWZLZgo6tdOJv7PNQsZI54vIL8IHIltlNSSjubeURi40Dq%2FMCcdzqQ%2BsLBMesGNClS6YVhosZkUVLGbzq42NGPN5owf66DJaxxK0DQ%3D%3D: 404 Client Error: Not Found for url: https://storage.googleapis.com/wandb-production.appspot.com/ada4321/DiffHPE/9b8k2jdf/conda-environment.yaml?Expires=1689058877&GoogleAccessId=gorilla-files-url-signer-man%40wandb-production.iam.gserviceaccount.com&Signature=jtr6diHewWP8XcCi65A9x2F5H2sDaaEiTHu%2BNOQb2N8JtQljtRIyiFE0hGXOjgntUYMSYeZgwqPKaG9ryaB08noRyX3vypzj0F67UaXrmAf2Jv8RI52z5BhZqny37c8SUEPc8qUC0w%2BffWRepyisdEWiYEFtyZHrmJOKTQ3vUjpm17BKRZCAsC5KlUBRkl1LEPkw70WNNq7Tfad2oTjFqGGwkV9E%2B30BsT7tiN4Fcw8SR0NBtWZLZgo6tdOJv7PNQsZI54vIL8IHIltlNSSjubeURi40Dq%2FMCcdzqQ%2BsLBMesGNClS6YVhosZkUVLGbzq42NGPN5owf66DJaxxK0DQ%3D%3D
2023-07-10 15:01:17,936 ERROR   wandb-upload_3:33911 [internal_api.py:upload_file():2194] upload_file request headers: {'User-Agent': 'python-requests/2.31.0', 'Accept-Encoding': 'gzip, deflate', 'Accept': '*/*', 'Connection': 'keep-alive', 'Content-Length': '1903'}
2023-07-10 15:01:17,936 ERROR   wandb-upload_3:33911 [internal_api.py:upload_file():2196] upload_file response body: b'<!DOCTYPE html>\n<html lang=en>\n  <meta charset=utf-8>\n  <meta name=viewport content="initial-scale=1, minimum-scale=1, width=device-width">\n  <title>Error 404 (Not Found)!!1</title>\n  <style>\n    *{margin:0;padding:0}html,code{font:15px/22px arial,sans-serif}html{background:#fff;color:#222;padding:15px}body{margin:7% auto 0;max-width:390px;min-height:180px;padding:30px 0 15px}* > body{background:url(//www.google.com/images/errors/robot.png) 100% 5px no-repeat;padding-right:205px}p{margin:11px 0 22px;overflow:hidden}ins{color:#777;text-decoration:none}a img{border:0}@media screen and (max-width:772px){body{background:none;margin-top:0;max-width:none;padding-right:0}}#logo{background:url(//www.google.com/images/branding/googlelogo/1x/googlelogo_color_150x54dp.png) no-repeat;margin-left:-5px}@media only screen and (min-resolution:192dpi){#logo{background:url(//www.google.com/images/branding/googlelogo/2x/googlelogo_color_150x54dp.png) no-repeat 0% 0%/100% 100%;-moz-border-image:url(//www.google.com/images/branding/googlelogo/2x/googlelogo_color_150x54dp.png) 0}}@media only screen and (-webkit-min-device-pixel-ratio:2){#logo{background:url(//www.google.com/images/branding/googlelogo/2x/googlelogo_color_150x54dp.png) no-repeat;-webkit-background-size:100% 100%}}#logo{display:inline-block;height:54px;width:150px}\n  </style>\n  <a href=//www.google.com/><span id=logo aria-label=Google></span></a>\n  <p><b>404.</b> <ins>That\xe2\x80\x99s an error.</ins>\n  <p>The requested URL <code>/wandb-production.appspot.com/ada4321/DiffHPE/9b8k2jdf/conda-environment.yaml</code> was not found on this server.  <ins>That\xe2\x80\x99s all we know.</ins>\n'
2023-07-10 15:01:17,959 ERROR   wandb-upload_0:33911 [internal_api.py:upload_file():2192] upload_file exception https://storage.googleapis.com/wandb-production.appspot.com/ada4321/DiffHPE/9b8k2jdf/wandb-summary.json?Expires=1689058877&GoogleAccessId=gorilla-files-url-signer-man%40wandb-production.iam.gserviceaccount.com&Signature=pex7AskRroFa3gFeNbR2z3Bmesl5BIue7o8uwF8E3juUibxc4Rk6fEWUHYFYLuppLLk%2BBhAEt8a2EVJ4Ihv%2BFbXJDss%2BNpBraoZTJOFHfuJVg0jLinCz3lbj6d5Y3cLdSEA7aLdo4S6OwWu1OPIPIEzEKjf4j5K13InIjs7%2Fcmw8qWLhUzzC%2FEf2DHSSjurvkCesDXxQExEB7BYn%2F317Yz%2FbgZKHXnMHKZGANPD51gmHt73eghZC19snUfhlLFqLvaor7xG7XLCRgevR0uLKbW5C5rrjauo6nOptD5JlessfqjZrFKbjHwNxyN1SuFwqLNv8oreVKS7iSwnZVaynsA%3D%3D: 404 Client Error: Not Found for url: https://storage.googleapis.com/wandb-production.appspot.com/ada4321/DiffHPE/9b8k2jdf/wandb-summary.json?Expires=1689058877&GoogleAccessId=gorilla-files-url-signer-man%40wandb-production.iam.gserviceaccount.com&Signature=pex7AskRroFa3gFeNbR2z3Bmesl5BIue7o8uwF8E3juUibxc4Rk6fEWUHYFYLuppLLk%2BBhAEt8a2EVJ4Ihv%2BFbXJDss%2BNpBraoZTJOFHfuJVg0jLinCz3lbj6d5Y3cLdSEA7aLdo4S6OwWu1OPIPIEzEKjf4j5K13InIjs7%2Fcmw8qWLhUzzC%2FEf2DHSSjurvkCesDXxQExEB7BYn%2F317Yz%2FbgZKHXnMHKZGANPD51gmHt73eghZC19snUfhlLFqLvaor7xG7XLCRgevR0uLKbW5C5rrjauo6nOptD5JlessfqjZrFKbjHwNxyN1SuFwqLNv8oreVKS7iSwnZVaynsA%3D%3D
2023-07-10 15:01:17,959 ERROR   wandb-upload_0:33911 [internal_api.py:upload_file():2194] upload_file request headers: {'User-Agent': 'python-requests/2.31.0', 'Accept-Encoding': 'gzip, deflate', 'Accept': '*/*', 'Connection': 'keep-alive', 'Content-Length': '26'}
2023-07-10 15:01:17,959 ERROR   wandb-upload_0:33911 [internal_api.py:upload_file():2196] upload_file response body: b'<!DOCTYPE html>\n<html lang=en>\n  <meta charset=utf-8>\n  <meta name=viewport content="initial-scale=1, minimum-scale=1, width=device-width">\n  <title>Error 404 (Not Found)!!1</title>\n  <style>\n    *{margin:0;padding:0}html,code{font:15px/22px arial,sans-serif}html{background:#fff;color:#222;padding:15px}body{margin:7% auto 0;max-width:390px;min-height:180px;padding:30px 0 15px}* > body{background:url(//www.google.com/images/errors/robot.png) 100% 5px no-repeat;padding-right:205px}p{margin:11px 0 22px;overflow:hidden}ins{color:#777;text-decoration:none}a img{border:0}@media screen and (max-width:772px){body{background:none;margin-top:0;max-width:none;padding-right:0}}#logo{background:url(//www.google.com/images/branding/googlelogo/1x/googlelogo_color_150x54dp.png) no-repeat;margin-left:-5px}@media only screen and (min-resolution:192dpi){#logo{background:url(//www.google.com/images/branding/googlelogo/2x/googlelogo_color_150x54dp.png) no-repeat 0% 0%/100% 100%;-moz-border-image:url(//www.google.com/images/branding/googlelogo/2x/googlelogo_color_150x54dp.png) 0}}@media only screen and (-webkit-min-device-pixel-ratio:2){#logo{background:url(//www.google.com/images/branding/googlelogo/2x/googlelogo_color_150x54dp.png) no-repeat;-webkit-background-size:100% 100%}}#logo{display:inline-block;height:54px;width:150px}\n  </style>\n  <a href=//www.google.com/><span id=logo aria-label=Google></span></a>\n  <p><b>404.</b> <ins>That\xe2\x80\x99s an error.</ins>\n  <p>The requested URL <code>/wandb-production.appspot.com/ada4321/DiffHPE/9b8k2jdf/wandb-summary.json</code> was not found on this server.  <ins>That\xe2\x80\x99s all we know.</ins>\n'
2023-07-10 15:01:17,976 ERROR   wandb-upload_4:33911 [internal_api.py:upload_file():2192] upload_file exception https://storage.googleapis.com/wandb-production.appspot.com/ada4321/DiffHPE/9b8k2jdf/output.log?Expires=1689058877&GoogleAccessId=gorilla-files-url-signer-man%40wandb-production.iam.gserviceaccount.com&Signature=sSl2Qczbt9%2BKqxxM6ztyUb6kniY0WnpK2PLmLKqqrLvZ1uk8nSuxe5gGV6ByT4v0RMnja8DWEph0d3ri70NlIhFjS0ZiDVynbICQGKYo%2FjL0jsxYU8CzmG4p3Eq4TP8t%2FaDX0YF%2Fve0S8MW9DpzDvc6cdQmUDiqeV527U%2BooQg6N5LmuwH3t14Yz29tbBbMb0R2nvJaj7fWA3h9fXdZXwsUm0NBRoYg2lG84loQwkmdgFE04VR35lIE4dVNmL2gqZFpQpCdbIkEJ4YcqMnwjRjUuVYi%2BQkC0AcbTbTC%2BlRPbckyr1HoLfQcC4zg0GP1vnWdnbM8jltkUCf7r8egl8w%3D%3D: 404 Client Error: Not Found for url: https://storage.googleapis.com/wandb-production.appspot.com/ada4321/DiffHPE/9b8k2jdf/output.log?Expires=1689058877&GoogleAccessId=gorilla-files-url-signer-man%40wandb-production.iam.gserviceaccount.com&Signature=sSl2Qczbt9%2BKqxxM6ztyUb6kniY0WnpK2PLmLKqqrLvZ1uk8nSuxe5gGV6ByT4v0RMnja8DWEph0d3ri70NlIhFjS0ZiDVynbICQGKYo%2FjL0jsxYU8CzmG4p3Eq4TP8t%2FaDX0YF%2Fve0S8MW9DpzDvc6cdQmUDiqeV527U%2BooQg6N5LmuwH3t14Yz29tbBbMb0R2nvJaj7fWA3h9fXdZXwsUm0NBRoYg2lG84loQwkmdgFE04VR35lIE4dVNmL2gqZFpQpCdbIkEJ4YcqMnwjRjUuVYi%2BQkC0AcbTbTC%2BlRPbckyr1HoLfQcC4zg0GP1vnWdnbM8jltkUCf7r8egl8w%3D%3D
2023-07-10 15:01:17,976 ERROR   wandb-upload_4:33911 [internal_api.py:upload_file():2194] upload_file request headers: {'User-Agent': 'python-requests/2.31.0', 'Accept-Encoding': 'gzip, deflate', 'Accept': '*/*', 'Connection': 'keep-alive', 'Content-Length': '2769'}
2023-07-10 15:01:17,976 ERROR   wandb-upload_4:33911 [internal_api.py:upload_file():2196] upload_file response body: b'<!DOCTYPE html>\n<html lang=en>\n  <meta charset=utf-8>\n  <meta name=viewport content="initial-scale=1, minimum-scale=1, width=device-width">\n  <title>Error 404 (Not Found)!!1</title>\n  <style>\n    *{margin:0;padding:0}html,code{font:15px/22px arial,sans-serif}html{background:#fff;color:#222;padding:15px}body{margin:7% auto 0;max-width:390px;min-height:180px;padding:30px 0 15px}* > body{background:url(//www.google.com/images/errors/robot.png) 100% 5px no-repeat;padding-right:205px}p{margin:11px 0 22px;overflow:hidden}ins{color:#777;text-decoration:none}a img{border:0}@media screen and (max-width:772px){body{background:none;margin-top:0;max-width:none;padding-right:0}}#logo{background:url(//www.google.com/images/branding/googlelogo/1x/googlelogo_color_150x54dp.png) no-repeat;margin-left:-5px}@media only screen and (min-resolution:192dpi){#logo{background:url(//www.google.com/images/branding/googlelogo/2x/googlelogo_color_150x54dp.png) no-repeat 0% 0%/100% 100%;-moz-border-image:url(//www.google.com/images/branding/googlelogo/2x/googlelogo_color_150x54dp.png) 0}}@media only screen and (-webkit-min-device-pixel-ratio:2){#logo{background:url(//www.google.com/images/branding/googlelogo/2x/googlelogo_color_150x54dp.png) no-repeat;-webkit-background-size:100% 100%}}#logo{display:inline-block;height:54px;width:150px}\n  </style>\n  <a href=//www.google.com/><span id=logo aria-label=Google></span></a>\n  <p><b>404.</b> <ins>That\xe2\x80\x99s an error.</ins>\n  <p>The requested URL <code>/wandb-production.appspot.com/ada4321/DiffHPE/9b8k2jdf/output.log</code> was not found on this server.  <ins>That\xe2\x80\x99s all we know.</ins>\n'
2023-07-10 15:01:18,138 DEBUG   HandlerThread:33911 [handler.py:handle_request():144] handle_request: keepalive
2023-07-10 15:01:18,660 ERROR   wandb-upload_1:33911 [upload_job.py:push():136] Failed to upload file: /home/zhuhe/HPE-with-Diffusion/wandb/run-20230710_150110-9b8k2jdf/files/config.yaml
Traceback (most recent call last):
  File "/home/zhuhe/.conda/envs/diffhpe/lib/python3.9/site-packages/wandb/apis/normalize.py", line 41, in wrapper
    return func(*args, **kwargs)
  File "/home/zhuhe/.conda/envs/diffhpe/lib/python3.9/site-packages/wandb/sdk/lib/retry.py", line 212, in wrapped_fn
    return retrier(*args, **kargs)
  File "/home/zhuhe/.conda/envs/diffhpe/lib/python3.9/site-packages/wandb/sdk/lib/retry.py", line 131, in __call__
    result = self._call_fn(*args, **kwargs)
  File "/home/zhuhe/.conda/envs/diffhpe/lib/python3.9/site-packages/wandb/sdk/internal/internal_api.py", line 2218, in upload_file
    wandb._sentry.reraise(e)
  File "/home/zhuhe/.conda/envs/diffhpe/lib/python3.9/site-packages/wandb/analytics/sentry.py", line 146, in reraise
    raise exc.with_traceback(sys.exc_info()[2])
  File "/home/zhuhe/.conda/envs/diffhpe/lib/python3.9/site-packages/wandb/sdk/internal/internal_api.py", line 2190, in upload_file
    response.raise_for_status()
  File "/home/zhuhe/.conda/envs/diffhpe/lib/python3.9/site-packages/requests/models.py", line 1021, in raise_for_status
    raise HTTPError(http_error_msg, response=self)
requests.exceptions.HTTPError: 404 Client Error: Not Found for url: https://storage.googleapis.com/wandb-production.appspot.com/ada4321/DiffHPE/9b8k2jdf/config.yaml?Expires=1689058877&GoogleAccessId=gorilla-files-url-signer-man%40wandb-production.iam.gserviceaccount.com&Signature=ZRGus5yWeBiofHv8kISECwHiWYjriTsIHT4iwT7YgBuLIuk6Hi%2F8aqQrGFMzuTfxdsjNx84gVzMJIJTkoSifP5Dqqfo01UaPTa9cq61h%2B3HcYK9iSv2kl1%2BnqdcPsLpPKshkOhclqbjqQrkCvGAg0UYuyeHVxXmNOku2xUWuK86PL3%2FzgJWfVEG2W82Y0D0paB%2FSNUPgEwxff4hULChoQsINKPehRbqX%2B1hDm6yTwW5sOCyeKcn4P%2B3hj31oCs5IKAgei%2B3iwrkdsdVIGHa8KtQ9vP4pZcttyYykyoxX6DLjaJWPp6PdQ%2BCvkjp9VYU2QRnXGAo0Hy0gwjUFt4TErg%3D%3D

During handling of the above exception, another exception occurred:

Traceback (most recent call last):
  File "/home/zhuhe/.conda/envs/diffhpe/lib/python3.9/site-packages/wandb/filesync/upload_job.py", line 127, in push
    self._api.upload_file_retry(
  File "/home/zhuhe/.conda/envs/diffhpe/lib/python3.9/site-packages/wandb/apis/normalize.py", line 51, in wrapper
    raise CommError(message, error)
wandb.errors.CommError: <Response [404]>
2023-07-10 15:01:18,661 ERROR   wandb-upload_2:33911 [upload_job.py:push():136] Failed to upload file: /home/zhuhe/HPE-with-Diffusion/wandb/run-20230710_150110-9b8k2jdf/files/requirements.txt
Traceback (most recent call last):
  File "/home/zhuhe/.conda/envs/diffhpe/lib/python3.9/site-packages/wandb/apis/normalize.py", line 41, in wrapper
    return func(*args, **kwargs)
  File "/home/zhuhe/.conda/envs/diffhpe/lib/python3.9/site-packages/wandb/sdk/lib/retry.py", line 212, in wrapped_fn
    return retrier(*args, **kargs)
  File "/home/zhuhe/.conda/envs/diffhpe/lib/python3.9/site-packages/wandb/sdk/lib/retry.py", line 131, in __call__
    result = self._call_fn(*args, **kwargs)
  File "/home/zhuhe/.conda/envs/diffhpe/lib/python3.9/site-packages/wandb/sdk/internal/internal_api.py", line 2218, in upload_file
    wandb._sentry.reraise(e)
  File "/home/zhuhe/.conda/envs/diffhpe/lib/python3.9/site-packages/wandb/analytics/sentry.py", line 146, in reraise
    raise exc.with_traceback(sys.exc_info()[2])
  File "/home/zhuhe/.conda/envs/diffhpe/lib/python3.9/site-packages/wandb/sdk/internal/internal_api.py", line 2190, in upload_file
    response.raise_for_status()
  File "/home/zhuhe/.conda/envs/diffhpe/lib/python3.9/site-packages/requests/models.py", line 1021, in raise_for_status
    raise HTTPError(http_error_msg, response=self)
requests.exceptions.HTTPError: 404 Client Error: Not Found for url: https://storage.googleapis.com/wandb-production.appspot.com/ada4321/DiffHPE/9b8k2jdf/requirements.txt?Expires=1689058877&GoogleAccessId=gorilla-files-url-signer-man%40wandb-production.iam.gserviceaccount.com&Signature=RQj1%2FwRpqETEWTqhx0u2%2Bp%2FHT3HWKWrcS5%2BrTBug76ClRaHPp%2F1mt6kE0kK4p2LXAIccUX8O%2BOogTwiUFRXZElemaPe%2BWGgyevyEAK68uQXea0bxxlaeiv9CIumXd%2BsrDnICUxi93jrc1k0im7c4XbZyj%2BCw2jjeKn3KEr6vKjoW4cJN7r2VMdIHuvu40qV0%2FkY0PHsI76ukjrPXj0BWjn76ZrqQhcTHi2XVBABdNoHaVqPOdIh%2Bk4vimJPhPBuVjQHoRVZsQp7YU%2F%2BqUX4QGsEK0PBuXwiLCgXs6ASpX5UDN2bCI6%2FjL%2B3EoBqggUyqcEsYjq%2BxkHNHkbeyDBrVNA%3D%3D

During handling of the above exception, another exception occurred:

Traceback (most recent call last):
  File "/home/zhuhe/.conda/envs/diffhpe/lib/python3.9/site-packages/wandb/filesync/upload_job.py", line 127, in push
    self._api.upload_file_retry(
  File "/home/zhuhe/.conda/envs/diffhpe/lib/python3.9/site-packages/wandb/apis/normalize.py", line 51, in wrapper
    raise CommError(message, error)
wandb.errors.CommError: <Response [404]>
2023-07-10 15:01:18,661 ERROR   wandb-upload_3:33911 [upload_job.py:push():136] Failed to upload file: /home/zhuhe/HPE-with-Diffusion/wandb/run-20230710_150110-9b8k2jdf/files/conda-environment.yaml
Traceback (most recent call last):
  File "/home/zhuhe/.conda/envs/diffhpe/lib/python3.9/site-packages/wandb/apis/normalize.py", line 41, in wrapper
    return func(*args, **kwargs)
  File "/home/zhuhe/.conda/envs/diffhpe/lib/python3.9/site-packages/wandb/sdk/lib/retry.py", line 212, in wrapped_fn
    return retrier(*args, **kargs)
  File "/home/zhuhe/.conda/envs/diffhpe/lib/python3.9/site-packages/wandb/sdk/lib/retry.py", line 131, in __call__
    result = self._call_fn(*args, **kwargs)
  File "/home/zhuhe/.conda/envs/diffhpe/lib/python3.9/site-packages/wandb/sdk/internal/internal_api.py", line 2218, in upload_file
    wandb._sentry.reraise(e)
  File "/home/zhuhe/.conda/envs/diffhpe/lib/python3.9/site-packages/wandb/analytics/sentry.py", line 146, in reraise
    raise exc.with_traceback(sys.exc_info()[2])
  File "/home/zhuhe/.conda/envs/diffhpe/lib/python3.9/site-packages/wandb/sdk/internal/internal_api.py", line 2190, in upload_file
    response.raise_for_status()
  File "/home/zhuhe/.conda/envs/diffhpe/lib/python3.9/site-packages/requests/models.py", line 1021, in raise_for_status
    raise HTTPError(http_error_msg, response=self)
requests.exceptions.HTTPError: 404 Client Error: Not Found for url: https://storage.googleapis.com/wandb-production.appspot.com/ada4321/DiffHPE/9b8k2jdf/conda-environment.yaml?Expires=1689058877&GoogleAccessId=gorilla-files-url-signer-man%40wandb-production.iam.gserviceaccount.com&Signature=jtr6diHewWP8XcCi65A9x2F5H2sDaaEiTHu%2BNOQb2N8JtQljtRIyiFE0hGXOjgntUYMSYeZgwqPKaG9ryaB08noRyX3vypzj0F67UaXrmAf2Jv8RI52z5BhZqny37c8SUEPc8qUC0w%2BffWRepyisdEWiYEFtyZHrmJOKTQ3vUjpm17BKRZCAsC5KlUBRkl1LEPkw70WNNq7Tfad2oTjFqGGwkV9E%2B30BsT7tiN4Fcw8SR0NBtWZLZgo6tdOJv7PNQsZI54vIL8IHIltlNSSjubeURi40Dq%2FMCcdzqQ%2BsLBMesGNClS6YVhosZkUVLGbzq42NGPN5owf66DJaxxK0DQ%3D%3D

During handling of the above exception, another exception occurred:

Traceback (most recent call last):
  File "/home/zhuhe/.conda/envs/diffhpe/lib/python3.9/site-packages/wandb/filesync/upload_job.py", line 127, in push
    self._api.upload_file_retry(
  File "/home/zhuhe/.conda/envs/diffhpe/lib/python3.9/site-packages/wandb/apis/normalize.py", line 51, in wrapper
    raise CommError(message, error)
wandb.errors.CommError: <Response [404]>
2023-07-10 15:01:18,661 ERROR   wandb-upload_0:33911 [upload_job.py:push():136] Failed to upload file: /home/zhuhe/HPE-with-Diffusion/wandb/run-20230710_150110-9b8k2jdf/files/wandb-summary.json
Traceback (most recent call last):
  File "/home/zhuhe/.conda/envs/diffhpe/lib/python3.9/site-packages/wandb/apis/normalize.py", line 41, in wrapper
    return func(*args, **kwargs)
  File "/home/zhuhe/.conda/envs/diffhpe/lib/python3.9/site-packages/wandb/sdk/lib/retry.py", line 212, in wrapped_fn
    return retrier(*args, **kargs)
  File "/home/zhuhe/.conda/envs/diffhpe/lib/python3.9/site-packages/wandb/sdk/lib/retry.py", line 131, in __call__
    result = self._call_fn(*args, **kwargs)
  File "/home/zhuhe/.conda/envs/diffhpe/lib/python3.9/site-packages/wandb/sdk/internal/internal_api.py", line 2218, in upload_file
    wandb._sentry.reraise(e)
  File "/home/zhuhe/.conda/envs/diffhpe/lib/python3.9/site-packages/wandb/analytics/sentry.py", line 146, in reraise
    raise exc.with_traceback(sys.exc_info()[2])
  File "/home/zhuhe/.conda/envs/diffhpe/lib/python3.9/site-packages/wandb/sdk/internal/internal_api.py", line 2190, in upload_file
    response.raise_for_status()
  File "/home/zhuhe/.conda/envs/diffhpe/lib/python3.9/site-packages/requests/models.py", line 1021, in raise_for_status
    raise HTTPError(http_error_msg, response=self)
requests.exceptions.HTTPError: 404 Client Error: Not Found for url: https://storage.googleapis.com/wandb-production.appspot.com/ada4321/DiffHPE/9b8k2jdf/wandb-summary.json?Expires=1689058877&GoogleAccessId=gorilla-files-url-signer-man%40wandb-production.iam.gserviceaccount.com&Signature=pex7AskRroFa3gFeNbR2z3Bmesl5BIue7o8uwF8E3juUibxc4Rk6fEWUHYFYLuppLLk%2BBhAEt8a2EVJ4Ihv%2BFbXJDss%2BNpBraoZTJOFHfuJVg0jLinCz3lbj6d5Y3cLdSEA7aLdo4S6OwWu1OPIPIEzEKjf4j5K13InIjs7%2Fcmw8qWLhUzzC%2FEf2DHSSjurvkCesDXxQExEB7BYn%2F317Yz%2FbgZKHXnMHKZGANPD51gmHt73eghZC19snUfhlLFqLvaor7xG7XLCRgevR0uLKbW5C5rrjauo6nOptD5JlessfqjZrFKbjHwNxyN1SuFwqLNv8oreVKS7iSwnZVaynsA%3D%3D

During handling of the above exception, another exception occurred:

Traceback (most recent call last):
  File "/home/zhuhe/.conda/envs/diffhpe/lib/python3.9/site-packages/wandb/filesync/upload_job.py", line 127, in push
    self._api.upload_file_retry(
  File "/home/zhuhe/.conda/envs/diffhpe/lib/python3.9/site-packages/wandb/apis/normalize.py", line 51, in wrapper
    raise CommError(message, error)
wandb.errors.CommError: <Response [404]>
2023-07-10 15:01:18,662 ERROR   wandb-upload_4:33911 [upload_job.py:push():136] Failed to upload file: /home/zhuhe/HPE-with-Diffusion/wandb/run-20230710_150110-9b8k2jdf/files/output.log
Traceback (most recent call last):
  File "/home/zhuhe/.conda/envs/diffhpe/lib/python3.9/site-packages/wandb/apis/normalize.py", line 41, in wrapper
    return func(*args, **kwargs)
  File "/home/zhuhe/.conda/envs/diffhpe/lib/python3.9/site-packages/wandb/sdk/lib/retry.py", line 212, in wrapped_fn
    return retrier(*args, **kargs)
  File "/home/zhuhe/.conda/envs/diffhpe/lib/python3.9/site-packages/wandb/sdk/lib/retry.py", line 131, in __call__
    result = self._call_fn(*args, **kwargs)
  File "/home/zhuhe/.conda/envs/diffhpe/lib/python3.9/site-packages/wandb/sdk/internal/internal_api.py", line 2218, in upload_file
    wandb._sentry.reraise(e)
  File "/home/zhuhe/.conda/envs/diffhpe/lib/python3.9/site-packages/wandb/analytics/sentry.py", line 146, in reraise
    raise exc.with_traceback(sys.exc_info()[2])
  File "/home/zhuhe/.conda/envs/diffhpe/lib/python3.9/site-packages/wandb/sdk/internal/internal_api.py", line 2190, in upload_file
    response.raise_for_status()
  File "/home/zhuhe/.conda/envs/diffhpe/lib/python3.9/site-packages/requests/models.py", line 1021, in raise_for_status
    raise HTTPError(http_error_msg, response=self)
requests.exceptions.HTTPError: 404 Client Error: Not Found for url: https://storage.googleapis.com/wandb-production.appspot.com/ada4321/DiffHPE/9b8k2jdf/output.log?Expires=1689058877&GoogleAccessId=gorilla-files-url-signer-man%40wandb-production.iam.gserviceaccount.com&Signature=sSl2Qczbt9%2BKqxxM6ztyUb6kniY0WnpK2PLmLKqqrLvZ1uk8nSuxe5gGV6ByT4v0RMnja8DWEph0d3ri70NlIhFjS0ZiDVynbICQGKYo%2FjL0jsxYU8CzmG4p3Eq4TP8t%2FaDX0YF%2Fve0S8MW9DpzDvc6cdQmUDiqeV527U%2BooQg6N5LmuwH3t14Yz29tbBbMb0R2nvJaj7fWA3h9fXdZXwsUm0NBRoYg2lG84loQwkmdgFE04VR35lIE4dVNmL2gqZFpQpCdbIkEJ4YcqMnwjRjUuVYi%2BQkC0AcbTbTC%2BlRPbckyr1HoLfQcC4zg0GP1vnWdnbM8jltkUCf7r8egl8w%3D%3D

During handling of the above exception, another exception occurred:

Traceback (most recent call last):
  File "/home/zhuhe/.conda/envs/diffhpe/lib/python3.9/site-packages/wandb/filesync/upload_job.py", line 127, in push
    self._api.upload_file_retry(
  File "/home/zhuhe/.conda/envs/diffhpe/lib/python3.9/site-packages/wandb/apis/normalize.py", line 51, in wrapper
    raise CommError(message, error)
wandb.errors.CommError: <Response [404]>
2023-07-10 15:01:19,685 ERROR   Thread-11 :33911 [step_upload.py:_handle_event():200] Failed to upload file: /home/zhuhe/HPE-with-Diffusion/wandb/run-20230710_150110-9b8k2jdf/files/conda-environment.yaml
Traceback (most recent call last):
  File "/home/zhuhe/.conda/envs/diffhpe/lib/python3.9/site-packages/wandb/apis/normalize.py", line 41, in wrapper
    return func(*args, **kwargs)
  File "/home/zhuhe/.conda/envs/diffhpe/lib/python3.9/site-packages/wandb/sdk/lib/retry.py", line 212, in wrapped_fn
    return retrier(*args, **kargs)
  File "/home/zhuhe/.conda/envs/diffhpe/lib/python3.9/site-packages/wandb/sdk/lib/retry.py", line 131, in __call__
    result = self._call_fn(*args, **kwargs)
  File "/home/zhuhe/.conda/envs/diffhpe/lib/python3.9/site-packages/wandb/sdk/internal/internal_api.py", line 2218, in upload_file
    wandb._sentry.reraise(e)
  File "/home/zhuhe/.conda/envs/diffhpe/lib/python3.9/site-packages/wandb/analytics/sentry.py", line 146, in reraise
    raise exc.with_traceback(sys.exc_info()[2])
  File "/home/zhuhe/.conda/envs/diffhpe/lib/python3.9/site-packages/wandb/sdk/internal/internal_api.py", line 2190, in upload_file
    response.raise_for_status()
  File "/home/zhuhe/.conda/envs/diffhpe/lib/python3.9/site-packages/requests/models.py", line 1021, in raise_for_status
    raise HTTPError(http_error_msg, response=self)
requests.exceptions.HTTPError: 404 Client Error: Not Found for url: https://storage.googleapis.com/wandb-production.appspot.com/ada4321/DiffHPE/9b8k2jdf/conda-environment.yaml?Expires=1689058877&GoogleAccessId=gorilla-files-url-signer-man%40wandb-production.iam.gserviceaccount.com&Signature=jtr6diHewWP8XcCi65A9x2F5H2sDaaEiTHu%2BNOQb2N8JtQljtRIyiFE0hGXOjgntUYMSYeZgwqPKaG9ryaB08noRyX3vypzj0F67UaXrmAf2Jv8RI52z5BhZqny37c8SUEPc8qUC0w%2BffWRepyisdEWiYEFtyZHrmJOKTQ3vUjpm17BKRZCAsC5KlUBRkl1LEPkw70WNNq7Tfad2oTjFqGGwkV9E%2B30BsT7tiN4Fcw8SR0NBtWZLZgo6tdOJv7PNQsZI54vIL8IHIltlNSSjubeURi40Dq%2FMCcdzqQ%2BsLBMesGNClS6YVhosZkUVLGbzq42NGPN5owf66DJaxxK0DQ%3D%3D

During handling of the above exception, another exception occurred:

Traceback (most recent call last):
  File "/home/zhuhe/.conda/envs/diffhpe/lib/python3.9/concurrent/futures/thread.py", line 58, in run
    result = self.fn(*self.args, **self.kwargs)
  File "/home/zhuhe/.conda/envs/diffhpe/lib/python3.9/site-packages/wandb/filesync/step_upload.py", line 288, in run_and_notify
    self._do_upload_sync(event)
  File "/home/zhuhe/.conda/envs/diffhpe/lib/python3.9/site-packages/wandb/filesync/step_upload.py", line 330, in _do_upload_sync
    job.run()
  File "/home/zhuhe/.conda/envs/diffhpe/lib/python3.9/site-packages/wandb/filesync/upload_job.py", line 57, in run
    self.push()
  File "/home/zhuhe/.conda/envs/diffhpe/lib/python3.9/site-packages/wandb/filesync/upload_job.py", line 127, in push
    self._api.upload_file_retry(
  File "/home/zhuhe/.conda/envs/diffhpe/lib/python3.9/site-packages/wandb/apis/normalize.py", line 51, in wrapper
    raise CommError(message, error)
wandb.errors.CommError: <Response [404]>
2023-07-10 15:01:19,685 ERROR   Thread-11 :33911 [step_upload.py:_handle_event():200] Failed to upload file: /home/zhuhe/HPE-with-Diffusion/wandb/run-20230710_150110-9b8k2jdf/files/config.yaml
Traceback (most recent call last):
  File "/home/zhuhe/.conda/envs/diffhpe/lib/python3.9/site-packages/wandb/apis/normalize.py", line 41, in wrapper
    return func(*args, **kwargs)
  File "/home/zhuhe/.conda/envs/diffhpe/lib/python3.9/site-packages/wandb/sdk/lib/retry.py", line 212, in wrapped_fn
    return retrier(*args, **kargs)
  File "/home/zhuhe/.conda/envs/diffhpe/lib/python3.9/site-packages/wandb/sdk/lib/retry.py", line 131, in __call__
    result = self._call_fn(*args, **kwargs)
  File "/home/zhuhe/.conda/envs/diffhpe/lib/python3.9/site-packages/wandb/sdk/internal/internal_api.py", line 2218, in upload_file
    wandb._sentry.reraise(e)
  File "/home/zhuhe/.conda/envs/diffhpe/lib/python3.9/site-packages/wandb/analytics/sentry.py", line 146, in reraise
    raise exc.with_traceback(sys.exc_info()[2])
  File "/home/zhuhe/.conda/envs/diffhpe/lib/python3.9/site-packages/wandb/sdk/internal/internal_api.py", line 2190, in upload_file
    response.raise_for_status()
  File "/home/zhuhe/.conda/envs/diffhpe/lib/python3.9/site-packages/requests/models.py", line 1021, in raise_for_status
    raise HTTPError(http_error_msg, response=self)
requests.exceptions.HTTPError: 404 Client Error: Not Found for url: https://storage.googleapis.com/wandb-production.appspot.com/ada4321/DiffHPE/9b8k2jdf/config.yaml?Expires=1689058877&GoogleAccessId=gorilla-files-url-signer-man%40wandb-production.iam.gserviceaccount.com&Signature=ZRGus5yWeBiofHv8kISECwHiWYjriTsIHT4iwT7YgBuLIuk6Hi%2F8aqQrGFMzuTfxdsjNx84gVzMJIJTkoSifP5Dqqfo01UaPTa9cq61h%2B3HcYK9iSv2kl1%2BnqdcPsLpPKshkOhclqbjqQrkCvGAg0UYuyeHVxXmNOku2xUWuK86PL3%2FzgJWfVEG2W82Y0D0paB%2FSNUPgEwxff4hULChoQsINKPehRbqX%2B1hDm6yTwW5sOCyeKcn4P%2B3hj31oCs5IKAgei%2B3iwrkdsdVIGHa8KtQ9vP4pZcttyYykyoxX6DLjaJWPp6PdQ%2BCvkjp9VYU2QRnXGAo0Hy0gwjUFt4TErg%3D%3D

During handling of the above exception, another exception occurred:

Traceback (most recent call last):
  File "/home/zhuhe/.conda/envs/diffhpe/lib/python3.9/concurrent/futures/thread.py", line 58, in run
    result = self.fn(*self.args, **self.kwargs)
  File "/home/zhuhe/.conda/envs/diffhpe/lib/python3.9/site-packages/wandb/filesync/step_upload.py", line 288, in run_and_notify
    self._do_upload_sync(event)
  File "/home/zhuhe/.conda/envs/diffhpe/lib/python3.9/site-packages/wandb/filesync/step_upload.py", line 330, in _do_upload_sync
    job.run()
  File "/home/zhuhe/.conda/envs/diffhpe/lib/python3.9/site-packages/wandb/filesync/upload_job.py", line 57, in run
    self.push()
  File "/home/zhuhe/.conda/envs/diffhpe/lib/python3.9/site-packages/wandb/filesync/upload_job.py", line 127, in push
    self._api.upload_file_retry(
  File "/home/zhuhe/.conda/envs/diffhpe/lib/python3.9/site-packages/wandb/apis/normalize.py", line 51, in wrapper
    raise CommError(message, error)
wandb.errors.CommError: <Response [404]>
2023-07-10 15:01:19,686 ERROR   Thread-11 :33911 [step_upload.py:_handle_event():200] Failed to upload file: /home/zhuhe/HPE-with-Diffusion/wandb/run-20230710_150110-9b8k2jdf/files/requirements.txt
Traceback (most recent call last):
  File "/home/zhuhe/.conda/envs/diffhpe/lib/python3.9/site-packages/wandb/apis/normalize.py", line 41, in wrapper
    return func(*args, **kwargs)
  File "/home/zhuhe/.conda/envs/diffhpe/lib/python3.9/site-packages/wandb/sdk/lib/retry.py", line 212, in wrapped_fn
    return retrier(*args, **kargs)
  File "/home/zhuhe/.conda/envs/diffhpe/lib/python3.9/site-packages/wandb/sdk/lib/retry.py", line 131, in __call__
    result = self._call_fn(*args, **kwargs)
  File "/home/zhuhe/.conda/envs/diffhpe/lib/python3.9/site-packages/wandb/sdk/internal/internal_api.py", line 2218, in upload_file
    wandb._sentry.reraise(e)
  File "/home/zhuhe/.conda/envs/diffhpe/lib/python3.9/site-packages/wandb/analytics/sentry.py", line 146, in reraise
    raise exc.with_traceback(sys.exc_info()[2])
  File "/home/zhuhe/.conda/envs/diffhpe/lib/python3.9/site-packages/wandb/sdk/internal/internal_api.py", line 2190, in upload_file
    response.raise_for_status()
  File "/home/zhuhe/.conda/envs/diffhpe/lib/python3.9/site-packages/requests/models.py", line 1021, in raise_for_status
    raise HTTPError(http_error_msg, response=self)
requests.exceptions.HTTPError: 404 Client Error: Not Found for url: https://storage.googleapis.com/wandb-production.appspot.com/ada4321/DiffHPE/9b8k2jdf/requirements.txt?Expires=1689058877&GoogleAccessId=gorilla-files-url-signer-man%40wandb-production.iam.gserviceaccount.com&Signature=RQj1%2FwRpqETEWTqhx0u2%2Bp%2FHT3HWKWrcS5%2BrTBug76ClRaHPp%2F1mt6kE0kK4p2LXAIccUX8O%2BOogTwiUFRXZElemaPe%2BWGgyevyEAK68uQXea0bxxlaeiv9CIumXd%2BsrDnICUxi93jrc1k0im7c4XbZyj%2BCw2jjeKn3KEr6vKjoW4cJN7r2VMdIHuvu40qV0%2FkY0PHsI76ukjrPXj0BWjn76ZrqQhcTHi2XVBABdNoHaVqPOdIh%2Bk4vimJPhPBuVjQHoRVZsQp7YU%2F%2BqUX4QGsEK0PBuXwiLCgXs6ASpX5UDN2bCI6%2FjL%2B3EoBqggUyqcEsYjq%2BxkHNHkbeyDBrVNA%3D%3D

During handling of the above exception, another exception occurred:

Traceback (most recent call last):
  File "/home/zhuhe/.conda/envs/diffhpe/lib/python3.9/concurrent/futures/thread.py", line 58, in run
    result = self.fn(*self.args, **self.kwargs)
  File "/home/zhuhe/.conda/envs/diffhpe/lib/python3.9/site-packages/wandb/filesync/step_upload.py", line 288, in run_and_notify
    self._do_upload_sync(event)
  File "/home/zhuhe/.conda/envs/diffhpe/lib/python3.9/site-packages/wandb/filesync/step_upload.py", line 330, in _do_upload_sync
    job.run()
  File "/home/zhuhe/.conda/envs/diffhpe/lib/python3.9/site-packages/wandb/filesync/upload_job.py", line 57, in run
    self.push()
  File "/home/zhuhe/.conda/envs/diffhpe/lib/python3.9/site-packages/wandb/filesync/upload_job.py", line 127, in push
    self._api.upload_file_retry(
  File "/home/zhuhe/.conda/envs/diffhpe/lib/python3.9/site-packages/wandb/apis/normalize.py", line 51, in wrapper
    raise CommError(message, error)
wandb.errors.CommError: <Response [404]>
2023-07-10 15:01:19,686 ERROR   Thread-11 :33911 [step_upload.py:_handle_event():200] Failed to upload file: /home/zhuhe/HPE-with-Diffusion/wandb/run-20230710_150110-9b8k2jdf/files/wandb-summary.json
Traceback (most recent call last):
  File "/home/zhuhe/.conda/envs/diffhpe/lib/python3.9/site-packages/wandb/apis/normalize.py", line 41, in wrapper
    return func(*args, **kwargs)
  File "/home/zhuhe/.conda/envs/diffhpe/lib/python3.9/site-packages/wandb/sdk/lib/retry.py", line 212, in wrapped_fn
    return retrier(*args, **kargs)
  File "/home/zhuhe/.conda/envs/diffhpe/lib/python3.9/site-packages/wandb/sdk/lib/retry.py", line 131, in __call__
    result = self._call_fn(*args, **kwargs)
  File "/home/zhuhe/.conda/envs/diffhpe/lib/python3.9/site-packages/wandb/sdk/internal/internal_api.py", line 2218, in upload_file
    wandb._sentry.reraise(e)
  File "/home/zhuhe/.conda/envs/diffhpe/lib/python3.9/site-packages/wandb/analytics/sentry.py", line 146, in reraise
    raise exc.with_traceback(sys.exc_info()[2])
  File "/home/zhuhe/.conda/envs/diffhpe/lib/python3.9/site-packages/wandb/sdk/internal/internal_api.py", line 2190, in upload_file
    response.raise_for_status()
  File "/home/zhuhe/.conda/envs/diffhpe/lib/python3.9/site-packages/requests/models.py", line 1021, in raise_for_status
    raise HTTPError(http_error_msg, response=self)
requests.exceptions.HTTPError: 404 Client Error: Not Found for url: https://storage.googleapis.com/wandb-production.appspot.com/ada4321/DiffHPE/9b8k2jdf/wandb-summary.json?Expires=1689058877&GoogleAccessId=gorilla-files-url-signer-man%40wandb-production.iam.gserviceaccount.com&Signature=pex7AskRroFa3gFeNbR2z3Bmesl5BIue7o8uwF8E3juUibxc4Rk6fEWUHYFYLuppLLk%2BBhAEt8a2EVJ4Ihv%2BFbXJDss%2BNpBraoZTJOFHfuJVg0jLinCz3lbj6d5Y3cLdSEA7aLdo4S6OwWu1OPIPIEzEKjf4j5K13InIjs7%2Fcmw8qWLhUzzC%2FEf2DHSSjurvkCesDXxQExEB7BYn%2F317Yz%2FbgZKHXnMHKZGANPD51gmHt73eghZC19snUfhlLFqLvaor7xG7XLCRgevR0uLKbW5C5rrjauo6nOptD5JlessfqjZrFKbjHwNxyN1SuFwqLNv8oreVKS7iSwnZVaynsA%3D%3D

During handling of the above exception, another exception occurred:

Traceback (most recent call last):
  File "/home/zhuhe/.conda/envs/diffhpe/lib/python3.9/concurrent/futures/thread.py", line 58, in run
    result = self.fn(*self.args, **self.kwargs)
  File "/home/zhuhe/.conda/envs/diffhpe/lib/python3.9/site-packages/wandb/filesync/step_upload.py", line 288, in run_and_notify
    self._do_upload_sync(event)
  File "/home/zhuhe/.conda/envs/diffhpe/lib/python3.9/site-packages/wandb/filesync/step_upload.py", line 330, in _do_upload_sync
    job.run()
  File "/home/zhuhe/.conda/envs/diffhpe/lib/python3.9/site-packages/wandb/filesync/upload_job.py", line 57, in run
    self.push()
  File "/home/zhuhe/.conda/envs/diffhpe/lib/python3.9/site-packages/wandb/filesync/upload_job.py", line 127, in push
    self._api.upload_file_retry(
  File "/home/zhuhe/.conda/envs/diffhpe/lib/python3.9/site-packages/wandb/apis/normalize.py", line 51, in wrapper
    raise CommError(message, error)
wandb.errors.CommError: <Response [404]>
2023-07-10 15:01:19,686 ERROR   Thread-11 :33911 [step_upload.py:_handle_event():200] Failed to upload file: /home/zhuhe/HPE-with-Diffusion/wandb/run-20230710_150110-9b8k2jdf/files/output.log
Traceback (most recent call last):
  File "/home/zhuhe/.conda/envs/diffhpe/lib/python3.9/site-packages/wandb/apis/normalize.py", line 41, in wrapper
    return func(*args, **kwargs)
  File "/home/zhuhe/.conda/envs/diffhpe/lib/python3.9/site-packages/wandb/sdk/lib/retry.py", line 212, in wrapped_fn
    return retrier(*args, **kargs)
  File "/home/zhuhe/.conda/envs/diffhpe/lib/python3.9/site-packages/wandb/sdk/lib/retry.py", line 131, in __call__
    result = self._call_fn(*args, **kwargs)
  File "/home/zhuhe/.conda/envs/diffhpe/lib/python3.9/site-packages/wandb/sdk/internal/internal_api.py", line 2218, in upload_file
    wandb._sentry.reraise(e)
  File "/home/zhuhe/.conda/envs/diffhpe/lib/python3.9/site-packages/wandb/analytics/sentry.py", line 146, in reraise
    raise exc.with_traceback(sys.exc_info()[2])
  File "/home/zhuhe/.conda/envs/diffhpe/lib/python3.9/site-packages/wandb/sdk/internal/internal_api.py", line 2190, in upload_file
    response.raise_for_status()
  File "/home/zhuhe/.conda/envs/diffhpe/lib/python3.9/site-packages/requests/models.py", line 1021, in raise_for_status
    raise HTTPError(http_error_msg, response=self)
requests.exceptions.HTTPError: 404 Client Error: Not Found for url: https://storage.googleapis.com/wandb-production.appspot.com/ada4321/DiffHPE/9b8k2jdf/output.log?Expires=1689058877&GoogleAccessId=gorilla-files-url-signer-man%40wandb-production.iam.gserviceaccount.com&Signature=sSl2Qczbt9%2BKqxxM6ztyUb6kniY0WnpK2PLmLKqqrLvZ1uk8nSuxe5gGV6ByT4v0RMnja8DWEph0d3ri70NlIhFjS0ZiDVynbICQGKYo%2FjL0jsxYU8CzmG4p3Eq4TP8t%2FaDX0YF%2Fve0S8MW9DpzDvc6cdQmUDiqeV527U%2BooQg6N5LmuwH3t14Yz29tbBbMb0R2nvJaj7fWA3h9fXdZXwsUm0NBRoYg2lG84loQwkmdgFE04VR35lIE4dVNmL2gqZFpQpCdbIkEJ4YcqMnwjRjUuVYi%2BQkC0AcbTbTC%2BlRPbckyr1HoLfQcC4zg0GP1vnWdnbM8jltkUCf7r8egl8w%3D%3D

During handling of the above exception, another exception occurred:

Traceback (most recent call last):
  File "/home/zhuhe/.conda/envs/diffhpe/lib/python3.9/concurrent/futures/thread.py", line 58, in run
    result = self.fn(*self.args, **self.kwargs)
  File "/home/zhuhe/.conda/envs/diffhpe/lib/python3.9/site-packages/wandb/filesync/step_upload.py", line 288, in run_and_notify
    self._do_upload_sync(event)
  File "/home/zhuhe/.conda/envs/diffhpe/lib/python3.9/site-packages/wandb/filesync/step_upload.py", line 330, in _do_upload_sync
    job.run()
  File "/home/zhuhe/.conda/envs/diffhpe/lib/python3.9/site-packages/wandb/filesync/upload_job.py", line 57, in run
    self.push()
  File "/home/zhuhe/.conda/envs/diffhpe/lib/python3.9/site-packages/wandb/filesync/upload_job.py", line 127, in push
    self._api.upload_file_retry(
  File "/home/zhuhe/.conda/envs/diffhpe/lib/python3.9/site-packages/wandb/apis/normalize.py", line 51, in wrapper
    raise CommError(message, error)
wandb.errors.CommError: <Response [404]>
2023-07-10 15:01:19,886 INFO    Thread-11 :33911 [sender.py:transition_state():602] send defer: 11
2023-07-10 15:01:19,886 DEBUG   HandlerThread:33911 [handler.py:handle_request():144] handle_request: defer
2023-07-10 15:01:19,886 INFO    HandlerThread:33911 [handler.py:handle_request_defer():170] handle defer: 11
2023-07-10 15:01:19,886 DEBUG   SenderThread:33911 [sender.py:send_request():396] send_request: defer
2023-07-10 15:01:19,887 INFO    SenderThread:33911 [sender.py:send_request_defer():598] handle sender defer: 11
2023-07-10 15:01:19,887 INFO    SenderThread:33911 [file_pusher.py:join():164] waiting for file pusher
2023-07-10 15:01:19,887 INFO    SenderThread:33911 [sender.py:transition_state():602] send defer: 12
2023-07-10 15:01:19,887 DEBUG   HandlerThread:33911 [handler.py:handle_request():144] handle_request: defer
2023-07-10 15:01:19,887 INFO    HandlerThread:33911 [handler.py:handle_request_defer():170] handle defer: 12
2023-07-10 15:01:19,887 DEBUG   SenderThread:33911 [sender.py:send_request():396] send_request: defer
2023-07-10 15:01:19,887 INFO    SenderThread:33911 [sender.py:send_request_defer():598] handle sender defer: 12
2023-07-10 15:01:20,167 INFO    SenderThread:33911 [sender.py:transition_state():602] send defer: 13
2023-07-10 15:01:20,167 DEBUG   HandlerThread:33911 [handler.py:handle_request():144] handle_request: defer
2023-07-10 15:01:20,167 INFO    HandlerThread:33911 [handler.py:handle_request_defer():170] handle defer: 13
2023-07-10 15:01:20,167 DEBUG   SenderThread:33911 [sender.py:send_request():396] send_request: defer
2023-07-10 15:01:20,167 INFO    SenderThread:33911 [sender.py:send_request_defer():598] handle sender defer: 13
2023-07-10 15:01:20,167 INFO    SenderThread:33911 [sender.py:transition_state():602] send defer: 14
2023-07-10 15:01:20,167 DEBUG   HandlerThread:33911 [handler.py:handle_request():144] handle_request: defer
2023-07-10 15:01:20,167 INFO    HandlerThread:33911 [handler.py:handle_request_defer():170] handle defer: 14
2023-07-10 15:01:20,167 DEBUG   SenderThread:33911 [sender.py:send():369] send: final
2023-07-10 15:01:20,168 DEBUG   SenderThread:33911 [sender.py:send():369] send: footer
2023-07-10 15:01:20,168 DEBUG   SenderThread:33911 [sender.py:send_request():396] send_request: defer
2023-07-10 15:01:20,168 INFO    SenderThread:33911 [sender.py:send_request_defer():598] handle sender defer: 14
2023-07-10 15:01:20,168 DEBUG   HandlerThread:33911 [handler.py:handle_request():144] handle_request: poll_exit
2023-07-10 15:01:20,168 DEBUG   HandlerThread:33911 [handler.py:handle_request():144] handle_request: server_info
2023-07-10 15:01:20,168 DEBUG   SenderThread:33911 [sender.py:send_request():396] send_request: poll_exit
2023-07-10 15:01:20,168 DEBUG   SenderThread:33911 [sender.py:send_request():396] send_request: server_info
2023-07-10 15:01:20,169 DEBUG   HandlerThread:33911 [handler.py:handle_request():144] handle_request: get_summary
2023-07-10 15:01:20,169 DEBUG   HandlerThread:33911 [handler.py:handle_request():144] handle_request: sampled_history
2023-07-10 15:01:20,620 INFO    MainThread:33911 [wandb_run.py:_footer_history_summary_info():3467] rendering history
2023-07-10 15:01:20,620 INFO    MainThread:33911 [wandb_run.py:_footer_history_summary_info():3499] rendering summary
2023-07-10 15:01:20,620 INFO    MainThread:33911 [wandb_run.py:_footer_sync_info():3426] logging synced files
2023-07-10 15:01:20,620 DEBUG   HandlerThread:33911 [handler.py:handle_request():144] handle_request: shutdown
2023-07-10 15:01:20,621 INFO    HandlerThread:33911 [handler.py:finish():854] shutting down handler
2023-07-10 15:01:21,168 INFO    WriterThread:33911 [datastore.py:close():298] close: /home/zhuhe/HPE-with-Diffusion/wandb/run-20230710_150110-9b8k2jdf/run-9b8k2jdf.wandb
2023-07-10 15:01:21,620 INFO    SenderThread:33911 [sender.py:finish():1526] shutting down sender
2023-07-10 15:01:21,620 INFO    SenderThread:33911 [file_pusher.py:finish():159] shutting down file pusher
2023-07-10 15:01:21,620 INFO    SenderThread:33911 [file_pusher.py:join():164] waiting for file pusher
