2023-07-11 12:11:13,393 INFO    StreamThr :106728 [internal.py:wandb_internal():86] W&B internal server running at pid: 106728, started at: 2023-07-11 12:11:13.392926
2023-07-11 12:11:13,394 DEBUG   HandlerThread:106728 [handler.py:handle_request():144] handle_request: status
2023-07-11 12:11:13,395 INFO    WriterThread:106728 [datastore.py:open_for_write():85] open: /home/zhuhe/HPE-with-Diffusion/wandb/run-20230711_121113-szgm6i37/run-szgm6i37.wandb
2023-07-11 12:11:13,395 DEBUG   SenderThread:106728 [sender.py:send():369] send: header
2023-07-11 12:11:13,395 DEBUG   SenderThread:106728 [sender.py:send():369] send: run
2023-07-11 12:11:14,212 INFO    SenderThread:106728 [dir_watcher.py:__init__():211] watching files in: /home/zhuhe/HPE-with-Diffusion/wandb/run-20230711_121113-szgm6i37/files
2023-07-11 12:11:14,212 INFO    SenderThread:106728 [sender.py:_start_run_threads():1100] run started: szgm6i37 with start time 1689048673.39283
2023-07-11 12:11:14,212 DEBUG   SenderThread:106728 [sender.py:send_request():396] send_request: summary_record
2023-07-11 12:11:14,212 INFO    SenderThread:106728 [sender.py:_save_file():1354] saving file wandb-summary.json with policy end
2023-07-11 12:11:14,214 DEBUG   HandlerThread:106728 [handler.py:handle_request():144] handle_request: check_version
2023-07-11 12:11:14,215 DEBUG   SenderThread:106728 [sender.py:send_request():396] send_request: check_version
2023-07-11 12:11:14,434 DEBUG   HandlerThread:106728 [handler.py:handle_request():144] handle_request: run_start
2023-07-11 12:11:14,439 DEBUG   HandlerThread:106728 [system_info.py:__init__():31] System info init
2023-07-11 12:11:14,439 DEBUG   HandlerThread:106728 [system_info.py:__init__():46] System info init done
2023-07-11 12:11:14,439 INFO    HandlerThread:106728 [system_monitor.py:start():181] Starting system monitor
2023-07-11 12:11:14,440 INFO    SystemMonitor:106728 [system_monitor.py:_start():145] Starting system asset monitoring threads
2023-07-11 12:11:14,440 INFO    HandlerThread:106728 [system_monitor.py:probe():201] Collecting system info
2023-07-11 12:11:14,440 INFO    SystemMonitor:106728 [interfaces.py:start():190] Started cpu monitoring
2023-07-11 12:11:14,441 INFO    SystemMonitor:106728 [interfaces.py:start():190] Started disk monitoring
2023-07-11 12:11:14,441 INFO    SystemMonitor:106728 [interfaces.py:start():190] Started gpu monitoring
2023-07-11 12:11:14,441 INFO    SystemMonitor:106728 [interfaces.py:start():190] Started memory monitoring
2023-07-11 12:11:14,442 INFO    SystemMonitor:106728 [interfaces.py:start():190] Started network monitoring
2023-07-11 12:11:14,456 DEBUG   HandlerThread:106728 [system_info.py:probe():195] Probing system
2023-07-11 12:11:14,461 DEBUG   HandlerThread:106728 [gitlib.py:_init_repo():53] git repository is invalid
2023-07-11 12:11:14,461 DEBUG   HandlerThread:106728 [system_info.py:probe():240] Probing system done
2023-07-11 12:11:14,461 DEBUG   HandlerThread:106728 [system_monitor.py:probe():210] {'os': 'Linux-5.19.0-46-generic-x86_64-with-glibc2.35', 'python': '3.9.16', 'heartbeatAt': '2023-07-11T04:11:14.457028', 'startedAt': '2023-07-11T04:11:13.387877', 'docker': None, 'cuda': None, 'args': ('--config', '/home/zhuhe/HPE-with-Diffusion/config/sanitycheck_val.json', '--phase', 'val', '--gpu_ids', '1'), 'state': 'running', 'program': '/home/zhuhe/HPE-with-Diffusion/main.py', 'codePath': 'main.py', 'host': '415-2', 'username': 'zhuhe', 'executable': '/home/zhuhe/.conda/envs/diffhpe/bin/python', 'cpu_count': 16, 'cpu_count_logical': 24, 'cpu_freq': {'current': 4734.1317500000005, 'min': 800.0, 'max': 4783.333333333333}, 'cpu_freq_per_core': [{'current': 5093.715, 'min': 800.0, 'max': 5100.0}, {'current': 5093.505, 'min': 800.0, 'max': 5100.0}, {'current': 5064.869, 'min': 800.0, 'max': 5100.0}, {'current': 5033.454, 'min': 800.0, 'max': 5100.0}, {'current': 5100.025, 'min': 800.0, 'max': 5100.0}, {'current': 5100.0, 'min': 800.0, 'max': 5100.0}, {'current': 5077.411, 'min': 800.0, 'max': 5100.0}, {'current': 4783.521, 'min': 800.0, 'max': 5100.0}, {'current': 5100.0, 'min': 800.0, 'max': 5200.0}, {'current': 5099.77, 'min': 800.0, 'max': 5200.0}, {'current': 5100.0, 'min': 800.0, 'max': 5200.0}, {'current': 5104.946, 'min': 800.0, 'max': 5200.0}, {'current': 5057.097, 'min': 800.0, 'max': 5100.0}, {'current': 4936.169, 'min': 800.0, 'max': 5100.0}, {'current': 5063.972, 'min': 800.0, 'max': 5100.0}, {'current': 5010.975, 'min': 800.0, 'max': 5100.0}, {'current': 4099.973, 'min': 800.0, 'max': 4100.0}, {'current': 4100.024, 'min': 800.0, 'max': 4100.0}, {'current': 4099.978, 'min': 800.0, 'max': 4100.0}, {'current': 4099.982, 'min': 800.0, 'max': 4100.0}, {'current': 4099.743, 'min': 800.0, 'max': 4100.0}, {'current': 4100.009, 'min': 800.0, 'max': 4100.0}, {'current': 4100.013, 'min': 800.0, 'max': 4100.0}, {'current': 4100.011, 'min': 800.0, 'max': 4100.0}], 'disk': {'total': 93.31179428100586, 'used': 0.019847869873046875}, 'gpu': 'NVIDIA GeForce RTX 3090', 'gpu_count': 2, 'gpu_devices': [{'name': 'NVIDIA GeForce RTX 3090', 'memory_total': 25769803776}, {'name': 'NVIDIA GeForce RTX 3090', 'memory_total': 25769803776}], 'memory': {'total': 31.185558319091797}}
2023-07-11 12:11:14,461 INFO    HandlerThread:106728 [system_monitor.py:probe():211] Finished collecting system info
2023-07-11 12:11:14,461 INFO    HandlerThread:106728 [system_monitor.py:probe():214] Publishing system info
2023-07-11 12:11:14,461 DEBUG   HandlerThread:106728 [system_info.py:_save_pip():51] Saving list of pip packages installed into the current environment
2023-07-11 12:11:14,461 DEBUG   HandlerThread:106728 [system_info.py:_save_pip():67] Saving pip packages done
2023-07-11 12:11:14,461 DEBUG   HandlerThread:106728 [system_info.py:_save_conda():74] Saving list of conda packages installed into the current environment
2023-07-11 12:11:15,213 INFO    Thread-12 :106728 [dir_watcher.py:_on_file_created():272] file/dir created: /home/zhuhe/HPE-with-Diffusion/wandb/run-20230711_121113-szgm6i37/files/conda-environment.yaml
2023-07-11 12:11:15,213 INFO    Thread-12 :106728 [dir_watcher.py:_on_file_created():272] file/dir created: /home/zhuhe/HPE-with-Diffusion/wandb/run-20230711_121113-szgm6i37/files/requirements.txt
2023-07-11 12:11:15,213 INFO    Thread-12 :106728 [dir_watcher.py:_on_file_created():272] file/dir created: /home/zhuhe/HPE-with-Diffusion/wandb/run-20230711_121113-szgm6i37/files/wandb-summary.json
2023-07-11 12:11:15,387 DEBUG   HandlerThread:106728 [system_info.py:_save_conda():86] Saving conda packages done
2023-07-11 12:11:15,388 INFO    HandlerThread:106728 [system_monitor.py:probe():216] Finished publishing system info
2023-07-11 12:11:15,389 DEBUG   SenderThread:106728 [sender.py:send():369] send: files
2023-07-11 12:11:15,389 INFO    SenderThread:106728 [sender.py:_save_file():1354] saving file wandb-metadata.json with policy now
2023-07-11 12:11:15,393 DEBUG   HandlerThread:106728 [handler.py:handle_request():144] handle_request: stop_status
2023-07-11 12:11:15,393 DEBUG   SenderThread:106728 [sender.py:send_request():396] send_request: stop_status
2023-07-11 12:11:15,924 ERROR   wandb-upload_0:106728 [internal_api.py:upload_file():2192] upload_file exception https://storage.googleapis.com/wandb-production.appspot.com/ada4321/DiffHPE/szgm6i37/wandb-metadata.json?Expires=1689135075&GoogleAccessId=gorilla-files-url-signer-man%40wandb-production.iam.gserviceaccount.com&Signature=bReSFRdJsvKXFOLuvyPdI5t27%2FgqdwXspNncVraZ0x340Y2mDWosI8Gbb%2FlhVelFpEejzmrvEBIbFCJmVnmChxl%2FJbPyZlSI0QbsCf%2FVpKUZ1dRkUcYIPGh2W5aBAfKS4rHLoscg2EBCekwrQEB0jL2PjqB3yvJoQuXErRoVVtwwkFkV%2BehoaLcqYqkz5aKOvFLCsTZ%2Fl4QCM6LyAYfR3MUeWt1j6Or7qhLiOyEBzQXFACqiMZ163bE2xOHe8Kx4E0TLv1jC5%2FpnBEiPHsAGtyQHYB04kDVZDRFuDCPfr6gtT%2FuOcZhGtS2NmMk84qiLDXXr0KWeaEoLCqDY9ebI7w%3D%3D: 404 Client Error: Not Found for url: https://storage.googleapis.com/wandb-production.appspot.com/ada4321/DiffHPE/szgm6i37/wandb-metadata.json?Expires=1689135075&GoogleAccessId=gorilla-files-url-signer-man%40wandb-production.iam.gserviceaccount.com&Signature=bReSFRdJsvKXFOLuvyPdI5t27%2FgqdwXspNncVraZ0x340Y2mDWosI8Gbb%2FlhVelFpEejzmrvEBIbFCJmVnmChxl%2FJbPyZlSI0QbsCf%2FVpKUZ1dRkUcYIPGh2W5aBAfKS4rHLoscg2EBCekwrQEB0jL2PjqB3yvJoQuXErRoVVtwwkFkV%2BehoaLcqYqkz5aKOvFLCsTZ%2Fl4QCM6LyAYfR3MUeWt1j6Or7qhLiOyEBzQXFACqiMZ163bE2xOHe8Kx4E0TLv1jC5%2FpnBEiPHsAGtyQHYB04kDVZDRFuDCPfr6gtT%2FuOcZhGtS2NmMk84qiLDXXr0KWeaEoLCqDY9ebI7w%3D%3D
2023-07-11 12:11:15,924 ERROR   wandb-upload_0:106728 [internal_api.py:upload_file():2194] upload_file request headers: {'User-Agent': 'python-requests/2.31.0', 'Accept-Encoding': 'gzip, deflate', 'Accept': '*/*', 'Connection': 'keep-alive', 'Content-Length': '3809'}
2023-07-11 12:11:15,924 ERROR   wandb-upload_0:106728 [internal_api.py:upload_file():2196] upload_file response body: b'<!DOCTYPE html>\n<html lang=en>\n  <meta charset=utf-8>\n  <meta name=viewport content="initial-scale=1, minimum-scale=1, width=device-width">\n  <title>Error 404 (Not Found)!!1</title>\n  <style>\n    *{margin:0;padding:0}html,code{font:15px/22px arial,sans-serif}html{background:#fff;color:#222;padding:15px}body{margin:7% auto 0;max-width:390px;min-height:180px;padding:30px 0 15px}* > body{background:url(//www.google.com/images/errors/robot.png) 100% 5px no-repeat;padding-right:205px}p{margin:11px 0 22px;overflow:hidden}ins{color:#777;text-decoration:none}a img{border:0}@media screen and (max-width:772px){body{background:none;margin-top:0;max-width:none;padding-right:0}}#logo{background:url(//www.google.com/images/branding/googlelogo/1x/googlelogo_color_150x54dp.png) no-repeat;margin-left:-5px}@media only screen and (min-resolution:192dpi){#logo{background:url(//www.google.com/images/branding/googlelogo/2x/googlelogo_color_150x54dp.png) no-repeat 0% 0%/100% 100%;-moz-border-image:url(//www.google.com/images/branding/googlelogo/2x/googlelogo_color_150x54dp.png) 0}}@media only screen and (-webkit-min-device-pixel-ratio:2){#logo{background:url(//www.google.com/images/branding/googlelogo/2x/googlelogo_color_150x54dp.png) no-repeat;-webkit-background-size:100% 100%}}#logo{display:inline-block;height:54px;width:150px}\n  </style>\n  <a href=//www.google.com/><span id=logo aria-label=Google></span></a>\n  <p><b>404.</b> <ins>That\xe2\x80\x99s an error.</ins>\n  <p>The requested URL <code>/wandb-production.appspot.com/ada4321/DiffHPE/szgm6i37/wandb-metadata.json</code> was not found on this server.  <ins>That\xe2\x80\x99s all we know.</ins>\n'
2023-07-11 12:11:15,942 DEBUG   SenderThread:106728 [sender.py:send():369] send: telemetry
2023-07-11 12:11:16,213 INFO    Thread-12 :106728 [dir_watcher.py:_on_file_modified():289] file/dir modified: /home/zhuhe/HPE-with-Diffusion/wandb/run-20230711_121113-szgm6i37/files/conda-environment.yaml
2023-07-11 12:11:16,214 INFO    Thread-12 :106728 [dir_watcher.py:_on_file_created():272] file/dir created: /home/zhuhe/HPE-with-Diffusion/wandb/run-20230711_121113-szgm6i37/files/output.log
2023-07-11 12:11:16,214 INFO    Thread-12 :106728 [dir_watcher.py:_on_file_created():272] file/dir created: /home/zhuhe/HPE-with-Diffusion/wandb/run-20230711_121113-szgm6i37/files/wandb-metadata.json
2023-07-11 12:11:16,501 ERROR   wandb-upload_0:106728 [upload_job.py:push():136] Failed to upload file: /tmp/tmphshbt3xwwandb/oqc5wem1-wandb-metadata.json
Traceback (most recent call last):
  File "/home/zhuhe/.conda/envs/diffhpe/lib/python3.9/site-packages/wandb/apis/normalize.py", line 41, in wrapper
    return func(*args, **kwargs)
  File "/home/zhuhe/.conda/envs/diffhpe/lib/python3.9/site-packages/wandb/sdk/lib/retry.py", line 212, in wrapped_fn
    return retrier(*args, **kargs)
  File "/home/zhuhe/.conda/envs/diffhpe/lib/python3.9/site-packages/wandb/sdk/lib/retry.py", line 131, in __call__
    result = self._call_fn(*args, **kwargs)
  File "/home/zhuhe/.conda/envs/diffhpe/lib/python3.9/site-packages/wandb/sdk/internal/internal_api.py", line 2218, in upload_file
    wandb._sentry.reraise(e)
  File "/home/zhuhe/.conda/envs/diffhpe/lib/python3.9/site-packages/wandb/analytics/sentry.py", line 146, in reraise
    raise exc.with_traceback(sys.exc_info()[2])
  File "/home/zhuhe/.conda/envs/diffhpe/lib/python3.9/site-packages/wandb/sdk/internal/internal_api.py", line 2190, in upload_file
    response.raise_for_status()
  File "/home/zhuhe/.conda/envs/diffhpe/lib/python3.9/site-packages/requests/models.py", line 1021, in raise_for_status
    raise HTTPError(http_error_msg, response=self)
requests.exceptions.HTTPError: 404 Client Error: Not Found for url: https://storage.googleapis.com/wandb-production.appspot.com/ada4321/DiffHPE/szgm6i37/wandb-metadata.json?Expires=1689135075&GoogleAccessId=gorilla-files-url-signer-man%40wandb-production.iam.gserviceaccount.com&Signature=bReSFRdJsvKXFOLuvyPdI5t27%2FgqdwXspNncVraZ0x340Y2mDWosI8Gbb%2FlhVelFpEejzmrvEBIbFCJmVnmChxl%2FJbPyZlSI0QbsCf%2FVpKUZ1dRkUcYIPGh2W5aBAfKS4rHLoscg2EBCekwrQEB0jL2PjqB3yvJoQuXErRoVVtwwkFkV%2BehoaLcqYqkz5aKOvFLCsTZ%2Fl4QCM6LyAYfR3MUeWt1j6Or7qhLiOyEBzQXFACqiMZ163bE2xOHe8Kx4E0TLv1jC5%2FpnBEiPHsAGtyQHYB04kDVZDRFuDCPfr6gtT%2FuOcZhGtS2NmMk84qiLDXXr0KWeaEoLCqDY9ebI7w%3D%3D

During handling of the above exception, another exception occurred:

Traceback (most recent call last):
  File "/home/zhuhe/.conda/envs/diffhpe/lib/python3.9/site-packages/wandb/filesync/upload_job.py", line 127, in push
    self._api.upload_file_retry(
  File "/home/zhuhe/.conda/envs/diffhpe/lib/python3.9/site-packages/wandb/apis/normalize.py", line 51, in wrapper
    raise CommError(message, error)
wandb.errors.CommError: <Response [404]>
2023-07-11 12:11:16,716 ERROR   Thread-11 :106728 [step_upload.py:_handle_event():200] Failed to upload file: /tmp/tmphshbt3xwwandb/oqc5wem1-wandb-metadata.json
Traceback (most recent call last):
  File "/home/zhuhe/.conda/envs/diffhpe/lib/python3.9/site-packages/wandb/apis/normalize.py", line 41, in wrapper
    return func(*args, **kwargs)
  File "/home/zhuhe/.conda/envs/diffhpe/lib/python3.9/site-packages/wandb/sdk/lib/retry.py", line 212, in wrapped_fn
    return retrier(*args, **kargs)
  File "/home/zhuhe/.conda/envs/diffhpe/lib/python3.9/site-packages/wandb/sdk/lib/retry.py", line 131, in __call__
    result = self._call_fn(*args, **kwargs)
  File "/home/zhuhe/.conda/envs/diffhpe/lib/python3.9/site-packages/wandb/sdk/internal/internal_api.py", line 2218, in upload_file
    wandb._sentry.reraise(e)
  File "/home/zhuhe/.conda/envs/diffhpe/lib/python3.9/site-packages/wandb/analytics/sentry.py", line 146, in reraise
    raise exc.with_traceback(sys.exc_info()[2])
  File "/home/zhuhe/.conda/envs/diffhpe/lib/python3.9/site-packages/wandb/sdk/internal/internal_api.py", line 2190, in upload_file
    response.raise_for_status()
  File "/home/zhuhe/.conda/envs/diffhpe/lib/python3.9/site-packages/requests/models.py", line 1021, in raise_for_status
    raise HTTPError(http_error_msg, response=self)
requests.exceptions.HTTPError: 404 Client Error: Not Found for url: https://storage.googleapis.com/wandb-production.appspot.com/ada4321/DiffHPE/szgm6i37/wandb-metadata.json?Expires=1689135075&GoogleAccessId=gorilla-files-url-signer-man%40wandb-production.iam.gserviceaccount.com&Signature=bReSFRdJsvKXFOLuvyPdI5t27%2FgqdwXspNncVraZ0x340Y2mDWosI8Gbb%2FlhVelFpEejzmrvEBIbFCJmVnmChxl%2FJbPyZlSI0QbsCf%2FVpKUZ1dRkUcYIPGh2W5aBAfKS4rHLoscg2EBCekwrQEB0jL2PjqB3yvJoQuXErRoVVtwwkFkV%2BehoaLcqYqkz5aKOvFLCsTZ%2Fl4QCM6LyAYfR3MUeWt1j6Or7qhLiOyEBzQXFACqiMZ163bE2xOHe8Kx4E0TLv1jC5%2FpnBEiPHsAGtyQHYB04kDVZDRFuDCPfr6gtT%2FuOcZhGtS2NmMk84qiLDXXr0KWeaEoLCqDY9ebI7w%3D%3D

During handling of the above exception, another exception occurred:

Traceback (most recent call last):
  File "/home/zhuhe/.conda/envs/diffhpe/lib/python3.9/concurrent/futures/thread.py", line 58, in run
    result = self.fn(*self.args, **self.kwargs)
  File "/home/zhuhe/.conda/envs/diffhpe/lib/python3.9/site-packages/wandb/filesync/step_upload.py", line 288, in run_and_notify
    self._do_upload_sync(event)
  File "/home/zhuhe/.conda/envs/diffhpe/lib/python3.9/site-packages/wandb/filesync/step_upload.py", line 330, in _do_upload_sync
    job.run()
  File "/home/zhuhe/.conda/envs/diffhpe/lib/python3.9/site-packages/wandb/filesync/upload_job.py", line 57, in run
    self.push()
  File "/home/zhuhe/.conda/envs/diffhpe/lib/python3.9/site-packages/wandb/filesync/upload_job.py", line 127, in push
    self._api.upload_file_retry(
  File "/home/zhuhe/.conda/envs/diffhpe/lib/python3.9/site-packages/wandb/apis/normalize.py", line 51, in wrapper
    raise CommError(message, error)
wandb.errors.CommError: <Response [404]>
2023-07-11 12:11:18,214 INFO    Thread-12 :106728 [dir_watcher.py:_on_file_modified():289] file/dir modified: /home/zhuhe/HPE-with-Diffusion/wandb/run-20230711_121113-szgm6i37/files/output.log
2023-07-11 12:11:18,686 DEBUG   HandlerThread:106728 [handler.py:handle_request():144] handle_request: status_report
2023-07-11 12:11:20,214 INFO    Thread-12 :106728 [dir_watcher.py:_on_file_modified():289] file/dir modified: /home/zhuhe/HPE-with-Diffusion/wandb/run-20230711_121113-szgm6i37/files/output.log
2023-07-11 12:11:23,939 DEBUG   HandlerThread:106728 [handler.py:handle_request():144] handle_request: status_report
2023-07-11 12:11:24,028 DEBUG   SenderThread:106728 [sender.py:send():369] send: telemetry
2023-07-11 12:11:26,216 INFO    Thread-12 :106728 [dir_watcher.py:_on_file_modified():289] file/dir modified: /home/zhuhe/HPE-with-Diffusion/wandb/run-20230711_121113-szgm6i37/files/output.log
2023-07-11 12:11:29,091 DEBUG   HandlerThread:106728 [handler.py:handle_request():144] handle_request: status_report
2023-07-11 12:11:30,217 INFO    Thread-12 :106728 [dir_watcher.py:_on_file_modified():289] file/dir modified: /home/zhuhe/HPE-with-Diffusion/wandb/run-20230711_121113-szgm6i37/files/output.log
2023-07-11 12:11:30,393 DEBUG   HandlerThread:106728 [handler.py:handle_request():144] handle_request: stop_status
2023-07-11 12:11:30,393 DEBUG   SenderThread:106728 [sender.py:send_request():396] send_request: stop_status
2023-07-11 12:11:32,218 INFO    Thread-12 :106728 [dir_watcher.py:_on_file_modified():289] file/dir modified: /home/zhuhe/HPE-with-Diffusion/wandb/run-20230711_121113-szgm6i37/files/output.log
2023-07-11 12:11:35,019 DEBUG   HandlerThread:106728 [handler.py:handle_request():144] handle_request: status_report
2023-07-11 12:11:35,192 DEBUG   SenderThread:106728 [sender.py:send():369] send: exit
2023-07-11 12:11:35,192 INFO    SenderThread:106728 [sender.py:send_exit():574] handling exit code: 0
2023-07-11 12:11:35,192 INFO    SenderThread:106728 [sender.py:send_exit():576] handling runtime: 20
2023-07-11 12:11:35,193 INFO    SenderThread:106728 [sender.py:_save_file():1354] saving file wandb-summary.json with policy end
2023-07-11 12:11:35,193 INFO    SenderThread:106728 [sender.py:send_exit():582] send defer
2023-07-11 12:11:35,193 DEBUG   HandlerThread:106728 [handler.py:handle_request():144] handle_request: defer
2023-07-11 12:11:35,193 INFO    HandlerThread:106728 [handler.py:handle_request_defer():170] handle defer: 0
2023-07-11 12:11:35,194 DEBUG   SenderThread:106728 [sender.py:send_request():396] send_request: defer
2023-07-11 12:11:35,194 INFO    SenderThread:106728 [sender.py:send_request_defer():598] handle sender defer: 0
2023-07-11 12:11:35,194 INFO    SenderThread:106728 [sender.py:transition_state():602] send defer: 1
2023-07-11 12:11:35,194 DEBUG   HandlerThread:106728 [handler.py:handle_request():144] handle_request: defer
2023-07-11 12:11:35,194 INFO    HandlerThread:106728 [handler.py:handle_request_defer():170] handle defer: 1
2023-07-11 12:11:35,194 DEBUG   SenderThread:106728 [sender.py:send_request():396] send_request: defer
2023-07-11 12:11:35,194 INFO    SenderThread:106728 [sender.py:send_request_defer():598] handle sender defer: 1
2023-07-11 12:11:35,194 INFO    SenderThread:106728 [sender.py:transition_state():602] send defer: 2
2023-07-11 12:11:35,194 DEBUG   HandlerThread:106728 [handler.py:handle_request():144] handle_request: defer
2023-07-11 12:11:35,194 INFO    HandlerThread:106728 [handler.py:handle_request_defer():170] handle defer: 2
2023-07-11 12:11:35,194 INFO    HandlerThread:106728 [system_monitor.py:finish():190] Stopping system monitor
2023-07-11 12:11:35,194 DEBUG   SystemMonitor:106728 [system_monitor.py:_start():159] Starting system metrics aggregation loop
2023-07-11 12:11:35,194 INFO    HandlerThread:106728 [interfaces.py:finish():202] Joined cpu monitor
2023-07-11 12:11:35,194 DEBUG   SystemMonitor:106728 [system_monitor.py:_start():166] Finished system metrics aggregation loop
2023-07-11 12:11:35,194 INFO    HandlerThread:106728 [interfaces.py:finish():202] Joined disk monitor
2023-07-11 12:11:35,195 DEBUG   SystemMonitor:106728 [system_monitor.py:_start():170] Publishing last batch of metrics
2023-07-11 12:11:35,218 INFO    Thread-12 :106728 [dir_watcher.py:_on_file_modified():289] file/dir modified: /home/zhuhe/HPE-with-Diffusion/wandb/run-20230711_121113-szgm6i37/files/wandb-summary.json
2023-07-11 12:11:35,277 INFO    HandlerThread:106728 [interfaces.py:finish():202] Joined gpu monitor
2023-07-11 12:11:35,278 INFO    HandlerThread:106728 [interfaces.py:finish():202] Joined memory monitor
2023-07-11 12:11:35,278 INFO    HandlerThread:106728 [interfaces.py:finish():202] Joined network monitor
2023-07-11 12:11:35,278 DEBUG   SenderThread:106728 [sender.py:send_request():396] send_request: defer
2023-07-11 12:11:35,278 INFO    SenderThread:106728 [sender.py:send_request_defer():598] handle sender defer: 2
2023-07-11 12:11:35,278 INFO    SenderThread:106728 [sender.py:transition_state():602] send defer: 3
2023-07-11 12:11:35,278 DEBUG   SenderThread:106728 [sender.py:send():369] send: stats
2023-07-11 12:11:35,278 DEBUG   HandlerThread:106728 [handler.py:handle_request():144] handle_request: defer
2023-07-11 12:11:35,278 INFO    HandlerThread:106728 [handler.py:handle_request_defer():170] handle defer: 3
2023-07-11 12:11:35,279 DEBUG   SenderThread:106728 [sender.py:send_request():396] send_request: defer
2023-07-11 12:11:35,279 INFO    SenderThread:106728 [sender.py:send_request_defer():598] handle sender defer: 3
2023-07-11 12:11:35,279 INFO    SenderThread:106728 [sender.py:transition_state():602] send defer: 4
2023-07-11 12:11:35,279 DEBUG   HandlerThread:106728 [handler.py:handle_request():144] handle_request: defer
2023-07-11 12:11:35,279 INFO    HandlerThread:106728 [handler.py:handle_request_defer():170] handle defer: 4
2023-07-11 12:11:35,279 DEBUG   SenderThread:106728 [sender.py:send_request():396] send_request: defer
2023-07-11 12:11:35,279 INFO    SenderThread:106728 [sender.py:send_request_defer():598] handle sender defer: 4
2023-07-11 12:11:35,279 INFO    SenderThread:106728 [sender.py:transition_state():602] send defer: 5
2023-07-11 12:11:35,279 DEBUG   HandlerThread:106728 [handler.py:handle_request():144] handle_request: defer
2023-07-11 12:11:35,279 INFO    HandlerThread:106728 [handler.py:handle_request_defer():170] handle defer: 5
2023-07-11 12:11:35,279 DEBUG   SenderThread:106728 [sender.py:send():369] send: summary
2023-07-11 12:11:35,280 INFO    SenderThread:106728 [sender.py:_save_file():1354] saving file wandb-summary.json with policy end
2023-07-11 12:11:35,280 DEBUG   SenderThread:106728 [sender.py:send_request():396] send_request: defer
2023-07-11 12:11:35,280 INFO    SenderThread:106728 [sender.py:send_request_defer():598] handle sender defer: 5
2023-07-11 12:11:35,280 INFO    SenderThread:106728 [sender.py:transition_state():602] send defer: 6
2023-07-11 12:11:35,280 DEBUG   HandlerThread:106728 [handler.py:handle_request():144] handle_request: defer
2023-07-11 12:11:35,280 INFO    HandlerThread:106728 [handler.py:handle_request_defer():170] handle defer: 6
2023-07-11 12:11:35,280 DEBUG   SenderThread:106728 [sender.py:send_request():396] send_request: defer
2023-07-11 12:11:35,280 INFO    SenderThread:106728 [sender.py:send_request_defer():598] handle sender defer: 6
2023-07-11 12:11:35,282 DEBUG   HandlerThread:106728 [handler.py:handle_request():144] handle_request: status_report
2023-07-11 12:11:35,590 INFO    SenderThread:106728 [sender.py:transition_state():602] send defer: 7
2023-07-11 12:11:35,591 DEBUG   HandlerThread:106728 [handler.py:handle_request():144] handle_request: defer
2023-07-11 12:11:35,591 INFO    HandlerThread:106728 [handler.py:handle_request_defer():170] handle defer: 7
2023-07-11 12:11:35,591 DEBUG   SenderThread:106728 [sender.py:send_request():396] send_request: defer
2023-07-11 12:11:35,591 INFO    SenderThread:106728 [sender.py:send_request_defer():598] handle sender defer: 7
2023-07-11 12:11:36,192 DEBUG   HandlerThread:106728 [handler.py:handle_request():144] handle_request: poll_exit
2023-07-11 12:11:36,219 INFO    Thread-12 :106728 [dir_watcher.py:_on_file_modified():289] file/dir modified: /home/zhuhe/HPE-with-Diffusion/wandb/run-20230711_121113-szgm6i37/files/output.log
2023-07-11 12:11:36,219 INFO    Thread-12 :106728 [dir_watcher.py:_on_file_modified():289] file/dir modified: /home/zhuhe/HPE-with-Diffusion/wandb/run-20230711_121113-szgm6i37/files/wandb-summary.json
2023-07-11 12:11:36,219 INFO    Thread-12 :106728 [dir_watcher.py:_on_file_modified():289] file/dir modified: /home/zhuhe/HPE-with-Diffusion/wandb/run-20230711_121113-szgm6i37/files/config.yaml
2023-07-11 12:11:37,969 INFO    SenderThread:106728 [sender.py:transition_state():602] send defer: 8
2023-07-11 12:11:37,969 DEBUG   SenderThread:106728 [sender.py:send_request():396] send_request: poll_exit
2023-07-11 12:11:37,969 DEBUG   HandlerThread:106728 [handler.py:handle_request():144] handle_request: defer
2023-07-11 12:11:37,969 INFO    HandlerThread:106728 [handler.py:handle_request_defer():170] handle defer: 8
2023-07-11 12:11:37,969 DEBUG   SenderThread:106728 [sender.py:send_request():396] send_request: defer
2023-07-11 12:11:37,969 INFO    SenderThread:106728 [sender.py:send_request_defer():598] handle sender defer: 8
2023-07-11 12:11:37,969 INFO    SenderThread:106728 [job_builder.py:build():232] Attempting to build job artifact
2023-07-11 12:11:37,969 INFO    SenderThread:106728 [job_builder.py:build():266] no source found
2023-07-11 12:11:37,969 INFO    SenderThread:106728 [sender.py:transition_state():602] send defer: 9
2023-07-11 12:11:37,969 DEBUG   HandlerThread:106728 [handler.py:handle_request():144] handle_request: defer
2023-07-11 12:11:37,970 INFO    HandlerThread:106728 [handler.py:handle_request_defer():170] handle defer: 9
2023-07-11 12:11:37,970 DEBUG   SenderThread:106728 [sender.py:send_request():396] send_request: defer
2023-07-11 12:11:37,970 INFO    SenderThread:106728 [sender.py:send_request_defer():598] handle sender defer: 9
2023-07-11 12:11:37,970 INFO    SenderThread:106728 [dir_watcher.py:finish():359] shutting down directory watcher
2023-07-11 12:11:38,219 INFO    Thread-12 :106728 [dir_watcher.py:_on_file_modified():289] file/dir modified: /home/zhuhe/HPE-with-Diffusion/wandb/run-20230711_121113-szgm6i37/files/output.log
2023-07-11 12:11:38,219 INFO    SenderThread:106728 [dir_watcher.py:finish():389] scan: /home/zhuhe/HPE-with-Diffusion/wandb/run-20230711_121113-szgm6i37/files
2023-07-11 12:11:38,219 INFO    SenderThread:106728 [dir_watcher.py:finish():403] scan save: /home/zhuhe/HPE-with-Diffusion/wandb/run-20230711_121113-szgm6i37/files/wandb-metadata.json wandb-metadata.json
2023-07-11 12:11:38,219 INFO    SenderThread:106728 [dir_watcher.py:finish():403] scan save: /home/zhuhe/HPE-with-Diffusion/wandb/run-20230711_121113-szgm6i37/files/config.yaml config.yaml
2023-07-11 12:11:38,219 INFO    SenderThread:106728 [dir_watcher.py:finish():403] scan save: /home/zhuhe/HPE-with-Diffusion/wandb/run-20230711_121113-szgm6i37/files/requirements.txt requirements.txt
2023-07-11 12:11:38,220 INFO    SenderThread:106728 [dir_watcher.py:finish():403] scan save: /home/zhuhe/HPE-with-Diffusion/wandb/run-20230711_121113-szgm6i37/files/wandb-summary.json wandb-summary.json
2023-07-11 12:11:38,220 INFO    SenderThread:106728 [dir_watcher.py:finish():403] scan save: /home/zhuhe/HPE-with-Diffusion/wandb/run-20230711_121113-szgm6i37/files/conda-environment.yaml conda-environment.yaml
2023-07-11 12:11:38,220 INFO    SenderThread:106728 [dir_watcher.py:finish():403] scan save: /home/zhuhe/HPE-with-Diffusion/wandb/run-20230711_121113-szgm6i37/files/output.log output.log
2023-07-11 12:11:38,220 INFO    SenderThread:106728 [sender.py:transition_state():602] send defer: 10
2023-07-11 12:11:38,222 DEBUG   HandlerThread:106728 [handler.py:handle_request():144] handle_request: defer
2023-07-11 12:11:38,223 INFO    HandlerThread:106728 [handler.py:handle_request_defer():170] handle defer: 10
2023-07-11 12:11:38,223 DEBUG   SenderThread:106728 [sender.py:send_request():396] send_request: defer
2023-07-11 12:11:38,224 INFO    SenderThread:106728 [sender.py:send_request_defer():598] handle sender defer: 10
2023-07-11 12:11:38,224 INFO    SenderThread:106728 [file_pusher.py:finish():159] shutting down file pusher
2023-07-11 12:11:38,684 ERROR   wandb-upload_1:106728 [internal_api.py:upload_file():2192] upload_file exception https://storage.googleapis.com/wandb-production.appspot.com/ada4321/DiffHPE/szgm6i37/requirements.txt?Expires=1689135098&GoogleAccessId=gorilla-files-url-signer-man%40wandb-production.iam.gserviceaccount.com&Signature=uAzZlyhw8HMzsGtG5rjVEp1nwFfKfDkVZoklYmD5OQ0AXDEQdPlSzFhWco4q038ze2TxBZ%2F6jrh4qSLdcVHmg2ob0mziAZwbmM0wkiBXiSOHuKrJFNSjQSOxnLpKxbwGHo1dSlAw%2B%2F3%2BzLCx%2BNsdjKHQMg%2F0B4U%2ByoTQmRaCkMeeqMYQKuG6aJG4zf5gP9DlNWZzBLRhZ98Uy0mpgRpjztvgHg0Ppi48rGEBpxdY3ixSEsRB0x%2BnqYz90A%2Ffs9qt3Nz8DTq0dat3ejYOz5OBwN4joTgZ0CGW6df5G9NMISap6Z7nUaS6Bz4mWwJEjIk4Nut39Yalc0sM7csmt%2FIUJg%3D%3D: 404 Client Error: Not Found for url: https://storage.googleapis.com/wandb-production.appspot.com/ada4321/DiffHPE/szgm6i37/requirements.txt?Expires=1689135098&GoogleAccessId=gorilla-files-url-signer-man%40wandb-production.iam.gserviceaccount.com&Signature=uAzZlyhw8HMzsGtG5rjVEp1nwFfKfDkVZoklYmD5OQ0AXDEQdPlSzFhWco4q038ze2TxBZ%2F6jrh4qSLdcVHmg2ob0mziAZwbmM0wkiBXiSOHuKrJFNSjQSOxnLpKxbwGHo1dSlAw%2B%2F3%2BzLCx%2BNsdjKHQMg%2F0B4U%2ByoTQmRaCkMeeqMYQKuG6aJG4zf5gP9DlNWZzBLRhZ98Uy0mpgRpjztvgHg0Ppi48rGEBpxdY3ixSEsRB0x%2BnqYz90A%2Ffs9qt3Nz8DTq0dat3ejYOz5OBwN4joTgZ0CGW6df5G9NMISap6Z7nUaS6Bz4mWwJEjIk4Nut39Yalc0sM7csmt%2FIUJg%3D%3D
2023-07-11 12:11:38,684 ERROR   wandb-upload_1:106728 [internal_api.py:upload_file():2194] upload_file request headers: {'User-Agent': 'python-requests/2.31.0', 'Accept-Encoding': 'gzip, deflate', 'Accept': '*/*', 'Connection': 'keep-alive', 'Content-Length': '926'}
2023-07-11 12:11:38,684 ERROR   wandb-upload_1:106728 [internal_api.py:upload_file():2196] upload_file response body: b'<!DOCTYPE html>\n<html lang=en>\n  <meta charset=utf-8>\n  <meta name=viewport content="initial-scale=1, minimum-scale=1, width=device-width">\n  <title>Error 404 (Not Found)!!1</title>\n  <style>\n    *{margin:0;padding:0}html,code{font:15px/22px arial,sans-serif}html{background:#fff;color:#222;padding:15px}body{margin:7% auto 0;max-width:390px;min-height:180px;padding:30px 0 15px}* > body{background:url(//www.google.com/images/errors/robot.png) 100% 5px no-repeat;padding-right:205px}p{margin:11px 0 22px;overflow:hidden}ins{color:#777;text-decoration:none}a img{border:0}@media screen and (max-width:772px){body{background:none;margin-top:0;max-width:none;padding-right:0}}#logo{background:url(//www.google.com/images/branding/googlelogo/1x/googlelogo_color_150x54dp.png) no-repeat;margin-left:-5px}@media only screen and (min-resolution:192dpi){#logo{background:url(//www.google.com/images/branding/googlelogo/2x/googlelogo_color_150x54dp.png) no-repeat 0% 0%/100% 100%;-moz-border-image:url(//www.google.com/images/branding/googlelogo/2x/googlelogo_color_150x54dp.png) 0}}@media only screen and (-webkit-min-device-pixel-ratio:2){#logo{background:url(//www.google.com/images/branding/googlelogo/2x/googlelogo_color_150x54dp.png) no-repeat;-webkit-background-size:100% 100%}}#logo{display:inline-block;height:54px;width:150px}\n  </style>\n  <a href=//www.google.com/><span id=logo aria-label=Google></span></a>\n  <p><b>404.</b> <ins>That\xe2\x80\x99s an error.</ins>\n  <p>The requested URL <code>/wandb-production.appspot.com/ada4321/DiffHPE/szgm6i37/requirements.txt</code> was not found on this server.  <ins>That\xe2\x80\x99s all we know.</ins>\n'
2023-07-11 12:11:38,690 ERROR   wandb-upload_0:106728 [internal_api.py:upload_file():2192] upload_file exception https://storage.googleapis.com/wandb-production.appspot.com/ada4321/DiffHPE/szgm6i37/config.yaml?Expires=1689135098&GoogleAccessId=gorilla-files-url-signer-man%40wandb-production.iam.gserviceaccount.com&Signature=M%2BZimABLPmyqi%2BC%2FhlCd%2FVGEI%2FRE6RYXCOAgJr%2F3g%2BggOvQjL6zZQwPdSUgms%2F0FzNL8Gmc5Mdx9uwfdgsZeHGwIoTQBSUFZ%2B9tkkHizKSEI1eLLFQznlTTQnFK7t80CBRRDJgASuf0HajxhdilIYowSkWzsd78DEr8j%2FrWnT5kvES3b57tdZc36lyZqDWJjbeO7kKWbgpZ15E4PyIOOe1tZpItVwriKWOVFL8w2RGnLjQKBJ9yDp8rp3WBUxcz%2BSRvSr4QEQmmGorNI66NVOsuOWGfFBLqQUrZBNalkkcchaHZ2DW22Ud9VGaDWl%2B3w1njZyDVeaFYRmFO5JdNtfQ%3D%3D: 404 Client Error: Not Found for url: https://storage.googleapis.com/wandb-production.appspot.com/ada4321/DiffHPE/szgm6i37/config.yaml?Expires=1689135098&GoogleAccessId=gorilla-files-url-signer-man%40wandb-production.iam.gserviceaccount.com&Signature=M%2BZimABLPmyqi%2BC%2FhlCd%2FVGEI%2FRE6RYXCOAgJr%2F3g%2BggOvQjL6zZQwPdSUgms%2F0FzNL8Gmc5Mdx9uwfdgsZeHGwIoTQBSUFZ%2B9tkkHizKSEI1eLLFQznlTTQnFK7t80CBRRDJgASuf0HajxhdilIYowSkWzsd78DEr8j%2FrWnT5kvES3b57tdZc36lyZqDWJjbeO7kKWbgpZ15E4PyIOOe1tZpItVwriKWOVFL8w2RGnLjQKBJ9yDp8rp3WBUxcz%2BSRvSr4QEQmmGorNI66NVOsuOWGfFBLqQUrZBNalkkcchaHZ2DW22Ud9VGaDWl%2B3w1njZyDVeaFYRmFO5JdNtfQ%3D%3D
2023-07-11 12:11:38,690 ERROR   wandb-upload_0:106728 [internal_api.py:upload_file():2194] upload_file request headers: {'User-Agent': 'python-requests/2.31.0', 'Accept-Encoding': 'gzip, deflate', 'Accept': '*/*', 'Connection': 'keep-alive', 'Content-Length': '557'}
2023-07-11 12:11:38,690 ERROR   wandb-upload_0:106728 [internal_api.py:upload_file():2196] upload_file response body: b'<!DOCTYPE html>\n<html lang=en>\n  <meta charset=utf-8>\n  <meta name=viewport content="initial-scale=1, minimum-scale=1, width=device-width">\n  <title>Error 404 (Not Found)!!1</title>\n  <style>\n    *{margin:0;padding:0}html,code{font:15px/22px arial,sans-serif}html{background:#fff;color:#222;padding:15px}body{margin:7% auto 0;max-width:390px;min-height:180px;padding:30px 0 15px}* > body{background:url(//www.google.com/images/errors/robot.png) 100% 5px no-repeat;padding-right:205px}p{margin:11px 0 22px;overflow:hidden}ins{color:#777;text-decoration:none}a img{border:0}@media screen and (max-width:772px){body{background:none;margin-top:0;max-width:none;padding-right:0}}#logo{background:url(//www.google.com/images/branding/googlelogo/1x/googlelogo_color_150x54dp.png) no-repeat;margin-left:-5px}@media only screen and (min-resolution:192dpi){#logo{background:url(//www.google.com/images/branding/googlelogo/2x/googlelogo_color_150x54dp.png) no-repeat 0% 0%/100% 100%;-moz-border-image:url(//www.google.com/images/branding/googlelogo/2x/googlelogo_color_150x54dp.png) 0}}@media only screen and (-webkit-min-device-pixel-ratio:2){#logo{background:url(//www.google.com/images/branding/googlelogo/2x/googlelogo_color_150x54dp.png) no-repeat;-webkit-background-size:100% 100%}}#logo{display:inline-block;height:54px;width:150px}\n  </style>\n  <a href=//www.google.com/><span id=logo aria-label=Google></span></a>\n  <p><b>404.</b> <ins>That\xe2\x80\x99s an error.</ins>\n  <p>The requested URL <code>/wandb-production.appspot.com/ada4321/DiffHPE/szgm6i37/config.yaml</code> was not found on this server.  <ins>That\xe2\x80\x99s all we know.</ins>\n'
2023-07-11 12:11:39,041 ERROR   wandb-upload_2:106728 [internal_api.py:upload_file():2192] upload_file exception https://storage.googleapis.com/wandb-production.appspot.com/ada4321/DiffHPE/szgm6i37/wandb-summary.json?Expires=1689135098&GoogleAccessId=gorilla-files-url-signer-man%40wandb-production.iam.gserviceaccount.com&Signature=JePoCqrqTRzVn9ClCnYD2Jzsyya1yj61EgUHYcGTxokM%2FMd0bJJsTaBDEcPagmzt1%2BXDuvjfO4lM87vXMPwTpLRBWVoCunaq4j%2BiGymXJwKq7P%2F%2B6IYok0PEPeOIeEJPIU5ifNkuXr8Eyc0RYwH9eA227Cspw%2BYVLvcfAP%2F63ibLUtc3KDNFglmKvHN0B8jK9iMt%2B7T8vFVjqmDQtYex2J%2BYAdtgbE1ROl%2Fnyo15l7lMejTFQrH0RFHlmBXvseCGojeuEn8rSYGDVGanj%2FFc8VhdvFDYPfbUfwy2BoIwvuUvthgVy4Q5agyghCsWw8nrkeloZNvfRq9g1e8uQ%2FObKQ%3D%3D: 404 Client Error: Not Found for url: https://storage.googleapis.com/wandb-production.appspot.com/ada4321/DiffHPE/szgm6i37/wandb-summary.json?Expires=1689135098&GoogleAccessId=gorilla-files-url-signer-man%40wandb-production.iam.gserviceaccount.com&Signature=JePoCqrqTRzVn9ClCnYD2Jzsyya1yj61EgUHYcGTxokM%2FMd0bJJsTaBDEcPagmzt1%2BXDuvjfO4lM87vXMPwTpLRBWVoCunaq4j%2BiGymXJwKq7P%2F%2B6IYok0PEPeOIeEJPIU5ifNkuXr8Eyc0RYwH9eA227Cspw%2BYVLvcfAP%2F63ibLUtc3KDNFglmKvHN0B8jK9iMt%2B7T8vFVjqmDQtYex2J%2BYAdtgbE1ROl%2Fnyo15l7lMejTFQrH0RFHlmBXvseCGojeuEn8rSYGDVGanj%2FFc8VhdvFDYPfbUfwy2BoIwvuUvthgVy4Q5agyghCsWw8nrkeloZNvfRq9g1e8uQ%2FObKQ%3D%3D
2023-07-11 12:11:39,041 ERROR   wandb-upload_2:106728 [internal_api.py:upload_file():2194] upload_file request headers: {'User-Agent': 'python-requests/2.31.0', 'Accept-Encoding': 'gzip, deflate', 'Accept': '*/*', 'Connection': 'keep-alive', 'Content-Length': '27'}
2023-07-11 12:11:39,041 ERROR   wandb-upload_2:106728 [internal_api.py:upload_file():2196] upload_file response body: b'<!DOCTYPE html>\n<html lang=en>\n  <meta charset=utf-8>\n  <meta name=viewport content="initial-scale=1, minimum-scale=1, width=device-width">\n  <title>Error 404 (Not Found)!!1</title>\n  <style>\n    *{margin:0;padding:0}html,code{font:15px/22px arial,sans-serif}html{background:#fff;color:#222;padding:15px}body{margin:7% auto 0;max-width:390px;min-height:180px;padding:30px 0 15px}* > body{background:url(//www.google.com/images/errors/robot.png) 100% 5px no-repeat;padding-right:205px}p{margin:11px 0 22px;overflow:hidden}ins{color:#777;text-decoration:none}a img{border:0}@media screen and (max-width:772px){body{background:none;margin-top:0;max-width:none;padding-right:0}}#logo{background:url(//www.google.com/images/branding/googlelogo/1x/googlelogo_color_150x54dp.png) no-repeat;margin-left:-5px}@media only screen and (min-resolution:192dpi){#logo{background:url(//www.google.com/images/branding/googlelogo/2x/googlelogo_color_150x54dp.png) no-repeat 0% 0%/100% 100%;-moz-border-image:url(//www.google.com/images/branding/googlelogo/2x/googlelogo_color_150x54dp.png) 0}}@media only screen and (-webkit-min-device-pixel-ratio:2){#logo{background:url(//www.google.com/images/branding/googlelogo/2x/googlelogo_color_150x54dp.png) no-repeat;-webkit-background-size:100% 100%}}#logo{display:inline-block;height:54px;width:150px}\n  </style>\n  <a href=//www.google.com/><span id=logo aria-label=Google></span></a>\n  <p><b>404.</b> <ins>That\xe2\x80\x99s an error.</ins>\n  <p>The requested URL <code>/wandb-production.appspot.com/ada4321/DiffHPE/szgm6i37/wandb-summary.json</code> was not found on this server.  <ins>That\xe2\x80\x99s all we know.</ins>\n'
2023-07-11 12:11:39,043 ERROR   wandb-upload_3:106728 [internal_api.py:upload_file():2192] upload_file exception https://storage.googleapis.com/wandb-production.appspot.com/ada4321/DiffHPE/szgm6i37/conda-environment.yaml?Expires=1689135098&GoogleAccessId=gorilla-files-url-signer-man%40wandb-production.iam.gserviceaccount.com&Signature=mCO1hK95AjrgwNaGCDtDvZrZByBTDFuZHT7ZUCQoehgatini5t4WsbHJB1CRkAdMX5xGYYkFaG1TwuSVObP51%2FYGHiSSJp2dGrmMIE9Ulq8xOB%2Fs32SRXfWseRDXWIgGsdgbHvMKd12dFFKwO6K61MJKPChgeX6taL%2FFVueBmHiCb1UBd%2BzkAP%2FTDfXvtQADt8Tcl2EufQsHQQUMpv58WP03QxSxHVVS3ib08lkpJFhXU7tJpJ5jbSoF9glb4zCBfojhNHXMdtR3QMTwkYAvMVODx6vyBbljBtPKbHIy3jLWn46gOdlh0qYk61RJadMGlc%2BYjAQB2NkA1RXnFoCPdQ%3D%3D: 404 Client Error: Not Found for url: https://storage.googleapis.com/wandb-production.appspot.com/ada4321/DiffHPE/szgm6i37/conda-environment.yaml?Expires=1689135098&GoogleAccessId=gorilla-files-url-signer-man%40wandb-production.iam.gserviceaccount.com&Signature=mCO1hK95AjrgwNaGCDtDvZrZByBTDFuZHT7ZUCQoehgatini5t4WsbHJB1CRkAdMX5xGYYkFaG1TwuSVObP51%2FYGHiSSJp2dGrmMIE9Ulq8xOB%2Fs32SRXfWseRDXWIgGsdgbHvMKd12dFFKwO6K61MJKPChgeX6taL%2FFVueBmHiCb1UBd%2BzkAP%2FTDfXvtQADt8Tcl2EufQsHQQUMpv58WP03QxSxHVVS3ib08lkpJFhXU7tJpJ5jbSoF9glb4zCBfojhNHXMdtR3QMTwkYAvMVODx6vyBbljBtPKbHIy3jLWn46gOdlh0qYk61RJadMGlc%2BYjAQB2NkA1RXnFoCPdQ%3D%3D
2023-07-11 12:11:39,043 ERROR   wandb-upload_3:106728 [internal_api.py:upload_file():2194] upload_file request headers: {'User-Agent': 'python-requests/2.31.0', 'Accept-Encoding': 'gzip, deflate', 'Accept': '*/*', 'Connection': 'keep-alive', 'Content-Length': '1925'}
2023-07-11 12:11:39,043 ERROR   wandb-upload_3:106728 [internal_api.py:upload_file():2196] upload_file response body: b'<!DOCTYPE html>\n<html lang=en>\n  <meta charset=utf-8>\n  <meta name=viewport content="initial-scale=1, minimum-scale=1, width=device-width">\n  <title>Error 404 (Not Found)!!1</title>\n  <style>\n    *{margin:0;padding:0}html,code{font:15px/22px arial,sans-serif}html{background:#fff;color:#222;padding:15px}body{margin:7% auto 0;max-width:390px;min-height:180px;padding:30px 0 15px}* > body{background:url(//www.google.com/images/errors/robot.png) 100% 5px no-repeat;padding-right:205px}p{margin:11px 0 22px;overflow:hidden}ins{color:#777;text-decoration:none}a img{border:0}@media screen and (max-width:772px){body{background:none;margin-top:0;max-width:none;padding-right:0}}#logo{background:url(//www.google.com/images/branding/googlelogo/1x/googlelogo_color_150x54dp.png) no-repeat;margin-left:-5px}@media only screen and (min-resolution:192dpi){#logo{background:url(//www.google.com/images/branding/googlelogo/2x/googlelogo_color_150x54dp.png) no-repeat 0% 0%/100% 100%;-moz-border-image:url(//www.google.com/images/branding/googlelogo/2x/googlelogo_color_150x54dp.png) 0}}@media only screen and (-webkit-min-device-pixel-ratio:2){#logo{background:url(//www.google.com/images/branding/googlelogo/2x/googlelogo_color_150x54dp.png) no-repeat;-webkit-background-size:100% 100%}}#logo{display:inline-block;height:54px;width:150px}\n  </style>\n  <a href=//www.google.com/><span id=logo aria-label=Google></span></a>\n  <p><b>404.</b> <ins>That\xe2\x80\x99s an error.</ins>\n  <p>The requested URL <code>/wandb-production.appspot.com/ada4321/DiffHPE/szgm6i37/conda-environment.yaml</code> was not found on this server.  <ins>That\xe2\x80\x99s all we know.</ins>\n'
2023-07-11 12:11:39,052 ERROR   wandb-upload_4:106728 [internal_api.py:upload_file():2192] upload_file exception https://storage.googleapis.com/wandb-production.appspot.com/ada4321/DiffHPE/szgm6i37/output.log?Expires=1689135098&GoogleAccessId=gorilla-files-url-signer-man%40wandb-production.iam.gserviceaccount.com&Signature=GJZob5XsI76GsVFPzy4F41Z3co5SYamS3HjtdCCuDRpiNbF1VoYQwObohy4FE%2F5Tal42P%2FfHA9ncu07s6ioxSlRs16gbAbE1O9SYzagryMBWggVaXax7GiCcZpQ6n70tZReqTLU8C6ZF%2FMh40JPNHKPY%2FCnFmeMH4uLCV35IigJdqPGQzaU3M2BfmI1u%2B3DV7cIMUl8sl8fRhxp54%2F3J%2BSkXZTjRtjU0x%2FwEcK3KQQ731N2viv7YDzVxwx0niXQ0phAECPsrA7z40MupAIp%2FlG4P09pjEdgfKQDi3jsNE7ZN%2F7tbSa5KPwrbGyR0V3pVd%2F%2F6oh298QYU0SfBgW8o1Q%3D%3D: 404 Client Error: Not Found for url: https://storage.googleapis.com/wandb-production.appspot.com/ada4321/DiffHPE/szgm6i37/output.log?Expires=1689135098&GoogleAccessId=gorilla-files-url-signer-man%40wandb-production.iam.gserviceaccount.com&Signature=GJZob5XsI76GsVFPzy4F41Z3co5SYamS3HjtdCCuDRpiNbF1VoYQwObohy4FE%2F5Tal42P%2FfHA9ncu07s6ioxSlRs16gbAbE1O9SYzagryMBWggVaXax7GiCcZpQ6n70tZReqTLU8C6ZF%2FMh40JPNHKPY%2FCnFmeMH4uLCV35IigJdqPGQzaU3M2BfmI1u%2B3DV7cIMUl8sl8fRhxp54%2F3J%2BSkXZTjRtjU0x%2FwEcK3KQQ731N2viv7YDzVxwx0niXQ0phAECPsrA7z40MupAIp%2FlG4P09pjEdgfKQDi3jsNE7ZN%2F7tbSa5KPwrbGyR0V3pVd%2F%2F6oh298QYU0SfBgW8o1Q%3D%3D
2023-07-11 12:11:39,052 ERROR   wandb-upload_4:106728 [internal_api.py:upload_file():2194] upload_file request headers: {'User-Agent': 'python-requests/2.31.0', 'Accept-Encoding': 'gzip, deflate', 'Accept': '*/*', 'Connection': 'keep-alive', 'Content-Length': '26408'}
2023-07-11 12:11:39,052 ERROR   wandb-upload_4:106728 [internal_api.py:upload_file():2196] upload_file response body: b'<!DOCTYPE html>\n<html lang=en>\n  <meta charset=utf-8>\n  <meta name=viewport content="initial-scale=1, minimum-scale=1, width=device-width">\n  <title>Error 404 (Not Found)!!1</title>\n  <style>\n    *{margin:0;padding:0}html,code{font:15px/22px arial,sans-serif}html{background:#fff;color:#222;padding:15px}body{margin:7% auto 0;max-width:390px;min-height:180px;padding:30px 0 15px}* > body{background:url(//www.google.com/images/errors/robot.png) 100% 5px no-repeat;padding-right:205px}p{margin:11px 0 22px;overflow:hidden}ins{color:#777;text-decoration:none}a img{border:0}@media screen and (max-width:772px){body{background:none;margin-top:0;max-width:none;padding-right:0}}#logo{background:url(//www.google.com/images/branding/googlelogo/1x/googlelogo_color_150x54dp.png) no-repeat;margin-left:-5px}@media only screen and (min-resolution:192dpi){#logo{background:url(//www.google.com/images/branding/googlelogo/2x/googlelogo_color_150x54dp.png) no-repeat 0% 0%/100% 100%;-moz-border-image:url(//www.google.com/images/branding/googlelogo/2x/googlelogo_color_150x54dp.png) 0}}@media only screen and (-webkit-min-device-pixel-ratio:2){#logo{background:url(//www.google.com/images/branding/googlelogo/2x/googlelogo_color_150x54dp.png) no-repeat;-webkit-background-size:100% 100%}}#logo{display:inline-block;height:54px;width:150px}\n  </style>\n  <a href=//www.google.com/><span id=logo aria-label=Google></span></a>\n  <p><b>404.</b> <ins>That\xe2\x80\x99s an error.</ins>\n  <p>The requested URL <code>/wandb-production.appspot.com/ada4321/DiffHPE/szgm6i37/output.log</code> was not found on this server.  <ins>That\xe2\x80\x99s all we know.</ins>\n'
2023-07-11 12:11:39,747 ERROR   wandb-upload_1:106728 [upload_job.py:push():136] Failed to upload file: /home/zhuhe/HPE-with-Diffusion/wandb/run-20230711_121113-szgm6i37/files/requirements.txt
Traceback (most recent call last):
  File "/home/zhuhe/.conda/envs/diffhpe/lib/python3.9/site-packages/wandb/apis/normalize.py", line 41, in wrapper
    return func(*args, **kwargs)
  File "/home/zhuhe/.conda/envs/diffhpe/lib/python3.9/site-packages/wandb/sdk/lib/retry.py", line 212, in wrapped_fn
    return retrier(*args, **kargs)
  File "/home/zhuhe/.conda/envs/diffhpe/lib/python3.9/site-packages/wandb/sdk/lib/retry.py", line 131, in __call__
    result = self._call_fn(*args, **kwargs)
  File "/home/zhuhe/.conda/envs/diffhpe/lib/python3.9/site-packages/wandb/sdk/internal/internal_api.py", line 2218, in upload_file
    wandb._sentry.reraise(e)
  File "/home/zhuhe/.conda/envs/diffhpe/lib/python3.9/site-packages/wandb/analytics/sentry.py", line 146, in reraise
    raise exc.with_traceback(sys.exc_info()[2])
  File "/home/zhuhe/.conda/envs/diffhpe/lib/python3.9/site-packages/wandb/sdk/internal/internal_api.py", line 2190, in upload_file
    response.raise_for_status()
  File "/home/zhuhe/.conda/envs/diffhpe/lib/python3.9/site-packages/requests/models.py", line 1021, in raise_for_status
    raise HTTPError(http_error_msg, response=self)
requests.exceptions.HTTPError: 404 Client Error: Not Found for url: https://storage.googleapis.com/wandb-production.appspot.com/ada4321/DiffHPE/szgm6i37/requirements.txt?Expires=1689135098&GoogleAccessId=gorilla-files-url-signer-man%40wandb-production.iam.gserviceaccount.com&Signature=uAzZlyhw8HMzsGtG5rjVEp1nwFfKfDkVZoklYmD5OQ0AXDEQdPlSzFhWco4q038ze2TxBZ%2F6jrh4qSLdcVHmg2ob0mziAZwbmM0wkiBXiSOHuKrJFNSjQSOxnLpKxbwGHo1dSlAw%2B%2F3%2BzLCx%2BNsdjKHQMg%2F0B4U%2ByoTQmRaCkMeeqMYQKuG6aJG4zf5gP9DlNWZzBLRhZ98Uy0mpgRpjztvgHg0Ppi48rGEBpxdY3ixSEsRB0x%2BnqYz90A%2Ffs9qt3Nz8DTq0dat3ejYOz5OBwN4joTgZ0CGW6df5G9NMISap6Z7nUaS6Bz4mWwJEjIk4Nut39Yalc0sM7csmt%2FIUJg%3D%3D

During handling of the above exception, another exception occurred:

Traceback (most recent call last):
  File "/home/zhuhe/.conda/envs/diffhpe/lib/python3.9/site-packages/wandb/filesync/upload_job.py", line 127, in push
    self._api.upload_file_retry(
  File "/home/zhuhe/.conda/envs/diffhpe/lib/python3.9/site-packages/wandb/apis/normalize.py", line 51, in wrapper
    raise CommError(message, error)
wandb.errors.CommError: <Response [404]>
2023-07-11 12:11:39,747 ERROR   wandb-upload_0:106728 [upload_job.py:push():136] Failed to upload file: /home/zhuhe/HPE-with-Diffusion/wandb/run-20230711_121113-szgm6i37/files/config.yaml
Traceback (most recent call last):
  File "/home/zhuhe/.conda/envs/diffhpe/lib/python3.9/site-packages/wandb/apis/normalize.py", line 41, in wrapper
    return func(*args, **kwargs)
  File "/home/zhuhe/.conda/envs/diffhpe/lib/python3.9/site-packages/wandb/sdk/lib/retry.py", line 212, in wrapped_fn
    return retrier(*args, **kargs)
  File "/home/zhuhe/.conda/envs/diffhpe/lib/python3.9/site-packages/wandb/sdk/lib/retry.py", line 131, in __call__
    result = self._call_fn(*args, **kwargs)
  File "/home/zhuhe/.conda/envs/diffhpe/lib/python3.9/site-packages/wandb/sdk/internal/internal_api.py", line 2218, in upload_file
    wandb._sentry.reraise(e)
  File "/home/zhuhe/.conda/envs/diffhpe/lib/python3.9/site-packages/wandb/analytics/sentry.py", line 146, in reraise
    raise exc.with_traceback(sys.exc_info()[2])
  File "/home/zhuhe/.conda/envs/diffhpe/lib/python3.9/site-packages/wandb/sdk/internal/internal_api.py", line 2190, in upload_file
    response.raise_for_status()
  File "/home/zhuhe/.conda/envs/diffhpe/lib/python3.9/site-packages/requests/models.py", line 1021, in raise_for_status
    raise HTTPError(http_error_msg, response=self)
requests.exceptions.HTTPError: 404 Client Error: Not Found for url: https://storage.googleapis.com/wandb-production.appspot.com/ada4321/DiffHPE/szgm6i37/config.yaml?Expires=1689135098&GoogleAccessId=gorilla-files-url-signer-man%40wandb-production.iam.gserviceaccount.com&Signature=M%2BZimABLPmyqi%2BC%2FhlCd%2FVGEI%2FRE6RYXCOAgJr%2F3g%2BggOvQjL6zZQwPdSUgms%2F0FzNL8Gmc5Mdx9uwfdgsZeHGwIoTQBSUFZ%2B9tkkHizKSEI1eLLFQznlTTQnFK7t80CBRRDJgASuf0HajxhdilIYowSkWzsd78DEr8j%2FrWnT5kvES3b57tdZc36lyZqDWJjbeO7kKWbgpZ15E4PyIOOe1tZpItVwriKWOVFL8w2RGnLjQKBJ9yDp8rp3WBUxcz%2BSRvSr4QEQmmGorNI66NVOsuOWGfFBLqQUrZBNalkkcchaHZ2DW22Ud9VGaDWl%2B3w1njZyDVeaFYRmFO5JdNtfQ%3D%3D

During handling of the above exception, another exception occurred:

Traceback (most recent call last):
  File "/home/zhuhe/.conda/envs/diffhpe/lib/python3.9/site-packages/wandb/filesync/upload_job.py", line 127, in push
    self._api.upload_file_retry(
  File "/home/zhuhe/.conda/envs/diffhpe/lib/python3.9/site-packages/wandb/apis/normalize.py", line 51, in wrapper
    raise CommError(message, error)
wandb.errors.CommError: <Response [404]>
2023-07-11 12:11:39,748 ERROR   wandb-upload_2:106728 [upload_job.py:push():136] Failed to upload file: /home/zhuhe/HPE-with-Diffusion/wandb/run-20230711_121113-szgm6i37/files/wandb-summary.json
Traceback (most recent call last):
  File "/home/zhuhe/.conda/envs/diffhpe/lib/python3.9/site-packages/wandb/apis/normalize.py", line 41, in wrapper
    return func(*args, **kwargs)
  File "/home/zhuhe/.conda/envs/diffhpe/lib/python3.9/site-packages/wandb/sdk/lib/retry.py", line 212, in wrapped_fn
    return retrier(*args, **kargs)
  File "/home/zhuhe/.conda/envs/diffhpe/lib/python3.9/site-packages/wandb/sdk/lib/retry.py", line 131, in __call__
    result = self._call_fn(*args, **kwargs)
  File "/home/zhuhe/.conda/envs/diffhpe/lib/python3.9/site-packages/wandb/sdk/internal/internal_api.py", line 2218, in upload_file
    wandb._sentry.reraise(e)
  File "/home/zhuhe/.conda/envs/diffhpe/lib/python3.9/site-packages/wandb/analytics/sentry.py", line 146, in reraise
    raise exc.with_traceback(sys.exc_info()[2])
  File "/home/zhuhe/.conda/envs/diffhpe/lib/python3.9/site-packages/wandb/sdk/internal/internal_api.py", line 2190, in upload_file
    response.raise_for_status()
  File "/home/zhuhe/.conda/envs/diffhpe/lib/python3.9/site-packages/requests/models.py", line 1021, in raise_for_status
    raise HTTPError(http_error_msg, response=self)
requests.exceptions.HTTPError: 404 Client Error: Not Found for url: https://storage.googleapis.com/wandb-production.appspot.com/ada4321/DiffHPE/szgm6i37/wandb-summary.json?Expires=1689135098&GoogleAccessId=gorilla-files-url-signer-man%40wandb-production.iam.gserviceaccount.com&Signature=JePoCqrqTRzVn9ClCnYD2Jzsyya1yj61EgUHYcGTxokM%2FMd0bJJsTaBDEcPagmzt1%2BXDuvjfO4lM87vXMPwTpLRBWVoCunaq4j%2BiGymXJwKq7P%2F%2B6IYok0PEPeOIeEJPIU5ifNkuXr8Eyc0RYwH9eA227Cspw%2BYVLvcfAP%2F63ibLUtc3KDNFglmKvHN0B8jK9iMt%2B7T8vFVjqmDQtYex2J%2BYAdtgbE1ROl%2Fnyo15l7lMejTFQrH0RFHlmBXvseCGojeuEn8rSYGDVGanj%2FFc8VhdvFDYPfbUfwy2BoIwvuUvthgVy4Q5agyghCsWw8nrkeloZNvfRq9g1e8uQ%2FObKQ%3D%3D

During handling of the above exception, another exception occurred:

Traceback (most recent call last):
  File "/home/zhuhe/.conda/envs/diffhpe/lib/python3.9/site-packages/wandb/filesync/upload_job.py", line 127, in push
    self._api.upload_file_retry(
  File "/home/zhuhe/.conda/envs/diffhpe/lib/python3.9/site-packages/wandb/apis/normalize.py", line 51, in wrapper
    raise CommError(message, error)
wandb.errors.CommError: <Response [404]>
2023-07-11 12:11:39,749 ERROR   wandb-upload_3:106728 [upload_job.py:push():136] Failed to upload file: /home/zhuhe/HPE-with-Diffusion/wandb/run-20230711_121113-szgm6i37/files/conda-environment.yaml
Traceback (most recent call last):
  File "/home/zhuhe/.conda/envs/diffhpe/lib/python3.9/site-packages/wandb/apis/normalize.py", line 41, in wrapper
    return func(*args, **kwargs)
  File "/home/zhuhe/.conda/envs/diffhpe/lib/python3.9/site-packages/wandb/sdk/lib/retry.py", line 212, in wrapped_fn
    return retrier(*args, **kargs)
  File "/home/zhuhe/.conda/envs/diffhpe/lib/python3.9/site-packages/wandb/sdk/lib/retry.py", line 131, in __call__
    result = self._call_fn(*args, **kwargs)
  File "/home/zhuhe/.conda/envs/diffhpe/lib/python3.9/site-packages/wandb/sdk/internal/internal_api.py", line 2218, in upload_file
    wandb._sentry.reraise(e)
  File "/home/zhuhe/.conda/envs/diffhpe/lib/python3.9/site-packages/wandb/analytics/sentry.py", line 146, in reraise
    raise exc.with_traceback(sys.exc_info()[2])
  File "/home/zhuhe/.conda/envs/diffhpe/lib/python3.9/site-packages/wandb/sdk/internal/internal_api.py", line 2190, in upload_file
    response.raise_for_status()
  File "/home/zhuhe/.conda/envs/diffhpe/lib/python3.9/site-packages/requests/models.py", line 1021, in raise_for_status
    raise HTTPError(http_error_msg, response=self)
requests.exceptions.HTTPError: 404 Client Error: Not Found for url: https://storage.googleapis.com/wandb-production.appspot.com/ada4321/DiffHPE/szgm6i37/conda-environment.yaml?Expires=1689135098&GoogleAccessId=gorilla-files-url-signer-man%40wandb-production.iam.gserviceaccount.com&Signature=mCO1hK95AjrgwNaGCDtDvZrZByBTDFuZHT7ZUCQoehgatini5t4WsbHJB1CRkAdMX5xGYYkFaG1TwuSVObP51%2FYGHiSSJp2dGrmMIE9Ulq8xOB%2Fs32SRXfWseRDXWIgGsdgbHvMKd12dFFKwO6K61MJKPChgeX6taL%2FFVueBmHiCb1UBd%2BzkAP%2FTDfXvtQADt8Tcl2EufQsHQQUMpv58WP03QxSxHVVS3ib08lkpJFhXU7tJpJ5jbSoF9glb4zCBfojhNHXMdtR3QMTwkYAvMVODx6vyBbljBtPKbHIy3jLWn46gOdlh0qYk61RJadMGlc%2BYjAQB2NkA1RXnFoCPdQ%3D%3D

During handling of the above exception, another exception occurred:

Traceback (most recent call last):
  File "/home/zhuhe/.conda/envs/diffhpe/lib/python3.9/site-packages/wandb/filesync/upload_job.py", line 127, in push
    self._api.upload_file_retry(
  File "/home/zhuhe/.conda/envs/diffhpe/lib/python3.9/site-packages/wandb/apis/normalize.py", line 51, in wrapper
    raise CommError(message, error)
wandb.errors.CommError: <Response [404]>
2023-07-11 12:11:39,749 ERROR   wandb-upload_4:106728 [upload_job.py:push():136] Failed to upload file: /home/zhuhe/HPE-with-Diffusion/wandb/run-20230711_121113-szgm6i37/files/output.log
Traceback (most recent call last):
  File "/home/zhuhe/.conda/envs/diffhpe/lib/python3.9/site-packages/wandb/apis/normalize.py", line 41, in wrapper
    return func(*args, **kwargs)
  File "/home/zhuhe/.conda/envs/diffhpe/lib/python3.9/site-packages/wandb/sdk/lib/retry.py", line 212, in wrapped_fn
    return retrier(*args, **kargs)
  File "/home/zhuhe/.conda/envs/diffhpe/lib/python3.9/site-packages/wandb/sdk/lib/retry.py", line 131, in __call__
    result = self._call_fn(*args, **kwargs)
  File "/home/zhuhe/.conda/envs/diffhpe/lib/python3.9/site-packages/wandb/sdk/internal/internal_api.py", line 2218, in upload_file
    wandb._sentry.reraise(e)
  File "/home/zhuhe/.conda/envs/diffhpe/lib/python3.9/site-packages/wandb/analytics/sentry.py", line 146, in reraise
    raise exc.with_traceback(sys.exc_info()[2])
  File "/home/zhuhe/.conda/envs/diffhpe/lib/python3.9/site-packages/wandb/sdk/internal/internal_api.py", line 2190, in upload_file
    response.raise_for_status()
  File "/home/zhuhe/.conda/envs/diffhpe/lib/python3.9/site-packages/requests/models.py", line 1021, in raise_for_status
    raise HTTPError(http_error_msg, response=self)
requests.exceptions.HTTPError: 404 Client Error: Not Found for url: https://storage.googleapis.com/wandb-production.appspot.com/ada4321/DiffHPE/szgm6i37/output.log?Expires=1689135098&GoogleAccessId=gorilla-files-url-signer-man%40wandb-production.iam.gserviceaccount.com&Signature=GJZob5XsI76GsVFPzy4F41Z3co5SYamS3HjtdCCuDRpiNbF1VoYQwObohy4FE%2F5Tal42P%2FfHA9ncu07s6ioxSlRs16gbAbE1O9SYzagryMBWggVaXax7GiCcZpQ6n70tZReqTLU8C6ZF%2FMh40JPNHKPY%2FCnFmeMH4uLCV35IigJdqPGQzaU3M2BfmI1u%2B3DV7cIMUl8sl8fRhxp54%2F3J%2BSkXZTjRtjU0x%2FwEcK3KQQ731N2viv7YDzVxwx0niXQ0phAECPsrA7z40MupAIp%2FlG4P09pjEdgfKQDi3jsNE7ZN%2F7tbSa5KPwrbGyR0V3pVd%2F%2F6oh298QYU0SfBgW8o1Q%3D%3D

During handling of the above exception, another exception occurred:

Traceback (most recent call last):
  File "/home/zhuhe/.conda/envs/diffhpe/lib/python3.9/site-packages/wandb/filesync/upload_job.py", line 127, in push
    self._api.upload_file_retry(
  File "/home/zhuhe/.conda/envs/diffhpe/lib/python3.9/site-packages/wandb/apis/normalize.py", line 51, in wrapper
    raise CommError(message, error)
wandb.errors.CommError: <Response [404]>
2023-07-11 12:11:40,817 ERROR   Thread-11 :106728 [step_upload.py:_handle_event():200] Failed to upload file: /home/zhuhe/HPE-with-Diffusion/wandb/run-20230711_121113-szgm6i37/files/requirements.txt
Traceback (most recent call last):
  File "/home/zhuhe/.conda/envs/diffhpe/lib/python3.9/site-packages/wandb/apis/normalize.py", line 41, in wrapper
    return func(*args, **kwargs)
  File "/home/zhuhe/.conda/envs/diffhpe/lib/python3.9/site-packages/wandb/sdk/lib/retry.py", line 212, in wrapped_fn
    return retrier(*args, **kargs)
  File "/home/zhuhe/.conda/envs/diffhpe/lib/python3.9/site-packages/wandb/sdk/lib/retry.py", line 131, in __call__
    result = self._call_fn(*args, **kwargs)
  File "/home/zhuhe/.conda/envs/diffhpe/lib/python3.9/site-packages/wandb/sdk/internal/internal_api.py", line 2218, in upload_file
    wandb._sentry.reraise(e)
  File "/home/zhuhe/.conda/envs/diffhpe/lib/python3.9/site-packages/wandb/analytics/sentry.py", line 146, in reraise
    raise exc.with_traceback(sys.exc_info()[2])
  File "/home/zhuhe/.conda/envs/diffhpe/lib/python3.9/site-packages/wandb/sdk/internal/internal_api.py", line 2190, in upload_file
    response.raise_for_status()
  File "/home/zhuhe/.conda/envs/diffhpe/lib/python3.9/site-packages/requests/models.py", line 1021, in raise_for_status
    raise HTTPError(http_error_msg, response=self)
requests.exceptions.HTTPError: 404 Client Error: Not Found for url: https://storage.googleapis.com/wandb-production.appspot.com/ada4321/DiffHPE/szgm6i37/requirements.txt?Expires=1689135098&GoogleAccessId=gorilla-files-url-signer-man%40wandb-production.iam.gserviceaccount.com&Signature=uAzZlyhw8HMzsGtG5rjVEp1nwFfKfDkVZoklYmD5OQ0AXDEQdPlSzFhWco4q038ze2TxBZ%2F6jrh4qSLdcVHmg2ob0mziAZwbmM0wkiBXiSOHuKrJFNSjQSOxnLpKxbwGHo1dSlAw%2B%2F3%2BzLCx%2BNsdjKHQMg%2F0B4U%2ByoTQmRaCkMeeqMYQKuG6aJG4zf5gP9DlNWZzBLRhZ98Uy0mpgRpjztvgHg0Ppi48rGEBpxdY3ixSEsRB0x%2BnqYz90A%2Ffs9qt3Nz8DTq0dat3ejYOz5OBwN4joTgZ0CGW6df5G9NMISap6Z7nUaS6Bz4mWwJEjIk4Nut39Yalc0sM7csmt%2FIUJg%3D%3D

During handling of the above exception, another exception occurred:

Traceback (most recent call last):
  File "/home/zhuhe/.conda/envs/diffhpe/lib/python3.9/concurrent/futures/thread.py", line 58, in run
    result = self.fn(*self.args, **self.kwargs)
  File "/home/zhuhe/.conda/envs/diffhpe/lib/python3.9/site-packages/wandb/filesync/step_upload.py", line 288, in run_and_notify
    self._do_upload_sync(event)
  File "/home/zhuhe/.conda/envs/diffhpe/lib/python3.9/site-packages/wandb/filesync/step_upload.py", line 330, in _do_upload_sync
    job.run()
  File "/home/zhuhe/.conda/envs/diffhpe/lib/python3.9/site-packages/wandb/filesync/upload_job.py", line 57, in run
    self.push()
  File "/home/zhuhe/.conda/envs/diffhpe/lib/python3.9/site-packages/wandb/filesync/upload_job.py", line 127, in push
    self._api.upload_file_retry(
  File "/home/zhuhe/.conda/envs/diffhpe/lib/python3.9/site-packages/wandb/apis/normalize.py", line 51, in wrapper
    raise CommError(message, error)
wandb.errors.CommError: <Response [404]>
2023-07-11 12:11:40,818 ERROR   Thread-11 :106728 [step_upload.py:_handle_event():200] Failed to upload file: /home/zhuhe/HPE-with-Diffusion/wandb/run-20230711_121113-szgm6i37/files/config.yaml
Traceback (most recent call last):
  File "/home/zhuhe/.conda/envs/diffhpe/lib/python3.9/site-packages/wandb/apis/normalize.py", line 41, in wrapper
    return func(*args, **kwargs)
  File "/home/zhuhe/.conda/envs/diffhpe/lib/python3.9/site-packages/wandb/sdk/lib/retry.py", line 212, in wrapped_fn
    return retrier(*args, **kargs)
  File "/home/zhuhe/.conda/envs/diffhpe/lib/python3.9/site-packages/wandb/sdk/lib/retry.py", line 131, in __call__
    result = self._call_fn(*args, **kwargs)
  File "/home/zhuhe/.conda/envs/diffhpe/lib/python3.9/site-packages/wandb/sdk/internal/internal_api.py", line 2218, in upload_file
    wandb._sentry.reraise(e)
  File "/home/zhuhe/.conda/envs/diffhpe/lib/python3.9/site-packages/wandb/analytics/sentry.py", line 146, in reraise
    raise exc.with_traceback(sys.exc_info()[2])
  File "/home/zhuhe/.conda/envs/diffhpe/lib/python3.9/site-packages/wandb/sdk/internal/internal_api.py", line 2190, in upload_file
    response.raise_for_status()
  File "/home/zhuhe/.conda/envs/diffhpe/lib/python3.9/site-packages/requests/models.py", line 1021, in raise_for_status
    raise HTTPError(http_error_msg, response=self)
requests.exceptions.HTTPError: 404 Client Error: Not Found for url: https://storage.googleapis.com/wandb-production.appspot.com/ada4321/DiffHPE/szgm6i37/config.yaml?Expires=1689135098&GoogleAccessId=gorilla-files-url-signer-man%40wandb-production.iam.gserviceaccount.com&Signature=M%2BZimABLPmyqi%2BC%2FhlCd%2FVGEI%2FRE6RYXCOAgJr%2F3g%2BggOvQjL6zZQwPdSUgms%2F0FzNL8Gmc5Mdx9uwfdgsZeHGwIoTQBSUFZ%2B9tkkHizKSEI1eLLFQznlTTQnFK7t80CBRRDJgASuf0HajxhdilIYowSkWzsd78DEr8j%2FrWnT5kvES3b57tdZc36lyZqDWJjbeO7kKWbgpZ15E4PyIOOe1tZpItVwriKWOVFL8w2RGnLjQKBJ9yDp8rp3WBUxcz%2BSRvSr4QEQmmGorNI66NVOsuOWGfFBLqQUrZBNalkkcchaHZ2DW22Ud9VGaDWl%2B3w1njZyDVeaFYRmFO5JdNtfQ%3D%3D

During handling of the above exception, another exception occurred:

Traceback (most recent call last):
  File "/home/zhuhe/.conda/envs/diffhpe/lib/python3.9/concurrent/futures/thread.py", line 58, in run
    result = self.fn(*self.args, **self.kwargs)
  File "/home/zhuhe/.conda/envs/diffhpe/lib/python3.9/site-packages/wandb/filesync/step_upload.py", line 288, in run_and_notify
    self._do_upload_sync(event)
  File "/home/zhuhe/.conda/envs/diffhpe/lib/python3.9/site-packages/wandb/filesync/step_upload.py", line 330, in _do_upload_sync
    job.run()
  File "/home/zhuhe/.conda/envs/diffhpe/lib/python3.9/site-packages/wandb/filesync/upload_job.py", line 57, in run
    self.push()
  File "/home/zhuhe/.conda/envs/diffhpe/lib/python3.9/site-packages/wandb/filesync/upload_job.py", line 127, in push
    self._api.upload_file_retry(
  File "/home/zhuhe/.conda/envs/diffhpe/lib/python3.9/site-packages/wandb/apis/normalize.py", line 51, in wrapper
    raise CommError(message, error)
wandb.errors.CommError: <Response [404]>
2023-07-11 12:11:40,818 ERROR   Thread-11 :106728 [step_upload.py:_handle_event():200] Failed to upload file: /home/zhuhe/HPE-with-Diffusion/wandb/run-20230711_121113-szgm6i37/files/wandb-summary.json
Traceback (most recent call last):
  File "/home/zhuhe/.conda/envs/diffhpe/lib/python3.9/site-packages/wandb/apis/normalize.py", line 41, in wrapper
    return func(*args, **kwargs)
  File "/home/zhuhe/.conda/envs/diffhpe/lib/python3.9/site-packages/wandb/sdk/lib/retry.py", line 212, in wrapped_fn
    return retrier(*args, **kargs)
  File "/home/zhuhe/.conda/envs/diffhpe/lib/python3.9/site-packages/wandb/sdk/lib/retry.py", line 131, in __call__
    result = self._call_fn(*args, **kwargs)
  File "/home/zhuhe/.conda/envs/diffhpe/lib/python3.9/site-packages/wandb/sdk/internal/internal_api.py", line 2218, in upload_file
    wandb._sentry.reraise(e)
  File "/home/zhuhe/.conda/envs/diffhpe/lib/python3.9/site-packages/wandb/analytics/sentry.py", line 146, in reraise
    raise exc.with_traceback(sys.exc_info()[2])
  File "/home/zhuhe/.conda/envs/diffhpe/lib/python3.9/site-packages/wandb/sdk/internal/internal_api.py", line 2190, in upload_file
    response.raise_for_status()
  File "/home/zhuhe/.conda/envs/diffhpe/lib/python3.9/site-packages/requests/models.py", line 1021, in raise_for_status
    raise HTTPError(http_error_msg, response=self)
requests.exceptions.HTTPError: 404 Client Error: Not Found for url: https://storage.googleapis.com/wandb-production.appspot.com/ada4321/DiffHPE/szgm6i37/wandb-summary.json?Expires=1689135098&GoogleAccessId=gorilla-files-url-signer-man%40wandb-production.iam.gserviceaccount.com&Signature=JePoCqrqTRzVn9ClCnYD2Jzsyya1yj61EgUHYcGTxokM%2FMd0bJJsTaBDEcPagmzt1%2BXDuvjfO4lM87vXMPwTpLRBWVoCunaq4j%2BiGymXJwKq7P%2F%2B6IYok0PEPeOIeEJPIU5ifNkuXr8Eyc0RYwH9eA227Cspw%2BYVLvcfAP%2F63ibLUtc3KDNFglmKvHN0B8jK9iMt%2B7T8vFVjqmDQtYex2J%2BYAdtgbE1ROl%2Fnyo15l7lMejTFQrH0RFHlmBXvseCGojeuEn8rSYGDVGanj%2FFc8VhdvFDYPfbUfwy2BoIwvuUvthgVy4Q5agyghCsWw8nrkeloZNvfRq9g1e8uQ%2FObKQ%3D%3D

During handling of the above exception, another exception occurred:

Traceback (most recent call last):
  File "/home/zhuhe/.conda/envs/diffhpe/lib/python3.9/concurrent/futures/thread.py", line 58, in run
    result = self.fn(*self.args, **self.kwargs)
  File "/home/zhuhe/.conda/envs/diffhpe/lib/python3.9/site-packages/wandb/filesync/step_upload.py", line 288, in run_and_notify
    self._do_upload_sync(event)
  File "/home/zhuhe/.conda/envs/diffhpe/lib/python3.9/site-packages/wandb/filesync/step_upload.py", line 330, in _do_upload_sync
    job.run()
  File "/home/zhuhe/.conda/envs/diffhpe/lib/python3.9/site-packages/wandb/filesync/upload_job.py", line 57, in run
    self.push()
  File "/home/zhuhe/.conda/envs/diffhpe/lib/python3.9/site-packages/wandb/filesync/upload_job.py", line 127, in push
    self._api.upload_file_retry(
  File "/home/zhuhe/.conda/envs/diffhpe/lib/python3.9/site-packages/wandb/apis/normalize.py", line 51, in wrapper
    raise CommError(message, error)
wandb.errors.CommError: <Response [404]>
2023-07-11 12:11:40,818 ERROR   Thread-11 :106728 [step_upload.py:_handle_event():200] Failed to upload file: /home/zhuhe/HPE-with-Diffusion/wandb/run-20230711_121113-szgm6i37/files/conda-environment.yaml
Traceback (most recent call last):
  File "/home/zhuhe/.conda/envs/diffhpe/lib/python3.9/site-packages/wandb/apis/normalize.py", line 41, in wrapper
    return func(*args, **kwargs)
  File "/home/zhuhe/.conda/envs/diffhpe/lib/python3.9/site-packages/wandb/sdk/lib/retry.py", line 212, in wrapped_fn
    return retrier(*args, **kargs)
  File "/home/zhuhe/.conda/envs/diffhpe/lib/python3.9/site-packages/wandb/sdk/lib/retry.py", line 131, in __call__
    result = self._call_fn(*args, **kwargs)
  File "/home/zhuhe/.conda/envs/diffhpe/lib/python3.9/site-packages/wandb/sdk/internal/internal_api.py", line 2218, in upload_file
    wandb._sentry.reraise(e)
  File "/home/zhuhe/.conda/envs/diffhpe/lib/python3.9/site-packages/wandb/analytics/sentry.py", line 146, in reraise
    raise exc.with_traceback(sys.exc_info()[2])
  File "/home/zhuhe/.conda/envs/diffhpe/lib/python3.9/site-packages/wandb/sdk/internal/internal_api.py", line 2190, in upload_file
    response.raise_for_status()
  File "/home/zhuhe/.conda/envs/diffhpe/lib/python3.9/site-packages/requests/models.py", line 1021, in raise_for_status
    raise HTTPError(http_error_msg, response=self)
requests.exceptions.HTTPError: 404 Client Error: Not Found for url: https://storage.googleapis.com/wandb-production.appspot.com/ada4321/DiffHPE/szgm6i37/conda-environment.yaml?Expires=1689135098&GoogleAccessId=gorilla-files-url-signer-man%40wandb-production.iam.gserviceaccount.com&Signature=mCO1hK95AjrgwNaGCDtDvZrZByBTDFuZHT7ZUCQoehgatini5t4WsbHJB1CRkAdMX5xGYYkFaG1TwuSVObP51%2FYGHiSSJp2dGrmMIE9Ulq8xOB%2Fs32SRXfWseRDXWIgGsdgbHvMKd12dFFKwO6K61MJKPChgeX6taL%2FFVueBmHiCb1UBd%2BzkAP%2FTDfXvtQADt8Tcl2EufQsHQQUMpv58WP03QxSxHVVS3ib08lkpJFhXU7tJpJ5jbSoF9glb4zCBfojhNHXMdtR3QMTwkYAvMVODx6vyBbljBtPKbHIy3jLWn46gOdlh0qYk61RJadMGlc%2BYjAQB2NkA1RXnFoCPdQ%3D%3D

During handling of the above exception, another exception occurred:

Traceback (most recent call last):
  File "/home/zhuhe/.conda/envs/diffhpe/lib/python3.9/concurrent/futures/thread.py", line 58, in run
    result = self.fn(*self.args, **self.kwargs)
  File "/home/zhuhe/.conda/envs/diffhpe/lib/python3.9/site-packages/wandb/filesync/step_upload.py", line 288, in run_and_notify
    self._do_upload_sync(event)
  File "/home/zhuhe/.conda/envs/diffhpe/lib/python3.9/site-packages/wandb/filesync/step_upload.py", line 330, in _do_upload_sync
    job.run()
  File "/home/zhuhe/.conda/envs/diffhpe/lib/python3.9/site-packages/wandb/filesync/upload_job.py", line 57, in run
    self.push()
  File "/home/zhuhe/.conda/envs/diffhpe/lib/python3.9/site-packages/wandb/filesync/upload_job.py", line 127, in push
    self._api.upload_file_retry(
  File "/home/zhuhe/.conda/envs/diffhpe/lib/python3.9/site-packages/wandb/apis/normalize.py", line 51, in wrapper
    raise CommError(message, error)
wandb.errors.CommError: <Response [404]>
2023-07-11 12:11:40,818 ERROR   Thread-11 :106728 [step_upload.py:_handle_event():200] Failed to upload file: /home/zhuhe/HPE-with-Diffusion/wandb/run-20230711_121113-szgm6i37/files/output.log
Traceback (most recent call last):
  File "/home/zhuhe/.conda/envs/diffhpe/lib/python3.9/site-packages/wandb/apis/normalize.py", line 41, in wrapper
    return func(*args, **kwargs)
  File "/home/zhuhe/.conda/envs/diffhpe/lib/python3.9/site-packages/wandb/sdk/lib/retry.py", line 212, in wrapped_fn
    return retrier(*args, **kargs)
  File "/home/zhuhe/.conda/envs/diffhpe/lib/python3.9/site-packages/wandb/sdk/lib/retry.py", line 131, in __call__
    result = self._call_fn(*args, **kwargs)
  File "/home/zhuhe/.conda/envs/diffhpe/lib/python3.9/site-packages/wandb/sdk/internal/internal_api.py", line 2218, in upload_file
    wandb._sentry.reraise(e)
  File "/home/zhuhe/.conda/envs/diffhpe/lib/python3.9/site-packages/wandb/analytics/sentry.py", line 146, in reraise
    raise exc.with_traceback(sys.exc_info()[2])
  File "/home/zhuhe/.conda/envs/diffhpe/lib/python3.9/site-packages/wandb/sdk/internal/internal_api.py", line 2190, in upload_file
    response.raise_for_status()
  File "/home/zhuhe/.conda/envs/diffhpe/lib/python3.9/site-packages/requests/models.py", line 1021, in raise_for_status
    raise HTTPError(http_error_msg, response=self)
requests.exceptions.HTTPError: 404 Client Error: Not Found for url: https://storage.googleapis.com/wandb-production.appspot.com/ada4321/DiffHPE/szgm6i37/output.log?Expires=1689135098&GoogleAccessId=gorilla-files-url-signer-man%40wandb-production.iam.gserviceaccount.com&Signature=GJZob5XsI76GsVFPzy4F41Z3co5SYamS3HjtdCCuDRpiNbF1VoYQwObohy4FE%2F5Tal42P%2FfHA9ncu07s6ioxSlRs16gbAbE1O9SYzagryMBWggVaXax7GiCcZpQ6n70tZReqTLU8C6ZF%2FMh40JPNHKPY%2FCnFmeMH4uLCV35IigJdqPGQzaU3M2BfmI1u%2B3DV7cIMUl8sl8fRhxp54%2F3J%2BSkXZTjRtjU0x%2FwEcK3KQQ731N2viv7YDzVxwx0niXQ0phAECPsrA7z40MupAIp%2FlG4P09pjEdgfKQDi3jsNE7ZN%2F7tbSa5KPwrbGyR0V3pVd%2F%2F6oh298QYU0SfBgW8o1Q%3D%3D

During handling of the above exception, another exception occurred:

Traceback (most recent call last):
  File "/home/zhuhe/.conda/envs/diffhpe/lib/python3.9/concurrent/futures/thread.py", line 58, in run
    result = self.fn(*self.args, **self.kwargs)
  File "/home/zhuhe/.conda/envs/diffhpe/lib/python3.9/site-packages/wandb/filesync/step_upload.py", line 288, in run_and_notify
    self._do_upload_sync(event)
  File "/home/zhuhe/.conda/envs/diffhpe/lib/python3.9/site-packages/wandb/filesync/step_upload.py", line 330, in _do_upload_sync
    job.run()
  File "/home/zhuhe/.conda/envs/diffhpe/lib/python3.9/site-packages/wandb/filesync/upload_job.py", line 57, in run
    self.push()
  File "/home/zhuhe/.conda/envs/diffhpe/lib/python3.9/site-packages/wandb/filesync/upload_job.py", line 127, in push
    self._api.upload_file_retry(
  File "/home/zhuhe/.conda/envs/diffhpe/lib/python3.9/site-packages/wandb/apis/normalize.py", line 51, in wrapper
    raise CommError(message, error)
wandb.errors.CommError: <Response [404]>
2023-07-11 12:11:41,018 INFO    Thread-11 :106728 [sender.py:transition_state():602] send defer: 11
2023-07-11 12:11:41,018 DEBUG   HandlerThread:106728 [handler.py:handle_request():144] handle_request: defer
2023-07-11 12:11:41,019 INFO    HandlerThread:106728 [handler.py:handle_request_defer():170] handle defer: 11
2023-07-11 12:11:41,019 DEBUG   SenderThread:106728 [sender.py:send_request():396] send_request: defer
2023-07-11 12:11:41,019 INFO    SenderThread:106728 [sender.py:send_request_defer():598] handle sender defer: 11
2023-07-11 12:11:41,019 INFO    SenderThread:106728 [file_pusher.py:join():164] waiting for file pusher
2023-07-11 12:11:41,019 INFO    SenderThread:106728 [sender.py:transition_state():602] send defer: 12
2023-07-11 12:11:41,019 DEBUG   HandlerThread:106728 [handler.py:handle_request():144] handle_request: defer
2023-07-11 12:11:41,019 INFO    HandlerThread:106728 [handler.py:handle_request_defer():170] handle defer: 12
2023-07-11 12:11:41,019 DEBUG   SenderThread:106728 [sender.py:send_request():396] send_request: defer
2023-07-11 12:11:41,020 INFO    SenderThread:106728 [sender.py:send_request_defer():598] handle sender defer: 12
2023-07-11 12:11:41,193 DEBUG   HandlerThread:106728 [handler.py:handle_request():144] handle_request: keepalive
2023-07-11 12:11:41,312 INFO    SenderThread:106728 [sender.py:transition_state():602] send defer: 13
2023-07-11 12:11:41,312 DEBUG   HandlerThread:106728 [handler.py:handle_request():144] handle_request: defer
2023-07-11 12:11:41,312 INFO    HandlerThread:106728 [handler.py:handle_request_defer():170] handle defer: 13
2023-07-11 12:11:41,312 DEBUG   SenderThread:106728 [sender.py:send_request():396] send_request: defer
2023-07-11 12:11:41,312 INFO    SenderThread:106728 [sender.py:send_request_defer():598] handle sender defer: 13
2023-07-11 12:11:41,312 INFO    SenderThread:106728 [sender.py:transition_state():602] send defer: 14
2023-07-11 12:11:41,312 DEBUG   HandlerThread:106728 [handler.py:handle_request():144] handle_request: defer
2023-07-11 12:11:41,312 INFO    HandlerThread:106728 [handler.py:handle_request_defer():170] handle defer: 14
2023-07-11 12:11:41,312 DEBUG   SenderThread:106728 [sender.py:send():369] send: final
2023-07-11 12:11:41,312 DEBUG   SenderThread:106728 [sender.py:send():369] send: footer
2023-07-11 12:11:41,313 DEBUG   SenderThread:106728 [sender.py:send_request():396] send_request: defer
2023-07-11 12:11:41,313 INFO    SenderThread:106728 [sender.py:send_request_defer():598] handle sender defer: 14
2023-07-11 12:11:41,313 DEBUG   HandlerThread:106728 [handler.py:handle_request():144] handle_request: poll_exit
2023-07-11 12:11:41,313 DEBUG   SenderThread:106728 [sender.py:send_request():396] send_request: poll_exit
2023-07-11 12:11:41,313 DEBUG   HandlerThread:106728 [handler.py:handle_request():144] handle_request: server_info
2023-07-11 12:11:41,313 DEBUG   SenderThread:106728 [sender.py:send_request():396] send_request: server_info
2023-07-11 12:11:41,314 DEBUG   HandlerThread:106728 [handler.py:handle_request():144] handle_request: get_summary
2023-07-11 12:11:41,314 DEBUG   HandlerThread:106728 [handler.py:handle_request():144] handle_request: sampled_history
2023-07-11 12:11:41,765 INFO    MainThread:106728 [wandb_run.py:_footer_history_summary_info():3467] rendering history
2023-07-11 12:11:41,765 INFO    MainThread:106728 [wandb_run.py:_footer_history_summary_info():3499] rendering summary
2023-07-11 12:11:41,765 INFO    MainThread:106728 [wandb_run.py:_footer_sync_info():3426] logging synced files
2023-07-11 12:11:41,765 DEBUG   HandlerThread:106728 [handler.py:handle_request():144] handle_request: shutdown
2023-07-11 12:11:41,765 INFO    HandlerThread:106728 [handler.py:finish():854] shutting down handler
2023-07-11 12:11:42,313 INFO    WriterThread:106728 [datastore.py:close():298] close: /home/zhuhe/HPE-with-Diffusion/wandb/run-20230711_121113-szgm6i37/run-szgm6i37.wandb
2023-07-11 12:11:42,765 INFO    SenderThread:106728 [sender.py:finish():1526] shutting down sender
2023-07-11 12:11:42,765 INFO    SenderThread:106728 [file_pusher.py:finish():159] shutting down file pusher
2023-07-11 12:11:42,765 INFO    SenderThread:106728 [file_pusher.py:join():164] waiting for file pusher
