2023-07-11 12:47:56,179 INFO    StreamThr :107870 [internal.py:wandb_internal():86] W&B internal server running at pid: 107870, started at: 2023-07-11 12:47:56.179537
2023-07-11 12:47:56,181 DEBUG   HandlerThread:107870 [handler.py:handle_request():144] handle_request: status
2023-07-11 12:47:56,182 INFO    WriterThread:107870 [datastore.py:open_for_write():85] open: /home/zhuhe/HPE-with-Diffusion/wandb/run-20230711_124756-1oq413sq/run-1oq413sq.wandb
2023-07-11 12:47:56,182 DEBUG   SenderThread:107870 [sender.py:send():369] send: header
2023-07-11 12:47:56,182 DEBUG   SenderThread:107870 [sender.py:send():369] send: run
2023-07-11 12:47:57,054 INFO    SenderThread:107870 [dir_watcher.py:__init__():211] watching files in: /home/zhuhe/HPE-with-Diffusion/wandb/run-20230711_124756-1oq413sq/files
2023-07-11 12:47:57,054 INFO    SenderThread:107870 [sender.py:_start_run_threads():1100] run started: 1oq413sq with start time 1689050876.179347
2023-07-11 12:47:57,054 DEBUG   SenderThread:107870 [sender.py:send_request():396] send_request: summary_record
2023-07-11 12:47:57,054 INFO    SenderThread:107870 [sender.py:_save_file():1354] saving file wandb-summary.json with policy end
2023-07-11 12:47:57,056 DEBUG   HandlerThread:107870 [handler.py:handle_request():144] handle_request: check_version
2023-07-11 12:47:57,056 DEBUG   SenderThread:107870 [sender.py:send_request():396] send_request: check_version
2023-07-11 12:47:57,253 DEBUG   HandlerThread:107870 [handler.py:handle_request():144] handle_request: run_start
2023-07-11 12:47:57,265 DEBUG   HandlerThread:107870 [system_info.py:__init__():31] System info init
2023-07-11 12:47:57,266 DEBUG   HandlerThread:107870 [system_info.py:__init__():46] System info init done
2023-07-11 12:47:57,266 INFO    HandlerThread:107870 [system_monitor.py:start():181] Starting system monitor
2023-07-11 12:47:57,266 INFO    SystemMonitor:107870 [system_monitor.py:_start():145] Starting system asset monitoring threads
2023-07-11 12:47:57,267 INFO    HandlerThread:107870 [system_monitor.py:probe():201] Collecting system info
2023-07-11 12:47:57,268 INFO    SystemMonitor:107870 [interfaces.py:start():190] Started cpu monitoring
2023-07-11 12:47:57,269 INFO    SystemMonitor:107870 [interfaces.py:start():190] Started disk monitoring
2023-07-11 12:47:57,270 INFO    SystemMonitor:107870 [interfaces.py:start():190] Started gpu monitoring
2023-07-11 12:47:57,271 INFO    SystemMonitor:107870 [interfaces.py:start():190] Started memory monitoring
2023-07-11 12:47:57,272 INFO    SystemMonitor:107870 [interfaces.py:start():190] Started network monitoring
2023-07-11 12:47:57,285 DEBUG   HandlerThread:107870 [system_info.py:probe():195] Probing system
2023-07-11 12:47:57,289 DEBUG   HandlerThread:107870 [gitlib.py:_init_repo():53] git repository is invalid
2023-07-11 12:47:57,289 DEBUG   HandlerThread:107870 [system_info.py:probe():240] Probing system done
2023-07-11 12:47:57,290 DEBUG   HandlerThread:107870 [system_monitor.py:probe():210] {'os': 'Linux-5.19.0-46-generic-x86_64-with-glibc2.35', 'python': '3.9.16', 'heartbeatAt': '2023-07-11T04:47:57.285872', 'startedAt': '2023-07-11T04:47:56.173857', 'docker': None, 'cuda': None, 'args': ('--config', '/home/zhuhe/HPE-with-Diffusion/config/sanitycheck_val.json', '--phase', 'val', '--gpu_ids', '1'), 'state': 'running', 'program': '/home/zhuhe/HPE-with-Diffusion/main.py', 'codePath': 'main.py', 'host': '415-2', 'username': 'zhuhe', 'executable': '/home/zhuhe/.conda/envs/diffhpe/bin/python', 'cpu_count': 16, 'cpu_count_logical': 24, 'cpu_freq': {'current': 1956.10575, 'min': 800.0, 'max': 4783.333333333333}, 'cpu_freq_per_core': [{'current': 1933.468, 'min': 800.0, 'max': 5100.0}, {'current': 2100.0, 'min': 800.0, 'max': 5100.0}, {'current': 1954.954, 'min': 800.0, 'max': 5100.0}, {'current': 2100.0, 'min': 800.0, 'max': 5100.0}, {'current': 2100.0, 'min': 800.0, 'max': 5100.0}, {'current': 1795.813, 'min': 800.0, 'max': 5100.0}, {'current': 1375.576, 'min': 800.0, 'max': 5100.0}, {'current': 1789.174, 'min': 800.0, 'max': 5100.0}, {'current': 1841.944, 'min': 800.0, 'max': 5200.0}, {'current': 2100.0, 'min': 800.0, 'max': 5200.0}, {'current': 1748.124, 'min': 800.0, 'max': 5200.0}, {'current': 1508.801, 'min': 800.0, 'max': 5200.0}, {'current': 1908.044, 'min': 800.0, 'max': 5100.0}, {'current': 2100.0, 'min': 800.0, 'max': 5100.0}, {'current': 1841.918, 'min': 800.0, 'max': 5100.0}, {'current': 2100.0, 'min': 800.0, 'max': 5100.0}, {'current': 2100.0, 'min': 800.0, 'max': 4100.0}, {'current': 2100.0, 'min': 800.0, 'max': 4100.0}, {'current': 2100.0, 'min': 800.0, 'max': 4100.0}, {'current': 2100.0, 'min': 800.0, 'max': 4100.0}, {'current': 2100.0, 'min': 800.0, 'max': 4100.0}, {'current': 2100.0, 'min': 800.0, 'max': 4100.0}, {'current': 2100.0, 'min': 800.0, 'max': 4100.0}, {'current': 2100.0, 'min': 800.0, 'max': 4100.0}], 'disk': {'total': 93.31179428100586, 'used': 0.019878387451171875}, 'gpu': 'NVIDIA GeForce RTX 3090', 'gpu_count': 2, 'gpu_devices': [{'name': 'NVIDIA GeForce RTX 3090', 'memory_total': 25769803776}, {'name': 'NVIDIA GeForce RTX 3090', 'memory_total': 25769803776}], 'memory': {'total': 31.185558319091797}}
2023-07-11 12:47:57,290 INFO    HandlerThread:107870 [system_monitor.py:probe():211] Finished collecting system info
2023-07-11 12:47:57,290 INFO    HandlerThread:107870 [system_monitor.py:probe():214] Publishing system info
2023-07-11 12:47:57,290 DEBUG   HandlerThread:107870 [system_info.py:_save_pip():51] Saving list of pip packages installed into the current environment
2023-07-11 12:47:57,290 DEBUG   HandlerThread:107870 [system_info.py:_save_pip():67] Saving pip packages done
2023-07-11 12:47:57,290 DEBUG   HandlerThread:107870 [system_info.py:_save_conda():74] Saving list of conda packages installed into the current environment
2023-07-11 12:47:58,055 INFO    Thread-12 :107870 [dir_watcher.py:_on_file_created():272] file/dir created: /home/zhuhe/HPE-with-Diffusion/wandb/run-20230711_124756-1oq413sq/files/requirements.txt
2023-07-11 12:47:58,055 INFO    Thread-12 :107870 [dir_watcher.py:_on_file_created():272] file/dir created: /home/zhuhe/HPE-with-Diffusion/wandb/run-20230711_124756-1oq413sq/files/conda-environment.yaml
2023-07-11 12:47:58,055 INFO    Thread-12 :107870 [dir_watcher.py:_on_file_created():272] file/dir created: /home/zhuhe/HPE-with-Diffusion/wandb/run-20230711_124756-1oq413sq/files/wandb-summary.json
2023-07-11 12:47:58,187 DEBUG   HandlerThread:107870 [system_info.py:_save_conda():86] Saving conda packages done
2023-07-11 12:47:58,187 INFO    HandlerThread:107870 [system_monitor.py:probe():216] Finished publishing system info
2023-07-11 12:47:58,188 DEBUG   SenderThread:107870 [sender.py:send():369] send: files
2023-07-11 12:47:58,189 INFO    SenderThread:107870 [sender.py:_save_file():1354] saving file wandb-metadata.json with policy now
2023-07-11 12:47:58,192 DEBUG   HandlerThread:107870 [handler.py:handle_request():144] handle_request: stop_status
2023-07-11 12:47:58,193 DEBUG   SenderThread:107870 [sender.py:send_request():396] send_request: stop_status
2023-07-11 12:47:58,660 ERROR   wandb-upload_0:107870 [internal_api.py:upload_file():2192] upload_file exception https://storage.googleapis.com/wandb-production.appspot.com/ada4321/DiffHPE/1oq413sq/wandb-metadata.json?Expires=1689137278&GoogleAccessId=gorilla-files-url-signer-man%40wandb-production.iam.gserviceaccount.com&Signature=IEJPPq7brxtSmvKNjeo6Xxf2z%2Bxzy7XpX8mgDSyg1qcEu%2FUC4%2B4jS1Rlei0pL55vjXB3pRSpYwpDCyYaxONxuOG4dLAsm%2BSxyos%2BgWhf1qEWurSvxxfXiQDEL3UO7NXxC29w2Z1KvWxeFAlyu5zJmg56ctOTvqLK0RP72sgDK7D%2B71lN3URvJ6kWNWilWTCdJIR3IHpG7QLMdgjM%2FYm3AzjJzA34iEa4iEGNaiZyLT3G%2FPtrT49p6O3sdPdbp3s892RS%2FKmNEy7IJEOqsRqwV6gXCHHLA5sIhiCtS2pRPO9YSrDhP29fre4kldmGI95JUBvTOBrsT44TWiavbIX%2Bvw%3D%3D: 404 Client Error: Not Found for url: https://storage.googleapis.com/wandb-production.appspot.com/ada4321/DiffHPE/1oq413sq/wandb-metadata.json?Expires=1689137278&GoogleAccessId=gorilla-files-url-signer-man%40wandb-production.iam.gserviceaccount.com&Signature=IEJPPq7brxtSmvKNjeo6Xxf2z%2Bxzy7XpX8mgDSyg1qcEu%2FUC4%2B4jS1Rlei0pL55vjXB3pRSpYwpDCyYaxONxuOG4dLAsm%2BSxyos%2BgWhf1qEWurSvxxfXiQDEL3UO7NXxC29w2Z1KvWxeFAlyu5zJmg56ctOTvqLK0RP72sgDK7D%2B71lN3URvJ6kWNWilWTCdJIR3IHpG7QLMdgjM%2FYm3AzjJzA34iEa4iEGNaiZyLT3G%2FPtrT49p6O3sdPdbp3s892RS%2FKmNEy7IJEOqsRqwV6gXCHHLA5sIhiCtS2pRPO9YSrDhP29fre4kldmGI95JUBvTOBrsT44TWiavbIX%2Bvw%3D%3D
2023-07-11 12:47:58,660 ERROR   wandb-upload_0:107870 [internal_api.py:upload_file():2194] upload_file request headers: {'User-Agent': 'python-requests/2.31.0', 'Accept-Encoding': 'gzip, deflate', 'Accept': '*/*', 'Connection': 'keep-alive', 'Content-Length': '3780'}
2023-07-11 12:47:58,660 ERROR   wandb-upload_0:107870 [internal_api.py:upload_file():2196] upload_file response body: b'<!DOCTYPE html>\n<html lang=en>\n  <meta charset=utf-8>\n  <meta name=viewport content="initial-scale=1, minimum-scale=1, width=device-width">\n  <title>Error 404 (Not Found)!!1</title>\n  <style>\n    *{margin:0;padding:0}html,code{font:15px/22px arial,sans-serif}html{background:#fff;color:#222;padding:15px}body{margin:7% auto 0;max-width:390px;min-height:180px;padding:30px 0 15px}* > body{background:url(//www.google.com/images/errors/robot.png) 100% 5px no-repeat;padding-right:205px}p{margin:11px 0 22px;overflow:hidden}ins{color:#777;text-decoration:none}a img{border:0}@media screen and (max-width:772px){body{background:none;margin-top:0;max-width:none;padding-right:0}}#logo{background:url(//www.google.com/images/branding/googlelogo/1x/googlelogo_color_150x54dp.png) no-repeat;margin-left:-5px}@media only screen and (min-resolution:192dpi){#logo{background:url(//www.google.com/images/branding/googlelogo/2x/googlelogo_color_150x54dp.png) no-repeat 0% 0%/100% 100%;-moz-border-image:url(//www.google.com/images/branding/googlelogo/2x/googlelogo_color_150x54dp.png) 0}}@media only screen and (-webkit-min-device-pixel-ratio:2){#logo{background:url(//www.google.com/images/branding/googlelogo/2x/googlelogo_color_150x54dp.png) no-repeat;-webkit-background-size:100% 100%}}#logo{display:inline-block;height:54px;width:150px}\n  </style>\n  <a href=//www.google.com/><span id=logo aria-label=Google></span></a>\n  <p><b>404.</b> <ins>That\xe2\x80\x99s an error.</ins>\n  <p>The requested URL <code>/wandb-production.appspot.com/ada4321/DiffHPE/1oq413sq/wandb-metadata.json</code> was not found on this server.  <ins>That\xe2\x80\x99s all we know.</ins>\n'
2023-07-11 12:47:58,735 DEBUG   SenderThread:107870 [sender.py:send():369] send: telemetry
2023-07-11 12:47:59,055 INFO    Thread-12 :107870 [dir_watcher.py:_on_file_modified():289] file/dir modified: /home/zhuhe/HPE-with-Diffusion/wandb/run-20230711_124756-1oq413sq/files/conda-environment.yaml
2023-07-11 12:47:59,056 INFO    Thread-12 :107870 [dir_watcher.py:_on_file_created():272] file/dir created: /home/zhuhe/HPE-with-Diffusion/wandb/run-20230711_124756-1oq413sq/files/wandb-metadata.json
2023-07-11 12:47:59,056 INFO    Thread-12 :107870 [dir_watcher.py:_on_file_created():272] file/dir created: /home/zhuhe/HPE-with-Diffusion/wandb/run-20230711_124756-1oq413sq/files/output.log
2023-07-11 12:48:00,582 ERROR   wandb-upload_0:107870 [upload_job.py:push():136] Failed to upload file: /tmp/tmppwii7pfkwandb/btg3lxqc-wandb-metadata.json
Traceback (most recent call last):
  File "/home/zhuhe/.conda/envs/diffhpe/lib/python3.9/site-packages/wandb/apis/normalize.py", line 41, in wrapper
    return func(*args, **kwargs)
  File "/home/zhuhe/.conda/envs/diffhpe/lib/python3.9/site-packages/wandb/sdk/lib/retry.py", line 212, in wrapped_fn
    return retrier(*args, **kargs)
  File "/home/zhuhe/.conda/envs/diffhpe/lib/python3.9/site-packages/wandb/sdk/lib/retry.py", line 131, in __call__
    result = self._call_fn(*args, **kwargs)
  File "/home/zhuhe/.conda/envs/diffhpe/lib/python3.9/site-packages/wandb/sdk/internal/internal_api.py", line 2218, in upload_file
    wandb._sentry.reraise(e)
  File "/home/zhuhe/.conda/envs/diffhpe/lib/python3.9/site-packages/wandb/analytics/sentry.py", line 146, in reraise
    raise exc.with_traceback(sys.exc_info()[2])
  File "/home/zhuhe/.conda/envs/diffhpe/lib/python3.9/site-packages/wandb/sdk/internal/internal_api.py", line 2190, in upload_file
    response.raise_for_status()
  File "/home/zhuhe/.conda/envs/diffhpe/lib/python3.9/site-packages/requests/models.py", line 1021, in raise_for_status
    raise HTTPError(http_error_msg, response=self)
requests.exceptions.HTTPError: 404 Client Error: Not Found for url: https://storage.googleapis.com/wandb-production.appspot.com/ada4321/DiffHPE/1oq413sq/wandb-metadata.json?Expires=1689137278&GoogleAccessId=gorilla-files-url-signer-man%40wandb-production.iam.gserviceaccount.com&Signature=IEJPPq7brxtSmvKNjeo6Xxf2z%2Bxzy7XpX8mgDSyg1qcEu%2FUC4%2B4jS1Rlei0pL55vjXB3pRSpYwpDCyYaxONxuOG4dLAsm%2BSxyos%2BgWhf1qEWurSvxxfXiQDEL3UO7NXxC29w2Z1KvWxeFAlyu5zJmg56ctOTvqLK0RP72sgDK7D%2B71lN3URvJ6kWNWilWTCdJIR3IHpG7QLMdgjM%2FYm3AzjJzA34iEa4iEGNaiZyLT3G%2FPtrT49p6O3sdPdbp3s892RS%2FKmNEy7IJEOqsRqwV6gXCHHLA5sIhiCtS2pRPO9YSrDhP29fre4kldmGI95JUBvTOBrsT44TWiavbIX%2Bvw%3D%3D

During handling of the above exception, another exception occurred:

Traceback (most recent call last):
  File "/home/zhuhe/.conda/envs/diffhpe/lib/python3.9/site-packages/wandb/filesync/upload_job.py", line 127, in push
    self._api.upload_file_retry(
  File "/home/zhuhe/.conda/envs/diffhpe/lib/python3.9/site-packages/wandb/apis/normalize.py", line 51, in wrapper
    raise CommError(message, error)
wandb.errors.CommError: <Response [404]>
2023-07-11 12:48:00,813 ERROR   Thread-11 :107870 [step_upload.py:_handle_event():200] Failed to upload file: /tmp/tmppwii7pfkwandb/btg3lxqc-wandb-metadata.json
Traceback (most recent call last):
  File "/home/zhuhe/.conda/envs/diffhpe/lib/python3.9/site-packages/wandb/apis/normalize.py", line 41, in wrapper
    return func(*args, **kwargs)
  File "/home/zhuhe/.conda/envs/diffhpe/lib/python3.9/site-packages/wandb/sdk/lib/retry.py", line 212, in wrapped_fn
    return retrier(*args, **kargs)
  File "/home/zhuhe/.conda/envs/diffhpe/lib/python3.9/site-packages/wandb/sdk/lib/retry.py", line 131, in __call__
    result = self._call_fn(*args, **kwargs)
  File "/home/zhuhe/.conda/envs/diffhpe/lib/python3.9/site-packages/wandb/sdk/internal/internal_api.py", line 2218, in upload_file
    wandb._sentry.reraise(e)
  File "/home/zhuhe/.conda/envs/diffhpe/lib/python3.9/site-packages/wandb/analytics/sentry.py", line 146, in reraise
    raise exc.with_traceback(sys.exc_info()[2])
  File "/home/zhuhe/.conda/envs/diffhpe/lib/python3.9/site-packages/wandb/sdk/internal/internal_api.py", line 2190, in upload_file
    response.raise_for_status()
  File "/home/zhuhe/.conda/envs/diffhpe/lib/python3.9/site-packages/requests/models.py", line 1021, in raise_for_status
    raise HTTPError(http_error_msg, response=self)
requests.exceptions.HTTPError: 404 Client Error: Not Found for url: https://storage.googleapis.com/wandb-production.appspot.com/ada4321/DiffHPE/1oq413sq/wandb-metadata.json?Expires=1689137278&GoogleAccessId=gorilla-files-url-signer-man%40wandb-production.iam.gserviceaccount.com&Signature=IEJPPq7brxtSmvKNjeo6Xxf2z%2Bxzy7XpX8mgDSyg1qcEu%2FUC4%2B4jS1Rlei0pL55vjXB3pRSpYwpDCyYaxONxuOG4dLAsm%2BSxyos%2BgWhf1qEWurSvxxfXiQDEL3UO7NXxC29w2Z1KvWxeFAlyu5zJmg56ctOTvqLK0RP72sgDK7D%2B71lN3URvJ6kWNWilWTCdJIR3IHpG7QLMdgjM%2FYm3AzjJzA34iEa4iEGNaiZyLT3G%2FPtrT49p6O3sdPdbp3s892RS%2FKmNEy7IJEOqsRqwV6gXCHHLA5sIhiCtS2pRPO9YSrDhP29fre4kldmGI95JUBvTOBrsT44TWiavbIX%2Bvw%3D%3D

During handling of the above exception, another exception occurred:

Traceback (most recent call last):
  File "/home/zhuhe/.conda/envs/diffhpe/lib/python3.9/concurrent/futures/thread.py", line 58, in run
    result = self.fn(*self.args, **self.kwargs)
  File "/home/zhuhe/.conda/envs/diffhpe/lib/python3.9/site-packages/wandb/filesync/step_upload.py", line 288, in run_and_notify
    self._do_upload_sync(event)
  File "/home/zhuhe/.conda/envs/diffhpe/lib/python3.9/site-packages/wandb/filesync/step_upload.py", line 330, in _do_upload_sync
    job.run()
  File "/home/zhuhe/.conda/envs/diffhpe/lib/python3.9/site-packages/wandb/filesync/upload_job.py", line 57, in run
    self.push()
  File "/home/zhuhe/.conda/envs/diffhpe/lib/python3.9/site-packages/wandb/filesync/upload_job.py", line 127, in push
    self._api.upload_file_retry(
  File "/home/zhuhe/.conda/envs/diffhpe/lib/python3.9/site-packages/wandb/apis/normalize.py", line 51, in wrapper
    raise CommError(message, error)
wandb.errors.CommError: <Response [404]>
2023-07-11 12:48:01,056 INFO    Thread-12 :107870 [dir_watcher.py:_on_file_modified():289] file/dir modified: /home/zhuhe/HPE-with-Diffusion/wandb/run-20230711_124756-1oq413sq/files/output.log
2023-07-11 12:48:01,265 DEBUG   HandlerThread:107870 [handler.py:handle_request():144] handle_request: status_report
2023-07-11 12:48:03,056 INFO    Thread-12 :107870 [dir_watcher.py:_on_file_modified():289] file/dir modified: /home/zhuhe/HPE-with-Diffusion/wandb/run-20230711_124756-1oq413sq/files/output.log
2023-07-11 12:48:06,163 DEBUG   SenderThread:107870 [sender.py:send():369] send: telemetry
2023-07-11 12:48:07,057 INFO    Thread-12 :107870 [dir_watcher.py:_on_file_modified():289] file/dir modified: /home/zhuhe/HPE-with-Diffusion/wandb/run-20230711_124756-1oq413sq/files/output.log
2023-07-11 12:48:07,223 DEBUG   HandlerThread:107870 [handler.py:handle_request():144] handle_request: status_report
2023-07-11 12:48:09,753 DEBUG   SenderThread:107870 [sender.py:send():369] send: exit
2023-07-11 12:48:09,755 INFO    SenderThread:107870 [sender.py:send_exit():574] handling exit code: 1
2023-07-11 12:48:09,755 INFO    SenderThread:107870 [sender.py:send_exit():576] handling runtime: 12
2023-07-11 12:48:09,755 INFO    SenderThread:107870 [sender.py:_save_file():1354] saving file wandb-summary.json with policy end
2023-07-11 12:48:09,755 INFO    SenderThread:107870 [sender.py:send_exit():582] send defer
2023-07-11 12:48:09,756 DEBUG   HandlerThread:107870 [handler.py:handle_request():144] handle_request: defer
2023-07-11 12:48:09,756 INFO    HandlerThread:107870 [handler.py:handle_request_defer():170] handle defer: 0
2023-07-11 12:48:09,756 DEBUG   SenderThread:107870 [sender.py:send_request():396] send_request: defer
2023-07-11 12:48:09,756 INFO    SenderThread:107870 [sender.py:send_request_defer():598] handle sender defer: 0
2023-07-11 12:48:09,756 INFO    SenderThread:107870 [sender.py:transition_state():602] send defer: 1
2023-07-11 12:48:09,756 DEBUG   HandlerThread:107870 [handler.py:handle_request():144] handle_request: defer
2023-07-11 12:48:09,756 INFO    HandlerThread:107870 [handler.py:handle_request_defer():170] handle defer: 1
2023-07-11 12:48:09,756 DEBUG   SenderThread:107870 [sender.py:send_request():396] send_request: defer
2023-07-11 12:48:09,756 INFO    SenderThread:107870 [sender.py:send_request_defer():598] handle sender defer: 1
2023-07-11 12:48:09,756 INFO    SenderThread:107870 [sender.py:transition_state():602] send defer: 2
2023-07-11 12:48:09,756 DEBUG   HandlerThread:107870 [handler.py:handle_request():144] handle_request: defer
2023-07-11 12:48:09,756 INFO    HandlerThread:107870 [handler.py:handle_request_defer():170] handle defer: 2
2023-07-11 12:48:09,756 INFO    HandlerThread:107870 [system_monitor.py:finish():190] Stopping system monitor
2023-07-11 12:48:09,756 INFO    HandlerThread:107870 [interfaces.py:finish():202] Joined cpu monitor
2023-07-11 12:48:09,756 INFO    HandlerThread:107870 [interfaces.py:finish():202] Joined disk monitor
2023-07-11 12:48:09,756 DEBUG   SystemMonitor:107870 [system_monitor.py:_start():159] Starting system metrics aggregation loop
2023-07-11 12:48:09,757 DEBUG   SystemMonitor:107870 [system_monitor.py:_start():166] Finished system metrics aggregation loop
2023-07-11 12:48:09,757 DEBUG   SystemMonitor:107870 [system_monitor.py:_start():170] Publishing last batch of metrics
2023-07-11 12:48:09,813 INFO    HandlerThread:107870 [interfaces.py:finish():202] Joined gpu monitor
2023-07-11 12:48:09,814 INFO    HandlerThread:107870 [interfaces.py:finish():202] Joined memory monitor
2023-07-11 12:48:09,814 INFO    HandlerThread:107870 [interfaces.py:finish():202] Joined network monitor
2023-07-11 12:48:09,814 DEBUG   SenderThread:107870 [sender.py:send_request():396] send_request: defer
2023-07-11 12:48:09,814 INFO    SenderThread:107870 [sender.py:send_request_defer():598] handle sender defer: 2
2023-07-11 12:48:09,814 INFO    SenderThread:107870 [sender.py:transition_state():602] send defer: 3
2023-07-11 12:48:09,814 DEBUG   SenderThread:107870 [sender.py:send():369] send: stats
2023-07-11 12:48:09,814 DEBUG   HandlerThread:107870 [handler.py:handle_request():144] handle_request: defer
2023-07-11 12:48:09,814 INFO    HandlerThread:107870 [handler.py:handle_request_defer():170] handle defer: 3
2023-07-11 12:48:09,815 DEBUG   SenderThread:107870 [sender.py:send_request():396] send_request: defer
2023-07-11 12:48:09,815 INFO    SenderThread:107870 [sender.py:send_request_defer():598] handle sender defer: 3
2023-07-11 12:48:09,815 INFO    SenderThread:107870 [sender.py:transition_state():602] send defer: 4
2023-07-11 12:48:09,815 DEBUG   HandlerThread:107870 [handler.py:handle_request():144] handle_request: defer
2023-07-11 12:48:09,815 INFO    HandlerThread:107870 [handler.py:handle_request_defer():170] handle defer: 4
2023-07-11 12:48:09,815 DEBUG   SenderThread:107870 [sender.py:send_request():396] send_request: defer
2023-07-11 12:48:09,815 INFO    SenderThread:107870 [sender.py:send_request_defer():598] handle sender defer: 4
2023-07-11 12:48:09,815 INFO    SenderThread:107870 [sender.py:transition_state():602] send defer: 5
2023-07-11 12:48:09,815 DEBUG   HandlerThread:107870 [handler.py:handle_request():144] handle_request: defer
2023-07-11 12:48:09,815 INFO    HandlerThread:107870 [handler.py:handle_request_defer():170] handle defer: 5
2023-07-11 12:48:09,815 DEBUG   SenderThread:107870 [sender.py:send():369] send: summary
2023-07-11 12:48:09,816 INFO    SenderThread:107870 [sender.py:_save_file():1354] saving file wandb-summary.json with policy end
2023-07-11 12:48:09,816 DEBUG   SenderThread:107870 [sender.py:send_request():396] send_request: defer
2023-07-11 12:48:09,816 INFO    SenderThread:107870 [sender.py:send_request_defer():598] handle sender defer: 5
2023-07-11 12:48:09,816 INFO    SenderThread:107870 [sender.py:transition_state():602] send defer: 6
2023-07-11 12:48:09,816 DEBUG   HandlerThread:107870 [handler.py:handle_request():144] handle_request: defer
2023-07-11 12:48:09,816 INFO    HandlerThread:107870 [handler.py:handle_request_defer():170] handle defer: 6
2023-07-11 12:48:09,816 DEBUG   SenderThread:107870 [sender.py:send_request():396] send_request: defer
2023-07-11 12:48:09,816 INFO    SenderThread:107870 [sender.py:send_request_defer():598] handle sender defer: 6
2023-07-11 12:48:09,817 DEBUG   HandlerThread:107870 [handler.py:handle_request():144] handle_request: status_report
2023-07-11 12:48:10,059 INFO    Thread-12 :107870 [dir_watcher.py:_on_file_modified():289] file/dir modified: /home/zhuhe/HPE-with-Diffusion/wandb/run-20230711_124756-1oq413sq/files/wandb-summary.json
2023-07-11 12:48:10,071 INFO    SenderThread:107870 [sender.py:transition_state():602] send defer: 7
2023-07-11 12:48:10,071 DEBUG   HandlerThread:107870 [handler.py:handle_request():144] handle_request: defer
2023-07-11 12:48:10,071 INFO    HandlerThread:107870 [handler.py:handle_request_defer():170] handle defer: 7
2023-07-11 12:48:10,072 DEBUG   SenderThread:107870 [sender.py:send_request():396] send_request: defer
2023-07-11 12:48:10,072 INFO    SenderThread:107870 [sender.py:send_request_defer():598] handle sender defer: 7
2023-07-11 12:48:10,760 DEBUG   HandlerThread:107870 [handler.py:handle_request():144] handle_request: poll_exit
2023-07-11 12:48:11,059 INFO    Thread-12 :107870 [dir_watcher.py:_on_file_modified():289] file/dir modified: /home/zhuhe/HPE-with-Diffusion/wandb/run-20230711_124756-1oq413sq/files/config.yaml
2023-07-11 12:48:11,060 INFO    Thread-12 :107870 [dir_watcher.py:_on_file_modified():289] file/dir modified: /home/zhuhe/HPE-with-Diffusion/wandb/run-20230711_124756-1oq413sq/files/output.log
2023-07-11 12:48:12,755 INFO    SenderThread:107870 [sender.py:transition_state():602] send defer: 8
2023-07-11 12:48:12,755 DEBUG   SenderThread:107870 [sender.py:send_request():396] send_request: poll_exit
2023-07-11 12:48:12,756 DEBUG   HandlerThread:107870 [handler.py:handle_request():144] handle_request: defer
2023-07-11 12:48:12,756 INFO    HandlerThread:107870 [handler.py:handle_request_defer():170] handle defer: 8
2023-07-11 12:48:12,757 DEBUG   SenderThread:107870 [sender.py:send_request():396] send_request: defer
2023-07-11 12:48:12,757 INFO    SenderThread:107870 [sender.py:send_request_defer():598] handle sender defer: 8
2023-07-11 12:48:12,757 INFO    SenderThread:107870 [job_builder.py:build():232] Attempting to build job artifact
2023-07-11 12:48:12,758 INFO    SenderThread:107870 [job_builder.py:build():266] no source found
2023-07-11 12:48:12,758 INFO    SenderThread:107870 [sender.py:transition_state():602] send defer: 9
2023-07-11 12:48:12,758 DEBUG   HandlerThread:107870 [handler.py:handle_request():144] handle_request: defer
2023-07-11 12:48:12,758 INFO    HandlerThread:107870 [handler.py:handle_request_defer():170] handle defer: 9
2023-07-11 12:48:12,759 DEBUG   SenderThread:107870 [sender.py:send_request():396] send_request: defer
2023-07-11 12:48:12,759 INFO    SenderThread:107870 [sender.py:send_request_defer():598] handle sender defer: 9
2023-07-11 12:48:12,759 INFO    SenderThread:107870 [dir_watcher.py:finish():359] shutting down directory watcher
2023-07-11 12:48:13,060 INFO    Thread-12 :107870 [dir_watcher.py:_on_file_modified():289] file/dir modified: /home/zhuhe/HPE-with-Diffusion/wandb/run-20230711_124756-1oq413sq/files/output.log
2023-07-11 12:48:13,061 INFO    SenderThread:107870 [dir_watcher.py:finish():389] scan: /home/zhuhe/HPE-with-Diffusion/wandb/run-20230711_124756-1oq413sq/files
2023-07-11 12:48:13,062 INFO    SenderThread:107870 [dir_watcher.py:finish():403] scan save: /home/zhuhe/HPE-with-Diffusion/wandb/run-20230711_124756-1oq413sq/files/wandb-metadata.json wandb-metadata.json
2023-07-11 12:48:13,062 INFO    SenderThread:107870 [dir_watcher.py:finish():403] scan save: /home/zhuhe/HPE-with-Diffusion/wandb/run-20230711_124756-1oq413sq/files/config.yaml config.yaml
2023-07-11 12:48:13,062 INFO    SenderThread:107870 [dir_watcher.py:finish():403] scan save: /home/zhuhe/HPE-with-Diffusion/wandb/run-20230711_124756-1oq413sq/files/requirements.txt requirements.txt
2023-07-11 12:48:13,062 INFO    SenderThread:107870 [dir_watcher.py:finish():403] scan save: /home/zhuhe/HPE-with-Diffusion/wandb/run-20230711_124756-1oq413sq/files/wandb-summary.json wandb-summary.json
2023-07-11 12:48:13,062 INFO    SenderThread:107870 [dir_watcher.py:finish():403] scan save: /home/zhuhe/HPE-with-Diffusion/wandb/run-20230711_124756-1oq413sq/files/conda-environment.yaml conda-environment.yaml
2023-07-11 12:48:13,063 INFO    SenderThread:107870 [dir_watcher.py:finish():403] scan save: /home/zhuhe/HPE-with-Diffusion/wandb/run-20230711_124756-1oq413sq/files/output.log output.log
2023-07-11 12:48:13,063 INFO    SenderThread:107870 [sender.py:transition_state():602] send defer: 10
2023-07-11 12:48:13,063 DEBUG   HandlerThread:107870 [handler.py:handle_request():144] handle_request: defer
2023-07-11 12:48:13,064 INFO    HandlerThread:107870 [handler.py:handle_request_defer():170] handle defer: 10
2023-07-11 12:48:13,073 DEBUG   SenderThread:107870 [sender.py:send_request():396] send_request: defer
2023-07-11 12:48:13,073 INFO    SenderThread:107870 [sender.py:send_request_defer():598] handle sender defer: 10
2023-07-11 12:48:13,073 INFO    SenderThread:107870 [file_pusher.py:finish():159] shutting down file pusher
2023-07-11 12:48:13,540 ERROR   wandb-upload_0:107870 [internal_api.py:upload_file():2192] upload_file exception https://storage.googleapis.com/wandb-production.appspot.com/ada4321/DiffHPE/1oq413sq/requirements.txt?Expires=1689137293&GoogleAccessId=gorilla-files-url-signer-man%40wandb-production.iam.gserviceaccount.com&Signature=uCim7WXqLPPG%2BwiQksN%2BWHAzE9rCslZKR%2FQw%2FSQ6IEJMuruMI9kGq%2BZvWyMq8VKca9GgyjkUNgBByOi5dIfmWNOfXtlXdUAUs%2BRz%2BuwHWy%2FPShGEXrboGaPXicm3o7YV9n1zEgEZhF26QTXKrP4WuXtY0i4OgwgNtJWoIcKssZDBMPgzh%2BDLK%2Fv84kgMIjVyHirZNHKThA0OeIfev9lCCJphyAY7EFdl%2FzBGipQL7Rd4cCZSk4IV1A7F51WBr%2FPgTgPIWVLJ88UFzjBPF92oI5qfel1c6hJ3kPBJoAUrCPDByFrNC4E%2BtQgjixvfR8q1IZJ4TRZM8yN071TwpdDOAw%3D%3D: 404 Client Error: Not Found for url: https://storage.googleapis.com/wandb-production.appspot.com/ada4321/DiffHPE/1oq413sq/requirements.txt?Expires=1689137293&GoogleAccessId=gorilla-files-url-signer-man%40wandb-production.iam.gserviceaccount.com&Signature=uCim7WXqLPPG%2BwiQksN%2BWHAzE9rCslZKR%2FQw%2FSQ6IEJMuruMI9kGq%2BZvWyMq8VKca9GgyjkUNgBByOi5dIfmWNOfXtlXdUAUs%2BRz%2BuwHWy%2FPShGEXrboGaPXicm3o7YV9n1zEgEZhF26QTXKrP4WuXtY0i4OgwgNtJWoIcKssZDBMPgzh%2BDLK%2Fv84kgMIjVyHirZNHKThA0OeIfev9lCCJphyAY7EFdl%2FzBGipQL7Rd4cCZSk4IV1A7F51WBr%2FPgTgPIWVLJ88UFzjBPF92oI5qfel1c6hJ3kPBJoAUrCPDByFrNC4E%2BtQgjixvfR8q1IZJ4TRZM8yN071TwpdDOAw%3D%3D
2023-07-11 12:48:13,541 ERROR   wandb-upload_0:107870 [internal_api.py:upload_file():2194] upload_file request headers: {'User-Agent': 'python-requests/2.31.0', 'Accept-Encoding': 'gzip, deflate', 'Accept': '*/*', 'Connection': 'keep-alive', 'Content-Length': '926'}
2023-07-11 12:48:13,541 ERROR   wandb-upload_0:107870 [internal_api.py:upload_file():2196] upload_file response body: b'<!DOCTYPE html>\n<html lang=en>\n  <meta charset=utf-8>\n  <meta name=viewport content="initial-scale=1, minimum-scale=1, width=device-width">\n  <title>Error 404 (Not Found)!!1</title>\n  <style>\n    *{margin:0;padding:0}html,code{font:15px/22px arial,sans-serif}html{background:#fff;color:#222;padding:15px}body{margin:7% auto 0;max-width:390px;min-height:180px;padding:30px 0 15px}* > body{background:url(//www.google.com/images/errors/robot.png) 100% 5px no-repeat;padding-right:205px}p{margin:11px 0 22px;overflow:hidden}ins{color:#777;text-decoration:none}a img{border:0}@media screen and (max-width:772px){body{background:none;margin-top:0;max-width:none;padding-right:0}}#logo{background:url(//www.google.com/images/branding/googlelogo/1x/googlelogo_color_150x54dp.png) no-repeat;margin-left:-5px}@media only screen and (min-resolution:192dpi){#logo{background:url(//www.google.com/images/branding/googlelogo/2x/googlelogo_color_150x54dp.png) no-repeat 0% 0%/100% 100%;-moz-border-image:url(//www.google.com/images/branding/googlelogo/2x/googlelogo_color_150x54dp.png) 0}}@media only screen and (-webkit-min-device-pixel-ratio:2){#logo{background:url(//www.google.com/images/branding/googlelogo/2x/googlelogo_color_150x54dp.png) no-repeat;-webkit-background-size:100% 100%}}#logo{display:inline-block;height:54px;width:150px}\n  </style>\n  <a href=//www.google.com/><span id=logo aria-label=Google></span></a>\n  <p><b>404.</b> <ins>That\xe2\x80\x99s an error.</ins>\n  <p>The requested URL <code>/wandb-production.appspot.com/ada4321/DiffHPE/1oq413sq/requirements.txt</code> was not found on this server.  <ins>That\xe2\x80\x99s all we know.</ins>\n'
2023-07-11 12:48:13,555 ERROR   wandb-upload_1:107870 [internal_api.py:upload_file():2192] upload_file exception https://storage.googleapis.com/wandb-production.appspot.com/ada4321/DiffHPE/1oq413sq/config.yaml?Expires=1689137293&GoogleAccessId=gorilla-files-url-signer-man%40wandb-production.iam.gserviceaccount.com&Signature=btqi7HO7bvFlbl2QZvY3iewrJaHxnfyOYazJY52NrhsMFixtPkDYcfWXsbfJIVGU%2Bp5UX7tJ2pXW448uQFw0pXTxeM2w6P0N5wiK5Acqu9TlL2oeze1RHL87JG0TcxsUE8AcGoBprA3qTRNN6Lp1xWSmeozBWjutAm3xDjPG2rhK3QgiKa9kUfjmgSCHmMT%2B5yKm87LYV6tXIJm4LxeOgeTAogL9mAFvD3IQjCJsCrSsbKrpYc%2FlI4sSFTkzWFcY%2FmNTZQuQVuuCyXjHU2wQH%2BAczMcXGhzZvQZ4RHaHqiDBk%2Brzd%2FmesvZakwB7DWme%2Fh6Iwj19cgavJ61Ww4BQuQ%3D%3D: 404 Client Error: Not Found for url: https://storage.googleapis.com/wandb-production.appspot.com/ada4321/DiffHPE/1oq413sq/config.yaml?Expires=1689137293&GoogleAccessId=gorilla-files-url-signer-man%40wandb-production.iam.gserviceaccount.com&Signature=btqi7HO7bvFlbl2QZvY3iewrJaHxnfyOYazJY52NrhsMFixtPkDYcfWXsbfJIVGU%2Bp5UX7tJ2pXW448uQFw0pXTxeM2w6P0N5wiK5Acqu9TlL2oeze1RHL87JG0TcxsUE8AcGoBprA3qTRNN6Lp1xWSmeozBWjutAm3xDjPG2rhK3QgiKa9kUfjmgSCHmMT%2B5yKm87LYV6tXIJm4LxeOgeTAogL9mAFvD3IQjCJsCrSsbKrpYc%2FlI4sSFTkzWFcY%2FmNTZQuQVuuCyXjHU2wQH%2BAczMcXGhzZvQZ4RHaHqiDBk%2Brzd%2FmesvZakwB7DWme%2Fh6Iwj19cgavJ61Ww4BQuQ%3D%3D
2023-07-11 12:48:13,555 ERROR   wandb-upload_1:107870 [internal_api.py:upload_file():2194] upload_file request headers: {'User-Agent': 'python-requests/2.31.0', 'Accept-Encoding': 'gzip, deflate', 'Accept': '*/*', 'Connection': 'keep-alive', 'Content-Length': '558'}
2023-07-11 12:48:13,555 ERROR   wandb-upload_1:107870 [internal_api.py:upload_file():2196] upload_file response body: b'<!DOCTYPE html>\n<html lang=en>\n  <meta charset=utf-8>\n  <meta name=viewport content="initial-scale=1, minimum-scale=1, width=device-width">\n  <title>Error 404 (Not Found)!!1</title>\n  <style>\n    *{margin:0;padding:0}html,code{font:15px/22px arial,sans-serif}html{background:#fff;color:#222;padding:15px}body{margin:7% auto 0;max-width:390px;min-height:180px;padding:30px 0 15px}* > body{background:url(//www.google.com/images/errors/robot.png) 100% 5px no-repeat;padding-right:205px}p{margin:11px 0 22px;overflow:hidden}ins{color:#777;text-decoration:none}a img{border:0}@media screen and (max-width:772px){body{background:none;margin-top:0;max-width:none;padding-right:0}}#logo{background:url(//www.google.com/images/branding/googlelogo/1x/googlelogo_color_150x54dp.png) no-repeat;margin-left:-5px}@media only screen and (min-resolution:192dpi){#logo{background:url(//www.google.com/images/branding/googlelogo/2x/googlelogo_color_150x54dp.png) no-repeat 0% 0%/100% 100%;-moz-border-image:url(//www.google.com/images/branding/googlelogo/2x/googlelogo_color_150x54dp.png) 0}}@media only screen and (-webkit-min-device-pixel-ratio:2){#logo{background:url(//www.google.com/images/branding/googlelogo/2x/googlelogo_color_150x54dp.png) no-repeat;-webkit-background-size:100% 100%}}#logo{display:inline-block;height:54px;width:150px}\n  </style>\n  <a href=//www.google.com/><span id=logo aria-label=Google></span></a>\n  <p><b>404.</b> <ins>That\xe2\x80\x99s an error.</ins>\n  <p>The requested URL <code>/wandb-production.appspot.com/ada4321/DiffHPE/1oq413sq/config.yaml</code> was not found on this server.  <ins>That\xe2\x80\x99s all we know.</ins>\n'
2023-07-11 12:48:13,985 ERROR   wandb-upload_4:107870 [internal_api.py:upload_file():2192] upload_file exception https://storage.googleapis.com/wandb-production.appspot.com/ada4321/DiffHPE/1oq413sq/output.log?Expires=1689137293&GoogleAccessId=gorilla-files-url-signer-man%40wandb-production.iam.gserviceaccount.com&Signature=wUvL24YJd4QXZp0nS0Mw1yz%2Bc8Y%2Bn%2B49jhqwwTQ2xPRTjvCtRuIDbTrY%2Bf5xauxbAejarFYtRRulbDA7IOMYFUWvcOI9AoGXACyeJA%2BqxEivHqlW0AIxcirKg4AuVH9bgyjnIV4YehFQpKBZBww%2Fm9svGLJjvlEo54DktF8bAlu0%2BWixFuQzduf3rkJCBXY%2BOHv%2FA8GW6KL1eqoRgFbsCWQqCq1G3%2B3N%2Bwmb5PIj0R%2BYxJfjifwqSSjZ%2Bh4Qp7L6atcFSWh1DaOoKAe3xuRrCCkOVQ4RlASrUQzyu8z2f%2BEe7JXnrDoJxVuA1AbtcXZmzFg3UybRqKM0mQqvYae3Jg%3D%3D: 404 Client Error: Not Found for url: https://storage.googleapis.com/wandb-production.appspot.com/ada4321/DiffHPE/1oq413sq/output.log?Expires=1689137293&GoogleAccessId=gorilla-files-url-signer-man%40wandb-production.iam.gserviceaccount.com&Signature=wUvL24YJd4QXZp0nS0Mw1yz%2Bc8Y%2Bn%2B49jhqwwTQ2xPRTjvCtRuIDbTrY%2Bf5xauxbAejarFYtRRulbDA7IOMYFUWvcOI9AoGXACyeJA%2BqxEivHqlW0AIxcirKg4AuVH9bgyjnIV4YehFQpKBZBww%2Fm9svGLJjvlEo54DktF8bAlu0%2BWixFuQzduf3rkJCBXY%2BOHv%2FA8GW6KL1eqoRgFbsCWQqCq1G3%2B3N%2Bwmb5PIj0R%2BYxJfjifwqSSjZ%2Bh4Qp7L6atcFSWh1DaOoKAe3xuRrCCkOVQ4RlASrUQzyu8z2f%2BEe7JXnrDoJxVuA1AbtcXZmzFg3UybRqKM0mQqvYae3Jg%3D%3D
2023-07-11 12:48:13,986 ERROR   wandb-upload_4:107870 [internal_api.py:upload_file():2194] upload_file request headers: {'User-Agent': 'python-requests/2.31.0', 'Accept-Encoding': 'gzip, deflate', 'Accept': '*/*', 'Connection': 'keep-alive', 'Content-Length': '5271'}
2023-07-11 12:48:13,986 ERROR   wandb-upload_4:107870 [internal_api.py:upload_file():2196] upload_file response body: b'<!DOCTYPE html>\n<html lang=en>\n  <meta charset=utf-8>\n  <meta name=viewport content="initial-scale=1, minimum-scale=1, width=device-width">\n  <title>Error 404 (Not Found)!!1</title>\n  <style>\n    *{margin:0;padding:0}html,code{font:15px/22px arial,sans-serif}html{background:#fff;color:#222;padding:15px}body{margin:7% auto 0;max-width:390px;min-height:180px;padding:30px 0 15px}* > body{background:url(//www.google.com/images/errors/robot.png) 100% 5px no-repeat;padding-right:205px}p{margin:11px 0 22px;overflow:hidden}ins{color:#777;text-decoration:none}a img{border:0}@media screen and (max-width:772px){body{background:none;margin-top:0;max-width:none;padding-right:0}}#logo{background:url(//www.google.com/images/branding/googlelogo/1x/googlelogo_color_150x54dp.png) no-repeat;margin-left:-5px}@media only screen and (min-resolution:192dpi){#logo{background:url(//www.google.com/images/branding/googlelogo/2x/googlelogo_color_150x54dp.png) no-repeat 0% 0%/100% 100%;-moz-border-image:url(//www.google.com/images/branding/googlelogo/2x/googlelogo_color_150x54dp.png) 0}}@media only screen and (-webkit-min-device-pixel-ratio:2){#logo{background:url(//www.google.com/images/branding/googlelogo/2x/googlelogo_color_150x54dp.png) no-repeat;-webkit-background-size:100% 100%}}#logo{display:inline-block;height:54px;width:150px}\n  </style>\n  <a href=//www.google.com/><span id=logo aria-label=Google></span></a>\n  <p><b>404.</b> <ins>That\xe2\x80\x99s an error.</ins>\n  <p>The requested URL <code>/wandb-production.appspot.com/ada4321/DiffHPE/1oq413sq/output.log</code> was not found on this server.  <ins>That\xe2\x80\x99s all we know.</ins>\n'
2023-07-11 12:48:13,988 ERROR   wandb-upload_0:107870 [upload_job.py:push():136] Failed to upload file: /home/zhuhe/HPE-with-Diffusion/wandb/run-20230711_124756-1oq413sq/files/requirements.txt
Traceback (most recent call last):
  File "/home/zhuhe/.conda/envs/diffhpe/lib/python3.9/site-packages/wandb/apis/normalize.py", line 41, in wrapper
    return func(*args, **kwargs)
  File "/home/zhuhe/.conda/envs/diffhpe/lib/python3.9/site-packages/wandb/sdk/lib/retry.py", line 212, in wrapped_fn
    return retrier(*args, **kargs)
  File "/home/zhuhe/.conda/envs/diffhpe/lib/python3.9/site-packages/wandb/sdk/lib/retry.py", line 131, in __call__
    result = self._call_fn(*args, **kwargs)
  File "/home/zhuhe/.conda/envs/diffhpe/lib/python3.9/site-packages/wandb/sdk/internal/internal_api.py", line 2218, in upload_file
    wandb._sentry.reraise(e)
  File "/home/zhuhe/.conda/envs/diffhpe/lib/python3.9/site-packages/wandb/analytics/sentry.py", line 146, in reraise
    raise exc.with_traceback(sys.exc_info()[2])
  File "/home/zhuhe/.conda/envs/diffhpe/lib/python3.9/site-packages/wandb/sdk/internal/internal_api.py", line 2190, in upload_file
    response.raise_for_status()
  File "/home/zhuhe/.conda/envs/diffhpe/lib/python3.9/site-packages/requests/models.py", line 1021, in raise_for_status
    raise HTTPError(http_error_msg, response=self)
requests.exceptions.HTTPError: 404 Client Error: Not Found for url: https://storage.googleapis.com/wandb-production.appspot.com/ada4321/DiffHPE/1oq413sq/requirements.txt?Expires=1689137293&GoogleAccessId=gorilla-files-url-signer-man%40wandb-production.iam.gserviceaccount.com&Signature=uCim7WXqLPPG%2BwiQksN%2BWHAzE9rCslZKR%2FQw%2FSQ6IEJMuruMI9kGq%2BZvWyMq8VKca9GgyjkUNgBByOi5dIfmWNOfXtlXdUAUs%2BRz%2BuwHWy%2FPShGEXrboGaPXicm3o7YV9n1zEgEZhF26QTXKrP4WuXtY0i4OgwgNtJWoIcKssZDBMPgzh%2BDLK%2Fv84kgMIjVyHirZNHKThA0OeIfev9lCCJphyAY7EFdl%2FzBGipQL7Rd4cCZSk4IV1A7F51WBr%2FPgTgPIWVLJ88UFzjBPF92oI5qfel1c6hJ3kPBJoAUrCPDByFrNC4E%2BtQgjixvfR8q1IZJ4TRZM8yN071TwpdDOAw%3D%3D

During handling of the above exception, another exception occurred:

Traceback (most recent call last):
  File "/home/zhuhe/.conda/envs/diffhpe/lib/python3.9/site-packages/wandb/filesync/upload_job.py", line 127, in push
    self._api.upload_file_retry(
  File "/home/zhuhe/.conda/envs/diffhpe/lib/python3.9/site-packages/wandb/apis/normalize.py", line 51, in wrapper
    raise CommError(message, error)
wandb.errors.CommError: <Response [404]>
2023-07-11 12:48:13,990 ERROR   wandb-upload_1:107870 [upload_job.py:push():136] Failed to upload file: /home/zhuhe/HPE-with-Diffusion/wandb/run-20230711_124756-1oq413sq/files/config.yaml
Traceback (most recent call last):
  File "/home/zhuhe/.conda/envs/diffhpe/lib/python3.9/site-packages/wandb/apis/normalize.py", line 41, in wrapper
    return func(*args, **kwargs)
  File "/home/zhuhe/.conda/envs/diffhpe/lib/python3.9/site-packages/wandb/sdk/lib/retry.py", line 212, in wrapped_fn
    return retrier(*args, **kargs)
  File "/home/zhuhe/.conda/envs/diffhpe/lib/python3.9/site-packages/wandb/sdk/lib/retry.py", line 131, in __call__
    result = self._call_fn(*args, **kwargs)
  File "/home/zhuhe/.conda/envs/diffhpe/lib/python3.9/site-packages/wandb/sdk/internal/internal_api.py", line 2218, in upload_file
    wandb._sentry.reraise(e)
  File "/home/zhuhe/.conda/envs/diffhpe/lib/python3.9/site-packages/wandb/analytics/sentry.py", line 146, in reraise
    raise exc.with_traceback(sys.exc_info()[2])
  File "/home/zhuhe/.conda/envs/diffhpe/lib/python3.9/site-packages/wandb/sdk/internal/internal_api.py", line 2190, in upload_file
    response.raise_for_status()
  File "/home/zhuhe/.conda/envs/diffhpe/lib/python3.9/site-packages/requests/models.py", line 1021, in raise_for_status
    raise HTTPError(http_error_msg, response=self)
requests.exceptions.HTTPError: 404 Client Error: Not Found for url: https://storage.googleapis.com/wandb-production.appspot.com/ada4321/DiffHPE/1oq413sq/config.yaml?Expires=1689137293&GoogleAccessId=gorilla-files-url-signer-man%40wandb-production.iam.gserviceaccount.com&Signature=btqi7HO7bvFlbl2QZvY3iewrJaHxnfyOYazJY52NrhsMFixtPkDYcfWXsbfJIVGU%2Bp5UX7tJ2pXW448uQFw0pXTxeM2w6P0N5wiK5Acqu9TlL2oeze1RHL87JG0TcxsUE8AcGoBprA3qTRNN6Lp1xWSmeozBWjutAm3xDjPG2rhK3QgiKa9kUfjmgSCHmMT%2B5yKm87LYV6tXIJm4LxeOgeTAogL9mAFvD3IQjCJsCrSsbKrpYc%2FlI4sSFTkzWFcY%2FmNTZQuQVuuCyXjHU2wQH%2BAczMcXGhzZvQZ4RHaHqiDBk%2Brzd%2FmesvZakwB7DWme%2Fh6Iwj19cgavJ61Ww4BQuQ%3D%3D

During handling of the above exception, another exception occurred:

Traceback (most recent call last):
  File "/home/zhuhe/.conda/envs/diffhpe/lib/python3.9/site-packages/wandb/filesync/upload_job.py", line 127, in push
    self._api.upload_file_retry(
  File "/home/zhuhe/.conda/envs/diffhpe/lib/python3.9/site-packages/wandb/apis/normalize.py", line 51, in wrapper
    raise CommError(message, error)
wandb.errors.CommError: <Response [404]>
2023-07-11 12:48:13,995 ERROR   wandb-upload_3:107870 [internal_api.py:upload_file():2192] upload_file exception https://storage.googleapis.com/wandb-production.appspot.com/ada4321/DiffHPE/1oq413sq/conda-environment.yaml?Expires=1689137293&GoogleAccessId=gorilla-files-url-signer-man%40wandb-production.iam.gserviceaccount.com&Signature=H8HMy%2BQk59k0zHeYXjRtJqMEKN%2F21u543Eqxi7kxPu8I%2F7WHcSDVCROVC2Bns7qzgXOcFNAHdB6fGlCvKwLOrxLaeSDLbjbOkD%2Bx%2FefYHQVXJU00maJKRE1gtrVL%2BcwFjYErJN1jJr6s5nMV%2BSUgSKW%2BGDrlCUAzBrT91nPknmW35vdzkY8eV4QJClG9oGuTRKWHWiTR3e5Jb2HDPlg30nNzQLEW6eMkMaBs5HVopcZPy3zmR751rYUlBe4RO%2BY71XjO0QyAonH8cmPYn8drKHM0lUQVm%2BhgqFX1Ks0q7ZyJaop36KrTWJUu7eztlTgQRoTjmG3BObKTbDPq34LMzQ%3D%3D: 404 Client Error: Not Found for url: https://storage.googleapis.com/wandb-production.appspot.com/ada4321/DiffHPE/1oq413sq/conda-environment.yaml?Expires=1689137293&GoogleAccessId=gorilla-files-url-signer-man%40wandb-production.iam.gserviceaccount.com&Signature=H8HMy%2BQk59k0zHeYXjRtJqMEKN%2F21u543Eqxi7kxPu8I%2F7WHcSDVCROVC2Bns7qzgXOcFNAHdB6fGlCvKwLOrxLaeSDLbjbOkD%2Bx%2FefYHQVXJU00maJKRE1gtrVL%2BcwFjYErJN1jJr6s5nMV%2BSUgSKW%2BGDrlCUAzBrT91nPknmW35vdzkY8eV4QJClG9oGuTRKWHWiTR3e5Jb2HDPlg30nNzQLEW6eMkMaBs5HVopcZPy3zmR751rYUlBe4RO%2BY71XjO0QyAonH8cmPYn8drKHM0lUQVm%2BhgqFX1Ks0q7ZyJaop36KrTWJUu7eztlTgQRoTjmG3BObKTbDPq34LMzQ%3D%3D
2023-07-11 12:48:14,001 ERROR   wandb-upload_2:107870 [internal_api.py:upload_file():2192] upload_file exception https://storage.googleapis.com/wandb-production.appspot.com/ada4321/DiffHPE/1oq413sq/wandb-summary.json?Expires=1689137293&GoogleAccessId=gorilla-files-url-signer-man%40wandb-production.iam.gserviceaccount.com&Signature=ubhXsPNaUV9JHGG0ZjnbBUDPA5j2hfWOrTo18Lv38dogRWetTsEsRNeXE6iGvj3U3yuKT74eCYUYQB7tDSrJz0%2B869raJadXeLpCEbRsQHwiEpyIyH%2FndoGAVxhUKgSf7ZJRBYTf6R4O5iuEwI7kO7ght2FME%2FArx09LSUwELzBmkRBLTlMjto%2BPvACf7j1ICeunp1EOshqUYueJsMQdQBcHqAYzp5Z%2B4nYwl9TUH%2Bp%2BeZuPECDmIxN9W51YehkEWlzuWoB84canoJufF0vMr1v%2Brkbo%2Bqx%2FOydA5IKHgid9hnJITxFh9zFR9nDIbMtzR2ssM%2FQOXFGuIxxna0adtw%3D%3D: 404 Client Error: Not Found for url: https://storage.googleapis.com/wandb-production.appspot.com/ada4321/DiffHPE/1oq413sq/wandb-summary.json?Expires=1689137293&GoogleAccessId=gorilla-files-url-signer-man%40wandb-production.iam.gserviceaccount.com&Signature=ubhXsPNaUV9JHGG0ZjnbBUDPA5j2hfWOrTo18Lv38dogRWetTsEsRNeXE6iGvj3U3yuKT74eCYUYQB7tDSrJz0%2B869raJadXeLpCEbRsQHwiEpyIyH%2FndoGAVxhUKgSf7ZJRBYTf6R4O5iuEwI7kO7ght2FME%2FArx09LSUwELzBmkRBLTlMjto%2BPvACf7j1ICeunp1EOshqUYueJsMQdQBcHqAYzp5Z%2B4nYwl9TUH%2Bp%2BeZuPECDmIxN9W51YehkEWlzuWoB84canoJufF0vMr1v%2Brkbo%2Bqx%2FOydA5IKHgid9hnJITxFh9zFR9nDIbMtzR2ssM%2FQOXFGuIxxna0adtw%3D%3D
2023-07-11 12:48:14,002 ERROR   wandb-upload_3:107870 [internal_api.py:upload_file():2194] upload_file request headers: {'User-Agent': 'python-requests/2.31.0', 'Accept-Encoding': 'gzip, deflate', 'Accept': '*/*', 'Connection': 'keep-alive', 'Content-Length': '1925'}
2023-07-11 12:48:14,002 ERROR   wandb-upload_2:107870 [internal_api.py:upload_file():2194] upload_file request headers: {'User-Agent': 'python-requests/2.31.0', 'Accept-Encoding': 'gzip, deflate', 'Accept': '*/*', 'Connection': 'keep-alive', 'Content-Length': '27'}
2023-07-11 12:48:14,003 ERROR   wandb-upload_3:107870 [internal_api.py:upload_file():2196] upload_file response body: b'<!DOCTYPE html>\n<html lang=en>\n  <meta charset=utf-8>\n  <meta name=viewport content="initial-scale=1, minimum-scale=1, width=device-width">\n  <title>Error 404 (Not Found)!!1</title>\n  <style>\n    *{margin:0;padding:0}html,code{font:15px/22px arial,sans-serif}html{background:#fff;color:#222;padding:15px}body{margin:7% auto 0;max-width:390px;min-height:180px;padding:30px 0 15px}* > body{background:url(//www.google.com/images/errors/robot.png) 100% 5px no-repeat;padding-right:205px}p{margin:11px 0 22px;overflow:hidden}ins{color:#777;text-decoration:none}a img{border:0}@media screen and (max-width:772px){body{background:none;margin-top:0;max-width:none;padding-right:0}}#logo{background:url(//www.google.com/images/branding/googlelogo/1x/googlelogo_color_150x54dp.png) no-repeat;margin-left:-5px}@media only screen and (min-resolution:192dpi){#logo{background:url(//www.google.com/images/branding/googlelogo/2x/googlelogo_color_150x54dp.png) no-repeat 0% 0%/100% 100%;-moz-border-image:url(//www.google.com/images/branding/googlelogo/2x/googlelogo_color_150x54dp.png) 0}}@media only screen and (-webkit-min-device-pixel-ratio:2){#logo{background:url(//www.google.com/images/branding/googlelogo/2x/googlelogo_color_150x54dp.png) no-repeat;-webkit-background-size:100% 100%}}#logo{display:inline-block;height:54px;width:150px}\n  </style>\n  <a href=//www.google.com/><span id=logo aria-label=Google></span></a>\n  <p><b>404.</b> <ins>That\xe2\x80\x99s an error.</ins>\n  <p>The requested URL <code>/wandb-production.appspot.com/ada4321/DiffHPE/1oq413sq/conda-environment.yaml</code> was not found on this server.  <ins>That\xe2\x80\x99s all we know.</ins>\n'
2023-07-11 12:48:14,003 ERROR   wandb-upload_2:107870 [internal_api.py:upload_file():2196] upload_file response body: b'<!DOCTYPE html>\n<html lang=en>\n  <meta charset=utf-8>\n  <meta name=viewport content="initial-scale=1, minimum-scale=1, width=device-width">\n  <title>Error 404 (Not Found)!!1</title>\n  <style>\n    *{margin:0;padding:0}html,code{font:15px/22px arial,sans-serif}html{background:#fff;color:#222;padding:15px}body{margin:7% auto 0;max-width:390px;min-height:180px;padding:30px 0 15px}* > body{background:url(//www.google.com/images/errors/robot.png) 100% 5px no-repeat;padding-right:205px}p{margin:11px 0 22px;overflow:hidden}ins{color:#777;text-decoration:none}a img{border:0}@media screen and (max-width:772px){body{background:none;margin-top:0;max-width:none;padding-right:0}}#logo{background:url(//www.google.com/images/branding/googlelogo/1x/googlelogo_color_150x54dp.png) no-repeat;margin-left:-5px}@media only screen and (min-resolution:192dpi){#logo{background:url(//www.google.com/images/branding/googlelogo/2x/googlelogo_color_150x54dp.png) no-repeat 0% 0%/100% 100%;-moz-border-image:url(//www.google.com/images/branding/googlelogo/2x/googlelogo_color_150x54dp.png) 0}}@media only screen and (-webkit-min-device-pixel-ratio:2){#logo{background:url(//www.google.com/images/branding/googlelogo/2x/googlelogo_color_150x54dp.png) no-repeat;-webkit-background-size:100% 100%}}#logo{display:inline-block;height:54px;width:150px}\n  </style>\n  <a href=//www.google.com/><span id=logo aria-label=Google></span></a>\n  <p><b>404.</b> <ins>That\xe2\x80\x99s an error.</ins>\n  <p>The requested URL <code>/wandb-production.appspot.com/ada4321/DiffHPE/1oq413sq/wandb-summary.json</code> was not found on this server.  <ins>That\xe2\x80\x99s all we know.</ins>\n'
2023-07-11 12:48:15,106 ERROR   wandb-upload_4:107870 [upload_job.py:push():136] Failed to upload file: /home/zhuhe/HPE-with-Diffusion/wandb/run-20230711_124756-1oq413sq/files/output.log
Traceback (most recent call last):
  File "/home/zhuhe/.conda/envs/diffhpe/lib/python3.9/site-packages/wandb/apis/normalize.py", line 41, in wrapper
    return func(*args, **kwargs)
  File "/home/zhuhe/.conda/envs/diffhpe/lib/python3.9/site-packages/wandb/sdk/lib/retry.py", line 212, in wrapped_fn
    return retrier(*args, **kargs)
  File "/home/zhuhe/.conda/envs/diffhpe/lib/python3.9/site-packages/wandb/sdk/lib/retry.py", line 131, in __call__
    result = self._call_fn(*args, **kwargs)
  File "/home/zhuhe/.conda/envs/diffhpe/lib/python3.9/site-packages/wandb/sdk/internal/internal_api.py", line 2218, in upload_file
    wandb._sentry.reraise(e)
  File "/home/zhuhe/.conda/envs/diffhpe/lib/python3.9/site-packages/wandb/analytics/sentry.py", line 146, in reraise
    raise exc.with_traceback(sys.exc_info()[2])
  File "/home/zhuhe/.conda/envs/diffhpe/lib/python3.9/site-packages/wandb/sdk/internal/internal_api.py", line 2190, in upload_file
    response.raise_for_status()
  File "/home/zhuhe/.conda/envs/diffhpe/lib/python3.9/site-packages/requests/models.py", line 1021, in raise_for_status
    raise HTTPError(http_error_msg, response=self)
requests.exceptions.HTTPError: 404 Client Error: Not Found for url: https://storage.googleapis.com/wandb-production.appspot.com/ada4321/DiffHPE/1oq413sq/output.log?Expires=1689137293&GoogleAccessId=gorilla-files-url-signer-man%40wandb-production.iam.gserviceaccount.com&Signature=wUvL24YJd4QXZp0nS0Mw1yz%2Bc8Y%2Bn%2B49jhqwwTQ2xPRTjvCtRuIDbTrY%2Bf5xauxbAejarFYtRRulbDA7IOMYFUWvcOI9AoGXACyeJA%2BqxEivHqlW0AIxcirKg4AuVH9bgyjnIV4YehFQpKBZBww%2Fm9svGLJjvlEo54DktF8bAlu0%2BWixFuQzduf3rkJCBXY%2BOHv%2FA8GW6KL1eqoRgFbsCWQqCq1G3%2B3N%2Bwmb5PIj0R%2BYxJfjifwqSSjZ%2Bh4Qp7L6atcFSWh1DaOoKAe3xuRrCCkOVQ4RlASrUQzyu8z2f%2BEe7JXnrDoJxVuA1AbtcXZmzFg3UybRqKM0mQqvYae3Jg%3D%3D

During handling of the above exception, another exception occurred:

Traceback (most recent call last):
  File "/home/zhuhe/.conda/envs/diffhpe/lib/python3.9/site-packages/wandb/filesync/upload_job.py", line 127, in push
    self._api.upload_file_retry(
  File "/home/zhuhe/.conda/envs/diffhpe/lib/python3.9/site-packages/wandb/apis/normalize.py", line 51, in wrapper
    raise CommError(message, error)
wandb.errors.CommError: <Response [404]>
2023-07-11 12:48:15,107 ERROR   wandb-upload_2:107870 [upload_job.py:push():136] Failed to upload file: /home/zhuhe/HPE-with-Diffusion/wandb/run-20230711_124756-1oq413sq/files/wandb-summary.json
Traceback (most recent call last):
  File "/home/zhuhe/.conda/envs/diffhpe/lib/python3.9/site-packages/wandb/apis/normalize.py", line 41, in wrapper
    return func(*args, **kwargs)
  File "/home/zhuhe/.conda/envs/diffhpe/lib/python3.9/site-packages/wandb/sdk/lib/retry.py", line 212, in wrapped_fn
    return retrier(*args, **kargs)
  File "/home/zhuhe/.conda/envs/diffhpe/lib/python3.9/site-packages/wandb/sdk/lib/retry.py", line 131, in __call__
    result = self._call_fn(*args, **kwargs)
  File "/home/zhuhe/.conda/envs/diffhpe/lib/python3.9/site-packages/wandb/sdk/internal/internal_api.py", line 2218, in upload_file
    wandb._sentry.reraise(e)
  File "/home/zhuhe/.conda/envs/diffhpe/lib/python3.9/site-packages/wandb/analytics/sentry.py", line 146, in reraise
    raise exc.with_traceback(sys.exc_info()[2])
  File "/home/zhuhe/.conda/envs/diffhpe/lib/python3.9/site-packages/wandb/sdk/internal/internal_api.py", line 2190, in upload_file
    response.raise_for_status()
  File "/home/zhuhe/.conda/envs/diffhpe/lib/python3.9/site-packages/requests/models.py", line 1021, in raise_for_status
    raise HTTPError(http_error_msg, response=self)
requests.exceptions.HTTPError: 404 Client Error: Not Found for url: https://storage.googleapis.com/wandb-production.appspot.com/ada4321/DiffHPE/1oq413sq/wandb-summary.json?Expires=1689137293&GoogleAccessId=gorilla-files-url-signer-man%40wandb-production.iam.gserviceaccount.com&Signature=ubhXsPNaUV9JHGG0ZjnbBUDPA5j2hfWOrTo18Lv38dogRWetTsEsRNeXE6iGvj3U3yuKT74eCYUYQB7tDSrJz0%2B869raJadXeLpCEbRsQHwiEpyIyH%2FndoGAVxhUKgSf7ZJRBYTf6R4O5iuEwI7kO7ght2FME%2FArx09LSUwELzBmkRBLTlMjto%2BPvACf7j1ICeunp1EOshqUYueJsMQdQBcHqAYzp5Z%2B4nYwl9TUH%2Bp%2BeZuPECDmIxN9W51YehkEWlzuWoB84canoJufF0vMr1v%2Brkbo%2Bqx%2FOydA5IKHgid9hnJITxFh9zFR9nDIbMtzR2ssM%2FQOXFGuIxxna0adtw%3D%3D

During handling of the above exception, another exception occurred:

Traceback (most recent call last):
  File "/home/zhuhe/.conda/envs/diffhpe/lib/python3.9/site-packages/wandb/filesync/upload_job.py", line 127, in push
    self._api.upload_file_retry(
  File "/home/zhuhe/.conda/envs/diffhpe/lib/python3.9/site-packages/wandb/apis/normalize.py", line 51, in wrapper
    raise CommError(message, error)
wandb.errors.CommError: <Response [404]>
2023-07-11 12:48:15,107 ERROR   wandb-upload_3:107870 [upload_job.py:push():136] Failed to upload file: /home/zhuhe/HPE-with-Diffusion/wandb/run-20230711_124756-1oq413sq/files/conda-environment.yaml
Traceback (most recent call last):
  File "/home/zhuhe/.conda/envs/diffhpe/lib/python3.9/site-packages/wandb/apis/normalize.py", line 41, in wrapper
    return func(*args, **kwargs)
  File "/home/zhuhe/.conda/envs/diffhpe/lib/python3.9/site-packages/wandb/sdk/lib/retry.py", line 212, in wrapped_fn
    return retrier(*args, **kargs)
  File "/home/zhuhe/.conda/envs/diffhpe/lib/python3.9/site-packages/wandb/sdk/lib/retry.py", line 131, in __call__
    result = self._call_fn(*args, **kwargs)
  File "/home/zhuhe/.conda/envs/diffhpe/lib/python3.9/site-packages/wandb/sdk/internal/internal_api.py", line 2218, in upload_file
    wandb._sentry.reraise(e)
  File "/home/zhuhe/.conda/envs/diffhpe/lib/python3.9/site-packages/wandb/analytics/sentry.py", line 146, in reraise
    raise exc.with_traceback(sys.exc_info()[2])
  File "/home/zhuhe/.conda/envs/diffhpe/lib/python3.9/site-packages/wandb/sdk/internal/internal_api.py", line 2190, in upload_file
    response.raise_for_status()
  File "/home/zhuhe/.conda/envs/diffhpe/lib/python3.9/site-packages/requests/models.py", line 1021, in raise_for_status
    raise HTTPError(http_error_msg, response=self)
requests.exceptions.HTTPError: 404 Client Error: Not Found for url: https://storage.googleapis.com/wandb-production.appspot.com/ada4321/DiffHPE/1oq413sq/conda-environment.yaml?Expires=1689137293&GoogleAccessId=gorilla-files-url-signer-man%40wandb-production.iam.gserviceaccount.com&Signature=H8HMy%2BQk59k0zHeYXjRtJqMEKN%2F21u543Eqxi7kxPu8I%2F7WHcSDVCROVC2Bns7qzgXOcFNAHdB6fGlCvKwLOrxLaeSDLbjbOkD%2Bx%2FefYHQVXJU00maJKRE1gtrVL%2BcwFjYErJN1jJr6s5nMV%2BSUgSKW%2BGDrlCUAzBrT91nPknmW35vdzkY8eV4QJClG9oGuTRKWHWiTR3e5Jb2HDPlg30nNzQLEW6eMkMaBs5HVopcZPy3zmR751rYUlBe4RO%2BY71XjO0QyAonH8cmPYn8drKHM0lUQVm%2BhgqFX1Ks0q7ZyJaop36KrTWJUu7eztlTgQRoTjmG3BObKTbDPq34LMzQ%3D%3D

During handling of the above exception, another exception occurred:

Traceback (most recent call last):
  File "/home/zhuhe/.conda/envs/diffhpe/lib/python3.9/site-packages/wandb/filesync/upload_job.py", line 127, in push
    self._api.upload_file_retry(
  File "/home/zhuhe/.conda/envs/diffhpe/lib/python3.9/site-packages/wandb/apis/normalize.py", line 51, in wrapper
    raise CommError(message, error)
wandb.errors.CommError: <Response [404]>
2023-07-11 12:48:15,110 ERROR   Thread-11 :107870 [step_upload.py:_handle_event():200] Failed to upload file: /home/zhuhe/HPE-with-Diffusion/wandb/run-20230711_124756-1oq413sq/files/config.yaml
Traceback (most recent call last):
  File "/home/zhuhe/.conda/envs/diffhpe/lib/python3.9/site-packages/wandb/apis/normalize.py", line 41, in wrapper
    return func(*args, **kwargs)
  File "/home/zhuhe/.conda/envs/diffhpe/lib/python3.9/site-packages/wandb/sdk/lib/retry.py", line 212, in wrapped_fn
    return retrier(*args, **kargs)
  File "/home/zhuhe/.conda/envs/diffhpe/lib/python3.9/site-packages/wandb/sdk/lib/retry.py", line 131, in __call__
    result = self._call_fn(*args, **kwargs)
  File "/home/zhuhe/.conda/envs/diffhpe/lib/python3.9/site-packages/wandb/sdk/internal/internal_api.py", line 2218, in upload_file
    wandb._sentry.reraise(e)
  File "/home/zhuhe/.conda/envs/diffhpe/lib/python3.9/site-packages/wandb/analytics/sentry.py", line 146, in reraise
    raise exc.with_traceback(sys.exc_info()[2])
  File "/home/zhuhe/.conda/envs/diffhpe/lib/python3.9/site-packages/wandb/sdk/internal/internal_api.py", line 2190, in upload_file
    response.raise_for_status()
  File "/home/zhuhe/.conda/envs/diffhpe/lib/python3.9/site-packages/requests/models.py", line 1021, in raise_for_status
    raise HTTPError(http_error_msg, response=self)
requests.exceptions.HTTPError: 404 Client Error: Not Found for url: https://storage.googleapis.com/wandb-production.appspot.com/ada4321/DiffHPE/1oq413sq/config.yaml?Expires=1689137293&GoogleAccessId=gorilla-files-url-signer-man%40wandb-production.iam.gserviceaccount.com&Signature=btqi7HO7bvFlbl2QZvY3iewrJaHxnfyOYazJY52NrhsMFixtPkDYcfWXsbfJIVGU%2Bp5UX7tJ2pXW448uQFw0pXTxeM2w6P0N5wiK5Acqu9TlL2oeze1RHL87JG0TcxsUE8AcGoBprA3qTRNN6Lp1xWSmeozBWjutAm3xDjPG2rhK3QgiKa9kUfjmgSCHmMT%2B5yKm87LYV6tXIJm4LxeOgeTAogL9mAFvD3IQjCJsCrSsbKrpYc%2FlI4sSFTkzWFcY%2FmNTZQuQVuuCyXjHU2wQH%2BAczMcXGhzZvQZ4RHaHqiDBk%2Brzd%2FmesvZakwB7DWme%2Fh6Iwj19cgavJ61Ww4BQuQ%3D%3D

During handling of the above exception, another exception occurred:

Traceback (most recent call last):
  File "/home/zhuhe/.conda/envs/diffhpe/lib/python3.9/concurrent/futures/thread.py", line 58, in run
    result = self.fn(*self.args, **self.kwargs)
  File "/home/zhuhe/.conda/envs/diffhpe/lib/python3.9/site-packages/wandb/filesync/step_upload.py", line 288, in run_and_notify
    self._do_upload_sync(event)
  File "/home/zhuhe/.conda/envs/diffhpe/lib/python3.9/site-packages/wandb/filesync/step_upload.py", line 330, in _do_upload_sync
    job.run()
  File "/home/zhuhe/.conda/envs/diffhpe/lib/python3.9/site-packages/wandb/filesync/upload_job.py", line 57, in run
    self.push()
  File "/home/zhuhe/.conda/envs/diffhpe/lib/python3.9/site-packages/wandb/filesync/upload_job.py", line 127, in push
    self._api.upload_file_retry(
  File "/home/zhuhe/.conda/envs/diffhpe/lib/python3.9/site-packages/wandb/apis/normalize.py", line 51, in wrapper
    raise CommError(message, error)
wandb.errors.CommError: <Response [404]>
2023-07-11 12:48:15,113 ERROR   Thread-11 :107870 [step_upload.py:_handle_event():200] Failed to upload file: /home/zhuhe/HPE-with-Diffusion/wandb/run-20230711_124756-1oq413sq/files/requirements.txt
Traceback (most recent call last):
  File "/home/zhuhe/.conda/envs/diffhpe/lib/python3.9/site-packages/wandb/apis/normalize.py", line 41, in wrapper
    return func(*args, **kwargs)
  File "/home/zhuhe/.conda/envs/diffhpe/lib/python3.9/site-packages/wandb/sdk/lib/retry.py", line 212, in wrapped_fn
    return retrier(*args, **kargs)
  File "/home/zhuhe/.conda/envs/diffhpe/lib/python3.9/site-packages/wandb/sdk/lib/retry.py", line 131, in __call__
    result = self._call_fn(*args, **kwargs)
  File "/home/zhuhe/.conda/envs/diffhpe/lib/python3.9/site-packages/wandb/sdk/internal/internal_api.py", line 2218, in upload_file
    wandb._sentry.reraise(e)
  File "/home/zhuhe/.conda/envs/diffhpe/lib/python3.9/site-packages/wandb/analytics/sentry.py", line 146, in reraise
    raise exc.with_traceback(sys.exc_info()[2])
  File "/home/zhuhe/.conda/envs/diffhpe/lib/python3.9/site-packages/wandb/sdk/internal/internal_api.py", line 2190, in upload_file
    response.raise_for_status()
  File "/home/zhuhe/.conda/envs/diffhpe/lib/python3.9/site-packages/requests/models.py", line 1021, in raise_for_status
    raise HTTPError(http_error_msg, response=self)
requests.exceptions.HTTPError: 404 Client Error: Not Found for url: https://storage.googleapis.com/wandb-production.appspot.com/ada4321/DiffHPE/1oq413sq/requirements.txt?Expires=1689137293&GoogleAccessId=gorilla-files-url-signer-man%40wandb-production.iam.gserviceaccount.com&Signature=uCim7WXqLPPG%2BwiQksN%2BWHAzE9rCslZKR%2FQw%2FSQ6IEJMuruMI9kGq%2BZvWyMq8VKca9GgyjkUNgBByOi5dIfmWNOfXtlXdUAUs%2BRz%2BuwHWy%2FPShGEXrboGaPXicm3o7YV9n1zEgEZhF26QTXKrP4WuXtY0i4OgwgNtJWoIcKssZDBMPgzh%2BDLK%2Fv84kgMIjVyHirZNHKThA0OeIfev9lCCJphyAY7EFdl%2FzBGipQL7Rd4cCZSk4IV1A7F51WBr%2FPgTgPIWVLJ88UFzjBPF92oI5qfel1c6hJ3kPBJoAUrCPDByFrNC4E%2BtQgjixvfR8q1IZJ4TRZM8yN071TwpdDOAw%3D%3D

During handling of the above exception, another exception occurred:

Traceback (most recent call last):
  File "/home/zhuhe/.conda/envs/diffhpe/lib/python3.9/concurrent/futures/thread.py", line 58, in run
    result = self.fn(*self.args, **self.kwargs)
  File "/home/zhuhe/.conda/envs/diffhpe/lib/python3.9/site-packages/wandb/filesync/step_upload.py", line 288, in run_and_notify
    self._do_upload_sync(event)
  File "/home/zhuhe/.conda/envs/diffhpe/lib/python3.9/site-packages/wandb/filesync/step_upload.py", line 330, in _do_upload_sync
    job.run()
  File "/home/zhuhe/.conda/envs/diffhpe/lib/python3.9/site-packages/wandb/filesync/upload_job.py", line 57, in run
    self.push()
  File "/home/zhuhe/.conda/envs/diffhpe/lib/python3.9/site-packages/wandb/filesync/upload_job.py", line 127, in push
    self._api.upload_file_retry(
  File "/home/zhuhe/.conda/envs/diffhpe/lib/python3.9/site-packages/wandb/apis/normalize.py", line 51, in wrapper
    raise CommError(message, error)
wandb.errors.CommError: <Response [404]>
2023-07-11 12:48:15,761 DEBUG   HandlerThread:107870 [handler.py:handle_request():144] handle_request: keepalive
2023-07-11 12:48:15,801 ERROR   Thread-11 :107870 [step_upload.py:_handle_event():200] Failed to upload file: /home/zhuhe/HPE-with-Diffusion/wandb/run-20230711_124756-1oq413sq/files/output.log
Traceback (most recent call last):
  File "/home/zhuhe/.conda/envs/diffhpe/lib/python3.9/site-packages/wandb/apis/normalize.py", line 41, in wrapper
    return func(*args, **kwargs)
  File "/home/zhuhe/.conda/envs/diffhpe/lib/python3.9/site-packages/wandb/sdk/lib/retry.py", line 212, in wrapped_fn
    return retrier(*args, **kargs)
  File "/home/zhuhe/.conda/envs/diffhpe/lib/python3.9/site-packages/wandb/sdk/lib/retry.py", line 131, in __call__
    result = self._call_fn(*args, **kwargs)
  File "/home/zhuhe/.conda/envs/diffhpe/lib/python3.9/site-packages/wandb/sdk/internal/internal_api.py", line 2218, in upload_file
    wandb._sentry.reraise(e)
  File "/home/zhuhe/.conda/envs/diffhpe/lib/python3.9/site-packages/wandb/analytics/sentry.py", line 146, in reraise
    raise exc.with_traceback(sys.exc_info()[2])
  File "/home/zhuhe/.conda/envs/diffhpe/lib/python3.9/site-packages/wandb/sdk/internal/internal_api.py", line 2190, in upload_file
    response.raise_for_status()
  File "/home/zhuhe/.conda/envs/diffhpe/lib/python3.9/site-packages/requests/models.py", line 1021, in raise_for_status
    raise HTTPError(http_error_msg, response=self)
requests.exceptions.HTTPError: 404 Client Error: Not Found for url: https://storage.googleapis.com/wandb-production.appspot.com/ada4321/DiffHPE/1oq413sq/output.log?Expires=1689137293&GoogleAccessId=gorilla-files-url-signer-man%40wandb-production.iam.gserviceaccount.com&Signature=wUvL24YJd4QXZp0nS0Mw1yz%2Bc8Y%2Bn%2B49jhqwwTQ2xPRTjvCtRuIDbTrY%2Bf5xauxbAejarFYtRRulbDA7IOMYFUWvcOI9AoGXACyeJA%2BqxEivHqlW0AIxcirKg4AuVH9bgyjnIV4YehFQpKBZBww%2Fm9svGLJjvlEo54DktF8bAlu0%2BWixFuQzduf3rkJCBXY%2BOHv%2FA8GW6KL1eqoRgFbsCWQqCq1G3%2B3N%2Bwmb5PIj0R%2BYxJfjifwqSSjZ%2Bh4Qp7L6atcFSWh1DaOoKAe3xuRrCCkOVQ4RlASrUQzyu8z2f%2BEe7JXnrDoJxVuA1AbtcXZmzFg3UybRqKM0mQqvYae3Jg%3D%3D

During handling of the above exception, another exception occurred:

Traceback (most recent call last):
  File "/home/zhuhe/.conda/envs/diffhpe/lib/python3.9/concurrent/futures/thread.py", line 58, in run
    result = self.fn(*self.args, **self.kwargs)
  File "/home/zhuhe/.conda/envs/diffhpe/lib/python3.9/site-packages/wandb/filesync/step_upload.py", line 288, in run_and_notify
    self._do_upload_sync(event)
  File "/home/zhuhe/.conda/envs/diffhpe/lib/python3.9/site-packages/wandb/filesync/step_upload.py", line 330, in _do_upload_sync
    job.run()
  File "/home/zhuhe/.conda/envs/diffhpe/lib/python3.9/site-packages/wandb/filesync/upload_job.py", line 57, in run
    self.push()
  File "/home/zhuhe/.conda/envs/diffhpe/lib/python3.9/site-packages/wandb/filesync/upload_job.py", line 127, in push
    self._api.upload_file_retry(
  File "/home/zhuhe/.conda/envs/diffhpe/lib/python3.9/site-packages/wandb/apis/normalize.py", line 51, in wrapper
    raise CommError(message, error)
wandb.errors.CommError: <Response [404]>
2023-07-11 12:48:15,802 ERROR   Thread-11 :107870 [step_upload.py:_handle_event():200] Failed to upload file: /home/zhuhe/HPE-with-Diffusion/wandb/run-20230711_124756-1oq413sq/files/wandb-summary.json
Traceback (most recent call last):
  File "/home/zhuhe/.conda/envs/diffhpe/lib/python3.9/site-packages/wandb/apis/normalize.py", line 41, in wrapper
    return func(*args, **kwargs)
  File "/home/zhuhe/.conda/envs/diffhpe/lib/python3.9/site-packages/wandb/sdk/lib/retry.py", line 212, in wrapped_fn
    return retrier(*args, **kargs)
  File "/home/zhuhe/.conda/envs/diffhpe/lib/python3.9/site-packages/wandb/sdk/lib/retry.py", line 131, in __call__
    result = self._call_fn(*args, **kwargs)
  File "/home/zhuhe/.conda/envs/diffhpe/lib/python3.9/site-packages/wandb/sdk/internal/internal_api.py", line 2218, in upload_file
    wandb._sentry.reraise(e)
  File "/home/zhuhe/.conda/envs/diffhpe/lib/python3.9/site-packages/wandb/analytics/sentry.py", line 146, in reraise
    raise exc.with_traceback(sys.exc_info()[2])
  File "/home/zhuhe/.conda/envs/diffhpe/lib/python3.9/site-packages/wandb/sdk/internal/internal_api.py", line 2190, in upload_file
    response.raise_for_status()
  File "/home/zhuhe/.conda/envs/diffhpe/lib/python3.9/site-packages/requests/models.py", line 1021, in raise_for_status
    raise HTTPError(http_error_msg, response=self)
requests.exceptions.HTTPError: 404 Client Error: Not Found for url: https://storage.googleapis.com/wandb-production.appspot.com/ada4321/DiffHPE/1oq413sq/wandb-summary.json?Expires=1689137293&GoogleAccessId=gorilla-files-url-signer-man%40wandb-production.iam.gserviceaccount.com&Signature=ubhXsPNaUV9JHGG0ZjnbBUDPA5j2hfWOrTo18Lv38dogRWetTsEsRNeXE6iGvj3U3yuKT74eCYUYQB7tDSrJz0%2B869raJadXeLpCEbRsQHwiEpyIyH%2FndoGAVxhUKgSf7ZJRBYTf6R4O5iuEwI7kO7ght2FME%2FArx09LSUwELzBmkRBLTlMjto%2BPvACf7j1ICeunp1EOshqUYueJsMQdQBcHqAYzp5Z%2B4nYwl9TUH%2Bp%2BeZuPECDmIxN9W51YehkEWlzuWoB84canoJufF0vMr1v%2Brkbo%2Bqx%2FOydA5IKHgid9hnJITxFh9zFR9nDIbMtzR2ssM%2FQOXFGuIxxna0adtw%3D%3D

During handling of the above exception, another exception occurred:

Traceback (most recent call last):
  File "/home/zhuhe/.conda/envs/diffhpe/lib/python3.9/concurrent/futures/thread.py", line 58, in run
    result = self.fn(*self.args, **self.kwargs)
  File "/home/zhuhe/.conda/envs/diffhpe/lib/python3.9/site-packages/wandb/filesync/step_upload.py", line 288, in run_and_notify
    self._do_upload_sync(event)
  File "/home/zhuhe/.conda/envs/diffhpe/lib/python3.9/site-packages/wandb/filesync/step_upload.py", line 330, in _do_upload_sync
    job.run()
  File "/home/zhuhe/.conda/envs/diffhpe/lib/python3.9/site-packages/wandb/filesync/upload_job.py", line 57, in run
    self.push()
  File "/home/zhuhe/.conda/envs/diffhpe/lib/python3.9/site-packages/wandb/filesync/upload_job.py", line 127, in push
    self._api.upload_file_retry(
  File "/home/zhuhe/.conda/envs/diffhpe/lib/python3.9/site-packages/wandb/apis/normalize.py", line 51, in wrapper
    raise CommError(message, error)
wandb.errors.CommError: <Response [404]>
2023-07-11 12:48:15,803 ERROR   Thread-11 :107870 [step_upload.py:_handle_event():200] Failed to upload file: /home/zhuhe/HPE-with-Diffusion/wandb/run-20230711_124756-1oq413sq/files/conda-environment.yaml
Traceback (most recent call last):
  File "/home/zhuhe/.conda/envs/diffhpe/lib/python3.9/site-packages/wandb/apis/normalize.py", line 41, in wrapper
    return func(*args, **kwargs)
  File "/home/zhuhe/.conda/envs/diffhpe/lib/python3.9/site-packages/wandb/sdk/lib/retry.py", line 212, in wrapped_fn
    return retrier(*args, **kargs)
  File "/home/zhuhe/.conda/envs/diffhpe/lib/python3.9/site-packages/wandb/sdk/lib/retry.py", line 131, in __call__
    result = self._call_fn(*args, **kwargs)
  File "/home/zhuhe/.conda/envs/diffhpe/lib/python3.9/site-packages/wandb/sdk/internal/internal_api.py", line 2218, in upload_file
    wandb._sentry.reraise(e)
  File "/home/zhuhe/.conda/envs/diffhpe/lib/python3.9/site-packages/wandb/analytics/sentry.py", line 146, in reraise
    raise exc.with_traceback(sys.exc_info()[2])
  File "/home/zhuhe/.conda/envs/diffhpe/lib/python3.9/site-packages/wandb/sdk/internal/internal_api.py", line 2190, in upload_file
    response.raise_for_status()
  File "/home/zhuhe/.conda/envs/diffhpe/lib/python3.9/site-packages/requests/models.py", line 1021, in raise_for_status
    raise HTTPError(http_error_msg, response=self)
requests.exceptions.HTTPError: 404 Client Error: Not Found for url: https://storage.googleapis.com/wandb-production.appspot.com/ada4321/DiffHPE/1oq413sq/conda-environment.yaml?Expires=1689137293&GoogleAccessId=gorilla-files-url-signer-man%40wandb-production.iam.gserviceaccount.com&Signature=H8HMy%2BQk59k0zHeYXjRtJqMEKN%2F21u543Eqxi7kxPu8I%2F7WHcSDVCROVC2Bns7qzgXOcFNAHdB6fGlCvKwLOrxLaeSDLbjbOkD%2Bx%2FefYHQVXJU00maJKRE1gtrVL%2BcwFjYErJN1jJr6s5nMV%2BSUgSKW%2BGDrlCUAzBrT91nPknmW35vdzkY8eV4QJClG9oGuTRKWHWiTR3e5Jb2HDPlg30nNzQLEW6eMkMaBs5HVopcZPy3zmR751rYUlBe4RO%2BY71XjO0QyAonH8cmPYn8drKHM0lUQVm%2BhgqFX1Ks0q7ZyJaop36KrTWJUu7eztlTgQRoTjmG3BObKTbDPq34LMzQ%3D%3D

During handling of the above exception, another exception occurred:

Traceback (most recent call last):
  File "/home/zhuhe/.conda/envs/diffhpe/lib/python3.9/concurrent/futures/thread.py", line 58, in run
    result = self.fn(*self.args, **self.kwargs)
  File "/home/zhuhe/.conda/envs/diffhpe/lib/python3.9/site-packages/wandb/filesync/step_upload.py", line 288, in run_and_notify
    self._do_upload_sync(event)
  File "/home/zhuhe/.conda/envs/diffhpe/lib/python3.9/site-packages/wandb/filesync/step_upload.py", line 330, in _do_upload_sync
    job.run()
  File "/home/zhuhe/.conda/envs/diffhpe/lib/python3.9/site-packages/wandb/filesync/upload_job.py", line 57, in run
    self.push()
  File "/home/zhuhe/.conda/envs/diffhpe/lib/python3.9/site-packages/wandb/filesync/upload_job.py", line 127, in push
    self._api.upload_file_retry(
  File "/home/zhuhe/.conda/envs/diffhpe/lib/python3.9/site-packages/wandb/apis/normalize.py", line 51, in wrapper
    raise CommError(message, error)
wandb.errors.CommError: <Response [404]>
2023-07-11 12:48:16,004 INFO    Thread-11 :107870 [sender.py:transition_state():602] send defer: 11
2023-07-11 12:48:16,005 DEBUG   HandlerThread:107870 [handler.py:handle_request():144] handle_request: defer
2023-07-11 12:48:16,005 INFO    HandlerThread:107870 [handler.py:handle_request_defer():170] handle defer: 11
2023-07-11 12:48:16,006 DEBUG   SenderThread:107870 [sender.py:send_request():396] send_request: defer
2023-07-11 12:48:16,006 INFO    SenderThread:107870 [sender.py:send_request_defer():598] handle sender defer: 11
2023-07-11 12:48:16,006 INFO    SenderThread:107870 [file_pusher.py:join():164] waiting for file pusher
2023-07-11 12:48:16,006 INFO    SenderThread:107870 [sender.py:transition_state():602] send defer: 12
2023-07-11 12:48:16,007 DEBUG   HandlerThread:107870 [handler.py:handle_request():144] handle_request: defer
2023-07-11 12:48:16,007 INFO    HandlerThread:107870 [handler.py:handle_request_defer():170] handle defer: 12
2023-07-11 12:48:16,007 DEBUG   SenderThread:107870 [sender.py:send_request():396] send_request: defer
2023-07-11 12:48:16,007 INFO    SenderThread:107870 [sender.py:send_request_defer():598] handle sender defer: 12
2023-07-11 12:48:16,256 INFO    SenderThread:107870 [sender.py:transition_state():602] send defer: 13
2023-07-11 12:48:16,257 DEBUG   HandlerThread:107870 [handler.py:handle_request():144] handle_request: defer
2023-07-11 12:48:16,257 INFO    HandlerThread:107870 [handler.py:handle_request_defer():170] handle defer: 13
2023-07-11 12:48:16,258 DEBUG   SenderThread:107870 [sender.py:send_request():396] send_request: defer
2023-07-11 12:48:16,258 INFO    SenderThread:107870 [sender.py:send_request_defer():598] handle sender defer: 13
2023-07-11 12:48:16,258 INFO    SenderThread:107870 [sender.py:transition_state():602] send defer: 14
2023-07-11 12:48:16,258 DEBUG   HandlerThread:107870 [handler.py:handle_request():144] handle_request: defer
2023-07-11 12:48:16,258 INFO    HandlerThread:107870 [handler.py:handle_request_defer():170] handle defer: 14
2023-07-11 12:48:16,259 DEBUG   SenderThread:107870 [sender.py:send():369] send: final
2023-07-11 12:48:16,259 DEBUG   SenderThread:107870 [sender.py:send():369] send: footer
2023-07-11 12:48:16,260 DEBUG   SenderThread:107870 [sender.py:send_request():396] send_request: defer
2023-07-11 12:48:16,260 INFO    SenderThread:107870 [sender.py:send_request_defer():598] handle sender defer: 14
2023-07-11 12:48:16,261 DEBUG   HandlerThread:107870 [handler.py:handle_request():144] handle_request: poll_exit
2023-07-11 12:48:16,261 DEBUG   SenderThread:107870 [sender.py:send_request():396] send_request: poll_exit
2023-07-11 12:48:16,262 DEBUG   HandlerThread:107870 [handler.py:handle_request():144] handle_request: server_info
2023-07-11 12:48:16,263 DEBUG   HandlerThread:107870 [handler.py:handle_request():144] handle_request: get_summary
2023-07-11 12:48:16,263 DEBUG   HandlerThread:107870 [handler.py:handle_request():144] handle_request: sampled_history
2023-07-11 12:48:16,264 DEBUG   SenderThread:107870 [sender.py:send_request():396] send_request: server_info
2023-07-11 12:48:16,718 INFO    MainThread:107870 [wandb_run.py:_footer_history_summary_info():3467] rendering history
2023-07-11 12:48:16,719 INFO    MainThread:107870 [wandb_run.py:_footer_history_summary_info():3499] rendering summary
2023-07-11 12:48:16,719 INFO    MainThread:107870 [wandb_run.py:_footer_sync_info():3426] logging synced files
2023-07-11 12:48:16,719 DEBUG   HandlerThread:107870 [handler.py:handle_request():144] handle_request: shutdown
2023-07-11 12:48:16,720 INFO    HandlerThread:107870 [handler.py:finish():854] shutting down handler
2023-07-11 12:48:17,264 INFO    WriterThread:107870 [datastore.py:close():298] close: /home/zhuhe/HPE-with-Diffusion/wandb/run-20230711_124756-1oq413sq/run-1oq413sq.wandb
2023-07-11 12:48:17,718 INFO    SenderThread:107870 [sender.py:finish():1526] shutting down sender
2023-07-11 12:48:17,718 INFO    SenderThread:107870 [file_pusher.py:finish():159] shutting down file pusher
2023-07-11 12:48:17,718 INFO    SenderThread:107870 [file_pusher.py:join():164] waiting for file pusher
