2023-07-10 15:38:16,304 INFO    StreamThr :45916 [internal.py:wandb_internal():86] W&B internal server running at pid: 45916, started at: 2023-07-10 15:38:16.304042
2023-07-10 15:38:16,305 DEBUG   HandlerThread:45916 [handler.py:handle_request():144] handle_request: status
2023-07-10 15:38:16,306 INFO    WriterThread:45916 [datastore.py:open_for_write():85] open: /home/zhuhe/HPE-with-Diffusion/wandb/run-20230710_153816-a3ox2pn0/run-a3ox2pn0.wandb
2023-07-10 15:38:16,307 DEBUG   SenderThread:45916 [sender.py:send():369] send: header
2023-07-10 15:38:16,307 DEBUG   SenderThread:45916 [sender.py:send():369] send: run
2023-07-10 15:38:17,154 INFO    SenderThread:45916 [dir_watcher.py:__init__():211] watching files in: /home/zhuhe/HPE-with-Diffusion/wandb/run-20230710_153816-a3ox2pn0/files
2023-07-10 15:38:17,154 INFO    SenderThread:45916 [sender.py:_start_run_threads():1100] run started: a3ox2pn0 with start time 1688974696.303792
2023-07-10 15:38:17,154 DEBUG   SenderThread:45916 [sender.py:send_request():396] send_request: summary_record
2023-07-10 15:38:17,154 INFO    SenderThread:45916 [sender.py:_save_file():1354] saving file wandb-summary.json with policy end
2023-07-10 15:38:17,155 DEBUG   HandlerThread:45916 [handler.py:handle_request():144] handle_request: check_version
2023-07-10 15:38:17,156 DEBUG   SenderThread:45916 [sender.py:send_request():396] send_request: check_version
2023-07-10 15:38:17,335 DEBUG   HandlerThread:45916 [handler.py:handle_request():144] handle_request: run_start
2023-07-10 15:38:17,340 DEBUG   HandlerThread:45916 [system_info.py:__init__():31] System info init
2023-07-10 15:38:17,340 DEBUG   HandlerThread:45916 [system_info.py:__init__():46] System info init done
2023-07-10 15:38:17,340 INFO    HandlerThread:45916 [system_monitor.py:start():181] Starting system monitor
2023-07-10 15:38:17,340 INFO    SystemMonitor:45916 [system_monitor.py:_start():145] Starting system asset monitoring threads
2023-07-10 15:38:17,341 INFO    HandlerThread:45916 [system_monitor.py:probe():201] Collecting system info
2023-07-10 15:38:17,341 INFO    SystemMonitor:45916 [interfaces.py:start():190] Started cpu monitoring
2023-07-10 15:38:17,341 INFO    SystemMonitor:45916 [interfaces.py:start():190] Started disk monitoring
2023-07-10 15:38:17,342 INFO    SystemMonitor:45916 [interfaces.py:start():190] Started gpu monitoring
2023-07-10 15:38:17,343 INFO    SystemMonitor:45916 [interfaces.py:start():190] Started memory monitoring
2023-07-10 15:38:17,343 INFO    SystemMonitor:45916 [interfaces.py:start():190] Started network monitoring
2023-07-10 15:38:17,360 DEBUG   HandlerThread:45916 [system_info.py:probe():195] Probing system
2023-07-10 15:38:17,363 DEBUG   HandlerThread:45916 [gitlib.py:_init_repo():53] git repository is invalid
2023-07-10 15:38:17,363 DEBUG   HandlerThread:45916 [system_info.py:probe():240] Probing system done
2023-07-10 15:38:17,363 DEBUG   HandlerThread:45916 [system_monitor.py:probe():210] {'os': 'Linux-5.19.0-46-generic-x86_64-with-glibc2.35', 'python': '3.9.16', 'heartbeatAt': '2023-07-10T07:38:17.360088', 'startedAt': '2023-07-10T07:38:16.300652', 'docker': None, 'cuda': None, 'args': ('--phase', 'train', '--gpu_ids', '1'), 'state': 'running', 'program': '/home/zhuhe/HPE-with-Diffusion/main.py', 'codePath': 'main.py', 'host': '415-2', 'username': 'zhuhe', 'executable': '/home/zhuhe/.conda/envs/diffhpe/bin/python', 'cpu_count': 16, 'cpu_count_logical': 24, 'cpu_freq': {'current': 3741.6277083333334, 'min': 800.0, 'max': 4783.333333333333}, 'cpu_freq_per_core': [{'current': 5100.0, 'min': 800.0, 'max': 5100.0}, {'current': 2100.0, 'min': 800.0, 'max': 5100.0}, {'current': 5100.0, 'min': 800.0, 'max': 5100.0}, {'current': 5100.0, 'min': 800.0, 'max': 5100.0}, {'current': 5100.0, 'min': 800.0, 'max': 5100.0}, {'current': 5103.953, 'min': 800.0, 'max': 5100.0}, {'current': 5096.853, 'min': 800.0, 'max': 5100.0}, {'current': 2100.0, 'min': 800.0, 'max': 5100.0}, {'current': 5100.0, 'min': 800.0, 'max': 5200.0}, {'current': 2100.0, 'min': 800.0, 'max': 5200.0}, {'current': 5100.0, 'min': 800.0, 'max': 5200.0}, {'current': 5100.0, 'min': 800.0, 'max': 5200.0}, {'current': 5100.02, 'min': 800.0, 'max': 5100.0}, {'current': 2100.0, 'min': 800.0, 'max': 5100.0}, {'current': 5100.0, 'min': 800.0, 'max': 5100.0}, {'current': 5100.0, 'min': 800.0, 'max': 5100.0}, {'current': 3958.512, 'min': 800.0, 'max': 4100.0}, {'current': 2100.0, 'min': 800.0, 'max': 4100.0}, {'current': 2100.0, 'min': 800.0, 'max': 4100.0}, {'current': 2100.0, 'min': 800.0, 'max': 4100.0}, {'current': 3703.285, 'min': 800.0, 'max': 4100.0}, {'current': 2100.0, 'min': 800.0, 'max': 4100.0}, {'current': 2100.0, 'min': 800.0, 'max': 4100.0}, {'current': 2100.0, 'min': 800.0, 'max': 4100.0}], 'disk': {'total': 93.31179428100586, 'used': 0.01844024658203125}, 'gpu': 'NVIDIA GeForce RTX 3090', 'gpu_count': 2, 'gpu_devices': [{'name': 'NVIDIA GeForce RTX 3090', 'memory_total': 25769803776}, {'name': 'NVIDIA GeForce RTX 3090', 'memory_total': 25769803776}], 'memory': {'total': 31.185562133789062}}
2023-07-10 15:38:17,363 INFO    HandlerThread:45916 [system_monitor.py:probe():211] Finished collecting system info
2023-07-10 15:38:17,363 INFO    HandlerThread:45916 [system_monitor.py:probe():214] Publishing system info
2023-07-10 15:38:17,363 DEBUG   HandlerThread:45916 [system_info.py:_save_pip():51] Saving list of pip packages installed into the current environment
2023-07-10 15:38:17,363 DEBUG   HandlerThread:45916 [system_info.py:_save_pip():67] Saving pip packages done
2023-07-10 15:38:17,363 DEBUG   HandlerThread:45916 [system_info.py:_save_conda():74] Saving list of conda packages installed into the current environment
2023-07-10 15:38:18,155 INFO    Thread-12 :45916 [dir_watcher.py:_on_file_created():272] file/dir created: /home/zhuhe/HPE-with-Diffusion/wandb/run-20230710_153816-a3ox2pn0/files/requirements.txt
2023-07-10 15:38:18,155 INFO    Thread-12 :45916 [dir_watcher.py:_on_file_created():272] file/dir created: /home/zhuhe/HPE-with-Diffusion/wandb/run-20230710_153816-a3ox2pn0/files/wandb-summary.json
2023-07-10 15:38:18,155 INFO    Thread-12 :45916 [dir_watcher.py:_on_file_created():272] file/dir created: /home/zhuhe/HPE-with-Diffusion/wandb/run-20230710_153816-a3ox2pn0/files/conda-environment.yaml
2023-07-10 15:38:18,221 DEBUG   HandlerThread:45916 [system_info.py:_save_conda():86] Saving conda packages done
2023-07-10 15:38:18,221 INFO    HandlerThread:45916 [system_monitor.py:probe():216] Finished publishing system info
2023-07-10 15:38:18,223 DEBUG   SenderThread:45916 [sender.py:send():369] send: files
2023-07-10 15:38:18,223 INFO    SenderThread:45916 [sender.py:_save_file():1354] saving file wandb-metadata.json with policy now
2023-07-10 15:38:18,226 DEBUG   HandlerThread:45916 [handler.py:handle_request():144] handle_request: stop_status
2023-07-10 15:38:18,226 DEBUG   SenderThread:45916 [sender.py:send_request():396] send_request: stop_status
2023-07-10 15:38:18,735 ERROR   wandb-upload_0:45916 [internal_api.py:upload_file():2192] upload_file exception https://storage.googleapis.com/wandb-production.appspot.com/ada4321/DiffHPE/a3ox2pn0/wandb-metadata.json?Expires=1689061098&GoogleAccessId=gorilla-files-url-signer-man%40wandb-production.iam.gserviceaccount.com&Signature=tsI3bXVL1r5g1dG5g%2FIl4SC1DHl0T7esrpx%2FsKKhE%2FTFtDUpA2ao2U%2BKlSIfyE7sdXBQwLVgeWWP%2BGkEcOqVFv92XtlGLTjdAowJUoKyGLoiMuAcJcVPkBfM0kBPzwbvsO7A0quwMTyp%2BwAMVEjqjTUVfrfWtBLPIUYTQ8J7I%2BH5RrYmZanidv1xPBNhwf89kK0%2BBc4KS%2FcNBTfVg6IqBFdHCTBSDMzDiJ%2BcxX9Gv9hdS10843T4dwBeSvnEILADnpAh1LKnxU7etggJB1ZH74HTLQtIKNjpzI9LpSyGJP4i31FhSPVTTIQA3M20DLmEmVqTNn8boe13Yu93GKeRPA%3D%3D: 404 Client Error: Not Found for url: https://storage.googleapis.com/wandb-production.appspot.com/ada4321/DiffHPE/a3ox2pn0/wandb-metadata.json?Expires=1689061098&GoogleAccessId=gorilla-files-url-signer-man%40wandb-production.iam.gserviceaccount.com&Signature=tsI3bXVL1r5g1dG5g%2FIl4SC1DHl0T7esrpx%2FsKKhE%2FTFtDUpA2ao2U%2BKlSIfyE7sdXBQwLVgeWWP%2BGkEcOqVFv92XtlGLTjdAowJUoKyGLoiMuAcJcVPkBfM0kBPzwbvsO7A0quwMTyp%2BwAMVEjqjTUVfrfWtBLPIUYTQ8J7I%2BH5RrYmZanidv1xPBNhwf89kK0%2BBc4KS%2FcNBTfVg6IqBFdHCTBSDMzDiJ%2BcxX9Gv9hdS10843T4dwBeSvnEILADnpAh1LKnxU7etggJB1ZH74HTLQtIKNjpzI9LpSyGJP4i31FhSPVTTIQA3M20DLmEmVqTNn8boe13Yu93GKeRPA%3D%3D
2023-07-10 15:38:18,735 ERROR   wandb-upload_0:45916 [internal_api.py:upload_file():2194] upload_file request headers: {'User-Agent': 'python-requests/2.31.0', 'Accept-Encoding': 'gzip, deflate', 'Accept': '*/*', 'Connection': 'keep-alive', 'Content-Length': '3688'}
2023-07-10 15:38:18,735 ERROR   wandb-upload_0:45916 [internal_api.py:upload_file():2196] upload_file response body: b'<!DOCTYPE html>\n<html lang=en>\n  <meta charset=utf-8>\n  <meta name=viewport content="initial-scale=1, minimum-scale=1, width=device-width">\n  <title>Error 404 (Not Found)!!1</title>\n  <style>\n    *{margin:0;padding:0}html,code{font:15px/22px arial,sans-serif}html{background:#fff;color:#222;padding:15px}body{margin:7% auto 0;max-width:390px;min-height:180px;padding:30px 0 15px}* > body{background:url(//www.google.com/images/errors/robot.png) 100% 5px no-repeat;padding-right:205px}p{margin:11px 0 22px;overflow:hidden}ins{color:#777;text-decoration:none}a img{border:0}@media screen and (max-width:772px){body{background:none;margin-top:0;max-width:none;padding-right:0}}#logo{background:url(//www.google.com/images/branding/googlelogo/1x/googlelogo_color_150x54dp.png) no-repeat;margin-left:-5px}@media only screen and (min-resolution:192dpi){#logo{background:url(//www.google.com/images/branding/googlelogo/2x/googlelogo_color_150x54dp.png) no-repeat 0% 0%/100% 100%;-moz-border-image:url(//www.google.com/images/branding/googlelogo/2x/googlelogo_color_150x54dp.png) 0}}@media only screen and (-webkit-min-device-pixel-ratio:2){#logo{background:url(//www.google.com/images/branding/googlelogo/2x/googlelogo_color_150x54dp.png) no-repeat;-webkit-background-size:100% 100%}}#logo{display:inline-block;height:54px;width:150px}\n  </style>\n  <a href=//www.google.com/><span id=logo aria-label=Google></span></a>\n  <p><b>404.</b> <ins>That\xe2\x80\x99s an error.</ins>\n  <p>The requested URL <code>/wandb-production.appspot.com/ada4321/DiffHPE/a3ox2pn0/wandb-metadata.json</code> was not found on this server.  <ins>That\xe2\x80\x99s all we know.</ins>\n'
2023-07-10 15:38:18,804 DEBUG   SenderThread:45916 [sender.py:send():369] send: telemetry
2023-07-10 15:38:19,155 INFO    Thread-12 :45916 [dir_watcher.py:_on_file_created():272] file/dir created: /home/zhuhe/HPE-with-Diffusion/wandb/run-20230710_153816-a3ox2pn0/files/output.log
2023-07-10 15:38:19,156 INFO    Thread-12 :45916 [dir_watcher.py:_on_file_created():272] file/dir created: /home/zhuhe/HPE-with-Diffusion/wandb/run-20230710_153816-a3ox2pn0/files/wandb-metadata.json
2023-07-10 15:38:19,275 ERROR   wandb-upload_0:45916 [upload_job.py:push():136] Failed to upload file: /tmp/tmp086cacvvwandb/jpl0qf1a-wandb-metadata.json
Traceback (most recent call last):
  File "/home/zhuhe/.conda/envs/diffhpe/lib/python3.9/site-packages/wandb/apis/normalize.py", line 41, in wrapper
    return func(*args, **kwargs)
  File "/home/zhuhe/.conda/envs/diffhpe/lib/python3.9/site-packages/wandb/sdk/lib/retry.py", line 212, in wrapped_fn
    return retrier(*args, **kargs)
  File "/home/zhuhe/.conda/envs/diffhpe/lib/python3.9/site-packages/wandb/sdk/lib/retry.py", line 131, in __call__
    result = self._call_fn(*args, **kwargs)
  File "/home/zhuhe/.conda/envs/diffhpe/lib/python3.9/site-packages/wandb/sdk/internal/internal_api.py", line 2218, in upload_file
    wandb._sentry.reraise(e)
  File "/home/zhuhe/.conda/envs/diffhpe/lib/python3.9/site-packages/wandb/analytics/sentry.py", line 146, in reraise
    raise exc.with_traceback(sys.exc_info()[2])
  File "/home/zhuhe/.conda/envs/diffhpe/lib/python3.9/site-packages/wandb/sdk/internal/internal_api.py", line 2190, in upload_file
    response.raise_for_status()
  File "/home/zhuhe/.conda/envs/diffhpe/lib/python3.9/site-packages/requests/models.py", line 1021, in raise_for_status
    raise HTTPError(http_error_msg, response=self)
requests.exceptions.HTTPError: 404 Client Error: Not Found for url: https://storage.googleapis.com/wandb-production.appspot.com/ada4321/DiffHPE/a3ox2pn0/wandb-metadata.json?Expires=1689061098&GoogleAccessId=gorilla-files-url-signer-man%40wandb-production.iam.gserviceaccount.com&Signature=tsI3bXVL1r5g1dG5g%2FIl4SC1DHl0T7esrpx%2FsKKhE%2FTFtDUpA2ao2U%2BKlSIfyE7sdXBQwLVgeWWP%2BGkEcOqVFv92XtlGLTjdAowJUoKyGLoiMuAcJcVPkBfM0kBPzwbvsO7A0quwMTyp%2BwAMVEjqjTUVfrfWtBLPIUYTQ8J7I%2BH5RrYmZanidv1xPBNhwf89kK0%2BBc4KS%2FcNBTfVg6IqBFdHCTBSDMzDiJ%2BcxX9Gv9hdS10843T4dwBeSvnEILADnpAh1LKnxU7etggJB1ZH74HTLQtIKNjpzI9LpSyGJP4i31FhSPVTTIQA3M20DLmEmVqTNn8boe13Yu93GKeRPA%3D%3D

During handling of the above exception, another exception occurred:

Traceback (most recent call last):
  File "/home/zhuhe/.conda/envs/diffhpe/lib/python3.9/site-packages/wandb/filesync/upload_job.py", line 127, in push
    self._api.upload_file_retry(
  File "/home/zhuhe/.conda/envs/diffhpe/lib/python3.9/site-packages/wandb/apis/normalize.py", line 51, in wrapper
    raise CommError(message, error)
wandb.errors.CommError: <Response [404]>
2023-07-10 15:38:19,481 ERROR   Thread-11 :45916 [step_upload.py:_handle_event():200] Failed to upload file: /tmp/tmp086cacvvwandb/jpl0qf1a-wandb-metadata.json
Traceback (most recent call last):
  File "/home/zhuhe/.conda/envs/diffhpe/lib/python3.9/site-packages/wandb/apis/normalize.py", line 41, in wrapper
    return func(*args, **kwargs)
  File "/home/zhuhe/.conda/envs/diffhpe/lib/python3.9/site-packages/wandb/sdk/lib/retry.py", line 212, in wrapped_fn
    return retrier(*args, **kargs)
  File "/home/zhuhe/.conda/envs/diffhpe/lib/python3.9/site-packages/wandb/sdk/lib/retry.py", line 131, in __call__
    result = self._call_fn(*args, **kwargs)
  File "/home/zhuhe/.conda/envs/diffhpe/lib/python3.9/site-packages/wandb/sdk/internal/internal_api.py", line 2218, in upload_file
    wandb._sentry.reraise(e)
  File "/home/zhuhe/.conda/envs/diffhpe/lib/python3.9/site-packages/wandb/analytics/sentry.py", line 146, in reraise
    raise exc.with_traceback(sys.exc_info()[2])
  File "/home/zhuhe/.conda/envs/diffhpe/lib/python3.9/site-packages/wandb/sdk/internal/internal_api.py", line 2190, in upload_file
    response.raise_for_status()
  File "/home/zhuhe/.conda/envs/diffhpe/lib/python3.9/site-packages/requests/models.py", line 1021, in raise_for_status
    raise HTTPError(http_error_msg, response=self)
requests.exceptions.HTTPError: 404 Client Error: Not Found for url: https://storage.googleapis.com/wandb-production.appspot.com/ada4321/DiffHPE/a3ox2pn0/wandb-metadata.json?Expires=1689061098&GoogleAccessId=gorilla-files-url-signer-man%40wandb-production.iam.gserviceaccount.com&Signature=tsI3bXVL1r5g1dG5g%2FIl4SC1DHl0T7esrpx%2FsKKhE%2FTFtDUpA2ao2U%2BKlSIfyE7sdXBQwLVgeWWP%2BGkEcOqVFv92XtlGLTjdAowJUoKyGLoiMuAcJcVPkBfM0kBPzwbvsO7A0quwMTyp%2BwAMVEjqjTUVfrfWtBLPIUYTQ8J7I%2BH5RrYmZanidv1xPBNhwf89kK0%2BBc4KS%2FcNBTfVg6IqBFdHCTBSDMzDiJ%2BcxX9Gv9hdS10843T4dwBeSvnEILADnpAh1LKnxU7etggJB1ZH74HTLQtIKNjpzI9LpSyGJP4i31FhSPVTTIQA3M20DLmEmVqTNn8boe13Yu93GKeRPA%3D%3D

During handling of the above exception, another exception occurred:

Traceback (most recent call last):
  File "/home/zhuhe/.conda/envs/diffhpe/lib/python3.9/concurrent/futures/thread.py", line 58, in run
    result = self.fn(*self.args, **self.kwargs)
  File "/home/zhuhe/.conda/envs/diffhpe/lib/python3.9/site-packages/wandb/filesync/step_upload.py", line 288, in run_and_notify
    self._do_upload_sync(event)
  File "/home/zhuhe/.conda/envs/diffhpe/lib/python3.9/site-packages/wandb/filesync/step_upload.py", line 330, in _do_upload_sync
    job.run()
  File "/home/zhuhe/.conda/envs/diffhpe/lib/python3.9/site-packages/wandb/filesync/upload_job.py", line 57, in run
    self.push()
  File "/home/zhuhe/.conda/envs/diffhpe/lib/python3.9/site-packages/wandb/filesync/upload_job.py", line 127, in push
    self._api.upload_file_retry(
  File "/home/zhuhe/.conda/envs/diffhpe/lib/python3.9/site-packages/wandb/apis/normalize.py", line 51, in wrapper
    raise CommError(message, error)
wandb.errors.CommError: <Response [404]>
2023-07-10 15:38:21,156 INFO    Thread-12 :45916 [dir_watcher.py:_on_file_modified():289] file/dir modified: /home/zhuhe/HPE-with-Diffusion/wandb/run-20230710_153816-a3ox2pn0/files/output.log
2023-07-10 15:38:21,794 DEBUG   HandlerThread:45916 [handler.py:handle_request():144] handle_request: status_report
2023-07-10 15:38:23,157 INFO    Thread-12 :45916 [dir_watcher.py:_on_file_modified():289] file/dir modified: /home/zhuhe/HPE-with-Diffusion/wandb/run-20230710_153816-a3ox2pn0/files/output.log
2023-07-10 15:38:26,418 DEBUG   SenderThread:45916 [sender.py:send():369] send: exit
2023-07-10 15:38:26,418 INFO    SenderThread:45916 [sender.py:send_exit():574] handling exit code: 1
2023-07-10 15:38:26,418 INFO    SenderThread:45916 [sender.py:send_exit():576] handling runtime: 9
2023-07-10 15:38:26,418 INFO    SenderThread:45916 [sender.py:_save_file():1354] saving file wandb-summary.json with policy end
2023-07-10 15:38:26,418 INFO    SenderThread:45916 [sender.py:send_exit():582] send defer
2023-07-10 15:38:26,418 DEBUG   HandlerThread:45916 [handler.py:handle_request():144] handle_request: defer
2023-07-10 15:38:26,418 INFO    HandlerThread:45916 [handler.py:handle_request_defer():170] handle defer: 0
2023-07-10 15:38:26,419 DEBUG   SenderThread:45916 [sender.py:send_request():396] send_request: defer
2023-07-10 15:38:26,419 INFO    SenderThread:45916 [sender.py:send_request_defer():598] handle sender defer: 0
2023-07-10 15:38:26,419 INFO    SenderThread:45916 [sender.py:transition_state():602] send defer: 1
2023-07-10 15:38:26,419 DEBUG   HandlerThread:45916 [handler.py:handle_request():144] handle_request: defer
2023-07-10 15:38:26,419 INFO    HandlerThread:45916 [handler.py:handle_request_defer():170] handle defer: 1
2023-07-10 15:38:26,419 DEBUG   SenderThread:45916 [sender.py:send_request():396] send_request: defer
2023-07-10 15:38:26,419 INFO    SenderThread:45916 [sender.py:send_request_defer():598] handle sender defer: 1
2023-07-10 15:38:26,419 INFO    SenderThread:45916 [sender.py:transition_state():602] send defer: 2
2023-07-10 15:38:26,419 DEBUG   HandlerThread:45916 [handler.py:handle_request():144] handle_request: defer
2023-07-10 15:38:26,419 INFO    HandlerThread:45916 [handler.py:handle_request_defer():170] handle defer: 2
2023-07-10 15:38:26,419 INFO    HandlerThread:45916 [system_monitor.py:finish():190] Stopping system monitor
2023-07-10 15:38:26,419 INFO    HandlerThread:45916 [interfaces.py:finish():202] Joined cpu monitor
2023-07-10 15:38:26,420 DEBUG   SystemMonitor:45916 [system_monitor.py:_start():159] Starting system metrics aggregation loop
2023-07-10 15:38:26,420 DEBUG   SystemMonitor:45916 [system_monitor.py:_start():166] Finished system metrics aggregation loop
2023-07-10 15:38:26,420 DEBUG   SystemMonitor:45916 [system_monitor.py:_start():170] Publishing last batch of metrics
2023-07-10 15:38:26,420 INFO    HandlerThread:45916 [interfaces.py:finish():202] Joined disk monitor
2023-07-10 15:38:26,482 INFO    HandlerThread:45916 [interfaces.py:finish():202] Joined gpu monitor
2023-07-10 15:38:26,482 INFO    HandlerThread:45916 [interfaces.py:finish():202] Joined memory monitor
2023-07-10 15:38:26,482 INFO    HandlerThread:45916 [interfaces.py:finish():202] Joined network monitor
2023-07-10 15:38:26,483 DEBUG   SenderThread:45916 [sender.py:send_request():396] send_request: defer
2023-07-10 15:38:26,483 INFO    SenderThread:45916 [sender.py:send_request_defer():598] handle sender defer: 2
2023-07-10 15:38:26,483 INFO    SenderThread:45916 [sender.py:transition_state():602] send defer: 3
2023-07-10 15:38:26,483 DEBUG   SenderThread:45916 [sender.py:send():369] send: stats
2023-07-10 15:38:26,483 DEBUG   HandlerThread:45916 [handler.py:handle_request():144] handle_request: defer
2023-07-10 15:38:26,483 INFO    HandlerThread:45916 [handler.py:handle_request_defer():170] handle defer: 3
2023-07-10 15:38:26,483 DEBUG   SenderThread:45916 [sender.py:send_request():396] send_request: defer
2023-07-10 15:38:26,483 INFO    SenderThread:45916 [sender.py:send_request_defer():598] handle sender defer: 3
2023-07-10 15:38:26,483 INFO    SenderThread:45916 [sender.py:transition_state():602] send defer: 4
2023-07-10 15:38:26,483 DEBUG   HandlerThread:45916 [handler.py:handle_request():144] handle_request: defer
2023-07-10 15:38:26,483 INFO    HandlerThread:45916 [handler.py:handle_request_defer():170] handle defer: 4
2023-07-10 15:38:26,483 DEBUG   SenderThread:45916 [sender.py:send_request():396] send_request: defer
2023-07-10 15:38:26,484 INFO    SenderThread:45916 [sender.py:send_request_defer():598] handle sender defer: 4
2023-07-10 15:38:26,484 INFO    SenderThread:45916 [sender.py:transition_state():602] send defer: 5
2023-07-10 15:38:26,484 DEBUG   HandlerThread:45916 [handler.py:handle_request():144] handle_request: defer
2023-07-10 15:38:26,484 INFO    HandlerThread:45916 [handler.py:handle_request_defer():170] handle defer: 5
2023-07-10 15:38:26,484 DEBUG   SenderThread:45916 [sender.py:send():369] send: summary
2023-07-10 15:38:26,484 INFO    SenderThread:45916 [sender.py:_save_file():1354] saving file wandb-summary.json with policy end
2023-07-10 15:38:26,484 DEBUG   SenderThread:45916 [sender.py:send_request():396] send_request: defer
2023-07-10 15:38:26,484 INFO    SenderThread:45916 [sender.py:send_request_defer():598] handle sender defer: 5
2023-07-10 15:38:26,484 INFO    SenderThread:45916 [sender.py:transition_state():602] send defer: 6
2023-07-10 15:38:26,484 DEBUG   HandlerThread:45916 [handler.py:handle_request():144] handle_request: defer
2023-07-10 15:38:26,484 INFO    HandlerThread:45916 [handler.py:handle_request_defer():170] handle defer: 6
2023-07-10 15:38:26,484 DEBUG   SenderThread:45916 [sender.py:send_request():396] send_request: defer
2023-07-10 15:38:26,484 INFO    SenderThread:45916 [sender.py:send_request_defer():598] handle sender defer: 6
2023-07-10 15:38:26,486 DEBUG   HandlerThread:45916 [handler.py:handle_request():144] handle_request: status_report
2023-07-10 15:38:26,738 INFO    SenderThread:45916 [sender.py:transition_state():602] send defer: 7
2023-07-10 15:38:26,738 DEBUG   HandlerThread:45916 [handler.py:handle_request():144] handle_request: defer
2023-07-10 15:38:26,738 INFO    HandlerThread:45916 [handler.py:handle_request_defer():170] handle defer: 7
2023-07-10 15:38:26,738 DEBUG   SenderThread:45916 [sender.py:send_request():396] send_request: defer
2023-07-10 15:38:26,739 INFO    SenderThread:45916 [sender.py:send_request_defer():598] handle sender defer: 7
2023-07-10 15:38:27,158 INFO    Thread-12 :45916 [dir_watcher.py:_on_file_modified():289] file/dir modified: /home/zhuhe/HPE-with-Diffusion/wandb/run-20230710_153816-a3ox2pn0/files/wandb-summary.json
2023-07-10 15:38:27,158 INFO    Thread-12 :45916 [dir_watcher.py:_on_file_modified():289] file/dir modified: /home/zhuhe/HPE-with-Diffusion/wandb/run-20230710_153816-a3ox2pn0/files/config.yaml
2023-07-10 15:38:27,158 INFO    Thread-12 :45916 [dir_watcher.py:_on_file_modified():289] file/dir modified: /home/zhuhe/HPE-with-Diffusion/wandb/run-20230710_153816-a3ox2pn0/files/output.log
2023-07-10 15:38:27,418 DEBUG   HandlerThread:45916 [handler.py:handle_request():144] handle_request: poll_exit
2023-07-10 15:38:29,159 INFO    Thread-12 :45916 [dir_watcher.py:_on_file_modified():289] file/dir modified: /home/zhuhe/HPE-with-Diffusion/wandb/run-20230710_153816-a3ox2pn0/files/output.log
2023-07-10 15:38:30,820 INFO    SenderThread:45916 [sender.py:transition_state():602] send defer: 8
2023-07-10 15:38:30,820 DEBUG   SenderThread:45916 [sender.py:send_request():396] send_request: poll_exit
2023-07-10 15:38:30,820 DEBUG   HandlerThread:45916 [handler.py:handle_request():144] handle_request: defer
2023-07-10 15:38:30,820 INFO    HandlerThread:45916 [handler.py:handle_request_defer():170] handle defer: 8
2023-07-10 15:38:30,821 DEBUG   SenderThread:45916 [sender.py:send_request():396] send_request: defer
2023-07-10 15:38:30,821 INFO    SenderThread:45916 [sender.py:send_request_defer():598] handle sender defer: 8
2023-07-10 15:38:30,821 INFO    SenderThread:45916 [job_builder.py:build():232] Attempting to build job artifact
2023-07-10 15:38:30,821 INFO    SenderThread:45916 [job_builder.py:build():266] no source found
2023-07-10 15:38:30,821 INFO    SenderThread:45916 [sender.py:transition_state():602] send defer: 9
2023-07-10 15:38:30,821 DEBUG   HandlerThread:45916 [handler.py:handle_request():144] handle_request: defer
2023-07-10 15:38:30,821 INFO    HandlerThread:45916 [handler.py:handle_request_defer():170] handle defer: 9
2023-07-10 15:38:30,821 DEBUG   SenderThread:45916 [sender.py:send_request():396] send_request: defer
2023-07-10 15:38:30,821 INFO    SenderThread:45916 [sender.py:send_request_defer():598] handle sender defer: 9
2023-07-10 15:38:30,821 INFO    SenderThread:45916 [dir_watcher.py:finish():359] shutting down directory watcher
2023-07-10 15:38:31,160 INFO    SenderThread:45916 [dir_watcher.py:_on_file_modified():289] file/dir modified: /home/zhuhe/HPE-with-Diffusion/wandb/run-20230710_153816-a3ox2pn0/files/output.log
2023-07-10 15:38:31,160 INFO    SenderThread:45916 [dir_watcher.py:finish():389] scan: /home/zhuhe/HPE-with-Diffusion/wandb/run-20230710_153816-a3ox2pn0/files
2023-07-10 15:38:31,160 INFO    SenderThread:45916 [dir_watcher.py:finish():403] scan save: /home/zhuhe/HPE-with-Diffusion/wandb/run-20230710_153816-a3ox2pn0/files/wandb-metadata.json wandb-metadata.json
2023-07-10 15:38:31,160 INFO    SenderThread:45916 [dir_watcher.py:finish():403] scan save: /home/zhuhe/HPE-with-Diffusion/wandb/run-20230710_153816-a3ox2pn0/files/config.yaml config.yaml
2023-07-10 15:38:31,160 INFO    SenderThread:45916 [dir_watcher.py:finish():403] scan save: /home/zhuhe/HPE-with-Diffusion/wandb/run-20230710_153816-a3ox2pn0/files/requirements.txt requirements.txt
2023-07-10 15:38:31,160 INFO    SenderThread:45916 [dir_watcher.py:finish():403] scan save: /home/zhuhe/HPE-with-Diffusion/wandb/run-20230710_153816-a3ox2pn0/files/wandb-summary.json wandb-summary.json
2023-07-10 15:38:31,160 INFO    SenderThread:45916 [dir_watcher.py:finish():403] scan save: /home/zhuhe/HPE-with-Diffusion/wandb/run-20230710_153816-a3ox2pn0/files/conda-environment.yaml conda-environment.yaml
2023-07-10 15:38:31,160 INFO    SenderThread:45916 [dir_watcher.py:finish():403] scan save: /home/zhuhe/HPE-with-Diffusion/wandb/run-20230710_153816-a3ox2pn0/files/output.log output.log
2023-07-10 15:38:31,161 INFO    SenderThread:45916 [sender.py:transition_state():602] send defer: 10
2023-07-10 15:38:31,164 DEBUG   HandlerThread:45916 [handler.py:handle_request():144] handle_request: defer
2023-07-10 15:38:31,165 INFO    HandlerThread:45916 [handler.py:handle_request_defer():170] handle defer: 10
2023-07-10 15:38:31,167 DEBUG   SenderThread:45916 [sender.py:send_request():396] send_request: defer
2023-07-10 15:38:31,167 INFO    SenderThread:45916 [sender.py:send_request_defer():598] handle sender defer: 10
2023-07-10 15:38:31,167 INFO    SenderThread:45916 [file_pusher.py:finish():159] shutting down file pusher
2023-07-10 15:38:31,618 ERROR   wandb-upload_0:45916 [internal_api.py:upload_file():2192] upload_file exception https://storage.googleapis.com/wandb-production.appspot.com/ada4321/DiffHPE/a3ox2pn0/config.yaml?Expires=1689061111&GoogleAccessId=gorilla-files-url-signer-man%40wandb-production.iam.gserviceaccount.com&Signature=wEghfE7lwSeKh5jAFat%2BRpebd0iLfnzIGhO0yurCAwQcIg%2F88bLYAMLyUiioh924QIYTVS8kKD3x5PbZjqpCTsw1uHUe9da%2FFruAqrol%2FSa2RVc9YMsu4VVj6AO%2BkhwwcXF0PPdSFgo%2BFIZvTK4mXR2Z%2FI5mMTrJuA0gX9UncU0Z9FqAaBCEGbxjAUivWiafPcqgtrIWjSzDYFrzI9qa8zF3cBfDP5SxJgZ5VFfxauURA5CP01z7KbhAbz%2BSO%2Ft9f2HXdhixu9x63vNZFWorefI4Gcvn5aeJE6TpJ3ONBGgHvYZv0j%2FKye83sy4pDDCy0A7sKjERan7FsFhAwcNCTw%3D%3D: 404 Client Error: Not Found for url: https://storage.googleapis.com/wandb-production.appspot.com/ada4321/DiffHPE/a3ox2pn0/config.yaml?Expires=1689061111&GoogleAccessId=gorilla-files-url-signer-man%40wandb-production.iam.gserviceaccount.com&Signature=wEghfE7lwSeKh5jAFat%2BRpebd0iLfnzIGhO0yurCAwQcIg%2F88bLYAMLyUiioh924QIYTVS8kKD3x5PbZjqpCTsw1uHUe9da%2FFruAqrol%2FSa2RVc9YMsu4VVj6AO%2BkhwwcXF0PPdSFgo%2BFIZvTK4mXR2Z%2FI5mMTrJuA0gX9UncU0Z9FqAaBCEGbxjAUivWiafPcqgtrIWjSzDYFrzI9qa8zF3cBfDP5SxJgZ5VFfxauURA5CP01z7KbhAbz%2BSO%2Ft9f2HXdhixu9x63vNZFWorefI4Gcvn5aeJE6TpJ3ONBGgHvYZv0j%2FKye83sy4pDDCy0A7sKjERan7FsFhAwcNCTw%3D%3D
2023-07-10 15:38:31,619 ERROR   wandb-upload_0:45916 [internal_api.py:upload_file():2194] upload_file request headers: {'User-Agent': 'python-requests/2.31.0', 'Accept-Encoding': 'gzip, deflate', 'Accept': '*/*', 'Connection': 'keep-alive', 'Content-Length': '514'}
2023-07-10 15:38:31,619 ERROR   wandb-upload_0:45916 [internal_api.py:upload_file():2196] upload_file response body: b'<!DOCTYPE html>\n<html lang=en>\n  <meta charset=utf-8>\n  <meta name=viewport content="initial-scale=1, minimum-scale=1, width=device-width">\n  <title>Error 404 (Not Found)!!1</title>\n  <style>\n    *{margin:0;padding:0}html,code{font:15px/22px arial,sans-serif}html{background:#fff;color:#222;padding:15px}body{margin:7% auto 0;max-width:390px;min-height:180px;padding:30px 0 15px}* > body{background:url(//www.google.com/images/errors/robot.png) 100% 5px no-repeat;padding-right:205px}p{margin:11px 0 22px;overflow:hidden}ins{color:#777;text-decoration:none}a img{border:0}@media screen and (max-width:772px){body{background:none;margin-top:0;max-width:none;padding-right:0}}#logo{background:url(//www.google.com/images/branding/googlelogo/1x/googlelogo_color_150x54dp.png) no-repeat;margin-left:-5px}@media only screen and (min-resolution:192dpi){#logo{background:url(//www.google.com/images/branding/googlelogo/2x/googlelogo_color_150x54dp.png) no-repeat 0% 0%/100% 100%;-moz-border-image:url(//www.google.com/images/branding/googlelogo/2x/googlelogo_color_150x54dp.png) 0}}@media only screen and (-webkit-min-device-pixel-ratio:2){#logo{background:url(//www.google.com/images/branding/googlelogo/2x/googlelogo_color_150x54dp.png) no-repeat;-webkit-background-size:100% 100%}}#logo{display:inline-block;height:54px;width:150px}\n  </style>\n  <a href=//www.google.com/><span id=logo aria-label=Google></span></a>\n  <p><b>404.</b> <ins>That\xe2\x80\x99s an error.</ins>\n  <p>The requested URL <code>/wandb-production.appspot.com/ada4321/DiffHPE/a3ox2pn0/config.yaml</code> was not found on this server.  <ins>That\xe2\x80\x99s all we know.</ins>\n'
2023-07-10 15:38:31,621 ERROR   wandb-upload_1:45916 [internal_api.py:upload_file():2192] upload_file exception https://storage.googleapis.com/wandb-production.appspot.com/ada4321/DiffHPE/a3ox2pn0/requirements.txt?Expires=1689061111&GoogleAccessId=gorilla-files-url-signer-man%40wandb-production.iam.gserviceaccount.com&Signature=RRDMrY7mYV%2FMs3IihyHICuvbQayKdg8AeQQY2UGZQdkJOILwzWT4jJWtvUQ%2FKXi4kDRwdXvabkE578D0d0tp38KquS2juLNuc%2FQFJdkV%2FRrzn8aqk3GeqI1sqKuJAkU1lco6CBASS34MjtYvC1ji%2FufyY2fujLCOfFghmsnCzM6nNpyT8pstpFsdFi82e5lcVQiKEHUxDT5UQA5xw8NsQGG5w6ycD4Ed87UoD8%2Bra9gvEpOZtk3CppX%2BZv2aODshUAEFYLcK%2BqanCkrMC8p7KvIlZI8FxbKPOQT44N1yHOmIeH2E8AyNnXlgqjGlLOve%2BxSSBUavsEiaHNPOUnyvKQ%3D%3D: 404 Client Error: Not Found for url: https://storage.googleapis.com/wandb-production.appspot.com/ada4321/DiffHPE/a3ox2pn0/requirements.txt?Expires=1689061111&GoogleAccessId=gorilla-files-url-signer-man%40wandb-production.iam.gserviceaccount.com&Signature=RRDMrY7mYV%2FMs3IihyHICuvbQayKdg8AeQQY2UGZQdkJOILwzWT4jJWtvUQ%2FKXi4kDRwdXvabkE578D0d0tp38KquS2juLNuc%2FQFJdkV%2FRrzn8aqk3GeqI1sqKuJAkU1lco6CBASS34MjtYvC1ji%2FufyY2fujLCOfFghmsnCzM6nNpyT8pstpFsdFi82e5lcVQiKEHUxDT5UQA5xw8NsQGG5w6ycD4Ed87UoD8%2Bra9gvEpOZtk3CppX%2BZv2aODshUAEFYLcK%2BqanCkrMC8p7KvIlZI8FxbKPOQT44N1yHOmIeH2E8AyNnXlgqjGlLOve%2BxSSBUavsEiaHNPOUnyvKQ%3D%3D
2023-07-10 15:38:31,622 ERROR   wandb-upload_1:45916 [internal_api.py:upload_file():2194] upload_file request headers: {'User-Agent': 'python-requests/2.31.0', 'Accept-Encoding': 'gzip, deflate', 'Accept': '*/*', 'Connection': 'keep-alive', 'Content-Length': '910'}
2023-07-10 15:38:31,622 ERROR   wandb-upload_1:45916 [internal_api.py:upload_file():2196] upload_file response body: b'<!DOCTYPE html>\n<html lang=en>\n  <meta charset=utf-8>\n  <meta name=viewport content="initial-scale=1, minimum-scale=1, width=device-width">\n  <title>Error 404 (Not Found)!!1</title>\n  <style>\n    *{margin:0;padding:0}html,code{font:15px/22px arial,sans-serif}html{background:#fff;color:#222;padding:15px}body{margin:7% auto 0;max-width:390px;min-height:180px;padding:30px 0 15px}* > body{background:url(//www.google.com/images/errors/robot.png) 100% 5px no-repeat;padding-right:205px}p{margin:11px 0 22px;overflow:hidden}ins{color:#777;text-decoration:none}a img{border:0}@media screen and (max-width:772px){body{background:none;margin-top:0;max-width:none;padding-right:0}}#logo{background:url(//www.google.com/images/branding/googlelogo/1x/googlelogo_color_150x54dp.png) no-repeat;margin-left:-5px}@media only screen and (min-resolution:192dpi){#logo{background:url(//www.google.com/images/branding/googlelogo/2x/googlelogo_color_150x54dp.png) no-repeat 0% 0%/100% 100%;-moz-border-image:url(//www.google.com/images/branding/googlelogo/2x/googlelogo_color_150x54dp.png) 0}}@media only screen and (-webkit-min-device-pixel-ratio:2){#logo{background:url(//www.google.com/images/branding/googlelogo/2x/googlelogo_color_150x54dp.png) no-repeat;-webkit-background-size:100% 100%}}#logo{display:inline-block;height:54px;width:150px}\n  </style>\n  <a href=//www.google.com/><span id=logo aria-label=Google></span></a>\n  <p><b>404.</b> <ins>That\xe2\x80\x99s an error.</ins>\n  <p>The requested URL <code>/wandb-production.appspot.com/ada4321/DiffHPE/a3ox2pn0/requirements.txt</code> was not found on this server.  <ins>That\xe2\x80\x99s all we know.</ins>\n'
2023-07-10 15:38:31,967 ERROR   wandb-upload_3:45916 [internal_api.py:upload_file():2192] upload_file exception https://storage.googleapis.com/wandb-production.appspot.com/ada4321/DiffHPE/a3ox2pn0/conda-environment.yaml?Expires=1689061111&GoogleAccessId=gorilla-files-url-signer-man%40wandb-production.iam.gserviceaccount.com&Signature=XDkGLnRjwwE2rBhZ8bndhWSnz6rbroQIEs7nmBWZDhTF7%2BXFRsV3BoP%2BvgBhwSdb0eURUoaT2Zsh6SyEHPwb5xB6LvxIb30I7Mm1tzGm0IGzQuwVdtjFEbIRZZFZ65Dgq2Lr3Ims9tCuUYx0ng33M9tgbjPjvnTTlwwvIF%2BI%2Bv%2BsWZKRjZRxDRxf6xSFkMwohABL8RM%2F%2BRn4igX%2Bx2gMIdFtrClOj7kTVh5FtUtwxswphWLGmO8dxDTtjTImUiiKv8hLwlhFKRwgZGXSLz5dqR61Sdz3HHtexXrbRMV8%2B1lijvFFoNFHd4EwFHINks9Tll4Eh9BN3CYhUBGL6X%2BEtg%3D%3D: 404 Client Error: Not Found for url: https://storage.googleapis.com/wandb-production.appspot.com/ada4321/DiffHPE/a3ox2pn0/conda-environment.yaml?Expires=1689061111&GoogleAccessId=gorilla-files-url-signer-man%40wandb-production.iam.gserviceaccount.com&Signature=XDkGLnRjwwE2rBhZ8bndhWSnz6rbroQIEs7nmBWZDhTF7%2BXFRsV3BoP%2BvgBhwSdb0eURUoaT2Zsh6SyEHPwb5xB6LvxIb30I7Mm1tzGm0IGzQuwVdtjFEbIRZZFZ65Dgq2Lr3Ims9tCuUYx0ng33M9tgbjPjvnTTlwwvIF%2BI%2Bv%2BsWZKRjZRxDRxf6xSFkMwohABL8RM%2F%2BRn4igX%2Bx2gMIdFtrClOj7kTVh5FtUtwxswphWLGmO8dxDTtjTImUiiKv8hLwlhFKRwgZGXSLz5dqR61Sdz3HHtexXrbRMV8%2B1lijvFFoNFHd4EwFHINks9Tll4Eh9BN3CYhUBGL6X%2BEtg%3D%3D
2023-07-10 15:38:31,967 ERROR   wandb-upload_3:45916 [internal_api.py:upload_file():2194] upload_file request headers: {'User-Agent': 'python-requests/2.31.0', 'Accept-Encoding': 'gzip, deflate', 'Accept': '*/*', 'Connection': 'keep-alive', 'Content-Length': '1903'}
2023-07-10 15:38:31,967 ERROR   wandb-upload_3:45916 [internal_api.py:upload_file():2196] upload_file response body: b'<!DOCTYPE html>\n<html lang=en>\n  <meta charset=utf-8>\n  <meta name=viewport content="initial-scale=1, minimum-scale=1, width=device-width">\n  <title>Error 404 (Not Found)!!1</title>\n  <style>\n    *{margin:0;padding:0}html,code{font:15px/22px arial,sans-serif}html{background:#fff;color:#222;padding:15px}body{margin:7% auto 0;max-width:390px;min-height:180px;padding:30px 0 15px}* > body{background:url(//www.google.com/images/errors/robot.png) 100% 5px no-repeat;padding-right:205px}p{margin:11px 0 22px;overflow:hidden}ins{color:#777;text-decoration:none}a img{border:0}@media screen and (max-width:772px){body{background:none;margin-top:0;max-width:none;padding-right:0}}#logo{background:url(//www.google.com/images/branding/googlelogo/1x/googlelogo_color_150x54dp.png) no-repeat;margin-left:-5px}@media only screen and (min-resolution:192dpi){#logo{background:url(//www.google.com/images/branding/googlelogo/2x/googlelogo_color_150x54dp.png) no-repeat 0% 0%/100% 100%;-moz-border-image:url(//www.google.com/images/branding/googlelogo/2x/googlelogo_color_150x54dp.png) 0}}@media only screen and (-webkit-min-device-pixel-ratio:2){#logo{background:url(//www.google.com/images/branding/googlelogo/2x/googlelogo_color_150x54dp.png) no-repeat;-webkit-background-size:100% 100%}}#logo{display:inline-block;height:54px;width:150px}\n  </style>\n  <a href=//www.google.com/><span id=logo aria-label=Google></span></a>\n  <p><b>404.</b> <ins>That\xe2\x80\x99s an error.</ins>\n  <p>The requested URL <code>/wandb-production.appspot.com/ada4321/DiffHPE/a3ox2pn0/conda-environment.yaml</code> was not found on this server.  <ins>That\xe2\x80\x99s all we know.</ins>\n'
2023-07-10 15:38:31,970 ERROR   wandb-upload_2:45916 [internal_api.py:upload_file():2192] upload_file exception https://storage.googleapis.com/wandb-production.appspot.com/ada4321/DiffHPE/a3ox2pn0/wandb-summary.json?Expires=1689061111&GoogleAccessId=gorilla-files-url-signer-man%40wandb-production.iam.gserviceaccount.com&Signature=hUIzrFXbfB3lwNvHXMZTGHvh8KAQyn5rN7edvdhh373b5DWK4hPTV7gnyjfwschtAZD7Pbnh%2B9Ih5SGF8n%2FYFkFo9ZD4NEsdv9bjSdlmz%2FXtYrZBIwOVMaxbSYXxK7vGLc3UuoRc%2BxTAAMGgK3FgJHSx9zweN%2BHPrlMusrZT6joiGh%2FXS0FH6M7LIoxvsXt6NXkUT9ARYRy4szOyD4r4IbWKidhpvziqNszPiunAdVjsoTJ%2BqPym%2FD2hSpvLRoaYwrTGRM4rGb5VbIMsxYUwWCf0CHOnYYfQ%2F%2B9s56FIOMZ28Ik76VS%2FK9ZfZokCCrhs0MrFu6LgIT6nZ6yDh1GB8Q%3D%3D: 404 Client Error: Not Found for url: https://storage.googleapis.com/wandb-production.appspot.com/ada4321/DiffHPE/a3ox2pn0/wandb-summary.json?Expires=1689061111&GoogleAccessId=gorilla-files-url-signer-man%40wandb-production.iam.gserviceaccount.com&Signature=hUIzrFXbfB3lwNvHXMZTGHvh8KAQyn5rN7edvdhh373b5DWK4hPTV7gnyjfwschtAZD7Pbnh%2B9Ih5SGF8n%2FYFkFo9ZD4NEsdv9bjSdlmz%2FXtYrZBIwOVMaxbSYXxK7vGLc3UuoRc%2BxTAAMGgK3FgJHSx9zweN%2BHPrlMusrZT6joiGh%2FXS0FH6M7LIoxvsXt6NXkUT9ARYRy4szOyD4r4IbWKidhpvziqNszPiunAdVjsoTJ%2BqPym%2FD2hSpvLRoaYwrTGRM4rGb5VbIMsxYUwWCf0CHOnYYfQ%2F%2B9s56FIOMZ28Ik76VS%2FK9ZfZokCCrhs0MrFu6LgIT6nZ6yDh1GB8Q%3D%3D
2023-07-10 15:38:31,970 ERROR   wandb-upload_2:45916 [internal_api.py:upload_file():2194] upload_file request headers: {'User-Agent': 'python-requests/2.31.0', 'Accept-Encoding': 'gzip, deflate', 'Accept': '*/*', 'Connection': 'keep-alive', 'Content-Length': '26'}
2023-07-10 15:38:31,970 ERROR   wandb-upload_2:45916 [internal_api.py:upload_file():2196] upload_file response body: b'<!DOCTYPE html>\n<html lang=en>\n  <meta charset=utf-8>\n  <meta name=viewport content="initial-scale=1, minimum-scale=1, width=device-width">\n  <title>Error 404 (Not Found)!!1</title>\n  <style>\n    *{margin:0;padding:0}html,code{font:15px/22px arial,sans-serif}html{background:#fff;color:#222;padding:15px}body{margin:7% auto 0;max-width:390px;min-height:180px;padding:30px 0 15px}* > body{background:url(//www.google.com/images/errors/robot.png) 100% 5px no-repeat;padding-right:205px}p{margin:11px 0 22px;overflow:hidden}ins{color:#777;text-decoration:none}a img{border:0}@media screen and (max-width:772px){body{background:none;margin-top:0;max-width:none;padding-right:0}}#logo{background:url(//www.google.com/images/branding/googlelogo/1x/googlelogo_color_150x54dp.png) no-repeat;margin-left:-5px}@media only screen and (min-resolution:192dpi){#logo{background:url(//www.google.com/images/branding/googlelogo/2x/googlelogo_color_150x54dp.png) no-repeat 0% 0%/100% 100%;-moz-border-image:url(//www.google.com/images/branding/googlelogo/2x/googlelogo_color_150x54dp.png) 0}}@media only screen and (-webkit-min-device-pixel-ratio:2){#logo{background:url(//www.google.com/images/branding/googlelogo/2x/googlelogo_color_150x54dp.png) no-repeat;-webkit-background-size:100% 100%}}#logo{display:inline-block;height:54px;width:150px}\n  </style>\n  <a href=//www.google.com/><span id=logo aria-label=Google></span></a>\n  <p><b>404.</b> <ins>That\xe2\x80\x99s an error.</ins>\n  <p>The requested URL <code>/wandb-production.appspot.com/ada4321/DiffHPE/a3ox2pn0/wandb-summary.json</code> was not found on this server.  <ins>That\xe2\x80\x99s all we know.</ins>\n'
2023-07-10 15:38:32,022 ERROR   wandb-upload_4:45916 [internal_api.py:upload_file():2192] upload_file exception https://storage.googleapis.com/wandb-production.appspot.com/ada4321/DiffHPE/a3ox2pn0/output.log?Expires=1689061111&GoogleAccessId=gorilla-files-url-signer-man%40wandb-production.iam.gserviceaccount.com&Signature=FIpZY78On0Ap6kVnIzK1T%2FnwfXPqfPi23t3%2BATPjGwveYploHtxzfXI8niSqhOJPya2DGKgz6DrLC6cU0Ac3uYdk0tNCEAGT%2BS9Rnl3mY%2BA5UPZijyaQtuI3ocbKPC%2BTh5xVnC0knSRXmGCOPmLk2Jg4srDqtAPFRVFrQebxPIYhS1YFMAOU7%2FBO4%2FtdN%2B5jyBjHWSwc44Bht2l3%2F8QQGJ%2Fqd3dEJRsbyTpYoJOdzIqx4C6kjBSZ1qNE67eYSg5MYN4uvcgQWHSZO29Ugy4z3WrGOPJQLb%2B%2BAn9Wj%2FBoU%2FowgWHav%2B6uEMWDswm3M6cKH5oDgJ%2FWiivzT3WXQGvQXg%3D%3D: 404 Client Error: Not Found for url: https://storage.googleapis.com/wandb-production.appspot.com/ada4321/DiffHPE/a3ox2pn0/output.log?Expires=1689061111&GoogleAccessId=gorilla-files-url-signer-man%40wandb-production.iam.gserviceaccount.com&Signature=FIpZY78On0Ap6kVnIzK1T%2FnwfXPqfPi23t3%2BATPjGwveYploHtxzfXI8niSqhOJPya2DGKgz6DrLC6cU0Ac3uYdk0tNCEAGT%2BS9Rnl3mY%2BA5UPZijyaQtuI3ocbKPC%2BTh5xVnC0knSRXmGCOPmLk2Jg4srDqtAPFRVFrQebxPIYhS1YFMAOU7%2FBO4%2FtdN%2B5jyBjHWSwc44Bht2l3%2F8QQGJ%2Fqd3dEJRsbyTpYoJOdzIqx4C6kjBSZ1qNE67eYSg5MYN4uvcgQWHSZO29Ugy4z3WrGOPJQLb%2B%2BAn9Wj%2FBoU%2FowgWHav%2B6uEMWDswm3M6cKH5oDgJ%2FWiivzT3WXQGvQXg%3D%3D
2023-07-10 15:38:32,022 ERROR   wandb-upload_4:45916 [internal_api.py:upload_file():2194] upload_file request headers: {'User-Agent': 'python-requests/2.31.0', 'Accept-Encoding': 'gzip, deflate', 'Accept': '*/*', 'Connection': 'keep-alive', 'Content-Length': '3077'}
2023-07-10 15:38:32,022 ERROR   wandb-upload_4:45916 [internal_api.py:upload_file():2196] upload_file response body: b'<!DOCTYPE html>\n<html lang=en>\n  <meta charset=utf-8>\n  <meta name=viewport content="initial-scale=1, minimum-scale=1, width=device-width">\n  <title>Error 404 (Not Found)!!1</title>\n  <style>\n    *{margin:0;padding:0}html,code{font:15px/22px arial,sans-serif}html{background:#fff;color:#222;padding:15px}body{margin:7% auto 0;max-width:390px;min-height:180px;padding:30px 0 15px}* > body{background:url(//www.google.com/images/errors/robot.png) 100% 5px no-repeat;padding-right:205px}p{margin:11px 0 22px;overflow:hidden}ins{color:#777;text-decoration:none}a img{border:0}@media screen and (max-width:772px){body{background:none;margin-top:0;max-width:none;padding-right:0}}#logo{background:url(//www.google.com/images/branding/googlelogo/1x/googlelogo_color_150x54dp.png) no-repeat;margin-left:-5px}@media only screen and (min-resolution:192dpi){#logo{background:url(//www.google.com/images/branding/googlelogo/2x/googlelogo_color_150x54dp.png) no-repeat 0% 0%/100% 100%;-moz-border-image:url(//www.google.com/images/branding/googlelogo/2x/googlelogo_color_150x54dp.png) 0}}@media only screen and (-webkit-min-device-pixel-ratio:2){#logo{background:url(//www.google.com/images/branding/googlelogo/2x/googlelogo_color_150x54dp.png) no-repeat;-webkit-background-size:100% 100%}}#logo{display:inline-block;height:54px;width:150px}\n  </style>\n  <a href=//www.google.com/><span id=logo aria-label=Google></span></a>\n  <p><b>404.</b> <ins>That\xe2\x80\x99s an error.</ins>\n  <p>The requested URL <code>/wandb-production.appspot.com/ada4321/DiffHPE/a3ox2pn0/output.log</code> was not found on this server.  <ins>That\xe2\x80\x99s all we know.</ins>\n'
2023-07-10 15:38:32,419 DEBUG   HandlerThread:45916 [handler.py:handle_request():144] handle_request: keepalive
2023-07-10 15:38:32,633 ERROR   wandb-upload_0:45916 [upload_job.py:push():136] Failed to upload file: /home/zhuhe/HPE-with-Diffusion/wandb/run-20230710_153816-a3ox2pn0/files/config.yaml
Traceback (most recent call last):
  File "/home/zhuhe/.conda/envs/diffhpe/lib/python3.9/site-packages/wandb/apis/normalize.py", line 41, in wrapper
    return func(*args, **kwargs)
  File "/home/zhuhe/.conda/envs/diffhpe/lib/python3.9/site-packages/wandb/sdk/lib/retry.py", line 212, in wrapped_fn
    return retrier(*args, **kargs)
  File "/home/zhuhe/.conda/envs/diffhpe/lib/python3.9/site-packages/wandb/sdk/lib/retry.py", line 131, in __call__
    result = self._call_fn(*args, **kwargs)
  File "/home/zhuhe/.conda/envs/diffhpe/lib/python3.9/site-packages/wandb/sdk/internal/internal_api.py", line 2218, in upload_file
    wandb._sentry.reraise(e)
  File "/home/zhuhe/.conda/envs/diffhpe/lib/python3.9/site-packages/wandb/analytics/sentry.py", line 146, in reraise
    raise exc.with_traceback(sys.exc_info()[2])
  File "/home/zhuhe/.conda/envs/diffhpe/lib/python3.9/site-packages/wandb/sdk/internal/internal_api.py", line 2190, in upload_file
    response.raise_for_status()
  File "/home/zhuhe/.conda/envs/diffhpe/lib/python3.9/site-packages/requests/models.py", line 1021, in raise_for_status
    raise HTTPError(http_error_msg, response=self)
requests.exceptions.HTTPError: 404 Client Error: Not Found for url: https://storage.googleapis.com/wandb-production.appspot.com/ada4321/DiffHPE/a3ox2pn0/config.yaml?Expires=1689061111&GoogleAccessId=gorilla-files-url-signer-man%40wandb-production.iam.gserviceaccount.com&Signature=wEghfE7lwSeKh5jAFat%2BRpebd0iLfnzIGhO0yurCAwQcIg%2F88bLYAMLyUiioh924QIYTVS8kKD3x5PbZjqpCTsw1uHUe9da%2FFruAqrol%2FSa2RVc9YMsu4VVj6AO%2BkhwwcXF0PPdSFgo%2BFIZvTK4mXR2Z%2FI5mMTrJuA0gX9UncU0Z9FqAaBCEGbxjAUivWiafPcqgtrIWjSzDYFrzI9qa8zF3cBfDP5SxJgZ5VFfxauURA5CP01z7KbhAbz%2BSO%2Ft9f2HXdhixu9x63vNZFWorefI4Gcvn5aeJE6TpJ3ONBGgHvYZv0j%2FKye83sy4pDDCy0A7sKjERan7FsFhAwcNCTw%3D%3D

During handling of the above exception, another exception occurred:

Traceback (most recent call last):
  File "/home/zhuhe/.conda/envs/diffhpe/lib/python3.9/site-packages/wandb/filesync/upload_job.py", line 127, in push
    self._api.upload_file_retry(
  File "/home/zhuhe/.conda/envs/diffhpe/lib/python3.9/site-packages/wandb/apis/normalize.py", line 51, in wrapper
    raise CommError(message, error)
wandb.errors.CommError: <Response [404]>
2023-07-10 15:38:32,633 ERROR   wandb-upload_1:45916 [upload_job.py:push():136] Failed to upload file: /home/zhuhe/HPE-with-Diffusion/wandb/run-20230710_153816-a3ox2pn0/files/requirements.txt
Traceback (most recent call last):
  File "/home/zhuhe/.conda/envs/diffhpe/lib/python3.9/site-packages/wandb/apis/normalize.py", line 41, in wrapper
    return func(*args, **kwargs)
  File "/home/zhuhe/.conda/envs/diffhpe/lib/python3.9/site-packages/wandb/sdk/lib/retry.py", line 212, in wrapped_fn
    return retrier(*args, **kargs)
  File "/home/zhuhe/.conda/envs/diffhpe/lib/python3.9/site-packages/wandb/sdk/lib/retry.py", line 131, in __call__
    result = self._call_fn(*args, **kwargs)
  File "/home/zhuhe/.conda/envs/diffhpe/lib/python3.9/site-packages/wandb/sdk/internal/internal_api.py", line 2218, in upload_file
    wandb._sentry.reraise(e)
  File "/home/zhuhe/.conda/envs/diffhpe/lib/python3.9/site-packages/wandb/analytics/sentry.py", line 146, in reraise
    raise exc.with_traceback(sys.exc_info()[2])
  File "/home/zhuhe/.conda/envs/diffhpe/lib/python3.9/site-packages/wandb/sdk/internal/internal_api.py", line 2190, in upload_file
    response.raise_for_status()
  File "/home/zhuhe/.conda/envs/diffhpe/lib/python3.9/site-packages/requests/models.py", line 1021, in raise_for_status
    raise HTTPError(http_error_msg, response=self)
requests.exceptions.HTTPError: 404 Client Error: Not Found for url: https://storage.googleapis.com/wandb-production.appspot.com/ada4321/DiffHPE/a3ox2pn0/requirements.txt?Expires=1689061111&GoogleAccessId=gorilla-files-url-signer-man%40wandb-production.iam.gserviceaccount.com&Signature=RRDMrY7mYV%2FMs3IihyHICuvbQayKdg8AeQQY2UGZQdkJOILwzWT4jJWtvUQ%2FKXi4kDRwdXvabkE578D0d0tp38KquS2juLNuc%2FQFJdkV%2FRrzn8aqk3GeqI1sqKuJAkU1lco6CBASS34MjtYvC1ji%2FufyY2fujLCOfFghmsnCzM6nNpyT8pstpFsdFi82e5lcVQiKEHUxDT5UQA5xw8NsQGG5w6ycD4Ed87UoD8%2Bra9gvEpOZtk3CppX%2BZv2aODshUAEFYLcK%2BqanCkrMC8p7KvIlZI8FxbKPOQT44N1yHOmIeH2E8AyNnXlgqjGlLOve%2BxSSBUavsEiaHNPOUnyvKQ%3D%3D

During handling of the above exception, another exception occurred:

Traceback (most recent call last):
  File "/home/zhuhe/.conda/envs/diffhpe/lib/python3.9/site-packages/wandb/filesync/upload_job.py", line 127, in push
    self._api.upload_file_retry(
  File "/home/zhuhe/.conda/envs/diffhpe/lib/python3.9/site-packages/wandb/apis/normalize.py", line 51, in wrapper
    raise CommError(message, error)
wandb.errors.CommError: <Response [404]>
2023-07-10 15:38:32,634 ERROR   wandb-upload_3:45916 [upload_job.py:push():136] Failed to upload file: /home/zhuhe/HPE-with-Diffusion/wandb/run-20230710_153816-a3ox2pn0/files/conda-environment.yaml
Traceback (most recent call last):
  File "/home/zhuhe/.conda/envs/diffhpe/lib/python3.9/site-packages/wandb/apis/normalize.py", line 41, in wrapper
    return func(*args, **kwargs)
  File "/home/zhuhe/.conda/envs/diffhpe/lib/python3.9/site-packages/wandb/sdk/lib/retry.py", line 212, in wrapped_fn
    return retrier(*args, **kargs)
  File "/home/zhuhe/.conda/envs/diffhpe/lib/python3.9/site-packages/wandb/sdk/lib/retry.py", line 131, in __call__
    result = self._call_fn(*args, **kwargs)
  File "/home/zhuhe/.conda/envs/diffhpe/lib/python3.9/site-packages/wandb/sdk/internal/internal_api.py", line 2218, in upload_file
    wandb._sentry.reraise(e)
  File "/home/zhuhe/.conda/envs/diffhpe/lib/python3.9/site-packages/wandb/analytics/sentry.py", line 146, in reraise
    raise exc.with_traceback(sys.exc_info()[2])
  File "/home/zhuhe/.conda/envs/diffhpe/lib/python3.9/site-packages/wandb/sdk/internal/internal_api.py", line 2190, in upload_file
    response.raise_for_status()
  File "/home/zhuhe/.conda/envs/diffhpe/lib/python3.9/site-packages/requests/models.py", line 1021, in raise_for_status
    raise HTTPError(http_error_msg, response=self)
requests.exceptions.HTTPError: 404 Client Error: Not Found for url: https://storage.googleapis.com/wandb-production.appspot.com/ada4321/DiffHPE/a3ox2pn0/conda-environment.yaml?Expires=1689061111&GoogleAccessId=gorilla-files-url-signer-man%40wandb-production.iam.gserviceaccount.com&Signature=XDkGLnRjwwE2rBhZ8bndhWSnz6rbroQIEs7nmBWZDhTF7%2BXFRsV3BoP%2BvgBhwSdb0eURUoaT2Zsh6SyEHPwb5xB6LvxIb30I7Mm1tzGm0IGzQuwVdtjFEbIRZZFZ65Dgq2Lr3Ims9tCuUYx0ng33M9tgbjPjvnTTlwwvIF%2BI%2Bv%2BsWZKRjZRxDRxf6xSFkMwohABL8RM%2F%2BRn4igX%2Bx2gMIdFtrClOj7kTVh5FtUtwxswphWLGmO8dxDTtjTImUiiKv8hLwlhFKRwgZGXSLz5dqR61Sdz3HHtexXrbRMV8%2B1lijvFFoNFHd4EwFHINks9Tll4Eh9BN3CYhUBGL6X%2BEtg%3D%3D

During handling of the above exception, another exception occurred:

Traceback (most recent call last):
  File "/home/zhuhe/.conda/envs/diffhpe/lib/python3.9/site-packages/wandb/filesync/upload_job.py", line 127, in push
    self._api.upload_file_retry(
  File "/home/zhuhe/.conda/envs/diffhpe/lib/python3.9/site-packages/wandb/apis/normalize.py", line 51, in wrapper
    raise CommError(message, error)
wandb.errors.CommError: <Response [404]>
2023-07-10 15:38:32,634 ERROR   wandb-upload_2:45916 [upload_job.py:push():136] Failed to upload file: /home/zhuhe/HPE-with-Diffusion/wandb/run-20230710_153816-a3ox2pn0/files/wandb-summary.json
Traceback (most recent call last):
  File "/home/zhuhe/.conda/envs/diffhpe/lib/python3.9/site-packages/wandb/apis/normalize.py", line 41, in wrapper
    return func(*args, **kwargs)
  File "/home/zhuhe/.conda/envs/diffhpe/lib/python3.9/site-packages/wandb/sdk/lib/retry.py", line 212, in wrapped_fn
    return retrier(*args, **kargs)
  File "/home/zhuhe/.conda/envs/diffhpe/lib/python3.9/site-packages/wandb/sdk/lib/retry.py", line 131, in __call__
    result = self._call_fn(*args, **kwargs)
  File "/home/zhuhe/.conda/envs/diffhpe/lib/python3.9/site-packages/wandb/sdk/internal/internal_api.py", line 2218, in upload_file
    wandb._sentry.reraise(e)
  File "/home/zhuhe/.conda/envs/diffhpe/lib/python3.9/site-packages/wandb/analytics/sentry.py", line 146, in reraise
    raise exc.with_traceback(sys.exc_info()[2])
  File "/home/zhuhe/.conda/envs/diffhpe/lib/python3.9/site-packages/wandb/sdk/internal/internal_api.py", line 2190, in upload_file
    response.raise_for_status()
  File "/home/zhuhe/.conda/envs/diffhpe/lib/python3.9/site-packages/requests/models.py", line 1021, in raise_for_status
    raise HTTPError(http_error_msg, response=self)
requests.exceptions.HTTPError: 404 Client Error: Not Found for url: https://storage.googleapis.com/wandb-production.appspot.com/ada4321/DiffHPE/a3ox2pn0/wandb-summary.json?Expires=1689061111&GoogleAccessId=gorilla-files-url-signer-man%40wandb-production.iam.gserviceaccount.com&Signature=hUIzrFXbfB3lwNvHXMZTGHvh8KAQyn5rN7edvdhh373b5DWK4hPTV7gnyjfwschtAZD7Pbnh%2B9Ih5SGF8n%2FYFkFo9ZD4NEsdv9bjSdlmz%2FXtYrZBIwOVMaxbSYXxK7vGLc3UuoRc%2BxTAAMGgK3FgJHSx9zweN%2BHPrlMusrZT6joiGh%2FXS0FH6M7LIoxvsXt6NXkUT9ARYRy4szOyD4r4IbWKidhpvziqNszPiunAdVjsoTJ%2BqPym%2FD2hSpvLRoaYwrTGRM4rGb5VbIMsxYUwWCf0CHOnYYfQ%2F%2B9s56FIOMZ28Ik76VS%2FK9ZfZokCCrhs0MrFu6LgIT6nZ6yDh1GB8Q%3D%3D

During handling of the above exception, another exception occurred:

Traceback (most recent call last):
  File "/home/zhuhe/.conda/envs/diffhpe/lib/python3.9/site-packages/wandb/filesync/upload_job.py", line 127, in push
    self._api.upload_file_retry(
  File "/home/zhuhe/.conda/envs/diffhpe/lib/python3.9/site-packages/wandb/apis/normalize.py", line 51, in wrapper
    raise CommError(message, error)
wandb.errors.CommError: <Response [404]>
2023-07-10 15:38:32,635 ERROR   wandb-upload_4:45916 [upload_job.py:push():136] Failed to upload file: /home/zhuhe/HPE-with-Diffusion/wandb/run-20230710_153816-a3ox2pn0/files/output.log
Traceback (most recent call last):
  File "/home/zhuhe/.conda/envs/diffhpe/lib/python3.9/site-packages/wandb/apis/normalize.py", line 41, in wrapper
    return func(*args, **kwargs)
  File "/home/zhuhe/.conda/envs/diffhpe/lib/python3.9/site-packages/wandb/sdk/lib/retry.py", line 212, in wrapped_fn
    return retrier(*args, **kargs)
  File "/home/zhuhe/.conda/envs/diffhpe/lib/python3.9/site-packages/wandb/sdk/lib/retry.py", line 131, in __call__
    result = self._call_fn(*args, **kwargs)
  File "/home/zhuhe/.conda/envs/diffhpe/lib/python3.9/site-packages/wandb/sdk/internal/internal_api.py", line 2218, in upload_file
    wandb._sentry.reraise(e)
  File "/home/zhuhe/.conda/envs/diffhpe/lib/python3.9/site-packages/wandb/analytics/sentry.py", line 146, in reraise
    raise exc.with_traceback(sys.exc_info()[2])
  File "/home/zhuhe/.conda/envs/diffhpe/lib/python3.9/site-packages/wandb/sdk/internal/internal_api.py", line 2190, in upload_file
    response.raise_for_status()
  File "/home/zhuhe/.conda/envs/diffhpe/lib/python3.9/site-packages/requests/models.py", line 1021, in raise_for_status
    raise HTTPError(http_error_msg, response=self)
requests.exceptions.HTTPError: 404 Client Error: Not Found for url: https://storage.googleapis.com/wandb-production.appspot.com/ada4321/DiffHPE/a3ox2pn0/output.log?Expires=1689061111&GoogleAccessId=gorilla-files-url-signer-man%40wandb-production.iam.gserviceaccount.com&Signature=FIpZY78On0Ap6kVnIzK1T%2FnwfXPqfPi23t3%2BATPjGwveYploHtxzfXI8niSqhOJPya2DGKgz6DrLC6cU0Ac3uYdk0tNCEAGT%2BS9Rnl3mY%2BA5UPZijyaQtuI3ocbKPC%2BTh5xVnC0knSRXmGCOPmLk2Jg4srDqtAPFRVFrQebxPIYhS1YFMAOU7%2FBO4%2FtdN%2B5jyBjHWSwc44Bht2l3%2F8QQGJ%2Fqd3dEJRsbyTpYoJOdzIqx4C6kjBSZ1qNE67eYSg5MYN4uvcgQWHSZO29Ugy4z3WrGOPJQLb%2B%2BAn9Wj%2FBoU%2FowgWHav%2B6uEMWDswm3M6cKH5oDgJ%2FWiivzT3WXQGvQXg%3D%3D

During handling of the above exception, another exception occurred:

Traceback (most recent call last):
  File "/home/zhuhe/.conda/envs/diffhpe/lib/python3.9/site-packages/wandb/filesync/upload_job.py", line 127, in push
    self._api.upload_file_retry(
  File "/home/zhuhe/.conda/envs/diffhpe/lib/python3.9/site-packages/wandb/apis/normalize.py", line 51, in wrapper
    raise CommError(message, error)
wandb.errors.CommError: <Response [404]>
2023-07-10 15:38:33,652 ERROR   Thread-11 :45916 [step_upload.py:_handle_event():200] Failed to upload file: /home/zhuhe/HPE-with-Diffusion/wandb/run-20230710_153816-a3ox2pn0/files/config.yaml
Traceback (most recent call last):
  File "/home/zhuhe/.conda/envs/diffhpe/lib/python3.9/site-packages/wandb/apis/normalize.py", line 41, in wrapper
    return func(*args, **kwargs)
  File "/home/zhuhe/.conda/envs/diffhpe/lib/python3.9/site-packages/wandb/sdk/lib/retry.py", line 212, in wrapped_fn
    return retrier(*args, **kargs)
  File "/home/zhuhe/.conda/envs/diffhpe/lib/python3.9/site-packages/wandb/sdk/lib/retry.py", line 131, in __call__
    result = self._call_fn(*args, **kwargs)
  File "/home/zhuhe/.conda/envs/diffhpe/lib/python3.9/site-packages/wandb/sdk/internal/internal_api.py", line 2218, in upload_file
    wandb._sentry.reraise(e)
  File "/home/zhuhe/.conda/envs/diffhpe/lib/python3.9/site-packages/wandb/analytics/sentry.py", line 146, in reraise
    raise exc.with_traceback(sys.exc_info()[2])
  File "/home/zhuhe/.conda/envs/diffhpe/lib/python3.9/site-packages/wandb/sdk/internal/internal_api.py", line 2190, in upload_file
    response.raise_for_status()
  File "/home/zhuhe/.conda/envs/diffhpe/lib/python3.9/site-packages/requests/models.py", line 1021, in raise_for_status
    raise HTTPError(http_error_msg, response=self)
requests.exceptions.HTTPError: 404 Client Error: Not Found for url: https://storage.googleapis.com/wandb-production.appspot.com/ada4321/DiffHPE/a3ox2pn0/config.yaml?Expires=1689061111&GoogleAccessId=gorilla-files-url-signer-man%40wandb-production.iam.gserviceaccount.com&Signature=wEghfE7lwSeKh5jAFat%2BRpebd0iLfnzIGhO0yurCAwQcIg%2F88bLYAMLyUiioh924QIYTVS8kKD3x5PbZjqpCTsw1uHUe9da%2FFruAqrol%2FSa2RVc9YMsu4VVj6AO%2BkhwwcXF0PPdSFgo%2BFIZvTK4mXR2Z%2FI5mMTrJuA0gX9UncU0Z9FqAaBCEGbxjAUivWiafPcqgtrIWjSzDYFrzI9qa8zF3cBfDP5SxJgZ5VFfxauURA5CP01z7KbhAbz%2BSO%2Ft9f2HXdhixu9x63vNZFWorefI4Gcvn5aeJE6TpJ3ONBGgHvYZv0j%2FKye83sy4pDDCy0A7sKjERan7FsFhAwcNCTw%3D%3D

During handling of the above exception, another exception occurred:

Traceback (most recent call last):
  File "/home/zhuhe/.conda/envs/diffhpe/lib/python3.9/concurrent/futures/thread.py", line 58, in run
    result = self.fn(*self.args, **self.kwargs)
  File "/home/zhuhe/.conda/envs/diffhpe/lib/python3.9/site-packages/wandb/filesync/step_upload.py", line 288, in run_and_notify
    self._do_upload_sync(event)
  File "/home/zhuhe/.conda/envs/diffhpe/lib/python3.9/site-packages/wandb/filesync/step_upload.py", line 330, in _do_upload_sync
    job.run()
  File "/home/zhuhe/.conda/envs/diffhpe/lib/python3.9/site-packages/wandb/filesync/upload_job.py", line 57, in run
    self.push()
  File "/home/zhuhe/.conda/envs/diffhpe/lib/python3.9/site-packages/wandb/filesync/upload_job.py", line 127, in push
    self._api.upload_file_retry(
  File "/home/zhuhe/.conda/envs/diffhpe/lib/python3.9/site-packages/wandb/apis/normalize.py", line 51, in wrapper
    raise CommError(message, error)
wandb.errors.CommError: <Response [404]>
2023-07-10 15:38:33,653 ERROR   Thread-11 :45916 [step_upload.py:_handle_event():200] Failed to upload file: /home/zhuhe/HPE-with-Diffusion/wandb/run-20230710_153816-a3ox2pn0/files/conda-environment.yaml
Traceback (most recent call last):
  File "/home/zhuhe/.conda/envs/diffhpe/lib/python3.9/site-packages/wandb/apis/normalize.py", line 41, in wrapper
    return func(*args, **kwargs)
  File "/home/zhuhe/.conda/envs/diffhpe/lib/python3.9/site-packages/wandb/sdk/lib/retry.py", line 212, in wrapped_fn
    return retrier(*args, **kargs)
  File "/home/zhuhe/.conda/envs/diffhpe/lib/python3.9/site-packages/wandb/sdk/lib/retry.py", line 131, in __call__
    result = self._call_fn(*args, **kwargs)
  File "/home/zhuhe/.conda/envs/diffhpe/lib/python3.9/site-packages/wandb/sdk/internal/internal_api.py", line 2218, in upload_file
    wandb._sentry.reraise(e)
  File "/home/zhuhe/.conda/envs/diffhpe/lib/python3.9/site-packages/wandb/analytics/sentry.py", line 146, in reraise
    raise exc.with_traceback(sys.exc_info()[2])
  File "/home/zhuhe/.conda/envs/diffhpe/lib/python3.9/site-packages/wandb/sdk/internal/internal_api.py", line 2190, in upload_file
    response.raise_for_status()
  File "/home/zhuhe/.conda/envs/diffhpe/lib/python3.9/site-packages/requests/models.py", line 1021, in raise_for_status
    raise HTTPError(http_error_msg, response=self)
requests.exceptions.HTTPError: 404 Client Error: Not Found for url: https://storage.googleapis.com/wandb-production.appspot.com/ada4321/DiffHPE/a3ox2pn0/conda-environment.yaml?Expires=1689061111&GoogleAccessId=gorilla-files-url-signer-man%40wandb-production.iam.gserviceaccount.com&Signature=XDkGLnRjwwE2rBhZ8bndhWSnz6rbroQIEs7nmBWZDhTF7%2BXFRsV3BoP%2BvgBhwSdb0eURUoaT2Zsh6SyEHPwb5xB6LvxIb30I7Mm1tzGm0IGzQuwVdtjFEbIRZZFZ65Dgq2Lr3Ims9tCuUYx0ng33M9tgbjPjvnTTlwwvIF%2BI%2Bv%2BsWZKRjZRxDRxf6xSFkMwohABL8RM%2F%2BRn4igX%2Bx2gMIdFtrClOj7kTVh5FtUtwxswphWLGmO8dxDTtjTImUiiKv8hLwlhFKRwgZGXSLz5dqR61Sdz3HHtexXrbRMV8%2B1lijvFFoNFHd4EwFHINks9Tll4Eh9BN3CYhUBGL6X%2BEtg%3D%3D

During handling of the above exception, another exception occurred:

Traceback (most recent call last):
  File "/home/zhuhe/.conda/envs/diffhpe/lib/python3.9/concurrent/futures/thread.py", line 58, in run
    result = self.fn(*self.args, **self.kwargs)
  File "/home/zhuhe/.conda/envs/diffhpe/lib/python3.9/site-packages/wandb/filesync/step_upload.py", line 288, in run_and_notify
    self._do_upload_sync(event)
  File "/home/zhuhe/.conda/envs/diffhpe/lib/python3.9/site-packages/wandb/filesync/step_upload.py", line 330, in _do_upload_sync
    job.run()
  File "/home/zhuhe/.conda/envs/diffhpe/lib/python3.9/site-packages/wandb/filesync/upload_job.py", line 57, in run
    self.push()
  File "/home/zhuhe/.conda/envs/diffhpe/lib/python3.9/site-packages/wandb/filesync/upload_job.py", line 127, in push
    self._api.upload_file_retry(
  File "/home/zhuhe/.conda/envs/diffhpe/lib/python3.9/site-packages/wandb/apis/normalize.py", line 51, in wrapper
    raise CommError(message, error)
wandb.errors.CommError: <Response [404]>
2023-07-10 15:38:33,653 ERROR   Thread-11 :45916 [step_upload.py:_handle_event():200] Failed to upload file: /home/zhuhe/HPE-with-Diffusion/wandb/run-20230710_153816-a3ox2pn0/files/requirements.txt
Traceback (most recent call last):
  File "/home/zhuhe/.conda/envs/diffhpe/lib/python3.9/site-packages/wandb/apis/normalize.py", line 41, in wrapper
    return func(*args, **kwargs)
  File "/home/zhuhe/.conda/envs/diffhpe/lib/python3.9/site-packages/wandb/sdk/lib/retry.py", line 212, in wrapped_fn
    return retrier(*args, **kargs)
  File "/home/zhuhe/.conda/envs/diffhpe/lib/python3.9/site-packages/wandb/sdk/lib/retry.py", line 131, in __call__
    result = self._call_fn(*args, **kwargs)
  File "/home/zhuhe/.conda/envs/diffhpe/lib/python3.9/site-packages/wandb/sdk/internal/internal_api.py", line 2218, in upload_file
    wandb._sentry.reraise(e)
  File "/home/zhuhe/.conda/envs/diffhpe/lib/python3.9/site-packages/wandb/analytics/sentry.py", line 146, in reraise
    raise exc.with_traceback(sys.exc_info()[2])
  File "/home/zhuhe/.conda/envs/diffhpe/lib/python3.9/site-packages/wandb/sdk/internal/internal_api.py", line 2190, in upload_file
    response.raise_for_status()
  File "/home/zhuhe/.conda/envs/diffhpe/lib/python3.9/site-packages/requests/models.py", line 1021, in raise_for_status
    raise HTTPError(http_error_msg, response=self)
requests.exceptions.HTTPError: 404 Client Error: Not Found for url: https://storage.googleapis.com/wandb-production.appspot.com/ada4321/DiffHPE/a3ox2pn0/requirements.txt?Expires=1689061111&GoogleAccessId=gorilla-files-url-signer-man%40wandb-production.iam.gserviceaccount.com&Signature=RRDMrY7mYV%2FMs3IihyHICuvbQayKdg8AeQQY2UGZQdkJOILwzWT4jJWtvUQ%2FKXi4kDRwdXvabkE578D0d0tp38KquS2juLNuc%2FQFJdkV%2FRrzn8aqk3GeqI1sqKuJAkU1lco6CBASS34MjtYvC1ji%2FufyY2fujLCOfFghmsnCzM6nNpyT8pstpFsdFi82e5lcVQiKEHUxDT5UQA5xw8NsQGG5w6ycD4Ed87UoD8%2Bra9gvEpOZtk3CppX%2BZv2aODshUAEFYLcK%2BqanCkrMC8p7KvIlZI8FxbKPOQT44N1yHOmIeH2E8AyNnXlgqjGlLOve%2BxSSBUavsEiaHNPOUnyvKQ%3D%3D

During handling of the above exception, another exception occurred:

Traceback (most recent call last):
  File "/home/zhuhe/.conda/envs/diffhpe/lib/python3.9/concurrent/futures/thread.py", line 58, in run
    result = self.fn(*self.args, **self.kwargs)
  File "/home/zhuhe/.conda/envs/diffhpe/lib/python3.9/site-packages/wandb/filesync/step_upload.py", line 288, in run_and_notify
    self._do_upload_sync(event)
  File "/home/zhuhe/.conda/envs/diffhpe/lib/python3.9/site-packages/wandb/filesync/step_upload.py", line 330, in _do_upload_sync
    job.run()
  File "/home/zhuhe/.conda/envs/diffhpe/lib/python3.9/site-packages/wandb/filesync/upload_job.py", line 57, in run
    self.push()
  File "/home/zhuhe/.conda/envs/diffhpe/lib/python3.9/site-packages/wandb/filesync/upload_job.py", line 127, in push
    self._api.upload_file_retry(
  File "/home/zhuhe/.conda/envs/diffhpe/lib/python3.9/site-packages/wandb/apis/normalize.py", line 51, in wrapper
    raise CommError(message, error)
wandb.errors.CommError: <Response [404]>
2023-07-10 15:38:33,653 ERROR   Thread-11 :45916 [step_upload.py:_handle_event():200] Failed to upload file: /home/zhuhe/HPE-with-Diffusion/wandb/run-20230710_153816-a3ox2pn0/files/output.log
Traceback (most recent call last):
  File "/home/zhuhe/.conda/envs/diffhpe/lib/python3.9/site-packages/wandb/apis/normalize.py", line 41, in wrapper
    return func(*args, **kwargs)
  File "/home/zhuhe/.conda/envs/diffhpe/lib/python3.9/site-packages/wandb/sdk/lib/retry.py", line 212, in wrapped_fn
    return retrier(*args, **kargs)
  File "/home/zhuhe/.conda/envs/diffhpe/lib/python3.9/site-packages/wandb/sdk/lib/retry.py", line 131, in __call__
    result = self._call_fn(*args, **kwargs)
  File "/home/zhuhe/.conda/envs/diffhpe/lib/python3.9/site-packages/wandb/sdk/internal/internal_api.py", line 2218, in upload_file
    wandb._sentry.reraise(e)
  File "/home/zhuhe/.conda/envs/diffhpe/lib/python3.9/site-packages/wandb/analytics/sentry.py", line 146, in reraise
    raise exc.with_traceback(sys.exc_info()[2])
  File "/home/zhuhe/.conda/envs/diffhpe/lib/python3.9/site-packages/wandb/sdk/internal/internal_api.py", line 2190, in upload_file
    response.raise_for_status()
  File "/home/zhuhe/.conda/envs/diffhpe/lib/python3.9/site-packages/requests/models.py", line 1021, in raise_for_status
    raise HTTPError(http_error_msg, response=self)
requests.exceptions.HTTPError: 404 Client Error: Not Found for url: https://storage.googleapis.com/wandb-production.appspot.com/ada4321/DiffHPE/a3ox2pn0/output.log?Expires=1689061111&GoogleAccessId=gorilla-files-url-signer-man%40wandb-production.iam.gserviceaccount.com&Signature=FIpZY78On0Ap6kVnIzK1T%2FnwfXPqfPi23t3%2BATPjGwveYploHtxzfXI8niSqhOJPya2DGKgz6DrLC6cU0Ac3uYdk0tNCEAGT%2BS9Rnl3mY%2BA5UPZijyaQtuI3ocbKPC%2BTh5xVnC0knSRXmGCOPmLk2Jg4srDqtAPFRVFrQebxPIYhS1YFMAOU7%2FBO4%2FtdN%2B5jyBjHWSwc44Bht2l3%2F8QQGJ%2Fqd3dEJRsbyTpYoJOdzIqx4C6kjBSZ1qNE67eYSg5MYN4uvcgQWHSZO29Ugy4z3WrGOPJQLb%2B%2BAn9Wj%2FBoU%2FowgWHav%2B6uEMWDswm3M6cKH5oDgJ%2FWiivzT3WXQGvQXg%3D%3D

During handling of the above exception, another exception occurred:

Traceback (most recent call last):
  File "/home/zhuhe/.conda/envs/diffhpe/lib/python3.9/concurrent/futures/thread.py", line 58, in run
    result = self.fn(*self.args, **self.kwargs)
  File "/home/zhuhe/.conda/envs/diffhpe/lib/python3.9/site-packages/wandb/filesync/step_upload.py", line 288, in run_and_notify
    self._do_upload_sync(event)
  File "/home/zhuhe/.conda/envs/diffhpe/lib/python3.9/site-packages/wandb/filesync/step_upload.py", line 330, in _do_upload_sync
    job.run()
  File "/home/zhuhe/.conda/envs/diffhpe/lib/python3.9/site-packages/wandb/filesync/upload_job.py", line 57, in run
    self.push()
  File "/home/zhuhe/.conda/envs/diffhpe/lib/python3.9/site-packages/wandb/filesync/upload_job.py", line 127, in push
    self._api.upload_file_retry(
  File "/home/zhuhe/.conda/envs/diffhpe/lib/python3.9/site-packages/wandb/apis/normalize.py", line 51, in wrapper
    raise CommError(message, error)
wandb.errors.CommError: <Response [404]>
2023-07-10 15:38:33,653 ERROR   Thread-11 :45916 [step_upload.py:_handle_event():200] Failed to upload file: /home/zhuhe/HPE-with-Diffusion/wandb/run-20230710_153816-a3ox2pn0/files/wandb-summary.json
Traceback (most recent call last):
  File "/home/zhuhe/.conda/envs/diffhpe/lib/python3.9/site-packages/wandb/apis/normalize.py", line 41, in wrapper
    return func(*args, **kwargs)
  File "/home/zhuhe/.conda/envs/diffhpe/lib/python3.9/site-packages/wandb/sdk/lib/retry.py", line 212, in wrapped_fn
    return retrier(*args, **kargs)
  File "/home/zhuhe/.conda/envs/diffhpe/lib/python3.9/site-packages/wandb/sdk/lib/retry.py", line 131, in __call__
    result = self._call_fn(*args, **kwargs)
  File "/home/zhuhe/.conda/envs/diffhpe/lib/python3.9/site-packages/wandb/sdk/internal/internal_api.py", line 2218, in upload_file
    wandb._sentry.reraise(e)
  File "/home/zhuhe/.conda/envs/diffhpe/lib/python3.9/site-packages/wandb/analytics/sentry.py", line 146, in reraise
    raise exc.with_traceback(sys.exc_info()[2])
  File "/home/zhuhe/.conda/envs/diffhpe/lib/python3.9/site-packages/wandb/sdk/internal/internal_api.py", line 2190, in upload_file
    response.raise_for_status()
  File "/home/zhuhe/.conda/envs/diffhpe/lib/python3.9/site-packages/requests/models.py", line 1021, in raise_for_status
    raise HTTPError(http_error_msg, response=self)
requests.exceptions.HTTPError: 404 Client Error: Not Found for url: https://storage.googleapis.com/wandb-production.appspot.com/ada4321/DiffHPE/a3ox2pn0/wandb-summary.json?Expires=1689061111&GoogleAccessId=gorilla-files-url-signer-man%40wandb-production.iam.gserviceaccount.com&Signature=hUIzrFXbfB3lwNvHXMZTGHvh8KAQyn5rN7edvdhh373b5DWK4hPTV7gnyjfwschtAZD7Pbnh%2B9Ih5SGF8n%2FYFkFo9ZD4NEsdv9bjSdlmz%2FXtYrZBIwOVMaxbSYXxK7vGLc3UuoRc%2BxTAAMGgK3FgJHSx9zweN%2BHPrlMusrZT6joiGh%2FXS0FH6M7LIoxvsXt6NXkUT9ARYRy4szOyD4r4IbWKidhpvziqNszPiunAdVjsoTJ%2BqPym%2FD2hSpvLRoaYwrTGRM4rGb5VbIMsxYUwWCf0CHOnYYfQ%2F%2B9s56FIOMZ28Ik76VS%2FK9ZfZokCCrhs0MrFu6LgIT6nZ6yDh1GB8Q%3D%3D

During handling of the above exception, another exception occurred:

Traceback (most recent call last):
  File "/home/zhuhe/.conda/envs/diffhpe/lib/python3.9/concurrent/futures/thread.py", line 58, in run
    result = self.fn(*self.args, **self.kwargs)
  File "/home/zhuhe/.conda/envs/diffhpe/lib/python3.9/site-packages/wandb/filesync/step_upload.py", line 288, in run_and_notify
    self._do_upload_sync(event)
  File "/home/zhuhe/.conda/envs/diffhpe/lib/python3.9/site-packages/wandb/filesync/step_upload.py", line 330, in _do_upload_sync
    job.run()
  File "/home/zhuhe/.conda/envs/diffhpe/lib/python3.9/site-packages/wandb/filesync/upload_job.py", line 57, in run
    self.push()
  File "/home/zhuhe/.conda/envs/diffhpe/lib/python3.9/site-packages/wandb/filesync/upload_job.py", line 127, in push
    self._api.upload_file_retry(
  File "/home/zhuhe/.conda/envs/diffhpe/lib/python3.9/site-packages/wandb/apis/normalize.py", line 51, in wrapper
    raise CommError(message, error)
wandb.errors.CommError: <Response [404]>
2023-07-10 15:38:33,854 INFO    Thread-11 :45916 [sender.py:transition_state():602] send defer: 11
2023-07-10 15:38:33,854 DEBUG   HandlerThread:45916 [handler.py:handle_request():144] handle_request: defer
2023-07-10 15:38:33,854 INFO    HandlerThread:45916 [handler.py:handle_request_defer():170] handle defer: 11
2023-07-10 15:38:33,854 DEBUG   SenderThread:45916 [sender.py:send_request():396] send_request: defer
2023-07-10 15:38:33,854 INFO    SenderThread:45916 [sender.py:send_request_defer():598] handle sender defer: 11
2023-07-10 15:38:33,854 INFO    SenderThread:45916 [file_pusher.py:join():164] waiting for file pusher
2023-07-10 15:38:33,854 INFO    SenderThread:45916 [sender.py:transition_state():602] send defer: 12
2023-07-10 15:38:33,855 DEBUG   HandlerThread:45916 [handler.py:handle_request():144] handle_request: defer
2023-07-10 15:38:33,855 INFO    HandlerThread:45916 [handler.py:handle_request_defer():170] handle defer: 12
2023-07-10 15:38:33,855 DEBUG   SenderThread:45916 [sender.py:send_request():396] send_request: defer
2023-07-10 15:38:33,855 INFO    SenderThread:45916 [sender.py:send_request_defer():598] handle sender defer: 12
2023-07-10 15:38:34,100 INFO    SenderThread:45916 [sender.py:transition_state():602] send defer: 13
2023-07-10 15:38:34,100 DEBUG   HandlerThread:45916 [handler.py:handle_request():144] handle_request: defer
2023-07-10 15:38:34,100 INFO    HandlerThread:45916 [handler.py:handle_request_defer():170] handle defer: 13
2023-07-10 15:38:34,100 DEBUG   SenderThread:45916 [sender.py:send_request():396] send_request: defer
2023-07-10 15:38:34,100 INFO    SenderThread:45916 [sender.py:send_request_defer():598] handle sender defer: 13
2023-07-10 15:38:34,100 INFO    SenderThread:45916 [sender.py:transition_state():602] send defer: 14
2023-07-10 15:38:34,100 DEBUG   HandlerThread:45916 [handler.py:handle_request():144] handle_request: defer
2023-07-10 15:38:34,100 INFO    HandlerThread:45916 [handler.py:handle_request_defer():170] handle defer: 14
2023-07-10 15:38:34,101 DEBUG   SenderThread:45916 [sender.py:send():369] send: final
2023-07-10 15:38:34,101 DEBUG   SenderThread:45916 [sender.py:send():369] send: footer
2023-07-10 15:38:34,101 DEBUG   SenderThread:45916 [sender.py:send_request():396] send_request: defer
2023-07-10 15:38:34,101 INFO    SenderThread:45916 [sender.py:send_request_defer():598] handle sender defer: 14
2023-07-10 15:38:34,101 DEBUG   HandlerThread:45916 [handler.py:handle_request():144] handle_request: poll_exit
2023-07-10 15:38:34,101 DEBUG   SenderThread:45916 [sender.py:send_request():396] send_request: poll_exit
2023-07-10 15:38:34,101 DEBUG   HandlerThread:45916 [handler.py:handle_request():144] handle_request: server_info
2023-07-10 15:38:34,101 DEBUG   SenderThread:45916 [sender.py:send_request():396] send_request: server_info
2023-07-10 15:38:34,103 DEBUG   HandlerThread:45916 [handler.py:handle_request():144] handle_request: get_summary
2023-07-10 15:38:34,103 DEBUG   HandlerThread:45916 [handler.py:handle_request():144] handle_request: sampled_history
2023-07-10 15:38:34,546 INFO    MainThread:45916 [wandb_run.py:_footer_history_summary_info():3467] rendering history
2023-07-10 15:38:34,546 INFO    MainThread:45916 [wandb_run.py:_footer_history_summary_info():3499] rendering summary
2023-07-10 15:38:34,546 INFO    MainThread:45916 [wandb_run.py:_footer_sync_info():3426] logging synced files
2023-07-10 15:38:34,546 DEBUG   HandlerThread:45916 [handler.py:handle_request():144] handle_request: shutdown
2023-07-10 15:38:34,547 INFO    HandlerThread:45916 [handler.py:finish():854] shutting down handler
2023-07-10 15:38:35,102 INFO    WriterThread:45916 [datastore.py:close():298] close: /home/zhuhe/HPE-with-Diffusion/wandb/run-20230710_153816-a3ox2pn0/run-a3ox2pn0.wandb
2023-07-10 15:38:35,546 INFO    SenderThread:45916 [sender.py:finish():1526] shutting down sender
2023-07-10 15:38:35,546 INFO    SenderThread:45916 [file_pusher.py:finish():159] shutting down file pusher
2023-07-10 15:38:35,546 INFO    SenderThread:45916 [file_pusher.py:join():164] waiting for file pusher
