2023-07-10 14:56:41,557 INFO    StreamThr :32738 [internal.py:wandb_internal():86] W&B internal server running at pid: 32738, started at: 2023-07-10 14:56:41.556900
2023-07-10 14:56:41,557 DEBUG   HandlerThread:32738 [handler.py:handle_request():144] handle_request: status
2023-07-10 14:56:41,558 INFO    WriterThread:32738 [datastore.py:open_for_write():85] open: /home/zhuhe/HPE-with-Diffusion/wandb/run-20230710_145641-tf2mpncg/run-tf2mpncg.wandb
2023-07-10 14:56:41,559 DEBUG   SenderThread:32738 [sender.py:send():369] send: header
2023-07-10 14:56:41,559 DEBUG   SenderThread:32738 [sender.py:send():369] send: run
2023-07-10 14:56:42,423 INFO    SenderThread:32738 [dir_watcher.py:__init__():211] watching files in: /home/zhuhe/HPE-with-Diffusion/wandb/run-20230710_145641-tf2mpncg/files
2023-07-10 14:56:42,423 INFO    SenderThread:32738 [sender.py:_start_run_threads():1100] run started: tf2mpncg with start time 1688972201.556711
2023-07-10 14:56:42,423 DEBUG   SenderThread:32738 [sender.py:send_request():396] send_request: summary_record
2023-07-10 14:56:42,423 INFO    SenderThread:32738 [sender.py:_save_file():1354] saving file wandb-summary.json with policy end
2023-07-10 14:56:42,425 DEBUG   HandlerThread:32738 [handler.py:handle_request():144] handle_request: check_version
2023-07-10 14:56:42,425 DEBUG   SenderThread:32738 [sender.py:send_request():396] send_request: check_version
2023-07-10 14:56:42,601 DEBUG   HandlerThread:32738 [handler.py:handle_request():144] handle_request: run_start
2023-07-10 14:56:42,605 DEBUG   HandlerThread:32738 [system_info.py:__init__():31] System info init
2023-07-10 14:56:42,605 DEBUG   HandlerThread:32738 [system_info.py:__init__():46] System info init done
2023-07-10 14:56:42,605 INFO    HandlerThread:32738 [system_monitor.py:start():181] Starting system monitor
2023-07-10 14:56:42,605 INFO    SystemMonitor:32738 [system_monitor.py:_start():145] Starting system asset monitoring threads
2023-07-10 14:56:42,606 INFO    HandlerThread:32738 [system_monitor.py:probe():201] Collecting system info
2023-07-10 14:56:42,606 INFO    SystemMonitor:32738 [interfaces.py:start():190] Started cpu monitoring
2023-07-10 14:56:42,607 INFO    SystemMonitor:32738 [interfaces.py:start():190] Started disk monitoring
2023-07-10 14:56:42,607 INFO    SystemMonitor:32738 [interfaces.py:start():190] Started gpu monitoring
2023-07-10 14:56:42,607 INFO    SystemMonitor:32738 [interfaces.py:start():190] Started memory monitoring
2023-07-10 14:56:42,607 INFO    SystemMonitor:32738 [interfaces.py:start():190] Started network monitoring
2023-07-10 14:56:42,623 DEBUG   HandlerThread:32738 [system_info.py:probe():195] Probing system
2023-07-10 14:56:42,627 DEBUG   HandlerThread:32738 [gitlib.py:_init_repo():53] git repository is invalid
2023-07-10 14:56:42,627 DEBUG   HandlerThread:32738 [system_info.py:probe():240] Probing system done
2023-07-10 14:56:42,627 DEBUG   HandlerThread:32738 [system_monitor.py:probe():210] {'os': 'Linux-5.19.0-46-generic-x86_64-with-glibc2.35', 'python': '3.9.16', 'heartbeatAt': '2023-07-10T06:56:42.623752', 'startedAt': '2023-07-10T06:56:41.553734', 'docker': None, 'cuda': None, 'args': ('--phase', 'train', '--gpu_ids', '1'), 'state': 'running', 'program': '/home/zhuhe/HPE-with-Diffusion/main.py', 'codePath': 'main.py', 'host': '415-2', 'username': 'zhuhe', 'executable': '/home/zhuhe/.conda/envs/diffhpe/bin/python', 'cpu_count': 16, 'cpu_count_logical': 24, 'cpu_freq': {'current': 3310.7315833333328, 'min': 800.0, 'max': 4783.333333333333}, 'cpu_freq_per_core': [{'current': 5084.061, 'min': 800.0, 'max': 5100.0}, {'current': 5105.13, 'min': 800.0, 'max': 5100.0}, {'current': 2100.0, 'min': 800.0, 'max': 5100.0}, {'current': 5100.0, 'min': 800.0, 'max': 5100.0}, {'current': 2100.0, 'min': 800.0, 'max': 5100.0}, {'current': 2100.0, 'min': 800.0, 'max': 5100.0}, {'current': 5055.144, 'min': 800.0, 'max': 5100.0}, {'current': 4310.914, 'min': 800.0, 'max': 5100.0}, {'current': 5037.731, 'min': 800.0, 'max': 5200.0}, {'current': 2100.0, 'min': 800.0, 'max': 5200.0}, {'current': 5100.0, 'min': 800.0, 'max': 5200.0}, {'current': 2100.0, 'min': 800.0, 'max': 5200.0}, {'current': 5100.0, 'min': 800.0, 'max': 5100.0}, {'current': 2100.0, 'min': 800.0, 'max': 5100.0}, {'current': 5100.0, 'min': 800.0, 'max': 5100.0}, {'current': 5064.578, 'min': 800.0, 'max': 5100.0}, {'current': 2100.0, 'min': 800.0, 'max': 4100.0}, {'current': 2100.0, 'min': 800.0, 'max': 4100.0}, {'current': 2100.0, 'min': 800.0, 'max': 4100.0}, {'current': 2100.0, 'min': 800.0, 'max': 4100.0}, {'current': 2100.0, 'min': 800.0, 'max': 4100.0}, {'current': 2100.0, 'min': 800.0, 'max': 4100.0}, {'current': 2100.0, 'min': 800.0, 'max': 4100.0}, {'current': 2100.0, 'min': 800.0, 'max': 4100.0}], 'disk': {'total': 93.31179428100586, 'used': 0.017879486083984375}, 'gpu': 'NVIDIA GeForce RTX 3090', 'gpu_count': 2, 'gpu_devices': [{'name': 'NVIDIA GeForce RTX 3090', 'memory_total': 25769803776}, {'name': 'NVIDIA GeForce RTX 3090', 'memory_total': 25769803776}], 'memory': {'total': 31.185562133789062}}
2023-07-10 14:56:42,627 INFO    HandlerThread:32738 [system_monitor.py:probe():211] Finished collecting system info
2023-07-10 14:56:42,627 INFO    HandlerThread:32738 [system_monitor.py:probe():214] Publishing system info
2023-07-10 14:56:42,627 DEBUG   HandlerThread:32738 [system_info.py:_save_pip():51] Saving list of pip packages installed into the current environment
2023-07-10 14:56:42,627 DEBUG   HandlerThread:32738 [system_info.py:_save_pip():67] Saving pip packages done
2023-07-10 14:56:42,627 DEBUG   HandlerThread:32738 [system_info.py:_save_conda():74] Saving list of conda packages installed into the current environment
2023-07-10 14:56:43,416 DEBUG   HandlerThread:32738 [system_info.py:_save_conda():86] Saving conda packages done
2023-07-10 14:56:43,416 INFO    HandlerThread:32738 [system_monitor.py:probe():216] Finished publishing system info
2023-07-10 14:56:43,418 DEBUG   SenderThread:32738 [sender.py:send():369] send: files
2023-07-10 14:56:43,418 INFO    SenderThread:32738 [sender.py:_save_file():1354] saving file wandb-metadata.json with policy now
2023-07-10 14:56:43,421 DEBUG   HandlerThread:32738 [handler.py:handle_request():144] handle_request: stop_status
2023-07-10 14:56:43,421 DEBUG   SenderThread:32738 [sender.py:send_request():396] send_request: stop_status
2023-07-10 14:56:43,424 INFO    Thread-12 :32738 [dir_watcher.py:_on_file_created():272] file/dir created: /home/zhuhe/HPE-with-Diffusion/wandb/run-20230710_145641-tf2mpncg/files/conda-environment.yaml
2023-07-10 14:56:43,424 INFO    Thread-12 :32738 [dir_watcher.py:_on_file_created():272] file/dir created: /home/zhuhe/HPE-with-Diffusion/wandb/run-20230710_145641-tf2mpncg/files/wandb-summary.json
2023-07-10 14:56:43,424 INFO    Thread-12 :32738 [dir_watcher.py:_on_file_created():272] file/dir created: /home/zhuhe/HPE-with-Diffusion/wandb/run-20230710_145641-tf2mpncg/files/requirements.txt
2023-07-10 14:56:43,424 INFO    Thread-12 :32738 [dir_watcher.py:_on_file_created():272] file/dir created: /home/zhuhe/HPE-with-Diffusion/wandb/run-20230710_145641-tf2mpncg/files/wandb-metadata.json
2023-07-10 14:56:43,935 ERROR   wandb-upload_0:32738 [internal_api.py:upload_file():2192] upload_file exception https://storage.googleapis.com/wandb-production.appspot.com/ada4321/DiffHPE/tf2mpncg/wandb-metadata.json?Expires=1689058603&GoogleAccessId=gorilla-files-url-signer-man%40wandb-production.iam.gserviceaccount.com&Signature=OZw88i5iBIlR%2Bh%2Bx1%2FtkU%2BGs%2BsCEgMZdgg79fBAdAP1dxM%2BeouSRii1sZL6yfNoP7exNA80uAAZkdXkBYH3i7SCRDS4mlhosurr1iraLYgKUWINE0Y6t2B03SbuzCX56mwuEn9zAJl6PdKJV7cXd7NkJozbiwrLGVhtngyPtStRz5b2eWxyWBCqUzJWpW95iwtU42ialkTXU%2B3SgA3P%2F4KM%2FW1DhbX%2BoG4YKqV3HQJaIBjbBqleNh49x9lXg1mcGa0QTaw1%2FUHUaSt75cF5Fo6AYh1DgxvjjhvljMYihfZBxe0eQPKdFTceLGyCcBxahyMAvEy8Z4%2BeowK25enNIhw%3D%3D: 404 Client Error: Not Found for url: https://storage.googleapis.com/wandb-production.appspot.com/ada4321/DiffHPE/tf2mpncg/wandb-metadata.json?Expires=1689058603&GoogleAccessId=gorilla-files-url-signer-man%40wandb-production.iam.gserviceaccount.com&Signature=OZw88i5iBIlR%2Bh%2Bx1%2FtkU%2BGs%2BsCEgMZdgg79fBAdAP1dxM%2BeouSRii1sZL6yfNoP7exNA80uAAZkdXkBYH3i7SCRDS4mlhosurr1iraLYgKUWINE0Y6t2B03SbuzCX56mwuEn9zAJl6PdKJV7cXd7NkJozbiwrLGVhtngyPtStRz5b2eWxyWBCqUzJWpW95iwtU42ialkTXU%2B3SgA3P%2F4KM%2FW1DhbX%2BoG4YKqV3HQJaIBjbBqleNh49x9lXg1mcGa0QTaw1%2FUHUaSt75cF5Fo6AYh1DgxvjjhvljMYihfZBxe0eQPKdFTceLGyCcBxahyMAvEy8Z4%2BeowK25enNIhw%3D%3D
2023-07-10 14:56:43,935 ERROR   wandb-upload_0:32738 [internal_api.py:upload_file():2194] upload_file request headers: {'User-Agent': 'python-requests/2.31.0', 'Accept-Encoding': 'gzip, deflate', 'Accept': '*/*', 'Connection': 'keep-alive', 'Content-Length': '3691'}
2023-07-10 14:56:43,935 ERROR   wandb-upload_0:32738 [internal_api.py:upload_file():2196] upload_file response body: b'<!DOCTYPE html>\n<html lang=en>\n  <meta charset=utf-8>\n  <meta name=viewport content="initial-scale=1, minimum-scale=1, width=device-width">\n  <title>Error 404 (Not Found)!!1</title>\n  <style>\n    *{margin:0;padding:0}html,code{font:15px/22px arial,sans-serif}html{background:#fff;color:#222;padding:15px}body{margin:7% auto 0;max-width:390px;min-height:180px;padding:30px 0 15px}* > body{background:url(//www.google.com/images/errors/robot.png) 100% 5px no-repeat;padding-right:205px}p{margin:11px 0 22px;overflow:hidden}ins{color:#777;text-decoration:none}a img{border:0}@media screen and (max-width:772px){body{background:none;margin-top:0;max-width:none;padding-right:0}}#logo{background:url(//www.google.com/images/branding/googlelogo/1x/googlelogo_color_150x54dp.png) no-repeat;margin-left:-5px}@media only screen and (min-resolution:192dpi){#logo{background:url(//www.google.com/images/branding/googlelogo/2x/googlelogo_color_150x54dp.png) no-repeat 0% 0%/100% 100%;-moz-border-image:url(//www.google.com/images/branding/googlelogo/2x/googlelogo_color_150x54dp.png) 0}}@media only screen and (-webkit-min-device-pixel-ratio:2){#logo{background:url(//www.google.com/images/branding/googlelogo/2x/googlelogo_color_150x54dp.png) no-repeat;-webkit-background-size:100% 100%}}#logo{display:inline-block;height:54px;width:150px}\n  </style>\n  <a href=//www.google.com/><span id=logo aria-label=Google></span></a>\n  <p><b>404.</b> <ins>That\xe2\x80\x99s an error.</ins>\n  <p>The requested URL <code>/wandb-production.appspot.com/ada4321/DiffHPE/tf2mpncg/wandb-metadata.json</code> was not found on this server.  <ins>That\xe2\x80\x99s all we know.</ins>\n'
2023-07-10 14:56:43,991 DEBUG   SenderThread:32738 [sender.py:send():369] send: telemetry
2023-07-10 14:56:43,991 DEBUG   SenderThread:32738 [sender.py:send():369] send: exit
2023-07-10 14:56:43,991 INFO    SenderThread:32738 [sender.py:send_exit():574] handling exit code: 1
2023-07-10 14:56:43,991 INFO    SenderThread:32738 [sender.py:send_exit():576] handling runtime: 0
2023-07-10 14:56:43,992 INFO    SenderThread:32738 [sender.py:_save_file():1354] saving file wandb-summary.json with policy end
2023-07-10 14:56:43,992 INFO    SenderThread:32738 [sender.py:send_exit():582] send defer
2023-07-10 14:56:43,992 DEBUG   HandlerThread:32738 [handler.py:handle_request():144] handle_request: defer
2023-07-10 14:56:43,992 INFO    HandlerThread:32738 [handler.py:handle_request_defer():170] handle defer: 0
2023-07-10 14:56:43,992 DEBUG   SenderThread:32738 [sender.py:send_request():396] send_request: defer
2023-07-10 14:56:43,992 INFO    SenderThread:32738 [sender.py:send_request_defer():598] handle sender defer: 0
2023-07-10 14:56:43,992 INFO    SenderThread:32738 [sender.py:transition_state():602] send defer: 1
2023-07-10 14:56:43,992 DEBUG   HandlerThread:32738 [handler.py:handle_request():144] handle_request: defer
2023-07-10 14:56:43,992 INFO    HandlerThread:32738 [handler.py:handle_request_defer():170] handle defer: 1
2023-07-10 14:56:43,992 DEBUG   SenderThread:32738 [sender.py:send_request():396] send_request: defer
2023-07-10 14:56:43,992 INFO    SenderThread:32738 [sender.py:send_request_defer():598] handle sender defer: 1
2023-07-10 14:56:43,992 INFO    SenderThread:32738 [sender.py:transition_state():602] send defer: 2
2023-07-10 14:56:43,992 DEBUG   HandlerThread:32738 [handler.py:handle_request():144] handle_request: defer
2023-07-10 14:56:43,992 INFO    HandlerThread:32738 [handler.py:handle_request_defer():170] handle defer: 2
2023-07-10 14:56:43,992 INFO    HandlerThread:32738 [system_monitor.py:finish():190] Stopping system monitor
2023-07-10 14:56:43,993 DEBUG   SystemMonitor:32738 [system_monitor.py:_start():159] Starting system metrics aggregation loop
2023-07-10 14:56:43,993 INFO    HandlerThread:32738 [interfaces.py:finish():202] Joined cpu monitor
2023-07-10 14:56:43,993 DEBUG   SystemMonitor:32738 [system_monitor.py:_start():166] Finished system metrics aggregation loop
2023-07-10 14:56:43,993 INFO    HandlerThread:32738 [interfaces.py:finish():202] Joined disk monitor
2023-07-10 14:56:43,993 DEBUG   SystemMonitor:32738 [system_monitor.py:_start():170] Publishing last batch of metrics
2023-07-10 14:56:44,042 INFO    HandlerThread:32738 [interfaces.py:finish():202] Joined gpu monitor
2023-07-10 14:56:44,042 INFO    HandlerThread:32738 [interfaces.py:finish():202] Joined memory monitor
2023-07-10 14:56:44,042 INFO    HandlerThread:32738 [interfaces.py:finish():202] Joined network monitor
2023-07-10 14:56:44,043 DEBUG   SenderThread:32738 [sender.py:send_request():396] send_request: defer
2023-07-10 14:56:44,043 INFO    SenderThread:32738 [sender.py:send_request_defer():598] handle sender defer: 2
2023-07-10 14:56:44,043 INFO    SenderThread:32738 [sender.py:transition_state():602] send defer: 3
2023-07-10 14:56:44,043 DEBUG   SenderThread:32738 [sender.py:send():369] send: stats
2023-07-10 14:56:44,043 DEBUG   HandlerThread:32738 [handler.py:handle_request():144] handle_request: defer
2023-07-10 14:56:44,043 INFO    HandlerThread:32738 [handler.py:handle_request_defer():170] handle defer: 3
2023-07-10 14:56:44,043 DEBUG   SenderThread:32738 [sender.py:send_request():396] send_request: defer
2023-07-10 14:56:44,043 INFO    SenderThread:32738 [sender.py:send_request_defer():598] handle sender defer: 3
2023-07-10 14:56:44,043 INFO    SenderThread:32738 [sender.py:transition_state():602] send defer: 4
2023-07-10 14:56:44,043 DEBUG   HandlerThread:32738 [handler.py:handle_request():144] handle_request: defer
2023-07-10 14:56:44,043 INFO    HandlerThread:32738 [handler.py:handle_request_defer():170] handle defer: 4
2023-07-10 14:56:44,043 DEBUG   SenderThread:32738 [sender.py:send_request():396] send_request: defer
2023-07-10 14:56:44,043 INFO    SenderThread:32738 [sender.py:send_request_defer():598] handle sender defer: 4
2023-07-10 14:56:44,043 INFO    SenderThread:32738 [sender.py:transition_state():602] send defer: 5
2023-07-10 14:56:44,044 DEBUG   HandlerThread:32738 [handler.py:handle_request():144] handle_request: defer
2023-07-10 14:56:44,044 INFO    HandlerThread:32738 [handler.py:handle_request_defer():170] handle defer: 5
2023-07-10 14:56:44,044 DEBUG   SenderThread:32738 [sender.py:send():369] send: summary
2023-07-10 14:56:44,044 INFO    SenderThread:32738 [sender.py:_save_file():1354] saving file wandb-summary.json with policy end
2023-07-10 14:56:44,044 DEBUG   SenderThread:32738 [sender.py:send_request():396] send_request: defer
2023-07-10 14:56:44,044 INFO    SenderThread:32738 [sender.py:send_request_defer():598] handle sender defer: 5
2023-07-10 14:56:44,044 INFO    SenderThread:32738 [sender.py:transition_state():602] send defer: 6
2023-07-10 14:56:44,044 DEBUG   HandlerThread:32738 [handler.py:handle_request():144] handle_request: defer
2023-07-10 14:56:44,044 INFO    HandlerThread:32738 [handler.py:handle_request_defer():170] handle defer: 6
2023-07-10 14:56:44,044 DEBUG   SenderThread:32738 [sender.py:send_request():396] send_request: defer
2023-07-10 14:56:44,044 INFO    SenderThread:32738 [sender.py:send_request_defer():598] handle sender defer: 6
2023-07-10 14:56:44,046 DEBUG   HandlerThread:32738 [handler.py:handle_request():144] handle_request: status_report
2023-07-10 14:56:44,292 INFO    SenderThread:32738 [sender.py:transition_state():602] send defer: 7
2023-07-10 14:56:44,292 DEBUG   HandlerThread:32738 [handler.py:handle_request():144] handle_request: defer
2023-07-10 14:56:44,292 INFO    HandlerThread:32738 [handler.py:handle_request_defer():170] handle defer: 7
2023-07-10 14:56:44,292 DEBUG   SenderThread:32738 [sender.py:send_request():396] send_request: defer
2023-07-10 14:56:44,292 INFO    SenderThread:32738 [sender.py:send_request_defer():598] handle sender defer: 7
2023-07-10 14:56:44,423 INFO    Thread-12 :32738 [dir_watcher.py:_on_file_modified():289] file/dir modified: /home/zhuhe/HPE-with-Diffusion/wandb/run-20230710_145641-tf2mpncg/files/wandb-summary.json
2023-07-10 14:56:44,424 INFO    Thread-12 :32738 [dir_watcher.py:_on_file_modified():289] file/dir modified: /home/zhuhe/HPE-with-Diffusion/wandb/run-20230710_145641-tf2mpncg/files/config.yaml
2023-07-10 14:56:44,424 INFO    Thread-12 :32738 [dir_watcher.py:_on_file_created():272] file/dir created: /home/zhuhe/HPE-with-Diffusion/wandb/run-20230710_145641-tf2mpncg/files/output.log
2023-07-10 14:56:44,424 DEBUG   HandlerThread:32738 [handler.py:handle_request():144] handle_request: poll_exit
2023-07-10 14:56:44,463 ERROR   wandb-upload_0:32738 [upload_job.py:push():136] Failed to upload file: /tmp/tmpgmu8bei2wandb/90nle618-wandb-metadata.json
Traceback (most recent call last):
  File "/home/zhuhe/.conda/envs/diffhpe/lib/python3.9/site-packages/wandb/apis/normalize.py", line 41, in wrapper
    return func(*args, **kwargs)
  File "/home/zhuhe/.conda/envs/diffhpe/lib/python3.9/site-packages/wandb/sdk/lib/retry.py", line 212, in wrapped_fn
    return retrier(*args, **kargs)
  File "/home/zhuhe/.conda/envs/diffhpe/lib/python3.9/site-packages/wandb/sdk/lib/retry.py", line 131, in __call__
    result = self._call_fn(*args, **kwargs)
  File "/home/zhuhe/.conda/envs/diffhpe/lib/python3.9/site-packages/wandb/sdk/internal/internal_api.py", line 2218, in upload_file
    wandb._sentry.reraise(e)
  File "/home/zhuhe/.conda/envs/diffhpe/lib/python3.9/site-packages/wandb/analytics/sentry.py", line 146, in reraise
    raise exc.with_traceback(sys.exc_info()[2])
  File "/home/zhuhe/.conda/envs/diffhpe/lib/python3.9/site-packages/wandb/sdk/internal/internal_api.py", line 2190, in upload_file
    response.raise_for_status()
  File "/home/zhuhe/.conda/envs/diffhpe/lib/python3.9/site-packages/requests/models.py", line 1021, in raise_for_status
    raise HTTPError(http_error_msg, response=self)
requests.exceptions.HTTPError: 404 Client Error: Not Found for url: https://storage.googleapis.com/wandb-production.appspot.com/ada4321/DiffHPE/tf2mpncg/wandb-metadata.json?Expires=1689058603&GoogleAccessId=gorilla-files-url-signer-man%40wandb-production.iam.gserviceaccount.com&Signature=OZw88i5iBIlR%2Bh%2Bx1%2FtkU%2BGs%2BsCEgMZdgg79fBAdAP1dxM%2BeouSRii1sZL6yfNoP7exNA80uAAZkdXkBYH3i7SCRDS4mlhosurr1iraLYgKUWINE0Y6t2B03SbuzCX56mwuEn9zAJl6PdKJV7cXd7NkJozbiwrLGVhtngyPtStRz5b2eWxyWBCqUzJWpW95iwtU42ialkTXU%2B3SgA3P%2F4KM%2FW1DhbX%2BoG4YKqV3HQJaIBjbBqleNh49x9lXg1mcGa0QTaw1%2FUHUaSt75cF5Fo6AYh1DgxvjjhvljMYihfZBxe0eQPKdFTceLGyCcBxahyMAvEy8Z4%2BeowK25enNIhw%3D%3D

During handling of the above exception, another exception occurred:

Traceback (most recent call last):
  File "/home/zhuhe/.conda/envs/diffhpe/lib/python3.9/site-packages/wandb/filesync/upload_job.py", line 127, in push
    self._api.upload_file_retry(
  File "/home/zhuhe/.conda/envs/diffhpe/lib/python3.9/site-packages/wandb/apis/normalize.py", line 51, in wrapper
    raise CommError(message, error)
wandb.errors.CommError: <Response [404]>
2023-07-10 14:56:44,668 ERROR   Thread-11 :32738 [step_upload.py:_handle_event():200] Failed to upload file: /tmp/tmpgmu8bei2wandb/90nle618-wandb-metadata.json
Traceback (most recent call last):
  File "/home/zhuhe/.conda/envs/diffhpe/lib/python3.9/site-packages/wandb/apis/normalize.py", line 41, in wrapper
    return func(*args, **kwargs)
  File "/home/zhuhe/.conda/envs/diffhpe/lib/python3.9/site-packages/wandb/sdk/lib/retry.py", line 212, in wrapped_fn
    return retrier(*args, **kargs)
  File "/home/zhuhe/.conda/envs/diffhpe/lib/python3.9/site-packages/wandb/sdk/lib/retry.py", line 131, in __call__
    result = self._call_fn(*args, **kwargs)
  File "/home/zhuhe/.conda/envs/diffhpe/lib/python3.9/site-packages/wandb/sdk/internal/internal_api.py", line 2218, in upload_file
    wandb._sentry.reraise(e)
  File "/home/zhuhe/.conda/envs/diffhpe/lib/python3.9/site-packages/wandb/analytics/sentry.py", line 146, in reraise
    raise exc.with_traceback(sys.exc_info()[2])
  File "/home/zhuhe/.conda/envs/diffhpe/lib/python3.9/site-packages/wandb/sdk/internal/internal_api.py", line 2190, in upload_file
    response.raise_for_status()
  File "/home/zhuhe/.conda/envs/diffhpe/lib/python3.9/site-packages/requests/models.py", line 1021, in raise_for_status
    raise HTTPError(http_error_msg, response=self)
requests.exceptions.HTTPError: 404 Client Error: Not Found for url: https://storage.googleapis.com/wandb-production.appspot.com/ada4321/DiffHPE/tf2mpncg/wandb-metadata.json?Expires=1689058603&GoogleAccessId=gorilla-files-url-signer-man%40wandb-production.iam.gserviceaccount.com&Signature=OZw88i5iBIlR%2Bh%2Bx1%2FtkU%2BGs%2BsCEgMZdgg79fBAdAP1dxM%2BeouSRii1sZL6yfNoP7exNA80uAAZkdXkBYH3i7SCRDS4mlhosurr1iraLYgKUWINE0Y6t2B03SbuzCX56mwuEn9zAJl6PdKJV7cXd7NkJozbiwrLGVhtngyPtStRz5b2eWxyWBCqUzJWpW95iwtU42ialkTXU%2B3SgA3P%2F4KM%2FW1DhbX%2BoG4YKqV3HQJaIBjbBqleNh49x9lXg1mcGa0QTaw1%2FUHUaSt75cF5Fo6AYh1DgxvjjhvljMYihfZBxe0eQPKdFTceLGyCcBxahyMAvEy8Z4%2BeowK25enNIhw%3D%3D

During handling of the above exception, another exception occurred:

Traceback (most recent call last):
  File "/home/zhuhe/.conda/envs/diffhpe/lib/python3.9/concurrent/futures/thread.py", line 58, in run
    result = self.fn(*self.args, **self.kwargs)
  File "/home/zhuhe/.conda/envs/diffhpe/lib/python3.9/site-packages/wandb/filesync/step_upload.py", line 288, in run_and_notify
    self._do_upload_sync(event)
  File "/home/zhuhe/.conda/envs/diffhpe/lib/python3.9/site-packages/wandb/filesync/step_upload.py", line 330, in _do_upload_sync
    job.run()
  File "/home/zhuhe/.conda/envs/diffhpe/lib/python3.9/site-packages/wandb/filesync/upload_job.py", line 57, in run
    self.push()
  File "/home/zhuhe/.conda/envs/diffhpe/lib/python3.9/site-packages/wandb/filesync/upload_job.py", line 127, in push
    self._api.upload_file_retry(
  File "/home/zhuhe/.conda/envs/diffhpe/lib/python3.9/site-packages/wandb/apis/normalize.py", line 51, in wrapper
    raise CommError(message, error)
wandb.errors.CommError: <Response [404]>
2023-07-10 14:56:45,996 INFO    SenderThread:32738 [sender.py:transition_state():602] send defer: 8
2023-07-10 14:56:45,997 DEBUG   SenderThread:32738 [sender.py:send_request():396] send_request: poll_exit
2023-07-10 14:56:45,997 DEBUG   HandlerThread:32738 [handler.py:handle_request():144] handle_request: defer
2023-07-10 14:56:45,997 INFO    HandlerThread:32738 [handler.py:handle_request_defer():170] handle defer: 8
2023-07-10 14:56:45,997 DEBUG   SenderThread:32738 [sender.py:send_request():396] send_request: defer
2023-07-10 14:56:45,997 INFO    SenderThread:32738 [sender.py:send_request_defer():598] handle sender defer: 8
2023-07-10 14:56:45,997 INFO    SenderThread:32738 [job_builder.py:build():232] Attempting to build job artifact
2023-07-10 14:56:45,997 INFO    SenderThread:32738 [job_builder.py:build():266] no source found
2023-07-10 14:56:45,997 INFO    SenderThread:32738 [sender.py:transition_state():602] send defer: 9
2023-07-10 14:56:45,997 DEBUG   HandlerThread:32738 [handler.py:handle_request():144] handle_request: defer
2023-07-10 14:56:45,997 INFO    HandlerThread:32738 [handler.py:handle_request_defer():170] handle defer: 9
2023-07-10 14:56:45,997 DEBUG   SenderThread:32738 [sender.py:send_request():396] send_request: defer
2023-07-10 14:56:45,997 INFO    SenderThread:32738 [sender.py:send_request_defer():598] handle sender defer: 9
2023-07-10 14:56:45,997 INFO    SenderThread:32738 [dir_watcher.py:finish():359] shutting down directory watcher
2023-07-10 14:56:46,424 INFO    Thread-12 :32738 [dir_watcher.py:_on_file_modified():289] file/dir modified: /home/zhuhe/HPE-with-Diffusion/wandb/run-20230710_145641-tf2mpncg/files/output.log
2023-07-10 14:56:46,425 INFO    SenderThread:32738 [dir_watcher.py:finish():389] scan: /home/zhuhe/HPE-with-Diffusion/wandb/run-20230710_145641-tf2mpncg/files
2023-07-10 14:56:46,425 INFO    SenderThread:32738 [dir_watcher.py:finish():403] scan save: /home/zhuhe/HPE-with-Diffusion/wandb/run-20230710_145641-tf2mpncg/files/wandb-metadata.json wandb-metadata.json
2023-07-10 14:56:46,425 INFO    SenderThread:32738 [dir_watcher.py:finish():403] scan save: /home/zhuhe/HPE-with-Diffusion/wandb/run-20230710_145641-tf2mpncg/files/config.yaml config.yaml
2023-07-10 14:56:46,425 INFO    SenderThread:32738 [dir_watcher.py:finish():403] scan save: /home/zhuhe/HPE-with-Diffusion/wandb/run-20230710_145641-tf2mpncg/files/requirements.txt requirements.txt
2023-07-10 14:56:46,425 INFO    SenderThread:32738 [dir_watcher.py:finish():403] scan save: /home/zhuhe/HPE-with-Diffusion/wandb/run-20230710_145641-tf2mpncg/files/wandb-summary.json wandb-summary.json
2023-07-10 14:56:46,425 INFO    SenderThread:32738 [dir_watcher.py:finish():403] scan save: /home/zhuhe/HPE-with-Diffusion/wandb/run-20230710_145641-tf2mpncg/files/conda-environment.yaml conda-environment.yaml
2023-07-10 14:56:46,425 INFO    SenderThread:32738 [dir_watcher.py:finish():403] scan save: /home/zhuhe/HPE-with-Diffusion/wandb/run-20230710_145641-tf2mpncg/files/output.log output.log
2023-07-10 14:56:46,425 INFO    SenderThread:32738 [sender.py:transition_state():602] send defer: 10
2023-07-10 14:56:46,425 DEBUG   HandlerThread:32738 [handler.py:handle_request():144] handle_request: defer
2023-07-10 14:56:46,428 INFO    HandlerThread:32738 [handler.py:handle_request_defer():170] handle defer: 10
2023-07-10 14:56:46,429 DEBUG   SenderThread:32738 [sender.py:send_request():396] send_request: defer
2023-07-10 14:56:46,429 INFO    SenderThread:32738 [sender.py:send_request_defer():598] handle sender defer: 10
2023-07-10 14:56:46,429 INFO    SenderThread:32738 [file_pusher.py:finish():159] shutting down file pusher
2023-07-10 14:56:46,969 ERROR   wandb-upload_1:32738 [internal_api.py:upload_file():2192] upload_file exception https://storage.googleapis.com/wandb-production.appspot.com/ada4321/DiffHPE/tf2mpncg/config.yaml?Expires=1689058606&GoogleAccessId=gorilla-files-url-signer-man%40wandb-production.iam.gserviceaccount.com&Signature=qC1Df2Oo06EaM5pfG1Wmg%2F0QFFYvT1ib5q3q1tIegAyDwyXDDGMJJ7pi29PvGnBSqeB2rMiBhC66Ee66Q6fy92TpNVQ3g%2BxAhBjDPV5Z0vrEhMNdKpXdHlm9rZs%2FUiScuoxguOyCe7bIptXQYwE8Ksj1fzKlsfclxDgXuS7LFtc8PWIE1bdjlwi4JdkvTOCPhyqDjTIvPXhlHH%2FZjmU%2F7OeNQ8g43yLONFucvPVZorwppwqM3ZImMjtmFEO6tIiWls6ripXxq2XewUI3yJlYM5ADPVHgPLlKpLiN340%2Bhieur%2FoNeLjk75gWa%2BOeR8NYc7UBTOkHCoaueDM%2B5EUEEg%3D%3D: 404 Client Error: Not Found for url: https://storage.googleapis.com/wandb-production.appspot.com/ada4321/DiffHPE/tf2mpncg/config.yaml?Expires=1689058606&GoogleAccessId=gorilla-files-url-signer-man%40wandb-production.iam.gserviceaccount.com&Signature=qC1Df2Oo06EaM5pfG1Wmg%2F0QFFYvT1ib5q3q1tIegAyDwyXDDGMJJ7pi29PvGnBSqeB2rMiBhC66Ee66Q6fy92TpNVQ3g%2BxAhBjDPV5Z0vrEhMNdKpXdHlm9rZs%2FUiScuoxguOyCe7bIptXQYwE8Ksj1fzKlsfclxDgXuS7LFtc8PWIE1bdjlwi4JdkvTOCPhyqDjTIvPXhlHH%2FZjmU%2F7OeNQ8g43yLONFucvPVZorwppwqM3ZImMjtmFEO6tIiWls6ripXxq2XewUI3yJlYM5ADPVHgPLlKpLiN340%2Bhieur%2FoNeLjk75gWa%2BOeR8NYc7UBTOkHCoaueDM%2B5EUEEg%3D%3D
2023-07-10 14:56:46,969 ERROR   wandb-upload_1:32738 [internal_api.py:upload_file():2194] upload_file request headers: {'User-Agent': 'python-requests/2.31.0', 'Accept-Encoding': 'gzip, deflate', 'Accept': '*/*', 'Connection': 'keep-alive', 'Content-Length': '514'}
2023-07-10 14:56:46,969 ERROR   wandb-upload_1:32738 [internal_api.py:upload_file():2196] upload_file response body: b'<!DOCTYPE html>\n<html lang=en>\n  <meta charset=utf-8>\n  <meta name=viewport content="initial-scale=1, minimum-scale=1, width=device-width">\n  <title>Error 404 (Not Found)!!1</title>\n  <style>\n    *{margin:0;padding:0}html,code{font:15px/22px arial,sans-serif}html{background:#fff;color:#222;padding:15px}body{margin:7% auto 0;max-width:390px;min-height:180px;padding:30px 0 15px}* > body{background:url(//www.google.com/images/errors/robot.png) 100% 5px no-repeat;padding-right:205px}p{margin:11px 0 22px;overflow:hidden}ins{color:#777;text-decoration:none}a img{border:0}@media screen and (max-width:772px){body{background:none;margin-top:0;max-width:none;padding-right:0}}#logo{background:url(//www.google.com/images/branding/googlelogo/1x/googlelogo_color_150x54dp.png) no-repeat;margin-left:-5px}@media only screen and (min-resolution:192dpi){#logo{background:url(//www.google.com/images/branding/googlelogo/2x/googlelogo_color_150x54dp.png) no-repeat 0% 0%/100% 100%;-moz-border-image:url(//www.google.com/images/branding/googlelogo/2x/googlelogo_color_150x54dp.png) 0}}@media only screen and (-webkit-min-device-pixel-ratio:2){#logo{background:url(//www.google.com/images/branding/googlelogo/2x/googlelogo_color_150x54dp.png) no-repeat;-webkit-background-size:100% 100%}}#logo{display:inline-block;height:54px;width:150px}\n  </style>\n  <a href=//www.google.com/><span id=logo aria-label=Google></span></a>\n  <p><b>404.</b> <ins>That\xe2\x80\x99s an error.</ins>\n  <p>The requested URL <code>/wandb-production.appspot.com/ada4321/DiffHPE/tf2mpncg/config.yaml</code> was not found on this server.  <ins>That\xe2\x80\x99s all we know.</ins>\n'
2023-07-10 14:56:46,975 ERROR   wandb-upload_0:32738 [internal_api.py:upload_file():2192] upload_file exception https://storage.googleapis.com/wandb-production.appspot.com/ada4321/DiffHPE/tf2mpncg/requirements.txt?Expires=1689058606&GoogleAccessId=gorilla-files-url-signer-man%40wandb-production.iam.gserviceaccount.com&Signature=X9Lug81i53qO7alf1HVZR5PaXEBBOl6rUsHPZfRxG65Uyg0guNsQSEQ9jbJtsWIgfCb5yuGTn%2BqLDhR96AWBrH9l6yp%2FPNzmhms5tb1VDOJ8HdpsUATBIbut%2FraH%2BABnwuUzNWH8UD2VdJaz54v5XLsI9i7plPPEXbIpwioiLZskj3YRSgjKROoHMU6V1xapT7pMbonFR3S39x85JT2mBN%2FHr6Zaevf7pMwSwDmqljp%2BvpYEcnG8DIdmzOaSRCNkBflFgizzHSpvsb2Q%2FIyCQUzuHad8Gs68qJLBYykT0hwi0IPXAVvdkCTwu3jIXss5cyeKC%2BCcazUIaEw1EZuXKA%3D%3D: 404 Client Error: Not Found for url: https://storage.googleapis.com/wandb-production.appspot.com/ada4321/DiffHPE/tf2mpncg/requirements.txt?Expires=1689058606&GoogleAccessId=gorilla-files-url-signer-man%40wandb-production.iam.gserviceaccount.com&Signature=X9Lug81i53qO7alf1HVZR5PaXEBBOl6rUsHPZfRxG65Uyg0guNsQSEQ9jbJtsWIgfCb5yuGTn%2BqLDhR96AWBrH9l6yp%2FPNzmhms5tb1VDOJ8HdpsUATBIbut%2FraH%2BABnwuUzNWH8UD2VdJaz54v5XLsI9i7plPPEXbIpwioiLZskj3YRSgjKROoHMU6V1xapT7pMbonFR3S39x85JT2mBN%2FHr6Zaevf7pMwSwDmqljp%2BvpYEcnG8DIdmzOaSRCNkBflFgizzHSpvsb2Q%2FIyCQUzuHad8Gs68qJLBYykT0hwi0IPXAVvdkCTwu3jIXss5cyeKC%2BCcazUIaEw1EZuXKA%3D%3D
2023-07-10 14:56:46,975 ERROR   wandb-upload_0:32738 [internal_api.py:upload_file():2194] upload_file request headers: {'User-Agent': 'python-requests/2.31.0', 'Accept-Encoding': 'gzip, deflate', 'Accept': '*/*', 'Connection': 'keep-alive', 'Content-Length': '910'}
2023-07-10 14:56:46,975 ERROR   wandb-upload_0:32738 [internal_api.py:upload_file():2196] upload_file response body: b'<!DOCTYPE html>\n<html lang=en>\n  <meta charset=utf-8>\n  <meta name=viewport content="initial-scale=1, minimum-scale=1, width=device-width">\n  <title>Error 404 (Not Found)!!1</title>\n  <style>\n    *{margin:0;padding:0}html,code{font:15px/22px arial,sans-serif}html{background:#fff;color:#222;padding:15px}body{margin:7% auto 0;max-width:390px;min-height:180px;padding:30px 0 15px}* > body{background:url(//www.google.com/images/errors/robot.png) 100% 5px no-repeat;padding-right:205px}p{margin:11px 0 22px;overflow:hidden}ins{color:#777;text-decoration:none}a img{border:0}@media screen and (max-width:772px){body{background:none;margin-top:0;max-width:none;padding-right:0}}#logo{background:url(//www.google.com/images/branding/googlelogo/1x/googlelogo_color_150x54dp.png) no-repeat;margin-left:-5px}@media only screen and (min-resolution:192dpi){#logo{background:url(//www.google.com/images/branding/googlelogo/2x/googlelogo_color_150x54dp.png) no-repeat 0% 0%/100% 100%;-moz-border-image:url(//www.google.com/images/branding/googlelogo/2x/googlelogo_color_150x54dp.png) 0}}@media only screen and (-webkit-min-device-pixel-ratio:2){#logo{background:url(//www.google.com/images/branding/googlelogo/2x/googlelogo_color_150x54dp.png) no-repeat;-webkit-background-size:100% 100%}}#logo{display:inline-block;height:54px;width:150px}\n  </style>\n  <a href=//www.google.com/><span id=logo aria-label=Google></span></a>\n  <p><b>404.</b> <ins>That\xe2\x80\x99s an error.</ins>\n  <p>The requested URL <code>/wandb-production.appspot.com/ada4321/DiffHPE/tf2mpncg/requirements.txt</code> was not found on this server.  <ins>That\xe2\x80\x99s all we know.</ins>\n'
2023-07-10 14:56:47,256 ERROR   wandb-upload_2:32738 [internal_api.py:upload_file():2192] upload_file exception https://storage.googleapis.com/wandb-production.appspot.com/ada4321/DiffHPE/tf2mpncg/wandb-summary.json?Expires=1689058606&GoogleAccessId=gorilla-files-url-signer-man%40wandb-production.iam.gserviceaccount.com&Signature=So0Nboocyhwm7M9xwt7GATUD2jhV5BWuLZzx1F4mJ91kyK4V0UFFhaCZSWzL%2F3xIMBesl94r4txnLHWL09A3xEyuvvgpcIrHi%2BOtTULGJUPpyxMXObQGyNzV1GnPLtyUvumDYVaUp59bdZXQIGQzoK%2F1eF1MGf3zsXD%2FYYh3Ngshap0lTGoWzJ9t5aBEuNOKTqkfgQ4MOSEvn5T6ZurGiWb1wcmwjmkQrp0lP%2FdcRTAxqGleXgOlH6BJOgSmv9i4XnVFU9Qz1G%2FueJ8AzBYWT4HA1%2BDZA6umjnbCvQLsmOM7RnXDkvk77xCRqwtK5VXk6fwqHyA0I%2BnlADEsrc0qJg%3D%3D: 404 Client Error: Not Found for url: https://storage.googleapis.com/wandb-production.appspot.com/ada4321/DiffHPE/tf2mpncg/wandb-summary.json?Expires=1689058606&GoogleAccessId=gorilla-files-url-signer-man%40wandb-production.iam.gserviceaccount.com&Signature=So0Nboocyhwm7M9xwt7GATUD2jhV5BWuLZzx1F4mJ91kyK4V0UFFhaCZSWzL%2F3xIMBesl94r4txnLHWL09A3xEyuvvgpcIrHi%2BOtTULGJUPpyxMXObQGyNzV1GnPLtyUvumDYVaUp59bdZXQIGQzoK%2F1eF1MGf3zsXD%2FYYh3Ngshap0lTGoWzJ9t5aBEuNOKTqkfgQ4MOSEvn5T6ZurGiWb1wcmwjmkQrp0lP%2FdcRTAxqGleXgOlH6BJOgSmv9i4XnVFU9Qz1G%2FueJ8AzBYWT4HA1%2BDZA6umjnbCvQLsmOM7RnXDkvk77xCRqwtK5VXk6fwqHyA0I%2BnlADEsrc0qJg%3D%3D
2023-07-10 14:56:47,256 ERROR   wandb-upload_2:32738 [internal_api.py:upload_file():2194] upload_file request headers: {'User-Agent': 'python-requests/2.31.0', 'Accept-Encoding': 'gzip, deflate', 'Accept': '*/*', 'Connection': 'keep-alive', 'Content-Length': '26'}
2023-07-10 14:56:47,256 ERROR   wandb-upload_2:32738 [internal_api.py:upload_file():2196] upload_file response body: b'<!DOCTYPE html>\n<html lang=en>\n  <meta charset=utf-8>\n  <meta name=viewport content="initial-scale=1, minimum-scale=1, width=device-width">\n  <title>Error 404 (Not Found)!!1</title>\n  <style>\n    *{margin:0;padding:0}html,code{font:15px/22px arial,sans-serif}html{background:#fff;color:#222;padding:15px}body{margin:7% auto 0;max-width:390px;min-height:180px;padding:30px 0 15px}* > body{background:url(//www.google.com/images/errors/robot.png) 100% 5px no-repeat;padding-right:205px}p{margin:11px 0 22px;overflow:hidden}ins{color:#777;text-decoration:none}a img{border:0}@media screen and (max-width:772px){body{background:none;margin-top:0;max-width:none;padding-right:0}}#logo{background:url(//www.google.com/images/branding/googlelogo/1x/googlelogo_color_150x54dp.png) no-repeat;margin-left:-5px}@media only screen and (min-resolution:192dpi){#logo{background:url(//www.google.com/images/branding/googlelogo/2x/googlelogo_color_150x54dp.png) no-repeat 0% 0%/100% 100%;-moz-border-image:url(//www.google.com/images/branding/googlelogo/2x/googlelogo_color_150x54dp.png) 0}}@media only screen and (-webkit-min-device-pixel-ratio:2){#logo{background:url(//www.google.com/images/branding/googlelogo/2x/googlelogo_color_150x54dp.png) no-repeat;-webkit-background-size:100% 100%}}#logo{display:inline-block;height:54px;width:150px}\n  </style>\n  <a href=//www.google.com/><span id=logo aria-label=Google></span></a>\n  <p><b>404.</b> <ins>That\xe2\x80\x99s an error.</ins>\n  <p>The requested URL <code>/wandb-production.appspot.com/ada4321/DiffHPE/tf2mpncg/wandb-summary.json</code> was not found on this server.  <ins>That\xe2\x80\x99s all we know.</ins>\n'
2023-07-10 14:56:47,275 ERROR   wandb-upload_4:32738 [internal_api.py:upload_file():2192] upload_file exception https://storage.googleapis.com/wandb-production.appspot.com/ada4321/DiffHPE/tf2mpncg/output.log?Expires=1689058606&GoogleAccessId=gorilla-files-url-signer-man%40wandb-production.iam.gserviceaccount.com&Signature=r8nVMotAuQ4zXdVqYa4AbkwIvU0T8y0U5AIl5H34mSWyehLD3gbOwnHeQdoHSip1JgfpRksUwZ377NiKB3TUyjluX3rUvIQ27E5b3HLPq5Y2Gy6Orvc2oNVmMwI1k2NU%2BfIZJf%2BqGGhSqeEKchCqw96p8dHwJlBUDtdsjThf4hzEsAZ30R1GVp73RT6au4LMFiZQy8dG%2FWTFKXfOVtiMOJnFMVBFbrUNLPo9G6XrtVguZz%2FDnyNeMwEhIHmqS8YS7ZDM2nCYlBY7WZ0L8gk%2Fzsl5uvmE1KRO%2FTxC7dVgWJoL2mOtRGWABykswBVI3Z%2Ff%2BcozxB49NrT3Q8ZBp8RqrQ%3D%3D: 404 Client Error: Not Found for url: https://storage.googleapis.com/wandb-production.appspot.com/ada4321/DiffHPE/tf2mpncg/output.log?Expires=1689058606&GoogleAccessId=gorilla-files-url-signer-man%40wandb-production.iam.gserviceaccount.com&Signature=r8nVMotAuQ4zXdVqYa4AbkwIvU0T8y0U5AIl5H34mSWyehLD3gbOwnHeQdoHSip1JgfpRksUwZ377NiKB3TUyjluX3rUvIQ27E5b3HLPq5Y2Gy6Orvc2oNVmMwI1k2NU%2BfIZJf%2BqGGhSqeEKchCqw96p8dHwJlBUDtdsjThf4hzEsAZ30R1GVp73RT6au4LMFiZQy8dG%2FWTFKXfOVtiMOJnFMVBFbrUNLPo9G6XrtVguZz%2FDnyNeMwEhIHmqS8YS7ZDM2nCYlBY7WZ0L8gk%2Fzsl5uvmE1KRO%2FTxC7dVgWJoL2mOtRGWABykswBVI3Z%2Ff%2BcozxB49NrT3Q8ZBp8RqrQ%3D%3D
2023-07-10 14:56:47,275 ERROR   wandb-upload_4:32738 [internal_api.py:upload_file():2194] upload_file request headers: {'User-Agent': 'python-requests/2.31.0', 'Accept-Encoding': 'gzip, deflate', 'Accept': '*/*', 'Connection': 'keep-alive', 'Content-Length': '2733'}
2023-07-10 14:56:47,275 ERROR   wandb-upload_4:32738 [internal_api.py:upload_file():2196] upload_file response body: b'<!DOCTYPE html>\n<html lang=en>\n  <meta charset=utf-8>\n  <meta name=viewport content="initial-scale=1, minimum-scale=1, width=device-width">\n  <title>Error 404 (Not Found)!!1</title>\n  <style>\n    *{margin:0;padding:0}html,code{font:15px/22px arial,sans-serif}html{background:#fff;color:#222;padding:15px}body{margin:7% auto 0;max-width:390px;min-height:180px;padding:30px 0 15px}* > body{background:url(//www.google.com/images/errors/robot.png) 100% 5px no-repeat;padding-right:205px}p{margin:11px 0 22px;overflow:hidden}ins{color:#777;text-decoration:none}a img{border:0}@media screen and (max-width:772px){body{background:none;margin-top:0;max-width:none;padding-right:0}}#logo{background:url(//www.google.com/images/branding/googlelogo/1x/googlelogo_color_150x54dp.png) no-repeat;margin-left:-5px}@media only screen and (min-resolution:192dpi){#logo{background:url(//www.google.com/images/branding/googlelogo/2x/googlelogo_color_150x54dp.png) no-repeat 0% 0%/100% 100%;-moz-border-image:url(//www.google.com/images/branding/googlelogo/2x/googlelogo_color_150x54dp.png) 0}}@media only screen and (-webkit-min-device-pixel-ratio:2){#logo{background:url(//www.google.com/images/branding/googlelogo/2x/googlelogo_color_150x54dp.png) no-repeat;-webkit-background-size:100% 100%}}#logo{display:inline-block;height:54px;width:150px}\n  </style>\n  <a href=//www.google.com/><span id=logo aria-label=Google></span></a>\n  <p><b>404.</b> <ins>That\xe2\x80\x99s an error.</ins>\n  <p>The requested URL <code>/wandb-production.appspot.com/ada4321/DiffHPE/tf2mpncg/output.log</code> was not found on this server.  <ins>That\xe2\x80\x99s all we know.</ins>\n'
2023-07-10 14:56:47,339 ERROR   wandb-upload_3:32738 [internal_api.py:upload_file():2192] upload_file exception https://storage.googleapis.com/wandb-production.appspot.com/ada4321/DiffHPE/tf2mpncg/conda-environment.yaml?Expires=1689058606&GoogleAccessId=gorilla-files-url-signer-man%40wandb-production.iam.gserviceaccount.com&Signature=N3Y3HUp%2FNwE4CfYNE6oWGmHkohQomh9t%2BiVvUNNzz96zyMxYLYXvjI1j2AkBU2j%2B8aJyneaPFVuv5L%2FP4gz4BdfLSVuaZgEDFidAFZXtFBrqTbF38gFX7%2Bw4m%2BAzpYRkx00%2BHegmx9JcLeazvPzysQcn0V4Tqx0jyUFDRqcek8Z0GhPYJJgVTxfHxPVUc4wcEN6iElA83fNpcZ%2FVABRycazE8XEvhS2JB82ia%2B1y7%2BsgrnUtlFWHnlRin9kbogWeqrQOjsreTs3npgBzmwH2Wnxg4cdI%2FCfS%2BfDlyxLkTS6wIG4%2F%2FGjpkJI3Xbe4Gp5oQc8ycdYtYbal6EQi0wY4Jg%3D%3D: 404 Client Error: Not Found for url: https://storage.googleapis.com/wandb-production.appspot.com/ada4321/DiffHPE/tf2mpncg/conda-environment.yaml?Expires=1689058606&GoogleAccessId=gorilla-files-url-signer-man%40wandb-production.iam.gserviceaccount.com&Signature=N3Y3HUp%2FNwE4CfYNE6oWGmHkohQomh9t%2BiVvUNNzz96zyMxYLYXvjI1j2AkBU2j%2B8aJyneaPFVuv5L%2FP4gz4BdfLSVuaZgEDFidAFZXtFBrqTbF38gFX7%2Bw4m%2BAzpYRkx00%2BHegmx9JcLeazvPzysQcn0V4Tqx0jyUFDRqcek8Z0GhPYJJgVTxfHxPVUc4wcEN6iElA83fNpcZ%2FVABRycazE8XEvhS2JB82ia%2B1y7%2BsgrnUtlFWHnlRin9kbogWeqrQOjsreTs3npgBzmwH2Wnxg4cdI%2FCfS%2BfDlyxLkTS6wIG4%2F%2FGjpkJI3Xbe4Gp5oQc8ycdYtYbal6EQi0wY4Jg%3D%3D
2023-07-10 14:56:47,339 ERROR   wandb-upload_3:32738 [internal_api.py:upload_file():2194] upload_file request headers: {'User-Agent': 'python-requests/2.31.0', 'Accept-Encoding': 'gzip, deflate', 'Accept': '*/*', 'Connection': 'keep-alive', 'Content-Length': '1903'}
2023-07-10 14:56:47,339 ERROR   wandb-upload_3:32738 [internal_api.py:upload_file():2196] upload_file response body: b'<!DOCTYPE html>\n<html lang=en>\n  <meta charset=utf-8>\n  <meta name=viewport content="initial-scale=1, minimum-scale=1, width=device-width">\n  <title>Error 404 (Not Found)!!1</title>\n  <style>\n    *{margin:0;padding:0}html,code{font:15px/22px arial,sans-serif}html{background:#fff;color:#222;padding:15px}body{margin:7% auto 0;max-width:390px;min-height:180px;padding:30px 0 15px}* > body{background:url(//www.google.com/images/errors/robot.png) 100% 5px no-repeat;padding-right:205px}p{margin:11px 0 22px;overflow:hidden}ins{color:#777;text-decoration:none}a img{border:0}@media screen and (max-width:772px){body{background:none;margin-top:0;max-width:none;padding-right:0}}#logo{background:url(//www.google.com/images/branding/googlelogo/1x/googlelogo_color_150x54dp.png) no-repeat;margin-left:-5px}@media only screen and (min-resolution:192dpi){#logo{background:url(//www.google.com/images/branding/googlelogo/2x/googlelogo_color_150x54dp.png) no-repeat 0% 0%/100% 100%;-moz-border-image:url(//www.google.com/images/branding/googlelogo/2x/googlelogo_color_150x54dp.png) 0}}@media only screen and (-webkit-min-device-pixel-ratio:2){#logo{background:url(//www.google.com/images/branding/googlelogo/2x/googlelogo_color_150x54dp.png) no-repeat;-webkit-background-size:100% 100%}}#logo{display:inline-block;height:54px;width:150px}\n  </style>\n  <a href=//www.google.com/><span id=logo aria-label=Google></span></a>\n  <p><b>404.</b> <ins>That\xe2\x80\x99s an error.</ins>\n  <p>The requested URL <code>/wandb-production.appspot.com/ada4321/DiffHPE/tf2mpncg/conda-environment.yaml</code> was not found on this server.  <ins>That\xe2\x80\x99s all we know.</ins>\n'
2023-07-10 14:56:47,978 ERROR   wandb-upload_1:32738 [upload_job.py:push():136] Failed to upload file: /home/zhuhe/HPE-with-Diffusion/wandb/run-20230710_145641-tf2mpncg/files/config.yaml
Traceback (most recent call last):
  File "/home/zhuhe/.conda/envs/diffhpe/lib/python3.9/site-packages/wandb/apis/normalize.py", line 41, in wrapper
    return func(*args, **kwargs)
  File "/home/zhuhe/.conda/envs/diffhpe/lib/python3.9/site-packages/wandb/sdk/lib/retry.py", line 212, in wrapped_fn
    return retrier(*args, **kargs)
  File "/home/zhuhe/.conda/envs/diffhpe/lib/python3.9/site-packages/wandb/sdk/lib/retry.py", line 131, in __call__
    result = self._call_fn(*args, **kwargs)
  File "/home/zhuhe/.conda/envs/diffhpe/lib/python3.9/site-packages/wandb/sdk/internal/internal_api.py", line 2218, in upload_file
    wandb._sentry.reraise(e)
  File "/home/zhuhe/.conda/envs/diffhpe/lib/python3.9/site-packages/wandb/analytics/sentry.py", line 146, in reraise
    raise exc.with_traceback(sys.exc_info()[2])
  File "/home/zhuhe/.conda/envs/diffhpe/lib/python3.9/site-packages/wandb/sdk/internal/internal_api.py", line 2190, in upload_file
    response.raise_for_status()
  File "/home/zhuhe/.conda/envs/diffhpe/lib/python3.9/site-packages/requests/models.py", line 1021, in raise_for_status
    raise HTTPError(http_error_msg, response=self)
requests.exceptions.HTTPError: 404 Client Error: Not Found for url: https://storage.googleapis.com/wandb-production.appspot.com/ada4321/DiffHPE/tf2mpncg/config.yaml?Expires=1689058606&GoogleAccessId=gorilla-files-url-signer-man%40wandb-production.iam.gserviceaccount.com&Signature=qC1Df2Oo06EaM5pfG1Wmg%2F0QFFYvT1ib5q3q1tIegAyDwyXDDGMJJ7pi29PvGnBSqeB2rMiBhC66Ee66Q6fy92TpNVQ3g%2BxAhBjDPV5Z0vrEhMNdKpXdHlm9rZs%2FUiScuoxguOyCe7bIptXQYwE8Ksj1fzKlsfclxDgXuS7LFtc8PWIE1bdjlwi4JdkvTOCPhyqDjTIvPXhlHH%2FZjmU%2F7OeNQ8g43yLONFucvPVZorwppwqM3ZImMjtmFEO6tIiWls6ripXxq2XewUI3yJlYM5ADPVHgPLlKpLiN340%2Bhieur%2FoNeLjk75gWa%2BOeR8NYc7UBTOkHCoaueDM%2B5EUEEg%3D%3D

During handling of the above exception, another exception occurred:

Traceback (most recent call last):
  File "/home/zhuhe/.conda/envs/diffhpe/lib/python3.9/site-packages/wandb/filesync/upload_job.py", line 127, in push
    self._api.upload_file_retry(
  File "/home/zhuhe/.conda/envs/diffhpe/lib/python3.9/site-packages/wandb/apis/normalize.py", line 51, in wrapper
    raise CommError(message, error)
wandb.errors.CommError: <Response [404]>
2023-07-10 14:56:47,978 ERROR   wandb-upload_0:32738 [upload_job.py:push():136] Failed to upload file: /home/zhuhe/HPE-with-Diffusion/wandb/run-20230710_145641-tf2mpncg/files/requirements.txt
Traceback (most recent call last):
  File "/home/zhuhe/.conda/envs/diffhpe/lib/python3.9/site-packages/wandb/apis/normalize.py", line 41, in wrapper
    return func(*args, **kwargs)
  File "/home/zhuhe/.conda/envs/diffhpe/lib/python3.9/site-packages/wandb/sdk/lib/retry.py", line 212, in wrapped_fn
    return retrier(*args, **kargs)
  File "/home/zhuhe/.conda/envs/diffhpe/lib/python3.9/site-packages/wandb/sdk/lib/retry.py", line 131, in __call__
    result = self._call_fn(*args, **kwargs)
  File "/home/zhuhe/.conda/envs/diffhpe/lib/python3.9/site-packages/wandb/sdk/internal/internal_api.py", line 2218, in upload_file
    wandb._sentry.reraise(e)
  File "/home/zhuhe/.conda/envs/diffhpe/lib/python3.9/site-packages/wandb/analytics/sentry.py", line 146, in reraise
    raise exc.with_traceback(sys.exc_info()[2])
  File "/home/zhuhe/.conda/envs/diffhpe/lib/python3.9/site-packages/wandb/sdk/internal/internal_api.py", line 2190, in upload_file
    response.raise_for_status()
  File "/home/zhuhe/.conda/envs/diffhpe/lib/python3.9/site-packages/requests/models.py", line 1021, in raise_for_status
    raise HTTPError(http_error_msg, response=self)
requests.exceptions.HTTPError: 404 Client Error: Not Found for url: https://storage.googleapis.com/wandb-production.appspot.com/ada4321/DiffHPE/tf2mpncg/requirements.txt?Expires=1689058606&GoogleAccessId=gorilla-files-url-signer-man%40wandb-production.iam.gserviceaccount.com&Signature=X9Lug81i53qO7alf1HVZR5PaXEBBOl6rUsHPZfRxG65Uyg0guNsQSEQ9jbJtsWIgfCb5yuGTn%2BqLDhR96AWBrH9l6yp%2FPNzmhms5tb1VDOJ8HdpsUATBIbut%2FraH%2BABnwuUzNWH8UD2VdJaz54v5XLsI9i7plPPEXbIpwioiLZskj3YRSgjKROoHMU6V1xapT7pMbonFR3S39x85JT2mBN%2FHr6Zaevf7pMwSwDmqljp%2BvpYEcnG8DIdmzOaSRCNkBflFgizzHSpvsb2Q%2FIyCQUzuHad8Gs68qJLBYykT0hwi0IPXAVvdkCTwu3jIXss5cyeKC%2BCcazUIaEw1EZuXKA%3D%3D

During handling of the above exception, another exception occurred:

Traceback (most recent call last):
  File "/home/zhuhe/.conda/envs/diffhpe/lib/python3.9/site-packages/wandb/filesync/upload_job.py", line 127, in push
    self._api.upload_file_retry(
  File "/home/zhuhe/.conda/envs/diffhpe/lib/python3.9/site-packages/wandb/apis/normalize.py", line 51, in wrapper
    raise CommError(message, error)
wandb.errors.CommError: <Response [404]>
2023-07-10 14:56:47,979 ERROR   wandb-upload_2:32738 [upload_job.py:push():136] Failed to upload file: /home/zhuhe/HPE-with-Diffusion/wandb/run-20230710_145641-tf2mpncg/files/wandb-summary.json
Traceback (most recent call last):
  File "/home/zhuhe/.conda/envs/diffhpe/lib/python3.9/site-packages/wandb/apis/normalize.py", line 41, in wrapper
    return func(*args, **kwargs)
  File "/home/zhuhe/.conda/envs/diffhpe/lib/python3.9/site-packages/wandb/sdk/lib/retry.py", line 212, in wrapped_fn
    return retrier(*args, **kargs)
  File "/home/zhuhe/.conda/envs/diffhpe/lib/python3.9/site-packages/wandb/sdk/lib/retry.py", line 131, in __call__
    result = self._call_fn(*args, **kwargs)
  File "/home/zhuhe/.conda/envs/diffhpe/lib/python3.9/site-packages/wandb/sdk/internal/internal_api.py", line 2218, in upload_file
    wandb._sentry.reraise(e)
  File "/home/zhuhe/.conda/envs/diffhpe/lib/python3.9/site-packages/wandb/analytics/sentry.py", line 146, in reraise
    raise exc.with_traceback(sys.exc_info()[2])
  File "/home/zhuhe/.conda/envs/diffhpe/lib/python3.9/site-packages/wandb/sdk/internal/internal_api.py", line 2190, in upload_file
    response.raise_for_status()
  File "/home/zhuhe/.conda/envs/diffhpe/lib/python3.9/site-packages/requests/models.py", line 1021, in raise_for_status
    raise HTTPError(http_error_msg, response=self)
requests.exceptions.HTTPError: 404 Client Error: Not Found for url: https://storage.googleapis.com/wandb-production.appspot.com/ada4321/DiffHPE/tf2mpncg/wandb-summary.json?Expires=1689058606&GoogleAccessId=gorilla-files-url-signer-man%40wandb-production.iam.gserviceaccount.com&Signature=So0Nboocyhwm7M9xwt7GATUD2jhV5BWuLZzx1F4mJ91kyK4V0UFFhaCZSWzL%2F3xIMBesl94r4txnLHWL09A3xEyuvvgpcIrHi%2BOtTULGJUPpyxMXObQGyNzV1GnPLtyUvumDYVaUp59bdZXQIGQzoK%2F1eF1MGf3zsXD%2FYYh3Ngshap0lTGoWzJ9t5aBEuNOKTqkfgQ4MOSEvn5T6ZurGiWb1wcmwjmkQrp0lP%2FdcRTAxqGleXgOlH6BJOgSmv9i4XnVFU9Qz1G%2FueJ8AzBYWT4HA1%2BDZA6umjnbCvQLsmOM7RnXDkvk77xCRqwtK5VXk6fwqHyA0I%2BnlADEsrc0qJg%3D%3D

During handling of the above exception, another exception occurred:

Traceback (most recent call last):
  File "/home/zhuhe/.conda/envs/diffhpe/lib/python3.9/site-packages/wandb/filesync/upload_job.py", line 127, in push
    self._api.upload_file_retry(
  File "/home/zhuhe/.conda/envs/diffhpe/lib/python3.9/site-packages/wandb/apis/normalize.py", line 51, in wrapper
    raise CommError(message, error)
wandb.errors.CommError: <Response [404]>
2023-07-10 14:56:47,979 ERROR   wandb-upload_3:32738 [upload_job.py:push():136] Failed to upload file: /home/zhuhe/HPE-with-Diffusion/wandb/run-20230710_145641-tf2mpncg/files/conda-environment.yaml
Traceback (most recent call last):
  File "/home/zhuhe/.conda/envs/diffhpe/lib/python3.9/site-packages/wandb/apis/normalize.py", line 41, in wrapper
    return func(*args, **kwargs)
  File "/home/zhuhe/.conda/envs/diffhpe/lib/python3.9/site-packages/wandb/sdk/lib/retry.py", line 212, in wrapped_fn
    return retrier(*args, **kargs)
  File "/home/zhuhe/.conda/envs/diffhpe/lib/python3.9/site-packages/wandb/sdk/lib/retry.py", line 131, in __call__
    result = self._call_fn(*args, **kwargs)
  File "/home/zhuhe/.conda/envs/diffhpe/lib/python3.9/site-packages/wandb/sdk/internal/internal_api.py", line 2218, in upload_file
    wandb._sentry.reraise(e)
  File "/home/zhuhe/.conda/envs/diffhpe/lib/python3.9/site-packages/wandb/analytics/sentry.py", line 146, in reraise
    raise exc.with_traceback(sys.exc_info()[2])
  File "/home/zhuhe/.conda/envs/diffhpe/lib/python3.9/site-packages/wandb/sdk/internal/internal_api.py", line 2190, in upload_file
    response.raise_for_status()
  File "/home/zhuhe/.conda/envs/diffhpe/lib/python3.9/site-packages/requests/models.py", line 1021, in raise_for_status
    raise HTTPError(http_error_msg, response=self)
requests.exceptions.HTTPError: 404 Client Error: Not Found for url: https://storage.googleapis.com/wandb-production.appspot.com/ada4321/DiffHPE/tf2mpncg/conda-environment.yaml?Expires=1689058606&GoogleAccessId=gorilla-files-url-signer-man%40wandb-production.iam.gserviceaccount.com&Signature=N3Y3HUp%2FNwE4CfYNE6oWGmHkohQomh9t%2BiVvUNNzz96zyMxYLYXvjI1j2AkBU2j%2B8aJyneaPFVuv5L%2FP4gz4BdfLSVuaZgEDFidAFZXtFBrqTbF38gFX7%2Bw4m%2BAzpYRkx00%2BHegmx9JcLeazvPzysQcn0V4Tqx0jyUFDRqcek8Z0GhPYJJgVTxfHxPVUc4wcEN6iElA83fNpcZ%2FVABRycazE8XEvhS2JB82ia%2B1y7%2BsgrnUtlFWHnlRin9kbogWeqrQOjsreTs3npgBzmwH2Wnxg4cdI%2FCfS%2BfDlyxLkTS6wIG4%2F%2FGjpkJI3Xbe4Gp5oQc8ycdYtYbal6EQi0wY4Jg%3D%3D

During handling of the above exception, another exception occurred:

Traceback (most recent call last):
  File "/home/zhuhe/.conda/envs/diffhpe/lib/python3.9/site-packages/wandb/filesync/upload_job.py", line 127, in push
    self._api.upload_file_retry(
  File "/home/zhuhe/.conda/envs/diffhpe/lib/python3.9/site-packages/wandb/apis/normalize.py", line 51, in wrapper
    raise CommError(message, error)
wandb.errors.CommError: <Response [404]>
2023-07-10 14:56:47,979 ERROR   wandb-upload_4:32738 [upload_job.py:push():136] Failed to upload file: /home/zhuhe/HPE-with-Diffusion/wandb/run-20230710_145641-tf2mpncg/files/output.log
Traceback (most recent call last):
  File "/home/zhuhe/.conda/envs/diffhpe/lib/python3.9/site-packages/wandb/apis/normalize.py", line 41, in wrapper
    return func(*args, **kwargs)
  File "/home/zhuhe/.conda/envs/diffhpe/lib/python3.9/site-packages/wandb/sdk/lib/retry.py", line 212, in wrapped_fn
    return retrier(*args, **kargs)
  File "/home/zhuhe/.conda/envs/diffhpe/lib/python3.9/site-packages/wandb/sdk/lib/retry.py", line 131, in __call__
    result = self._call_fn(*args, **kwargs)
  File "/home/zhuhe/.conda/envs/diffhpe/lib/python3.9/site-packages/wandb/sdk/internal/internal_api.py", line 2218, in upload_file
    wandb._sentry.reraise(e)
  File "/home/zhuhe/.conda/envs/diffhpe/lib/python3.9/site-packages/wandb/analytics/sentry.py", line 146, in reraise
    raise exc.with_traceback(sys.exc_info()[2])
  File "/home/zhuhe/.conda/envs/diffhpe/lib/python3.9/site-packages/wandb/sdk/internal/internal_api.py", line 2190, in upload_file
    response.raise_for_status()
  File "/home/zhuhe/.conda/envs/diffhpe/lib/python3.9/site-packages/requests/models.py", line 1021, in raise_for_status
    raise HTTPError(http_error_msg, response=self)
requests.exceptions.HTTPError: 404 Client Error: Not Found for url: https://storage.googleapis.com/wandb-production.appspot.com/ada4321/DiffHPE/tf2mpncg/output.log?Expires=1689058606&GoogleAccessId=gorilla-files-url-signer-man%40wandb-production.iam.gserviceaccount.com&Signature=r8nVMotAuQ4zXdVqYa4AbkwIvU0T8y0U5AIl5H34mSWyehLD3gbOwnHeQdoHSip1JgfpRksUwZ377NiKB3TUyjluX3rUvIQ27E5b3HLPq5Y2Gy6Orvc2oNVmMwI1k2NU%2BfIZJf%2BqGGhSqeEKchCqw96p8dHwJlBUDtdsjThf4hzEsAZ30R1GVp73RT6au4LMFiZQy8dG%2FWTFKXfOVtiMOJnFMVBFbrUNLPo9G6XrtVguZz%2FDnyNeMwEhIHmqS8YS7ZDM2nCYlBY7WZ0L8gk%2Fzsl5uvmE1KRO%2FTxC7dVgWJoL2mOtRGWABykswBVI3Z%2Ff%2BcozxB49NrT3Q8ZBp8RqrQ%3D%3D

During handling of the above exception, another exception occurred:

Traceback (most recent call last):
  File "/home/zhuhe/.conda/envs/diffhpe/lib/python3.9/site-packages/wandb/filesync/upload_job.py", line 127, in push
    self._api.upload_file_retry(
  File "/home/zhuhe/.conda/envs/diffhpe/lib/python3.9/site-packages/wandb/apis/normalize.py", line 51, in wrapper
    raise CommError(message, error)
wandb.errors.CommError: <Response [404]>
2023-07-10 14:56:48,996 ERROR   Thread-11 :32738 [step_upload.py:_handle_event():200] Failed to upload file: /home/zhuhe/HPE-with-Diffusion/wandb/run-20230710_145641-tf2mpncg/files/config.yaml
Traceback (most recent call last):
  File "/home/zhuhe/.conda/envs/diffhpe/lib/python3.9/site-packages/wandb/apis/normalize.py", line 41, in wrapper
    return func(*args, **kwargs)
  File "/home/zhuhe/.conda/envs/diffhpe/lib/python3.9/site-packages/wandb/sdk/lib/retry.py", line 212, in wrapped_fn
    return retrier(*args, **kargs)
  File "/home/zhuhe/.conda/envs/diffhpe/lib/python3.9/site-packages/wandb/sdk/lib/retry.py", line 131, in __call__
    result = self._call_fn(*args, **kwargs)
  File "/home/zhuhe/.conda/envs/diffhpe/lib/python3.9/site-packages/wandb/sdk/internal/internal_api.py", line 2218, in upload_file
    wandb._sentry.reraise(e)
  File "/home/zhuhe/.conda/envs/diffhpe/lib/python3.9/site-packages/wandb/analytics/sentry.py", line 146, in reraise
    raise exc.with_traceback(sys.exc_info()[2])
  File "/home/zhuhe/.conda/envs/diffhpe/lib/python3.9/site-packages/wandb/sdk/internal/internal_api.py", line 2190, in upload_file
    response.raise_for_status()
  File "/home/zhuhe/.conda/envs/diffhpe/lib/python3.9/site-packages/requests/models.py", line 1021, in raise_for_status
    raise HTTPError(http_error_msg, response=self)
requests.exceptions.HTTPError: 404 Client Error: Not Found for url: https://storage.googleapis.com/wandb-production.appspot.com/ada4321/DiffHPE/tf2mpncg/config.yaml?Expires=1689058606&GoogleAccessId=gorilla-files-url-signer-man%40wandb-production.iam.gserviceaccount.com&Signature=qC1Df2Oo06EaM5pfG1Wmg%2F0QFFYvT1ib5q3q1tIegAyDwyXDDGMJJ7pi29PvGnBSqeB2rMiBhC66Ee66Q6fy92TpNVQ3g%2BxAhBjDPV5Z0vrEhMNdKpXdHlm9rZs%2FUiScuoxguOyCe7bIptXQYwE8Ksj1fzKlsfclxDgXuS7LFtc8PWIE1bdjlwi4JdkvTOCPhyqDjTIvPXhlHH%2FZjmU%2F7OeNQ8g43yLONFucvPVZorwppwqM3ZImMjtmFEO6tIiWls6ripXxq2XewUI3yJlYM5ADPVHgPLlKpLiN340%2Bhieur%2FoNeLjk75gWa%2BOeR8NYc7UBTOkHCoaueDM%2B5EUEEg%3D%3D

During handling of the above exception, another exception occurred:

Traceback (most recent call last):
  File "/home/zhuhe/.conda/envs/diffhpe/lib/python3.9/concurrent/futures/thread.py", line 58, in run
    result = self.fn(*self.args, **self.kwargs)
  File "/home/zhuhe/.conda/envs/diffhpe/lib/python3.9/site-packages/wandb/filesync/step_upload.py", line 288, in run_and_notify
    self._do_upload_sync(event)
  File "/home/zhuhe/.conda/envs/diffhpe/lib/python3.9/site-packages/wandb/filesync/step_upload.py", line 330, in _do_upload_sync
    job.run()
  File "/home/zhuhe/.conda/envs/diffhpe/lib/python3.9/site-packages/wandb/filesync/upload_job.py", line 57, in run
    self.push()
  File "/home/zhuhe/.conda/envs/diffhpe/lib/python3.9/site-packages/wandb/filesync/upload_job.py", line 127, in push
    self._api.upload_file_retry(
  File "/home/zhuhe/.conda/envs/diffhpe/lib/python3.9/site-packages/wandb/apis/normalize.py", line 51, in wrapper
    raise CommError(message, error)
wandb.errors.CommError: <Response [404]>
2023-07-10 14:56:48,997 ERROR   Thread-11 :32738 [step_upload.py:_handle_event():200] Failed to upload file: /home/zhuhe/HPE-with-Diffusion/wandb/run-20230710_145641-tf2mpncg/files/requirements.txt
Traceback (most recent call last):
  File "/home/zhuhe/.conda/envs/diffhpe/lib/python3.9/site-packages/wandb/apis/normalize.py", line 41, in wrapper
    return func(*args, **kwargs)
  File "/home/zhuhe/.conda/envs/diffhpe/lib/python3.9/site-packages/wandb/sdk/lib/retry.py", line 212, in wrapped_fn
    return retrier(*args, **kargs)
  File "/home/zhuhe/.conda/envs/diffhpe/lib/python3.9/site-packages/wandb/sdk/lib/retry.py", line 131, in __call__
    result = self._call_fn(*args, **kwargs)
  File "/home/zhuhe/.conda/envs/diffhpe/lib/python3.9/site-packages/wandb/sdk/internal/internal_api.py", line 2218, in upload_file
    wandb._sentry.reraise(e)
  File "/home/zhuhe/.conda/envs/diffhpe/lib/python3.9/site-packages/wandb/analytics/sentry.py", line 146, in reraise
    raise exc.with_traceback(sys.exc_info()[2])
  File "/home/zhuhe/.conda/envs/diffhpe/lib/python3.9/site-packages/wandb/sdk/internal/internal_api.py", line 2190, in upload_file
    response.raise_for_status()
  File "/home/zhuhe/.conda/envs/diffhpe/lib/python3.9/site-packages/requests/models.py", line 1021, in raise_for_status
    raise HTTPError(http_error_msg, response=self)
requests.exceptions.HTTPError: 404 Client Error: Not Found for url: https://storage.googleapis.com/wandb-production.appspot.com/ada4321/DiffHPE/tf2mpncg/requirements.txt?Expires=1689058606&GoogleAccessId=gorilla-files-url-signer-man%40wandb-production.iam.gserviceaccount.com&Signature=X9Lug81i53qO7alf1HVZR5PaXEBBOl6rUsHPZfRxG65Uyg0guNsQSEQ9jbJtsWIgfCb5yuGTn%2BqLDhR96AWBrH9l6yp%2FPNzmhms5tb1VDOJ8HdpsUATBIbut%2FraH%2BABnwuUzNWH8UD2VdJaz54v5XLsI9i7plPPEXbIpwioiLZskj3YRSgjKROoHMU6V1xapT7pMbonFR3S39x85JT2mBN%2FHr6Zaevf7pMwSwDmqljp%2BvpYEcnG8DIdmzOaSRCNkBflFgizzHSpvsb2Q%2FIyCQUzuHad8Gs68qJLBYykT0hwi0IPXAVvdkCTwu3jIXss5cyeKC%2BCcazUIaEw1EZuXKA%3D%3D

During handling of the above exception, another exception occurred:

Traceback (most recent call last):
  File "/home/zhuhe/.conda/envs/diffhpe/lib/python3.9/concurrent/futures/thread.py", line 58, in run
    result = self.fn(*self.args, **self.kwargs)
  File "/home/zhuhe/.conda/envs/diffhpe/lib/python3.9/site-packages/wandb/filesync/step_upload.py", line 288, in run_and_notify
    self._do_upload_sync(event)
  File "/home/zhuhe/.conda/envs/diffhpe/lib/python3.9/site-packages/wandb/filesync/step_upload.py", line 330, in _do_upload_sync
    job.run()
  File "/home/zhuhe/.conda/envs/diffhpe/lib/python3.9/site-packages/wandb/filesync/upload_job.py", line 57, in run
    self.push()
  File "/home/zhuhe/.conda/envs/diffhpe/lib/python3.9/site-packages/wandb/filesync/upload_job.py", line 127, in push
    self._api.upload_file_retry(
  File "/home/zhuhe/.conda/envs/diffhpe/lib/python3.9/site-packages/wandb/apis/normalize.py", line 51, in wrapper
    raise CommError(message, error)
wandb.errors.CommError: <Response [404]>
2023-07-10 14:56:48,997 ERROR   Thread-11 :32738 [step_upload.py:_handle_event():200] Failed to upload file: /home/zhuhe/HPE-with-Diffusion/wandb/run-20230710_145641-tf2mpncg/files/wandb-summary.json
Traceback (most recent call last):
  File "/home/zhuhe/.conda/envs/diffhpe/lib/python3.9/site-packages/wandb/apis/normalize.py", line 41, in wrapper
    return func(*args, **kwargs)
  File "/home/zhuhe/.conda/envs/diffhpe/lib/python3.9/site-packages/wandb/sdk/lib/retry.py", line 212, in wrapped_fn
    return retrier(*args, **kargs)
  File "/home/zhuhe/.conda/envs/diffhpe/lib/python3.9/site-packages/wandb/sdk/lib/retry.py", line 131, in __call__
    result = self._call_fn(*args, **kwargs)
  File "/home/zhuhe/.conda/envs/diffhpe/lib/python3.9/site-packages/wandb/sdk/internal/internal_api.py", line 2218, in upload_file
    wandb._sentry.reraise(e)
  File "/home/zhuhe/.conda/envs/diffhpe/lib/python3.9/site-packages/wandb/analytics/sentry.py", line 146, in reraise
    raise exc.with_traceback(sys.exc_info()[2])
  File "/home/zhuhe/.conda/envs/diffhpe/lib/python3.9/site-packages/wandb/sdk/internal/internal_api.py", line 2190, in upload_file
    response.raise_for_status()
  File "/home/zhuhe/.conda/envs/diffhpe/lib/python3.9/site-packages/requests/models.py", line 1021, in raise_for_status
    raise HTTPError(http_error_msg, response=self)
requests.exceptions.HTTPError: 404 Client Error: Not Found for url: https://storage.googleapis.com/wandb-production.appspot.com/ada4321/DiffHPE/tf2mpncg/wandb-summary.json?Expires=1689058606&GoogleAccessId=gorilla-files-url-signer-man%40wandb-production.iam.gserviceaccount.com&Signature=So0Nboocyhwm7M9xwt7GATUD2jhV5BWuLZzx1F4mJ91kyK4V0UFFhaCZSWzL%2F3xIMBesl94r4txnLHWL09A3xEyuvvgpcIrHi%2BOtTULGJUPpyxMXObQGyNzV1GnPLtyUvumDYVaUp59bdZXQIGQzoK%2F1eF1MGf3zsXD%2FYYh3Ngshap0lTGoWzJ9t5aBEuNOKTqkfgQ4MOSEvn5T6ZurGiWb1wcmwjmkQrp0lP%2FdcRTAxqGleXgOlH6BJOgSmv9i4XnVFU9Qz1G%2FueJ8AzBYWT4HA1%2BDZA6umjnbCvQLsmOM7RnXDkvk77xCRqwtK5VXk6fwqHyA0I%2BnlADEsrc0qJg%3D%3D

During handling of the above exception, another exception occurred:

Traceback (most recent call last):
  File "/home/zhuhe/.conda/envs/diffhpe/lib/python3.9/concurrent/futures/thread.py", line 58, in run
    result = self.fn(*self.args, **self.kwargs)
  File "/home/zhuhe/.conda/envs/diffhpe/lib/python3.9/site-packages/wandb/filesync/step_upload.py", line 288, in run_and_notify
    self._do_upload_sync(event)
  File "/home/zhuhe/.conda/envs/diffhpe/lib/python3.9/site-packages/wandb/filesync/step_upload.py", line 330, in _do_upload_sync
    job.run()
  File "/home/zhuhe/.conda/envs/diffhpe/lib/python3.9/site-packages/wandb/filesync/upload_job.py", line 57, in run
    self.push()
  File "/home/zhuhe/.conda/envs/diffhpe/lib/python3.9/site-packages/wandb/filesync/upload_job.py", line 127, in push
    self._api.upload_file_retry(
  File "/home/zhuhe/.conda/envs/diffhpe/lib/python3.9/site-packages/wandb/apis/normalize.py", line 51, in wrapper
    raise CommError(message, error)
wandb.errors.CommError: <Response [404]>
2023-07-10 14:56:48,997 ERROR   Thread-11 :32738 [step_upload.py:_handle_event():200] Failed to upload file: /home/zhuhe/HPE-with-Diffusion/wandb/run-20230710_145641-tf2mpncg/files/conda-environment.yaml
Traceback (most recent call last):
  File "/home/zhuhe/.conda/envs/diffhpe/lib/python3.9/site-packages/wandb/apis/normalize.py", line 41, in wrapper
    return func(*args, **kwargs)
  File "/home/zhuhe/.conda/envs/diffhpe/lib/python3.9/site-packages/wandb/sdk/lib/retry.py", line 212, in wrapped_fn
    return retrier(*args, **kargs)
  File "/home/zhuhe/.conda/envs/diffhpe/lib/python3.9/site-packages/wandb/sdk/lib/retry.py", line 131, in __call__
    result = self._call_fn(*args, **kwargs)
  File "/home/zhuhe/.conda/envs/diffhpe/lib/python3.9/site-packages/wandb/sdk/internal/internal_api.py", line 2218, in upload_file
    wandb._sentry.reraise(e)
  File "/home/zhuhe/.conda/envs/diffhpe/lib/python3.9/site-packages/wandb/analytics/sentry.py", line 146, in reraise
    raise exc.with_traceback(sys.exc_info()[2])
  File "/home/zhuhe/.conda/envs/diffhpe/lib/python3.9/site-packages/wandb/sdk/internal/internal_api.py", line 2190, in upload_file
    response.raise_for_status()
  File "/home/zhuhe/.conda/envs/diffhpe/lib/python3.9/site-packages/requests/models.py", line 1021, in raise_for_status
    raise HTTPError(http_error_msg, response=self)
requests.exceptions.HTTPError: 404 Client Error: Not Found for url: https://storage.googleapis.com/wandb-production.appspot.com/ada4321/DiffHPE/tf2mpncg/conda-environment.yaml?Expires=1689058606&GoogleAccessId=gorilla-files-url-signer-man%40wandb-production.iam.gserviceaccount.com&Signature=N3Y3HUp%2FNwE4CfYNE6oWGmHkohQomh9t%2BiVvUNNzz96zyMxYLYXvjI1j2AkBU2j%2B8aJyneaPFVuv5L%2FP4gz4BdfLSVuaZgEDFidAFZXtFBrqTbF38gFX7%2Bw4m%2BAzpYRkx00%2BHegmx9JcLeazvPzysQcn0V4Tqx0jyUFDRqcek8Z0GhPYJJgVTxfHxPVUc4wcEN6iElA83fNpcZ%2FVABRycazE8XEvhS2JB82ia%2B1y7%2BsgrnUtlFWHnlRin9kbogWeqrQOjsreTs3npgBzmwH2Wnxg4cdI%2FCfS%2BfDlyxLkTS6wIG4%2F%2FGjpkJI3Xbe4Gp5oQc8ycdYtYbal6EQi0wY4Jg%3D%3D

During handling of the above exception, another exception occurred:

Traceback (most recent call last):
  File "/home/zhuhe/.conda/envs/diffhpe/lib/python3.9/concurrent/futures/thread.py", line 58, in run
    result = self.fn(*self.args, **self.kwargs)
  File "/home/zhuhe/.conda/envs/diffhpe/lib/python3.9/site-packages/wandb/filesync/step_upload.py", line 288, in run_and_notify
    self._do_upload_sync(event)
  File "/home/zhuhe/.conda/envs/diffhpe/lib/python3.9/site-packages/wandb/filesync/step_upload.py", line 330, in _do_upload_sync
    job.run()
  File "/home/zhuhe/.conda/envs/diffhpe/lib/python3.9/site-packages/wandb/filesync/upload_job.py", line 57, in run
    self.push()
  File "/home/zhuhe/.conda/envs/diffhpe/lib/python3.9/site-packages/wandb/filesync/upload_job.py", line 127, in push
    self._api.upload_file_retry(
  File "/home/zhuhe/.conda/envs/diffhpe/lib/python3.9/site-packages/wandb/apis/normalize.py", line 51, in wrapper
    raise CommError(message, error)
wandb.errors.CommError: <Response [404]>
2023-07-10 14:56:48,997 ERROR   Thread-11 :32738 [step_upload.py:_handle_event():200] Failed to upload file: /home/zhuhe/HPE-with-Diffusion/wandb/run-20230710_145641-tf2mpncg/files/output.log
Traceback (most recent call last):
  File "/home/zhuhe/.conda/envs/diffhpe/lib/python3.9/site-packages/wandb/apis/normalize.py", line 41, in wrapper
    return func(*args, **kwargs)
  File "/home/zhuhe/.conda/envs/diffhpe/lib/python3.9/site-packages/wandb/sdk/lib/retry.py", line 212, in wrapped_fn
    return retrier(*args, **kargs)
  File "/home/zhuhe/.conda/envs/diffhpe/lib/python3.9/site-packages/wandb/sdk/lib/retry.py", line 131, in __call__
    result = self._call_fn(*args, **kwargs)
  File "/home/zhuhe/.conda/envs/diffhpe/lib/python3.9/site-packages/wandb/sdk/internal/internal_api.py", line 2218, in upload_file
    wandb._sentry.reraise(e)
  File "/home/zhuhe/.conda/envs/diffhpe/lib/python3.9/site-packages/wandb/analytics/sentry.py", line 146, in reraise
    raise exc.with_traceback(sys.exc_info()[2])
  File "/home/zhuhe/.conda/envs/diffhpe/lib/python3.9/site-packages/wandb/sdk/internal/internal_api.py", line 2190, in upload_file
    response.raise_for_status()
  File "/home/zhuhe/.conda/envs/diffhpe/lib/python3.9/site-packages/requests/models.py", line 1021, in raise_for_status
    raise HTTPError(http_error_msg, response=self)
requests.exceptions.HTTPError: 404 Client Error: Not Found for url: https://storage.googleapis.com/wandb-production.appspot.com/ada4321/DiffHPE/tf2mpncg/output.log?Expires=1689058606&GoogleAccessId=gorilla-files-url-signer-man%40wandb-production.iam.gserviceaccount.com&Signature=r8nVMotAuQ4zXdVqYa4AbkwIvU0T8y0U5AIl5H34mSWyehLD3gbOwnHeQdoHSip1JgfpRksUwZ377NiKB3TUyjluX3rUvIQ27E5b3HLPq5Y2Gy6Orvc2oNVmMwI1k2NU%2BfIZJf%2BqGGhSqeEKchCqw96p8dHwJlBUDtdsjThf4hzEsAZ30R1GVp73RT6au4LMFiZQy8dG%2FWTFKXfOVtiMOJnFMVBFbrUNLPo9G6XrtVguZz%2FDnyNeMwEhIHmqS8YS7ZDM2nCYlBY7WZ0L8gk%2Fzsl5uvmE1KRO%2FTxC7dVgWJoL2mOtRGWABykswBVI3Z%2Ff%2BcozxB49NrT3Q8ZBp8RqrQ%3D%3D

During handling of the above exception, another exception occurred:

Traceback (most recent call last):
  File "/home/zhuhe/.conda/envs/diffhpe/lib/python3.9/concurrent/futures/thread.py", line 58, in run
    result = self.fn(*self.args, **self.kwargs)
  File "/home/zhuhe/.conda/envs/diffhpe/lib/python3.9/site-packages/wandb/filesync/step_upload.py", line 288, in run_and_notify
    self._do_upload_sync(event)
  File "/home/zhuhe/.conda/envs/diffhpe/lib/python3.9/site-packages/wandb/filesync/step_upload.py", line 330, in _do_upload_sync
    job.run()
  File "/home/zhuhe/.conda/envs/diffhpe/lib/python3.9/site-packages/wandb/filesync/upload_job.py", line 57, in run
    self.push()
  File "/home/zhuhe/.conda/envs/diffhpe/lib/python3.9/site-packages/wandb/filesync/upload_job.py", line 127, in push
    self._api.upload_file_retry(
  File "/home/zhuhe/.conda/envs/diffhpe/lib/python3.9/site-packages/wandb/apis/normalize.py", line 51, in wrapper
    raise CommError(message, error)
wandb.errors.CommError: <Response [404]>
2023-07-10 14:56:49,197 INFO    Thread-11 :32738 [sender.py:transition_state():602] send defer: 11
2023-07-10 14:56:49,198 DEBUG   HandlerThread:32738 [handler.py:handle_request():144] handle_request: defer
2023-07-10 14:56:49,198 INFO    HandlerThread:32738 [handler.py:handle_request_defer():170] handle defer: 11
2023-07-10 14:56:49,198 DEBUG   SenderThread:32738 [sender.py:send_request():396] send_request: defer
2023-07-10 14:56:49,198 INFO    SenderThread:32738 [sender.py:send_request_defer():598] handle sender defer: 11
2023-07-10 14:56:49,198 INFO    SenderThread:32738 [file_pusher.py:join():164] waiting for file pusher
2023-07-10 14:56:49,198 INFO    SenderThread:32738 [sender.py:transition_state():602] send defer: 12
2023-07-10 14:56:49,198 DEBUG   HandlerThread:32738 [handler.py:handle_request():144] handle_request: defer
2023-07-10 14:56:49,198 INFO    HandlerThread:32738 [handler.py:handle_request_defer():170] handle defer: 12
2023-07-10 14:56:49,198 DEBUG   SenderThread:32738 [sender.py:send_request():396] send_request: defer
2023-07-10 14:56:49,198 INFO    SenderThread:32738 [sender.py:send_request_defer():598] handle sender defer: 12
2023-07-10 14:56:49,426 DEBUG   HandlerThread:32738 [handler.py:handle_request():144] handle_request: keepalive
2023-07-10 14:56:49,465 INFO    SenderThread:32738 [sender.py:transition_state():602] send defer: 13
2023-07-10 14:56:49,465 DEBUG   HandlerThread:32738 [handler.py:handle_request():144] handle_request: defer
2023-07-10 14:56:49,465 INFO    HandlerThread:32738 [handler.py:handle_request_defer():170] handle defer: 13
2023-07-10 14:56:49,466 DEBUG   SenderThread:32738 [sender.py:send_request():396] send_request: defer
2023-07-10 14:56:49,466 INFO    SenderThread:32738 [sender.py:send_request_defer():598] handle sender defer: 13
2023-07-10 14:56:49,466 INFO    SenderThread:32738 [sender.py:transition_state():602] send defer: 14
2023-07-10 14:56:49,466 DEBUG   HandlerThread:32738 [handler.py:handle_request():144] handle_request: defer
2023-07-10 14:56:49,466 INFO    HandlerThread:32738 [handler.py:handle_request_defer():170] handle defer: 14
2023-07-10 14:56:49,466 DEBUG   SenderThread:32738 [sender.py:send():369] send: final
2023-07-10 14:56:49,466 DEBUG   SenderThread:32738 [sender.py:send():369] send: footer
2023-07-10 14:56:49,466 DEBUG   SenderThread:32738 [sender.py:send_request():396] send_request: defer
2023-07-10 14:56:49,466 INFO    SenderThread:32738 [sender.py:send_request_defer():598] handle sender defer: 14
2023-07-10 14:56:49,467 DEBUG   HandlerThread:32738 [handler.py:handle_request():144] handle_request: poll_exit
2023-07-10 14:56:49,467 DEBUG   HandlerThread:32738 [handler.py:handle_request():144] handle_request: server_info
2023-07-10 14:56:49,467 DEBUG   HandlerThread:32738 [handler.py:handle_request():144] handle_request: get_summary
2023-07-10 14:56:49,467 DEBUG   SenderThread:32738 [sender.py:send_request():396] send_request: poll_exit
2023-07-10 14:56:49,467 DEBUG   SenderThread:32738 [sender.py:send_request():396] send_request: server_info
2023-07-10 14:56:49,468 DEBUG   HandlerThread:32738 [handler.py:handle_request():144] handle_request: sampled_history
2023-07-10 14:56:49,933 INFO    MainThread:32738 [wandb_run.py:_footer_history_summary_info():3467] rendering history
2023-07-10 14:56:49,933 INFO    MainThread:32738 [wandb_run.py:_footer_history_summary_info():3499] rendering summary
2023-07-10 14:56:49,933 INFO    MainThread:32738 [wandb_run.py:_footer_sync_info():3426] logging synced files
2023-07-10 14:56:49,933 DEBUG   HandlerThread:32738 [handler.py:handle_request():144] handle_request: shutdown
2023-07-10 14:56:49,933 INFO    HandlerThread:32738 [handler.py:finish():854] shutting down handler
2023-07-10 14:56:50,467 INFO    WriterThread:32738 [datastore.py:close():298] close: /home/zhuhe/HPE-with-Diffusion/wandb/run-20230710_145641-tf2mpncg/run-tf2mpncg.wandb
2023-07-10 14:56:50,933 INFO    SenderThread:32738 [sender.py:finish():1526] shutting down sender
2023-07-10 14:56:50,933 INFO    SenderThread:32738 [file_pusher.py:finish():159] shutting down file pusher
2023-07-10 14:56:50,933 INFO    SenderThread:32738 [file_pusher.py:join():164] waiting for file pusher
